<?xml version="1.0" encoding="utf-8"?><testsuites><testsuite name="docker-py" errors="0" failures="77" skipped="5" tests="266" time="2288.487" timestamp="2022-05-24T10:39:22.088563" hostname="acnologia"><testcase classname="tests.integration.api_build_test.BuildTest" name="test_build_container_with_target" time="24.009" /><testcase classname="tests.integration.api_build_test.BuildTest" name="test_build_from_stringio" time="9.668" /><testcase classname="tests.integration.api_build_test.BuildTest" name="test_build_gzip_custom_encoding" time="10.627" /><testcase classname="tests.integration.api_build_test.BuildTest" name="test_build_gzip_encoding" time="11.598" /><testcase classname="tests.integration.api_build_test.BuildTest" name="test_build_in_context_abs_dockerfile" time="11.979" /><testcase classname="tests.integration.api_build_test.BuildTest" name="test_build_in_context_dockerfile" time="11.542" /><testcase classname="tests.integration.api_build_test.BuildTest" name="test_build_in_context_nested_dockerfile" time="11.577" /><testcase classname="tests.integration.api_build_test.BuildTest" name="test_build_invalid_platform" time="11.532" /><testcase classname="tests.integration.api_build_test.BuildTest" name="test_build_isolation" time="8.831" /><testcase classname="tests.integration.api_build_test.BuildTest" name="test_build_labels" time="8.970" /><testcase classname="tests.integration.api_build_test.BuildTest" name="test_build_out_of_context_dockerfile" time="11.065" /><testcase classname="tests.integration.api_build_test.BuildTest" name="test_build_shmsize" time="8.902" /><testcase classname="tests.integration.api_build_test.BuildTest" name="test_build_squash" time="22.690" /><testcase classname="tests.integration.api_build_test.BuildTest" name="test_build_stderr_data" time="10.113" /><testcase classname="tests.integration.api_build_test.BuildTest" name="test_build_streaming" time="9.555" /><testcase classname="tests.integration.api_build_test.BuildTest" name="test_build_with_buildargs" time="9.463" /><testcase classname="tests.integration.api_build_test.BuildTest" name="test_build_with_cache_from" time="12.208"><failure message="assert 3 == 0">tests/integration/api_build_test.py:248: in test_build_with_cache_from
    assert counter == 0
E   assert 3 == 0</failure><system-out>--------------------------------- Captured Log ---------------------------------

--------------------------------- Captured Out ---------------------------------

</system-out><system-err>--------------------------------- Captured Err ---------------------------------

</system-err></testcase><testcase classname="tests.integration.api_build_test.BuildTest" name="test_build_with_dockerfile_empty_lines" time="7.916" /><testcase classname="tests.integration.api_build_test.BuildTest" name="test_build_with_dockerignore" time="10.226" /><testcase classname="tests.integration.api_build_test.BuildTest" name="test_build_with_extra_hosts" time="7.846"><failure message="docker.errors.APIError: 400 Client Error for http+docker://localhost/v1.40/build?t=dockerpytest_extrahost_build&amp;q=False&amp;nocache=False&amp;rm=False&amp;forcerm=False&amp;pull=False&amp;extrahosts=extrahost.local.test%3A127.0.0.1&amp;extrahosts=hello.world.test%3A127.0.0.1: Bad Request (&quot;failed to parse query parameter 'extrahosts': &quot;hello.world.test:127.0.0.1&quot;: invalid character 'h' looking for beginning of value&quot;)">docker/api/client.py:296: in _raise_for_status
    response.raise_for_status()
../../.virtualenvs/docker-py/lib/python3.10/site-packages/requests/models.py:953: in raise_for_status
    raise HTTPError(http_error_msg, response=self)
E   requests.exceptions.HTTPError: 400 Client Error: Bad Request for url: http+docker://localhost/v1.40/build?t=dockerpytest_extrahost_build&amp;q=False&amp;nocache=False&amp;rm=False&amp;forcerm=False&amp;pull=False&amp;extrahosts=extrahost.local.test%3A127.0.0.1&amp;extrahosts=hello.world.test%3A127.0.0.1

During handling of the above exception, another exception occurred:
tests/integration/api_build_test.py:333: in test_build_with_extra_hosts
    for chunk in stream:
docker/api/client.py:386: in _stream_helper
    yield self._result(response, json=decode)
docker/api/client.py:302: in _result
    self._raise_for_status(response)
docker/api/client.py:298: in _raise_for_status
    raise create_api_error_from_http_exception(e)
docker/errors.py:31: in create_api_error_from_http_exception
    raise cls(e, response=response, explanation=explanation)
E   docker.errors.APIError: 400 Client Error for http+docker://localhost/v1.40/build?t=dockerpytest_extrahost_build&amp;q=False&amp;nocache=False&amp;rm=False&amp;forcerm=False&amp;pull=False&amp;extrahosts=extrahost.local.test%3A127.0.0.1&amp;extrahosts=hello.world.test%3A127.0.0.1: Bad Request ("failed to parse query parameter 'extrahosts': "hello.world.test:127.0.0.1": invalid character 'h' looking for beginning of value")</failure><system-out>--------------------------------- Captured Log ---------------------------------

--------------------------------- Captured Out ---------------------------------

</system-out><system-err>--------------------------------- Captured Err ---------------------------------

</system-err></testcase><testcase classname="tests.integration.api_build_test.BuildTest" name="test_build_with_network_mode" time="8.562"><failure message="docker.errors.APIError: 500 Server Error for http+docker://localhost/v1.40/networks/3621e0789689815d68e93d3616f681aa022805dc8aaa74915a314419cd9892bb/connect: Internal Server Error (&quot;&quot;slirp4netns&quot; is not supported: invalid network mode&quot;)">docker/api/client.py:296: in _raise_for_status
    response.raise_for_status()
../../.virtualenvs/docker-py/lib/python3.10/site-packages/requests/models.py:953: in raise_for_status
    raise HTTPError(http_error_msg, response=self)
E   requests.exceptions.HTTPError: 500 Server Error: Internal Server Error for url: http+docker://localhost/v1.40/networks/3621e0789689815d68e93d3616f681aa022805dc8aaa74915a314419cd9892bb/connect

During handling of the above exception, another exception occurred:
tests/integration/api_build_test.py:280: in test_build_with_network_mode
    self.client.connect_container_to_network(
docker/utils/decorators.py:19: in wrapped
    return f(self, resource_id, *args, **kwargs)
docker/api/network.py:250: in connect_container_to_network
    self._raise_for_status(res)
docker/api/client.py:298: in _raise_for_status
    raise create_api_error_from_http_exception(e)
docker/errors.py:31: in create_api_error_from_http_exception
    raise cls(e, response=response, explanation=explanation)
E   docker.errors.APIError: 500 Server Error for http+docker://localhost/v1.40/networks/3621e0789689815d68e93d3616f681aa022805dc8aaa74915a314419cd9892bb/connect: Internal Server Error (""slirp4netns" is not supported: invalid network mode")</failure><system-out>--------------------------------- Captured Log ---------------------------------

--------------------------------- Captured Out ---------------------------------

</system-out><system-err>--------------------------------- Captured Err ---------------------------------

</system-err></testcase><testcase classname="tests.integration.api_build_test.BuildTest" name="test_build_with_proxy" time="8.105" /><testcase classname="tests.integration.api_build_test.BuildTest" name="test_build_with_proxy_and_buildargs" time="8.005" /><testcase classname="tests.integration.api_build_test.BuildTest" name="test_prune_builds" time="8.513"><skipped type="pytest.xfail" message="Currently fails on 18.09: https://github.com/moby/moby/issues/37920" /></testcase><testcase classname="tests.integration.api_client_test.InformationTest" name="test_info" time="10.059" /><testcase classname="tests.integration.api_client_test.InformationTest" name="test_version" time="10.523" /><testcase classname="tests.integration.api_client_test.AutoDetectVersionTest" name="test_client_init" time="7.887" /><testcase classname="tests.integration.api_client_test.ConnectionTimeoutTest" name="test_timeout" time="0.505" /><testcase classname="tests.integration.api_client_test.UnixconnTest" name="test_resource_warnings" time="2.828" /><testcase classname="tests.integration.api_container_test.ListContainersTest" name="test_list_containers" time="8.265" /><testcase classname="tests.integration.api_container_test.CreateContainerTest" name="test_create" time="8.032" /><testcase classname="tests.integration.api_container_test.CreateContainerTest" name="test_create_container_with_volumes_from" time="9.291" /><testcase classname="tests.integration.api_container_test.CreateContainerTest" name="test_create_with_auto_remove" time="8.594" /><testcase classname="tests.integration.api_container_test.CreateContainerTest" name="test_create_with_cpu_rt_options" time="7.961" /><testcase classname="tests.integration.api_container_test.CreateContainerTest" name="test_create_with_device_cgroup_rules" time="7.970"><failure message="AssertionError: assert None == ['c 7:128 rwm']">tests/integration/api_container_test.py:470: in test_create_with_device_cgroup_rules
    assert config['HostConfig']['DeviceCgroupRules'] == [rule]
E   AssertionError: assert None == ['c 7:128 rwm']</failure><system-out>--------------------------------- Captured Log ---------------------------------

--------------------------------- Captured Out ---------------------------------

</system-out><system-err>--------------------------------- Captured Err ---------------------------------

</system-err></testcase><testcase classname="tests.integration.api_container_test.CreateContainerTest" name="test_create_with_environment_variable_no_value" time="7.973"><failure message="AssertionError: assert 'Foo' in ['PATH=/usr/local/sbin:/usr/local/bin:/usr/sbin:/usr/bin:/sbin:/bin', 'TERM=xterm', 'container=podman', 'Other=one', 'Blank=']">tests/integration/api_container_test.py:366: in test_create_with_environment_variable_no_value
    assert 'Foo' in config['Config']['Env']
E   AssertionError: assert 'Foo' in ['PATH=/usr/local/sbin:/usr/local/bin:/usr/sbin:/usr/bin:/sbin:/bin', 'TERM=xterm', 'container=podman', 'Other=one', 'Blank=']</failure><system-out>--------------------------------- Captured Log ---------------------------------

--------------------------------- Captured Out ---------------------------------

</system-out><system-err>--------------------------------- Captured Err ---------------------------------

</system-err></testcase><testcase classname="tests.integration.api_container_test.CreateContainerTest" name="test_create_with_host_pid_mode" time="8.395" /><testcase classname="tests.integration.api_container_test.CreateContainerTest" name="test_create_with_init" time="7.942" /><testcase classname="tests.integration.api_container_test.CreateContainerTest" name="test_create_with_isolation" time="8.065"><failure message="AssertionError: assert '' == 'default'&#10;  - default">tests/integration/api_container_test.py:395: in test_create_with_isolation
    assert config['HostConfig']['Isolation'] == 'default'
E   AssertionError: assert '' == 'default'
E     - default</failure><system-out>--------------------------------- Captured Log ---------------------------------

--------------------------------- Captured Out ---------------------------------

</system-out><system-err>--------------------------------- Captured Err ---------------------------------

</system-err></testcase><testcase classname="tests.integration.api_container_test.CreateContainerTest" name="test_create_with_links" time="9.494"><failure message="docker.errors.APIError: 400 Client Error for http+docker://localhost/v1.40/containers/create: Bad Request (&quot;bad parameter: Link is not supported&quot;)">docker/api/client.py:296: in _raise_for_status
    response.raise_for_status()
../../.virtualenvs/docker-py/lib/python3.10/site-packages/requests/models.py:953: in raise_for_status
    raise HTTPError(http_error_msg, response=self)
E   requests.exceptions.HTTPError: 400 Client Error: Bad Request for url: http+docker://localhost/v1.40/containers/create

During handling of the above exception, another exception occurred:
tests/integration/api_container_test.py:95: in test_create_with_links
    res2 = self.client.create_container(
docker/api/container.py:428: in create_container
    return self.create_container_from_config(config, name)
docker/api/container.py:439: in create_container_from_config
    return self._result(res, True)
docker/api/client.py:302: in _result
    self._raise_for_status(response)
docker/api/client.py:298: in _raise_for_status
    raise create_api_error_from_http_exception(e)
docker/errors.py:31: in create_api_error_from_http_exception
    raise cls(e, response=response, explanation=explanation)
E   docker.errors.APIError: 400 Client Error for http+docker://localhost/v1.40/containers/create: Bad Request ("bad parameter: Link is not supported")</failure><system-out>--------------------------------- Captured Log ---------------------------------

--------------------------------- Captured Out ---------------------------------

</system-out><system-err>--------------------------------- Captured Err ---------------------------------

</system-err></testcase><testcase classname="tests.integration.api_container_test.CreateContainerTest" name="test_create_with_mac_address" time="8.279"><failure message="AssertionError: assert '02:42:ac:11:00:0a' == ''&#10;  + 02:42:ac:11:00:0a">tests/integration/api_container_test.py:214: in test_create_with_mac_address
    assert mac_address_expected == res['NetworkSettings']['MacAddress']
E   AssertionError: assert '02:42:ac:11:00:0a' == ''
E     + 02:42:ac:11:00:0a</failure><system-out>--------------------------------- Captured Log ---------------------------------

--------------------------------- Captured Out ---------------------------------

</system-out><system-err>--------------------------------- Captured Err ---------------------------------

</system-err></testcase><testcase classname="tests.integration.api_container_test.CreateContainerTest" name="test_create_with_memory_constraints_with_int" time="8.390" /><testcase classname="tests.integration.api_container_test.CreateContainerTest" name="test_create_with_memory_constraints_with_str" time="8.311" /><testcase classname="tests.integration.api_container_test.CreateContainerTest" name="test_create_with_restart_policy" time="10.388"><failure message="Failed: DID NOT RAISE &lt;class 'docker.errors.APIError'&gt;">tests/integration/api_container_test.py:123: in test_create_with_restart_policy
    with pytest.raises(docker.errors.APIError) as exc:
E   Failed: DID NOT RAISE &lt;class 'docker.errors.APIError'&gt;</failure><system-out>--------------------------------- Captured Log ---------------------------------

--------------------------------- Captured Out ---------------------------------

</system-out><system-err>--------------------------------- Captured Err ---------------------------------

</system-err></testcase><testcase classname="tests.integration.api_container_test.CreateContainerTest" name="test_create_with_stop_timeout" time="8.012" /><testcase classname="tests.integration.api_container_test.CreateContainerTest" name="test_create_with_storage_opt" time="7.894"><skipped type="pytest.xfail" message="Not supported on most drivers" /></testcase><testcase classname="tests.integration.api_container_test.CreateContainerTest" name="test_create_with_tmpfs" time="7.983"><failure message="AssertionError: assert {'/tmp1': 'si...ev,tmpcopyup'} == {'/tmp1': 'size=3M'}&#10;  Differing items:&#10;  {'/tmp1': 'size=3M,rw,rprivate,nosuid,nodev,tmpcopyup'} != {'/tmp1': 'size=3M'}&#10;  Full diff:&#10;  - {'/tmp1': 'size=3M'}&#10;  + {'/tmp1': 'size=3M,rw,rprivate,nosuid,nodev,tmpcopyup'}">tests/integration/api_container_test.py:384: in test_create_with_tmpfs
    assert config['HostConfig']['Tmpfs'] == tmpfs
E   AssertionError: assert {'/tmp1': 'si...ev,tmpcopyup'} == {'/tmp1': 'size=3M'}
E     Differing items:
E     {'/tmp1': 'size=3M,rw,rprivate,nosuid,nodev,tmpcopyup'} != {'/tmp1': 'size=3M'}
E     Full diff:
E     - {'/tmp1': 'size=3M'}
E     + {'/tmp1': 'size=3M,rw,rprivate,nosuid,nodev,tmpcopyup'}</failure><system-out>--------------------------------- Captured Log ---------------------------------

--------------------------------- Captured Out ---------------------------------

</system-out><system-err>--------------------------------- Captured Err ---------------------------------

</system-err></testcase><testcase classname="tests.integration.api_container_test.CreateContainerTest" name="test_create_with_uts_mode" time="7.947" /><testcase classname="tests.integration.api_container_test.CreateContainerTest" name="test_group_id_ints" time="8.643" /><testcase classname="tests.integration.api_container_test.CreateContainerTest" name="test_group_id_strings" time="8.290" /><testcase classname="tests.integration.api_container_test.CreateContainerTest" name="test_invalid_log_driver_raises_exception" time="7.918"><failure message="assert 'container create: error running container create option: invalid log driver: invalid argument' in [&quot;logger: no log driver named 'asdf' is registered&quot;, 'error looking up logging plugin asdf: plugin &quot;asdf&quot; not found']&#10; +  where 'container create: error running container create option: invalid log driver: invalid argument' = APIError(HTTPError('500 Server Error: Internal Server Error for url: http+docker://localhost/v1.40/containers/create')).explanation&#10; +    where APIError(HTTPError('500 Server Error: Internal Server Error for url: http+docker://localhost/v1.40/containers/create')) = &lt;ExceptionInfo APIError(HTTPError('500 Server Error: Internal Server Error for url: http+docker://localhost/v1.40/containers/create')) tblen=6&gt;.value">tests/integration/api_container_test.py:286: in test_invalid_log_driver_raises_exception
    assert excinfo.value.explanation in expected_msgs
E   assert 'container create: error running container create option: invalid log driver: invalid argument' in ["logger: no log driver named 'asdf' is registered", 'error looking up logging plugin asdf: plugin "asdf" not found']
E    +  where 'container create: error running container create option: invalid log driver: invalid argument' = APIError(HTTPError('500 Server Error: Internal Server Error for url: http+docker://localhost/v1.40/containers/create')).explanation
E    +    where APIError(HTTPError('500 Server Error: Internal Server Error for url: http+docker://localhost/v1.40/containers/create')) = &lt;ExceptionInfo APIError(HTTPError('500 Server Error: Internal Server Error for url: http+docker://localhost/v1.40/containers/create')) tblen=6&gt;.value</failure><system-out>--------------------------------- Captured Log ---------------------------------

--------------------------------- Captured Out ---------------------------------

</system-out><system-err>--------------------------------- Captured Err ---------------------------------

</system-err></testcase><testcase classname="tests.integration.api_container_test.CreateContainerTest" name="test_valid_log_driver_and_log_opt" time="8.245"><failure message="AssertionError: assert None == {'max-file': '100'}&#10; +  where {'max-file': '100'} = {'Type': 'json-file', 'Config': {'max-file': '100'}}.config">tests/integration/api_container_test.py:265: in test_valid_log_driver_and_log_opt
    assert container_log_config['Config'] == log_config.config
E   AssertionError: assert None == {'max-file': '100'}
E    +  where {'max-file': '100'} = {'Type': 'json-file', 'Config': {'max-file': '100'}}.config</failure><system-out>--------------------------------- Captured Log ---------------------------------

--------------------------------- Captured Out ---------------------------------

</system-out><system-err>--------------------------------- Captured Err ---------------------------------

</system-err></testcase><testcase classname="tests.integration.api_container_test.CreateContainerTest" name="test_valid_no_config_specified" time="8.346"><failure message="assert None == {}">tests/integration/api_container_test.py:324: in test_valid_no_config_specified
    assert container_log_config['Config'] == {}
E   assert None == {}</failure><system-out>--------------------------------- Captured Log ---------------------------------

--------------------------------- Captured Out ---------------------------------

</system-out><system-err>--------------------------------- Captured Err ---------------------------------

</system-err></testcase><testcase classname="tests.integration.api_container_test.CreateContainerTest" name="test_valid_no_log_driver_specified" time="8.349"><failure message="AssertionError: assert 'journald' == 'json-file'&#10;  - json-file&#10;  + journald">tests/integration/api_container_test.py:304: in test_valid_no_log_driver_specified
    assert container_log_config['Type'] == "json-file"
E   AssertionError: assert 'journald' == 'json-file'
E     - json-file
E     + journald</failure><system-out>--------------------------------- Captured Log ---------------------------------

--------------------------------- Captured Out ---------------------------------

</system-out><system-err>--------------------------------- Captured Err ---------------------------------

</system-err></testcase><testcase classname="tests.integration.api_container_test.VolumeBindTest" name="test_create_with_binds_ro" time="9.317" /><testcase classname="tests.integration.api_container_test.VolumeBindTest" name="test_create_with_binds_rw" time="9.104" /><testcase classname="tests.integration.api_container_test.VolumeBindTest" name="test_create_with_mounts" time="9.064" /><testcase classname="tests.integration.api_container_test.VolumeBindTest" name="test_create_with_mounts_ro" time="9.367" /><testcase classname="tests.integration.api_container_test.VolumeBindTest" name="test_create_with_volume_mount" time="8.386" /><testcase classname="tests.integration.api_container_test.ArchiveTest" name="test_copy_directory_to_container" time="8.694" /><testcase classname="tests.integration.api_container_test.ArchiveTest" name="test_copy_file_to_container" time="8.706" /><testcase classname="tests.integration.api_container_test.ArchiveTest" name="test_get_file_archive_from_container" time="9.072" /><testcase classname="tests.integration.api_container_test.ArchiveTest" name="test_get_file_stat_from_container" time="9.079" /><testcase classname="tests.integration.api_container_test.RenameContainerTest" name="test_rename_container" time="10.698" /><testcase classname="tests.integration.api_container_test.StartContainerTest" name="test_run_shlex_commands" time="10.439" /><testcase classname="tests.integration.api_container_test.StartContainerTest" name="test_start_container" time="8.514" /><testcase classname="tests.integration.api_container_test.StartContainerTest" name="test_start_container_with_dict_instead_of_id" time="8.250" /><testcase classname="tests.integration.api_container_test.WaitTest" name="test_wait" time="11.159" /><testcase classname="tests.integration.api_container_test.WaitTest" name="test_wait_with_condition" time="12.813" /><testcase classname="tests.integration.api_container_test.WaitTest" name="test_wait_with_dict_instead_of_id" time="11.208" /><testcase classname="tests.integration.api_container_test.LogsTest" name="test_logs" time="8.515" /><testcase classname="tests.integration.api_container_test.LogsTest" name="test_logs_streaming_and_follow" time="8.594" /><testcase classname="tests.integration.api_container_test.LogsTest" name="test_logs_streaming_and_follow_and_cancel" time="5.001"><failure message="Failed: Timeout &gt;5.0s">tests/integration/base.py:80: in setUp
    self.is_podman = self._is_podman(self.client)
tests/integration/base.py:103: in _is_podman
    in client.version()['Components']
docker/api/daemon.py:181: in version
    return self._result(self._get(url), json=True)
docker/utils/decorators.py:46: in inner
    return f(self, *args, **kwargs)
docker/api/client.py:251: in _get
    return self.get(url, **self._set_request_timeout(kwargs))
../../.virtualenvs/docker-py/lib/python3.10/site-packages/requests/sessions.py:555: in get
    return self.request('GET', url, **kwargs)
../../.virtualenvs/docker-py/lib/python3.10/site-packages/requests/sessions.py:542: in request
    resp = self.send(prep, **send_kwargs)
../../.virtualenvs/docker-py/lib/python3.10/site-packages/requests/sessions.py:655: in send
    r = adapter.send(request, **kwargs)
../../.virtualenvs/docker-py/lib/python3.10/site-packages/requests/adapters.py:439: in send
    resp = conn.urlopen(
../../.virtualenvs/docker-py/lib/python3.10/site-packages/urllib3/connectionpool.py:699: in urlopen
    httplib_response = self._make_request(
../../.virtualenvs/docker-py/lib/python3.10/site-packages/urllib3/connectionpool.py:445: in _make_request
    six.raise_from(e, None)
../../.virtualenvs/docker-py/lib/python3.10/site-packages/urllib3/connectionpool.py:440: in _make_request
    httplib_response = conn.getresponse()
/usr/lib/python3.10/http/client.py:1374: in getresponse
    response.begin()
/usr/lib/python3.10/http/client.py:318: in begin
    version, status, reason = self._read_status()
/usr/lib/python3.10/http/client.py:279: in _read_status
    line = str(self.fp.readline(_MAXLINE + 1), "iso-8859-1")
/usr/lib/python3.10/socket.py:705: in readinto
    return self._sock.recv_into(b)
E   Failed: Timeout &gt;5.0s</failure><system-out>--------------------------------- Captured Log ---------------------------------

--------------------------------- Captured Out ---------------------------------

</system-out><system-err>--------------------------------- Captured Err ---------------------------------

</system-err></testcase><testcase classname="tests.integration.api_container_test.LogsTest" name="test_logs_tail_option" time="8.593" /><testcase classname="tests.integration.api_container_test.LogsTest" name="test_logs_with_dict_instead_of_id" time="8.649" /><testcase classname="tests.integration.api_container_test.LogsTest" name="test_logs_with_tail_0" time="8.594" /><testcase classname="tests.integration.api_container_test.LogsTest" name="test_logs_with_until" time="8.673" /><testcase classname="tests.integration.api_container_test.DiffTest" name="test_diff" time="8.422" /><testcase classname="tests.integration.api_container_test.DiffTest" name="test_diff_with_dict_instead_of_id" time="8.391" /><testcase classname="tests.integration.api_container_test.StopTest" name="test_stop" time="10.848" /><testcase classname="tests.integration.api_container_test.StopTest" name="test_stop_with_dict_instead_of_id" time="11.113" /><testcase classname="tests.integration.api_container_test.KillTest" name="test_kill" time="8.322" /><testcase classname="tests.integration.api_container_test.KillTest" name="test_kill_with_dict_instead_of_id" time="8.442" /><testcase classname="tests.integration.api_container_test.KillTest" name="test_kill_with_signal" time="8.416" /><testcase classname="tests.integration.api_container_test.KillTest" name="test_kill_with_signal_integer" time="8.445" /><testcase classname="tests.integration.api_container_test.KillTest" name="test_kill_with_signal_name" time="8.319" /><testcase classname="tests.integration.api_container_test.PortTest" name="test_port" time="9.337" /><testcase classname="tests.integration.api_container_test.ContainerTopTest" name="test_top" time="8.833"><skipped type="pytest.xfail" message="Output of docker top depends on host distro, and is not formalized." /></testcase><testcase classname="tests.integration.api_container_test.ContainerTopTest" name="test_top_with_psargs" time="8.828"><skipped type="pytest.xfail" message="Output of docker top depends on host distro, and is not formalized." /></testcase><testcase classname="tests.integration.api_container_test.RestartContainerTest" name="test_restart" time="11.136" /><testcase classname="tests.integration.api_container_test.RestartContainerTest" name="test_restart_with_dict_instead_of_id" time="10.972" /><testcase classname="tests.integration.api_container_test.RestartContainerTest" name="test_restart_with_low_timeout" time="11.474" /><testcase classname="tests.integration.api_container_test.RemoveContainerTest" name="test_remove" time="8.310" /><testcase classname="tests.integration.api_container_test.RemoveContainerTest" name="test_remove_with_dict_instead_of_id" time="8.418" /><testcase classname="tests.integration.api_container_test.AttachContainerTest" name="test_attach_no_stream" time="8.670"><failure message="AssertionError: assert b'hello' == b'hello\n'&#10;  Full diff:&#10;  - b'hello\n'&#10;  ?        --&#10;  + b'hello'">tests/integration/api_container_test.py:1230: in test_attach_no_stream
    assert output == 'hello\n'.encode(encoding='ascii')
E   AssertionError: assert b'hello' == b'hello\n'
E     Full diff:
E     - b'hello\n'
E     ?        --
E     + b'hello'</failure><system-out>--------------------------------- Captured Log ---------------------------------

--------------------------------- Captured Out ---------------------------------

</system-out><system-err>--------------------------------- Captured Err ---------------------------------

</system-err></testcase><testcase classname="tests.integration.api_container_test.AttachContainerTest" name="test_attach_stream_and_cancel" time="10.001"><failure message="Failed: Timeout &gt;10.0s">tests/integration/base.py:83: in tearDown
    super().tearDown()
tests/integration/base.py:30: in tearDown
    client = docker.from_env(version=TEST_API_VERSION)
docker/client.py:96: in from_env
    return cls(
docker/client.py:45: in __init__
    self.api = APIClient(*args, **kwargs)
docker/api/client.py:197: in __init__
    self._version = self._retrieve_server_version()
docker/api/client.py:214: in _retrieve_server_version
    return self.version(api_version=False)["ApiVersion"]
docker/api/daemon.py:181: in version
    return self._result(self._get(url), json=True)
docker/utils/decorators.py:46: in inner
    return f(self, *args, **kwargs)
docker/api/client.py:251: in _get
    return self.get(url, **self._set_request_timeout(kwargs))
../../.virtualenvs/docker-py/lib/python3.10/site-packages/requests/sessions.py:555: in get
    return self.request('GET', url, **kwargs)
../../.virtualenvs/docker-py/lib/python3.10/site-packages/requests/sessions.py:542: in request
    resp = self.send(prep, **send_kwargs)
../../.virtualenvs/docker-py/lib/python3.10/site-packages/requests/sessions.py:655: in send
    r = adapter.send(request, **kwargs)
../../.virtualenvs/docker-py/lib/python3.10/site-packages/requests/adapters.py:439: in send
    resp = conn.urlopen(
../../.virtualenvs/docker-py/lib/python3.10/site-packages/urllib3/connectionpool.py:699: in urlopen
    httplib_response = self._make_request(
../../.virtualenvs/docker-py/lib/python3.10/site-packages/urllib3/connectionpool.py:445: in _make_request
    six.raise_from(e, None)
../../.virtualenvs/docker-py/lib/python3.10/site-packages/urllib3/connectionpool.py:440: in _make_request
    httplib_response = conn.getresponse()
/usr/lib/python3.10/http/client.py:1374: in getresponse
    response.begin()
/usr/lib/python3.10/http/client.py:318: in begin
    version, status, reason = self._read_status()
/usr/lib/python3.10/http/client.py:279: in _read_status
    line = str(self.fp.readline(_MAXLINE + 1), "iso-8859-1")
/usr/lib/python3.10/socket.py:705: in readinto
    return self._sock.recv_into(b)
E   Failed: Timeout &gt;10.0s</failure><system-out>--------------------------------- Captured Log ---------------------------------

--------------------------------- Captured Out ---------------------------------

</system-out><system-err>--------------------------------- Captured Err ---------------------------------

</system-err></testcase><testcase classname="tests.integration.api_container_test.AttachContainerTest" name="test_detach_with_arg" time="9.157" /><testcase classname="tests.integration.api_container_test.AttachContainerTest" name="test_detach_with_config_file" time="9.144" /><testcase classname="tests.integration.api_container_test.AttachContainerTest" name="test_detach_with_default" time="9.616" /><testcase classname="tests.integration.api_container_test.AttachContainerTest" name="test_run_container_reading_socket" time="8.530" /><testcase classname="tests.integration.api_container_test.AttachContainerTest" name="test_run_container_streaming" time="8.552" /><testcase classname="tests.integration.api_container_test.PauseTest" name="test_pause_unpause" time="8.752" /><testcase classname="tests.integration.api_container_test.PruneTest" name="test_prune_containers" time="9.100" /><testcase classname="tests.integration.api_container_test.GetContainerStatsTest" name="test_get_container_stats_no_stream" time="8.290" /><testcase classname="tests.integration.api_container_test.ContainerUpdateTest" name="test_restart_policy_update" time="8.535"><failure message="docker.errors.NotFound: 404 Client Error for http+docker://localhost/v1.40/containers/e3b54aecf9a75594c672b547011f35392b9797955d16411d12f85f5cabca412e/update: Not Found (&quot;b'Not Found'&quot;)">docker/api/client.py:296: in _raise_for_status
    response.raise_for_status()
../../.virtualenvs/docker-py/lib/python3.10/site-packages/requests/models.py:953: in raise_for_status
    raise HTTPError(http_error_msg, response=self)
E   requests.exceptions.HTTPError: 404 Client Error: Not Found for url: http+docker://localhost/v1.40/containers/e3b54aecf9a75594c672b547011f35392b9797955d16411d12f85f5cabca412e/update

During handling of the above exception, another exception occurred:
tests/integration/api_container_test.py:1416: in test_restart_policy_update
    self.client.update_container(container,
docker/utils/decorators.py:34: in wrapper
    return f(self, *args, **kwargs)
docker/utils/decorators.py:19: in wrapped
    return f(self, resource_id, *args, **kwargs)
docker/api/container.py:1268: in update_container
    return self._result(res, True)
docker/api/client.py:302: in _result
    self._raise_for_status(response)
docker/api/client.py:298: in _raise_for_status
    raise create_api_error_from_http_exception(e)
docker/errors.py:31: in create_api_error_from_http_exception
    raise cls(e, response=response, explanation=explanation)
E   docker.errors.NotFound: 404 Client Error for http+docker://localhost/v1.40/containers/e3b54aecf9a75594c672b547011f35392b9797955d16411d12f85f5cabca412e/update: Not Found ("b'Not Found'")</failure><system-out>--------------------------------- Captured Log ---------------------------------

--------------------------------- Captured Out ---------------------------------

</system-out><system-err>--------------------------------- Captured Err ---------------------------------

</system-err></testcase><testcase classname="tests.integration.api_container_test.ContainerUpdateTest" name="test_update_container" time="8.503"><failure message="docker.errors.NotFound: 404 Client Error for http+docker://localhost/v1.40/containers/984ad1cf0813bea55c1fd9d77d8e7821438ed8852533af34f84cd6f340407ac2/update: Not Found (&quot;b'Not Found'&quot;)">docker/api/client.py:296: in _raise_for_status
    response.raise_for_status()
../../.virtualenvs/docker-py/lib/python3.10/site-packages/requests/models.py:953: in raise_for_status
    raise HTTPError(http_error_msg, response=self)
E   requests.exceptions.HTTPError: 404 Client Error: Not Found for url: http+docker://localhost/v1.40/containers/984ad1cf0813bea55c1fd9d77d8e7821438ed8852533af34f84cd6f340407ac2/update

During handling of the above exception, another exception occurred:
tests/integration/api_container_test.py:1394: in test_update_container
    self.client.update_container(container, mem_limit=new_mem_limit)
docker/utils/decorators.py:34: in wrapper
    return f(self, *args, **kwargs)
docker/utils/decorators.py:19: in wrapped
    return f(self, resource_id, *args, **kwargs)
docker/api/container.py:1268: in update_container
    return self._result(res, True)
docker/api/client.py:302: in _result
    self._raise_for_status(response)
docker/api/client.py:298: in _raise_for_status
    raise create_api_error_from_http_exception(e)
docker/errors.py:31: in create_api_error_from_http_exception
    raise cls(e, response=response, explanation=explanation)
E   docker.errors.NotFound: 404 Client Error for http+docker://localhost/v1.40/containers/984ad1cf0813bea55c1fd9d77d8e7821438ed8852533af34f84cd6f340407ac2/update: Not Found ("b'Not Found'")</failure><system-out>--------------------------------- Captured Log ---------------------------------

--------------------------------- Captured Out ---------------------------------

</system-out><system-err>--------------------------------- Captured Err ---------------------------------

</system-err></testcase><testcase classname="tests.integration.api_container_test.ContainerCPUTest" name="test_container_cpu_shares" time="8.328" /><testcase classname="tests.integration.api_container_test.ContainerCPUTest" name="test_container_cpuset" time="8.218" /><testcase classname="tests.integration.api_container_test.ContainerCPUTest" name="test_create_with_runtime" time="8.341"><failure message="AssertionError: assert 'oci' == 'runc'&#10;  - runc&#10;  + oci">tests/integration/api_container_test.py:1461: in test_create_with_runtime
    assert config['HostConfig']['Runtime'] == 'runc'
E   AssertionError: assert 'oci' == 'runc'
E     - runc
E     + oci</failure><system-out>--------------------------------- Captured Log ---------------------------------

--------------------------------- Captured Out ---------------------------------

</system-out><system-err>--------------------------------- Captured Err ---------------------------------

</system-err></testcase><testcase classname="tests.integration.api_exec_test.ExecTest" name="test_detach_with_config_file" time="13.749"><failure message="AssertionError">tests/integration/api_exec_test.py:227: in test_detach_with_config_file
    assert_cat_socket_detached_with_keys(sock, [ctrl_with('p')])
tests/helpers.py:137: in assert_cat_socket_detached_with_keys
    assert data == b'' or data.startswith(
E   AssertionError</failure><system-out>--------------------------------- Captured Log ---------------------------------

--------------------------------- Captured Out ---------------------------------

</system-out><system-err>--------------------------------- Captured Err ---------------------------------

</system-err></testcase><testcase classname="tests.integration.api_exec_test.ExecTest" name="test_detach_with_default" time="14.267"><failure message="AssertionError">tests/integration/api_exec_test.py:208: in test_detach_with_default
    assert_cat_socket_detached_with_keys(
tests/helpers.py:137: in assert_cat_socket_detached_with_keys
    assert data == b'' or data.startswith(
E   AssertionError</failure><system-out>--------------------------------- Captured Log ---------------------------------

--------------------------------- Captured Out ---------------------------------

</system-out><system-err>--------------------------------- Captured Err ---------------------------------

</system-err></testcase><testcase classname="tests.integration.api_exec_test.ExecTest" name="test_exec_command_as_root" time="8.872" /><testcase classname="tests.integration.api_exec_test.ExecTest" name="test_exec_command_as_user" time="8.727" /><testcase classname="tests.integration.api_exec_test.ExecTest" name="test_exec_command_streaming" time="10.015" /><testcase classname="tests.integration.api_exec_test.ExecTest" name="test_exec_command_string" time="8.871" /><testcase classname="tests.integration.api_exec_test.ExecTest" name="test_exec_command_with_env" time="8.893" /><testcase classname="tests.integration.api_exec_test.ExecTest" name="test_exec_command_with_workdir" time="8.888" /><testcase classname="tests.integration.api_exec_test.ExecTest" name="test_exec_inspect" time="8.996" /><testcase classname="tests.integration.api_exec_test.ExecTest" name="test_exec_start_detached" time="8.774"><failure message="AssertionError: assert '\n' == ''&#10;  Strings contain only whitespace, escaping them using repr()&#10;  - ''&#10;  + '\n'">tests/integration/api_exec_test.py:152: in test_exec_start_detached
    assert response == ""
E   AssertionError: assert '\n' == ''
E     Strings contain only whitespace, escaping them using repr()
E     - ''
E     + '\n'</failure><system-out>--------------------------------- Captured Log ---------------------------------

--------------------------------- Captured Out ---------------------------------

</system-out><system-err>--------------------------------- Captured Err ---------------------------------

</system-err></testcase><testcase classname="tests.integration.api_exec_test.ExecTest" name="test_exec_start_socket" time="8.806"><failure message="assert 121 == 1">tests/integration/api_exec_test.py:134: in test_exec_start_socket
    assert stream == 1  # stdout (0 = stdin, 1 = stdout, 2 = stderr)
E   assert 121 == 1</failure><system-out>--------------------------------- Captured Log ---------------------------------

--------------------------------- Captured Out ---------------------------------

</system-out><system-err>--------------------------------- Captured Err ---------------------------------

</system-err></testcase><testcase classname="tests.integration.api_exec_test.ExecTest" name="test_execute_command" time="8.925" /><testcase classname="tests.integration.api_exec_test.ExecTest" name="test_execute_command_with_proxy_env" time="9.440" /><testcase classname="tests.integration.api_exec_test.ExecDemuxTest" name="test_exec_command_no_stream_demux" time="9.632" /><testcase classname="tests.integration.api_exec_test.ExecDemuxTest" name="test_exec_command_no_stream_no_demux" time="9.639" /><testcase classname="tests.integration.api_exec_test.ExecDemuxTest" name="test_exec_command_stream_demux" time="9.426" /><testcase classname="tests.integration.api_exec_test.ExecDemuxTest" name="test_exec_command_stream_no_demux" time="9.132" /><testcase classname="tests.integration.api_exec_test.ExecDemuxTest" name="test_exec_command_tty_no_stream_demux" time="8.667"><failure message="ValueError: 104 is not a valid stream">tests/integration/api_exec_test.py:299: in test_exec_command_tty_no_stream_demux
    exec_log = self.client.exec_start(res, demux=True)
docker/utils/decorators.py:19: in wrapped
    return f(self, resource_id, *args, **kwargs)
docker/api/exec_api.py:173: in exec_start
    output = self._read_from_socket(res, stream, tty=tty, demux=demux)
docker/api/client.py:457: in _read_from_socket
    return consume_socket_output(gen, demux=demux)
docker/utils/socket.py:140: in consume_socket_output
    for frame in frames:
docker/api/client.py:447: in &lt;genexpr&gt;
    gen = (demux_adaptor(*frame) for frame in gen)
docker/utils/socket.py:167: in demux_adaptor
    raise ValueError(f'{stream_id} is not a valid stream')
E   ValueError: 104 is not a valid stream</failure><system-out>--------------------------------- Captured Log ---------------------------------

--------------------------------- Captured Out ---------------------------------

</system-out><system-err>--------------------------------- Captured Err ---------------------------------

</system-err></testcase><testcase classname="tests.integration.api_exec_test.ExecDemuxTest" name="test_exec_command_tty_no_stream_no_demux" time="9.241"><failure message="AssertionError: assert b't\r\nhello err\r\n' == b'hello out\r\nhello err\r\n'&#10;  At index 0 diff: b't' != b'h'&#10;  Full diff:&#10;  - b'hello out\r\nhello err\r\n'&#10;  ?   --------&#10;  + b't\r\nhello err\r\n'">tests/integration/api_exec_test.py:282: in test_exec_command_tty_no_stream_no_demux
    assert exec_log == b'hello out\r\nhello err\r\n'
E   AssertionError: assert b't\r\nhello err\r\n' == b'hello out\r\nhello err\r\n'
E     At index 0 diff: b't' != b'h'
E     Full diff:
E     - b'hello out\r\nhello err\r\n'
E     ?   --------
E     + b't\r\nhello err\r\n'</failure><system-out>--------------------------------- Captured Log ---------------------------------

--------------------------------- Captured Out ---------------------------------

</system-out><system-err>--------------------------------- Captured Err ---------------------------------

</system-err></testcase><testcase classname="tests.integration.api_exec_test.ExecDemuxTest" name="test_exec_command_tty_stream_demux" time="8.594"><failure message="ValueError: 104 is not a valid stream">tests/integration/api_exec_test.py:305: in test_exec_command_tty_stream_demux
    exec_log = list(self.client.exec_start(res, demux=True, stream=True))
docker/types/daemon.py:32: in __next__
    return next(self._stream)
docker/api/client.py:447: in &lt;genexpr&gt;
    gen = (demux_adaptor(*frame) for frame in gen)
docker/utils/socket.py:167: in demux_adaptor
    raise ValueError(f'{stream_id} is not a valid stream')
E   ValueError: 104 is not a valid stream</failure><system-out>--------------------------------- Captured Log ---------------------------------

--------------------------------- Captured Out ---------------------------------

</system-out><system-err>--------------------------------- Captured Err ---------------------------------

</system-err></testcase><testcase classname="tests.integration.api_exec_test.ExecDemuxTest" name="test_exec_command_tty_stream_no_demux" time="9.154"><failure message="AssertionError: assert b'hello out\r\n' in [b't\r\n', b'hello err\r\n']">tests/integration/api_exec_test.py:288: in test_exec_command_tty_stream_no_demux
    assert b'hello out\r\n' in exec_log
E   AssertionError: assert b'hello out\r\n' in [b't\r\n', b'hello err\r\n']</failure><system-out>--------------------------------- Captured Log ---------------------------------

--------------------------------- Captured Out ---------------------------------

</system-out><system-err>--------------------------------- Captured Err ---------------------------------

</system-err></testcase><testcase classname="tests.integration.api_healthcheck_test.HealthcheckTest" name="test_healthcheck_fails" time="8.796" /><testcase classname="tests.integration.api_healthcheck_test.HealthcheckTest" name="test_healthcheck_passes" time="9.037" /><testcase classname="tests.integration.api_healthcheck_test.HealthcheckTest" name="test_healthcheck_shell_command" time="7.933" /><testcase classname="tests.integration.api_healthcheck_test.HealthcheckTest" name="test_healthcheck_start_period" time="12.884" /><testcase classname="tests.integration.api_image_test.ListImagesTest" name="test_images" time="9.667" /><testcase classname="tests.integration.api_image_test.ListImagesTest" name="test_images_quiet" time="7.756" /><testcase classname="tests.integration.api_image_test.PullImageTest" name="test_pull" time="12.014" /><testcase classname="tests.integration.api_image_test.PullImageTest" name="test_pull_invalid_platform" time="12.289"><failure message="Failed: DID NOT RAISE &lt;class 'docker.errors.APIError'&gt;">tests/integration/api_image_test.py:68: in test_pull_invalid_platform
    with pytest.raises(docker.errors.APIError) as excinfo:
E   Failed: DID NOT RAISE &lt;class 'docker.errors.APIError'&gt;</failure><system-out>--------------------------------- Captured Log ---------------------------------

--------------------------------- Captured Out ---------------------------------

</system-out><system-err>--------------------------------- Captured Err ---------------------------------

</system-err></testcase><testcase classname="tests.integration.api_image_test.PullImageTest" name="test_pull_streaming" time="11.402" /><testcase classname="tests.integration.api_image_test.CommitTest" name="test_commit" time="8.586"><failure message="AssertionError: assert False&#10; +  where False = &lt;built-in method startswith of str object at 0x7fddcf130030&gt;('8e9921d6ede4564754624d4c9283eb93e43ba7c4af84ded0ef3237a57d44ee87')&#10; +    where &lt;built-in method startswith of str object at 0x7fddcf130030&gt; = ''.startswith">tests/integration/api_image_test.py:89: in test_commit
    assert img['Container'].startswith(id)
E   AssertionError: assert False
E    +  where False = &lt;built-in method startswith of str object at 0x7fddcf130030&gt;('8e9921d6ede4564754624d4c9283eb93e43ba7c4af84ded0ef3237a57d44ee87')
E    +    where &lt;built-in method startswith of str object at 0x7fddcf130030&gt; = ''.startswith</failure><system-out>--------------------------------- Captured Log ---------------------------------

--------------------------------- Captured Out ---------------------------------

</system-out><system-err>--------------------------------- Captured Err ---------------------------------

</system-err></testcase><testcase classname="tests.integration.api_image_test.CommitTest" name="test_commit_with_changes" time="9.085"><failure message="AssertionError: assert False&#10; +  where False = &lt;built-in method startswith of str object at 0x7fddcf130030&gt;('f80eac0fb2e0611cac6630229387ab6dbdc72e7384a8d4283cadbba356cd4975')&#10; +    where &lt;built-in method startswith of str object at 0x7fddcf130030&gt; = ''.startswith">tests/integration/api_image_test.py:107: in test_commit_with_changes
    assert img['Container'].startswith(cid['Id'])
E   AssertionError: assert False
E    +  where False = &lt;built-in method startswith of str object at 0x7fddcf130030&gt;('f80eac0fb2e0611cac6630229387ab6dbdc72e7384a8d4283cadbba356cd4975')
E    +    where &lt;built-in method startswith of str object at 0x7fddcf130030&gt; = ''.startswith</failure><system-out>--------------------------------- Captured Log ---------------------------------

--------------------------------- Captured Out ---------------------------------

</system-out><system-err>--------------------------------- Captured Err ---------------------------------

</system-err></testcase><testcase classname="tests.integration.api_image_test.RemoveImageTest" name="test_remove" time="9.099" /><testcase classname="tests.integration.api_image_test.ImportImageTest" name="test_get_load_image" time="11.348"><failure message="assert False&#10; +  where False = any([])">tests/integration/api_image_test.py:266: in test_get_load_image
    assert any([
E   assert False
E    +  where False = any([])</failure><system-out>--------------------------------- Captured Log ---------------------------------

--------------------------------- Captured Out ---------------------------------

</system-out><system-err>--------------------------------- Captured Err ---------------------------------

</system-err></testcase><testcase classname="tests.integration.api_image_test.ImportImageTest" name="test_import_from_bytes" time="8.030" /><testcase classname="tests.integration.api_image_test.ImportImageTest" name="test_import_from_file" time="7.956" /><testcase classname="tests.integration.api_image_test.ImportImageTest" name="test_import_from_stream" time="7.988" /><testcase classname="tests.integration.api_image_test.ImportImageTest" name="test_import_from_url" time="0.000"><skipped type="pytest.skip" message="Doesn't work inside a container - FIXME">/home/riyad/src/docker-py/tests/integration/api_image_test.py:291: Doesn't work inside a container - FIXME</skipped><system-out>--------------------------------- Captured Log ---------------------------------

--------------------------------- Captured Out ---------------------------------

</system-out><system-err>--------------------------------- Captured Err ---------------------------------

</system-err></testcase><testcase classname="tests.integration.api_image_test.ImportImageTest" name="test_import_image_from_data_with_changes" time="7.982" /><testcase classname="tests.integration.api_image_test.ImportImageTest" name="test_import_image_with_changes" time="8.051" /><testcase classname="tests.integration.api_image_test.PruneImagesTest" name="test_prune_images" time="11.799"><failure message="docker.errors.APIError: 500 Server Error for http+docker://localhost/v1.40/images/prune: Internal Server Error (&quot;Image used by dc943baa6eac7d2e3126b52e41cd80d6450c71ebe9314324aec964b5344c68ff: image is in use by a container&quot;)">docker/api/client.py:296: in _raise_for_status
    response.raise_for_status()
../../.virtualenvs/docker-py/lib/python3.10/site-packages/requests/models.py:953: in raise_for_status
    raise HTTPError(http_error_msg, response=self)
E   requests.exceptions.HTTPError: 500 Server Error: Internal Server Error for url: http+docker://localhost/v1.40/images/prune

During handling of the above exception, another exception occurred:
tests/integration/api_image_test.py:327: in test_prune_images
    result = self.client.prune_images()
docker/utils/decorators.py:34: in wrapper
    return f(self, *args, **kwargs)
docker/api/image.py:349: in prune_images
    return self._result(self._post(url, params=params), True)
docker/api/client.py:302: in _result
    self._raise_for_status(response)
docker/api/client.py:298: in _raise_for_status
    raise create_api_error_from_http_exception(e)
docker/errors.py:31: in create_api_error_from_http_exception
    raise cls(e, response=response, explanation=explanation)
E   docker.errors.APIError: 500 Server Error for http+docker://localhost/v1.40/images/prune: Internal Server Error ("Image used by dc943baa6eac7d2e3126b52e41cd80d6450c71ebe9314324aec964b5344c68ff: image is in use by a container")</failure><system-out>--------------------------------- Captured Log ---------------------------------

--------------------------------- Captured Out ---------------------------------

</system-out><system-err>--------------------------------- Captured Err ---------------------------------

</system-err></testcase><testcase classname="tests.integration.api_image_test.SaveLoadImagesTest" name="test_get_image_load_image" time="8.027"><failure message="assert False is True">tests/integration/api_image_test.py:360: in test_get_image_load_image
    assert success is True
E   assert False is True</failure><system-out>--------------------------------- Captured Log ---------------------------------

--------------------------------- Captured Out ---------------------------------
{'stream': 'Loaded image: docker.io/library/alpine:3.10'}

</system-out><system-err>--------------------------------- Captured Err ---------------------------------

</system-err></testcase><testcase classname="tests.integration.api_image_test.InspectDistributionTest" name="test_inspect_distribution" time="7.658"><failure message="docker.errors.NotFound: 404 Client Error for http+docker://localhost/v1.40/distribution/busybox:latest/json: Not Found (&quot;Path /v1.40/distribution/busybox:latest/json is not supported&quot;)">docker/api/client.py:296: in _raise_for_status
    response.raise_for_status()
../../.virtualenvs/docker-py/lib/python3.10/site-packages/requests/models.py:953: in raise_for_status
    raise HTTPError(http_error_msg, response=self)
E   requests.exceptions.HTTPError: 404 Client Error: Not Found for url: http+docker://localhost/v1.40/distribution/busybox:latest/json

During handling of the above exception, another exception occurred:
tests/integration/api_image_test.py:366: in test_inspect_distribution
    data = self.client.inspect_distribution('busybox:latest')
docker/utils/decorators.py:34: in wrapper
    return f(self, *args, **kwargs)
docker/utils/decorators.py:19: in wrapped
    return f(self, resource_id, *args, **kwargs)
docker/api/image.py:287: in inspect_distribution
    return self._result(
docker/api/client.py:302: in _result
    self._raise_for_status(response)
docker/api/client.py:298: in _raise_for_status
    raise create_api_error_from_http_exception(e)
docker/errors.py:31: in create_api_error_from_http_exception
    raise cls(e, response=response, explanation=explanation)
E   docker.errors.NotFound: 404 Client Error for http+docker://localhost/v1.40/distribution/busybox:latest/json: Not Found ("Path /v1.40/distribution/busybox:latest/json is not supported")</failure><system-out>--------------------------------- Captured Log ---------------------------------

--------------------------------- Captured Out ---------------------------------

</system-out><system-err>--------------------------------- Captured Err ---------------------------------

</system-err></testcase><testcase classname="tests.integration.api_network_test.TestNetworks" name="test_connect_and_disconnect_container" time="8.332"><failure message="docker.errors.APIError: 500 Server Error for http+docker://localhost/v1.40/networks/d4970218686bf5c5f62ab606629220084f831ffd33a2fcee6efca273e5bb227c/connect: Internal Server Error (&quot;&quot;slirp4netns&quot; is not supported: invalid network mode&quot;)">docker/api/client.py:296: in _raise_for_status
    response.raise_for_status()
../../.virtualenvs/docker-py/lib/python3.10/site-packages/requests/models.py:953: in raise_for_status
    raise HTTPError(http_error_msg, response=self)
E   requests.exceptions.HTTPError: 500 Server Error: Internal Server Error for url: http+docker://localhost/v1.40/networks/d4970218686bf5c5f62ab606629220084f831ffd33a2fcee6efca273e5bb227c/connect

During handling of the above exception, another exception occurred:
tests/integration/api_network_test.py:98: in test_connect_and_disconnect_container
    self.client.connect_container_to_network(container, net_id)
docker/utils/decorators.py:19: in wrapped
    return f(self, resource_id, *args, **kwargs)
docker/api/network.py:250: in connect_container_to_network
    self._raise_for_status(res)
docker/api/client.py:298: in _raise_for_status
    raise create_api_error_from_http_exception(e)
docker/errors.py:31: in create_api_error_from_http_exception
    raise cls(e, response=response, explanation=explanation)
E   docker.errors.APIError: 500 Server Error for http+docker://localhost/v1.40/networks/d4970218686bf5c5f62ab606629220084f831ffd33a2fcee6efca273e5bb227c/connect: Internal Server Error (""slirp4netns" is not supported: invalid network mode")</failure><system-out>--------------------------------- Captured Log ---------------------------------

--------------------------------- Captured Out ---------------------------------

</system-out><system-err>--------------------------------- Captured Err ---------------------------------

</system-err></testcase><testcase classname="tests.integration.api_network_test.TestNetworks" name="test_connect_and_force_disconnect_container" time="8.458"><failure message="docker.errors.APIError: 500 Server Error for http+docker://localhost/v1.40/networks/3ffdbfeeba7b4a8831054910351bef7f5f05fc5204095fcc4bc4903a7850575a/connect: Internal Server Error (&quot;&quot;slirp4netns&quot; is not supported: invalid network mode&quot;)">docker/api/client.py:296: in _raise_for_status
    response.raise_for_status()
../../.virtualenvs/docker-py/lib/python3.10/site-packages/requests/models.py:953: in raise_for_status
    raise HTTPError(http_error_msg, response=self)
E   requests.exceptions.HTTPError: 500 Server Error: Internal Server Error for url: http+docker://localhost/v1.40/networks/3ffdbfeeba7b4a8831054910351bef7f5f05fc5204095fcc4bc4903a7850575a/connect

During handling of the above exception, another exception occurred:
tests/integration/api_network_test.py:125: in test_connect_and_force_disconnect_container
    self.client.connect_container_to_network(container, net_id)
docker/utils/decorators.py:19: in wrapped
    return f(self, resource_id, *args, **kwargs)
docker/api/network.py:250: in connect_container_to_network
    self._raise_for_status(res)
docker/api/client.py:298: in _raise_for_status
    raise create_api_error_from_http_exception(e)
docker/errors.py:31: in create_api_error_from_http_exception
    raise cls(e, response=response, explanation=explanation)
E   docker.errors.APIError: 500 Server Error for http+docker://localhost/v1.40/networks/3ffdbfeeba7b4a8831054910351bef7f5f05fc5204095fcc4bc4903a7850575a/connect: Internal Server Error (""slirp4netns" is not supported: invalid network mode")</failure><system-out>--------------------------------- Captured Log ---------------------------------

--------------------------------- Captured Out ---------------------------------

</system-out><system-err>--------------------------------- Captured Err ---------------------------------

</system-err></testcase><testcase classname="tests.integration.api_network_test.TestNetworks" name="test_connect_on_container_create" time="8.751" /><testcase classname="tests.integration.api_network_test.TestNetworks" name="test_connect_with_aliases" time="8.313"><failure message="docker.errors.APIError: 500 Server Error for http+docker://localhost/v1.40/networks/704ecd91de49cd06df68067630ca30ebbd4fb6053893ea91823eabfe7d73643c/connect: Internal Server Error (&quot;&quot;slirp4netns&quot; is not supported: invalid network mode&quot;)">docker/api/client.py:296: in _raise_for_status
    response.raise_for_status()
../../.virtualenvs/docker-py/lib/python3.10/site-packages/requests/models.py:953: in raise_for_status
    raise HTTPError(http_error_msg, response=self)
E   requests.exceptions.HTTPError: 500 Server Error: Internal Server Error for url: http+docker://localhost/v1.40/networks/704ecd91de49cd06df68067630ca30ebbd4fb6053893ea91823eabfe7d73643c/connect

During handling of the above exception, another exception occurred:
tests/integration/api_network_test.py:147: in test_connect_with_aliases
    self.client.connect_container_to_network(
docker/utils/decorators.py:19: in wrapped
    return f(self, resource_id, *args, **kwargs)
docker/api/network.py:250: in connect_container_to_network
    self._raise_for_status(res)
docker/api/client.py:298: in _raise_for_status
    raise create_api_error_from_http_exception(e)
docker/errors.py:31: in create_api_error_from_http_exception
    raise cls(e, response=response, explanation=explanation)
E   docker.errors.APIError: 500 Server Error for http+docker://localhost/v1.40/networks/704ecd91de49cd06df68067630ca30ebbd4fb6053893ea91823eabfe7d73643c/connect: Internal Server Error (""slirp4netns" is not supported: invalid network mode")</failure><system-out>--------------------------------- Captured Log ---------------------------------

--------------------------------- Captured Out ---------------------------------

</system-out><system-err>--------------------------------- Captured Err ---------------------------------

</system-err></testcase><testcase classname="tests.integration.api_network_test.TestNetworks" name="test_connect_with_ipv4_address" time="9.167"><failure message="TypeError: 'NoneType' object is not subscriptable">tests/integration/api_network_test.py:379: in test_connect_with_ipv4_address
    assert net_data['IPAMConfig']['IPv4Address'] == '172.28.5.24'
E   TypeError: 'NoneType' object is not subscriptable</failure><system-out>--------------------------------- Captured Log ---------------------------------

--------------------------------- Captured Out ---------------------------------

</system-out><system-err>--------------------------------- Captured Err ---------------------------------

</system-err></testcase><testcase classname="tests.integration.api_network_test.TestNetworks" name="test_connect_with_ipv6_address" time="9.189"><failure message="TypeError: 'NoneType' object is not subscriptable">tests/integration/api_network_test.py:405: in test_connect_with_ipv6_address
    assert net_data['IPAMConfig']['IPv6Address'] == '2001:389::f00d'
E   TypeError: 'NoneType' object is not subscriptable</failure><system-out>--------------------------------- Captured Log ---------------------------------

--------------------------------- Captured Out ---------------------------------

</system-out><system-err>--------------------------------- Captured Err ---------------------------------

</system-err></testcase><testcase classname="tests.integration.api_network_test.TestNetworks" name="test_connect_with_links" time="9.101"><failure message="AssertionError: assert None == ['docker-py-test-upstream:bar']">tests/integration/api_network_test.py:344: in test_connect_with_links
    assert net_settings['Networks'][net_name]['Links'] == [
E   AssertionError: assert None == ['docker-py-test-upstream:bar']</failure><system-out>--------------------------------- Captured Log ---------------------------------

--------------------------------- Captured Out ---------------------------------

</system-out><system-err>--------------------------------- Captured Err ---------------------------------

</system-err></testcase><testcase classname="tests.integration.api_network_test.TestNetworks" name="test_create_check_duplicate" time="7.776"><failure message="docker.errors.APIError: 500 Server Error for http+docker://localhost/v1.40/networks/create: Internal Server Error (&quot;network name dockerpytest_31cda9692682136c already used: network already exists&quot;)">docker/api/client.py:296: in _raise_for_status
    response.raise_for_status()
../../.virtualenvs/docker-py/lib/python3.10/site-packages/requests/models.py:953: in raise_for_status
    raise HTTPError(http_error_msg, response=self)
E   requests.exceptions.HTTPError: 500 Server Error: Internal Server Error for url: http+docker://localhost/v1.40/networks/create

During handling of the above exception, another exception occurred:
tests/integration/api_network_test.py:326: in test_create_check_duplicate
    net_id = self.client.create_network(net_name, check_duplicate=False)
docker/api/network.py:153: in create_network
    return self._result(res, json=True)
docker/api/client.py:302: in _result
    self._raise_for_status(response)
docker/api/client.py:298: in _raise_for_status
    raise create_api_error_from_http_exception(e)
docker/errors.py:31: in create_api_error_from_http_exception
    raise cls(e, response=response, explanation=explanation)
E   docker.errors.APIError: 500 Server Error for http+docker://localhost/v1.40/networks/create: Internal Server Error ("network name dockerpytest_31cda9692682136c already used: network already exists")</failure><system-out>--------------------------------- Captured Log ---------------------------------

--------------------------------- Captured Out ---------------------------------

</system-out><system-err>--------------------------------- Captured Err ---------------------------------

</system-err></testcase><testcase classname="tests.integration.api_network_test.TestNetworks" name="test_create_internal_networks" time="7.715" /><testcase classname="tests.integration.api_network_test.TestNetworks" name="test_create_network_ipv6_enabled" time="7.691" /><testcase classname="tests.integration.api_network_test.TestNetworks" name="test_create_network_with_host_driver_fails" time="7.722" /><testcase classname="tests.integration.api_network_test.TestNetworks" name="test_create_network_with_ipam_config" time="7.693"><failure message="AssertionError: assert {'driver': 'host-local'} is None&#10; +  where {'driver': 'host-local'} = &lt;built-in method pop of dict object at 0x7fddcbb4b740&gt;('Options', None)&#10; +    where &lt;built-in method pop of dict object at 0x7fddcbb4b740&gt; = {'Config': [{'Gateway': '172.28.5.254', 'Subnet': '172.28.0.0/16'}], 'Driver': 'default'}.pop">tests/integration/api_network_test.py:62: in test_create_network_with_ipam_config
    assert ipam.pop('Options', None) is None
E   AssertionError: assert {'driver': 'host-local'} is None
E    +  where {'driver': 'host-local'} = &lt;built-in method pop of dict object at 0x7fddcbb4b740&gt;('Options', None)
E    +    where &lt;built-in method pop of dict object at 0x7fddcbb4b740&gt; = {'Config': [{'Gateway': '172.28.5.254', 'Subnet': '172.28.0.0/16'}], 'Driver': 'default'}.pop</failure><system-out>--------------------------------- Captured Log ---------------------------------

--------------------------------- Captured Out ---------------------------------

</system-out><system-err>--------------------------------- Captured Err ---------------------------------

</system-err></testcase><testcase classname="tests.integration.api_network_test.TestNetworks" name="test_create_network_with_labels" time="7.722" /><testcase classname="tests.integration.api_network_test.TestNetworks" name="test_create_network_with_labels_wrong_type" time="7.658" /><testcase classname="tests.integration.api_network_test.TestNetworks" name="test_create_remove_network_with_space_in_name" time="7.690"><failure message="docker.errors.APIError: 500 Server Error for http+docker://localhost/v1.40/networks/create: Internal Server Error (&quot;network name test 01 invalid: names must match [a-zA-Z0-9][a-zA-Z0-9_.-]*: invalid argument&quot;)">docker/api/client.py:296: in _raise_for_status
    response.raise_for_status()
../../.virtualenvs/docker-py/lib/python3.10/site-packages/requests/models.py:953: in raise_for_status
    raise HTTPError(http_error_msg, response=self)
E   requests.exceptions.HTTPError: 500 Server Error: Internal Server Error for url: http+docker://localhost/v1.40/networks/create

During handling of the above exception, another exception occurred:
tests/integration/api_network_test.py:454: in test_create_remove_network_with_space_in_name
    net_id = self.client.create_network('test 01')
docker/api/network.py:153: in create_network
    return self._result(res, json=True)
docker/api/client.py:302: in _result
    self._raise_for_status(response)
docker/api/client.py:298: in _raise_for_status
    raise create_api_error_from_http_exception(e)
docker/errors.py:31: in create_api_error_from_http_exception
    raise cls(e, response=response, explanation=explanation)
E   docker.errors.APIError: 500 Server Error for http+docker://localhost/v1.40/networks/create: Internal Server Error ("network name test 01 invalid: names must match [a-zA-Z0-9][a-zA-Z0-9_.-]*: invalid argument")</failure><system-out>--------------------------------- Captured Log ---------------------------------

--------------------------------- Captured Out ---------------------------------

</system-out><system-err>--------------------------------- Captured Err ---------------------------------

</system-err></testcase><testcase classname="tests.integration.api_network_test.TestNetworks" name="test_create_with_aliases" time="8.647" /><testcase classname="tests.integration.api_network_test.TestNetworks" name="test_create_with_driveropt" time="7.791"><failure message="docker.errors.APIError: 500 Server Error for http+docker://localhost/v1.40/containers/create: Internal Server Error (&quot;container create: unable to find network with name or ID bridge: network not found&quot;)">docker/api/client.py:296: in _raise_for_status
    response.raise_for_status()
../../.virtualenvs/docker-py/lib/python3.10/site-packages/requests/models.py:953: in raise_for_status
    raise HTTPError(http_error_msg, response=self)
E   requests.exceptions.HTTPError: 500 Server Error: Internal Server Error for url: http+docker://localhost/v1.40/containers/create

During handling of the above exception, another exception occurred:
tests/integration/api_network_test.py:276: in test_create_with_driveropt
    container = self.client.create_container(
docker/api/container.py:428: in create_container
    return self.create_container_from_config(config, name)
docker/api/container.py:439: in create_container_from_config
    return self._result(res, True)
docker/api/client.py:302: in _result
    self._raise_for_status(response)
docker/api/client.py:298: in _raise_for_status
    raise create_api_error_from_http_exception(e)
docker/errors.py:31: in create_api_error_from_http_exception
    raise cls(e, response=response, explanation=explanation)
E   docker.errors.APIError: 500 Server Error for http+docker://localhost/v1.40/containers/create: Internal Server Error ("container create: unable to find network with name or ID bridge: network not found")</failure><system-out>--------------------------------- Captured Log ---------------------------------

--------------------------------- Captured Out ---------------------------------

</system-out><system-err>--------------------------------- Captured Err ---------------------------------

</system-err></testcase><testcase classname="tests.integration.api_network_test.TestNetworks" name="test_create_with_ipv4_address" time="8.644"><failure message="TypeError: 'NoneType' object is not subscriptable">tests/integration/api_network_test.py:224: in test_create_with_ipv4_address
    assert net_settings['Networks'][net_name]['IPAMConfig']['IPv4Address']\
E   TypeError: 'NoneType' object is not subscriptable</failure><system-out>--------------------------------- Captured Log ---------------------------------

--------------------------------- Captured Out ---------------------------------

</system-out><system-err>--------------------------------- Captured Err ---------------------------------

</system-err></testcase><testcase classname="tests.integration.api_network_test.TestNetworks" name="test_create_with_ipv6_address" time="8.737"><failure message="TypeError: 'NoneType' object is not subscriptable">tests/integration/api_network_test.py:250: in test_create_with_ipv6_address
    assert net_settings['Networks'][net_name]['IPAMConfig']['IPv6Address']\
E   TypeError: 'NoneType' object is not subscriptable</failure><system-out>--------------------------------- Captured Log ---------------------------------

--------------------------------- Captured Out ---------------------------------

</system-out><system-err>--------------------------------- Captured Err ---------------------------------

</system-err></testcase><testcase classname="tests.integration.api_network_test.TestNetworks" name="test_create_with_linklocal_ips" time="7.818"><failure message="docker.errors.APIError: 500 Server Error for http+docker://localhost/v1.40/containers/create: Internal Server Error (&quot;container create: unable to find network with name or ID bridge: network not found&quot;)">docker/api/client.py:296: in _raise_for_status
    response.raise_for_status()
../../.virtualenvs/docker-py/lib/python3.10/site-packages/requests/models.py:953: in raise_for_status
    raise HTTPError(http_error_msg, response=self)
E   requests.exceptions.HTTPError: 500 Server Error: Internal Server Error for url: http+docker://localhost/v1.40/containers/create

During handling of the above exception, another exception occurred:
tests/integration/api_network_test.py:255: in test_create_with_linklocal_ips
    container = self.client.create_container(
docker/api/container.py:428: in create_container
    return self.create_container_from_config(config, name)
docker/api/container.py:439: in create_container_from_config
    return self._result(res, True)
docker/api/client.py:302: in _result
    self._raise_for_status(response)
docker/api/client.py:298: in _raise_for_status
    raise create_api_error_from_http_exception(e)
docker/errors.py:31: in create_api_error_from_http_exception
    raise cls(e, response=response, explanation=explanation)
E   docker.errors.APIError: 500 Server Error for http+docker://localhost/v1.40/containers/create: Internal Server Error ("container create: unable to find network with name or ID bridge: network not found")</failure><system-out>--------------------------------- Captured Log ---------------------------------

--------------------------------- Captured Out ---------------------------------

</system-out><system-err>--------------------------------- Captured Err ---------------------------------

</system-err></testcase><testcase classname="tests.integration.api_network_test.TestNetworks" name="test_create_with_links" time="8.841"><failure message="AssertionError: assert None == ['docker-py-test-upstream:bar']">tests/integration/api_network_test.py:311: in test_create_with_links
    assert net_settings['Networks'][net_name]['Links'] == [
E   AssertionError: assert None == ['docker-py-test-upstream:bar']</failure><system-out>--------------------------------- Captured Log ---------------------------------

--------------------------------- Captured Out ---------------------------------

</system-out><system-err>--------------------------------- Captured Err ---------------------------------

</system-err></testcase><testcase classname="tests.integration.api_network_test.TestNetworks" name="test_inspect_network" time="8.672" /><testcase classname="tests.integration.api_network_test.TestNetworks" name="test_list_networks" time="8.281" /><testcase classname="tests.integration.api_network_test.TestNetworks" name="test_prune_networks" time="8.144" /><testcase classname="tests.integration.api_network_test.TestNetworks" name="test_remove_network" time="7.979" /><testcase classname="tests.integration.api_secret_test.SecretAPITest" name="test_create_secret" time="13.635" /><testcase classname="tests.integration.api_secret_test.SecretAPITest" name="test_create_secret_unicode_data" time="8.120" /><testcase classname="tests.integration.api_secret_test.SecretAPITest" name="test_inspect_secret" time="8.379" /><testcase classname="tests.integration.api_secret_test.SecretAPITest" name="test_list_secrets" time="8.656" /><testcase classname="tests.integration.api_secret_test.SecretAPITest" name="test_remove_secret" time="13.591" /><testcase classname="tests.integration.api_volume_test.TestVolumes" name="test_create_volume" time="7.833" /><testcase classname="tests.integration.api_volume_test.TestVolumes" name="test_create_volume_invalid_driver" time="7.921"><failure message="docker.errors.APIError: 500 Server Error for http+docker://localhost/v1.40/volumes/create: Internal Server Error (&quot;volume perfectcherryblossom uses volume plugin invalid.driver but it could not be retrieved: no volume plugin with name invalid.driver available: required plugin missing&quot;)">docker/api/client.py:296: in _raise_for_status
    response.raise_for_status()
../../.virtualenvs/docker-py/lib/python3.10/site-packages/requests/models.py:953: in raise_for_status
    raise HTTPError(http_error_msg, response=self)
E   requests.exceptions.HTTPError: 500 Server Error: Internal Server Error for url: http+docker://localhost/v1.40/volumes/create

During handling of the above exception, another exception occurred:
tests/integration/api_volume_test.py:22: in test_create_volume_invalid_driver
    self.client.create_volume('perfectcherryblossom', driver_name)
docker/api/volume.py:89: in create_volume
    return self._result(self._post_json(url, data=data), True)
docker/api/client.py:302: in _result
    self._raise_for_status(response)
docker/api/client.py:298: in _raise_for_status
    raise create_api_error_from_http_exception(e)
docker/errors.py:31: in create_api_error_from_http_exception
    raise cls(e, response=response, explanation=explanation)
E   docker.errors.APIError: 500 Server Error for http+docker://localhost/v1.40/volumes/create: Internal Server Error ("volume perfectcherryblossom uses volume plugin invalid.driver but it could not be retrieved: no volume plugin with name invalid.driver available: required plugin missing")</failure><system-out>--------------------------------- Captured Log ---------------------------------

--------------------------------- Captured Out ---------------------------------

</system-out><system-err>--------------------------------- Captured Err ---------------------------------

</system-err></testcase><testcase classname="tests.integration.api_volume_test.TestVolumes" name="test_force_remove_volume" time="7.923" /><testcase classname="tests.integration.api_volume_test.TestVolumes" name="test_inspect_nonexistent_volume" time="9.380" /><testcase classname="tests.integration.api_volume_test.TestVolumes" name="test_inspect_volume" time="10.835"><failure message="AssertionError: assert {'CreatedAt':...l/_data', ...} == {'CreatedAt':...l/_data', ...}&#10;  Omitting 6 identical items, use -vv to show&#10;  Differing items:&#10;  {'Options': None} != {'Options': {}}&#10;  Full diff:&#10;    {&#10;     'CreatedAt': '2022-05-24T11:07:52+02:00',&#10;     'Driver': 'local',...&#10;  &#10;  ...Full output truncated (10 lines hidden), use '-vv' to show">tests/integration/api_volume_test.py:38: in test_inspect_volume
    assert volume_info == result
E   AssertionError: assert {'CreatedAt':...l/_data', ...} == {'CreatedAt':...l/_data', ...}
E     Omitting 6 identical items, use -vv to show
E     Differing items:
E     {'Options': None} != {'Options': {}}
E     Full diff:
E       {
E        'CreatedAt': '2022-05-24T11:07:52+02:00',
E        'Driver': 'local',...
E     
E     ...Full output truncated (10 lines hidden), use '-vv' to show</failure><system-out>--------------------------------- Captured Log ---------------------------------

--------------------------------- Captured Out ---------------------------------

</system-out><system-err>--------------------------------- Captured Err ---------------------------------

</system-err></testcase><testcase classname="tests.integration.api_volume_test.TestVolumes" name="test_list_volumes" time="9.388"><failure message="AssertionError: assert {'CreatedAt': '2022-05-24T11:08:03+02:00', 'Driver': 'local', 'Labels': {}, 'Mountpoint': '/home/riyad/podman/storage/volumes/imperishablenight/_data', ...} in [{'CreatedAt': '2022-05-24T10:48:36+02:00', 'Driver': 'local', 'Labels': {}, 'Mountpoint': '/home/riyad/podman/storage/volumes/dockerpytest_1e0e0554c987a9f/_data', ...}, {'CreatedAt': '2022-05-24T11:08:03+02:00', 'Driver': 'local', 'Labels': {}, 'Mountpoint': '/home/riyad/podman/storage/volumes/imperishablenight/_data', ...}]">tests/integration/api_volume_test.py:31: in test_list_volumes
    assert volume_info in volumes
E   AssertionError: assert {'CreatedAt': '2022-05-24T11:08:03+02:00', 'Driver': 'local', 'Labels': {}, 'Mountpoint': '/home/riyad/podman/storage/volumes/imperishablenight/_data', ...} in [{'CreatedAt': '2022-05-24T10:48:36+02:00', 'Driver': 'local', 'Labels': {}, 'Mountpoint': '/home/riyad/podman/storage/volumes/dockerpytest_1e0e0554c987a9f/_data', ...}, {'CreatedAt': '2022-05-24T11:08:03+02:00', 'Driver': 'local', 'Labels': {}, 'Mountpoint': '/home/riyad/podman/storage/volumes/imperishablenight/_data', ...}]</failure><system-out>--------------------------------- Captured Log ---------------------------------

--------------------------------- Captured Out ---------------------------------

</system-out><system-err>--------------------------------- Captured Err ---------------------------------

</system-err></testcase><testcase classname="tests.integration.api_volume_test.TestVolumes" name="test_prune_volumes" time="9.533" /><testcase classname="tests.integration.api_volume_test.TestVolumes" name="test_remove_nonexistent_volume" time="9.993" /><testcase classname="tests.integration.api_volume_test.TestVolumes" name="test_remove_volume" time="9.588" /><testcase classname="tests.integration.client_test.ClientTest" name="test_df" time="0.095" /><testcase classname="tests.integration.client_test.ClientTest" name="test_info" time="2.490" /><testcase classname="tests.integration.client_test.ClientTest" name="test_ping" time="0.004" /><testcase classname="tests.integration.client_test.ClientTest" name="test_version" time="2.836" /><testcase classname="tests.integration.client_test.CancellableEventsTest" name="test_cancel_events" time="2.005" /><testcase classname="tests.integration.context_api_test.ContextLifecycleTest" name="test_context_remove" time="8.371" /><testcase classname="tests.integration.context_api_test.ContextLifecycleTest" name="test_lifecycle" time="8.183" /><testcase classname="tests.integration.context_api_test.ContextLifecycleTest" name="test_load_context_without_orchestrator" time="8.221" /><testcase classname="tests.integration.errors_test.ErrorsTest" name="test_api_error_parses_json" time="8.911"><failure message="AssertionError: assert 'You cannot remove a running container' in 'cannot remove container e08704a72869d49830be0cbffc587c9e173143ee35e7583e0fdd9be7fdf54dd8 as it is running - running or paused containers cannot be removed without force: container state improper'">tests/integration/errors_test.py:13: in test_api_error_parses_json
    assert 'You cannot remove a running container' in explanation
E   AssertionError: assert 'You cannot remove a running container' in 'cannot remove container e08704a72869d49830be0cbffc587c9e173143ee35e7583e0fdd9be7fdf54dd8 as it is running - running or paused containers cannot be removed without force: container state improper'</failure><system-out>--------------------------------- Captured Log ---------------------------------

--------------------------------- Captured Out ---------------------------------

</system-out><system-err>--------------------------------- Captured Err ---------------------------------

</system-err></testcase><testcase classname="tests.integration.models_containers_test.ContainerCollectionTest" name="test_get" time="10.730"><failure message="AssertionError: assert 'docker.io/li...alpine:latest' == 'alpine'&#10;  - alpine&#10;  + docker.io/library/alpine:latest">tests/integration/models_containers_test.py:189: in test_get
    assert client.containers.get(container.id).attrs[
E   AssertionError: assert 'docker.io/li...alpine:latest' == 'alpine'
E     - alpine
E     + docker.io/library/alpine:latest</failure><system-out>--------------------------------- Captured Log ---------------------------------

--------------------------------- Captured Out ---------------------------------

</system-out><system-err>--------------------------------- Captured Err ---------------------------------

</system-err></testcase><testcase classname="tests.integration.models_containers_test.ContainerCollectionTest" name="test_list" time="6.121"><failure message="AssertionError: assert 'docker.io/li...alpine:latest' == 'alpine'&#10;  - alpine&#10;  + docker.io/library/alpine:latest">tests/integration/models_containers_test.py:202: in test_list
    assert container.attrs['Config']['Image'] == 'alpine'
E   AssertionError: assert 'docker.io/li...alpine:latest' == 'alpine'
E     - alpine
E     + docker.io/library/alpine:latest</failure><system-out>--------------------------------- Captured Log ---------------------------------

--------------------------------- Captured Out ---------------------------------

</system-out><system-err>--------------------------------- Captured Err ---------------------------------

</system-err></testcase><testcase classname="tests.integration.models_containers_test.ContainerCollectionTest" name="test_list_sparse" time="6.047"><failure message="AssertionError: assert 'docker.io/li...alpine:latest' == 'alpine'&#10;  - alpine&#10;  + docker.io/library/alpine:latest">tests/integration/models_containers_test.py:220: in test_list_sparse
    assert container.attrs['Image'] == 'alpine'
E   AssertionError: assert 'docker.io/li...alpine:latest' == 'alpine'
E     - alpine
E     + docker.io/library/alpine:latest</failure><system-out>--------------------------------- Captured Log ---------------------------------

--------------------------------- Captured Out ---------------------------------

</system-out><system-err>--------------------------------- Captured Err ---------------------------------

</system-err></testcase><testcase classname="tests.integration.models_containers_test.ContainerCollectionTest" name="test_run" time="5.998" /><testcase classname="tests.integration.models_containers_test.ContainerCollectionTest" name="test_run_detach" time="5.960"><failure message="AssertionError: assert 'docker.io/li...alpine:latest' == 'alpine'&#10;  - alpine&#10;  + docker.io/library/alpine:latest">tests/integration/models_containers_test.py:26: in test_run_detach
    assert container.attrs['Config']['Image'] == "alpine"
E   AssertionError: assert 'docker.io/li...alpine:latest' == 'alpine'
E     - alpine
E     + docker.io/library/alpine:latest</failure><system-out>--------------------------------- Captured Log ---------------------------------

--------------------------------- Captured Out ---------------------------------

</system-out><system-err>--------------------------------- Captured Err ---------------------------------

</system-err></testcase><testcase classname="tests.integration.models_containers_test.ContainerCollectionTest" name="test_run_with_auto_remove" time="7.975" /><testcase classname="tests.integration.models_containers_test.ContainerCollectionTest" name="test_run_with_auto_remove_error" time="8.604"><failure message="docker.errors.NotFound: 404 Client Error for http+docker://localhost/v1.40/containers/ba0defe2f80c9dcd619a15dd0e9394ea858fd3219875603eedfb3c1adbbe17c1/json: Not Found (&quot;no container with name or ID &quot;ba0defe2f80c9dcd619a15dd0e9394ea858fd3219875603eedfb3c1adbbe17c1&quot; found: no such container&quot;)">docker/api/client.py:296: in _raise_for_status
    response.raise_for_status()
../../.virtualenvs/docker-py/lib/python3.10/site-packages/requests/models.py:953: in raise_for_status
    raise HTTPError(http_error_msg, response=self)
E   requests.exceptions.HTTPError: 404 Client Error: Not Found for url: http+docker://localhost/v1.40/containers/ba0defe2f80c9dcd619a15dd0e9394ea858fd3219875603eedfb3c1adbbe17c1/json

During handling of the above exception, another exception occurred:
tests/integration/models_containers_test.py:139: in test_run_with_auto_remove_error
    client.containers.run(
docker/models/containers.py:835: in run
    out = container.logs(
docker/models/containers.py:306: in logs
    return self.client.api.logs(self.id, **kwargs)
docker/utils/decorators.py:19: in wrapped
    return f(self, resource_id, *args, **kwargs)
docker/api/container.py:869: in logs
    output = self._get_result(container, stream, res)
docker/api/client.py:495: in _get_result
    return self._get_result_tty(stream, res, self._check_is_tty(container))
docker/utils/decorators.py:19: in wrapped
    return f(self, resource_id, *args, **kwargs)
docker/api/client.py:491: in _check_is_tty
    cont = self.inspect_container(container)
docker/utils/decorators.py:19: in wrapped
    return f(self, resource_id, *args, **kwargs)
docker/api/container.py:771: in inspect_container
    return self._result(
docker/api/client.py:302: in _result
    self._raise_for_status(response)
docker/api/client.py:298: in _raise_for_status
    raise create_api_error_from_http_exception(e)
docker/errors.py:31: in create_api_error_from_http_exception
    raise cls(e, response=response, explanation=explanation)
E   docker.errors.NotFound: 404 Client Error for http+docker://localhost/v1.40/containers/ba0defe2f80c9dcd619a15dd0e9394ea858fd3219875603eedfb3c1adbbe17c1/json: Not Found ("no container with name or ID "ba0defe2f80c9dcd619a15dd0e9394ea858fd3219875603eedfb3c1adbbe17c1" found: no such container")</failure><system-out>--------------------------------- Captured Log ---------------------------------

--------------------------------- Captured Out ---------------------------------

</system-out><system-err>--------------------------------- Captured Err ---------------------------------

</system-err></testcase><testcase classname="tests.integration.models_containers_test.ContainerCollectionTest" name="test_run_with_error" time="6.487" /><testcase classname="tests.integration.models_containers_test.ContainerCollectionTest" name="test_run_with_image_that_does_not_exist" time="7.296" /><testcase classname="tests.integration.models_containers_test.ContainerCollectionTest" name="test_run_with_json_file_driver" time="6.356" /><testcase classname="tests.integration.models_containers_test.ContainerCollectionTest" name="test_run_with_named_volume" time="7.037" /><testcase classname="tests.integration.models_containers_test.ContainerCollectionTest" name="test_run_with_network" time="6.371" /><testcase classname="tests.integration.models_containers_test.ContainerCollectionTest" name="test_run_with_none_driver" time="6.063" /><testcase classname="tests.integration.models_containers_test.ContainerCollectionTest" name="test_run_with_proxy_config" time="5.785" /><testcase classname="tests.integration.models_containers_test.ContainerCollectionTest" name="test_run_with_streamed_logs" time="5.884" /><testcase classname="tests.integration.models_containers_test.ContainerCollectionTest" name="test_run_with_streamed_logs_and_cancel" time="5.001"><failure message="Failed: Timeout &gt;5.0s">tests/integration/base.py:30: in tearDown
    client = docker.from_env(version=TEST_API_VERSION)
docker/client.py:96: in from_env
    return cls(
docker/client.py:45: in __init__
    self.api = APIClient(*args, **kwargs)
docker/api/client.py:197: in __init__
    self._version = self._retrieve_server_version()
docker/api/client.py:214: in _retrieve_server_version
    return self.version(api_version=False)["ApiVersion"]
docker/api/daemon.py:181: in version
    return self._result(self._get(url), json=True)
docker/utils/decorators.py:46: in inner
    return f(self, *args, **kwargs)
docker/api/client.py:251: in _get
    return self.get(url, **self._set_request_timeout(kwargs))
../../.virtualenvs/docker-py/lib/python3.10/site-packages/requests/sessions.py:555: in get
    return self.request('GET', url, **kwargs)
../../.virtualenvs/docker-py/lib/python3.10/site-packages/requests/sessions.py:542: in request
    resp = self.send(prep, **send_kwargs)
../../.virtualenvs/docker-py/lib/python3.10/site-packages/requests/sessions.py:655: in send
    r = adapter.send(request, **kwargs)
../../.virtualenvs/docker-py/lib/python3.10/site-packages/requests/adapters.py:439: in send
    resp = conn.urlopen(
../../.virtualenvs/docker-py/lib/python3.10/site-packages/urllib3/connectionpool.py:699: in urlopen
    httplib_response = self._make_request(
../../.virtualenvs/docker-py/lib/python3.10/site-packages/urllib3/connectionpool.py:445: in _make_request
    six.raise_from(e, None)
../../.virtualenvs/docker-py/lib/python3.10/site-packages/urllib3/connectionpool.py:440: in _make_request
    httplib_response = conn.getresponse()
/usr/lib/python3.10/http/client.py:1374: in getresponse
    response.begin()
/usr/lib/python3.10/http/client.py:318: in begin
    version, status, reason = self._read_status()
/usr/lib/python3.10/http/client.py:279: in _read_status
    line = str(self.fp.readline(_MAXLINE + 1), "iso-8859-1")
/usr/lib/python3.10/socket.py:705: in readinto
    return self._sock.recv_into(b)
E   Failed: Timeout &gt;5.0s</failure><system-out>--------------------------------- Captured Log ---------------------------------

--------------------------------- Captured Out ---------------------------------

</system-out><system-err>--------------------------------- Captured Err ---------------------------------

</system-err></testcase><testcase classname="tests.integration.models_containers_test.ContainerCollectionTest" name="test_run_with_volume" time="6.312" /><testcase classname="tests.integration.models_containers_test.ContainerTest" name="test_commit" time="7.206" /><testcase classname="tests.integration.models_containers_test.ContainerTest" name="test_create_with_volume_driver" time="5.861"><failure message="AssertionError: assert '' == 'foo'&#10;  - foo">tests/integration/models_containers_test.py:456: in test_create_with_volume_driver
    assert container.attrs['HostConfig']['VolumeDriver'] == 'foo'
E   AssertionError: assert '' == 'foo'
E     - foo</failure><system-out>--------------------------------- Captured Log ---------------------------------

--------------------------------- Captured Out ---------------------------------

</system-out><system-err>--------------------------------- Captured Err ---------------------------------

</system-err></testcase><testcase classname="tests.integration.models_containers_test.ContainerTest" name="test_diff" time="6.226"><failure message="AssertionError: assert [{'Kind': 0, ...th': '/test'}] == [{'Kind': 1, 'Path': '/test'}]&#10;  At index 0 diff: {'Path': '/etc', 'Kind': 0} != {'Path': '/test', 'Kind': 1}&#10;  Left contains one more item: {'Kind': 1, 'Path': '/test'}&#10;  Full diff:&#10;  - [{'Kind': 1, 'Path': '/test'}]&#10;  + [{'Kind': 0, 'Path': '/etc'}, {'Kind': 1, 'Path': '/test'}]">tests/integration/models_containers_test.py:251: in test_diff
    assert container.diff() == [{'Path': '/test', 'Kind': 1}]
E   AssertionError: assert [{'Kind': 0, ...th': '/test'}] == [{'Kind': 1, 'Path': '/test'}]
E     At index 0 diff: {'Path': '/etc', 'Kind': 0} != {'Path': '/test', 'Kind': 1}
E     Left contains one more item: {'Kind': 1, 'Path': '/test'}
E     Full diff:
E     - [{'Kind': 1, 'Path': '/test'}]
E     + [{'Kind': 0, 'Path': '/etc'}, {'Kind': 1, 'Path': '/test'}]</failure><system-out>--------------------------------- Captured Log ---------------------------------

--------------------------------- Captured Out ---------------------------------

</system-out><system-err>--------------------------------- Captured Err ---------------------------------

</system-err></testcase><testcase classname="tests.integration.models_containers_test.ContainerTest" name="test_exec_run_failed" time="7.029"><failure message="assert 127 == 126">tests/integration/models_containers_test.py:270: in test_exec_run_failed
    assert exec_output[0] == 126
E   assert 127 == 126</failure><system-out>--------------------------------- Captured Log ---------------------------------

--------------------------------- Captured Out ---------------------------------

</system-out><system-err>--------------------------------- Captured Err ---------------------------------

</system-err></testcase><testcase classname="tests.integration.models_containers_test.ContainerTest" name="test_exec_run_success" time="6.589" /><testcase classname="tests.integration.models_containers_test.ContainerTest" name="test_kill" time="6.896"><failure message="AssertionError: assert 'stopped' == 'exited'&#10;  - exited&#10;  + stopped">tests/integration/models_containers_test.py:281: in test_kill
    assert container.status == 'exited'
E   AssertionError: assert 'stopped' == 'exited'
E     - exited
E     + stopped</failure><system-out>--------------------------------- Captured Log ---------------------------------

--------------------------------- Captured Out ---------------------------------

</system-out><system-err>--------------------------------- Captured Err ---------------------------------

</system-err></testcase><testcase classname="tests.integration.models_containers_test.ContainerTest" name="test_logs" time="9.009" /><testcase classname="tests.integration.models_containers_test.ContainerTest" name="test_pause" time="11.628" /><testcase classname="tests.integration.models_containers_test.ContainerTest" name="test_ports_target_list" time="6.626" /><testcase classname="tests.integration.models_containers_test.ContainerTest" name="test_ports_target_none" time="7.570" /><testcase classname="tests.integration.models_containers_test.ContainerTest" name="test_ports_target_tuple" time="7.110" /><testcase classname="tests.integration.models_containers_test.ContainerTest" name="test_remove" time="7.340" /><testcase classname="tests.integration.models_containers_test.ContainerTest" name="test_rename" time="5.897" /><testcase classname="tests.integration.models_containers_test.ContainerTest" name="test_restart" time="16.816" /><testcase classname="tests.integration.models_containers_test.ContainerTest" name="test_start" time="5.414"><failure message="AssertionError: assert 'initialized' == 'created'&#10;  - created&#10;  + initialized">tests/integration/models_containers_test.py:336: in test_start
    assert container.status == "created"
E   AssertionError: assert 'initialized' == 'created'
E     - created
E     + initialized</failure><system-out>--------------------------------- Captured Log ---------------------------------

--------------------------------- Captured Out ---------------------------------

</system-out><system-err>--------------------------------- Captured Err ---------------------------------

</system-err></testcase><testcase classname="tests.integration.models_containers_test.ContainerTest" name="test_stats" time="5.989" /><testcase classname="tests.integration.models_containers_test.ContainerTest" name="test_stop" time="6.938"><failure message="AssertionError: assert 'initialized' in ('running', 'created')&#10; +  where 'initialized' = &lt;Container: 4869c1ff74&gt;.status">tests/integration/models_containers_test.py:414: in test_stop
    assert container.status in ("running", "created")
E   AssertionError: assert 'initialized' in ('running', 'created')
E    +  where 'initialized' = &lt;Container: 4869c1ff74&gt;.status</failure><system-out>--------------------------------- Captured Log ---------------------------------

--------------------------------- Captured Out ---------------------------------

</system-out><system-err>--------------------------------- Captured Err ---------------------------------

</system-err></testcase><testcase classname="tests.integration.models_containers_test.ContainerTest" name="test_top" time="7.559"><failure message="AssertionError: assert 'sleep 60' in ['1 root      0:00 sleep 60']">tests/integration/models_containers_test.py:425: in test_top
    assert 'sleep 60' in top['Processes'][0]
E   AssertionError: assert 'sleep 60' in ['1 root      0:00 sleep 60']</failure><system-out>--------------------------------- Captured Log ---------------------------------

--------------------------------- Captured Out ---------------------------------

</system-out><system-err>--------------------------------- Captured Err ---------------------------------

</system-err></testcase><testcase classname="tests.integration.models_containers_test.ContainerTest" name="test_update" time="6.579"><failure message="docker.errors.NotFound: 404 Client Error for http+docker://localhost/v1.40/containers/ec8168a4689e4d3df38e79ee68faea2ff8d3f30863db49c33bb855b4c85058ac/update: Not Found (&quot;b'Not Found'&quot;)">docker/api/client.py:296: in _raise_for_status
    response.raise_for_status()
../../.virtualenvs/docker-py/lib/python3.10/site-packages/requests/models.py:953: in raise_for_status
    raise HTTPError(http_error_msg, response=self)
E   requests.exceptions.HTTPError: 404 Client Error: Not Found for url: http+docker://localhost/v1.40/containers/ec8168a4689e4d3df38e79ee68faea2ff8d3f30863db49c33bb855b4c85058ac/update

During handling of the above exception, another exception occurred:
tests/integration/models_containers_test.py:433: in test_update
    container.update(cpu_shares=3)
docker/models/containers.py:489: in update
    return self.client.api.update_container(self.id, **kwargs)
docker/utils/decorators.py:34: in wrapper
    return f(self, *args, **kwargs)
docker/utils/decorators.py:19: in wrapped
    return f(self, resource_id, *args, **kwargs)
docker/api/container.py:1268: in update_container
    return self._result(res, True)
docker/api/client.py:302: in _result
    self._raise_for_status(response)
docker/api/client.py:298: in _raise_for_status
    raise create_api_error_from_http_exception(e)
docker/errors.py:31: in create_api_error_from_http_exception
    raise cls(e, response=response, explanation=explanation)
E   docker.errors.NotFound: 404 Client Error for http+docker://localhost/v1.40/containers/ec8168a4689e4d3df38e79ee68faea2ff8d3f30863db49c33bb855b4c85058ac/update: Not Found ("b'Not Found'")</failure><system-out>--------------------------------- Captured Log ---------------------------------

--------------------------------- Captured Out ---------------------------------

</system-out><system-err>--------------------------------- Captured Err ---------------------------------

</system-err></testcase><testcase classname="tests.integration.models_containers_test.ContainerTest" name="test_wait" time="6.589" /><testcase classname="tests.integration.models_images_test.ImageCollectionTest" name="test_build" time="8.923" /><testcase classname="tests.integration.models_images_test.ImageCollectionTest" name="test_build_with_error" time="7.705"><failure message="assert &quot;The command '/bin/sh -c exit 1' returned a non-zero code: 1&quot; in 'docker.errors.BuildError: error building at STEP &quot;RUN exit 1&quot;: error while running runtime: exit status 1'&#10; +  where 'docker.errors.BuildError: error building at STEP &quot;RUN exit 1&quot;: error while running runtime: exit status 1' = &lt;bound method ExceptionInfo.exconly of &lt;ExceptionInfo BuildError('error building at STEP &quot;RUN exit 1&quot;: error while running runtime: exit status 1\n') tblen=2&gt;&gt;()&#10; +    where &lt;bound method ExceptionInfo.exconly of &lt;ExceptionInfo BuildError('error building at STEP &quot;RUN exit 1&quot;: error while running runtime: exit status 1\n') tblen=2&gt;&gt; = &lt;ExceptionInfo BuildError('error building at STEP &quot;RUN exit 1&quot;: error while running runtime: exit status 1\n') tblen=2&gt;.exconly">tests/integration/models_images_test.py:30: in test_build_with_error
    assert (
E   assert "The command '/bin/sh -c exit 1' returned a non-zero code: 1" in 'docker.errors.BuildError: error building at STEP "RUN exit 1": error while running runtime: exit status 1'
E    +  where 'docker.errors.BuildError: error building at STEP "RUN exit 1": error while running runtime: exit status 1' = &lt;bound method ExceptionInfo.exconly of &lt;ExceptionInfo BuildError('error building at STEP "RUN exit 1": error while running runtime: exit status 1\n') tblen=2&gt;&gt;()
E    +    where &lt;bound method ExceptionInfo.exconly of &lt;ExceptionInfo BuildError('error building at STEP "RUN exit 1": error while running runtime: exit status 1\n') tblen=2&gt;&gt; = &lt;ExceptionInfo BuildError('error building at STEP "RUN exit 1": error while running runtime: exit status 1\n') tblen=2&gt;.exconly</failure><system-out>--------------------------------- Captured Log ---------------------------------

--------------------------------- Captured Out ---------------------------------

</system-out><system-err>--------------------------------- Captured Err ---------------------------------

</system-err></testcase><testcase classname="tests.integration.models_images_test.ImageCollectionTest" name="test_build_with_multiple_success" time="8.365" /><testcase classname="tests.integration.models_images_test.ImageCollectionTest" name="test_build_with_success_build_output" time="6.788" /><testcase classname="tests.integration.models_images_test.ImageCollectionTest" name="test_list" time="9.133" /><testcase classname="tests.integration.models_images_test.ImageCollectionTest" name="test_list_with_repository" time="9.001" /><testcase classname="tests.integration.models_images_test.ImageCollectionTest" name="test_load_error" time="6.502"><failure message="docker.errors.APIError: 500 Server Error for http+docker://localhost/v1.40/images/load: Internal Server Error (&quot;failed to load image: payload does not match any of the supported image formats:&#10; * oci: initializing source oci:/var/tmp/api_load.tar3512957392:: open /var/tmp/api_load.tar3512957392/index.json: not a directory&#10; * oci-archive: creating temp directory: untarring file &quot;/var/tmp/oci2156895096&quot;: unexpected EOF&#10; * docker-archive: loading tar component manifest.json: unexpected EOF&#10; * dir: open /var/tmp/api_load.tar3512957392/manifest.json: not a directory&quot;)">docker/api/client.py:296: in _raise_for_status
    response.raise_for_status()
../../.virtualenvs/docker-py/lib/python3.10/site-packages/requests/models.py:953: in raise_for_status
    raise HTTPError(http_error_msg, response=self)
E   requests.exceptions.HTTPError: 500 Server Error: Internal Server Error for url: http+docker://localhost/v1.40/images/load

During handling of the above exception, another exception occurred:
tests/integration/models_images_test.py:98: in test_load_error
    client.images.load('abc')
docker/models/images.py:382: in load
    for chunk in resp:
docker/api/client.py:386: in _stream_helper
    yield self._result(response, json=decode)
docker/api/client.py:302: in _result
    self._raise_for_status(response)
docker/api/client.py:298: in _raise_for_status
    raise create_api_error_from_http_exception(e)
docker/errors.py:31: in create_api_error_from_http_exception
    raise cls(e, response=response, explanation=explanation)
E   docker.errors.APIError: 500 Server Error for http+docker://localhost/v1.40/images/load: Internal Server Error ("failed to load image: payload does not match any of the supported image formats:
E    * oci: initializing source oci:/var/tmp/api_load.tar3512957392:: open /var/tmp/api_load.tar3512957392/index.json: not a directory
E    * oci-archive: creating temp directory: untarring file "/var/tmp/oci2156895096": unexpected EOF
E    * docker-archive: loading tar component manifest.json: unexpected EOF
E    * dir: open /var/tmp/api_load.tar3512957392/manifest.json: not a directory")</failure><system-out>--------------------------------- Captured Log ---------------------------------

--------------------------------- Captured Out ---------------------------------

</system-out><system-err>--------------------------------- Captured Err ---------------------------------

</system-err></testcase><testcase classname="tests.integration.models_images_test.ImageCollectionTest" name="test_pull" time="8.949"><failure message="AssertionError: assert 'alpine:latest' in ['docker.io/library/alpine:latest']">tests/integration/models_images_test.py:71: in test_pull
    assert 'alpine:latest' in image.attrs['RepoTags']
E   AssertionError: assert 'alpine:latest' in ['docker.io/library/alpine:latest']</failure><system-out>--------------------------------- Captured Log ---------------------------------

--------------------------------- Captured Out ---------------------------------

</system-out><system-err>--------------------------------- Captured Err ---------------------------------

</system-err></testcase><testcase classname="tests.integration.models_images_test.ImageCollectionTest" name="test_pull_multiple" time="10.541"><failure message="assert False&#10; +  where False = any([False])">tests/integration/models_images_test.py:91: in test_pull_multiple
    assert any([
E   assert False
E    +  where False = any([False])</failure><system-out>--------------------------------- Captured Log ---------------------------------

--------------------------------- Captured Out ---------------------------------

</system-out><system-err>--------------------------------- Captured Err ---------------------------------

</system-err></testcase><testcase classname="tests.integration.models_images_test.ImageCollectionTest" name="test_pull_with_sha" time="12.601"><failure message="AssertionError: assert 'hello-world@sha256:083de497cff944f969d8499ab94f07134c50bcf5e6b9559b27182d3fa80ce3f7' in ['docker.io/library/hello-world@sha256:083de497cff944f969d8499ab94f07134c50bcf5e6b9559b27182d3fa80ce3f7', 'docker.io/library/hello-world@sha256:8072a54ebb3bc136150e2f2860f00a7bf45f13eeb917cca2430fcd0054c8e51b']">tests/integration/models_images_test.py:85: in test_pull_with_sha
    assert image_ref in image.attrs['RepoDigests']
E   AssertionError: assert 'hello-world@sha256:083de497cff944f969d8499ab94f07134c50bcf5e6b9559b27182d3fa80ce3f7' in ['docker.io/library/hello-world@sha256:083de497cff944f969d8499ab94f07134c50bcf5e6b9559b27182d3fa80ce3f7', 'docker.io/library/hello-world@sha256:8072a54ebb3bc136150e2f2860f00a7bf45f13eeb917cca2430fcd0054c8e51b']</failure><system-out>--------------------------------- Captured Log ---------------------------------

--------------------------------- Captured Out ---------------------------------

</system-out><system-err>--------------------------------- Captured Err ---------------------------------

</system-err></testcase><testcase classname="tests.integration.models_images_test.ImageCollectionTest" name="test_pull_with_tag" time="9.558"><failure message="AssertionError: assert 'alpine:3.10' in ['docker.io/library/alpine:3.10']">tests/integration/models_images_test.py:76: in test_pull_with_tag
    assert 'alpine:3.10' in image.attrs['RepoTags']
E   AssertionError: assert 'alpine:3.10' in ['docker.io/library/alpine:3.10']</failure><system-out>--------------------------------- Captured Log ---------------------------------

--------------------------------- Captured Out ---------------------------------

</system-out><system-err>--------------------------------- Captured Err ---------------------------------

</system-err></testcase><testcase classname="tests.integration.models_images_test.ImageCollectionTest" name="test_save_and_load" time="6.087" /><testcase classname="tests.integration.models_images_test.ImageCollectionTest" name="test_save_and_load_repo_name" time="5.978"><failure message="docker.errors.InvalidArgument: dockerpytest_dace50a99222055e:latest is not a valid tag for this image">tests/integration/models_images_test.py:122: in test_save_and_load_repo_name
    stream = image.save(named=f'{additional_tag}:latest')
docker/models/images.py:96: in save
    raise InvalidArgument(
E   docker.errors.InvalidArgument: dockerpytest_dace50a99222055e:latest is not a valid tag for this image</failure><system-out>--------------------------------- Captured Log ---------------------------------

--------------------------------- Captured Out ---------------------------------

</system-out><system-err>--------------------------------- Captured Err ---------------------------------

</system-err></testcase><testcase classname="tests.integration.models_images_test.ImageCollectionTest" name="test_save_name_error" time="7.296" /><testcase classname="tests.integration.models_images_test.ImageTest" name="test_tag_and_remove" time="10.096" /><testcase classname="tests.integration.models_networks_test.NetworkCollectionTest" name="test_create" time="6.702" /><testcase classname="tests.integration.models_networks_test.NetworkCollectionTest" name="test_get" time="6.215" /><testcase classname="tests.integration.models_networks_test.NetworkCollectionTest" name="test_list_remove" time="6.479" /><testcase classname="tests.integration.models_networks_test.NetworkTest" name="test_connect_disconnect" time="5.752"><failure message="docker.errors.APIError: 500 Server Error for http+docker://localhost/v1.40/networks/7a4a8b3b7f1a88f0154d1d7cb0b5871be2a71ed53a0590444c2b3a0df2ea10aa/connect: Internal Server Error (&quot;&quot;slirp4netns&quot; is not supported: invalid network mode&quot;)">docker/api/client.py:296: in _raise_for_status
    response.raise_for_status()
../../.virtualenvs/docker-py/lib/python3.10/site-packages/requests/models.py:953: in raise_for_status
    raise HTTPError(http_error_msg, response=self)
E   requests.exceptions.HTTPError: 500 Server Error: Internal Server Error for url: http+docker://localhost/v1.40/networks/7a4a8b3b7f1a88f0154d1d7cb0b5871be2a71ed53a0590444c2b3a0df2ea10aa/connect

During handling of the above exception, another exception occurred:
tests/integration/models_networks_test.py:59: in test_connect_disconnect
    network.connect(container)
docker/models/networks.py:58: in connect
    return self.client.api.connect_container_to_network(
docker/utils/decorators.py:19: in wrapped
    return f(self, resource_id, *args, **kwargs)
docker/api/network.py:250: in connect_container_to_network
    self._raise_for_status(res)
docker/api/client.py:298: in _raise_for_status
    raise create_api_error_from_http_exception(e)
docker/errors.py:31: in create_api_error_from_http_exception
    raise cls(e, response=response, explanation=explanation)
E   docker.errors.APIError: 500 Server Error for http+docker://localhost/v1.40/networks/7a4a8b3b7f1a88f0154d1d7cb0b5871be2a71ed53a0590444c2b3a0df2ea10aa/connect: Internal Server Error (""slirp4netns" is not supported: invalid network mode")</failure><system-out>--------------------------------- Captured Log ---------------------------------

--------------------------------- Captured Out ---------------------------------

</system-out><system-err>--------------------------------- Captured Err ---------------------------------

</system-err></testcase><testcase classname="tests.integration.models_resources_test.ModelTest" name="test_reload" time="6.780" /><testcase classname="tests.integration.models_volumes_test.VolumesTest" name="test_create_get" time="5.978" /><testcase classname="tests.integration.models_volumes_test.VolumesTest" name="test_list_remove" time="8.016"><failure message="AssertionError: assert &lt;Volume: dockerpyte&gt; in []&#10; +  where [] = &lt;bound method VolumeCollection.list of &lt;docker.models.volumes.VolumeCollection object at 0x7fddcbb47d30&gt;&gt;(filters={'name': 'dockerpytest_'})&#10; +    where &lt;bound method VolumeCollection.list of &lt;docker.models.volumes.VolumeCollection object at 0x7fddcbb47d30&gt;&gt; = &lt;docker.models.volumes.VolumeCollection object at 0x7fddcbb47d30&gt;.list&#10; +      where &lt;docker.models.volumes.VolumeCollection object at 0x7fddcbb47d30&gt; = &lt;docker.client.DockerClient object at 0x7fddcbb471c0&gt;.volumes">tests/integration/models_volumes_test.py:26: in test_list_remove
    assert volume in client.volumes.list(filters={'name': 'dockerpytest_'})
E   AssertionError: assert &lt;Volume: dockerpyte&gt; in []
E    +  where [] = &lt;bound method VolumeCollection.list of &lt;docker.models.volumes.VolumeCollection object at 0x7fddcbb47d30&gt;&gt;(filters={'name': 'dockerpytest_'})
E    +    where &lt;bound method VolumeCollection.list of &lt;docker.models.volumes.VolumeCollection object at 0x7fddcbb47d30&gt;&gt; = &lt;docker.models.volumes.VolumeCollection object at 0x7fddcbb47d30&gt;.list
E    +      where &lt;docker.models.volumes.VolumeCollection object at 0x7fddcbb47d30&gt; = &lt;docker.client.DockerClient object at 0x7fddcbb471c0&gt;.volumes</failure><system-out>--------------------------------- Captured Log ---------------------------------

--------------------------------- Captured Out ---------------------------------

</system-out><system-err>--------------------------------- Captured Err ---------------------------------

</system-err></testcase><testcase classname="tests.integration.regression_test.TestRegressions" name="test_443_handle_nonchunked_response_in_stream" time="9.054"><failure message="Failed: DID NOT RAISE &lt;class 'docker.errors.APIError'&gt;">tests/integration/regression_test.py:13: in test_443_handle_nonchunked_response_in_stream
    with pytest.raises(docker.errors.APIError) as exc:
E   Failed: DID NOT RAISE &lt;class 'docker.errors.APIError'&gt;</failure><system-out>--------------------------------- Captured Log ---------------------------------

--------------------------------- Captured Out ---------------------------------

</system-out><system-err>--------------------------------- Captured Err ---------------------------------

</system-err></testcase><testcase classname="tests.integration.regression_test.TestRegressions" name="test_542_truncate_ids_client_side" time="8.862" /><testcase classname="tests.integration.regression_test.TestRegressions" name="test_647_support_doubleslash_in_image_names" time="8.661" /><testcase classname="tests.integration.regression_test.TestRegressions" name="test_649_handle_timeout_value_none" time="9.303" /><testcase classname="tests.integration.regression_test.TestRegressions" name="test_715_handle_user_param_as_int_value" time="9.218" /><testcase classname="tests.integration.regression_test.TestRegressions" name="test_792_explicit_port_protocol" time="10.056" /><testcase classname="tests.integration.credentials.utils_test" name="test_create_environment_dict" time="0.012" /></testsuite></testsuites>