<?xml version="1.0" encoding="utf-8"?><testsuites><testsuite name="docker-py" errors="0" failures="74" skipped="7" tests="269" time="2765.528" timestamp="2023-02-28T14:42:17.654089" hostname="acnologia"><testcase classname="tests.integration.api_build_test.BuildTest" name="test_build_container_with_target" time="21.113" /><testcase classname="tests.integration.api_build_test.BuildTest" name="test_build_from_stringio" time="10.171" /><testcase classname="tests.integration.api_build_test.BuildTest" name="test_build_gzip_custom_encoding" time="8.487" /><testcase classname="tests.integration.api_build_test.BuildTest" name="test_build_gzip_encoding" time="8.876" /><testcase classname="tests.integration.api_build_test.BuildTest" name="test_build_in_context_abs_dockerfile" time="8.388" /><testcase classname="tests.integration.api_build_test.BuildTest" name="test_build_in_context_dockerfile" time="8.287" /><testcase classname="tests.integration.api_build_test.BuildTest" name="test_build_in_context_nested_dockerfile" time="8.437" /><testcase classname="tests.integration.api_build_test.BuildTest" name="test_build_invalid_platform" time="9.917"><failure message="AssertionError: assert ('unknown operating system' in 'docker.errors.APIError: 400 Client Error for http+docker://localhost/v1.41/build?q=False&amp;nocache=False&amp;rm=False&amp;forcerm=False&amp;pull=False&amp;platform=foobar: Bad Request' or 'invalid platform' in 'docker.errors.APIError: 400 Client Error for http+docker://localhost/v1.41/build?q=False&amp;nocache=False&amp;rm=False&amp;forcerm=False&amp;pull=False&amp;platform=foobar: Bad Request')&#10; +  where 'docker.errors.APIError: 400 Client Error for http+docker://localhost/v1.41/build?q=False&amp;nocache=False&amp;rm=False&amp;forcerm=False&amp;pull=False&amp;platform=foobar: Bad Request' = &lt;bound method ExceptionInfo.exconly of &lt;ExceptionInfo APIError(HTTPError('400 Client Error: Bad Request for url: http+docker://localhost/v1.41/build?q=False&amp;nocache=False&amp;rm=False&amp;forcerm=False&amp;pull=False&amp;platform=foobar')) tblen=5&gt;&gt;()&#10; +    where &lt;bound method ExceptionInfo.exconly of &lt;ExceptionInfo APIError(HTTPError('400 Client Error: Bad Request for url: http+docker://localhost/v1.41/build?q=False&amp;nocache=False&amp;rm=False&amp;forcerm=False&amp;pull=False&amp;platform=foobar')) tblen=5&gt;&gt; = &lt;ExceptionInfo APIError(HTTPError('400 Client Error: Bad Request for url: http+docker://localhost/v1.41/build?q=False&amp;nocache=False&amp;rm=False&amp;forcerm=False&amp;pull=False&amp;platform=foobar')) tblen=5&gt;.exconly&#10; +  and   'docker.errors.APIError: 400 Client Error for http+docker://localhost/v1.41/build?q=False&amp;nocache=False&amp;rm=False&amp;forcerm=False&amp;pull=False&amp;platform=foobar: Bad Request' = &lt;bound method ExceptionInfo.exconly of &lt;ExceptionInfo APIError(HTTPError('400 Client Error: Bad Request for url: http+docker://localhost/v1.41/build?q=False&amp;nocache=False&amp;rm=False&amp;forcerm=False&amp;pull=False&amp;platform=foobar')) tblen=5&gt;&gt;()&#10; +    where &lt;bound method ExceptionInfo.exconly of &lt;ExceptionInfo APIError(HTTPError('400 Client Error: Bad Request for url: http+docker://localhost/v1.41/build?q=False&amp;nocache=False&amp;rm=False&amp;forcerm=False&amp;pull=False&amp;platform=foobar')) tblen=5&gt;&gt; = &lt;ExceptionInfo APIError(HTTPError('400 Client Error: Bad Request for url: http+docker://localhost/v1.41/build?q=False&amp;nocache=False&amp;rm=False&amp;forcerm=False&amp;pull=False&amp;platform=foobar')) tblen=5&gt;.exconly">tests/integration/api_build_test.py:464: in test_build_invalid_platform
    assert 'unknown operating system' in excinfo.exconly() \
E   AssertionError: assert ('unknown operating system' in 'docker.errors.APIError: 400 Client Error for http+docker://localhost/v1.41/build?q=False&amp;nocache=False&amp;rm=False&amp;forcerm=False&amp;pull=False&amp;platform=foobar: Bad Request' or 'invalid platform' in 'docker.errors.APIError: 400 Client Error for http+docker://localhost/v1.41/build?q=False&amp;nocache=False&amp;rm=False&amp;forcerm=False&amp;pull=False&amp;platform=foobar: Bad Request')
E    +  where 'docker.errors.APIError: 400 Client Error for http+docker://localhost/v1.41/build?q=False&amp;nocache=False&amp;rm=False&amp;forcerm=False&amp;pull=False&amp;platform=foobar: Bad Request' = &lt;bound method ExceptionInfo.exconly of &lt;ExceptionInfo APIError(HTTPError('400 Client Error: Bad Request for url: http+docker://localhost/v1.41/build?q=False&amp;nocache=False&amp;rm=False&amp;forcerm=False&amp;pull=False&amp;platform=foobar')) tblen=5&gt;&gt;()
E    +    where &lt;bound method ExceptionInfo.exconly of &lt;ExceptionInfo APIError(HTTPError('400 Client Error: Bad Request for url: http+docker://localhost/v1.41/build?q=False&amp;nocache=False&amp;rm=False&amp;forcerm=False&amp;pull=False&amp;platform=foobar')) tblen=5&gt;&gt; = &lt;ExceptionInfo APIError(HTTPError('400 Client Error: Bad Request for url: http+docker://localhost/v1.41/build?q=False&amp;nocache=False&amp;rm=False&amp;forcerm=False&amp;pull=False&amp;platform=foobar')) tblen=5&gt;.exconly
E    +  and   'docker.errors.APIError: 400 Client Error for http+docker://localhost/v1.41/build?q=False&amp;nocache=False&amp;rm=False&amp;forcerm=False&amp;pull=False&amp;platform=foobar: Bad Request' = &lt;bound method ExceptionInfo.exconly of &lt;ExceptionInfo APIError(HTTPError('400 Client Error: Bad Request for url: http+docker://localhost/v1.41/build?q=False&amp;nocache=False&amp;rm=False&amp;forcerm=False&amp;pull=False&amp;platform=foobar')) tblen=5&gt;&gt;()
E    +    where &lt;bound method ExceptionInfo.exconly of &lt;ExceptionInfo APIError(HTTPError('400 Client Error: Bad Request for url: http+docker://localhost/v1.41/build?q=False&amp;nocache=False&amp;rm=False&amp;forcerm=False&amp;pull=False&amp;platform=foobar')) tblen=5&gt;&gt; = &lt;ExceptionInfo APIError(HTTPError('400 Client Error: Bad Request for url: http+docker://localhost/v1.41/build?q=False&amp;nocache=False&amp;rm=False&amp;forcerm=False&amp;pull=False&amp;platform=foobar')) tblen=5&gt;.exconly</failure><system-out>--------------------------------- Captured Log ---------------------------------

--------------------------------- Captured Out ---------------------------------

</system-out><system-err>--------------------------------- Captured Err ---------------------------------

</system-err></testcase><testcase classname="tests.integration.api_build_test.BuildTest" name="test_build_isolation" time="8.555" /><testcase classname="tests.integration.api_build_test.BuildTest" name="test_build_labels" time="8.950" /><testcase classname="tests.integration.api_build_test.BuildTest" name="test_build_out_of_context_dockerfile" time="8.481" /><testcase classname="tests.integration.api_build_test.BuildTest" name="test_build_shmsize" time="7.995" /><testcase classname="tests.integration.api_build_test.BuildTest" name="test_build_squash" time="11.912" /><testcase classname="tests.integration.api_build_test.BuildTest" name="test_build_stderr_data" time="9.021" /><testcase classname="tests.integration.api_build_test.BuildTest" name="test_build_streaming" time="8.372" /><testcase classname="tests.integration.api_build_test.BuildTest" name="test_build_with_buildargs" time="8.884" /><testcase classname="tests.integration.api_build_test.BuildTest" name="test_build_with_cache_from" time="9.699"><failure message="assert 3 == 0">tests/integration/api_build_test.py:257: in test_build_with_cache_from
    assert counter == 0
E   assert 3 == 0</failure><system-out>--------------------------------- Captured Log ---------------------------------

--------------------------------- Captured Out ---------------------------------

</system-out><system-err>--------------------------------- Captured Err ---------------------------------

</system-err></testcase><testcase classname="tests.integration.api_build_test.BuildTest" name="test_build_with_dockerfile_empty_lines" time="7.846" /><testcase classname="tests.integration.api_build_test.BuildTest" name="test_build_with_dockerignore" time="9.581"><failure message="AssertionError: assert ['/test/#file.../not-ignored'] == ['/test/#file.../not-ignored']&#10;  At index 2 diff: '/test/not-ignored' != '/test/ignored/subdir/excepted-with-spaces'&#10;  Right contains one more item: '/test/not-ignored'&#10;  Full diff:&#10;    [&#10;     '/test/#file.txt',&#10;     '/test/ignored/subdir/excepted-file',&#10;  -  '/test/ignored/subdir/excepted-with-spaces',...&#10;  &#10;  ...Full output truncated (3 lines hidden), use '-vv' to show">tests/integration/api_build_test.py:145: in test_build_with_dockerignore
    assert sorted(list(filter(None, logs.split('\n')))) == sorted([
E   AssertionError: assert ['/test/#file.../not-ignored'] == ['/test/#file.../not-ignored']
E     At index 2 diff: '/test/not-ignored' != '/test/ignored/subdir/excepted-with-spaces'
E     Right contains one more item: '/test/not-ignored'
E     Full diff:
E       [
E        '/test/#file.txt',
E        '/test/ignored/subdir/excepted-file',
E     -  '/test/ignored/subdir/excepted-with-spaces',...
E     
E     ...Full output truncated (3 lines hidden), use '-vv' to show</failure><system-out>--------------------------------- Captured Log ---------------------------------

--------------------------------- Captured Out ---------------------------------

</system-out><system-err>--------------------------------- Captured Err ---------------------------------

</system-err></testcase><testcase classname="tests.integration.api_build_test.BuildTest" name="test_build_with_extra_hosts" time="8.815"><failure message="docker.errors.APIError: 400 Client Error for http+docker://localhost/v1.41/build?t=dockerpytest_extrahost_build&amp;q=False&amp;nocache=False&amp;rm=False&amp;forcerm=False&amp;pull=False&amp;extrahosts=extrahost.local.test%3A127.0.0.1&amp;extrahosts=hello.world.test%3A127.0.0.1: Bad Request">docker/api/client.py:296: in _raise_for_status
    response.raise_for_status()
../../.virtualenvs/docker-py/lib/python3.10/site-packages/requests/models.py:1021: in raise_for_status
    raise HTTPError(http_error_msg, response=self)
E   requests.exceptions.HTTPError: 400 Client Error: Bad Request for url: http+docker://localhost/v1.41/build?t=dockerpytest_extrahost_build&amp;q=False&amp;nocache=False&amp;rm=False&amp;forcerm=False&amp;pull=False&amp;extrahosts=extrahost.local.test%3A127.0.0.1&amp;extrahosts=hello.world.test%3A127.0.0.1

The above exception was the direct cause of the following exception:
tests/integration/api_build_test.py:342: in test_build_with_extra_hosts
    for chunk in stream:
docker/api/client.py:386: in _stream_helper
    yield self._result(response, json=decode)
docker/api/client.py:302: in _result
    self._raise_for_status(response)
docker/api/client.py:298: in _raise_for_status
    raise create_api_error_from_http_exception(e) from e
docker/errors.py:39: in create_api_error_from_http_exception
    raise cls(e, response=response, explanation=explanation) from e
E   docker.errors.APIError: 400 Client Error for http+docker://localhost/v1.41/build?t=dockerpytest_extrahost_build&amp;q=False&amp;nocache=False&amp;rm=False&amp;forcerm=False&amp;pull=False&amp;extrahosts=extrahost.local.test%3A127.0.0.1&amp;extrahosts=hello.world.test%3A127.0.0.1: Bad Request</failure><system-out>--------------------------------- Captured Log ---------------------------------

--------------------------------- Captured Out ---------------------------------

</system-out><system-err>--------------------------------- Captured Err ---------------------------------

</system-err></testcase><testcase classname="tests.integration.api_build_test.BuildTest" name="test_build_with_network_mode" time="10.113"><failure message="docker.errors.ImageNotFound: 404 Client Error for http+docker://localhost/v1.41/images/dockerpytest_customnetbuild/json: Not Found (&quot;failed to find image dockerpytest_customnetbuild: docker.io/library/dockerpytest_customnetbuild: No such image&quot;)">docker/api/client.py:296: in _raise_for_status
    response.raise_for_status()
../../.virtualenvs/docker-py/lib/python3.10/site-packages/requests/models.py:1021: in raise_for_status
    raise HTTPError(http_error_msg, response=self)
E   requests.exceptions.HTTPError: 404 Client Error: Not Found for url: http+docker://localhost/v1.41/images/dockerpytest_customnetbuild/json

The above exception was the direct cause of the following exception:
tests/integration/api_build_test.py:307: in test_build_with_network_mode
    assert self.client.inspect_image('dockerpytest_customnetbuild')
docker/utils/decorators.py:19: in wrapped
    return f(self, resource_id, *args, **kwargs)
docker/api/image.py:251: in inspect_image
    return self._result(
docker/api/client.py:302: in _result
    self._raise_for_status(response)
docker/api/client.py:298: in _raise_for_status
    raise create_api_error_from_http_exception(e) from e
docker/errors.py:39: in create_api_error_from_http_exception
    raise cls(e, response=response, explanation=explanation) from e
E   docker.errors.ImageNotFound: 404 Client Error for http+docker://localhost/v1.41/images/dockerpytest_customnetbuild/json: Not Found ("failed to find image dockerpytest_customnetbuild: docker.io/library/dockerpytest_customnetbuild: No such image")</failure><system-out>--------------------------------- Captured Log ---------------------------------

--------------------------------- Captured Out ---------------------------------

</system-out><system-err>--------------------------------- Captured Err ---------------------------------

</system-err></testcase><testcase classname="tests.integration.api_build_test.BuildTest" name="test_build_with_proxy" time="8.350" /><testcase classname="tests.integration.api_build_test.BuildTest" name="test_build_with_proxy_and_buildargs" time="8.855" /><testcase classname="tests.integration.api_build_test.BuildTest" name="test_prune_builds" time="8.176"><skipped type="pytest.xfail" message="Currently fails on 18.09: https://github.com/moby/moby/issues/37920" /></testcase><testcase classname="tests.integration.api_client_test.InformationTest" name="test_info" time="10.161" /><testcase classname="tests.integration.api_client_test.InformationTest" name="test_version" time="10.089" /><testcase classname="tests.integration.api_client_test.AutoDetectVersionTest" name="test_client_init" time="7.551" /><testcase classname="tests.integration.api_client_test.ConnectionTimeoutTest" name="test_timeout" time="0.504" /><testcase classname="tests.integration.api_client_test.UnixconnTest" name="test_resource_warnings" time="2.877" /><testcase classname="tests.integration.api_container_test.ListContainersTest" name="test_list_containers" time="8.199" /><testcase classname="tests.integration.api_container_test.CreateContainerTest" name="test_create" time="8.053" /><testcase classname="tests.integration.api_container_test.CreateContainerTest" name="test_create_container_with_volumes_from" time="9.471" /><testcase classname="tests.integration.api_container_test.CreateContainerTest" name="test_create_with_auto_remove" time="9.798" /><testcase classname="tests.integration.api_container_test.CreateContainerTest" name="test_create_with_cgroupns" time="11.795"><failure message="AssertionError: assert 'private' == ''&#10;  + private">tests/integration/api_container_test.py:230: in test_create_with_cgroupns
    assert 'private' == res['HostConfig']['CgroupnsMode']
E   AssertionError: assert 'private' == ''
E     + private</failure><system-out>--------------------------------- Captured Log ---------------------------------

--------------------------------- Captured Out ---------------------------------

</system-out><system-err>--------------------------------- Captured Err ---------------------------------

</system-err></testcase><testcase classname="tests.integration.api_container_test.CreateContainerTest" name="test_create_with_cpu_rt_options" time="9.800"><skipped type="pytest.xfail" message="CONFIG_RT_GROUP_SCHED isn't enabled" /></testcase><testcase classname="tests.integration.api_container_test.CreateContainerTest" name="test_create_with_device_cgroup_rules" time="9.482"><failure message="AssertionError: assert None == ['c 7:128 rwm']">tests/integration/api_container_test.py:483: in test_create_with_device_cgroup_rules
    assert config['HostConfig']['DeviceCgroupRules'] == [rule]
E   AssertionError: assert None == ['c 7:128 rwm']</failure><system-out>--------------------------------- Captured Log ---------------------------------

--------------------------------- Captured Out ---------------------------------

</system-out><system-err>--------------------------------- Captured Err ---------------------------------

</system-err></testcase><testcase classname="tests.integration.api_container_test.CreateContainerTest" name="test_create_with_environment_variable_no_value" time="9.175"><failure message="AssertionError: assert 'Foo' in ['PATH=/usr/local/sbin:/usr/local/bin:/usr/sbin:/usr/bin:/sbin:/bin', 'TERM=xterm', 'container=podman', 'Other=one', 'Blank=']">tests/integration/api_container_test.py:380: in test_create_with_environment_variable_no_value
    assert 'Foo' in config['Config']['Env']
E   AssertionError: assert 'Foo' in ['PATH=/usr/local/sbin:/usr/local/bin:/usr/sbin:/usr/bin:/sbin:/bin', 'TERM=xterm', 'container=podman', 'Other=one', 'Blank=']</failure><system-out>--------------------------------- Captured Log ---------------------------------

--------------------------------- Captured Out ---------------------------------

</system-out><system-err>--------------------------------- Captured Err ---------------------------------

</system-err></testcase><testcase classname="tests.integration.api_container_test.CreateContainerTest" name="test_create_with_host_pid_mode" time="8.009" /><testcase classname="tests.integration.api_container_test.CreateContainerTest" name="test_create_with_init" time="7.596" /><testcase classname="tests.integration.api_container_test.CreateContainerTest" name="test_create_with_isolation" time="8.690"><failure message="AssertionError: assert '' == 'default'&#10;  - default">tests/integration/api_container_test.py:409: in test_create_with_isolation
    assert config['HostConfig']['Isolation'] == 'default'
E   AssertionError: assert '' == 'default'
E     - default</failure><system-out>--------------------------------- Captured Log ---------------------------------

--------------------------------- Captured Out ---------------------------------

</system-out><system-err>--------------------------------- Captured Err ---------------------------------

</system-err></testcase><testcase classname="tests.integration.api_container_test.CreateContainerTest" name="test_create_with_links" time="8.464"><failure message="docker.errors.APIError: 400 Client Error for http+docker://localhost/v1.41/containers/create: Bad Request (&quot;bad parameter: link is not supported&quot;)">docker/api/client.py:296: in _raise_for_status
    response.raise_for_status()
../../.virtualenvs/docker-py/lib/python3.10/site-packages/requests/models.py:1021: in raise_for_status
    raise HTTPError(http_error_msg, response=self)
E   requests.exceptions.HTTPError: 400 Client Error: Bad Request for url: http+docker://localhost/v1.41/containers/create

The above exception was the direct cause of the following exception:
tests/integration/api_container_test.py:95: in test_create_with_links
    res2 = self.client.create_container(
docker/api/container.py:431: in create_container
    return self.create_container_from_config(config, name, platform)
docker/api/container.py:448: in create_container_from_config
    return self._result(res, True)
docker/api/client.py:302: in _result
    self._raise_for_status(response)
docker/api/client.py:298: in _raise_for_status
    raise create_api_error_from_http_exception(e) from e
docker/errors.py:39: in create_api_error_from_http_exception
    raise cls(e, response=response, explanation=explanation) from e
E   docker.errors.APIError: 400 Client Error for http+docker://localhost/v1.41/containers/create: Bad Request ("bad parameter: link is not supported")</failure><system-out>--------------------------------- Captured Log ---------------------------------

--------------------------------- Captured Out ---------------------------------

</system-out><system-err>--------------------------------- Captured Err ---------------------------------

</system-err></testcase><testcase classname="tests.integration.api_container_test.CreateContainerTest" name="test_create_with_mac_address" time="7.879"><failure message="AssertionError: assert '02:42:ac:11:00:0a' == '92:47:52:ec:43:7c'&#10;  - 92:47:52:ec:43:7c&#10;  + 02:42:ac:11:00:0a">tests/integration/api_container_test.py:214: in test_create_with_mac_address
    assert mac_address_expected == res['NetworkSettings']['MacAddress']
E   AssertionError: assert '02:42:ac:11:00:0a' == '92:47:52:ec:43:7c'
E     - 92:47:52:ec:43:7c
E     + 02:42:ac:11:00:0a</failure><system-out>--------------------------------- Captured Log ---------------------------------

--------------------------------- Captured Out ---------------------------------

</system-out><system-err>--------------------------------- Captured Err ---------------------------------

</system-err></testcase><testcase classname="tests.integration.api_container_test.CreateContainerTest" name="test_create_with_memory_constraints_with_int" time="8.046"><failure message="docker.errors.APIError: 500 Server Error for http+docker://localhost/v1.41/containers/7299948755f4c42fd8ef813a426331fcf06d34e4b8be62761014570064d04fe1/start: Internal Server Error (&quot;crun: cannot set memory swappiness with cgroupv2: OCI runtime error&quot;)">docker/api/client.py:296: in _raise_for_status
    response.raise_for_status()
../../.virtualenvs/docker-py/lib/python3.10/site-packages/requests/models.py:1021: in raise_for_status
    raise HTTPError(http_error_msg, response=self)
E   requests.exceptions.HTTPError: 500 Server Error: Internal Server Error for url: http+docker://localhost/v1.41/containers/7299948755f4c42fd8ef813a426331fcf06d34e4b8be62761014570064d04fe1/start

The above exception was the direct cause of the following exception:
tests/integration/api_container_test.py:365: in test_create_with_memory_constraints_with_int
    self.client.start(ctnr)
docker/utils/decorators.py:19: in wrapped
    return f(self, resource_id, *args, **kwargs)
docker/api/container.py:1126: in start
    self._raise_for_status(res)
docker/api/client.py:298: in _raise_for_status
    raise create_api_error_from_http_exception(e) from e
docker/errors.py:39: in create_api_error_from_http_exception
    raise cls(e, response=response, explanation=explanation) from e
E   docker.errors.APIError: 500 Server Error for http+docker://localhost/v1.41/containers/7299948755f4c42fd8ef813a426331fcf06d34e4b8be62761014570064d04fe1/start: Internal Server Error ("crun: cannot set memory swappiness with cgroupv2: OCI runtime error")</failure><system-out>--------------------------------- Captured Log ---------------------------------

--------------------------------- Captured Out ---------------------------------

</system-out><system-err>--------------------------------- Captured Err ---------------------------------

</system-err></testcase><testcase classname="tests.integration.api_container_test.CreateContainerTest" name="test_create_with_memory_constraints_with_str" time="7.963" /><testcase classname="tests.integration.api_container_test.CreateContainerTest" name="test_create_with_restart_policy" time="30.087"><failure message="AssertionError: assert 'You cannot remove ' in 'cannot remove container 4ee585ef65b3b6a5973dafeb517c47d14b809f569bc9d54a41e5146492f5edfa as it is running - running or paused containers cannot be removed without force: container state improper'">tests/integration/api_container_test.py:126: in test_create_with_restart_policy
    assert 'You cannot remove ' in err
E   AssertionError: assert 'You cannot remove ' in 'cannot remove container 4ee585ef65b3b6a5973dafeb517c47d14b809f569bc9d54a41e5146492f5edfa as it is running - running or paused containers cannot be removed without force: container state improper'</failure><system-out>--------------------------------- Captured Log ---------------------------------

--------------------------------- Captured Out ---------------------------------

</system-out><system-err>--------------------------------- Captured Err ---------------------------------

</system-err></testcase><testcase classname="tests.integration.api_container_test.CreateContainerTest" name="test_create_with_stop_timeout" time="8.184" /><testcase classname="tests.integration.api_container_test.CreateContainerTest" name="test_create_with_storage_opt" time="8.007"><skipped type="pytest.xfail" message="Not supported on most drivers" /></testcase><testcase classname="tests.integration.api_container_test.CreateContainerTest" name="test_create_with_tmpfs" time="8.009"><failure message="AssertionError: assert {'/tmp1': 'si...ev,tmpcopyup'} == {'/tmp1': 'size=3M'}&#10;  Differing items:&#10;  {'/tmp1': 'size=3M,rw,rprivate,nosuid,nodev,tmpcopyup'} != {'/tmp1': 'size=3M'}&#10;  Full diff:&#10;  - {'/tmp1': 'size=3M'}&#10;  + {'/tmp1': 'size=3M,rw,rprivate,nosuid,nodev,tmpcopyup'}">tests/integration/api_container_test.py:398: in test_create_with_tmpfs
    assert config['HostConfig']['Tmpfs'] == tmpfs
E   AssertionError: assert {'/tmp1': 'si...ev,tmpcopyup'} == {'/tmp1': 'size=3M'}
E     Differing items:
E     {'/tmp1': 'size=3M,rw,rprivate,nosuid,nodev,tmpcopyup'} != {'/tmp1': 'size=3M'}
E     Full diff:
E     - {'/tmp1': 'size=3M'}
E     + {'/tmp1': 'size=3M,rw,rprivate,nosuid,nodev,tmpcopyup'}</failure><system-out>--------------------------------- Captured Log ---------------------------------

--------------------------------- Captured Out ---------------------------------

</system-out><system-err>--------------------------------- Captured Err ---------------------------------

</system-err></testcase><testcase classname="tests.integration.api_container_test.CreateContainerTest" name="test_create_with_uts_mode" time="7.887" /><testcase classname="tests.integration.api_container_test.CreateContainerTest" name="test_group_id_ints" time="8.713" /><testcase classname="tests.integration.api_container_test.CreateContainerTest" name="test_group_id_strings" time="9.607" /><testcase classname="tests.integration.api_container_test.CreateContainerTest" name="test_invalid_log_driver_raises_exception" time="7.862"><failure message="assert 'container create: running container create option: invalid log driver: invalid argument' in [&quot;logger: no log driver named 'asdf' is registered&quot;, 'error looking up logging plugin asdf: plugin &quot;asdf&quot; not found']&#10; +  where 'container create: running container create option: invalid log driver: invalid argument' = APIError(HTTPError('500 Server Error: Internal Server Error for url: http+docker://localhost/v1.41/containers/create')).explanation&#10; +    where APIError(HTTPError('500 Server Error: Internal Server Error for url: http+docker://localhost/v1.41/containers/create')) = &lt;ExceptionInfo APIError(HTTPError('500 Server Error: Internal Server Error for url: http+docker://localhost/v1.41/containers/create')) tblen=6&gt;.value">tests/integration/api_container_test.py:300: in test_invalid_log_driver_raises_exception
    assert excinfo.value.explanation in expected_msgs
E   assert 'container create: running container create option: invalid log driver: invalid argument' in ["logger: no log driver named 'asdf' is registered", 'error looking up logging plugin asdf: plugin "asdf" not found']
E    +  where 'container create: running container create option: invalid log driver: invalid argument' = APIError(HTTPError('500 Server Error: Internal Server Error for url: http+docker://localhost/v1.41/containers/create')).explanation
E    +    where APIError(HTTPError('500 Server Error: Internal Server Error for url: http+docker://localhost/v1.41/containers/create')) = &lt;ExceptionInfo APIError(HTTPError('500 Server Error: Internal Server Error for url: http+docker://localhost/v1.41/containers/create')) tblen=6&gt;.value</failure><system-out>--------------------------------- Captured Log ---------------------------------

--------------------------------- Captured Out ---------------------------------

</system-out><system-err>--------------------------------- Captured Err ---------------------------------

</system-err></testcase><testcase classname="tests.integration.api_container_test.CreateContainerTest" name="test_valid_log_driver_and_log_opt" time="8.248"><failure message="AssertionError: assert None == {'max-file': '100'}&#10; +  where {'max-file': '100'} = {'Type': 'json-file', 'Config': {'max-file': '100'}}.config">tests/integration/api_container_test.py:279: in test_valid_log_driver_and_log_opt
    assert container_log_config['Config'] == log_config.config
E   AssertionError: assert None == {'max-file': '100'}
E    +  where {'max-file': '100'} = {'Type': 'json-file', 'Config': {'max-file': '100'}}.config</failure><system-out>--------------------------------- Captured Log ---------------------------------

--------------------------------- Captured Out ---------------------------------

</system-out><system-err>--------------------------------- Captured Err ---------------------------------

</system-err></testcase><testcase classname="tests.integration.api_container_test.CreateContainerTest" name="test_valid_no_config_specified" time="8.236"><failure message="assert None == {}">tests/integration/api_container_test.py:338: in test_valid_no_config_specified
    assert container_log_config['Config'] == {}
E   assert None == {}</failure><system-out>--------------------------------- Captured Log ---------------------------------

--------------------------------- Captured Out ---------------------------------

</system-out><system-err>--------------------------------- Captured Err ---------------------------------

</system-err></testcase><testcase classname="tests.integration.api_container_test.CreateContainerTest" name="test_valid_no_log_driver_specified" time="8.169"><failure message="AssertionError: assert 'journald' == 'json-file'&#10;  - json-file&#10;  + journald">tests/integration/api_container_test.py:318: in test_valid_no_log_driver_specified
    assert container_log_config['Type'] == "json-file"
E   AssertionError: assert 'journald' == 'json-file'
E     - json-file
E     + journald</failure><system-out>--------------------------------- Captured Log ---------------------------------

--------------------------------- Captured Out ---------------------------------

</system-out><system-err>--------------------------------- Captured Err ---------------------------------

</system-err></testcase><testcase classname="tests.integration.api_container_test.VolumeBindTest" name="test_create_with_binds_ro" time="9.918" /><testcase classname="tests.integration.api_container_test.VolumeBindTest" name="test_create_with_binds_rw" time="8.815" /><testcase classname="tests.integration.api_container_test.VolumeBindTest" name="test_create_with_mounts" time="10.722" /><testcase classname="tests.integration.api_container_test.VolumeBindTest" name="test_create_with_mounts_ro" time="9.028" /><testcase classname="tests.integration.api_container_test.VolumeBindTest" name="test_create_with_volume_mount" time="9.103" /><testcase classname="tests.integration.api_container_test.ArchiveTest" name="test_copy_directory_to_container" time="8.840" /><testcase classname="tests.integration.api_container_test.ArchiveTest" name="test_copy_file_to_container" time="8.687" /><testcase classname="tests.integration.api_container_test.ArchiveTest" name="test_get_file_archive_from_container" time="8.883" /><testcase classname="tests.integration.api_container_test.ArchiveTest" name="test_get_file_stat_from_container" time="10.090" /><testcase classname="tests.integration.api_container_test.RenameContainerTest" name="test_rename_container" time="12.680" /><testcase classname="tests.integration.api_container_test.StartContainerTest" name="test_run_shlex_commands" time="15.829" /><testcase classname="tests.integration.api_container_test.StartContainerTest" name="test_start_container" time="9.281" /><testcase classname="tests.integration.api_container_test.StartContainerTest" name="test_start_container_with_dict_instead_of_id" time="9.519" /><testcase classname="tests.integration.api_container_test.WaitTest" name="test_wait" time="13.916" /><testcase classname="tests.integration.api_container_test.WaitTest" name="test_wait_with_condition" time="14.237" /><testcase classname="tests.integration.api_container_test.WaitTest" name="test_wait_with_dict_instead_of_id" time="12.797" /><testcase classname="tests.integration.api_container_test.LogsTest" name="test_logs" time="9.657" /><testcase classname="tests.integration.api_container_test.LogsTest" name="test_logs_streaming_and_follow" time="9.041" /><testcase classname="tests.integration.api_container_test.LogsTest" name="test_logs_streaming_and_follow_and_cancel" time="5.000"><failure message="Failed: Timeout &gt;5.0s">tests/integration/base.py:80: in setUp
    self.is_podman = self._is_podman(self.client)
tests/integration/base.py:103: in _is_podman
    in client.version()['Components']
docker/api/daemon.py:181: in version
    return self._result(self._get(url), json=True)
docker/utils/decorators.py:46: in inner
    return f(self, *args, **kwargs)
docker/api/client.py:251: in _get
    return self.get(url, **self._set_request_timeout(kwargs))
../../.virtualenvs/docker-py/lib/python3.10/site-packages/requests/sessions.py:600: in get
    return self.request("GET", url, **kwargs)
../../.virtualenvs/docker-py/lib/python3.10/site-packages/requests/sessions.py:587: in request
    resp = self.send(prep, **send_kwargs)
../../.virtualenvs/docker-py/lib/python3.10/site-packages/requests/sessions.py:701: in send
    r = adapter.send(request, **kwargs)
../../.virtualenvs/docker-py/lib/python3.10/site-packages/requests/adapters.py:489: in send
    resp = conn.urlopen(
../../.virtualenvs/docker-py/lib/python3.10/site-packages/urllib3/connectionpool.py:703: in urlopen
    httplib_response = self._make_request(
../../.virtualenvs/docker-py/lib/python3.10/site-packages/urllib3/connectionpool.py:449: in _make_request
    six.raise_from(e, None)
../../.virtualenvs/docker-py/lib/python3.10/site-packages/urllib3/connectionpool.py:444: in _make_request
    httplib_response = conn.getresponse()
/usr/lib/python3.10/http/client.py:1374: in getresponse
    response.begin()
/usr/lib/python3.10/http/client.py:318: in begin
    version, status, reason = self._read_status()
/usr/lib/python3.10/http/client.py:279: in _read_status
    line = str(self.fp.readline(_MAXLINE + 1), "iso-8859-1")
/usr/lib/python3.10/socket.py:705: in readinto
    return self._sock.recv_into(b)
E   Failed: Timeout &gt;5.0s</failure><system-out>--------------------------------- Captured Log ---------------------------------

--------------------------------- Captured Out ---------------------------------

</system-out><system-err>--------------------------------- Captured Err ---------------------------------

</system-err></testcase><testcase classname="tests.integration.api_container_test.LogsTest" name="test_logs_tail_option" time="9.368" /><testcase classname="tests.integration.api_container_test.LogsTest" name="test_logs_with_dict_instead_of_id" time="9.151" /><testcase classname="tests.integration.api_container_test.LogsTest" name="test_logs_with_tail_0" time="9.074" /><testcase classname="tests.integration.api_container_test.LogsTest" name="test_logs_with_until" time="9.717" /><testcase classname="tests.integration.api_container_test.DiffTest" name="test_diff" time="9.367" /><testcase classname="tests.integration.api_container_test.DiffTest" name="test_diff_with_dict_instead_of_id" time="9.241" /><testcase classname="tests.integration.api_container_test.StopTest" name="test_stop" time="10.898" /><testcase classname="tests.integration.api_container_test.StopTest" name="test_stop_with_dict_instead_of_id" time="10.514" /><testcase classname="tests.integration.api_container_test.KillTest" name="test_kill" time="8.788" /><testcase classname="tests.integration.api_container_test.KillTest" name="test_kill_with_dict_instead_of_id" time="8.763" /><testcase classname="tests.integration.api_container_test.KillTest" name="test_kill_with_signal" time="8.708" /><testcase classname="tests.integration.api_container_test.KillTest" name="test_kill_with_signal_integer" time="8.805" /><testcase classname="tests.integration.api_container_test.KillTest" name="test_kill_with_signal_name" time="8.695" /><testcase classname="tests.integration.api_container_test.PortTest" name="test_port" time="8.870" /><testcase classname="tests.integration.api_container_test.ContainerTopTest" name="test_top" time="8.733"><skipped type="pytest.xfail" message="Output of docker top depends on host distro, and is not formalized." /></testcase><testcase classname="tests.integration.api_container_test.ContainerTopTest" name="test_top_with_psargs" time="8.850"><skipped type="pytest.xfail" message="Output of docker top depends on host distro, and is not formalized." /></testcase><testcase classname="tests.integration.api_container_test.RestartContainerTest" name="test_restart" time="11.404" /><testcase classname="tests.integration.api_container_test.RestartContainerTest" name="test_restart_with_dict_instead_of_id" time="11.262" /><testcase classname="tests.integration.api_container_test.RestartContainerTest" name="test_restart_with_low_timeout" time="13.120" /><testcase classname="tests.integration.api_container_test.RemoveContainerTest" name="test_remove" time="12.227" /><testcase classname="tests.integration.api_container_test.RemoveContainerTest" name="test_remove_with_dict_instead_of_id" time="10.645" /><testcase classname="tests.integration.api_container_test.AttachContainerTest" name="test_attach_no_stream" time="10.001"><failure message="Failed: Timeout &gt;10.0s">tests/integration/base.py:83: in tearDown
    super().tearDown()
tests/integration/base.py:30: in tearDown
    client = docker.from_env(version=TEST_API_VERSION)
docker/client.py:96: in from_env
    return cls(
docker/client.py:45: in __init__
    self.api = APIClient(*args, **kwargs)
docker/api/client.py:197: in __init__
    self._version = self._retrieve_server_version()
docker/api/client.py:214: in _retrieve_server_version
    return self.version(api_version=False)["ApiVersion"]
docker/api/daemon.py:181: in version
    return self._result(self._get(url), json=True)
docker/utils/decorators.py:46: in inner
    return f(self, *args, **kwargs)
docker/api/client.py:251: in _get
    return self.get(url, **self._set_request_timeout(kwargs))
../../.virtualenvs/docker-py/lib/python3.10/site-packages/requests/sessions.py:600: in get
    return self.request("GET", url, **kwargs)
../../.virtualenvs/docker-py/lib/python3.10/site-packages/requests/sessions.py:587: in request
    resp = self.send(prep, **send_kwargs)
../../.virtualenvs/docker-py/lib/python3.10/site-packages/requests/sessions.py:701: in send
    r = adapter.send(request, **kwargs)
../../.virtualenvs/docker-py/lib/python3.10/site-packages/requests/adapters.py:489: in send
    resp = conn.urlopen(
../../.virtualenvs/docker-py/lib/python3.10/site-packages/urllib3/connectionpool.py:703: in urlopen
    httplib_response = self._make_request(
../../.virtualenvs/docker-py/lib/python3.10/site-packages/urllib3/connectionpool.py:449: in _make_request
    six.raise_from(e, None)
../../.virtualenvs/docker-py/lib/python3.10/site-packages/urllib3/connectionpool.py:444: in _make_request
    httplib_response = conn.getresponse()
/usr/lib/python3.10/http/client.py:1374: in getresponse
    response.begin()
/usr/lib/python3.10/http/client.py:318: in begin
    version, status, reason = self._read_status()
/usr/lib/python3.10/http/client.py:279: in _read_status
    line = str(self.fp.readline(_MAXLINE + 1), "iso-8859-1")
/usr/lib/python3.10/socket.py:705: in readinto
    return self._sock.recv_into(b)
E   Failed: Timeout &gt;10.0s</failure><system-out>--------------------------------- Captured Log ---------------------------------

--------------------------------- Captured Out ---------------------------------

</system-out><system-err>--------------------------------- Captured Err ---------------------------------

</system-err></testcase><testcase classname="tests.integration.api_container_test.AttachContainerTest" name="test_attach_stream_and_cancel" time="10.000"><failure message="Failed: Timeout &gt;10.0s">tests/integration/base.py:83: in tearDown
    super().tearDown()
tests/integration/base.py:30: in tearDown
    client = docker.from_env(version=TEST_API_VERSION)
docker/client.py:96: in from_env
    return cls(
docker/client.py:45: in __init__
    self.api = APIClient(*args, **kwargs)
docker/api/client.py:197: in __init__
    self._version = self._retrieve_server_version()
docker/api/client.py:214: in _retrieve_server_version
    return self.version(api_version=False)["ApiVersion"]
docker/api/daemon.py:181: in version
    return self._result(self._get(url), json=True)
docker/utils/decorators.py:46: in inner
    return f(self, *args, **kwargs)
docker/api/client.py:251: in _get
    return self.get(url, **self._set_request_timeout(kwargs))
../../.virtualenvs/docker-py/lib/python3.10/site-packages/requests/sessions.py:600: in get
    return self.request("GET", url, **kwargs)
../../.virtualenvs/docker-py/lib/python3.10/site-packages/requests/sessions.py:587: in request
    resp = self.send(prep, **send_kwargs)
../../.virtualenvs/docker-py/lib/python3.10/site-packages/requests/sessions.py:701: in send
    r = adapter.send(request, **kwargs)
../../.virtualenvs/docker-py/lib/python3.10/site-packages/requests/adapters.py:489: in send
    resp = conn.urlopen(
../../.virtualenvs/docker-py/lib/python3.10/site-packages/urllib3/connectionpool.py:703: in urlopen
    httplib_response = self._make_request(
../../.virtualenvs/docker-py/lib/python3.10/site-packages/urllib3/connectionpool.py:449: in _make_request
    six.raise_from(e, None)
../../.virtualenvs/docker-py/lib/python3.10/site-packages/urllib3/connectionpool.py:444: in _make_request
    httplib_response = conn.getresponse()
/usr/lib/python3.10/http/client.py:1374: in getresponse
    response.begin()
/usr/lib/python3.10/http/client.py:318: in begin
    version, status, reason = self._read_status()
/usr/lib/python3.10/http/client.py:279: in _read_status
    line = str(self.fp.readline(_MAXLINE + 1), "iso-8859-1")
/usr/lib/python3.10/socket.py:705: in readinto
    return self._sock.recv_into(b)
E   Failed: Timeout &gt;10.0s</failure><system-out>--------------------------------- Captured Log ---------------------------------

--------------------------------- Captured Out ---------------------------------

</system-out><system-err>--------------------------------- Captured Err ---------------------------------

</system-err></testcase><testcase classname="tests.integration.api_container_test.AttachContainerTest" name="test_detach_with_arg" time="10.875" /><testcase classname="tests.integration.api_container_test.AttachContainerTest" name="test_detach_with_config_file" time="12.295" /><testcase classname="tests.integration.api_container_test.AttachContainerTest" name="test_detach_with_default" time="15.702" /><testcase classname="tests.integration.api_container_test.AttachContainerTest" name="test_run_container_reading_socket_http" time="11.470" /><testcase classname="tests.integration.api_container_test.AttachContainerTest" name="test_run_container_reading_socket_ws" time="14.948"><failure message="ValueError: scheme http+docker is invalid">tests/integration/api_container_test.py:1245: in test_run_container_reading_socket_ws
    pty_stdout = self.client.attach_socket(container, opts, ws=True)
docker/utils/decorators.py:19: in wrapped
    return f(self, resource_id, *args, **kwargs)
docker/api/container.py:98: in attach_socket
    return self._attach_websocket(container, params)
docker/utils/decorators.py:19: in wrapped
    return f(self, resource_id, *args, **kwargs)
docker/api/client.py:340: in _attach_websocket
    return self._create_websocket_connection(full_url)
docker/api/client.py:343: in _create_websocket_connection
    return websocket.create_connection(url)
../../.virtualenvs/docker-py/lib/python3.10/site-packages/websocket/_core.py:601: in create_connection
    websock.connect(url, **options)
../../.virtualenvs/docker-py/lib/python3.10/site-packages/websocket/_core.py:244: in connect
    self.sock, addrs = connect(url, self.sock_opt, proxy_info(**options),
../../.virtualenvs/docker-py/lib/python3.10/site-packages/websocket/_http.py:117: in connect
    hostname, port, resource, is_secure = parse_url(url)
../../.virtualenvs/docker-py/lib/python3.10/site-packages/websocket/_url.py:62: in parse_url
    raise ValueError("scheme %s is invalid" % scheme)
E   ValueError: scheme http+docker is invalid</failure><system-out>--------------------------------- Captured Log ---------------------------------

--------------------------------- Captured Out ---------------------------------

</system-out><system-err>--------------------------------- Captured Err ---------------------------------

</system-err></testcase><testcase classname="tests.integration.api_container_test.AttachContainerTest" name="test_run_container_streaming" time="21.291" /><testcase classname="tests.integration.api_container_test.PauseTest" name="test_pause_unpause" time="20.907" /><testcase classname="tests.integration.api_container_test.PruneTest" name="test_prune_containers" time="21.522" /><testcase classname="tests.integration.api_container_test.GetContainerStatsTest" name="test_get_container_stats_no_stream" time="20.859" /><testcase classname="tests.integration.api_container_test.ContainerUpdateTest" name="test_restart_policy_update" time="22.441"><failure message="TypeError: a bytes-like object is required, not 'str'">docker/api/client.py:296: in _raise_for_status
    response.raise_for_status()
../../.virtualenvs/docker-py/lib/python3.10/site-packages/requests/models.py:1021: in raise_for_status
    raise HTTPError(http_error_msg, response=self)
E   requests.exceptions.HTTPError: 404 Client Error: Not Found for url: http+docker://localhost/v1.41/containers/b04d2f621aca0ad72c298f0244c8caab37bd0a6fb6b08a511faafc40ca78f841/update

During handling of the above exception, another exception occurred:
tests/integration/api_container_test.py:1448: in test_restart_policy_update
    self.client.update_container(container,
docker/utils/decorators.py:34: in wrapper
    return f(self, *args, **kwargs)
docker/utils/decorators.py:19: in wrapped
    return f(self, resource_id, *args, **kwargs)
docker/api/container.py:1301: in update_container
    return self._result(res, True)
docker/api/client.py:302: in _result
    self._raise_for_status(response)
docker/api/client.py:298: in _raise_for_status
    raise create_api_error_from_http_exception(e) from e
docker/errors.py:34: in create_api_error_from_http_exception
    if any(fragment in explanation_msg
docker/errors.py:34: in &lt;genexpr&gt;
    if any(fragment in explanation_msg
E   TypeError: a bytes-like object is required, not 'str'</failure><system-out>--------------------------------- Captured Log ---------------------------------

--------------------------------- Captured Out ---------------------------------

</system-out><system-err>--------------------------------- Captured Err ---------------------------------

</system-err></testcase><testcase classname="tests.integration.api_container_test.ContainerUpdateTest" name="test_update_container" time="19.860"><failure message="TypeError: a bytes-like object is required, not 'str'">docker/api/client.py:296: in _raise_for_status
    response.raise_for_status()
../../.virtualenvs/docker-py/lib/python3.10/site-packages/requests/models.py:1021: in raise_for_status
    raise HTTPError(http_error_msg, response=self)
E   requests.exceptions.HTTPError: 404 Client Error: Not Found for url: http+docker://localhost/v1.41/containers/6b07334e5a30c99d86e3d5a49cee117b9c57b4b0c07d09fb5c26328e0c4c2dfc/update

During handling of the above exception, another exception occurred:
tests/integration/api_container_test.py:1426: in test_update_container
    self.client.update_container(container, mem_limit=new_mem_limit)
docker/utils/decorators.py:34: in wrapper
    return f(self, *args, **kwargs)
docker/utils/decorators.py:19: in wrapped
    return f(self, resource_id, *args, **kwargs)
docker/api/container.py:1301: in update_container
    return self._result(res, True)
docker/api/client.py:302: in _result
    self._raise_for_status(response)
docker/api/client.py:298: in _raise_for_status
    raise create_api_error_from_http_exception(e) from e
docker/errors.py:34: in create_api_error_from_http_exception
    if any(fragment in explanation_msg
docker/errors.py:34: in &lt;genexpr&gt;
    if any(fragment in explanation_msg
E   TypeError: a bytes-like object is required, not 'str'</failure><system-out>--------------------------------- Captured Log ---------------------------------

--------------------------------- Captured Out ---------------------------------

</system-out><system-err>--------------------------------- Captured Err ---------------------------------

</system-err></testcase><testcase classname="tests.integration.api_container_test.ContainerCPUTest" name="test_container_cpu_shares" time="23.337" /><testcase classname="tests.integration.api_container_test.ContainerCPUTest" name="test_container_cpuset" time="24.257" /><testcase classname="tests.integration.api_container_test.ContainerCPUTest" name="test_create_with_runtime" time="22.002"><failure message="AssertionError: assert 'oci' == 'runc'&#10;  - runc&#10;  + oci">tests/integration/api_container_test.py:1493: in test_create_with_runtime
    assert config['HostConfig']['Runtime'] == 'runc'
E   AssertionError: assert 'oci' == 'runc'
E     - runc
E     + oci</failure><system-out>--------------------------------- Captured Log ---------------------------------

--------------------------------- Captured Out ---------------------------------

</system-out><system-err>--------------------------------- Captured Err ---------------------------------

</system-err></testcase><testcase classname="tests.integration.api_exec_test.ExecTest" name="test_detach_with_config_file" time="32.401"><failure message="AssertionError">tests/integration/api_exec_test.py:227: in test_detach_with_config_file
    assert_cat_socket_detached_with_keys(sock, [ctrl_with('p')])
tests/helpers.py:137: in assert_cat_socket_detached_with_keys
    assert data == b'' or data.startswith(
E   AssertionError</failure><system-out>--------------------------------- Captured Log ---------------------------------

--------------------------------- Captured Out ---------------------------------

</system-out><system-err>--------------------------------- Captured Err ---------------------------------

</system-err></testcase><testcase classname="tests.integration.api_exec_test.ExecTest" name="test_detach_with_default" time="29.426"><failure message="AssertionError">tests/integration/api_exec_test.py:208: in test_detach_with_default
    assert_cat_socket_detached_with_keys(
tests/helpers.py:137: in assert_cat_socket_detached_with_keys
    assert data == b'' or data.startswith(
E   AssertionError</failure><system-out>--------------------------------- Captured Log ---------------------------------

--------------------------------- Captured Out ---------------------------------

</system-out><system-err>--------------------------------- Captured Err ---------------------------------

</system-err></testcase><testcase classname="tests.integration.api_exec_test.ExecTest" name="test_exec_command_as_root" time="19.558" /><testcase classname="tests.integration.api_exec_test.ExecTest" name="test_exec_command_as_user" time="18.543" /><testcase classname="tests.integration.api_exec_test.ExecTest" name="test_exec_command_streaming" time="20.920" /><testcase classname="tests.integration.api_exec_test.ExecTest" name="test_exec_command_string" time="20.690" /><testcase classname="tests.integration.api_exec_test.ExecTest" name="test_exec_command_with_env" time="23.852" /><testcase classname="tests.integration.api_exec_test.ExecTest" name="test_exec_command_with_workdir" time="23.734" /><testcase classname="tests.integration.api_exec_test.ExecTest" name="test_exec_inspect" time="24.448" /><testcase classname="tests.integration.api_exec_test.ExecTest" name="test_exec_start_detached" time="22.695"><failure message="AssertionError: assert '\n' == ''&#10;  Strings contain only whitespace, escaping them using repr()&#10;  - ''&#10;  + '\n'">tests/integration/api_exec_test.py:152: in test_exec_start_detached
    assert response == ""
E   AssertionError: assert '\n' == ''
E     Strings contain only whitespace, escaping them using repr()
E     - ''
E     + '\n'</failure><system-out>--------------------------------- Captured Log ---------------------------------

--------------------------------- Captured Out ---------------------------------

</system-out><system-err>--------------------------------- Captured Err ---------------------------------

</system-err></testcase><testcase classname="tests.integration.api_exec_test.ExecTest" name="test_exec_start_socket" time="22.447"><failure message="assert 121 == 1">tests/integration/api_exec_test.py:134: in test_exec_start_socket
    assert stream == 1  # stdout (0 = stdin, 1 = stdout, 2 = stderr)
E   assert 121 == 1</failure><system-out>--------------------------------- Captured Log ---------------------------------

--------------------------------- Captured Out ---------------------------------

</system-out><system-err>--------------------------------- Captured Err ---------------------------------

</system-err></testcase><testcase classname="tests.integration.api_exec_test.ExecTest" name="test_execute_command" time="23.528" /><testcase classname="tests.integration.api_exec_test.ExecTest" name="test_execute_command_with_proxy_env" time="22.578" /><testcase classname="tests.integration.api_exec_test.ExecDemuxTest" name="test_exec_command_no_stream_demux" time="22.397" /><testcase classname="tests.integration.api_exec_test.ExecDemuxTest" name="test_exec_command_no_stream_no_demux" time="22.703" /><testcase classname="tests.integration.api_exec_test.ExecDemuxTest" name="test_exec_command_stream_demux" time="20.788" /><testcase classname="tests.integration.api_exec_test.ExecDemuxTest" name="test_exec_command_stream_no_demux" time="18.640" /><testcase classname="tests.integration.api_exec_test.ExecDemuxTest" name="test_exec_command_tty_no_stream_demux" time="15.589"><failure message="ValueError: 104 is not a valid stream">tests/integration/api_exec_test.py:299: in test_exec_command_tty_no_stream_demux
    exec_log = self.client.exec_start(res, demux=True)
docker/utils/decorators.py:19: in wrapped
    return f(self, resource_id, *args, **kwargs)
docker/api/exec_api.py:173: in exec_start
    output = self._read_from_socket(res, stream, tty=tty, demux=demux)
docker/api/client.py:457: in _read_from_socket
    return consume_socket_output(gen, demux=demux)
docker/utils/socket.py:154: in consume_socket_output
    for frame in frames:
docker/api/client.py:447: in &lt;genexpr&gt;
    gen = (demux_adaptor(*frame) for frame in gen)
docker/utils/socket.py:181: in demux_adaptor
    raise ValueError(f'{stream_id} is not a valid stream')
E   ValueError: 104 is not a valid stream</failure><system-out>--------------------------------- Captured Log ---------------------------------

--------------------------------- Captured Out ---------------------------------

</system-out><system-err>--------------------------------- Captured Err ---------------------------------

</system-err></testcase><testcase classname="tests.integration.api_exec_test.ExecDemuxTest" name="test_exec_command_tty_no_stream_no_demux" time="10.651"><failure message="AssertionError: assert b't\r\nhello err\r\n' == b'hello out\r\nhello err\r\n'&#10;  At index 0 diff: b't' != b'h'&#10;  Full diff:&#10;  - b'hello out\r\nhello err\r\n'&#10;  ?   --------&#10;  + b't\r\nhello err\r\n'">tests/integration/api_exec_test.py:282: in test_exec_command_tty_no_stream_no_demux
    assert exec_log == b'hello out\r\nhello err\r\n'
E   AssertionError: assert b't\r\nhello err\r\n' == b'hello out\r\nhello err\r\n'
E     At index 0 diff: b't' != b'h'
E     Full diff:
E     - b'hello out\r\nhello err\r\n'
E     ?   --------
E     + b't\r\nhello err\r\n'</failure><system-out>--------------------------------- Captured Log ---------------------------------

--------------------------------- Captured Out ---------------------------------

</system-out><system-err>--------------------------------- Captured Err ---------------------------------

</system-err></testcase><testcase classname="tests.integration.api_exec_test.ExecDemuxTest" name="test_exec_command_tty_stream_demux" time="10.512"><failure message="ValueError: 104 is not a valid stream">tests/integration/api_exec_test.py:305: in test_exec_command_tty_stream_demux
    exec_log = list(self.client.exec_start(res, demux=True, stream=True))
docker/types/daemon.py:32: in __next__
    return next(self._stream)
docker/api/client.py:447: in &lt;genexpr&gt;
    gen = (demux_adaptor(*frame) for frame in gen)
docker/utils/socket.py:181: in demux_adaptor
    raise ValueError(f'{stream_id} is not a valid stream')
E   ValueError: 104 is not a valid stream</failure><system-out>--------------------------------- Captured Log ---------------------------------

--------------------------------- Captured Out ---------------------------------

</system-out><system-err>--------------------------------- Captured Err ---------------------------------

</system-err></testcase><testcase classname="tests.integration.api_exec_test.ExecDemuxTest" name="test_exec_command_tty_stream_no_demux" time="10.368"><failure message="AssertionError: assert b'hello out\r\n' in [b't\r\n', b'hello err\r\n']">tests/integration/api_exec_test.py:288: in test_exec_command_tty_stream_no_demux
    assert b'hello out\r\n' in exec_log
E   AssertionError: assert b'hello out\r\n' in [b't\r\n', b'hello err\r\n']</failure><system-out>--------------------------------- Captured Log ---------------------------------

--------------------------------- Captured Out ---------------------------------

</system-out><system-err>--------------------------------- Captured Err ---------------------------------

</system-err></testcase><testcase classname="tests.integration.api_healthcheck_test.HealthcheckTest" name="test_healthcheck_fails" time="9.896" /><testcase classname="tests.integration.api_healthcheck_test.HealthcheckTest" name="test_healthcheck_passes" time="9.463" /><testcase classname="tests.integration.api_healthcheck_test.HealthcheckTest" name="test_healthcheck_shell_command" time="8.549" /><testcase classname="tests.integration.api_healthcheck_test.HealthcheckTest" name="test_healthcheck_start_period" time="12.843" /><testcase classname="tests.integration.api_image_test.ListImagesTest" name="test_images" time="12.420" /><testcase classname="tests.integration.api_image_test.ListImagesTest" name="test_images_quiet" time="9.060" /><testcase classname="tests.integration.api_image_test.PullImageTest" name="test_pull" time="13.447" /><testcase classname="tests.integration.api_image_test.PullImageTest" name="test_pull_invalid_platform" time="11.452"><failure message="Failed: DID NOT RAISE &lt;class 'docker.errors.APIError'&gt;">tests/integration/api_image_test.py:68: in test_pull_invalid_platform
    with pytest.raises(docker.errors.APIError) as excinfo:
E   Failed: DID NOT RAISE &lt;class 'docker.errors.APIError'&gt;</failure><system-out>--------------------------------- Captured Log ---------------------------------

--------------------------------- Captured Out ---------------------------------

</system-out><system-err>--------------------------------- Captured Err ---------------------------------

</system-err></testcase><testcase classname="tests.integration.api_image_test.PullImageTest" name="test_pull_streaming" time="11.964" /><testcase classname="tests.integration.api_image_test.CommitTest" name="test_commit" time="11.401"><failure message="AssertionError: assert False&#10; +  where False = &lt;built-in method startswith of str object at 0x7fca5fa3c030&gt;('6b186ff59cea94db1783627d0b439daadaf63899323ac572f157e1793bb2f5cf')&#10; +    where &lt;built-in method startswith of str object at 0x7fca5fa3c030&gt; = ''.startswith">tests/integration/api_image_test.py:89: in test_commit
    assert img['Container'].startswith(id)
E   AssertionError: assert False
E    +  where False = &lt;built-in method startswith of str object at 0x7fca5fa3c030&gt;('6b186ff59cea94db1783627d0b439daadaf63899323ac572f157e1793bb2f5cf')
E    +    where &lt;built-in method startswith of str object at 0x7fca5fa3c030&gt; = ''.startswith</failure><system-out>--------------------------------- Captured Log ---------------------------------

--------------------------------- Captured Out ---------------------------------

</system-out><system-err>--------------------------------- Captured Err ---------------------------------

</system-err></testcase><testcase classname="tests.integration.api_image_test.CommitTest" name="test_commit_with_changes" time="14.136"><failure message="AssertionError: assert False&#10; +  where False = &lt;built-in method startswith of str object at 0x7fca5fa3c030&gt;('6ceb3461cdf5d414aabeeee11e551a9e823809ccb1aae97b4cc21e5665d630af')&#10; +    where &lt;built-in method startswith of str object at 0x7fca5fa3c030&gt; = ''.startswith">tests/integration/api_image_test.py:107: in test_commit_with_changes
    assert img['Container'].startswith(cid['Id'])
E   AssertionError: assert False
E    +  where False = &lt;built-in method startswith of str object at 0x7fca5fa3c030&gt;('6ceb3461cdf5d414aabeeee11e551a9e823809ccb1aae97b4cc21e5665d630af')
E    +    where &lt;built-in method startswith of str object at 0x7fca5fa3c030&gt; = ''.startswith</failure><system-out>--------------------------------- Captured Log ---------------------------------

--------------------------------- Captured Out ---------------------------------

</system-out><system-err>--------------------------------- Captured Err ---------------------------------

</system-err></testcase><testcase classname="tests.integration.api_image_test.RemoveImageTest" name="test_remove" time="10.636" /><testcase classname="tests.integration.api_image_test.ImportImageTest" name="test_get_load_image" time="11.774"><failure message="assert False&#10; +  where False = any([])">tests/integration/api_image_test.py:266: in test_get_load_image
    assert any([
E   assert False
E    +  where False = any([])</failure><system-out>--------------------------------- Captured Log ---------------------------------

--------------------------------- Captured Out ---------------------------------

</system-out><system-err>--------------------------------- Captured Err ---------------------------------

</system-err></testcase><testcase classname="tests.integration.api_image_test.ImportImageTest" name="test_import_from_bytes" time="10.032" /><testcase classname="tests.integration.api_image_test.ImportImageTest" name="test_import_from_file" time="9.991" /><testcase classname="tests.integration.api_image_test.ImportImageTest" name="test_import_from_stream" time="10.752" /><testcase classname="tests.integration.api_image_test.ImportImageTest" name="test_import_from_url" time="0.000"><skipped type="pytest.skip" message="Doesn't work inside a container - FIXME">/home/riyad/src/docker-py/tests/integration/api_image_test.py:291: Doesn't work inside a container - FIXME</skipped><system-out>--------------------------------- Captured Log ---------------------------------

--------------------------------- Captured Out ---------------------------------

</system-out><system-err>--------------------------------- Captured Err ---------------------------------

</system-err></testcase><testcase classname="tests.integration.api_image_test.ImportImageTest" name="test_import_image_from_data_with_changes" time="11.530" /><testcase classname="tests.integration.api_image_test.ImportImageTest" name="test_import_image_with_changes" time="11.011" /><testcase classname="tests.integration.api_image_test.PruneImagesTest" name="test_prune_images" time="14.158"><failure message="docker.errors.APIError: 500 Server Error for http+docker://localhost/v1.41/images/prune?filters=%7B%22dangling%22%3A+%5B%22false%22%5D%7D: Internal Server Error (&quot;specifying &quot;dangling&quot; filter more than once with different values is not supported&quot;)">docker/api/client.py:296: in _raise_for_status
    response.raise_for_status()
../../.virtualenvs/docker-py/lib/python3.10/site-packages/requests/models.py:1021: in raise_for_status
    raise HTTPError(http_error_msg, response=self)
E   requests.exceptions.HTTPError: 500 Server Error: Internal Server Error for url: http+docker://localhost/v1.41/images/prune?filters=%7B%22dangling%22%3A+%5B%22false%22%5D%7D

The above exception was the direct cause of the following exception:
tests/integration/api_image_test.py:331: in test_prune_images
    result = self.client.prune_images({'dangling': False})
docker/utils/decorators.py:34: in wrapper
    return f(self, *args, **kwargs)
docker/api/image.py:349: in prune_images
    return self._result(self._post(url, params=params), True)
docker/api/client.py:302: in _result
    self._raise_for_status(response)
docker/api/client.py:298: in _raise_for_status
    raise create_api_error_from_http_exception(e) from e
docker/errors.py:39: in create_api_error_from_http_exception
    raise cls(e, response=response, explanation=explanation) from e
E   docker.errors.APIError: 500 Server Error for http+docker://localhost/v1.41/images/prune?filters=%7B%22dangling%22%3A+%5B%22false%22%5D%7D: Internal Server Error ("specifying "dangling" filter more than once with different values is not supported")</failure><system-out>--------------------------------- Captured Log ---------------------------------

--------------------------------- Captured Out ---------------------------------

</system-out><system-err>--------------------------------- Captured Err ---------------------------------

</system-err></testcase><testcase classname="tests.integration.api_image_test.SaveLoadImagesTest" name="test_get_image_load_image" time="12.512"><failure message="assert False is True">tests/integration/api_image_test.py:360: in test_get_image_load_image
    assert success is True
E   assert False is True</failure><system-out>--------------------------------- Captured Log ---------------------------------

--------------------------------- Captured Out ---------------------------------
{'stream': 'Loaded image: docker.io/library/alpine:3.10'}

</system-out><system-err>--------------------------------- Captured Err ---------------------------------

</system-err></testcase><testcase classname="tests.integration.api_image_test.InspectDistributionTest" name="test_inspect_distribution" time="11.343"><failure message="docker.errors.NotFound: 404 Client Error for http+docker://localhost/v1.41/distribution/busybox:latest/json: Not Found (&quot;Path /v1.41/distribution/busybox:latest/json is not supported&quot;)">docker/api/client.py:296: in _raise_for_status
    response.raise_for_status()
../../.virtualenvs/docker-py/lib/python3.10/site-packages/requests/models.py:1021: in raise_for_status
    raise HTTPError(http_error_msg, response=self)
E   requests.exceptions.HTTPError: 404 Client Error: Not Found for url: http+docker://localhost/v1.41/distribution/busybox:latest/json

The above exception was the direct cause of the following exception:
tests/integration/api_image_test.py:366: in test_inspect_distribution
    data = self.client.inspect_distribution('busybox:latest')
docker/utils/decorators.py:34: in wrapper
    return f(self, *args, **kwargs)
docker/utils/decorators.py:19: in wrapped
    return f(self, resource_id, *args, **kwargs)
docker/api/image.py:287: in inspect_distribution
    return self._result(
docker/api/client.py:302: in _result
    self._raise_for_status(response)
docker/api/client.py:298: in _raise_for_status
    raise create_api_error_from_http_exception(e) from e
docker/errors.py:39: in create_api_error_from_http_exception
    raise cls(e, response=response, explanation=explanation) from e
E   docker.errors.NotFound: 404 Client Error for http+docker://localhost/v1.41/distribution/busybox:latest/json: Not Found ("Path /v1.41/distribution/busybox:latest/json is not supported")</failure><system-out>--------------------------------- Captured Log ---------------------------------

--------------------------------- Captured Out ---------------------------------

</system-out><system-err>--------------------------------- Captured Err ---------------------------------

</system-err></testcase><testcase classname="tests.integration.api_network_test.TestNetworks" name="test_connect_and_disconnect_container" time="13.577" /><testcase classname="tests.integration.api_network_test.TestNetworks" name="test_connect_and_force_disconnect_container" time="14.195" /><testcase classname="tests.integration.api_network_test.TestNetworks" name="test_connect_on_container_create" time="10.495" /><testcase classname="tests.integration.api_network_test.TestNetworks" name="test_connect_with_aliases" time="9.775" /><testcase classname="tests.integration.api_network_test.TestNetworks" name="test_connect_with_ipv4_address" time="11.549"><failure message="TypeError: 'NoneType' object is not subscriptable">tests/integration/api_network_test.py:379: in test_connect_with_ipv4_address
    assert net_data['IPAMConfig']['IPv4Address'] == '172.28.5.24'
E   TypeError: 'NoneType' object is not subscriptable</failure><system-out>--------------------------------- Captured Log ---------------------------------

--------------------------------- Captured Out ---------------------------------

</system-out><system-err>--------------------------------- Captured Err ---------------------------------

</system-err></testcase><testcase classname="tests.integration.api_network_test.TestNetworks" name="test_connect_with_ipv6_address" time="10.524"><failure message="TypeError: 'NoneType' object is not subscriptable">tests/integration/api_network_test.py:405: in test_connect_with_ipv6_address
    assert net_data['IPAMConfig']['IPv6Address'] == '2001:389::f00d'
E   TypeError: 'NoneType' object is not subscriptable</failure><system-out>--------------------------------- Captured Log ---------------------------------

--------------------------------- Captured Out ---------------------------------

</system-out><system-err>--------------------------------- Captured Err ---------------------------------

</system-err></testcase><testcase classname="tests.integration.api_network_test.TestNetworks" name="test_connect_with_links" time="12.187"><failure message="AssertionError: assert None == ['docker-py-test-upstream:bar']">tests/integration/api_network_test.py:344: in test_connect_with_links
    assert net_settings['Networks'][net_name]['Links'] == [
E   AssertionError: assert None == ['docker-py-test-upstream:bar']</failure><system-out>--------------------------------- Captured Log ---------------------------------

--------------------------------- Captured Out ---------------------------------

</system-out><system-err>--------------------------------- Captured Err ---------------------------------

</system-err></testcase><testcase classname="tests.integration.api_network_test.TestNetworks" name="test_connect_with_mac_address" time="10.546"><failure message="AssertionError: assert '' == '02:42:ac:11:00:02'&#10;  - 02:42:ac:11:00:02">tests/integration/api_network_test.py:421: in test_connect_with_mac_address
    assert net_data['MacAddress'] == '02:42:ac:11:00:02'
E   AssertionError: assert '' == '02:42:ac:11:00:02'
E     - 02:42:ac:11:00:02</failure><system-out>--------------------------------- Captured Log ---------------------------------

--------------------------------- Captured Out ---------------------------------

</system-out><system-err>--------------------------------- Captured Err ---------------------------------

</system-err></testcase><testcase classname="tests.integration.api_network_test.TestNetworks" name="test_create_check_duplicate" time="8.473" /><testcase classname="tests.integration.api_network_test.TestNetworks" name="test_create_internal_networks" time="8.750" /><testcase classname="tests.integration.api_network_test.TestNetworks" name="test_create_network_ipv6_enabled" time="8.708" /><testcase classname="tests.integration.api_network_test.TestNetworks" name="test_create_network_with_host_driver_fails" time="7.836" /><testcase classname="tests.integration.api_network_test.TestNetworks" name="test_create_network_with_ipam_config" time="8.668"><failure message="AssertionError: assert {'driver': 'host-local'} is None&#10; +  where {'driver': 'host-local'} = &lt;built-in method pop of dict object at 0x7fca5ccf4880&gt;('Options', None)&#10; +    where &lt;built-in method pop of dict object at 0x7fca5ccf4880&gt; = {'Config': [{'Gateway': '172.28.5.254', 'Subnet': '172.28.0.0/16'}], 'Driver': 'default'}.pop">tests/integration/api_network_test.py:62: in test_create_network_with_ipam_config
    assert ipam.pop('Options', None) is None
E   AssertionError: assert {'driver': 'host-local'} is None
E    +  where {'driver': 'host-local'} = &lt;built-in method pop of dict object at 0x7fca5ccf4880&gt;('Options', None)
E    +    where &lt;built-in method pop of dict object at 0x7fca5ccf4880&gt; = {'Config': [{'Gateway': '172.28.5.254', 'Subnet': '172.28.0.0/16'}], 'Driver': 'default'}.pop</failure><system-out>--------------------------------- Captured Log ---------------------------------

--------------------------------- Captured Out ---------------------------------

</system-out><system-err>--------------------------------- Captured Err ---------------------------------

</system-err></testcase><testcase classname="tests.integration.api_network_test.TestNetworks" name="test_create_network_with_labels" time="8.705" /><testcase classname="tests.integration.api_network_test.TestNetworks" name="test_create_network_with_labels_wrong_type" time="8.349" /><testcase classname="tests.integration.api_network_test.TestNetworks" name="test_create_remove_network_with_space_in_name" time="7.812"><failure message="docker.errors.APIError: 500 Server Error for http+docker://localhost/v1.41/networks/create: Internal Server Error (&quot;network name test 01 invalid: names must match [a-zA-Z0-9][a-zA-Z0-9_.-]*: invalid argument&quot;)">docker/api/client.py:296: in _raise_for_status
    response.raise_for_status()
../../.virtualenvs/docker-py/lib/python3.10/site-packages/requests/models.py:1021: in raise_for_status
    raise HTTPError(http_error_msg, response=self)
E   requests.exceptions.HTTPError: 500 Server Error: Internal Server Error for url: http+docker://localhost/v1.41/networks/create

The above exception was the direct cause of the following exception:
tests/integration/api_network_test.py:470: in test_create_remove_network_with_space_in_name
    net_id = self.client.create_network('test 01')
docker/api/network.py:153: in create_network
    return self._result(res, json=True)
docker/api/client.py:302: in _result
    self._raise_for_status(response)
docker/api/client.py:298: in _raise_for_status
    raise create_api_error_from_http_exception(e) from e
docker/errors.py:39: in create_api_error_from_http_exception
    raise cls(e, response=response, explanation=explanation) from e
E   docker.errors.APIError: 500 Server Error for http+docker://localhost/v1.41/networks/create: Internal Server Error ("network name test 01 invalid: names must match [a-zA-Z0-9][a-zA-Z0-9_.-]*: invalid argument")</failure><system-out>--------------------------------- Captured Log ---------------------------------

--------------------------------- Captured Out ---------------------------------

</system-out><system-err>--------------------------------- Captured Err ---------------------------------

</system-err></testcase><testcase classname="tests.integration.api_network_test.TestNetworks" name="test_create_with_aliases" time="8.476" /><testcase classname="tests.integration.api_network_test.TestNetworks" name="test_create_with_driveropt" time="8.566"><failure message="docker.errors.APIError: 500 Server Error for http+docker://localhost/v1.41/containers/create: Internal Server Error (&quot;container create: unable to find network with name or ID bridge: network not found&quot;)">docker/api/client.py:296: in _raise_for_status
    response.raise_for_status()
../../.virtualenvs/docker-py/lib/python3.10/site-packages/requests/models.py:1021: in raise_for_status
    raise HTTPError(http_error_msg, response=self)
E   requests.exceptions.HTTPError: 500 Server Error: Internal Server Error for url: http+docker://localhost/v1.41/containers/create

The above exception was the direct cause of the following exception:
tests/integration/api_network_test.py:276: in test_create_with_driveropt
    container = self.client.create_container(
docker/api/container.py:431: in create_container
    return self.create_container_from_config(config, name, platform)
docker/api/container.py:448: in create_container_from_config
    return self._result(res, True)
docker/api/client.py:302: in _result
    self._raise_for_status(response)
docker/api/client.py:298: in _raise_for_status
    raise create_api_error_from_http_exception(e) from e
docker/errors.py:39: in create_api_error_from_http_exception
    raise cls(e, response=response, explanation=explanation) from e
E   docker.errors.APIError: 500 Server Error for http+docker://localhost/v1.41/containers/create: Internal Server Error ("container create: unable to find network with name or ID bridge: network not found")</failure><system-out>--------------------------------- Captured Log ---------------------------------

--------------------------------- Captured Out ---------------------------------

</system-out><system-err>--------------------------------- Captured Err ---------------------------------

</system-err></testcase><testcase classname="tests.integration.api_network_test.TestNetworks" name="test_create_with_ipv4_address" time="8.339"><failure message="TypeError: 'NoneType' object is not subscriptable">tests/integration/api_network_test.py:224: in test_create_with_ipv4_address
    assert net_settings['Networks'][net_name]['IPAMConfig']['IPv4Address']\
E   TypeError: 'NoneType' object is not subscriptable</failure><system-out>--------------------------------- Captured Log ---------------------------------

--------------------------------- Captured Out ---------------------------------

</system-out><system-err>--------------------------------- Captured Err ---------------------------------

</system-err></testcase><testcase classname="tests.integration.api_network_test.TestNetworks" name="test_create_with_ipv6_address" time="8.354"><failure message="TypeError: 'NoneType' object is not subscriptable">tests/integration/api_network_test.py:250: in test_create_with_ipv6_address
    assert net_settings['Networks'][net_name]['IPAMConfig']['IPv6Address']\
E   TypeError: 'NoneType' object is not subscriptable</failure><system-out>--------------------------------- Captured Log ---------------------------------

--------------------------------- Captured Out ---------------------------------

</system-out><system-err>--------------------------------- Captured Err ---------------------------------

</system-err></testcase><testcase classname="tests.integration.api_network_test.TestNetworks" name="test_create_with_linklocal_ips" time="8.462"><failure message="docker.errors.APIError: 500 Server Error for http+docker://localhost/v1.41/containers/create: Internal Server Error (&quot;container create: unable to find network with name or ID bridge: network not found&quot;)">docker/api/client.py:296: in _raise_for_status
    response.raise_for_status()
../../.virtualenvs/docker-py/lib/python3.10/site-packages/requests/models.py:1021: in raise_for_status
    raise HTTPError(http_error_msg, response=self)
E   requests.exceptions.HTTPError: 500 Server Error: Internal Server Error for url: http+docker://localhost/v1.41/containers/create

The above exception was the direct cause of the following exception:
tests/integration/api_network_test.py:255: in test_create_with_linklocal_ips
    container = self.client.create_container(
docker/api/container.py:431: in create_container
    return self.create_container_from_config(config, name, platform)
docker/api/container.py:448: in create_container_from_config
    return self._result(res, True)
docker/api/client.py:302: in _result
    self._raise_for_status(response)
docker/api/client.py:298: in _raise_for_status
    raise create_api_error_from_http_exception(e) from e
docker/errors.py:39: in create_api_error_from_http_exception
    raise cls(e, response=response, explanation=explanation) from e
E   docker.errors.APIError: 500 Server Error for http+docker://localhost/v1.41/containers/create: Internal Server Error ("container create: unable to find network with name or ID bridge: network not found")</failure><system-out>--------------------------------- Captured Log ---------------------------------

--------------------------------- Captured Out ---------------------------------

</system-out><system-err>--------------------------------- Captured Err ---------------------------------

</system-err></testcase><testcase classname="tests.integration.api_network_test.TestNetworks" name="test_create_with_links" time="8.331"><failure message="AssertionError: assert None == ['docker-py-test-upstream:bar']">tests/integration/api_network_test.py:311: in test_create_with_links
    assert net_settings['Networks'][net_name]['Links'] == [
E   AssertionError: assert None == ['docker-py-test-upstream:bar']</failure><system-out>--------------------------------- Captured Log ---------------------------------

--------------------------------- Captured Out ---------------------------------

</system-out><system-err>--------------------------------- Captured Err ---------------------------------

</system-err></testcase><testcase classname="tests.integration.api_network_test.TestNetworks" name="test_inspect_network" time="8.468" /><testcase classname="tests.integration.api_network_test.TestNetworks" name="test_list_networks" time="8.594" /><testcase classname="tests.integration.api_network_test.TestNetworks" name="test_prune_networks" time="10.572" /><testcase classname="tests.integration.api_network_test.TestNetworks" name="test_remove_network" time="8.843" /><testcase classname="tests.integration.api_secret_test.SecretAPITest" name="test_create_secret" time="13.681" /><testcase classname="tests.integration.api_secret_test.SecretAPITest" name="test_create_secret_unicode_data" time="8.611" /><testcase classname="tests.integration.api_secret_test.SecretAPITest" name="test_inspect_secret" time="7.750" /><testcase classname="tests.integration.api_secret_test.SecretAPITest" name="test_list_secrets" time="7.720" /><testcase classname="tests.integration.api_secret_test.SecretAPITest" name="test_remove_secret" time="12.893" /><testcase classname="tests.integration.api_volume_test.TestVolumes" name="test_create_volume" time="8.562" /><testcase classname="tests.integration.api_volume_test.TestVolumes" name="test_create_volume_invalid_driver" time="7.617"><failure message="docker.errors.APIError: 500 Server Error for http+docker://localhost/v1.41/volumes/create: Internal Server Error (&quot;volume perfectcherryblossom uses volume plugin invalid.driver but it could not be retrieved: no volume plugin with name invalid.driver available: required plugin missing&quot;)">docker/api/client.py:296: in _raise_for_status
    response.raise_for_status()
../../.virtualenvs/docker-py/lib/python3.10/site-packages/requests/models.py:1021: in raise_for_status
    raise HTTPError(http_error_msg, response=self)
E   requests.exceptions.HTTPError: 500 Server Error: Internal Server Error for url: http+docker://localhost/v1.41/volumes/create

The above exception was the direct cause of the following exception:
tests/integration/api_volume_test.py:22: in test_create_volume_invalid_driver
    self.client.create_volume('perfectcherryblossom', driver_name)
docker/api/volume.py:92: in create_volume
    return self._result(self._post_json(url, data=data), True)
docker/api/client.py:302: in _result
    self._raise_for_status(response)
docker/api/client.py:298: in _raise_for_status
    raise create_api_error_from_http_exception(e) from e
docker/errors.py:39: in create_api_error_from_http_exception
    raise cls(e, response=response, explanation=explanation) from e
E   docker.errors.APIError: 500 Server Error for http+docker://localhost/v1.41/volumes/create: Internal Server Error ("volume perfectcherryblossom uses volume plugin invalid.driver but it could not be retrieved: no volume plugin with name invalid.driver available: required plugin missing")</failure><system-out>--------------------------------- Captured Log ---------------------------------

--------------------------------- Captured Out ---------------------------------

</system-out><system-err>--------------------------------- Captured Err ---------------------------------

</system-err></testcase><testcase classname="tests.integration.api_volume_test.TestVolumes" name="test_force_remove_volume" time="7.709" /><testcase classname="tests.integration.api_volume_test.TestVolumes" name="test_inspect_nonexistent_volume" time="7.620" /><testcase classname="tests.integration.api_volume_test.TestVolumes" name="test_inspect_volume" time="7.720"><failure message="AssertionError: assert {'CreatedAt':...l/_data', ...} == {'CreatedAt':...l/_data', ...}&#10;  Omitting 6 identical items, use -vv to show&#10;  Differing items:&#10;  {'Options': None} != {'Options': {}}&#10;  Full diff:&#10;    {&#10;     'CreatedAt': '2023-02-28T15:19:06+01:00',&#10;     'Driver': 'local',...&#10;  &#10;  ...Full output truncated (10 lines hidden), use '-vv' to show">tests/integration/api_volume_test.py:38: in test_inspect_volume
    assert volume_info == result
E   AssertionError: assert {'CreatedAt':...l/_data', ...} == {'CreatedAt':...l/_data', ...}
E     Omitting 6 identical items, use -vv to show
E     Differing items:
E     {'Options': None} != {'Options': {}}
E     Full diff:
E       {
E        'CreatedAt': '2023-02-28T15:19:06+01:00',
E        'Driver': 'local',...
E     
E     ...Full output truncated (10 lines hidden), use '-vv' to show</failure><system-out>--------------------------------- Captured Log ---------------------------------

--------------------------------- Captured Out ---------------------------------

</system-out><system-err>--------------------------------- Captured Err ---------------------------------

</system-err></testcase><testcase classname="tests.integration.api_volume_test.TestVolumes" name="test_list_volumes" time="7.671"><failure message="AssertionError: assert {'CreatedAt': '2023-02-28T15:19:13+01:00', 'Driver': 'local', 'Labels': {}, 'Mountpoint': '/home/riyad/podman/storage/volumes/imperishablenight/_data', ...} in [{'CreatedAt': '2023-02-28T14:51:35+01:00', 'Driver': 'local', 'Labels': {}, 'Mountpoint': '/home/riyad/podman/storage/volumes/dockerpytest_e5b3477d7a4076b/_data', ...}, {'CreatedAt': '2023-02-28T15:19:13+01:00', 'Driver': 'local', 'Labels': {}, 'Mountpoint': '/home/riyad/podman/storage/volumes/imperishablenight/_data', ...}, {'CreatedAt': '2023-02-26T14:26:57+01:00', 'Driver': 'local', 'Labels': {}, 'Mountpoint': '/home/riyad/podman/storage/volumes/somevolume/_data', ...}]">tests/integration/api_volume_test.py:31: in test_list_volumes
    assert volume_info in volumes
E   AssertionError: assert {'CreatedAt': '2023-02-28T15:19:13+01:00', 'Driver': 'local', 'Labels': {}, 'Mountpoint': '/home/riyad/podman/storage/volumes/imperishablenight/_data', ...} in [{'CreatedAt': '2023-02-28T14:51:35+01:00', 'Driver': 'local', 'Labels': {}, 'Mountpoint': '/home/riyad/podman/storage/volumes/dockerpytest_e5b3477d7a4076b/_data', ...}, {'CreatedAt': '2023-02-28T15:19:13+01:00', 'Driver': 'local', 'Labels': {}, 'Mountpoint': '/home/riyad/podman/storage/volumes/imperishablenight/_data', ...}, {'CreatedAt': '2023-02-26T14:26:57+01:00', 'Driver': 'local', 'Labels': {}, 'Mountpoint': '/home/riyad/podman/storage/volumes/somevolume/_data', ...}]</failure><system-out>--------------------------------- Captured Log ---------------------------------

--------------------------------- Captured Out ---------------------------------

</system-out><system-err>--------------------------------- Captured Err ---------------------------------

</system-err></testcase><testcase classname="tests.integration.api_volume_test.TestVolumes" name="test_prune_volumes" time="7.751" /><testcase classname="tests.integration.api_volume_test.TestVolumes" name="test_remove_nonexistent_volume" time="7.619" /><testcase classname="tests.integration.api_volume_test.TestVolumes" name="test_remove_volume" time="7.762" /><testcase classname="tests.integration.client_test.ClientTest" name="test_df" time="0.118"><failure message="docker.errors.APIError: 500 Server Error for http+docker://localhost/v1.41/system/df: Internal Server Error (&quot;runtime error: invalid memory address or nil pointer dereference&quot;)">docker/api/client.py:296: in _raise_for_status
    response.raise_for_status()
../../.virtualenvs/docker-py/lib/python3.10/site-packages/requests/models.py:1021: in raise_for_status
    raise HTTPError(http_error_msg, response=self)
E   requests.exceptions.HTTPError: 500 Server Error: Internal Server Error for url: http+docker://localhost/v1.41/system/df

The above exception was the direct cause of the following exception:
tests/integration/client_test.py:28: in test_df
    data = self.client.df()
docker/client.py:191: in df
    return self.api.df()
docker/utils/decorators.py:34: in wrapper
    return f(self, *args, **kwargs)
docker/api/daemon.py:22: in df
    return self._result(self._get(url), True)
docker/api/client.py:302: in _result
    self._raise_for_status(response)
docker/api/client.py:298: in _raise_for_status
    raise create_api_error_from_http_exception(e) from e
docker/errors.py:39: in create_api_error_from_http_exception
    raise cls(e, response=response, explanation=explanation) from e
E   docker.errors.APIError: 500 Server Error for http+docker://localhost/v1.41/system/df: Internal Server Error ("runtime error: invalid memory address or nil pointer dereference")</failure><system-out>--------------------------------- Captured Log ---------------------------------

--------------------------------- Captured Out ---------------------------------

</system-out><system-err>--------------------------------- Captured Err ---------------------------------

</system-err></testcase><testcase classname="tests.integration.client_test.ClientTest" name="test_info" time="2.066" /><testcase classname="tests.integration.client_test.ClientTest" name="test_ping" time="0.003" /><testcase classname="tests.integration.client_test.ClientTest" name="test_version" time="2.857" /><testcase classname="tests.integration.client_test.CancellableEventsTest" name="test_cancel_events" time="2.003" /><testcase classname="tests.integration.context_api_test.ContextLifecycleTest" name="test_context_remove" time="7.810" /><testcase classname="tests.integration.context_api_test.ContextLifecycleTest" name="test_lifecycle" time="7.647" /><testcase classname="tests.integration.context_api_test.ContextLifecycleTest" name="test_load_context_without_orchestrator" time="8.266" /><testcase classname="tests.integration.errors_test.ErrorsTest" name="test_api_error_parses_json" time="7.931"><failure message="AssertionError: assert 'You cannot remove a running container' in 'cannot remove container bbc5d544abe3e3e79882f237184da89dbb7994d9cedc4c554a51202ad0df075c as it is running - running or paused containers cannot be removed without force: container state improper'">tests/integration/errors_test.py:13: in test_api_error_parses_json
    assert 'You cannot remove a running container' in explanation
E   AssertionError: assert 'You cannot remove a running container' in 'cannot remove container bbc5d544abe3e3e79882f237184da89dbb7994d9cedc4c554a51202ad0df075c as it is running - running or paused containers cannot be removed without force: container state improper'</failure><system-out>--------------------------------- Captured Log ---------------------------------

--------------------------------- Captured Out ---------------------------------

</system-out><system-err>--------------------------------- Captured Err ---------------------------------

</system-err></testcase><testcase classname="tests.integration.models_containers_test.ContainerCollectionTest" name="test_get" time="5.700"><failure message="AssertionError: assert 'docker.io/li...alpine:latest' == 'alpine'&#10;  - alpine&#10;  + docker.io/library/alpine:latest">tests/integration/models_containers_test.py:189: in test_get
    assert client.containers.get(container.id).attrs[
E   AssertionError: assert 'docker.io/li...alpine:latest' == 'alpine'
E     - alpine
E     + docker.io/library/alpine:latest</failure><system-out>--------------------------------- Captured Log ---------------------------------

--------------------------------- Captured Out ---------------------------------

</system-out><system-err>--------------------------------- Captured Err ---------------------------------

</system-err></testcase><testcase classname="tests.integration.models_containers_test.ContainerCollectionTest" name="test_list" time="5.739"><failure message="AssertionError: assert 'docker.io/li...alpine:latest' == 'alpine'&#10;  - alpine&#10;  + docker.io/library/alpine:latest">tests/integration/models_containers_test.py:202: in test_list
    assert container.attrs['Config']['Image'] == 'alpine'
E   AssertionError: assert 'docker.io/li...alpine:latest' == 'alpine'
E     - alpine
E     + docker.io/library/alpine:latest</failure><system-out>--------------------------------- Captured Log ---------------------------------

--------------------------------- Captured Out ---------------------------------

</system-out><system-err>--------------------------------- Captured Err ---------------------------------

</system-err></testcase><testcase classname="tests.integration.models_containers_test.ContainerCollectionTest" name="test_list_sparse" time="5.646"><failure message="AssertionError: assert 'docker.io/li...alpine:latest' == 'alpine'&#10;  - alpine&#10;  + docker.io/library/alpine:latest">tests/integration/models_containers_test.py:220: in test_list_sparse
    assert container.attrs['Image'] == 'alpine'
E   AssertionError: assert 'docker.io/li...alpine:latest' == 'alpine'
E     - alpine
E     + docker.io/library/alpine:latest</failure><system-out>--------------------------------- Captured Log ---------------------------------

--------------------------------- Captured Out ---------------------------------

</system-out><system-err>--------------------------------- Captured Err ---------------------------------

</system-err></testcase><testcase classname="tests.integration.models_containers_test.ContainerCollectionTest" name="test_run" time="6.150" /><testcase classname="tests.integration.models_containers_test.ContainerCollectionTest" name="test_run_detach" time="5.681"><failure message="AssertionError: assert 'docker.io/li...alpine:latest' == 'alpine'&#10;  - alpine&#10;  + docker.io/library/alpine:latest">tests/integration/models_containers_test.py:26: in test_run_detach
    assert container.attrs['Config']['Image'] == "alpine"
E   AssertionError: assert 'docker.io/li...alpine:latest' == 'alpine'
E     - alpine
E     + docker.io/library/alpine:latest</failure><system-out>--------------------------------- Captured Log ---------------------------------

--------------------------------- Captured Out ---------------------------------

</system-out><system-err>--------------------------------- Captured Err ---------------------------------

</system-err></testcase><testcase classname="tests.integration.models_containers_test.ContainerCollectionTest" name="test_run_with_auto_remove" time="8.555" /><testcase classname="tests.integration.models_containers_test.ContainerCollectionTest" name="test_run_with_auto_remove_error" time="8.259"><failure message="docker.errors.NotFound: 404 Client Error for http+docker://localhost/v1.41/containers/1eae984b7eeea63b026bb20317ed6ae5d906a251054a961b32dea3778dd48977/json: Not Found (&quot;no container with name or ID &quot;1eae984b7eeea63b026bb20317ed6ae5d906a251054a961b32dea3778dd48977&quot; found: no such container&quot;)">docker/api/client.py:296: in _raise_for_status
    response.raise_for_status()
../../.virtualenvs/docker-py/lib/python3.10/site-packages/requests/models.py:1021: in raise_for_status
    raise HTTPError(http_error_msg, response=self)
E   requests.exceptions.HTTPError: 404 Client Error: Not Found for url: http+docker://localhost/v1.41/containers/1eae984b7eeea63b026bb20317ed6ae5d906a251054a961b32dea3778dd48977/json

The above exception was the direct cause of the following exception:
tests/integration/models_containers_test.py:139: in test_run_with_auto_remove_error
    client.containers.run(
docker/models/containers.py:873: in run
    out = container.logs(
docker/models/containers.py:307: in logs
    return self.client.api.logs(self.id, **kwargs)
docker/utils/decorators.py:19: in wrapped
    return f(self, resource_id, *args, **kwargs)
docker/api/container.py:886: in logs
    output = self._get_result(container, stream, res)
docker/api/client.py:495: in _get_result
    return self._get_result_tty(stream, res, self._check_is_tty(container))
docker/utils/decorators.py:19: in wrapped
    return f(self, resource_id, *args, **kwargs)
docker/api/client.py:491: in _check_is_tty
    cont = self.inspect_container(container)
docker/utils/decorators.py:19: in wrapped
    return f(self, resource_id, *args, **kwargs)
docker/api/container.py:783: in inspect_container
    return self._result(
docker/api/client.py:302: in _result
    self._raise_for_status(response)
docker/api/client.py:298: in _raise_for_status
    raise create_api_error_from_http_exception(e) from e
docker/errors.py:39: in create_api_error_from_http_exception
    raise cls(e, response=response, explanation=explanation) from e
E   docker.errors.NotFound: 404 Client Error for http+docker://localhost/v1.41/containers/1eae984b7eeea63b026bb20317ed6ae5d906a251054a961b32dea3778dd48977/json: Not Found ("no container with name or ID "1eae984b7eeea63b026bb20317ed6ae5d906a251054a961b32dea3778dd48977" found: no such container")</failure><system-out>--------------------------------- Captured Log ---------------------------------

--------------------------------- Captured Out ---------------------------------

</system-out><system-err>--------------------------------- Captured Err ---------------------------------

</system-err></testcase><testcase classname="tests.integration.models_containers_test.ContainerCollectionTest" name="test_run_with_error" time="7.097" /><testcase classname="tests.integration.models_containers_test.ContainerCollectionTest" name="test_run_with_image_that_does_not_exist" time="7.895" /><testcase classname="tests.integration.models_containers_test.ContainerCollectionTest" name="test_run_with_json_file_driver" time="7.288" /><testcase classname="tests.integration.models_containers_test.ContainerCollectionTest" name="test_run_with_named_volume" time="8.211" /><testcase classname="tests.integration.models_containers_test.ContainerCollectionTest" name="test_run_with_network" time="6.741" /><testcase classname="tests.integration.models_containers_test.ContainerCollectionTest" name="test_run_with_none_driver" time="7.642" /><testcase classname="tests.integration.models_containers_test.ContainerCollectionTest" name="test_run_with_proxy_config" time="7.080" /><testcase classname="tests.integration.models_containers_test.ContainerCollectionTest" name="test_run_with_streamed_logs" time="7.284" /><testcase classname="tests.integration.models_containers_test.ContainerCollectionTest" name="test_run_with_streamed_logs_and_cancel" time="5.000"><failure message="Failed: Timeout &gt;5.0s">tests/integration/base.py:30: in tearDown
    client = docker.from_env(version=TEST_API_VERSION)
docker/client.py:96: in from_env
    return cls(
docker/client.py:45: in __init__
    self.api = APIClient(*args, **kwargs)
docker/api/client.py:197: in __init__
    self._version = self._retrieve_server_version()
docker/api/client.py:214: in _retrieve_server_version
    return self.version(api_version=False)["ApiVersion"]
docker/api/daemon.py:181: in version
    return self._result(self._get(url), json=True)
docker/utils/decorators.py:46: in inner
    return f(self, *args, **kwargs)
docker/api/client.py:251: in _get
    return self.get(url, **self._set_request_timeout(kwargs))
../../.virtualenvs/docker-py/lib/python3.10/site-packages/requests/sessions.py:600: in get
    return self.request("GET", url, **kwargs)
../../.virtualenvs/docker-py/lib/python3.10/site-packages/requests/sessions.py:587: in request
    resp = self.send(prep, **send_kwargs)
../../.virtualenvs/docker-py/lib/python3.10/site-packages/requests/sessions.py:701: in send
    r = adapter.send(request, **kwargs)
../../.virtualenvs/docker-py/lib/python3.10/site-packages/requests/adapters.py:489: in send
    resp = conn.urlopen(
../../.virtualenvs/docker-py/lib/python3.10/site-packages/urllib3/connectionpool.py:703: in urlopen
    httplib_response = self._make_request(
../../.virtualenvs/docker-py/lib/python3.10/site-packages/urllib3/connectionpool.py:449: in _make_request
    six.raise_from(e, None)
../../.virtualenvs/docker-py/lib/python3.10/site-packages/urllib3/connectionpool.py:444: in _make_request
    httplib_response = conn.getresponse()
/usr/lib/python3.10/http/client.py:1374: in getresponse
    response.begin()
/usr/lib/python3.10/http/client.py:318: in begin
    version, status, reason = self._read_status()
/usr/lib/python3.10/http/client.py:279: in _read_status
    line = str(self.fp.readline(_MAXLINE + 1), "iso-8859-1")
/usr/lib/python3.10/socket.py:705: in readinto
    return self._sock.recv_into(b)
E   Failed: Timeout &gt;5.0s</failure><system-out>--------------------------------- Captured Log ---------------------------------

--------------------------------- Captured Out ---------------------------------

</system-out><system-err>--------------------------------- Captured Err ---------------------------------

</system-err></testcase><testcase classname="tests.integration.models_containers_test.ContainerCollectionTest" name="test_run_with_volume" time="8.145" /><testcase classname="tests.integration.models_containers_test.ContainerTest" name="test_commit" time="8.782" /><testcase classname="tests.integration.models_containers_test.ContainerTest" name="test_create_with_volume_driver" time="6.651"><failure message="AssertionError: assert '' == 'foo'&#10;  - foo">tests/integration/models_containers_test.py:456: in test_create_with_volume_driver
    assert container.attrs['HostConfig']['VolumeDriver'] == 'foo'
E   AssertionError: assert '' == 'foo'
E     - foo</failure><system-out>--------------------------------- Captured Log ---------------------------------

--------------------------------- Captured Out ---------------------------------

</system-out><system-err>--------------------------------- Captured Err ---------------------------------

</system-err></testcase><testcase classname="tests.integration.models_containers_test.ContainerTest" name="test_diff" time="7.642"><failure message="AssertionError: assert [{'Kind': 1, ...ath': '/etc'}] == [{'Kind': 1, 'Path': '/test'}]&#10;  Left contains one more item: {'Kind': 0, 'Path': '/etc'}&#10;  Full diff:&#10;  - [{'Kind': 1, 'Path': '/test'}]&#10;  + [{'Kind': 1, 'Path': '/test'}, {'Kind': 0, 'Path': '/etc'}]">tests/integration/models_containers_test.py:251: in test_diff
    assert container.diff() == [{'Path': '/test', 'Kind': 1}]
E   AssertionError: assert [{'Kind': 1, ...ath': '/etc'}] == [{'Kind': 1, 'Path': '/test'}]
E     Left contains one more item: {'Kind': 0, 'Path': '/etc'}
E     Full diff:
E     - [{'Kind': 1, 'Path': '/test'}]
E     + [{'Kind': 1, 'Path': '/test'}, {'Kind': 0, 'Path': '/etc'}]</failure><system-out>--------------------------------- Captured Log ---------------------------------

--------------------------------- Captured Out ---------------------------------

</system-out><system-err>--------------------------------- Captured Err ---------------------------------

</system-err></testcase><testcase classname="tests.integration.models_containers_test.ContainerTest" name="test_exec_run_failed" time="6.848"><failure message="assert 127 == 126">tests/integration/models_containers_test.py:270: in test_exec_run_failed
    assert exec_output[0] == 126
E   assert 127 == 126</failure><system-out>--------------------------------- Captured Log ---------------------------------

--------------------------------- Captured Out ---------------------------------

</system-out><system-err>--------------------------------- Captured Err ---------------------------------

</system-err></testcase><testcase classname="tests.integration.models_containers_test.ContainerTest" name="test_exec_run_success" time="7.197" /><testcase classname="tests.integration.models_containers_test.ContainerTest" name="test_kill" time="7.143" /><testcase classname="tests.integration.models_containers_test.ContainerTest" name="test_logs" time="7.216" /><testcase classname="tests.integration.models_containers_test.ContainerTest" name="test_pause" time="6.884" /><testcase classname="tests.integration.models_containers_test.ContainerTest" name="test_ports_target_list" time="7.248" /><testcase classname="tests.integration.models_containers_test.ContainerTest" name="test_ports_target_none" time="7.063" /><testcase classname="tests.integration.models_containers_test.ContainerTest" name="test_ports_target_tuple" time="7.029" /><testcase classname="tests.integration.models_containers_test.ContainerTest" name="test_remove" time="7.088" /><testcase classname="tests.integration.models_containers_test.ContainerTest" name="test_rename" time="6.776" /><testcase classname="tests.integration.models_containers_test.ContainerTest" name="test_restart" time="17.269" /><testcase classname="tests.integration.models_containers_test.ContainerTest" name="test_start" time="6.872" /><testcase classname="tests.integration.models_containers_test.ContainerTest" name="test_stats" time="6.889" /><testcase classname="tests.integration.models_containers_test.ContainerTest" name="test_stop" time="6.907" /><testcase classname="tests.integration.models_containers_test.ContainerTest" name="test_top" time="6.956"><failure message="AssertionError: assert 'sleep 60' in ['1 root      0:00 sleep 60']">tests/integration/models_containers_test.py:425: in test_top
    assert 'sleep 60' in top['Processes'][0]
E   AssertionError: assert 'sleep 60' in ['1 root      0:00 sleep 60']</failure><system-out>--------------------------------- Captured Log ---------------------------------

--------------------------------- Captured Out ---------------------------------

</system-out><system-err>--------------------------------- Captured Err ---------------------------------

</system-err></testcase><testcase classname="tests.integration.models_containers_test.ContainerTest" name="test_update" time="7.416"><failure message="TypeError: a bytes-like object is required, not 'str'">docker/api/client.py:296: in _raise_for_status
    response.raise_for_status()
../../.virtualenvs/docker-py/lib/python3.10/site-packages/requests/models.py:1021: in raise_for_status
    raise HTTPError(http_error_msg, response=self)
E   requests.exceptions.HTTPError: 404 Client Error: Not Found for url: http+docker://localhost/v1.41/containers/c9a2b69effe0918b219d077295a02af9d16516a39f5d72b5b742a37f8e2526c6/update

During handling of the above exception, another exception occurred:
tests/integration/models_containers_test.py:433: in test_update
    container.update(cpu_shares=3)
docker/models/containers.py:490: in update
    return self.client.api.update_container(self.id, **kwargs)
docker/utils/decorators.py:34: in wrapper
    return f(self, *args, **kwargs)
docker/utils/decorators.py:19: in wrapped
    return f(self, resource_id, *args, **kwargs)
docker/api/container.py:1301: in update_container
    return self._result(res, True)
docker/api/client.py:302: in _result
    self._raise_for_status(response)
docker/api/client.py:298: in _raise_for_status
    raise create_api_error_from_http_exception(e) from e
docker/errors.py:34: in create_api_error_from_http_exception
    if any(fragment in explanation_msg
docker/errors.py:34: in &lt;genexpr&gt;
    if any(fragment in explanation_msg
E   TypeError: a bytes-like object is required, not 'str'</failure><system-out>--------------------------------- Captured Log ---------------------------------

--------------------------------- Captured Out ---------------------------------

</system-out><system-err>--------------------------------- Captured Err ---------------------------------

</system-err></testcase><testcase classname="tests.integration.models_containers_test.ContainerTest" name="test_wait" time="8.900" /><testcase classname="tests.integration.models_images_test.ImageCollectionTest" name="test_build" time="8.511" /><testcase classname="tests.integration.models_images_test.ImageCollectionTest" name="test_build_with_error" time="7.151"><failure message="assert &quot;The command '/bin/sh -c exit 1' returned a non-zero code: 1&quot; in 'docker.errors.BuildError: building at STEP &quot;RUN exit 1&quot;: while running runtime: exit status 1'&#10; +  where 'docker.errors.BuildError: building at STEP &quot;RUN exit 1&quot;: while running runtime: exit status 1' = &lt;bound method ExceptionInfo.exconly of &lt;ExceptionInfo BuildError('building at STEP &quot;RUN exit 1&quot;: while running runtime: exit status 1\n') tblen=2&gt;&gt;()&#10; +    where &lt;bound method ExceptionInfo.exconly of &lt;ExceptionInfo BuildError('building at STEP &quot;RUN exit 1&quot;: while running runtime: exit status 1\n') tblen=2&gt;&gt; = &lt;ExceptionInfo BuildError('building at STEP &quot;RUN exit 1&quot;: while running runtime: exit status 1\n') tblen=2&gt;.exconly">tests/integration/models_images_test.py:30: in test_build_with_error
    assert (
E   assert "The command '/bin/sh -c exit 1' returned a non-zero code: 1" in 'docker.errors.BuildError: building at STEP "RUN exit 1": while running runtime: exit status 1'
E    +  where 'docker.errors.BuildError: building at STEP "RUN exit 1": while running runtime: exit status 1' = &lt;bound method ExceptionInfo.exconly of &lt;ExceptionInfo BuildError('building at STEP "RUN exit 1": while running runtime: exit status 1\n') tblen=2&gt;&gt;()
E    +    where &lt;bound method ExceptionInfo.exconly of &lt;ExceptionInfo BuildError('building at STEP "RUN exit 1": while running runtime: exit status 1\n') tblen=2&gt;&gt; = &lt;ExceptionInfo BuildError('building at STEP "RUN exit 1": while running runtime: exit status 1\n') tblen=2&gt;.exconly</failure><system-out>--------------------------------- Captured Log ---------------------------------

--------------------------------- Captured Out ---------------------------------

</system-out><system-err>--------------------------------- Captured Err ---------------------------------

</system-err></testcase><testcase classname="tests.integration.models_images_test.ImageCollectionTest" name="test_build_with_multiple_success" time="7.731" /><testcase classname="tests.integration.models_images_test.ImageCollectionTest" name="test_build_with_success_build_output" time="7.262" /><testcase classname="tests.integration.models_images_test.ImageCollectionTest" name="test_list" time="9.251" /><testcase classname="tests.integration.models_images_test.ImageCollectionTest" name="test_list_with_repository" time="8.820" /><testcase classname="tests.integration.models_images_test.ImageCollectionTest" name="test_load_error" time="6.354"><failure message="docker.errors.APIError: 500 Server Error for http+docker://localhost/v1.41/images/load: Internal Server Error (&quot;failed to load image: payload does not match any of the supported image formats:&#10; * oci: initializing source oci:/var/tmp/api_load.tar248707198:: open /var/tmp/api_load.tar248707198/index.json: not a directory&#10; * oci-archive: creating temp directory: untarring file &quot;/var/tmp/oci3177840431&quot;: unexpected EOF&#10; * docker-archive: loading tar component manifest.json: unexpected EOF&#10; * dir: open /var/tmp/api_load.tar248707198/manifest.json: not a directory&quot;)">docker/api/client.py:296: in _raise_for_status
    response.raise_for_status()
../../.virtualenvs/docker-py/lib/python3.10/site-packages/requests/models.py:1021: in raise_for_status
    raise HTTPError(http_error_msg, response=self)
E   requests.exceptions.HTTPError: 500 Server Error: Internal Server Error for url: http+docker://localhost/v1.41/images/load

The above exception was the direct cause of the following exception:
tests/integration/models_images_test.py:98: in test_load_error
    client.images.load('abc')
docker/models/images.py:403: in load
    for chunk in resp:
docker/api/client.py:386: in _stream_helper
    yield self._result(response, json=decode)
docker/api/client.py:302: in _result
    self._raise_for_status(response)
docker/api/client.py:298: in _raise_for_status
    raise create_api_error_from_http_exception(e) from e
docker/errors.py:39: in create_api_error_from_http_exception
    raise cls(e, response=response, explanation=explanation) from e
E   docker.errors.APIError: 500 Server Error for http+docker://localhost/v1.41/images/load: Internal Server Error ("failed to load image: payload does not match any of the supported image formats:
E    * oci: initializing source oci:/var/tmp/api_load.tar248707198:: open /var/tmp/api_load.tar248707198/index.json: not a directory
E    * oci-archive: creating temp directory: untarring file "/var/tmp/oci3177840431": unexpected EOF
E    * docker-archive: loading tar component manifest.json: unexpected EOF
E    * dir: open /var/tmp/api_load.tar248707198/manifest.json: not a directory")</failure><system-out>--------------------------------- Captured Log ---------------------------------

--------------------------------- Captured Out ---------------------------------

</system-out><system-err>--------------------------------- Captured Err ---------------------------------

</system-err></testcase><testcase classname="tests.integration.models_images_test.ImageCollectionTest" name="test_pull" time="8.341"><failure message="AssertionError: assert 'alpine:latest' in ['docker.io/library/alpine:latest']">tests/integration/models_images_test.py:71: in test_pull
    assert 'alpine:latest' in image.attrs['RepoTags']
E   AssertionError: assert 'alpine:latest' in ['docker.io/library/alpine:latest']</failure><system-out>--------------------------------- Captured Log ---------------------------------

--------------------------------- Captured Out ---------------------------------

</system-out><system-err>--------------------------------- Captured Err ---------------------------------

</system-err></testcase><testcase classname="tests.integration.models_images_test.ImageCollectionTest" name="test_pull_multiple" time="8.849"><failure message="assert False&#10; +  where False = any([False])">tests/integration/models_images_test.py:91: in test_pull_multiple
    assert any([
E   assert False
E    +  where False = any([False])</failure><system-out>--------------------------------- Captured Log ---------------------------------

--------------------------------- Captured Out ---------------------------------

</system-out><system-err>--------------------------------- Captured Err ---------------------------------

</system-err></testcase><testcase classname="tests.integration.models_images_test.ImageCollectionTest" name="test_pull_with_sha" time="9.520"><failure message="AssertionError: assert 'hello-world@sha256:083de497cff944f969d8499ab94f07134c50bcf5e6b9559b27182d3fa80ce3f7' in ['docker.io/library/hello-world@sha256:083de497cff944f969d8499ab94f07134c50bcf5e6b9559b27182d3fa80ce3f7', 'docker.io/library/hello-world@sha256:8072a54ebb3bc136150e2f2860f00a7bf45f13eeb917cca2430fcd0054c8e51b']">tests/integration/models_images_test.py:85: in test_pull_with_sha
    assert image_ref in image.attrs['RepoDigests']
E   AssertionError: assert 'hello-world@sha256:083de497cff944f969d8499ab94f07134c50bcf5e6b9559b27182d3fa80ce3f7' in ['docker.io/library/hello-world@sha256:083de497cff944f969d8499ab94f07134c50bcf5e6b9559b27182d3fa80ce3f7', 'docker.io/library/hello-world@sha256:8072a54ebb3bc136150e2f2860f00a7bf45f13eeb917cca2430fcd0054c8e51b']</failure><system-out>--------------------------------- Captured Log ---------------------------------

--------------------------------- Captured Out ---------------------------------

</system-out><system-err>--------------------------------- Captured Err ---------------------------------

</system-err></testcase><testcase classname="tests.integration.models_images_test.ImageCollectionTest" name="test_pull_with_tag" time="8.251"><failure message="AssertionError: assert 'alpine:3.10' in ['docker.io/library/alpine:3.10']">tests/integration/models_images_test.py:76: in test_pull_with_tag
    assert 'alpine:3.10' in image.attrs['RepoTags']
E   AssertionError: assert 'alpine:3.10' in ['docker.io/library/alpine:3.10']</failure><system-out>--------------------------------- Captured Log ---------------------------------

--------------------------------- Captured Out ---------------------------------

</system-out><system-err>--------------------------------- Captured Err ---------------------------------

</system-err></testcase><testcase classname="tests.integration.models_images_test.ImageCollectionTest" name="test_save_and_load" time="6.594" /><testcase classname="tests.integration.models_images_test.ImageCollectionTest" name="test_save_and_load_repo_name" time="6.331"><failure message="docker.errors.InvalidArgument: dockerpytest_87de41fc4a8a43e3:latest is not a valid tag for this image">tests/integration/models_images_test.py:122: in test_save_and_load_repo_name
    stream = image.save(named=f'{additional_tag}:latest')
docker/models/images.py:117: in save
    raise InvalidArgument(
E   docker.errors.InvalidArgument: dockerpytest_87de41fc4a8a43e3:latest is not a valid tag for this image</failure><system-out>--------------------------------- Captured Log ---------------------------------

--------------------------------- Captured Out ---------------------------------

</system-out><system-err>--------------------------------- Captured Err ---------------------------------

</system-err></testcase><testcase classname="tests.integration.models_images_test.ImageCollectionTest" name="test_save_name_error" time="6.319" /><testcase classname="tests.integration.models_images_test.ImageTest" name="test_tag_and_remove" time="7.910" /><testcase classname="tests.integration.models_networks_test.NetworkCollectionTest" name="test_create" time="5.742" /><testcase classname="tests.integration.models_networks_test.NetworkCollectionTest" name="test_get" time="5.520" /><testcase classname="tests.integration.models_networks_test.NetworkCollectionTest" name="test_list_remove" time="5.586" /><testcase classname="tests.integration.models_networks_test.NetworkTest" name="test_connect_disconnect" time="6.795" /><testcase classname="tests.integration.models_resources_test.ModelTest" name="test_reload" time="6.260" /><testcase classname="tests.integration.models_volumes_test.VolumesTest" name="test_create_get" time="5.558" /><testcase classname="tests.integration.models_volumes_test.VolumesTest" name="test_list_remove" time="5.765" /><testcase classname="tests.integration.regression_test.TestRegressions" name="test_443_handle_nonchunked_response_in_stream" time="10.046"><skipped type="pytest.xfail" message="Docker API always returns chunked resp" /></testcase><testcase classname="tests.integration.regression_test.TestRegressions" name="test_542_truncate_ids_client_side" time="8.691" /><testcase classname="tests.integration.regression_test.TestRegressions" name="test_647_support_doubleslash_in_image_names" time="8.665" /><testcase classname="tests.integration.regression_test.TestRegressions" name="test_649_handle_timeout_value_none" time="8.860" /><testcase classname="tests.integration.regression_test.TestRegressions" name="test_715_handle_user_param_as_int_value" time="8.378" /><testcase classname="tests.integration.regression_test.TestRegressions" name="test_792_explicit_port_protocol" time="8.240" /><testcase classname="tests.integration.credentials.utils_test" name="test_create_environment_dict" time="0.007" /></testsuite></testsuites>