<?xml version="1.0" encoding="utf-8"?><testsuites><testsuite name="docker-py" errors="5" failures="80" skipped="5" tests="266" time="2219.551" timestamp="2021-10-29T12:12:19.536445" hostname="acnologia"><testcase classname="tests.integration.api_build_test.BuildTest" name="test_build_container_with_target" time="17.443" /><testcase classname="tests.integration.api_build_test.BuildTest" name="test_build_from_stringio" time="8.270" /><testcase classname="tests.integration.api_build_test.BuildTest" name="test_build_gzip_custom_encoding" time="8.165" /><testcase classname="tests.integration.api_build_test.BuildTest" name="test_build_gzip_encoding" time="11.438" /><testcase classname="tests.integration.api_build_test.BuildTest" name="test_build_in_context_abs_dockerfile" time="11.628" /><testcase classname="tests.integration.api_build_test.BuildTest" name="test_build_in_context_dockerfile" time="11.868" /><testcase classname="tests.integration.api_build_test.BuildTest" name="test_build_in_context_nested_dockerfile" time="9.941" /><testcase classname="tests.integration.api_build_test.BuildTest" name="test_build_invalid_platform" time="10.813" /><testcase classname="tests.integration.api_build_test.BuildTest" name="test_build_isolation" time="9.052" /><testcase classname="tests.integration.api_build_test.BuildTest" name="test_build_labels" time="8.768"><failure message="AssertionError: assert {'io.buildah.... 'test': 'OK'} == {'test': 'OK'}&#10;  Omitting 1 identical items, use -vv to show&#10;  Left contains 1 more item:&#10;  {'io.buildah.version': '1.23.1'}&#10;  Full diff:&#10;  - {'test': 'OK'}&#10;  + {'io.buildah.version': '1.23.1', 'test': 'OK'}">tests/integration/api_build_test.py:211: in test_build_labels
    assert info['Config']['Labels'] == labels
E   AssertionError: assert {'io.buildah.... 'test': 'OK'} == {'test': 'OK'}
E     Omitting 1 identical items, use -vv to show
E     Left contains 1 more item:
E     {'io.buildah.version': '1.23.1'}
E     Full diff:
E     - {'test': 'OK'}
E     + {'io.buildah.version': '1.23.1', 'test': 'OK'}</failure><system-out>--------------------------------- Captured Log ---------------------------------

--------------------------------- Captured Out ---------------------------------

</system-out><system-err>--------------------------------- Captured Err ---------------------------------

</system-err></testcase><testcase classname="tests.integration.api_build_test.BuildTest" name="test_build_out_of_context_dockerfile" time="10.797" /><testcase classname="tests.integration.api_build_test.BuildTest" name="test_build_shmsize" time="8.812" /><testcase classname="tests.integration.api_build_test.BuildTest" name="test_build_squash" time="15.552"><failure message="AssertionError: assert 2 == 4&#10;  +2&#10;  -4">tests/integration/api_build_test.py:370: in test_build_squash
    assert len(non_squashed['RootFS']['Layers']) == 4
E   AssertionError: assert 2 == 4
E     +2
E     -4</failure><system-out>--------------------------------- Captured Log ---------------------------------

--------------------------------- Captured Out ---------------------------------

</system-out><system-err>--------------------------------- Captured Err ---------------------------------

</system-err></testcase><testcase classname="tests.integration.api_build_test.BuildTest" name="test_build_stderr_data" time="9.378"><failure message="AssertionError: assert False&#10; +  where False = any([False, False, False, False, False, False, ...])">tests/integration/api_build_test.py:390: in test_build_stderr_data
    assert any([line == expected for line in lines])
E   AssertionError: assert False
E    +  where False = any([False, False, False, False, False, False, ...])</failure><system-out>--------------------------------- Captured Log ---------------------------------

--------------------------------- Captured Out ---------------------------------

</system-out><system-err>--------------------------------- Captured Err ---------------------------------

</system-err></testcase><testcase classname="tests.integration.api_build_test.BuildTest" name="test_build_streaming" time="8.927" /><testcase classname="tests.integration.api_build_test.BuildTest" name="test_build_with_buildargs" time="9.041" /><testcase classname="tests.integration.api_build_test.BuildTest" name="test_build_with_cache_from" time="12.026"><failure message="AssertionError: assert 0 == 3&#10;  +0&#10;  -3">tests/integration/api_build_test.py:236: in test_build_with_cache_from
    assert counter == 3
E   AssertionError: assert 0 == 3
E     +0
E     -3</failure><system-out>--------------------------------- Captured Log ---------------------------------

--------------------------------- Captured Out ---------------------------------

</system-out><system-err>--------------------------------- Captured Err ---------------------------------

</system-err></testcase><testcase classname="tests.integration.api_build_test.BuildTest" name="test_build_with_dockerfile_empty_lines" time="7.975" /><testcase classname="tests.integration.api_build_test.BuildTest" name="test_build_with_dockerignore" time="9.899" /><testcase classname="tests.integration.api_build_test.BuildTest" name="test_build_with_extra_hosts" time="8.305"><failure message="docker.errors.APIError: 400 Client Error for http+docker://localhost/v1.40/build?t=dockerpytest_extrahost_build&amp;q=False&amp;nocache=False&amp;rm=False&amp;forcerm=False&amp;pull=False&amp;extrahosts=extrahost.local.test%3A127.0.0.1&amp;extrahosts=hello.world.test%3A127.0.0.1: Bad Request (&quot;failed to parse query parameter 'extrahosts': &quot;hello.world.test:127.0.0.1&quot;: invalid character 'h' looking for beginning of value&quot;)">docker/api/client.py:296: in _raise_for_status
    response.raise_for_status()
../../.virtualenvs/docker-py/lib/python3.9/site-packages/requests/models.py:953: in raise_for_status
    raise HTTPError(http_error_msg, response=self)
E   requests.exceptions.HTTPError: 400 Client Error: Bad Request for url: http+docker://localhost/v1.40/build?t=dockerpytest_extrahost_build&amp;q=False&amp;nocache=False&amp;rm=False&amp;forcerm=False&amp;pull=False&amp;extrahosts=extrahost.local.test%3A127.0.0.1&amp;extrahosts=hello.world.test%3A127.0.0.1

During handling of the above exception, another exception occurred:
tests/integration/api_build_test.py:332: in test_build_with_extra_hosts
    for chunk in stream:
docker/api/client.py:386: in _stream_helper
    yield self._result(response, json=decode)
docker/api/client.py:302: in _result
    self._raise_for_status(response)
docker/api/client.py:298: in _raise_for_status
    raise create_api_error_from_http_exception(e)
docker/errors.py:31: in create_api_error_from_http_exception
    raise cls(e, response=response, explanation=explanation)
E   docker.errors.APIError: 400 Client Error for http+docker://localhost/v1.40/build?t=dockerpytest_extrahost_build&amp;q=False&amp;nocache=False&amp;rm=False&amp;forcerm=False&amp;pull=False&amp;extrahosts=extrahost.local.test%3A127.0.0.1&amp;extrahosts=hello.world.test%3A127.0.0.1: Bad Request ("failed to parse query parameter 'extrahosts': "hello.world.test:127.0.0.1": invalid character 'h' looking for beginning of value")</failure><system-out>--------------------------------- Captured Log ---------------------------------

--------------------------------- Captured Out ---------------------------------

</system-out><system-err>--------------------------------- Captured Err ---------------------------------

</system-err></testcase><testcase classname="tests.integration.api_build_test.BuildTest" name="test_build_with_network_mode" time="11.880"><failure message="docker.errors.ImageNotFound: 404 Client Error for http+docker://localhost/v1.40/images/dockerpytest_customnetbuild/json: Not Found (&quot;failed to find image dockerpytest_customnetbuild: dockerpytest_customnetbuild: No such image&quot;)">docker/api/client.py:296: in _raise_for_status
    response.raise_for_status()
../../.virtualenvs/docker-py/lib/python3.9/site-packages/requests/models.py:953: in raise_for_status
    raise HTTPError(http_error_msg, response=self)
E   requests.exceptions.HTTPError: 404 Client Error: Not Found for url: http+docker://localhost/v1.40/images/dockerpytest_customnetbuild/json

During handling of the above exception, another exception occurred:
tests/integration/api_build_test.py:297: in test_build_with_network_mode
    assert self.client.inspect_image('dockerpytest_customnetbuild')
docker/utils/decorators.py:19: in wrapped
    return f(self, resource_id, *args, **kwargs)
docker/api/image.py:251: in inspect_image
    return self._result(
docker/api/client.py:302: in _result
    self._raise_for_status(response)
docker/api/client.py:298: in _raise_for_status
    raise create_api_error_from_http_exception(e)
docker/errors.py:31: in create_api_error_from_http_exception
    raise cls(e, response=response, explanation=explanation)
E   docker.errors.ImageNotFound: 404 Client Error for http+docker://localhost/v1.40/images/dockerpytest_customnetbuild/json: Not Found ("failed to find image dockerpytest_customnetbuild: dockerpytest_customnetbuild: No such image")</failure><system-out>--------------------------------- Captured Log ---------------------------------

--------------------------------- Captured Out ---------------------------------

</system-out><system-err>--------------------------------- Captured Err ---------------------------------

</system-err></testcase><testcase classname="tests.integration.api_build_test.BuildTest" name="test_build_with_proxy" time="8.382" /><testcase classname="tests.integration.api_build_test.BuildTest" name="test_build_with_proxy_and_buildargs" time="8.326" /><testcase classname="tests.integration.api_build_test.BuildTest" name="test_prune_builds" time="10.522"><skipped type="pytest.xfail" message="Currently fails on 18.09: https://github.com/moby/moby/issues/37920" /></testcase><testcase classname="tests.integration.api_client_test.InformationTest" name="test_info" time="10.976" /><testcase classname="tests.integration.api_client_test.InformationTest" name="test_version" time="11.325" /><testcase classname="tests.integration.api_client_test.AutoDetectVersionTest" name="test_client_init" time="8.512" /><testcase classname="tests.integration.api_client_test.ConnectionTimeoutTest" name="test_timeout" time="0.505" /><testcase classname="tests.integration.api_client_test.UnixconnTest" name="test_resource_warnings" time="2.934" /><testcase classname="tests.integration.api_container_test.ListContainersTest" name="test_list_containers" time="9.762" /><testcase classname="tests.integration.api_container_test.CreateContainerTest" name="test_create" time="9.110" /><testcase classname="tests.integration.api_container_test.CreateContainerTest" name="test_create_container_with_volumes_from" time="11.769" /><testcase classname="tests.integration.api_container_test.CreateContainerTest" name="test_create_with_auto_remove" time="11.184" /><testcase classname="tests.integration.api_container_test.CreateContainerTest" name="test_create_with_cpu_rt_options" time="10.351" /><testcase classname="tests.integration.api_container_test.CreateContainerTest" name="test_create_with_device_cgroup_rules" time="9.770"><failure message="AssertionError: assert None == ['c 7:128 rwm']&#10;  +None&#10;  -['c 7:128 rwm']">tests/integration/api_container_test.py:470: in test_create_with_device_cgroup_rules
    assert config['HostConfig']['DeviceCgroupRules'] == [rule]
E   AssertionError: assert None == ['c 7:128 rwm']
E     +None
E     -['c 7:128 rwm']</failure><system-out>--------------------------------- Captured Log ---------------------------------

--------------------------------- Captured Out ---------------------------------

</system-out><system-err>--------------------------------- Captured Err ---------------------------------

</system-err></testcase><testcase classname="tests.integration.api_container_test.CreateContainerTest" name="test_create_with_environment_variable_no_value" time="9.258"><failure message="AssertionError: assert 'Foo' in ['PATH=/usr/local/sbin:/usr/local/bin:/usr/sbin:/usr/bin:/sbin:/bin', 'TERM=xterm', 'container=podman', 'PATH=/usr/local/sbin:/usr/local/bin:/usr/sbin:/usr/bin:/sbin:/bin', 'TERM=xterm', 'Other=one', ...]">tests/integration/api_container_test.py:366: in test_create_with_environment_variable_no_value
    assert 'Foo' in config['Config']['Env']
E   AssertionError: assert 'Foo' in ['PATH=/usr/local/sbin:/usr/local/bin:/usr/sbin:/usr/bin:/sbin:/bin', 'TERM=xterm', 'container=podman', 'PATH=/usr/local/sbin:/usr/local/bin:/usr/sbin:/usr/bin:/sbin:/bin', 'TERM=xterm', 'Other=one', ...]</failure><system-out>--------------------------------- Captured Log ---------------------------------

--------------------------------- Captured Out ---------------------------------

</system-out><system-err>--------------------------------- Captured Err ---------------------------------

</system-err></testcase><testcase classname="tests.integration.api_container_test.CreateContainerTest" name="test_create_with_host_pid_mode" time="9.500" /><testcase classname="tests.integration.api_container_test.CreateContainerTest" name="test_create_with_init" time="9.279" /><testcase classname="tests.integration.api_container_test.CreateContainerTest" name="test_create_with_isolation" time="9.490"><failure message="AssertionError: assert '' == 'default'&#10;  - default">tests/integration/api_container_test.py:395: in test_create_with_isolation
    assert config['HostConfig']['Isolation'] == 'default'
E   AssertionError: assert '' == 'default'
E     - default</failure><system-out>--------------------------------- Captured Log ---------------------------------

--------------------------------- Captured Out ---------------------------------

</system-out><system-err>--------------------------------- Captured Err ---------------------------------

</system-err></testcase><testcase classname="tests.integration.api_container_test.CreateContainerTest" name="test_create_with_links" time="9.687"><failure message="docker.errors.APIError: 400 Client Error for http+docker://localhost/v1.40/containers/create: Bad Request (&quot;bad parameter: Link is not supported&quot;)">docker/api/client.py:296: in _raise_for_status
    response.raise_for_status()
../../.virtualenvs/docker-py/lib/python3.9/site-packages/requests/models.py:953: in raise_for_status
    raise HTTPError(http_error_msg, response=self)
E   requests.exceptions.HTTPError: 400 Client Error: Bad Request for url: http+docker://localhost/v1.40/containers/create

During handling of the above exception, another exception occurred:
tests/integration/api_container_test.py:95: in test_create_with_links
    res2 = self.client.create_container(
docker/api/container.py:428: in create_container
    return self.create_container_from_config(config, name)
docker/api/container.py:439: in create_container_from_config
    return self._result(res, True)
docker/api/client.py:302: in _result
    self._raise_for_status(response)
docker/api/client.py:298: in _raise_for_status
    raise create_api_error_from_http_exception(e)
docker/errors.py:31: in create_api_error_from_http_exception
    raise cls(e, response=response, explanation=explanation)
E   docker.errors.APIError: 400 Client Error for http+docker://localhost/v1.40/containers/create: Bad Request ("bad parameter: Link is not supported")</failure><system-out>--------------------------------- Captured Log ---------------------------------

--------------------------------- Captured Out ---------------------------------

</system-out><system-err>--------------------------------- Captured Err ---------------------------------

</system-err></testcase><testcase classname="tests.integration.api_container_test.CreateContainerTest" name="test_create_with_mac_address" time="8.756"><failure message="AssertionError: assert '02:42:ac:11:00:0a' == '5e:86:2e:4e:f0:9b'&#10;  - 5e:86:2e:4e:f0:9b&#10;  + 02:42:ac:11:00:0a">tests/integration/api_container_test.py:214: in test_create_with_mac_address
    assert mac_address_expected == res['NetworkSettings']['MacAddress']
E   AssertionError: assert '02:42:ac:11:00:0a' == '5e:86:2e:4e:f0:9b'
E     - 5e:86:2e:4e:f0:9b
E     + 02:42:ac:11:00:0a</failure><system-out>--------------------------------- Captured Log ---------------------------------

--------------------------------- Captured Out ---------------------------------

</system-out><system-err>--------------------------------- Captured Err ---------------------------------

</system-err></testcase><testcase classname="tests.integration.api_container_test.CreateContainerTest" name="test_create_with_memory_constraints_with_int" time="8.667" /><testcase classname="tests.integration.api_container_test.CreateContainerTest" name="test_create_with_memory_constraints_with_str" time="8.673" /><testcase classname="tests.integration.api_container_test.CreateContainerTest" name="test_create_with_restart_policy" time="10.497"><failure message="Failed: DID NOT RAISE &lt;class 'docker.errors.APIError'&gt;">tests/integration/api_container_test.py:124: in test_create_with_restart_policy
    self.client.remove_container(id)
E   Failed: DID NOT RAISE &lt;class 'docker.errors.APIError'&gt;</failure><system-out>--------------------------------- Captured Log ---------------------------------

--------------------------------- Captured Out ---------------------------------

</system-out><system-err>--------------------------------- Captured Err ---------------------------------

</system-err></testcase><testcase classname="tests.integration.api_container_test.CreateContainerTest" name="test_create_with_stop_timeout" time="8.213" /><testcase classname="tests.integration.api_container_test.CreateContainerTest" name="test_create_with_storage_opt" time="8.180"><skipped type="pytest.xfail" message="Not supported on most drivers" /></testcase><testcase classname="tests.integration.api_container_test.CreateContainerTest" name="test_create_with_tmpfs" time="8.224"><failure message="AssertionError: assert {'/tmp1': 'si...ev,tmpcopyup'} == {'/tmp1': 'size=3M'}&#10;  Differing items:&#10;  {'/tmp1': 'size=3M,rw,rprivate,nosuid,nodev,tmpcopyup'} != {'/tmp1': 'size=3M'}&#10;  Full diff:&#10;  - {'/tmp1': 'size=3M'}&#10;  + {'/tmp1': 'size=3M,rw,rprivate,nosuid,nodev,tmpcopyup'}">tests/integration/api_container_test.py:384: in test_create_with_tmpfs
    assert config['HostConfig']['Tmpfs'] == tmpfs
E   AssertionError: assert {'/tmp1': 'si...ev,tmpcopyup'} == {'/tmp1': 'size=3M'}
E     Differing items:
E     {'/tmp1': 'size=3M,rw,rprivate,nosuid,nodev,tmpcopyup'} != {'/tmp1': 'size=3M'}
E     Full diff:
E     - {'/tmp1': 'size=3M'}
E     + {'/tmp1': 'size=3M,rw,rprivate,nosuid,nodev,tmpcopyup'}</failure><system-out>--------------------------------- Captured Log ---------------------------------

--------------------------------- Captured Out ---------------------------------

</system-out><system-err>--------------------------------- Captured Err ---------------------------------

</system-err></testcase><testcase classname="tests.integration.api_container_test.CreateContainerTest" name="test_create_with_uts_mode" time="8.339" /><testcase classname="tests.integration.api_container_test.CreateContainerTest" name="test_group_id_ints" time="8.979" /><testcase classname="tests.integration.api_container_test.CreateContainerTest" name="test_group_id_strings" time="8.659" /><testcase classname="tests.integration.api_container_test.CreateContainerTest" name="test_invalid_log_driver_raises_exception" time="8.253"><failure message="AssertionError: assert 'container create: error running container create option: invalid log driver: invalid argument' in [&quot;logger: no log driver named 'asdf' is registered&quot;, 'error looking up logging plugin asdf: plugin &quot;asdf&quot; not found']&#10; +  where 'container create: error running container create option: invalid log driver: invalid argument' = APIError(HTTPError('500 Server Error: Internal Server Error for url: http+docker://localhost/v1.40/containers/create')).explanation&#10; +    where APIError(HTTPError('500 Server Error: Internal Server Error for url: http+docker://localhost/v1.40/containers/create')) = &lt;ExceptionInfo APIError(HTTPError('500 Server Error: Internal Server Error for url: http+docker://localhost/v1.40/containers/create')) tblen=6&gt;.value">tests/integration/api_container_test.py:286: in test_invalid_log_driver_raises_exception
    assert excinfo.value.explanation in expected_msgs
E   AssertionError: assert 'container create: error running container create option: invalid log driver: invalid argument' in ["logger: no log driver named 'asdf' is registered", 'error looking up logging plugin asdf: plugin "asdf" not found']
E    +  where 'container create: error running container create option: invalid log driver: invalid argument' = APIError(HTTPError('500 Server Error: Internal Server Error for url: http+docker://localhost/v1.40/containers/create')).explanation
E    +    where APIError(HTTPError('500 Server Error: Internal Server Error for url: http+docker://localhost/v1.40/containers/create')) = &lt;ExceptionInfo APIError(HTTPError('500 Server Error: Internal Server Error for url: http+docker://localhost/v1.40/containers/create')) tblen=6&gt;.value</failure><system-out>--------------------------------- Captured Log ---------------------------------

--------------------------------- Captured Out ---------------------------------

</system-out><system-err>--------------------------------- Captured Err ---------------------------------

</system-err></testcase><testcase classname="tests.integration.api_container_test.CreateContainerTest" name="test_valid_log_driver_and_log_opt" time="8.516"><failure message="AssertionError: assert None == {'max-file': '100'}&#10;  +None&#10;  -{'max-file': '100'}">tests/integration/api_container_test.py:265: in test_valid_log_driver_and_log_opt
    assert container_log_config['Config'] == log_config.config
E   AssertionError: assert None == {'max-file': '100'}
E     +None
E     -{'max-file': '100'}</failure><system-out>--------------------------------- Captured Log ---------------------------------

--------------------------------- Captured Out ---------------------------------

</system-out><system-err>--------------------------------- Captured Err ---------------------------------

</system-err></testcase><testcase classname="tests.integration.api_container_test.CreateContainerTest" name="test_valid_no_config_specified" time="8.577"><failure message="AssertionError: assert None == {}&#10;  +None&#10;  -{}">tests/integration/api_container_test.py:324: in test_valid_no_config_specified
    assert container_log_config['Config'] == {}
E   AssertionError: assert None == {}
E     +None
E     -{}</failure><system-out>--------------------------------- Captured Log ---------------------------------

--------------------------------- Captured Out ---------------------------------

</system-out><system-err>--------------------------------- Captured Err ---------------------------------

</system-err></testcase><testcase classname="tests.integration.api_container_test.CreateContainerTest" name="test_valid_no_log_driver_specified" time="8.542"><failure message="AssertionError: assert 'journald' == 'json-file'&#10;  - json-file&#10;  + journald">tests/integration/api_container_test.py:304: in test_valid_no_log_driver_specified
    assert container_log_config['Type'] == "json-file"
E   AssertionError: assert 'journald' == 'json-file'
E     - json-file
E     + journald</failure><system-out>--------------------------------- Captured Log ---------------------------------

--------------------------------- Captured Out ---------------------------------

</system-out><system-err>--------------------------------- Captured Err ---------------------------------

</system-err></testcase><testcase classname="tests.integration.api_container_test.VolumeBindTest" name="test_create_with_binds_ro" time="8.940" /><testcase classname="tests.integration.api_container_test.VolumeBindTest" name="test_create_with_binds_rw" time="8.616" /><testcase classname="tests.integration.api_container_test.VolumeBindTest" name="test_create_with_mounts" time="8.970" /><testcase classname="tests.integration.api_container_test.VolumeBindTest" name="test_create_with_mounts_ro" time="8.979" /><testcase classname="tests.integration.api_container_test.VolumeBindTest" name="test_create_with_volume_mount" time="8.604"><failure message="AssertionError: assert False is True">tests/integration/api_container_test.py:587: in test_create_with_volume_mount
    assert mount_data['RW'] is True
E   AssertionError: assert False is True</failure><system-out>--------------------------------- Captured Log ---------------------------------

--------------------------------- Captured Out ---------------------------------

</system-out><system-err>--------------------------------- Captured Err ---------------------------------

</system-err></testcase><testcase classname="tests.integration.api_container_test.ArchiveTest" name="test_copy_directory_to_container" time="8.668" /><testcase classname="tests.integration.api_container_test.ArchiveTest" name="test_copy_file_to_container" time="8.992" /><testcase classname="tests.integration.api_container_test.ArchiveTest" name="test_get_file_archive_from_container" time="9.146" /><testcase classname="tests.integration.api_container_test.ArchiveTest" name="test_get_file_stat_from_container" time="9.593" /><testcase classname="tests.integration.api_container_test.RenameContainerTest" name="test_rename_container" time="11.168" /><testcase classname="tests.integration.api_container_test.StartContainerTest" name="test_run_shlex_commands" time="11.778" /><testcase classname="tests.integration.api_container_test.StartContainerTest" name="test_start_container" time="8.761" /><testcase classname="tests.integration.api_container_test.StartContainerTest" name="test_start_container_with_dict_instead_of_id" time="8.740" /><testcase classname="tests.integration.api_container_test.WaitTest" name="test_wait" time="11.569" /><testcase classname="tests.integration.api_container_test.WaitTest" name="test_wait_with_condition" time="13.492" /><testcase classname="tests.integration.api_container_test.WaitTest" name="test_wait_with_dict_instead_of_id" time="11.557" /><testcase classname="tests.integration.api_container_test.LogsTest" name="test_logs" time="8.706" /><testcase classname="tests.integration.api_container_test.LogsTest" name="test_logs_streaming_and_follow" time="8.764" /><testcase classname="tests.integration.api_container_test.LogsTest" name="test_logs_streaming_and_follow_and_cancel" time="5.000"><failure message="Failed: Timeout &gt;5.0s">tests/integration/base.py:80: in setUp
    self.is_podman = self._is_podman(self.client)
tests/integration/base.py:103: in _is_podman
    in client.version()['Components']
docker/api/daemon.py:181: in version
    return self._result(self._get(url), json=True)
docker/utils/decorators.py:46: in inner
    return f(self, *args, **kwargs)
docker/api/client.py:251: in _get
    return self.get(url, **self._set_request_timeout(kwargs))
../../.virtualenvs/docker-py/lib/python3.9/site-packages/requests/sessions.py:555: in get
    return self.request('GET', url, **kwargs)
../../.virtualenvs/docker-py/lib/python3.9/site-packages/requests/sessions.py:542: in request
    resp = self.send(prep, **send_kwargs)
../../.virtualenvs/docker-py/lib/python3.9/site-packages/requests/sessions.py:655: in send
    r = adapter.send(request, **kwargs)
../../.virtualenvs/docker-py/lib/python3.9/site-packages/requests/adapters.py:439: in send
    resp = conn.urlopen(
../../.virtualenvs/docker-py/lib/python3.9/site-packages/urllib3/connectionpool.py:699: in urlopen
    httplib_response = self._make_request(
../../.virtualenvs/docker-py/lib/python3.9/site-packages/urllib3/connectionpool.py:445: in _make_request
    six.raise_from(e, None)
../../.virtualenvs/docker-py/lib/python3.9/site-packages/urllib3/connectionpool.py:440: in _make_request
    httplib_response = conn.getresponse()
/usr/lib/python3.9/http/client.py:1371: in getresponse
    response.begin()
/usr/lib/python3.9/http/client.py:319: in begin
    version, status, reason = self._read_status()
/usr/lib/python3.9/http/client.py:280: in _read_status
    line = str(self.fp.readline(_MAXLINE + 1), "iso-8859-1")
/usr/lib/python3.9/socket.py:704: in readinto
    return self._sock.recv_into(b)
E   Failed: Timeout &gt;5.0s</failure><system-out>--------------------------------- Captured Log ---------------------------------

--------------------------------- Captured Out ---------------------------------

</system-out><system-err>--------------------------------- Captured Err ---------------------------------

</system-err></testcase><testcase classname="tests.integration.api_container_test.LogsTest" name="test_logs_tail_option" time="8.790" /><testcase classname="tests.integration.api_container_test.LogsTest" name="test_logs_with_dict_instead_of_id" time="8.709" /><testcase classname="tests.integration.api_container_test.LogsTest" name="test_logs_with_tail_0" time="8.808" /><testcase classname="tests.integration.api_container_test.LogsTest" name="test_logs_with_until" time="8.850" /><testcase classname="tests.integration.api_container_test.DiffTest" name="test_diff" time="8.885" /><testcase classname="tests.integration.api_container_test.DiffTest" name="test_diff_with_dict_instead_of_id" time="9.243" /><testcase classname="tests.integration.api_container_test.StopTest" name="test_stop" time="11.146" /><testcase classname="tests.integration.api_container_test.StopTest" name="test_stop_with_dict_instead_of_id" time="11.046" /><testcase classname="tests.integration.api_container_test.KillTest" name="test_kill" time="8.675" /><testcase classname="tests.integration.api_container_test.KillTest" name="test_kill_with_dict_instead_of_id" time="8.928" /><testcase classname="tests.integration.api_container_test.KillTest" name="test_kill_with_signal" time="8.710" /><testcase classname="tests.integration.api_container_test.KillTest" name="test_kill_with_signal_integer" time="9.217" /><testcase classname="tests.integration.api_container_test.KillTest" name="test_kill_with_signal_name" time="8.786" /><testcase classname="tests.integration.api_container_test.PortTest" name="test_port" time="8.626"><failure message="docker.errors.APIError: 500 Server Error for http+docker://localhost/v1.40/containers/9ef9a2af46f85a98cd5a9c0680da7c8a5b3dfc17b7fb58c5086949e3893b84a7/start: Internal Server Error (&quot;could not find &quot;rootlessport&quot; in one of [/usr/local/libexec/podman /usr/local/lib/podman /usr/libexec/podman /usr/lib/podman]&quot;)">docker/api/client.py:296: in _raise_for_status
    response.raise_for_status()
../../.virtualenvs/docker-py/lib/python3.9/site-packages/requests/models.py:953: in raise_for_status
    raise HTTPError(http_error_msg, response=self)
E   requests.exceptions.HTTPError: 500 Server Error: Internal Server Error for url: http+docker://localhost/v1.40/containers/9ef9a2af46f85a98cd5a9c0680da7c8a5b3dfc17b7fb58c5086949e3893b84a7/start

During handling of the above exception, another exception occurred:
tests/integration/api_container_test.py:1068: in test_port
    self.client.start(container)
docker/utils/decorators.py:19: in wrapped
    return f(self, resource_id, *args, **kwargs)
docker/api/container.py:1109: in start
    self._raise_for_status(res)
docker/api/client.py:298: in _raise_for_status
    raise create_api_error_from_http_exception(e)
docker/errors.py:31: in create_api_error_from_http_exception
    raise cls(e, response=response, explanation=explanation)
E   docker.errors.APIError: 500 Server Error for http+docker://localhost/v1.40/containers/9ef9a2af46f85a98cd5a9c0680da7c8a5b3dfc17b7fb58c5086949e3893b84a7/start: Internal Server Error ("could not find "rootlessport" in one of [/usr/local/libexec/podman /usr/local/lib/podman /usr/libexec/podman /usr/lib/podman]")</failure><system-out>--------------------------------- Captured Log ---------------------------------

--------------------------------- Captured Out ---------------------------------

</system-out><system-err>--------------------------------- Captured Err ---------------------------------

</system-err></testcase><testcase classname="tests.integration.api_container_test.ContainerTopTest" name="test_top" time="8.974"><skipped type="pytest.xfail" message="Output of docker top depends on host distro, and is not formalized." /></testcase><testcase classname="tests.integration.api_container_test.ContainerTopTest" name="test_top_with_psargs" time="9.139"><skipped type="pytest.xfail" message="Output of docker top depends on host distro, and is not formalized." /></testcase><testcase classname="tests.integration.api_container_test.RestartContainerTest" name="test_restart" time="11.469" /><testcase classname="tests.integration.api_container_test.RestartContainerTest" name="test_restart_with_dict_instead_of_id" time="11.198" /><testcase classname="tests.integration.api_container_test.RestartContainerTest" name="test_restart_with_low_timeout" time="11.910" /><testcase classname="tests.integration.api_container_test.RemoveContainerTest" name="test_remove" time="8.865" /><testcase classname="tests.integration.api_container_test.RemoveContainerTest" name="test_remove_with_dict_instead_of_id" time="8.867" /><testcase classname="tests.integration.api_container_test.AttachContainerTest" name="test_attach_no_stream" time="8.806"><failure message="docker.errors.APIError: 500 Server Error for http+docker://localhost/v1.40/containers/eaee64f957d1cbda39295879db444ca744ba0f84447ac4f427525fb2241dd4e0/attach?logs=1&amp;stdout=1&amp;stderr=1&amp;stream=0: Internal Server Error (&quot;can only attach to created or running containers - currently in state stopped: container state improper&quot;)">docker/api/client.py:296: in _raise_for_status
    response.raise_for_status()
../../.virtualenvs/docker-py/lib/python3.9/site-packages/requests/models.py:953: in raise_for_status
    raise HTTPError(http_error_msg, response=self)
E   requests.exceptions.HTTPError: 500 Server Error: Internal Server Error for url: http+docker://localhost/v1.40/containers/eaee64f957d1cbda39295879db444ca744ba0f84447ac4f427525fb2241dd4e0/attach?logs=1&amp;stdout=1&amp;stderr=1&amp;stream=0

During handling of the above exception, another exception occurred:
tests/integration/api_container_test.py:1229: in test_attach_no_stream
    output = self.client.attach(container, stream=False, logs=True)
docker/utils/decorators.py:19: in wrapped
    return f(self, resource_id, *args, **kwargs)
docker/api/container.py:60: in attach
    output = self._read_from_socket(
docker/api/client.py:441: in _read_from_socket
    socket = self._get_raw_response_socket(response)
docker/api/client.py:346: in _get_raw_response_socket
    self._raise_for_status(response)
docker/api/client.py:298: in _raise_for_status
    raise create_api_error_from_http_exception(e)
docker/errors.py:31: in create_api_error_from_http_exception
    raise cls(e, response=response, explanation=explanation)
E   docker.errors.APIError: 500 Server Error for http+docker://localhost/v1.40/containers/eaee64f957d1cbda39295879db444ca744ba0f84447ac4f427525fb2241dd4e0/attach?logs=1&amp;stdout=1&amp;stderr=1&amp;stream=0: Internal Server Error ("can only attach to created or running containers - currently in state stopped: container state improper")</failure><system-out>--------------------------------- Captured Log ---------------------------------

--------------------------------- Captured Out ---------------------------------

</system-out><system-err>--------------------------------- Captured Err ---------------------------------

</system-err></testcase><testcase classname="tests.integration.api_container_test.AttachContainerTest" name="test_attach_stream_and_cancel" time="10.005"><failure message="Failed: Timeout &gt;10.0s">tests/integration/base.py:83: in tearDown
    super().tearDown()
tests/integration/base.py:30: in tearDown
    client = docker.from_env(version=TEST_API_VERSION)
docker/client.py:96: in from_env
    return cls(
docker/client.py:45: in __init__
    self.api = APIClient(*args, **kwargs)
docker/api/client.py:197: in __init__
    self._version = self._retrieve_server_version()
docker/api/client.py:214: in _retrieve_server_version
    return self.version(api_version=False)["ApiVersion"]
docker/api/daemon.py:181: in version
    return self._result(self._get(url), json=True)
docker/utils/decorators.py:46: in inner
    return f(self, *args, **kwargs)
docker/api/client.py:251: in _get
    return self.get(url, **self._set_request_timeout(kwargs))
../../.virtualenvs/docker-py/lib/python3.9/site-packages/requests/sessions.py:555: in get
    return self.request('GET', url, **kwargs)
../../.virtualenvs/docker-py/lib/python3.9/site-packages/requests/sessions.py:542: in request
    resp = self.send(prep, **send_kwargs)
../../.virtualenvs/docker-py/lib/python3.9/site-packages/requests/sessions.py:655: in send
    r = adapter.send(request, **kwargs)
../../.virtualenvs/docker-py/lib/python3.9/site-packages/requests/adapters.py:439: in send
    resp = conn.urlopen(
../../.virtualenvs/docker-py/lib/python3.9/site-packages/urllib3/connectionpool.py:699: in urlopen
    httplib_response = self._make_request(
../../.virtualenvs/docker-py/lib/python3.9/site-packages/urllib3/connectionpool.py:445: in _make_request
    six.raise_from(e, None)
../../.virtualenvs/docker-py/lib/python3.9/site-packages/urllib3/connectionpool.py:440: in _make_request
    httplib_response = conn.getresponse()
/usr/lib/python3.9/http/client.py:1371: in getresponse
    response.begin()
/usr/lib/python3.9/http/client.py:319: in begin
    version, status, reason = self._read_status()
/usr/lib/python3.9/http/client.py:280: in _read_status
    line = str(self.fp.readline(_MAXLINE + 1), "iso-8859-1")
/usr/lib/python3.9/socket.py:704: in readinto
    return self._sock.recv_into(b)
E   Failed: Timeout &gt;10.0s</failure><system-out>--------------------------------- Captured Log ---------------------------------

--------------------------------- Captured Out ---------------------------------

</system-out><system-err>--------------------------------- Captured Err ---------------------------------

</system-err></testcase><testcase classname="tests.integration.api_container_test.AttachContainerTest" name="test_detach_with_arg" time="9.566" /><testcase classname="tests.integration.api_container_test.AttachContainerTest" name="test_detach_with_config_file" time="9.271" /><testcase classname="tests.integration.api_container_test.AttachContainerTest" name="test_detach_with_default" time="9.868" /><testcase classname="tests.integration.api_container_test.AttachContainerTest" name="test_run_container_reading_socket" time="8.564" /><testcase classname="tests.integration.api_container_test.AttachContainerTest" name="test_run_container_streaming" time="8.772" /><testcase classname="tests.integration.api_container_test.PauseTest" name="test_pause_unpause" time="8.808" /><testcase classname="tests.integration.api_container_test.PruneTest" name="test_prune_containers" time="9.109" /><testcase classname="tests.integration.api_container_test.GetContainerStatsTest" name="test_get_container_stats_no_stream" time="8.653" /><testcase classname="tests.integration.api_container_test.ContainerUpdateTest" name="test_restart_policy_update" time="8.771"><failure message="docker.errors.NotFound: 404 Client Error for http+docker://localhost/v1.40/containers/5c6d72495828120206c3fa3d232b640fd209c79ad4b68798fc5879a2dbc37d36/update: Not Found (&quot;b'Not Found'&quot;)">docker/api/client.py:296: in _raise_for_status
    response.raise_for_status()
../../.virtualenvs/docker-py/lib/python3.9/site-packages/requests/models.py:953: in raise_for_status
    raise HTTPError(http_error_msg, response=self)
E   requests.exceptions.HTTPError: 404 Client Error: Not Found for url: http+docker://localhost/v1.40/containers/5c6d72495828120206c3fa3d232b640fd209c79ad4b68798fc5879a2dbc37d36/update

During handling of the above exception, another exception occurred:
tests/integration/api_container_test.py:1416: in test_restart_policy_update
    self.client.update_container(container,
docker/utils/decorators.py:34: in wrapper
    return f(self, *args, **kwargs)
docker/utils/decorators.py:19: in wrapped
    return f(self, resource_id, *args, **kwargs)
docker/api/container.py:1268: in update_container
    return self._result(res, True)
docker/api/client.py:302: in _result
    self._raise_for_status(response)
docker/api/client.py:298: in _raise_for_status
    raise create_api_error_from_http_exception(e)
docker/errors.py:31: in create_api_error_from_http_exception
    raise cls(e, response=response, explanation=explanation)
E   docker.errors.NotFound: 404 Client Error for http+docker://localhost/v1.40/containers/5c6d72495828120206c3fa3d232b640fd209c79ad4b68798fc5879a2dbc37d36/update: Not Found ("b'Not Found'")</failure><system-out>--------------------------------- Captured Log ---------------------------------

--------------------------------- Captured Out ---------------------------------

</system-out><system-err>--------------------------------- Captured Err ---------------------------------

</system-err></testcase><testcase classname="tests.integration.api_container_test.ContainerUpdateTest" name="test_update_container" time="8.819"><failure message="docker.errors.NotFound: 404 Client Error for http+docker://localhost/v1.40/containers/3e0651c3e4a1be6cb87245d1870fc4dc7cd0bebcce211d460c14a799d59ef1b5/update: Not Found (&quot;b'Not Found'&quot;)">docker/api/client.py:296: in _raise_for_status
    response.raise_for_status()
../../.virtualenvs/docker-py/lib/python3.9/site-packages/requests/models.py:953: in raise_for_status
    raise HTTPError(http_error_msg, response=self)
E   requests.exceptions.HTTPError: 404 Client Error: Not Found for url: http+docker://localhost/v1.40/containers/3e0651c3e4a1be6cb87245d1870fc4dc7cd0bebcce211d460c14a799d59ef1b5/update

During handling of the above exception, another exception occurred:
tests/integration/api_container_test.py:1394: in test_update_container
    self.client.update_container(container, mem_limit=new_mem_limit)
docker/utils/decorators.py:34: in wrapper
    return f(self, *args, **kwargs)
docker/utils/decorators.py:19: in wrapped
    return f(self, resource_id, *args, **kwargs)
docker/api/container.py:1268: in update_container
    return self._result(res, True)
docker/api/client.py:302: in _result
    self._raise_for_status(response)
docker/api/client.py:298: in _raise_for_status
    raise create_api_error_from_http_exception(e)
docker/errors.py:31: in create_api_error_from_http_exception
    raise cls(e, response=response, explanation=explanation)
E   docker.errors.NotFound: 404 Client Error for http+docker://localhost/v1.40/containers/3e0651c3e4a1be6cb87245d1870fc4dc7cd0bebcce211d460c14a799d59ef1b5/update: Not Found ("b'Not Found'")</failure><system-out>--------------------------------- Captured Log ---------------------------------

--------------------------------- Captured Out ---------------------------------

</system-out><system-err>--------------------------------- Captured Err ---------------------------------

</system-err></testcase><testcase classname="tests.integration.api_container_test.ContainerCPUTest" name="test_container_cpu_shares" time="8.649" /><testcase classname="tests.integration.api_container_test.ContainerCPUTest" name="test_container_cpuset" time="8.632" /><testcase classname="tests.integration.api_container_test.ContainerCPUTest" name="test_create_with_runtime" time="8.296"><failure message="AssertionError: assert 'oci' == 'runc'&#10;  - runc&#10;  + oci">tests/integration/api_container_test.py:1461: in test_create_with_runtime
    assert config['HostConfig']['Runtime'] == 'runc'
E   AssertionError: assert 'oci' == 'runc'
E     - runc
E     + oci</failure><system-out>--------------------------------- Captured Log ---------------------------------

--------------------------------- Captured Out ---------------------------------

</system-out><system-err>--------------------------------- Captured Err ---------------------------------

</system-err></testcase><testcase classname="tests.integration.api_exec_test.ExecTest" name="test_detach_with_config_file" time="14.024"><failure message="AssertionError">/home/ubuntu/docker-py/tests/integration/api_exec_test.py:227: in test_detach_with_config_file
    ???
tests/helpers.py:137: in assert_cat_socket_detached_with_keys
    assert data == b'' or data.startswith(
E   AssertionError</failure><system-out>--------------------------------- Captured Log ---------------------------------

--------------------------------- Captured Out ---------------------------------

</system-out><system-err>--------------------------------- Captured Err ---------------------------------

</system-err></testcase><testcase classname="tests.integration.api_exec_test.ExecTest" name="test_detach_with_default" time="9.685" /><testcase classname="tests.integration.api_exec_test.ExecTest" name="test_exec_command_as_root" time="8.854" /><testcase classname="tests.integration.api_exec_test.ExecTest" name="test_exec_command_as_user" time="8.815" /><testcase classname="tests.integration.api_exec_test.ExecTest" name="test_exec_command_streaming" time="9.406" /><testcase classname="tests.integration.api_exec_test.ExecTest" name="test_exec_command_string" time="9.473" /><testcase classname="tests.integration.api_exec_test.ExecTest" name="test_exec_command_with_env" time="8.855" /><testcase classname="tests.integration.api_exec_test.ExecTest" name="test_exec_command_with_workdir" time="9.167" /><testcase classname="tests.integration.api_exec_test.ExecTest" name="test_exec_inspect" time="9.597" /><testcase classname="tests.integration.api_exec_test.ExecTest" name="test_exec_start_detached" time="9.231"><failure message="AssertionError: assert '\n' == ''&#10;  Strings contain only whitespace, escaping them using repr()&#10;  - ''&#10;  + '\n'">/home/ubuntu/docker-py/tests/integration/api_exec_test.py:152: in test_exec_start_detached
    ???
E   AssertionError: assert '\n' == ''
E     Strings contain only whitespace, escaping them using repr()
E     - ''
E     + '\n'</failure><system-out>--------------------------------- Captured Log ---------------------------------

--------------------------------- Captured Out ---------------------------------

</system-out><system-err>--------------------------------- Captured Err ---------------------------------

</system-err></testcase><testcase classname="tests.integration.api_exec_test.ExecTest" name="test_exec_start_socket" time="8.981"><failure message="AssertionError: assert 121 == 1&#10;  +121&#10;  -1">/home/ubuntu/docker-py/tests/integration/api_exec_test.py:134: in test_exec_start_socket
    ???
E   AssertionError: assert 121 == 1
E     +121
E     -1</failure><system-out>--------------------------------- Captured Log ---------------------------------

--------------------------------- Captured Out ---------------------------------

</system-out><system-err>--------------------------------- Captured Err ---------------------------------

</system-err></testcase><testcase classname="tests.integration.api_exec_test.ExecTest" name="test_execute_command" time="8.908" /><testcase classname="tests.integration.api_exec_test.ExecTest" name="test_execute_command_with_proxy_env" time="9.121" /><testcase classname="tests.integration.api_exec_test.ExecDemuxTest" name="test_exec_command_no_stream_demux" time="9.556" /><testcase classname="tests.integration.api_exec_test.ExecDemuxTest" name="test_exec_command_no_stream_no_demux" time="9.376" /><testcase classname="tests.integration.api_exec_test.ExecDemuxTest" name="test_exec_command_stream_demux" time="9.459" /><testcase classname="tests.integration.api_exec_test.ExecDemuxTest" name="test_exec_command_stream_no_demux" time="9.499" /><testcase classname="tests.integration.api_exec_test.ExecDemuxTest" name="test_exec_command_tty_no_stream_demux" time="8.917"><failure message="ValueError: 104 is not a valid stream">/home/ubuntu/docker-py/tests/integration/api_exec_test.py:299: in test_exec_command_tty_no_stream_demux
    ???
docker/utils/decorators.py:19: in wrapped
    return f(self, resource_id, *args, **kwargs)
docker/api/exec_api.py:173: in exec_start
    output = self._read_from_socket(res, stream, tty=tty, demux=demux)
docker/api/client.py:457: in _read_from_socket
    return consume_socket_output(gen, demux=demux)
docker/utils/socket.py:140: in consume_socket_output
    for frame in frames:
docker/api/client.py:447: in &lt;genexpr&gt;
    gen = (demux_adaptor(*frame) for frame in gen)
docker/utils/socket.py:167: in demux_adaptor
    raise ValueError(f'{stream_id} is not a valid stream')
E   ValueError: 104 is not a valid stream</failure><system-out>--------------------------------- Captured Log ---------------------------------

--------------------------------- Captured Out ---------------------------------

</system-out><system-err>--------------------------------- Captured Err ---------------------------------

</system-err></testcase><testcase classname="tests.integration.api_exec_test.ExecDemuxTest" name="test_exec_command_tty_no_stream_no_demux" time="9.626"><failure message="AssertionError: assert b't\r\nhello err\r\n' == b'hello out\r\nhello err\r\n'&#10;  At index 0 diff: b't' != b'h'&#10;  Full diff:&#10;  - b'hello out\r\nhello err\r\n'&#10;  ?   --------&#10;  + b't\r\nhello err\r\n'">/home/ubuntu/docker-py/tests/integration/api_exec_test.py:282: in test_exec_command_tty_no_stream_no_demux
    ???
E   AssertionError: assert b't\r\nhello err\r\n' == b'hello out\r\nhello err\r\n'
E     At index 0 diff: b't' != b'h'
E     Full diff:
E     - b'hello out\r\nhello err\r\n'
E     ?   --------
E     + b't\r\nhello err\r\n'</failure><system-out>--------------------------------- Captured Log ---------------------------------

--------------------------------- Captured Out ---------------------------------

</system-out><system-err>--------------------------------- Captured Err ---------------------------------

</system-err></testcase><testcase classname="tests.integration.api_exec_test.ExecDemuxTest" name="test_exec_command_tty_stream_demux" time="12.429"><failure message="ValueError: 104 is not a valid stream">/home/ubuntu/docker-py/tests/integration/api_exec_test.py:305: in test_exec_command_tty_stream_demux
    ???
docker/types/daemon.py:32: in __next__
    return next(self._stream)
docker/api/client.py:447: in &lt;genexpr&gt;
    gen = (demux_adaptor(*frame) for frame in gen)
docker/utils/socket.py:167: in demux_adaptor
    raise ValueError(f'{stream_id} is not a valid stream')
E   ValueError: 104 is not a valid stream</failure><system-out>--------------------------------- Captured Log ---------------------------------

--------------------------------- Captured Out ---------------------------------

</system-out><system-err>--------------------------------- Captured Err ---------------------------------

</system-err></testcase><testcase classname="tests.integration.api_exec_test.ExecDemuxTest" name="test_exec_command_tty_stream_no_demux" time="9.829"><failure message="AssertionError: assert b'hello out\r\n' in [b't\r\n', b'hello err\r\n']">/home/ubuntu/docker-py/tests/integration/api_exec_test.py:288: in test_exec_command_tty_stream_no_demux
    ???
E   AssertionError: assert b'hello out\r\n' in [b't\r\n', b'hello err\r\n']</failure><system-out>--------------------------------- Captured Log ---------------------------------

--------------------------------- Captured Out ---------------------------------

</system-out><system-err>--------------------------------- Captured Err ---------------------------------

</system-err></testcase><testcase classname="tests.integration.api_healthcheck_test.HealthcheckTest" name="test_healthcheck_fails" time="10.160" /><testcase classname="tests.integration.api_healthcheck_test.HealthcheckTest" name="test_healthcheck_passes" time="10.070" /><testcase classname="tests.integration.api_healthcheck_test.HealthcheckTest" name="test_healthcheck_shell_command" time="8.984" /><testcase classname="tests.integration.api_healthcheck_test.HealthcheckTest" name="test_healthcheck_start_period" time="13.159" /><testcase classname="tests.integration.api_image_test.ListImagesTest" name="test_images" time="10.422" /><testcase classname="tests.integration.api_image_test.ListImagesTest" name="test_images_quiet" time="8.370" /><testcase classname="tests.integration.api_image_test.PullImageTest" name="test_pull" time="11.335" /><testcase classname="tests.integration.api_image_test.PullImageTest" name="test_pull_invalid_platform" time="11.488"><failure message="Failed: DID NOT RAISE &lt;class 'docker.errors.APIError'&gt;">/home/ubuntu/docker-py/tests/integration/api_image_test.py:69: in test_pull_invalid_platform
    ???
E   Failed: DID NOT RAISE &lt;class 'docker.errors.APIError'&gt;</failure><system-out>--------------------------------- Captured Log ---------------------------------

--------------------------------- Captured Out ---------------------------------

</system-out><system-err>--------------------------------- Captured Err ---------------------------------

</system-err></testcase><testcase classname="tests.integration.api_image_test.PullImageTest" name="test_pull_streaming" time="11.160" /><testcase classname="tests.integration.api_image_test.CommitTest" name="test_commit" time="9.475"><failure message="AssertionError: assert False&#10; +  where False = &lt;built-in method startswith of str object at 0x7fa7e9ae4670&gt;('4ca2346640f6e84abfb54683e0c420e7ec43aa9974d050dc1050e6f9e365e762')&#10; +    where &lt;built-in method startswith of str object at 0x7fa7e9ae4670&gt; = ''.startswith">/home/ubuntu/docker-py/tests/integration/api_image_test.py:89: in test_commit
    ???
E   AssertionError: assert False
E    +  where False = &lt;built-in method startswith of str object at 0x7fa7e9ae4670&gt;('4ca2346640f6e84abfb54683e0c420e7ec43aa9974d050dc1050e6f9e365e762')
E    +    where &lt;built-in method startswith of str object at 0x7fa7e9ae4670&gt; = ''.startswith</failure><system-out>--------------------------------- Captured Log ---------------------------------

--------------------------------- Captured Out ---------------------------------

</system-out><system-err>--------------------------------- Captured Err ---------------------------------

</system-err></testcase><testcase classname="tests.integration.api_image_test.CommitTest" name="test_commit_with_changes" time="8.927"><failure message="docker.errors.APIError: 500 Server Error for http+docker://localhost/v1.40/commit?container=b8ad6a8949e4a95bb0ef69221b0be730861fbab74a98fafe8a0753fa72f688f9&amp;changes=EXPOSE+8000&amp;changes=CMD+%5B%22bash%22%5D: Internal Server Error (&quot;CommitFailure: invalid change &quot;CMD&quot; - must be formatted as KEY VALUE&quot;)">docker/api/client.py:296: in _raise_for_status
    response.raise_for_status()
../../.virtualenvs/docker-py/lib/python3.9/site-packages/requests/models.py:953: in raise_for_status
    raise HTTPError(http_error_msg, response=self)
E   requests.exceptions.HTTPError: 500 Server Error: Internal Server Error for url: http+docker://localhost/v1.40/commit?container=b8ad6a8949e4a95bb0ef69221b0be730861fbab74a98fafe8a0753fa72f688f9&amp;changes=EXPOSE+8000&amp;changes=CMD+%5B%22bash%22%5D

During handling of the above exception, another exception occurred:
/home/ubuntu/docker-py/tests/integration/api_image_test.py:101: in test_commit_with_changes
    ???
docker/utils/decorators.py:19: in wrapped
    return f(self, resource_id, *args, **kwargs)
docker/api/container.py:145: in commit
    return self._result(
docker/api/client.py:302: in _result
    self._raise_for_status(response)
docker/api/client.py:298: in _raise_for_status
    raise create_api_error_from_http_exception(e)
docker/errors.py:31: in create_api_error_from_http_exception
    raise cls(e, response=response, explanation=explanation)
E   docker.errors.APIError: 500 Server Error for http+docker://localhost/v1.40/commit?container=b8ad6a8949e4a95bb0ef69221b0be730861fbab74a98fafe8a0753fa72f688f9&amp;changes=EXPOSE+8000&amp;changes=CMD+%5B%22bash%22%5D: Internal Server Error ("CommitFailure: invalid change "CMD" - must be formatted as KEY VALUE")</failure><system-out>--------------------------------- Captured Log ---------------------------------

--------------------------------- Captured Out ---------------------------------

</system-out><system-err>--------------------------------- Captured Err ---------------------------------

</system-err></testcase><testcase classname="tests.integration.api_image_test.RemoveImageTest" name="test_remove" time="9.187" /><testcase classname="tests.integration.api_image_test.ImportImageTest" name="test_get_load_image" time="11.357"><failure message="AssertionError: assert False&#10; +  where False = any([])">/home/ubuntu/docker-py/tests/integration/api_image_test.py:266: in test_get_load_image
    ???
E   AssertionError: assert False
E    +  where False = any([])</failure><system-out>--------------------------------- Captured Log ---------------------------------

--------------------------------- Captured Out ---------------------------------

</system-out><system-err>--------------------------------- Captured Err ---------------------------------

</system-err></testcase><testcase classname="tests.integration.api_image_test.ImportImageTest" name="test_import_from_bytes" time="8.333" /><testcase classname="tests.integration.api_image_test.ImportImageTest" name="test_import_from_file" time="8.529" /><testcase classname="tests.integration.api_image_test.ImportImageTest" name="test_import_from_stream" time="8.339" /><testcase classname="tests.integration.api_image_test.ImportImageTest" name="test_import_from_url" time="0.000"><skipped type="pytest.skip" message="Doesn't work inside a container - FIXME">/home/ubuntu/docker-py/tests/integration/api_image_test.py:291: Doesn't work inside a container - FIXME</skipped><system-out>--------------------------------- Captured Log ---------------------------------

--------------------------------- Captured Out ---------------------------------

</system-out><system-err>--------------------------------- Captured Err ---------------------------------

</system-err></testcase><testcase classname="tests.integration.api_image_test.ImportImageTest" name="test_import_image_from_data_with_changes" time="8.464" /><testcase classname="tests.integration.api_image_test.ImportImageTest" name="test_import_image_with_changes" time="8.391" /><testcase classname="tests.integration.api_image_test.PruneImagesTest" name="test_prune_images" time="11.380"><failure message="AssertionError: assert 0 &gt; 0">/home/ubuntu/docker-py/tests/integration/api_image_test.py:332: in test_prune_images
    ???
E   AssertionError: assert 0 &gt; 0</failure><system-out>--------------------------------- Captured Log ---------------------------------

--------------------------------- Captured Out ---------------------------------

</system-out><system-err>--------------------------------- Captured Err ---------------------------------

</system-err></testcase><testcase classname="tests.integration.api_image_test.SaveLoadImagesTest" name="test_get_image_load_image" time="8.328"><failure message="AssertionError: assert False is True">/home/ubuntu/docker-py/tests/integration/api_image_test.py:360: in test_get_image_load_image
    ???
E   AssertionError: assert False is True</failure><system-out>--------------------------------- Captured Log ---------------------------------

--------------------------------- Captured Out ---------------------------------
{'stream': 'Loaded image: docker.io/library/alpine:3.10\n'}

</system-out><system-err>--------------------------------- Captured Err ---------------------------------

</system-err></testcase><testcase classname="tests.integration.api_image_test.InspectDistributionTest" name="test_inspect_distribution" time="8.161"><failure message="docker.errors.NotFound: 404 Client Error for http+docker://localhost/v1.40/distribution/busybox:latest/json: Not Found (&quot;Path /v1.40/distribution/busybox:latest/json is not supported&quot;)">docker/api/client.py:296: in _raise_for_status
    response.raise_for_status()
../../.virtualenvs/docker-py/lib/python3.9/site-packages/requests/models.py:953: in raise_for_status
    raise HTTPError(http_error_msg, response=self)
E   requests.exceptions.HTTPError: 404 Client Error: Not Found for url: http+docker://localhost/v1.40/distribution/busybox:latest/json

During handling of the above exception, another exception occurred:
/home/ubuntu/docker-py/tests/integration/api_image_test.py:366: in test_inspect_distribution
    ???
docker/utils/decorators.py:34: in wrapper
    return f(self, *args, **kwargs)
docker/utils/decorators.py:19: in wrapped
    return f(self, resource_id, *args, **kwargs)
docker/api/image.py:287: in inspect_distribution
    return self._result(
docker/api/client.py:302: in _result
    self._raise_for_status(response)
docker/api/client.py:298: in _raise_for_status
    raise create_api_error_from_http_exception(e)
docker/errors.py:31: in create_api_error_from_http_exception
    raise cls(e, response=response, explanation=explanation)
E   docker.errors.NotFound: 404 Client Error for http+docker://localhost/v1.40/distribution/busybox:latest/json: Not Found ("Path /v1.40/distribution/busybox:latest/json is not supported")</failure><system-out>--------------------------------- Captured Log ---------------------------------

--------------------------------- Captured Out ---------------------------------

</system-out><system-err>--------------------------------- Captured Err ---------------------------------

</system-err></testcase><testcase classname="tests.integration.api_network_test.TestNetworks" name="test_connect_and_disconnect_container" time="9.225" /><testcase classname="tests.integration.api_network_test.TestNetworks" name="test_connect_and_force_disconnect_container" time="9.121" /><testcase classname="tests.integration.api_network_test.TestNetworks" name="test_connect_on_container_create" time="8.734" /><testcase classname="tests.integration.api_network_test.TestNetworks" name="test_connect_with_aliases" time="9.389" /><testcase classname="tests.integration.api_network_test.TestNetworks" name="test_connect_with_ipv4_address" time="8.216"><failure message="docker.errors.APIError: 500 Server Error for http+docker://localhost/v1.40/containers/656f6aff5aa5fbb0b4e2c97bddfc5a3772089d6f3c4a132aee5138aca50e800b/start: Internal Server Error (&quot;plugin type=&quot;bridge&quot; failed (add): cni plugin bridge failed: failed to set bridge addr: &quot;cni-podman1&quot; already has an IP address different from 172.28.5.254/16&quot;)">docker/api/client.py:296: in _raise_for_status
    response.raise_for_status()
../../.virtualenvs/docker-py/lib/python3.9/site-packages/requests/models.py:953: in raise_for_status
    raise HTTPError(http_error_msg, response=self)
E   requests.exceptions.HTTPError: 500 Server Error: Internal Server Error for url: http+docker://localhost/v1.40/containers/656f6aff5aa5fbb0b4e2c97bddfc5a3772089d6f3c4a132aee5138aca50e800b/start

During handling of the above exception, another exception occurred:
tests/integration/api_network_test.py:369: in test_connect_with_ipv4_address
    container = self.create_and_start(
tests/integration/base.py:124: in create_and_start
    self.client.start(container)
docker/utils/decorators.py:19: in wrapped
    return f(self, resource_id, *args, **kwargs)
docker/api/container.py:1109: in start
    self._raise_for_status(res)
docker/api/client.py:298: in _raise_for_status
    raise create_api_error_from_http_exception(e)
docker/errors.py:31: in create_api_error_from_http_exception
    raise cls(e, response=response, explanation=explanation)
E   docker.errors.APIError: 500 Server Error for http+docker://localhost/v1.40/containers/656f6aff5aa5fbb0b4e2c97bddfc5a3772089d6f3c4a132aee5138aca50e800b/start: Internal Server Error ("plugin type="bridge" failed (add): cni plugin bridge failed: failed to set bridge addr: "cni-podman1" already has an IP address different from 172.28.5.254/16")</failure><system-out>--------------------------------- Captured Log ---------------------------------

--------------------------------- Captured Out ---------------------------------

</system-out><system-err>--------------------------------- Captured Err ---------------------------------

</system-err></testcase><testcase classname="tests.integration.api_network_test.TestNetworks" name="test_connect_with_ipv6_address" time="11.655"><failure message="TypeError: 'NoneType' object is not subscriptable">tests/integration/api_network_test.py:405: in test_connect_with_ipv6_address
    assert net_data['IPAMConfig']['IPv6Address'] == '2001:389::f00d'
E   TypeError: 'NoneType' object is not subscriptable</failure><system-out>--------------------------------- Captured Log ---------------------------------

--------------------------------- Captured Out ---------------------------------

</system-out><system-err>--------------------------------- Captured Err ---------------------------------

</system-err></testcase><testcase classname="tests.integration.api_network_test.TestNetworks" name="test_connect_with_links" time="8.902"><failure message="AssertionError: assert None == ['docker-py-t...upstream:bar']&#10;  +None&#10;  -['docker-py-test-upstream:bar']">tests/integration/api_network_test.py:344: in test_connect_with_links
    assert net_settings['Networks'][net_name]['Links'] == [
E   AssertionError: assert None == ['docker-py-t...upstream:bar']
E     +None
E     -['docker-py-test-upstream:bar']</failure><system-out>--------------------------------- Captured Log ---------------------------------

--------------------------------- Captured Out ---------------------------------

</system-out><system-err>--------------------------------- Captured Err ---------------------------------

</system-err></testcase><testcase classname="tests.integration.api_network_test.TestNetworks" name="test_create_check_duplicate" time="7.841"><failure message="docker.errors.APIError: 500 Server Error for http+docker://localhost/v1.40/networks/create: Internal Server Error (&quot;network name dockerpytest_a9a46d1dc8b22676 already used: network already exists&quot;)">docker/api/client.py:296: in _raise_for_status
    response.raise_for_status()
../../.virtualenvs/docker-py/lib/python3.9/site-packages/requests/models.py:953: in raise_for_status
    raise HTTPError(http_error_msg, response=self)
E   requests.exceptions.HTTPError: 500 Server Error: Internal Server Error for url: http+docker://localhost/v1.40/networks/create

During handling of the above exception, another exception occurred:
tests/integration/api_network_test.py:326: in test_create_check_duplicate
    net_id = self.client.create_network(net_name, check_duplicate=False)
docker/api/network.py:153: in create_network
    return self._result(res, json=True)
docker/api/client.py:302: in _result
    self._raise_for_status(response)
docker/api/client.py:298: in _raise_for_status
    raise create_api_error_from_http_exception(e)
docker/errors.py:31: in create_api_error_from_http_exception
    raise cls(e, response=response, explanation=explanation)
E   docker.errors.APIError: 500 Server Error for http+docker://localhost/v1.40/networks/create: Internal Server Error ("network name dockerpytest_a9a46d1dc8b22676 already used: network already exists")</failure><system-out>--------------------------------- Captured Log ---------------------------------

--------------------------------- Captured Out ---------------------------------

</system-out><system-err>--------------------------------- Captured Err ---------------------------------

</system-err></testcase><testcase classname="tests.integration.api_network_test.TestNetworks" name="test_create_internal_networks" time="8.033" /><testcase classname="tests.integration.api_network_test.TestNetworks" name="test_create_network_ipv6_enabled" time="7.846" /><testcase classname="tests.integration.api_network_test.TestNetworks" name="test_create_network_with_host_driver_fails" time="7.983" /><testcase classname="tests.integration.api_network_test.TestNetworks" name="test_create_network_with_ipam_config" time="7.847"><failure message="AssertionError: assert {'driver': 'host-local'} is None&#10; +  where {'driver': 'host-local'} = &lt;built-in method pop of dict object at 0x7fa7e6612200&gt;('Options', None)&#10; +    where &lt;built-in method pop of dict object at 0x7fa7e6612200&gt; = {'Config': [{'Gateway': '172.28.5.254', 'Subnet': '172.28.0.0/16'}], 'Driver': 'default'}.pop">tests/integration/api_network_test.py:62: in test_create_network_with_ipam_config
    assert ipam.pop('Options', None) is None
E   AssertionError: assert {'driver': 'host-local'} is None
E    +  where {'driver': 'host-local'} = &lt;built-in method pop of dict object at 0x7fa7e6612200&gt;('Options', None)
E    +    where &lt;built-in method pop of dict object at 0x7fa7e6612200&gt; = {'Config': [{'Gateway': '172.28.5.254', 'Subnet': '172.28.0.0/16'}], 'Driver': 'default'}.pop</failure><system-out>--------------------------------- Captured Log ---------------------------------

--------------------------------- Captured Out ---------------------------------

</system-out><system-err>--------------------------------- Captured Err ---------------------------------

</system-err></testcase><testcase classname="tests.integration.api_network_test.TestNetworks" name="test_create_network_with_labels" time="7.892" /><testcase classname="tests.integration.api_network_test.TestNetworks" name="test_create_network_with_labels_wrong_type" time="7.921" /><testcase classname="tests.integration.api_network_test.TestNetworks" name="test_create_remove_network_with_space_in_name" time="7.857"><failure message="docker.errors.APIError: 500 Server Error for http+docker://localhost/v1.40/networks/create: Internal Server Error (&quot;network name test 01 invalid: names must match [a-zA-Z0-9][a-zA-Z0-9_.-]*: invalid argument&quot;)">docker/api/client.py:296: in _raise_for_status
    response.raise_for_status()
../../.virtualenvs/docker-py/lib/python3.9/site-packages/requests/models.py:953: in raise_for_status
    raise HTTPError(http_error_msg, response=self)
E   requests.exceptions.HTTPError: 500 Server Error: Internal Server Error for url: http+docker://localhost/v1.40/networks/create

During handling of the above exception, another exception occurred:
tests/integration/api_network_test.py:454: in test_create_remove_network_with_space_in_name
    net_id = self.client.create_network('test 01')
docker/api/network.py:153: in create_network
    return self._result(res, json=True)
docker/api/client.py:302: in _result
    self._raise_for_status(response)
docker/api/client.py:298: in _raise_for_status
    raise create_api_error_from_http_exception(e)
docker/errors.py:31: in create_api_error_from_http_exception
    raise cls(e, response=response, explanation=explanation)
E   docker.errors.APIError: 500 Server Error for http+docker://localhost/v1.40/networks/create: Internal Server Error ("network name test 01 invalid: names must match [a-zA-Z0-9][a-zA-Z0-9_.-]*: invalid argument")</failure><system-out>--------------------------------- Captured Log ---------------------------------

--------------------------------- Captured Out ---------------------------------

</system-out><system-err>--------------------------------- Captured Err ---------------------------------

</system-err></testcase><testcase classname="tests.integration.api_network_test.TestNetworks" name="test_create_with_aliases" time="8.433" /><testcase classname="tests.integration.api_network_test.TestNetworks" name="test_create_with_driveropt" time="7.880"><failure message="docker.errors.APIError: 500 Server Error for http+docker://localhost/v1.40/containers/create: Internal Server Error (&quot;container create: unable to find network with name or ID bridge: network not found&quot;)">docker/api/client.py:296: in _raise_for_status
    response.raise_for_status()
../../.virtualenvs/docker-py/lib/python3.9/site-packages/requests/models.py:953: in raise_for_status
    raise HTTPError(http_error_msg, response=self)
E   requests.exceptions.HTTPError: 500 Server Error: Internal Server Error for url: http+docker://localhost/v1.40/containers/create

During handling of the above exception, another exception occurred:
tests/integration/api_network_test.py:276: in test_create_with_driveropt
    container = self.client.create_container(
docker/api/container.py:428: in create_container
    return self.create_container_from_config(config, name)
docker/api/container.py:439: in create_container_from_config
    return self._result(res, True)
docker/api/client.py:302: in _result
    self._raise_for_status(response)
docker/api/client.py:298: in _raise_for_status
    raise create_api_error_from_http_exception(e)
docker/errors.py:31: in create_api_error_from_http_exception
    raise cls(e, response=response, explanation=explanation)
E   docker.errors.APIError: 500 Server Error for http+docker://localhost/v1.40/containers/create: Internal Server Error ("container create: unable to find network with name or ID bridge: network not found")</failure><system-out>--------------------------------- Captured Log ---------------------------------

--------------------------------- Captured Out ---------------------------------

</system-out><system-err>--------------------------------- Captured Err ---------------------------------

</system-err></testcase><testcase classname="tests.integration.api_network_test.TestNetworks" name="test_create_with_ipv4_address" time="8.326"><failure message="docker.errors.APIError: 500 Server Error for http+docker://localhost/v1.40/containers/d899b9224716b5b7f205ff1c551c8e963705117b5c1f215de859ee5923efe33e/start: Internal Server Error (&quot;plugin type=&quot;bridge&quot; failed (add): cni plugin bridge failed: failed to set bridge addr: &quot;cni-podman1&quot; already has an IP address different from 132.124.0.1/16&quot;)">docker/api/client.py:296: in _raise_for_status
    response.raise_for_status()
../../.virtualenvs/docker-py/lib/python3.9/site-packages/requests/models.py:953: in raise_for_status
    raise HTTPError(http_error_msg, response=self)
E   requests.exceptions.HTTPError: 500 Server Error: Internal Server Error for url: http+docker://localhost/v1.40/containers/d899b9224716b5b7f205ff1c551c8e963705117b5c1f215de859ee5923efe33e/start

During handling of the above exception, another exception occurred:
tests/integration/api_network_test.py:219: in test_create_with_ipv4_address
    self.client.start(container)
docker/utils/decorators.py:19: in wrapped
    return f(self, resource_id, *args, **kwargs)
docker/api/container.py:1109: in start
    self._raise_for_status(res)
docker/api/client.py:298: in _raise_for_status
    raise create_api_error_from_http_exception(e)
docker/errors.py:31: in create_api_error_from_http_exception
    raise cls(e, response=response, explanation=explanation)
E   docker.errors.APIError: 500 Server Error for http+docker://localhost/v1.40/containers/d899b9224716b5b7f205ff1c551c8e963705117b5c1f215de859ee5923efe33e/start: Internal Server Error ("plugin type="bridge" failed (add): cni plugin bridge failed: failed to set bridge addr: "cni-podman1" already has an IP address different from 132.124.0.1/16")</failure><system-out>--------------------------------- Captured Log ---------------------------------

--------------------------------- Captured Out ---------------------------------

</system-out><system-err>--------------------------------- Captured Err ---------------------------------

</system-err></testcase><testcase classname="tests.integration.api_network_test.TestNetworks" name="test_create_with_ipv6_address" time="10.172"><failure message="docker.errors.APIError: 500 Server Error for http+docker://localhost/v1.40/containers/41f2358b6d0dcac42e6a424b2aa102a75566a27b7d4ec2e3863aa18bf0aaabce/start: Internal Server Error (&quot;plugin type=&quot;bridge&quot; failed (add): cni plugin bridge failed: failed to set bridge addr: &quot;cni-podman1&quot; already has an IP address different from 2001:389::1/64&quot;)">docker/api/client.py:296: in _raise_for_status
    response.raise_for_status()
../../.virtualenvs/docker-py/lib/python3.9/site-packages/requests/models.py:953: in raise_for_status
    raise HTTPError(http_error_msg, response=self)
E   requests.exceptions.HTTPError: 500 Server Error: Internal Server Error for url: http+docker://localhost/v1.40/containers/41f2358b6d0dcac42e6a424b2aa102a75566a27b7d4ec2e3863aa18bf0aaabce/start

During handling of the above exception, another exception occurred:
tests/integration/api_network_test.py:245: in test_create_with_ipv6_address
    self.client.start(container)
docker/utils/decorators.py:19: in wrapped
    return f(self, resource_id, *args, **kwargs)
docker/api/container.py:1109: in start
    self._raise_for_status(res)
docker/api/client.py:298: in _raise_for_status
    raise create_api_error_from_http_exception(e)
docker/errors.py:31: in create_api_error_from_http_exception
    raise cls(e, response=response, explanation=explanation)
E   docker.errors.APIError: 500 Server Error for http+docker://localhost/v1.40/containers/41f2358b6d0dcac42e6a424b2aa102a75566a27b7d4ec2e3863aa18bf0aaabce/start: Internal Server Error ("plugin type="bridge" failed (add): cni plugin bridge failed: failed to set bridge addr: "cni-podman1" already has an IP address different from 2001:389::1/64")</failure><system-out>--------------------------------- Captured Log ---------------------------------

--------------------------------- Captured Out ---------------------------------

</system-out><system-err>--------------------------------- Captured Err ---------------------------------

</system-err></testcase><testcase classname="tests.integration.api_network_test.TestNetworks" name="test_create_with_linklocal_ips" time="7.906"><failure message="docker.errors.APIError: 500 Server Error for http+docker://localhost/v1.40/containers/create: Internal Server Error (&quot;container create: unable to find network with name or ID bridge: network not found&quot;)">docker/api/client.py:296: in _raise_for_status
    response.raise_for_status()
../../.virtualenvs/docker-py/lib/python3.9/site-packages/requests/models.py:953: in raise_for_status
    raise HTTPError(http_error_msg, response=self)
E   requests.exceptions.HTTPError: 500 Server Error: Internal Server Error for url: http+docker://localhost/v1.40/containers/create

During handling of the above exception, another exception occurred:
tests/integration/api_network_test.py:255: in test_create_with_linklocal_ips
    container = self.client.create_container(
docker/api/container.py:428: in create_container
    return self.create_container_from_config(config, name)
docker/api/container.py:439: in create_container_from_config
    return self._result(res, True)
docker/api/client.py:302: in _result
    self._raise_for_status(response)
docker/api/client.py:298: in _raise_for_status
    raise create_api_error_from_http_exception(e)
docker/errors.py:31: in create_api_error_from_http_exception
    raise cls(e, response=response, explanation=explanation)
E   docker.errors.APIError: 500 Server Error for http+docker://localhost/v1.40/containers/create: Internal Server Error ("container create: unable to find network with name or ID bridge: network not found")</failure><system-out>--------------------------------- Captured Log ---------------------------------

--------------------------------- Captured Out ---------------------------------

</system-out><system-err>--------------------------------- Captured Err ---------------------------------

</system-err></testcase><testcase classname="tests.integration.api_network_test.TestNetworks" name="test_create_with_links" time="8.453"><failure message="AssertionError: assert None == ['docker-py-t...upstream:bar']&#10;  +None&#10;  -['docker-py-test-upstream:bar']">tests/integration/api_network_test.py:311: in test_create_with_links
    assert net_settings['Networks'][net_name]['Links'] == [
E   AssertionError: assert None == ['docker-py-t...upstream:bar']
E     +None
E     -['docker-py-test-upstream:bar']</failure><system-out>--------------------------------- Captured Log ---------------------------------

--------------------------------- Captured Out ---------------------------------

</system-out><system-err>--------------------------------- Captured Err ---------------------------------

</system-err></testcase><testcase classname="tests.integration.api_network_test.TestNetworks" name="test_inspect_network" time="7.901" /><testcase classname="tests.integration.api_network_test.TestNetworks" name="test_list_networks" time="7.983" /><testcase classname="tests.integration.api_network_test.TestNetworks" name="test_prune_networks" time="7.875" /><testcase classname="tests.integration.api_network_test.TestNetworks" name="test_remove_network" time="8.014" /><testcase classname="tests.integration.api_secret_test.SecretAPITest" name="test_create_secret" time="5.249"><error message="failed on setup with &quot;docker.errors.APIError: 503 Server Error for http+docker://localhost/v1.40/swarm/init: Service Unavailable (&quot;Podman does not support service: /v1.40/swarm/init&quot;)&quot;">docker/api/client.py:296: in _raise_for_status
    response.raise_for_status()
../../.virtualenvs/docker-py/lib/python3.9/site-packages/requests/models.py:953: in raise_for_status
    raise HTTPError(http_error_msg, response=self)
E   requests.exceptions.HTTPError: 503 Server Error: Service Unavailable for url: http+docker://localhost/v1.40/swarm/init

During handling of the above exception, another exception occurred:
tests/integration/api_secret_test.py:15: in setup_class
    cls._init_swarm(client)
tests/integration/base.py:94: in _init_swarm
    return client.init_swarm(
docker/utils/decorators.py:34: in wrapper
    return f(self, *args, **kwargs)
docker/api/swarm.py:170: in init_swarm
    return self._result(response, json=True)
docker/api/client.py:302: in _result
    self._raise_for_status(response)
docker/api/client.py:298: in _raise_for_status
    raise create_api_error_from_http_exception(e)
docker/errors.py:31: in create_api_error_from_http_exception
    raise cls(e, response=response, explanation=explanation)
E   docker.errors.APIError: 503 Server Error for http+docker://localhost/v1.40/swarm/init: Service Unavailable ("Podman does not support service: /v1.40/swarm/init")</error></testcase><testcase classname="tests.integration.api_secret_test.SecretAPITest" name="test_create_secret_unicode_data" time="0.000"><error message="failed on setup with &quot;docker.errors.APIError: 503 Server Error for http+docker://localhost/v1.40/swarm/init: Service Unavailable (&quot;Podman does not support service: /v1.40/swarm/init&quot;)&quot;">docker/api/client.py:296: in _raise_for_status
    response.raise_for_status()
../../.virtualenvs/docker-py/lib/python3.9/site-packages/requests/models.py:953: in raise_for_status
    raise HTTPError(http_error_msg, response=self)
E   requests.exceptions.HTTPError: 503 Server Error: Service Unavailable for url: http+docker://localhost/v1.40/swarm/init

During handling of the above exception, another exception occurred:
tests/integration/api_secret_test.py:15: in setup_class
    cls._init_swarm(client)
tests/integration/base.py:94: in _init_swarm
    return client.init_swarm(
docker/utils/decorators.py:34: in wrapper
    return f(self, *args, **kwargs)
docker/api/swarm.py:170: in init_swarm
    return self._result(response, json=True)
docker/api/client.py:302: in _result
    self._raise_for_status(response)
docker/api/client.py:298: in _raise_for_status
    raise create_api_error_from_http_exception(e)
docker/errors.py:31: in create_api_error_from_http_exception
    raise cls(e, response=response, explanation=explanation)
E   docker.errors.APIError: 503 Server Error for http+docker://localhost/v1.40/swarm/init: Service Unavailable ("Podman does not support service: /v1.40/swarm/init")</error></testcase><testcase classname="tests.integration.api_secret_test.SecretAPITest" name="test_inspect_secret" time="0.000"><error message="failed on setup with &quot;docker.errors.APIError: 503 Server Error for http+docker://localhost/v1.40/swarm/init: Service Unavailable (&quot;Podman does not support service: /v1.40/swarm/init&quot;)&quot;">docker/api/client.py:296: in _raise_for_status
    response.raise_for_status()
../../.virtualenvs/docker-py/lib/python3.9/site-packages/requests/models.py:953: in raise_for_status
    raise HTTPError(http_error_msg, response=self)
E   requests.exceptions.HTTPError: 503 Server Error: Service Unavailable for url: http+docker://localhost/v1.40/swarm/init

During handling of the above exception, another exception occurred:
tests/integration/api_secret_test.py:15: in setup_class
    cls._init_swarm(client)
tests/integration/base.py:94: in _init_swarm
    return client.init_swarm(
docker/utils/decorators.py:34: in wrapper
    return f(self, *args, **kwargs)
docker/api/swarm.py:170: in init_swarm
    return self._result(response, json=True)
docker/api/client.py:302: in _result
    self._raise_for_status(response)
docker/api/client.py:298: in _raise_for_status
    raise create_api_error_from_http_exception(e)
docker/errors.py:31: in create_api_error_from_http_exception
    raise cls(e, response=response, explanation=explanation)
E   docker.errors.APIError: 503 Server Error for http+docker://localhost/v1.40/swarm/init: Service Unavailable ("Podman does not support service: /v1.40/swarm/init")</error></testcase><testcase classname="tests.integration.api_secret_test.SecretAPITest" name="test_list_secrets" time="0.000"><error message="failed on setup with &quot;docker.errors.APIError: 503 Server Error for http+docker://localhost/v1.40/swarm/init: Service Unavailable (&quot;Podman does not support service: /v1.40/swarm/init&quot;)&quot;">docker/api/client.py:296: in _raise_for_status
    response.raise_for_status()
../../.virtualenvs/docker-py/lib/python3.9/site-packages/requests/models.py:953: in raise_for_status
    raise HTTPError(http_error_msg, response=self)
E   requests.exceptions.HTTPError: 503 Server Error: Service Unavailable for url: http+docker://localhost/v1.40/swarm/init

During handling of the above exception, another exception occurred:
tests/integration/api_secret_test.py:15: in setup_class
    cls._init_swarm(client)
tests/integration/base.py:94: in _init_swarm
    return client.init_swarm(
docker/utils/decorators.py:34: in wrapper
    return f(self, *args, **kwargs)
docker/api/swarm.py:170: in init_swarm
    return self._result(response, json=True)
docker/api/client.py:302: in _result
    self._raise_for_status(response)
docker/api/client.py:298: in _raise_for_status
    raise create_api_error_from_http_exception(e)
docker/errors.py:31: in create_api_error_from_http_exception
    raise cls(e, response=response, explanation=explanation)
E   docker.errors.APIError: 503 Server Error for http+docker://localhost/v1.40/swarm/init: Service Unavailable ("Podman does not support service: /v1.40/swarm/init")</error></testcase><testcase classname="tests.integration.api_secret_test.SecretAPITest" name="test_remove_secret" time="0.001"><error message="failed on setup with &quot;docker.errors.APIError: 503 Server Error for http+docker://localhost/v1.40/swarm/init: Service Unavailable (&quot;Podman does not support service: /v1.40/swarm/init&quot;)&quot;">docker/api/client.py:296: in _raise_for_status
    response.raise_for_status()
../../.virtualenvs/docker-py/lib/python3.9/site-packages/requests/models.py:953: in raise_for_status
    raise HTTPError(http_error_msg, response=self)
E   requests.exceptions.HTTPError: 503 Server Error: Service Unavailable for url: http+docker://localhost/v1.40/swarm/init

During handling of the above exception, another exception occurred:
tests/integration/api_secret_test.py:15: in setup_class
    cls._init_swarm(client)
tests/integration/base.py:94: in _init_swarm
    return client.init_swarm(
docker/utils/decorators.py:34: in wrapper
    return f(self, *args, **kwargs)
docker/api/swarm.py:170: in init_swarm
    return self._result(response, json=True)
docker/api/client.py:302: in _result
    self._raise_for_status(response)
docker/api/client.py:298: in _raise_for_status
    raise create_api_error_from_http_exception(e)
docker/errors.py:31: in create_api_error_from_http_exception
    raise cls(e, response=response, explanation=explanation)
E   docker.errors.APIError: 503 Server Error for http+docker://localhost/v1.40/swarm/init: Service Unavailable ("Podman does not support service: /v1.40/swarm/init")</error></testcase><testcase classname="tests.integration.api_volume_test.TestVolumes" name="test_create_volume" time="7.929" /><testcase classname="tests.integration.api_volume_test.TestVolumes" name="test_create_volume_invalid_driver" time="7.906"><failure message="docker.errors.APIError: 500 Server Error for http+docker://localhost/v1.40/volumes/create: Internal Server Error (&quot;volume perfectcherryblossom uses volume plugin invalid.driver but it could not be retrieved: no volume plugin with name invalid.driver available: required plugin missing&quot;)">docker/api/client.py:296: in _raise_for_status
    response.raise_for_status()
../../.virtualenvs/docker-py/lib/python3.9/site-packages/requests/models.py:953: in raise_for_status
    raise HTTPError(http_error_msg, response=self)
E   requests.exceptions.HTTPError: 500 Server Error: Internal Server Error for url: http+docker://localhost/v1.40/volumes/create

During handling of the above exception, another exception occurred:
/home/ubuntu/docker-py/tests/integration/api_volume_test.py:22: in test_create_volume_invalid_driver
    ???
docker/api/volume.py:89: in create_volume
    return self._result(self._post_json(url, data=data), True)
docker/api/client.py:302: in _result
    self._raise_for_status(response)
docker/api/client.py:298: in _raise_for_status
    raise create_api_error_from_http_exception(e)
docker/errors.py:31: in create_api_error_from_http_exception
    raise cls(e, response=response, explanation=explanation)
E   docker.errors.APIError: 500 Server Error for http+docker://localhost/v1.40/volumes/create: Internal Server Error ("volume perfectcherryblossom uses volume plugin invalid.driver but it could not be retrieved: no volume plugin with name invalid.driver available: required plugin missing")</failure><system-out>--------------------------------- Captured Log ---------------------------------

--------------------------------- Captured Out ---------------------------------

</system-out><system-err>--------------------------------- Captured Err ---------------------------------

</system-err></testcase><testcase classname="tests.integration.api_volume_test.TestVolumes" name="test_force_remove_volume" time="7.854" /><testcase classname="tests.integration.api_volume_test.TestVolumes" name="test_inspect_nonexistent_volume" time="7.866" /><testcase classname="tests.integration.api_volume_test.TestVolumes" name="test_inspect_volume" time="7.833"><failure message="AssertionError: assert {'CreatedAt':...l/_data', ...} == {'CreatedAt':...l/_data', ...}&#10;  Omitting 6 identical items, use -vv to show&#10;  Differing items:&#10;  {'Options': None} != {'Options': {}}&#10;  Full diff:&#10;    {&#10;     'CreatedAt': '2021-10-29T12:40:33+02:00',&#10;     'Driver': 'local',...&#10;  &#10;  ...Full output truncated (10 lines hidden), use '-vv' to show">/home/ubuntu/docker-py/tests/integration/api_volume_test.py:38: in test_inspect_volume
    ???
E   AssertionError: assert {'CreatedAt':...l/_data', ...} == {'CreatedAt':...l/_data', ...}
E     Omitting 6 identical items, use -vv to show
E     Differing items:
E     {'Options': None} != {'Options': {}}
E     Full diff:
E       {
E        'CreatedAt': '2021-10-29T12:40:33+02:00',
E        'Driver': 'local',...
E     
E     ...Full output truncated (10 lines hidden), use '-vv' to show</failure><system-out>--------------------------------- Captured Log ---------------------------------

--------------------------------- Captured Out ---------------------------------

</system-out><system-err>--------------------------------- Captured Err ---------------------------------

</system-err></testcase><testcase classname="tests.integration.api_volume_test.TestVolumes" name="test_list_volumes" time="7.902"><failure message="AssertionError: assert {'CreatedAt': '2021-10-29T12:40:41+02:00', 'Driver': 'local', 'Labels': {}, 'Mountpoint': '/home/riyad/podman/storage/volumes/imperishablenight/_data', ...} in [{'CreatedAt': '2021-10-29T11:53:22+02:00', 'Driver': 'local', 'Labels': {}, 'Mountpoint': '/home/riyad/podman/storage...00', 'Driver': 'local', 'Labels': {}, 'Mountpoint': '/home/riyad/podman/storage/volumes/imperishablenight/_data', ...}]">/home/ubuntu/docker-py/tests/integration/api_volume_test.py:31: in test_list_volumes
    ???
E   AssertionError: assert {'CreatedAt': '2021-10-29T12:40:41+02:00', 'Driver': 'local', 'Labels': {}, 'Mountpoint': '/home/riyad/podman/storage/volumes/imperishablenight/_data', ...} in [{'CreatedAt': '2021-10-29T11:53:22+02:00', 'Driver': 'local', 'Labels': {}, 'Mountpoint': '/home/riyad/podman/storage...00', 'Driver': 'local', 'Labels': {}, 'Mountpoint': '/home/riyad/podman/storage/volumes/imperishablenight/_data', ...}]</failure><system-out>--------------------------------- Captured Log ---------------------------------

--------------------------------- Captured Out ---------------------------------

</system-out><system-err>--------------------------------- Captured Err ---------------------------------

</system-err></testcase><testcase classname="tests.integration.api_volume_test.TestVolumes" name="test_prune_volumes" time="7.840" /><testcase classname="tests.integration.api_volume_test.TestVolumes" name="test_remove_nonexistent_volume" time="7.857" /><testcase classname="tests.integration.api_volume_test.TestVolumes" name="test_remove_volume" time="9.808" /><testcase classname="tests.integration.client_test.ClientTest" name="test_df" time="0.065" /><testcase classname="tests.integration.client_test.ClientTest" name="test_info" time="2.085" /><testcase classname="tests.integration.client_test.ClientTest" name="test_ping" time="0.006" /><testcase classname="tests.integration.client_test.ClientTest" name="test_version" time="2.762" /><testcase classname="tests.integration.client_test.CancellableEventsTest" name="test_cancel_events" time="2.007" /><testcase classname="tests.integration.context_api_test.ContextLifecycleTest" name="test_context_remove" time="8.021" /><testcase classname="tests.integration.context_api_test.ContextLifecycleTest" name="test_lifecycle" time="8.173" /><testcase classname="tests.integration.context_api_test.ContextLifecycleTest" name="test_load_context_without_orchestrator" time="8.124" /><testcase classname="tests.integration.errors_test.ErrorsTest" name="test_api_error_parses_json" time="8.202"><failure message="AssertionError: assert 'You cannot remove a running container' in 'cannot remove container 7638410a0cd99fb4cd3fa345ecb29852033465d06707936fb224ffba917f2d9c as it is running - running or paused containers cannot be removed without force: container state improper'">/home/ubuntu/docker-py/tests/integration/errors_test.py:13: in test_api_error_parses_json
    ???
E   AssertionError: assert 'You cannot remove a running container' in 'cannot remove container 7638410a0cd99fb4cd3fa345ecb29852033465d06707936fb224ffba917f2d9c as it is running - running or paused containers cannot be removed without force: container state improper'</failure><system-out>--------------------------------- Captured Log ---------------------------------

--------------------------------- Captured Out ---------------------------------

</system-out><system-err>--------------------------------- Captured Err ---------------------------------

</system-err></testcase><testcase classname="tests.integration.models_containers_test.ContainerCollectionTest" name="test_get" time="5.789"><failure message="AssertionError: assert 'docker.io/li...alpine:latest' == 'alpine'&#10;  - alpine&#10;  + docker.io/library/alpine:latest">/home/ubuntu/docker-py/tests/integration/models_containers_test.py:189: in test_get
    ???
E   AssertionError: assert 'docker.io/li...alpine:latest' == 'alpine'
E     - alpine
E     + docker.io/library/alpine:latest</failure><system-out>--------------------------------- Captured Log ---------------------------------

--------------------------------- Captured Out ---------------------------------

</system-out><system-err>--------------------------------- Captured Err ---------------------------------

</system-err></testcase><testcase classname="tests.integration.models_containers_test.ContainerCollectionTest" name="test_list" time="5.933"><failure message="AssertionError: assert 'docker.io/li...alpine:latest' == 'alpine'&#10;  - alpine&#10;  + docker.io/library/alpine:latest">/home/ubuntu/docker-py/tests/integration/models_containers_test.py:202: in test_list
    ???
E   AssertionError: assert 'docker.io/li...alpine:latest' == 'alpine'
E     - alpine
E     + docker.io/library/alpine:latest</failure><system-out>--------------------------------- Captured Log ---------------------------------

--------------------------------- Captured Out ---------------------------------

</system-out><system-err>--------------------------------- Captured Err ---------------------------------

</system-err></testcase><testcase classname="tests.integration.models_containers_test.ContainerCollectionTest" name="test_list_sparse" time="5.850"><failure message="AssertionError: assert 'docker.io/li...alpine:latest' == 'alpine'&#10;  - alpine&#10;  + docker.io/library/alpine:latest">/home/ubuntu/docker-py/tests/integration/models_containers_test.py:220: in test_list_sparse
    ???
E   AssertionError: assert 'docker.io/li...alpine:latest' == 'alpine'
E     - alpine
E     + docker.io/library/alpine:latest</failure><system-out>--------------------------------- Captured Log ---------------------------------

--------------------------------- Captured Out ---------------------------------

</system-out><system-err>--------------------------------- Captured Err ---------------------------------

</system-err></testcase><testcase classname="tests.integration.models_containers_test.ContainerCollectionTest" name="test_run" time="5.896" /><testcase classname="tests.integration.models_containers_test.ContainerCollectionTest" name="test_run_detach" time="5.954"><failure message="AssertionError: assert 'docker.io/li...alpine:latest' == 'alpine'&#10;  - alpine&#10;  + docker.io/library/alpine:latest">/home/ubuntu/docker-py/tests/integration/models_containers_test.py:26: in test_run_detach
    ???
E   AssertionError: assert 'docker.io/li...alpine:latest' == 'alpine'
E     - alpine
E     + docker.io/library/alpine:latest</failure><system-out>--------------------------------- Captured Log ---------------------------------

--------------------------------- Captured Out ---------------------------------

</system-out><system-err>--------------------------------- Captured Err ---------------------------------

</system-err></testcase><testcase classname="tests.integration.models_containers_test.ContainerCollectionTest" name="test_run_with_auto_remove" time="7.938" /><testcase classname="tests.integration.models_containers_test.ContainerCollectionTest" name="test_run_with_auto_remove_error" time="7.907"><failure message="docker.errors.NotFound: 404 Client Error for http+docker://localhost/v1.40/containers/c9be59401100d14161fa4ef037f975eff8d82a85b42a825f7923238b00e7870e/json: Not Found (&quot;no container with name or ID &quot;c9be59401100d14161fa4ef037f975eff8d82a85b42a825f7923238b00e7870e&quot; found: no such container&quot;)">docker/api/client.py:296: in _raise_for_status
    response.raise_for_status()
../../.virtualenvs/docker-py/lib/python3.9/site-packages/requests/models.py:953: in raise_for_status
    raise HTTPError(http_error_msg, response=self)
E   requests.exceptions.HTTPError: 404 Client Error: Not Found for url: http+docker://localhost/v1.40/containers/c9be59401100d14161fa4ef037f975eff8d82a85b42a825f7923238b00e7870e/json

During handling of the above exception, another exception occurred:
/home/ubuntu/docker-py/tests/integration/models_containers_test.py:139: in test_run_with_auto_remove_error
    ???
docker/models/containers.py:835: in run
    out = container.logs(
docker/models/containers.py:306: in logs
    return self.client.api.logs(self.id, **kwargs)
docker/utils/decorators.py:19: in wrapped
    return f(self, resource_id, *args, **kwargs)
docker/api/container.py:869: in logs
    output = self._get_result(container, stream, res)
docker/api/client.py:495: in _get_result
    return self._get_result_tty(stream, res, self._check_is_tty(container))
docker/utils/decorators.py:19: in wrapped
    return f(self, resource_id, *args, **kwargs)
docker/api/client.py:491: in _check_is_tty
    cont = self.inspect_container(container)
docker/utils/decorators.py:19: in wrapped
    return f(self, resource_id, *args, **kwargs)
docker/api/container.py:771: in inspect_container
    return self._result(
docker/api/client.py:302: in _result
    self._raise_for_status(response)
docker/api/client.py:298: in _raise_for_status
    raise create_api_error_from_http_exception(e)
docker/errors.py:31: in create_api_error_from_http_exception
    raise cls(e, response=response, explanation=explanation)
E   docker.errors.NotFound: 404 Client Error for http+docker://localhost/v1.40/containers/c9be59401100d14161fa4ef037f975eff8d82a85b42a825f7923238b00e7870e/json: Not Found ("no container with name or ID "c9be59401100d14161fa4ef037f975eff8d82a85b42a825f7923238b00e7870e" found: no such container")</failure><system-out>--------------------------------- Captured Log ---------------------------------

--------------------------------- Captured Out ---------------------------------

</system-out><system-err>--------------------------------- Captured Err ---------------------------------

</system-err></testcase><testcase classname="tests.integration.models_containers_test.ContainerCollectionTest" name="test_run_with_error" time="5.687" /><testcase classname="tests.integration.models_containers_test.ContainerCollectionTest" name="test_run_with_image_that_does_not_exist" time="5.590"><failure message="docker.errors.NotFound: 404 Client Error for http+docker://localhost/v1.40/containers/create: Not Found (&quot;dockerpytest_does_not_exist: image not known&quot;)">docker/api/client.py:296: in _raise_for_status
    response.raise_for_status()
../../.virtualenvs/docker-py/lib/python3.9/site-packages/requests/models.py:953: in raise_for_status
    raise HTTPError(http_error_msg, response=self)
E   requests.exceptions.HTTPError: 404 Client Error: Not Found for url: http+docker://localhost/v1.40/containers/create

During handling of the above exception, another exception occurred:
/home/ubuntu/docker-py/tests/integration/models_containers_test.py:41: in test_run_with_image_that_does_not_exist
    ???
docker/models/containers.py:819: in run
    container = self.create(image=image, command=command,
docker/models/containers.py:878: in create
    resp = self.client.api.create_container(**create_kwargs)
docker/api/container.py:428: in create_container
    return self.create_container_from_config(config, name)
docker/api/container.py:439: in create_container_from_config
    return self._result(res, True)
docker/api/client.py:302: in _result
    self._raise_for_status(response)
docker/api/client.py:298: in _raise_for_status
    raise create_api_error_from_http_exception(e)
docker/errors.py:31: in create_api_error_from_http_exception
    raise cls(e, response=response, explanation=explanation)
E   docker.errors.NotFound: 404 Client Error for http+docker://localhost/v1.40/containers/create: Not Found ("dockerpytest_does_not_exist: image not known")</failure><system-out>--------------------------------- Captured Log ---------------------------------

--------------------------------- Captured Out ---------------------------------

</system-out><system-err>--------------------------------- Captured Err ---------------------------------

</system-err></testcase><testcase classname="tests.integration.models_containers_test.ContainerCollectionTest" name="test_run_with_json_file_driver" time="6.013" /><testcase classname="tests.integration.models_containers_test.ContainerCollectionTest" name="test_run_with_named_volume" time="6.425" /><testcase classname="tests.integration.models_containers_test.ContainerCollectionTest" name="test_run_with_network" time="6.078" /><testcase classname="tests.integration.models_containers_test.ContainerCollectionTest" name="test_run_with_none_driver" time="5.970" /><testcase classname="tests.integration.models_containers_test.ContainerCollectionTest" name="test_run_with_proxy_config" time="5.850" /><testcase classname="tests.integration.models_containers_test.ContainerCollectionTest" name="test_run_with_streamed_logs" time="5.774" /><testcase classname="tests.integration.models_containers_test.ContainerCollectionTest" name="test_run_with_streamed_logs_and_cancel" time="5.000"><failure message="Failed: Timeout &gt;5.0s">tests/integration/base.py:30: in tearDown
    client = docker.from_env(version=TEST_API_VERSION)
docker/client.py:96: in from_env
    return cls(
docker/client.py:45: in __init__
    self.api = APIClient(*args, **kwargs)
docker/api/client.py:197: in __init__
    self._version = self._retrieve_server_version()
docker/api/client.py:214: in _retrieve_server_version
    return self.version(api_version=False)["ApiVersion"]
docker/api/daemon.py:181: in version
    return self._result(self._get(url), json=True)
docker/utils/decorators.py:46: in inner
    return f(self, *args, **kwargs)
docker/api/client.py:251: in _get
    return self.get(url, **self._set_request_timeout(kwargs))
../../.virtualenvs/docker-py/lib/python3.9/site-packages/requests/sessions.py:555: in get
    return self.request('GET', url, **kwargs)
../../.virtualenvs/docker-py/lib/python3.9/site-packages/requests/sessions.py:542: in request
    resp = self.send(prep, **send_kwargs)
../../.virtualenvs/docker-py/lib/python3.9/site-packages/requests/sessions.py:655: in send
    r = adapter.send(request, **kwargs)
../../.virtualenvs/docker-py/lib/python3.9/site-packages/requests/adapters.py:439: in send
    resp = conn.urlopen(
../../.virtualenvs/docker-py/lib/python3.9/site-packages/urllib3/connectionpool.py:699: in urlopen
    httplib_response = self._make_request(
../../.virtualenvs/docker-py/lib/python3.9/site-packages/urllib3/connectionpool.py:445: in _make_request
    six.raise_from(e, None)
../../.virtualenvs/docker-py/lib/python3.9/site-packages/urllib3/connectionpool.py:440: in _make_request
    httplib_response = conn.getresponse()
/usr/lib/python3.9/http/client.py:1371: in getresponse
    response.begin()
/usr/lib/python3.9/http/client.py:319: in begin
    version, status, reason = self._read_status()
/usr/lib/python3.9/http/client.py:280: in _read_status
    line = str(self.fp.readline(_MAXLINE + 1), "iso-8859-1")
/usr/lib/python3.9/socket.py:704: in readinto
    return self._sock.recv_into(b)
E   Failed: Timeout &gt;5.0s</failure><system-out>--------------------------------- Captured Log ---------------------------------

--------------------------------- Captured Out ---------------------------------

</system-out><system-err>--------------------------------- Captured Err ---------------------------------

</system-err></testcase><testcase classname="tests.integration.models_containers_test.ContainerCollectionTest" name="test_run_with_volume" time="6.486" /><testcase classname="tests.integration.models_containers_test.ContainerTest" name="test_commit" time="7.762" /><testcase classname="tests.integration.models_containers_test.ContainerTest" name="test_create_with_volume_driver" time="5.799"><failure message="AssertionError: assert '' == 'foo'&#10;  - foo">/home/ubuntu/docker-py/tests/integration/models_containers_test.py:456: in test_create_with_volume_driver
    ???
E   AssertionError: assert '' == 'foo'
E     - foo</failure><system-out>--------------------------------- Captured Log ---------------------------------

--------------------------------- Captured Out ---------------------------------

</system-out><system-err>--------------------------------- Captured Err ---------------------------------

</system-err></testcase><testcase classname="tests.integration.models_containers_test.ContainerTest" name="test_diff" time="6.072"><failure message="AssertionError: assert [{'Kind': 1, ...ath': '/etc'}] == [{'Kind': 1, 'Path': '/test'}]&#10;  Left contains one more item: {'Kind': 0, 'Path': '/etc'}&#10;  Full diff:&#10;  - [{'Kind': 1, 'Path': '/test'}]&#10;  + [{'Kind': 1, 'Path': '/test'}, {'Kind': 0, 'Path': '/etc'}]">/home/ubuntu/docker-py/tests/integration/models_containers_test.py:251: in test_diff
    ???
E   AssertionError: assert [{'Kind': 1, ...ath': '/etc'}] == [{'Kind': 1, 'Path': '/test'}]
E     Left contains one more item: {'Kind': 0, 'Path': '/etc'}
E     Full diff:
E     - [{'Kind': 1, 'Path': '/test'}]
E     + [{'Kind': 1, 'Path': '/test'}, {'Kind': 0, 'Path': '/etc'}]</failure><system-out>--------------------------------- Captured Log ---------------------------------

--------------------------------- Captured Out ---------------------------------

</system-out><system-err>--------------------------------- Captured Err ---------------------------------

</system-err></testcase><testcase classname="tests.integration.models_containers_test.ContainerTest" name="test_exec_run_failed" time="6.430"><failure message="AssertionError: assert 127 == 126&#10;  +127&#10;  -126">/home/ubuntu/docker-py/tests/integration/models_containers_test.py:270: in test_exec_run_failed
    ???
E   AssertionError: assert 127 == 126
E     +127
E     -126</failure><system-out>--------------------------------- Captured Log ---------------------------------

--------------------------------- Captured Out ---------------------------------

</system-out><system-err>--------------------------------- Captured Err ---------------------------------

</system-err></testcase><testcase classname="tests.integration.models_containers_test.ContainerTest" name="test_exec_run_success" time="6.111" /><testcase classname="tests.integration.models_containers_test.ContainerTest" name="test_kill" time="5.801"><failure message="AssertionError: assert 'stopped' == 'exited'&#10;  - exited&#10;  + stopped">/home/ubuntu/docker-py/tests/integration/models_containers_test.py:281: in test_kill
    ???
E   AssertionError: assert 'stopped' == 'exited'
E     - exited
E     + stopped</failure><system-out>--------------------------------- Captured Log ---------------------------------

--------------------------------- Captured Out ---------------------------------

</system-out><system-err>--------------------------------- Captured Err ---------------------------------

</system-err></testcase><testcase classname="tests.integration.models_containers_test.ContainerTest" name="test_logs" time="5.950" /><testcase classname="tests.integration.models_containers_test.ContainerTest" name="test_pause" time="6.176" /><testcase classname="tests.integration.models_containers_test.ContainerTest" name="test_ports_target_list" time="5.892"><failure message="docker.errors.APIError: 500 Server Error for http+docker://localhost/v1.40/containers/47fe60a680c27785de421bae39caecbae36e099bc9877ca659d1865a544e6752/start: Internal Server Error (&quot;could not find &quot;rootlessport&quot; in one of [/usr/local/libexec/podman /usr/local/lib/podman /usr/libexec/podman /usr/lib/podman]&quot;)">docker/api/client.py:296: in _raise_for_status
    response.raise_for_status()
../../.virtualenvs/docker-py/lib/python3.9/site-packages/requests/models.py:953: in raise_for_status
    raise HTTPError(http_error_msg, response=self)
E   requests.exceptions.HTTPError: 500 Server Error: Internal Server Error for url: http+docker://localhost/v1.40/containers/47fe60a680c27785de421bae39caecbae36e099bc9877ca659d1865a544e6752/start

During handling of the above exception, another exception occurred:
/home/ubuntu/docker-py/tests/integration/models_containers_test.py:394: in test_ports_target_list
    ???
docker/models/containers.py:826: in run
    container.start()
docker/models/containers.py:404: in start
    return self.client.api.start(self.id, **kwargs)
docker/utils/decorators.py:19: in wrapped
    return f(self, resource_id, *args, **kwargs)
docker/api/container.py:1109: in start
    self._raise_for_status(res)
docker/api/client.py:298: in _raise_for_status
    raise create_api_error_from_http_exception(e)
docker/errors.py:31: in create_api_error_from_http_exception
    raise cls(e, response=response, explanation=explanation)
E   docker.errors.APIError: 500 Server Error for http+docker://localhost/v1.40/containers/47fe60a680c27785de421bae39caecbae36e099bc9877ca659d1865a544e6752/start: Internal Server Error ("could not find "rootlessport" in one of [/usr/local/libexec/podman /usr/local/lib/podman /usr/libexec/podman /usr/lib/podman]")</failure><system-out>--------------------------------- Captured Log ---------------------------------

--------------------------------- Captured Out ---------------------------------

</system-out><system-err>--------------------------------- Captured Err ---------------------------------

</system-err></testcase><testcase classname="tests.integration.models_containers_test.ContainerTest" name="test_ports_target_none" time="5.641"><failure message="docker.errors.APIError: 500 Server Error for http+docker://localhost/v1.40/containers/2e92bb184e0249b58aaa3a71057f5766aa1ca544da5a5c57c2b3c2bb320a8324/start: Internal Server Error (&quot;could not find &quot;rootlessport&quot; in one of [/usr/local/libexec/podman /usr/local/lib/podman /usr/libexec/podman /usr/lib/podman]&quot;)">docker/api/client.py:296: in _raise_for_status
    response.raise_for_status()
../../.virtualenvs/docker-py/lib/python3.9/site-packages/requests/models.py:953: in raise_for_status
    raise HTTPError(http_error_msg, response=self)
E   requests.exceptions.HTTPError: 500 Server Error: Internal Server Error for url: http+docker://localhost/v1.40/containers/2e92bb184e0249b58aaa3a71057f5766aa1ca544da5a5c57c2b3c2bb320a8324/start

During handling of the above exception, another exception occurred:
/home/ubuntu/docker-py/tests/integration/models_containers_test.py:354: in test_ports_target_none
    ???
docker/models/containers.py:826: in run
    container.start()
docker/models/containers.py:404: in start
    return self.client.api.start(self.id, **kwargs)
docker/utils/decorators.py:19: in wrapped
    return f(self, resource_id, *args, **kwargs)
docker/api/container.py:1109: in start
    self._raise_for_status(res)
docker/api/client.py:298: in _raise_for_status
    raise create_api_error_from_http_exception(e)
docker/errors.py:31: in create_api_error_from_http_exception
    raise cls(e, response=response, explanation=explanation)
E   docker.errors.APIError: 500 Server Error for http+docker://localhost/v1.40/containers/2e92bb184e0249b58aaa3a71057f5766aa1ca544da5a5c57c2b3c2bb320a8324/start: Internal Server Error ("could not find "rootlessport" in one of [/usr/local/libexec/podman /usr/local/lib/podman /usr/libexec/podman /usr/lib/podman]")</failure><system-out>--------------------------------- Captured Log ---------------------------------

--------------------------------- Captured Out ---------------------------------

</system-out><system-err>--------------------------------- Captured Err ---------------------------------

</system-err></testcase><testcase classname="tests.integration.models_containers_test.ContainerTest" name="test_ports_target_tuple" time="5.701"><failure message="docker.errors.APIError: 500 Server Error for http+docker://localhost/v1.40/containers/03052ed359a54ef06b64c033aa79cee8f688534aa77bbbae92888aeee95311b6/start: Internal Server Error (&quot;could not find &quot;rootlessport&quot; in one of [/usr/local/libexec/podman /usr/local/lib/podman /usr/libexec/podman /usr/lib/podman]&quot;)">docker/api/client.py:296: in _raise_for_status
    response.raise_for_status()
../../.virtualenvs/docker-py/lib/python3.9/site-packages/requests/models.py:953: in raise_for_status
    raise HTTPError(http_error_msg, response=self)
E   requests.exceptions.HTTPError: 500 Server Error: Internal Server Error for url: http+docker://localhost/v1.40/containers/03052ed359a54ef06b64c033aa79cee8f688534aa77bbbae92888aeee95311b6/start

During handling of the above exception, another exception occurred:
/home/ubuntu/docker-py/tests/integration/models_containers_test.py:374: in test_ports_target_tuple
    ???
docker/models/containers.py:826: in run
    container.start()
docker/models/containers.py:404: in start
    return self.client.api.start(self.id, **kwargs)
docker/utils/decorators.py:19: in wrapped
    return f(self, resource_id, *args, **kwargs)
docker/api/container.py:1109: in start
    self._raise_for_status(res)
docker/api/client.py:298: in _raise_for_status
    raise create_api_error_from_http_exception(e)
docker/errors.py:31: in create_api_error_from_http_exception
    raise cls(e, response=response, explanation=explanation)
E   docker.errors.APIError: 500 Server Error for http+docker://localhost/v1.40/containers/03052ed359a54ef06b64c033aa79cee8f688534aa77bbbae92888aeee95311b6/start: Internal Server Error ("could not find "rootlessport" in one of [/usr/local/libexec/podman /usr/local/lib/podman /usr/libexec/podman /usr/lib/podman]")</failure><system-out>--------------------------------- Captured Log ---------------------------------

--------------------------------- Captured Out ---------------------------------

</system-out><system-err>--------------------------------- Captured Err ---------------------------------

</system-err></testcase><testcase classname="tests.integration.models_containers_test.ContainerTest" name="test_remove" time="6.560" /><testcase classname="tests.integration.models_containers_test.ContainerTest" name="test_rename" time="6.631" /><testcase classname="tests.integration.models_containers_test.ContainerTest" name="test_restart" time="16.841" /><testcase classname="tests.integration.models_containers_test.ContainerTest" name="test_start" time="6.544" /><testcase classname="tests.integration.models_containers_test.ContainerTest" name="test_stats" time="7.080" /><testcase classname="tests.integration.models_containers_test.ContainerTest" name="test_stop" time="6.426" /><testcase classname="tests.integration.models_containers_test.ContainerTest" name="test_top" time="6.233"><failure message="AssertionError: assert 'sleep 60' in ['1 root      0:00 sleep 60']">/home/ubuntu/docker-py/tests/integration/models_containers_test.py:425: in test_top
    ???
E   AssertionError: assert 'sleep 60' in ['1 root      0:00 sleep 60']</failure><system-out>--------------------------------- Captured Log ---------------------------------

--------------------------------- Captured Out ---------------------------------

</system-out><system-err>--------------------------------- Captured Err ---------------------------------

</system-err></testcase><testcase classname="tests.integration.models_containers_test.ContainerTest" name="test_update" time="6.543"><failure message="docker.errors.NotFound: 404 Client Error for http+docker://localhost/v1.40/containers/b1c2c8b105b88813b21931e315c689aa155b93aae57894ee2332aed20d748e69/update: Not Found (&quot;b'Not Found'&quot;)">docker/api/client.py:296: in _raise_for_status
    response.raise_for_status()
../../.virtualenvs/docker-py/lib/python3.9/site-packages/requests/models.py:953: in raise_for_status
    raise HTTPError(http_error_msg, response=self)
E   requests.exceptions.HTTPError: 404 Client Error: Not Found for url: http+docker://localhost/v1.40/containers/b1c2c8b105b88813b21931e315c689aa155b93aae57894ee2332aed20d748e69/update

During handling of the above exception, another exception occurred:
/home/ubuntu/docker-py/tests/integration/models_containers_test.py:433: in test_update
    ???
docker/models/containers.py:489: in update
    return self.client.api.update_container(self.id, **kwargs)
docker/utils/decorators.py:34: in wrapper
    return f(self, *args, **kwargs)
docker/utils/decorators.py:19: in wrapped
    return f(self, resource_id, *args, **kwargs)
docker/api/container.py:1268: in update_container
    return self._result(res, True)
docker/api/client.py:302: in _result
    self._raise_for_status(response)
docker/api/client.py:298: in _raise_for_status
    raise create_api_error_from_http_exception(e)
docker/errors.py:31: in create_api_error_from_http_exception
    raise cls(e, response=response, explanation=explanation)
E   docker.errors.NotFound: 404 Client Error for http+docker://localhost/v1.40/containers/b1c2c8b105b88813b21931e315c689aa155b93aae57894ee2332aed20d748e69/update: Not Found ("b'Not Found'")</failure><system-out>--------------------------------- Captured Log ---------------------------------

--------------------------------- Captured Out ---------------------------------

</system-out><system-err>--------------------------------- Captured Err ---------------------------------

</system-err></testcase><testcase classname="tests.integration.models_containers_test.ContainerTest" name="test_wait" time="6.234" /><testcase classname="tests.integration.models_images_test.ImageCollectionTest" name="test_build" time="6.484" /><testcase classname="tests.integration.models_images_test.ImageCollectionTest" name="test_build_with_error" time="5.878"><failure message="AssertionError: assert &quot;The command '/bin/sh -c exit 1' returned a non-zero code: 1&quot; in 'docker.errors.BuildError: error building at STEP &quot;RUN exit 1&quot;: error while running runtime: exit status 1'&#10; +  where 'docker.errors.BuildError: error building at STEP &quot;RUN exit 1&quot;: error while running runtime: exit status 1' = &lt;bound method ExceptionInfo.exconly of &lt;ExceptionInfo BuildError('error building at STEP &quot;RUN exit 1&quot;: error while running runtime: exit status 1\n') tblen=2&gt;&gt;()&#10; +    where &lt;bound method ExceptionInfo.exconly of &lt;ExceptionInfo BuildError('error building at STEP &quot;RUN exit 1&quot;: error while running runtime: exit status 1\n') tblen=2&gt;&gt; = &lt;ExceptionInfo BuildError('error building at STEP &quot;RUN exit 1&quot;: error while running runtime: exit status 1\n') tblen=2&gt;.exconly">/home/ubuntu/docker-py/tests/integration/models_images_test.py:30: in test_build_with_error
    ???
E   AssertionError: assert "The command '/bin/sh -c exit 1' returned a non-zero code: 1" in 'docker.errors.BuildError: error building at STEP "RUN exit 1": error while running runtime: exit status 1'
E    +  where 'docker.errors.BuildError: error building at STEP "RUN exit 1": error while running runtime: exit status 1' = &lt;bound method ExceptionInfo.exconly of &lt;ExceptionInfo BuildError('error building at STEP "RUN exit 1": error while running runtime: exit status 1\n') tblen=2&gt;&gt;()
E    +    where &lt;bound method ExceptionInfo.exconly of &lt;ExceptionInfo BuildError('error building at STEP "RUN exit 1": error while running runtime: exit status 1\n') tblen=2&gt;&gt; = &lt;ExceptionInfo BuildError('error building at STEP "RUN exit 1": error while running runtime: exit status 1\n') tblen=2&gt;.exconly</failure><system-out>--------------------------------- Captured Log ---------------------------------

--------------------------------- Captured Out ---------------------------------

</system-out><system-err>--------------------------------- Captured Err ---------------------------------

</system-err></testcase><testcase classname="tests.integration.models_images_test.ImageCollectionTest" name="test_build_with_multiple_success" time="6.650" /><testcase classname="tests.integration.models_images_test.ImageCollectionTest" name="test_build_with_success_build_output" time="6.052" /><testcase classname="tests.integration.models_images_test.ImageCollectionTest" name="test_list" time="7.939" /><testcase classname="tests.integration.models_images_test.ImageCollectionTest" name="test_list_with_repository" time="7.654" /><testcase classname="tests.integration.models_images_test.ImageCollectionTest" name="test_load_error" time="5.522"><failure message="docker.errors.APIError: 500 Server Error for http+docker://localhost/v1.40/images/load: Internal Server Error (&quot;failed to load image: payload does not match any of the supported image formats:&#10; * docker-archive: loading tar component manifest.json: unexpected EOF&#10; * oci: initializing source oci:/var/tmp/api_load.tar792841159:: open /var/tmp/api_load.tar792841159/index.json: not a directory&#10; * oci-archive: creating temp directory: untarring file &quot;/var/tmp/oci3953166116&quot;: unexpected EOF&#10; * dir: determining manifest MIME type for dir:/var/tmp/api_load.tar792841159: open /var/tmp/api_load.tar792841159/manifest.json: not a directory&quot;)">docker/api/client.py:296: in _raise_for_status
    response.raise_for_status()
../../.virtualenvs/docker-py/lib/python3.9/site-packages/requests/models.py:953: in raise_for_status
    raise HTTPError(http_error_msg, response=self)
E   requests.exceptions.HTTPError: 500 Server Error: Internal Server Error for url: http+docker://localhost/v1.40/images/load

During handling of the above exception, another exception occurred:
/home/ubuntu/docker-py/tests/integration/models_images_test.py:98: in test_load_error
    ???
docker/models/images.py:382: in load
    for chunk in resp:
docker/api/client.py:386: in _stream_helper
    yield self._result(response, json=decode)
docker/api/client.py:302: in _result
    self._raise_for_status(response)
docker/api/client.py:298: in _raise_for_status
    raise create_api_error_from_http_exception(e)
docker/errors.py:31: in create_api_error_from_http_exception
    raise cls(e, response=response, explanation=explanation)
E   docker.errors.APIError: 500 Server Error for http+docker://localhost/v1.40/images/load: Internal Server Error ("failed to load image: payload does not match any of the supported image formats:
E    * docker-archive: loading tar component manifest.json: unexpected EOF
E    * oci: initializing source oci:/var/tmp/api_load.tar792841159:: open /var/tmp/api_load.tar792841159/index.json: not a directory
E    * oci-archive: creating temp directory: untarring file "/var/tmp/oci3953166116": unexpected EOF
E    * dir: determining manifest MIME type for dir:/var/tmp/api_load.tar792841159: open /var/tmp/api_load.tar792841159/manifest.json: not a directory")</failure><system-out>--------------------------------- Captured Log ---------------------------------

--------------------------------- Captured Out ---------------------------------

</system-out><system-err>--------------------------------- Captured Err ---------------------------------

</system-err></testcase><testcase classname="tests.integration.models_images_test.ImageCollectionTest" name="test_pull" time="7.949"><failure message="AssertionError: assert 'alpine:latest' in ['docker.io/library/alpine:latest', 'docker.io/library/alpine:3.14']">/home/ubuntu/docker-py/tests/integration/models_images_test.py:71: in test_pull
    ???
E   AssertionError: assert 'alpine:latest' in ['docker.io/library/alpine:latest', 'docker.io/library/alpine:3.14']</failure><system-out>--------------------------------- Captured Log ---------------------------------

--------------------------------- Captured Out ---------------------------------

</system-out><system-err>--------------------------------- Captured Err ---------------------------------

</system-err></testcase><testcase classname="tests.integration.models_images_test.ImageCollectionTest" name="test_pull_multiple" time="8.313"><failure message="AssertionError: assert False&#10; +  where False = any([False])">/home/ubuntu/docker-py/tests/integration/models_images_test.py:91: in test_pull_multiple
    ???
E   AssertionError: assert False
E    +  where False = any([False])</failure><system-out>--------------------------------- Captured Log ---------------------------------

--------------------------------- Captured Out ---------------------------------

</system-out><system-err>--------------------------------- Captured Err ---------------------------------

</system-err></testcase><testcase classname="tests.integration.models_images_test.ImageCollectionTest" name="test_pull_with_sha" time="8.273"><failure message="AssertionError: assert 'hello-world@sha256:083de497cff944f969d8499ab94f07134c50bcf5e6b9559b27182d3fa80ce3f7' in ['docker.io/library/hello-world@sha256:083de497cff944f969d8499ab94f07134c50bcf5e6b9559b27182d3fa80ce3f7', 'docker.io/library/hello-world@sha256:8072a54ebb3bc136150e2f2860f00a7bf45f13eeb917cca2430fcd0054c8e51b']">/home/ubuntu/docker-py/tests/integration/models_images_test.py:85: in test_pull_with_sha
    ???
E   AssertionError: assert 'hello-world@sha256:083de497cff944f969d8499ab94f07134c50bcf5e6b9559b27182d3fa80ce3f7' in ['docker.io/library/hello-world@sha256:083de497cff944f969d8499ab94f07134c50bcf5e6b9559b27182d3fa80ce3f7', 'docker.io/library/hello-world@sha256:8072a54ebb3bc136150e2f2860f00a7bf45f13eeb917cca2430fcd0054c8e51b']</failure><system-out>--------------------------------- Captured Log ---------------------------------

--------------------------------- Captured Out ---------------------------------

</system-out><system-err>--------------------------------- Captured Err ---------------------------------

</system-err></testcase><testcase classname="tests.integration.models_images_test.ImageCollectionTest" name="test_pull_with_tag" time="7.974"><failure message="AssertionError: assert 'alpine:3.10' in ['docker.io/library/alpine:3.10']">/home/ubuntu/docker-py/tests/integration/models_images_test.py:76: in test_pull_with_tag
    ???
E   AssertionError: assert 'alpine:3.10' in ['docker.io/library/alpine:3.10']</failure><system-out>--------------------------------- Captured Log ---------------------------------

--------------------------------- Captured Out ---------------------------------

</system-out><system-err>--------------------------------- Captured Err ---------------------------------

</system-err></testcase><testcase classname="tests.integration.models_images_test.ImageCollectionTest" name="test_save_and_load" time="5.402" /><testcase classname="tests.integration.models_images_test.ImageCollectionTest" name="test_save_and_load_repo_name" time="5.178"><failure message="docker.errors.InvalidArgument: dockerpytest_625989a0bf805545:latest is not a valid tag for this image">/home/ubuntu/docker-py/tests/integration/models_images_test.py:122: in test_save_and_load_repo_name
    ???
docker/models/images.py:96: in save
    raise InvalidArgument(
E   docker.errors.InvalidArgument: dockerpytest_625989a0bf805545:latest is not a valid tag for this image</failure><system-out>--------------------------------- Captured Log ---------------------------------

--------------------------------- Captured Out ---------------------------------

</system-out><system-err>--------------------------------- Captured Err ---------------------------------

</system-err></testcase><testcase classname="tests.integration.models_images_test.ImageCollectionTest" name="test_save_name_error" time="5.724" /><testcase classname="tests.integration.models_images_test.ImageTest" name="test_tag_and_remove" time="7.739" /><testcase classname="tests.integration.models_networks_test.NetworkCollectionTest" name="test_create" time="8.588" /><testcase classname="tests.integration.models_networks_test.NetworkCollectionTest" name="test_get" time="6.442" /><testcase classname="tests.integration.models_networks_test.NetworkCollectionTest" name="test_list_remove" time="6.286" /><testcase classname="tests.integration.models_networks_test.NetworkTest" name="test_connect_disconnect" time="6.929" /><testcase classname="tests.integration.models_resources_test.ModelTest" name="test_reload" time="6.867" /><testcase classname="tests.integration.models_volumes_test.VolumesTest" name="test_create_get" time="5.631" /><testcase classname="tests.integration.models_volumes_test.VolumesTest" name="test_list_remove" time="6.989"><failure message="AssertionError: assert &lt;Volume: dockerpyte&gt; in []&#10; +  where [] = &lt;bound method VolumeCollection.list of &lt;docker.models.volumes.VolumeCollection object at 0x7fa7e65cad00&gt;&gt;(filters={'name': 'dockerpytest_'})&#10; +    where &lt;bound method VolumeCollection.list of &lt;docker.models.volumes.VolumeCollection object at 0x7fa7e65cad00&gt;&gt; = &lt;docker.models.volumes.VolumeCollection object at 0x7fa7e65cad00&gt;.list&#10; +      where &lt;docker.models.volumes.VolumeCollection object at 0x7fa7e65cad00&gt; = &lt;docker.client.DockerClient object at 0x7fa7e65cad60&gt;.volumes">/home/ubuntu/docker-py/tests/integration/models_volumes_test.py:26: in test_list_remove
    ???
E   AssertionError: assert &lt;Volume: dockerpyte&gt; in []
E    +  where [] = &lt;bound method VolumeCollection.list of &lt;docker.models.volumes.VolumeCollection object at 0x7fa7e65cad00&gt;&gt;(filters={'name': 'dockerpytest_'})
E    +    where &lt;bound method VolumeCollection.list of &lt;docker.models.volumes.VolumeCollection object at 0x7fa7e65cad00&gt;&gt; = &lt;docker.models.volumes.VolumeCollection object at 0x7fa7e65cad00&gt;.list
E    +      where &lt;docker.models.volumes.VolumeCollection object at 0x7fa7e65cad00&gt; = &lt;docker.client.DockerClient object at 0x7fa7e65cad60&gt;.volumes</failure><system-out>--------------------------------- Captured Log ---------------------------------

--------------------------------- Captured Out ---------------------------------

</system-out><system-err>--------------------------------- Captured Err ---------------------------------

</system-err></testcase><testcase classname="tests.integration.regression_test.TestRegressions" name="test_443_handle_nonchunked_response_in_stream" time="15.179"><failure message="Failed: DID NOT RAISE &lt;class 'docker.errors.APIError'&gt;">/home/ubuntu/docker-py/tests/integration/regression_test.py:15: in test_443_handle_nonchunked_response_in_stream
    ???
E   Failed: DID NOT RAISE &lt;class 'docker.errors.APIError'&gt;</failure><system-out>--------------------------------- Captured Log ---------------------------------

--------------------------------- Captured Out ---------------------------------

</system-out><system-err>--------------------------------- Captured Err ---------------------------------

</system-err></testcase><testcase classname="tests.integration.regression_test.TestRegressions" name="test_542_truncate_ids_client_side" time="9.094" /><testcase classname="tests.integration.regression_test.TestRegressions" name="test_647_support_doubleslash_in_image_names" time="8.207" /><testcase classname="tests.integration.regression_test.TestRegressions" name="test_649_handle_timeout_value_none" time="8.957" /><testcase classname="tests.integration.regression_test.TestRegressions" name="test_715_handle_user_param_as_int_value" time="8.817" /><testcase classname="tests.integration.regression_test.TestRegressions" name="test_792_explicit_port_protocol" time="8.225"><failure message="docker.errors.APIError: 500 Server Error for http+docker://localhost/v1.40/containers/5f8418117e1b300c9d00efd6f6627fc33ea879b52577a321598122dfa3706fb4/start: Internal Server Error (&quot;could not find &quot;rootlessport&quot; in one of [/usr/local/libexec/podman /usr/local/lib/podman /usr/libexec/podman /usr/lib/podman]&quot;)">docker/api/client.py:296: in _raise_for_status
    response.raise_for_status()
../../.virtualenvs/docker-py/lib/python3.9/site-packages/requests/models.py:953: in raise_for_status
    raise HTTPError(http_error_msg, response=self)
E   requests.exceptions.HTTPError: 500 Server Error: Internal Server Error for url: http+docker://localhost/v1.40/containers/5f8418117e1b300c9d00efd6f6627fc33ea879b52577a321598122dfa3706fb4/start

During handling of the above exception, another exception occurred:
/home/ubuntu/docker-py/tests/integration/regression_test.py:54: in test_792_explicit_port_protocol
    ???
docker/utils/decorators.py:19: in wrapped
    return f(self, resource_id, *args, **kwargs)
docker/api/container.py:1109: in start
    self._raise_for_status(res)
docker/api/client.py:298: in _raise_for_status
    raise create_api_error_from_http_exception(e)
docker/errors.py:31: in create_api_error_from_http_exception
    raise cls(e, response=response, explanation=explanation)
E   docker.errors.APIError: 500 Server Error for http+docker://localhost/v1.40/containers/5f8418117e1b300c9d00efd6f6627fc33ea879b52577a321598122dfa3706fb4/start: Internal Server Error ("could not find "rootlessport" in one of [/usr/local/libexec/podman /usr/local/lib/podman /usr/libexec/podman /usr/lib/podman]")</failure><system-out>--------------------------------- Captured Log ---------------------------------

--------------------------------- Captured Out ---------------------------------

</system-out><system-err>--------------------------------- Captured Err ---------------------------------

</system-err></testcase><testcase classname="tests.integration.credentials.utils_test" name="test_create_environment_dict" time="0.004" /></testsuite></testsuites>