<?xml version="1.0" encoding="utf-8"?><testsuites><testsuite name="docker-py" errors="0" failures="77" skipped="5" tests="266" time="1991.396" timestamp="2022-05-03T15:51:20.310126" hostname="acnologia"><testcase classname="tests.integration.api_build_test.BuildTest" name="test_build_container_with_target" time="17.560" /><testcase classname="tests.integration.api_build_test.BuildTest" name="test_build_from_stringio" time="7.208" /><testcase classname="tests.integration.api_build_test.BuildTest" name="test_build_gzip_custom_encoding" time="7.261" /><testcase classname="tests.integration.api_build_test.BuildTest" name="test_build_gzip_encoding" time="8.471" /><testcase classname="tests.integration.api_build_test.BuildTest" name="test_build_in_context_abs_dockerfile" time="8.615" /><testcase classname="tests.integration.api_build_test.BuildTest" name="test_build_in_context_dockerfile" time="7.935" /><testcase classname="tests.integration.api_build_test.BuildTest" name="test_build_in_context_nested_dockerfile" time="9.199" /><testcase classname="tests.integration.api_build_test.BuildTest" name="test_build_invalid_platform" time="8.865" /><testcase classname="tests.integration.api_build_test.BuildTest" name="test_build_isolation" time="7.347" /><testcase classname="tests.integration.api_build_test.BuildTest" name="test_build_labels" time="7.292" /><testcase classname="tests.integration.api_build_test.BuildTest" name="test_build_out_of_context_dockerfile" time="8.200" /><testcase classname="tests.integration.api_build_test.BuildTest" name="test_build_shmsize" time="7.348" /><testcase classname="tests.integration.api_build_test.BuildTest" name="test_build_squash" time="12.491" /><testcase classname="tests.integration.api_build_test.BuildTest" name="test_build_stderr_data" time="8.691" /><testcase classname="tests.integration.api_build_test.BuildTest" name="test_build_streaming" time="7.939" /><testcase classname="tests.integration.api_build_test.BuildTest" name="test_build_with_buildargs" time="7.323" /><testcase classname="tests.integration.api_build_test.BuildTest" name="test_build_with_cache_from" time="9.998"><failure message="AssertionError: assert 3 == 0&#10;  +3&#10;  -0">tests/integration/api_build_test.py:248: in test_build_with_cache_from
    assert counter == 0
E   AssertionError: assert 3 == 0
E     +3
E     -0</failure><system-out>--------------------------------- Captured Log ---------------------------------

--------------------------------- Captured Out ---------------------------------

</system-out><system-err>--------------------------------- Captured Err ---------------------------------

</system-err></testcase><testcase classname="tests.integration.api_build_test.BuildTest" name="test_build_with_dockerfile_empty_lines" time="7.215" /><testcase classname="tests.integration.api_build_test.BuildTest" name="test_build_with_dockerignore" time="8.844" /><testcase classname="tests.integration.api_build_test.BuildTest" name="test_build_with_extra_hosts" time="7.219"><failure message="docker.errors.APIError: 400 Client Error for http+docker://localhost/v1.40/build?t=dockerpytest_extrahost_build&amp;q=False&amp;nocache=False&amp;rm=False&amp;forcerm=False&amp;pull=False&amp;extrahosts=extrahost.local.test%3A127.0.0.1&amp;extrahosts=hello.world.test%3A127.0.0.1: Bad Request (&quot;failed to parse query parameter 'extrahosts': &quot;hello.world.test:127.0.0.1&quot;: invalid character 'h' looking for beginning of value&quot;)">docker/api/client.py:296: in _raise_for_status
    response.raise_for_status()
../../.virtualenvs/docker-py/lib/python3.9/site-packages/requests/models.py:953: in raise_for_status
    raise HTTPError(http_error_msg, response=self)
E   requests.exceptions.HTTPError: 400 Client Error: Bad Request for url: http+docker://localhost/v1.40/build?t=dockerpytest_extrahost_build&amp;q=False&amp;nocache=False&amp;rm=False&amp;forcerm=False&amp;pull=False&amp;extrahosts=extrahost.local.test%3A127.0.0.1&amp;extrahosts=hello.world.test%3A127.0.0.1

During handling of the above exception, another exception occurred:
tests/integration/api_build_test.py:333: in test_build_with_extra_hosts
    for chunk in stream:
docker/api/client.py:386: in _stream_helper
    yield self._result(response, json=decode)
docker/api/client.py:302: in _result
    self._raise_for_status(response)
docker/api/client.py:298: in _raise_for_status
    raise create_api_error_from_http_exception(e)
docker/errors.py:31: in create_api_error_from_http_exception
    raise cls(e, response=response, explanation=explanation)
E   docker.errors.APIError: 400 Client Error for http+docker://localhost/v1.40/build?t=dockerpytest_extrahost_build&amp;q=False&amp;nocache=False&amp;rm=False&amp;forcerm=False&amp;pull=False&amp;extrahosts=extrahost.local.test%3A127.0.0.1&amp;extrahosts=hello.world.test%3A127.0.0.1: Bad Request ("failed to parse query parameter 'extrahosts': "hello.world.test:127.0.0.1": invalid character 'h' looking for beginning of value")</failure><system-out>--------------------------------- Captured Log ---------------------------------

--------------------------------- Captured Out ---------------------------------

</system-out><system-err>--------------------------------- Captured Err ---------------------------------

</system-err></testcase><testcase classname="tests.integration.api_build_test.BuildTest" name="test_build_with_network_mode" time="8.725"><failure message="docker.errors.ImageNotFound: 404 Client Error for http+docker://localhost/v1.40/images/dockerpytest_customnetbuild/json: Not Found (&quot;failed to find image dockerpytest_customnetbuild: docker.io/library/dockerpytest_customnetbuild: No such image&quot;)">docker/api/client.py:296: in _raise_for_status
    response.raise_for_status()
../../.virtualenvs/docker-py/lib/python3.9/site-packages/requests/models.py:953: in raise_for_status
    raise HTTPError(http_error_msg, response=self)
E   requests.exceptions.HTTPError: 404 Client Error: Not Found for url: http+docker://localhost/v1.40/images/dockerpytest_customnetbuild/json

During handling of the above exception, another exception occurred:
tests/integration/api_build_test.py:298: in test_build_with_network_mode
    assert self.client.inspect_image('dockerpytest_customnetbuild')
docker/utils/decorators.py:19: in wrapped
    return f(self, resource_id, *args, **kwargs)
docker/api/image.py:251: in inspect_image
    return self._result(
docker/api/client.py:302: in _result
    self._raise_for_status(response)
docker/api/client.py:298: in _raise_for_status
    raise create_api_error_from_http_exception(e)
docker/errors.py:31: in create_api_error_from_http_exception
    raise cls(e, response=response, explanation=explanation)
E   docker.errors.ImageNotFound: 404 Client Error for http+docker://localhost/v1.40/images/dockerpytest_customnetbuild/json: Not Found ("failed to find image dockerpytest_customnetbuild: docker.io/library/dockerpytest_customnetbuild: No such image")</failure><system-out>--------------------------------- Captured Log ---------------------------------

--------------------------------- Captured Out ---------------------------------

</system-out><system-err>--------------------------------- Captured Err ---------------------------------

</system-err></testcase><testcase classname="tests.integration.api_build_test.BuildTest" name="test_build_with_proxy" time="7.351" /><testcase classname="tests.integration.api_build_test.BuildTest" name="test_build_with_proxy_and_buildargs" time="7.297" /><testcase classname="tests.integration.api_build_test.BuildTest" name="test_prune_builds" time="7.618"><skipped type="pytest.xfail" message="Currently fails on 18.09: https://github.com/moby/moby/issues/37920" /></testcase><testcase classname="tests.integration.api_client_test.InformationTest" name="test_info" time="10.730" /><testcase classname="tests.integration.api_client_test.InformationTest" name="test_version" time="9.952" /><testcase classname="tests.integration.api_client_test.AutoDetectVersionTest" name="test_client_init" time="8.291" /><testcase classname="tests.integration.api_client_test.ConnectionTimeoutTest" name="test_timeout" time="0.504" /><testcase classname="tests.integration.api_client_test.UnixconnTest" name="test_resource_warnings" time="2.708" /><testcase classname="tests.integration.api_container_test.ListContainersTest" name="test_list_containers" time="7.801" /><testcase classname="tests.integration.api_container_test.CreateContainerTest" name="test_create" time="7.403" /><testcase classname="tests.integration.api_container_test.CreateContainerTest" name="test_create_container_with_volumes_from" time="8.303" /><testcase classname="tests.integration.api_container_test.CreateContainerTest" name="test_create_with_auto_remove" time="7.424" /><testcase classname="tests.integration.api_container_test.CreateContainerTest" name="test_create_with_cpu_rt_options" time="7.833" /><testcase classname="tests.integration.api_container_test.CreateContainerTest" name="test_create_with_device_cgroup_rules" time="7.544"><failure message="AssertionError: assert None == ['c 7:128 rwm']&#10;  +None&#10;  -['c 7:128 rwm']">tests/integration/api_container_test.py:470: in test_create_with_device_cgroup_rules
    assert config['HostConfig']['DeviceCgroupRules'] == [rule]
E   AssertionError: assert None == ['c 7:128 rwm']
E     +None
E     -['c 7:128 rwm']</failure><system-out>--------------------------------- Captured Log ---------------------------------

--------------------------------- Captured Out ---------------------------------

</system-out><system-err>--------------------------------- Captured Err ---------------------------------

</system-err></testcase><testcase classname="tests.integration.api_container_test.CreateContainerTest" name="test_create_with_environment_variable_no_value" time="7.172"><failure message="AssertionError: assert 'Foo' in ['container=podman', 'Other=one', 'Blank=', 'PATH=/usr/local/sbin:/usr/local/bin:/usr/sbin:/usr/bin:/sbin:/bin', 'TERM=xterm']">tests/integration/api_container_test.py:366: in test_create_with_environment_variable_no_value
    assert 'Foo' in config['Config']['Env']
E   AssertionError: assert 'Foo' in ['container=podman', 'Other=one', 'Blank=', 'PATH=/usr/local/sbin:/usr/local/bin:/usr/sbin:/usr/bin:/sbin:/bin', 'TERM=xterm']</failure><system-out>--------------------------------- Captured Log ---------------------------------

--------------------------------- Captured Out ---------------------------------

</system-out><system-err>--------------------------------- Captured Err ---------------------------------

</system-err></testcase><testcase classname="tests.integration.api_container_test.CreateContainerTest" name="test_create_with_host_pid_mode" time="7.433" /><testcase classname="tests.integration.api_container_test.CreateContainerTest" name="test_create_with_init" time="7.213" /><testcase classname="tests.integration.api_container_test.CreateContainerTest" name="test_create_with_isolation" time="7.215"><failure message="AssertionError: assert '' == 'default'&#10;  - default">tests/integration/api_container_test.py:395: in test_create_with_isolation
    assert config['HostConfig']['Isolation'] == 'default'
E   AssertionError: assert '' == 'default'
E     - default</failure><system-out>--------------------------------- Captured Log ---------------------------------

--------------------------------- Captured Out ---------------------------------

</system-out><system-err>--------------------------------- Captured Err ---------------------------------

</system-err></testcase><testcase classname="tests.integration.api_container_test.CreateContainerTest" name="test_create_with_links" time="8.432"><failure message="docker.errors.APIError: 400 Client Error for http+docker://localhost/v1.40/containers/create: Bad Request (&quot;bad parameter: Link is not supported&quot;)">docker/api/client.py:296: in _raise_for_status
    response.raise_for_status()
../../.virtualenvs/docker-py/lib/python3.9/site-packages/requests/models.py:953: in raise_for_status
    raise HTTPError(http_error_msg, response=self)
E   requests.exceptions.HTTPError: 400 Client Error: Bad Request for url: http+docker://localhost/v1.40/containers/create

During handling of the above exception, another exception occurred:
tests/integration/api_container_test.py:95: in test_create_with_links
    res2 = self.client.create_container(
docker/api/container.py:428: in create_container
    return self.create_container_from_config(config, name)
docker/api/container.py:439: in create_container_from_config
    return self._result(res, True)
docker/api/client.py:302: in _result
    self._raise_for_status(response)
docker/api/client.py:298: in _raise_for_status
    raise create_api_error_from_http_exception(e)
docker/errors.py:31: in create_api_error_from_http_exception
    raise cls(e, response=response, explanation=explanation)
E   docker.errors.APIError: 400 Client Error for http+docker://localhost/v1.40/containers/create: Bad Request ("bad parameter: Link is not supported")</failure><system-out>--------------------------------- Captured Log ---------------------------------

--------------------------------- Captured Out ---------------------------------

</system-out><system-err>--------------------------------- Captured Err ---------------------------------

</system-err></testcase><testcase classname="tests.integration.api_container_test.CreateContainerTest" name="test_create_with_mac_address" time="7.465"><failure message="AssertionError: assert '02:42:ac:11:00:0a' == '82:fc:74:08:fb:03'&#10;  - 82:fc:74:08:fb:03&#10;  + 02:42:ac:11:00:0a">tests/integration/api_container_test.py:214: in test_create_with_mac_address
    assert mac_address_expected == res['NetworkSettings']['MacAddress']
E   AssertionError: assert '02:42:ac:11:00:0a' == '82:fc:74:08:fb:03'
E     - 82:fc:74:08:fb:03
E     + 02:42:ac:11:00:0a</failure><system-out>--------------------------------- Captured Log ---------------------------------

--------------------------------- Captured Out ---------------------------------

</system-out><system-err>--------------------------------- Captured Err ---------------------------------

</system-err></testcase><testcase classname="tests.integration.api_container_test.CreateContainerTest" name="test_create_with_memory_constraints_with_int" time="7.506" /><testcase classname="tests.integration.api_container_test.CreateContainerTest" name="test_create_with_memory_constraints_with_str" time="7.421" /><testcase classname="tests.integration.api_container_test.CreateContainerTest" name="test_create_with_restart_policy" time="9.395"><failure message="Failed: DID NOT RAISE &lt;class 'docker.errors.APIError'&gt;">tests/integration/api_container_test.py:124: in test_create_with_restart_policy
    self.client.remove_container(id)
E   Failed: DID NOT RAISE &lt;class 'docker.errors.APIError'&gt;</failure><system-out>--------------------------------- Captured Log ---------------------------------

--------------------------------- Captured Out ---------------------------------

</system-out><system-err>--------------------------------- Captured Err ---------------------------------

</system-err></testcase><testcase classname="tests.integration.api_container_test.CreateContainerTest" name="test_create_with_stop_timeout" time="7.201" /><testcase classname="tests.integration.api_container_test.CreateContainerTest" name="test_create_with_storage_opt" time="7.106"><skipped type="pytest.xfail" message="Not supported on most drivers" /></testcase><testcase classname="tests.integration.api_container_test.CreateContainerTest" name="test_create_with_tmpfs" time="7.199"><failure message="AssertionError: assert {'/tmp1': 'si...ev,tmpcopyup'} == {'/tmp1': 'size=3M'}&#10;  Differing items:&#10;  {'/tmp1': 'size=3M,rw,rprivate,nosuid,nodev,tmpcopyup'} != {'/tmp1': 'size=3M'}&#10;  Full diff:&#10;  - {'/tmp1': 'size=3M'}&#10;  + {'/tmp1': 'size=3M,rw,rprivate,nosuid,nodev,tmpcopyup'}">tests/integration/api_container_test.py:384: in test_create_with_tmpfs
    assert config['HostConfig']['Tmpfs'] == tmpfs
E   AssertionError: assert {'/tmp1': 'si...ev,tmpcopyup'} == {'/tmp1': 'size=3M'}
E     Differing items:
E     {'/tmp1': 'size=3M,rw,rprivate,nosuid,nodev,tmpcopyup'} != {'/tmp1': 'size=3M'}
E     Full diff:
E     - {'/tmp1': 'size=3M'}
E     + {'/tmp1': 'size=3M,rw,rprivate,nosuid,nodev,tmpcopyup'}</failure><system-out>--------------------------------- Captured Log ---------------------------------

--------------------------------- Captured Out ---------------------------------

</system-out><system-err>--------------------------------- Captured Err ---------------------------------

</system-err></testcase><testcase classname="tests.integration.api_container_test.CreateContainerTest" name="test_create_with_uts_mode" time="7.171" /><testcase classname="tests.integration.api_container_test.CreateContainerTest" name="test_group_id_ints" time="7.599" /><testcase classname="tests.integration.api_container_test.CreateContainerTest" name="test_group_id_strings" time="7.816" /><testcase classname="tests.integration.api_container_test.CreateContainerTest" name="test_invalid_log_driver_raises_exception" time="7.159"><failure message="AssertionError: assert 'container create: error running container create option: invalid log driver: invalid argument' in [&quot;logger: no log driver named 'asdf' is registered&quot;, 'error looking up logging plugin asdf: plugin &quot;asdf&quot; not found']&#10; +  where 'container create: error running container create option: invalid log driver: invalid argument' = APIError(HTTPError('500 Server Error: Internal Server Error for url: http+docker://localhost/v1.40/containers/create')).explanation&#10; +    where APIError(HTTPError('500 Server Error: Internal Server Error for url: http+docker://localhost/v1.40/containers/create')) = &lt;ExceptionInfo APIError(HTTPError('500 Server Error: Internal Server Error for url: http+docker://localhost/v1.40/containers/create')) tblen=6&gt;.value">tests/integration/api_container_test.py:286: in test_invalid_log_driver_raises_exception
    assert excinfo.value.explanation in expected_msgs
E   AssertionError: assert 'container create: error running container create option: invalid log driver: invalid argument' in ["logger: no log driver named 'asdf' is registered", 'error looking up logging plugin asdf: plugin "asdf" not found']
E    +  where 'container create: error running container create option: invalid log driver: invalid argument' = APIError(HTTPError('500 Server Error: Internal Server Error for url: http+docker://localhost/v1.40/containers/create')).explanation
E    +    where APIError(HTTPError('500 Server Error: Internal Server Error for url: http+docker://localhost/v1.40/containers/create')) = &lt;ExceptionInfo APIError(HTTPError('500 Server Error: Internal Server Error for url: http+docker://localhost/v1.40/containers/create')) tblen=6&gt;.value</failure><system-out>--------------------------------- Captured Log ---------------------------------

--------------------------------- Captured Out ---------------------------------

</system-out><system-err>--------------------------------- Captured Err ---------------------------------

</system-err></testcase><testcase classname="tests.integration.api_container_test.CreateContainerTest" name="test_valid_log_driver_and_log_opt" time="7.581"><failure message="AssertionError: assert None == {'max-file': '100'}&#10;  +None&#10;  -{'max-file': '100'}">tests/integration/api_container_test.py:265: in test_valid_log_driver_and_log_opt
    assert container_log_config['Config'] == log_config.config
E   AssertionError: assert None == {'max-file': '100'}
E     +None
E     -{'max-file': '100'}</failure><system-out>--------------------------------- Captured Log ---------------------------------

--------------------------------- Captured Out ---------------------------------

</system-out><system-err>--------------------------------- Captured Err ---------------------------------

</system-err></testcase><testcase classname="tests.integration.api_container_test.CreateContainerTest" name="test_valid_no_config_specified" time="7.550"><failure message="AssertionError: assert None == {}&#10;  +None&#10;  -{}">tests/integration/api_container_test.py:324: in test_valid_no_config_specified
    assert container_log_config['Config'] == {}
E   AssertionError: assert None == {}
E     +None
E     -{}</failure><system-out>--------------------------------- Captured Log ---------------------------------

--------------------------------- Captured Out ---------------------------------

</system-out><system-err>--------------------------------- Captured Err ---------------------------------

</system-err></testcase><testcase classname="tests.integration.api_container_test.CreateContainerTest" name="test_valid_no_log_driver_specified" time="7.562"><failure message="AssertionError: assert 'journald' == 'json-file'&#10;  - json-file&#10;  + journald">tests/integration/api_container_test.py:304: in test_valid_no_log_driver_specified
    assert container_log_config['Type'] == "json-file"
E   AssertionError: assert 'journald' == 'json-file'
E     - json-file
E     + journald</failure><system-out>--------------------------------- Captured Log ---------------------------------

--------------------------------- Captured Out ---------------------------------

</system-out><system-err>--------------------------------- Captured Err ---------------------------------

</system-err></testcase><testcase classname="tests.integration.api_container_test.VolumeBindTest" name="test_create_with_binds_ro" time="7.827" /><testcase classname="tests.integration.api_container_test.VolumeBindTest" name="test_create_with_binds_rw" time="7.626" /><testcase classname="tests.integration.api_container_test.VolumeBindTest" name="test_create_with_mounts" time="8.050" /><testcase classname="tests.integration.api_container_test.VolumeBindTest" name="test_create_with_mounts_ro" time="7.896" /><testcase classname="tests.integration.api_container_test.VolumeBindTest" name="test_create_with_volume_mount" time="7.426" /><testcase classname="tests.integration.api_container_test.ArchiveTest" name="test_copy_directory_to_container" time="7.686" /><testcase classname="tests.integration.api_container_test.ArchiveTest" name="test_copy_file_to_container" time="7.820" /><testcase classname="tests.integration.api_container_test.ArchiveTest" name="test_get_file_archive_from_container" time="7.958" /><testcase classname="tests.integration.api_container_test.ArchiveTest" name="test_get_file_stat_from_container" time="7.839" /><testcase classname="tests.integration.api_container_test.RenameContainerTest" name="test_rename_container" time="9.605" /><testcase classname="tests.integration.api_container_test.StartContainerTest" name="test_run_shlex_commands" time="9.949" /><testcase classname="tests.integration.api_container_test.StartContainerTest" name="test_start_container" time="7.564" /><testcase classname="tests.integration.api_container_test.StartContainerTest" name="test_start_container_with_dict_instead_of_id" time="7.578" /><testcase classname="tests.integration.api_container_test.WaitTest" name="test_wait" time="10.582" /><testcase classname="tests.integration.api_container_test.WaitTest" name="test_wait_with_condition" time="12.131" /><testcase classname="tests.integration.api_container_test.WaitTest" name="test_wait_with_dict_instead_of_id" time="10.587" /><testcase classname="tests.integration.api_container_test.LogsTest" name="test_logs" time="7.584" /><testcase classname="tests.integration.api_container_test.LogsTest" name="test_logs_streaming_and_follow" time="7.599" /><testcase classname="tests.integration.api_container_test.LogsTest" name="test_logs_streaming_and_follow_and_cancel" time="7.751"><failure message="Failed: Timeout &gt;5.0s">tests/integration/api_container_test.py:861: in test_logs_streaming_and_follow_and_cancel
    self.client.start(id)
docker/utils/decorators.py:19: in wrapped
    return f(self, resource_id, *args, **kwargs)
docker/api/container.py:1108: in start
    res = self._post(url)
docker/utils/decorators.py:46: in inner
    return f(self, *args, **kwargs)
docker/api/client.py:240: in _post
    return self.post(url, **self._set_request_timeout(kwargs))
../../.virtualenvs/docker-py/lib/python3.9/site-packages/requests/sessions.py:590: in post
    return self.request('POST', url, data=data, json=json, **kwargs)
../../.virtualenvs/docker-py/lib/python3.9/site-packages/requests/sessions.py:542: in request
    resp = self.send(prep, **send_kwargs)
../../.virtualenvs/docker-py/lib/python3.9/site-packages/requests/sessions.py:655: in send
    r = adapter.send(request, **kwargs)
../../.virtualenvs/docker-py/lib/python3.9/site-packages/requests/adapters.py:439: in send
    resp = conn.urlopen(
../../.virtualenvs/docker-py/lib/python3.9/site-packages/urllib3/connectionpool.py:699: in urlopen
    httplib_response = self._make_request(
../../.virtualenvs/docker-py/lib/python3.9/site-packages/urllib3/connectionpool.py:445: in _make_request
    six.raise_from(e, None)
&lt;string&gt;:3: in raise_from
    ???
../../.virtualenvs/docker-py/lib/python3.9/site-packages/urllib3/connectionpool.py:440: in _make_request
    httplib_response = conn.getresponse()
/usr/lib/python3.9/http/client.py:1371: in getresponse
    response.begin()
/usr/lib/python3.9/http/client.py:319: in begin
    version, status, reason = self._read_status()
/usr/lib/python3.9/http/client.py:280: in _read_status
    line = str(self.fp.readline(_MAXLINE + 1), "iso-8859-1")
/usr/lib/python3.9/socket.py:704: in readinto
    return self._sock.recv_into(b)
E   Failed: Timeout &gt;5.0s</failure><system-out>--------------------------------- Captured Log ---------------------------------

--------------------------------- Captured Out ---------------------------------

</system-out><system-err>--------------------------------- Captured Err ---------------------------------

</system-err></testcase><testcase classname="tests.integration.api_container_test.LogsTest" name="test_logs_tail_option" time="7.945" /><testcase classname="tests.integration.api_container_test.LogsTest" name="test_logs_with_dict_instead_of_id" time="7.805" /><testcase classname="tests.integration.api_container_test.LogsTest" name="test_logs_with_tail_0" time="7.639" /><testcase classname="tests.integration.api_container_test.LogsTest" name="test_logs_with_until" time="7.679" /><testcase classname="tests.integration.api_container_test.DiffTest" name="test_diff" time="7.629" /><testcase classname="tests.integration.api_container_test.DiffTest" name="test_diff_with_dict_instead_of_id" time="7.667" /><testcase classname="tests.integration.api_container_test.StopTest" name="test_stop" time="9.889" /><testcase classname="tests.integration.api_container_test.StopTest" name="test_stop_with_dict_instead_of_id" time="9.911" /><testcase classname="tests.integration.api_container_test.KillTest" name="test_kill" time="7.680" /><testcase classname="tests.integration.api_container_test.KillTest" name="test_kill_with_dict_instead_of_id" time="7.694" /><testcase classname="tests.integration.api_container_test.KillTest" name="test_kill_with_signal" time="7.678" /><testcase classname="tests.integration.api_container_test.KillTest" name="test_kill_with_signal_integer" time="7.601" /><testcase classname="tests.integration.api_container_test.KillTest" name="test_kill_with_signal_name" time="7.636" /><testcase classname="tests.integration.api_container_test.PortTest" name="test_port" time="7.408"><failure message="docker.errors.APIError: 500 Server Error for http+docker://localhost/v1.40/containers/87fd2a03ba685fa17e13b73e33c85702699c1b86dd84c9510cade0ee326142da/start: Internal Server Error (&quot;could not find &quot;rootlessport&quot; in one of [/usr/local/libexec/podman /usr/local/lib/podman /usr/libexec/podman /usr/lib/podman].  To resolve this error, set the helper_binaries_dir key in the `[engine]` section of containers.conf to the directory containing your helper binaries.&quot;)">docker/api/client.py:296: in _raise_for_status
    response.raise_for_status()
../../.virtualenvs/docker-py/lib/python3.9/site-packages/requests/models.py:953: in raise_for_status
    raise HTTPError(http_error_msg, response=self)
E   requests.exceptions.HTTPError: 500 Server Error: Internal Server Error for url: http+docker://localhost/v1.40/containers/87fd2a03ba685fa17e13b73e33c85702699c1b86dd84c9510cade0ee326142da/start

During handling of the above exception, another exception occurred:
tests/integration/api_container_test.py:1068: in test_port
    self.client.start(container)
docker/utils/decorators.py:19: in wrapped
    return f(self, resource_id, *args, **kwargs)
docker/api/container.py:1109: in start
    self._raise_for_status(res)
docker/api/client.py:298: in _raise_for_status
    raise create_api_error_from_http_exception(e)
docker/errors.py:31: in create_api_error_from_http_exception
    raise cls(e, response=response, explanation=explanation)
E   docker.errors.APIError: 500 Server Error for http+docker://localhost/v1.40/containers/87fd2a03ba685fa17e13b73e33c85702699c1b86dd84c9510cade0ee326142da/start: Internal Server Error ("could not find "rootlessport" in one of [/usr/local/libexec/podman /usr/local/lib/podman /usr/libexec/podman /usr/lib/podman].  To resolve this error, set the helper_binaries_dir key in the `[engine]` section of containers.conf to the directory containing your helper binaries.")</failure><system-out>--------------------------------- Captured Log ---------------------------------

--------------------------------- Captured Out ---------------------------------

</system-out><system-err>--------------------------------- Captured Err ---------------------------------

</system-err></testcase><testcase classname="tests.integration.api_container_test.ContainerTopTest" name="test_top" time="7.939"><skipped type="pytest.xfail" message="Output of docker top depends on host distro, and is not formalized." /></testcase><testcase classname="tests.integration.api_container_test.ContainerTopTest" name="test_top_with_psargs" time="8.026"><skipped type="pytest.xfail" message="Output of docker top depends on host distro, and is not formalized." /></testcase><testcase classname="tests.integration.api_container_test.RestartContainerTest" name="test_restart" time="10.203" /><testcase classname="tests.integration.api_container_test.RestartContainerTest" name="test_restart_with_dict_instead_of_id" time="10.061" /><testcase classname="tests.integration.api_container_test.RestartContainerTest" name="test_restart_with_low_timeout" time="10.850" /><testcase classname="tests.integration.api_container_test.RemoveContainerTest" name="test_remove" time="7.678" /><testcase classname="tests.integration.api_container_test.RemoveContainerTest" name="test_remove_with_dict_instead_of_id" time="7.630" /><testcase classname="tests.integration.api_container_test.AttachContainerTest" name="test_attach_no_stream" time="7.800"><failure message="AssertionError: assert b'hello' == b'hello\n'&#10;  Full diff:&#10;  - b'hello\n'&#10;  ?        --&#10;  + b'hello'">tests/integration/api_container_test.py:1230: in test_attach_no_stream
    assert output == 'hello\n'.encode(encoding='ascii')
E   AssertionError: assert b'hello' == b'hello\n'
E     Full diff:
E     - b'hello\n'
E     ?        --
E     + b'hello'</failure><system-out>--------------------------------- Captured Log ---------------------------------

--------------------------------- Captured Out ---------------------------------

</system-out><system-err>--------------------------------- Captured Err ---------------------------------

</system-err></testcase><testcase classname="tests.integration.api_container_test.AttachContainerTest" name="test_attach_stream_and_cancel" time="10.000"><failure message="Failed: Timeout &gt;10.0s">tests/integration/base.py:83: in tearDown
    super().tearDown()
tests/integration/base.py:30: in tearDown
    client = docker.from_env(version=TEST_API_VERSION)
docker/client.py:96: in from_env
    return cls(
docker/client.py:45: in __init__
    self.api = APIClient(*args, **kwargs)
docker/api/client.py:197: in __init__
    self._version = self._retrieve_server_version()
docker/api/client.py:214: in _retrieve_server_version
    return self.version(api_version=False)["ApiVersion"]
docker/api/daemon.py:181: in version
    return self._result(self._get(url), json=True)
docker/utils/decorators.py:46: in inner
    return f(self, *args, **kwargs)
docker/api/client.py:251: in _get
    return self.get(url, **self._set_request_timeout(kwargs))
../../.virtualenvs/docker-py/lib/python3.9/site-packages/requests/sessions.py:555: in get
    return self.request('GET', url, **kwargs)
../../.virtualenvs/docker-py/lib/python3.9/site-packages/requests/sessions.py:542: in request
    resp = self.send(prep, **send_kwargs)
../../.virtualenvs/docker-py/lib/python3.9/site-packages/requests/sessions.py:655: in send
    r = adapter.send(request, **kwargs)
../../.virtualenvs/docker-py/lib/python3.9/site-packages/requests/adapters.py:439: in send
    resp = conn.urlopen(
../../.virtualenvs/docker-py/lib/python3.9/site-packages/urllib3/connectionpool.py:699: in urlopen
    httplib_response = self._make_request(
../../.virtualenvs/docker-py/lib/python3.9/site-packages/urllib3/connectionpool.py:445: in _make_request
    six.raise_from(e, None)
../../.virtualenvs/docker-py/lib/python3.9/site-packages/urllib3/connectionpool.py:440: in _make_request
    httplib_response = conn.getresponse()
/usr/lib/python3.9/http/client.py:1371: in getresponse
    response.begin()
/usr/lib/python3.9/http/client.py:319: in begin
    version, status, reason = self._read_status()
/usr/lib/python3.9/http/client.py:280: in _read_status
    line = str(self.fp.readline(_MAXLINE + 1), "iso-8859-1")
/usr/lib/python3.9/socket.py:704: in readinto
    return self._sock.recv_into(b)
E   Failed: Timeout &gt;10.0s</failure><system-out>--------------------------------- Captured Log ---------------------------------

--------------------------------- Captured Out ---------------------------------

</system-out><system-err>--------------------------------- Captured Err ---------------------------------

</system-err></testcase><testcase classname="tests.integration.api_container_test.AttachContainerTest" name="test_detach_with_arg" time="8.288" /><testcase classname="tests.integration.api_container_test.AttachContainerTest" name="test_detach_with_config_file" time="8.221" /><testcase classname="tests.integration.api_container_test.AttachContainerTest" name="test_detach_with_default" time="8.770" /><testcase classname="tests.integration.api_container_test.AttachContainerTest" name="test_run_container_reading_socket" time="7.435" /><testcase classname="tests.integration.api_container_test.AttachContainerTest" name="test_run_container_streaming" time="7.746" /><testcase classname="tests.integration.api_container_test.PauseTest" name="test_pause_unpause" time="7.875" /><testcase classname="tests.integration.api_container_test.PruneTest" name="test_prune_containers" time="7.917" /><testcase classname="tests.integration.api_container_test.GetContainerStatsTest" name="test_get_container_stats_no_stream" time="7.499" /><testcase classname="tests.integration.api_container_test.ContainerUpdateTest" name="test_restart_policy_update" time="7.751"><failure message="docker.errors.NotFound: 404 Client Error for http+docker://localhost/v1.40/containers/85ce8001b4112cefe1fb3b53143467f7be85a8c73d74a8a8ce87c8e8effba350/update: Not Found (&quot;b'Not Found'&quot;)">docker/api/client.py:296: in _raise_for_status
    response.raise_for_status()
../../.virtualenvs/docker-py/lib/python3.9/site-packages/requests/models.py:953: in raise_for_status
    raise HTTPError(http_error_msg, response=self)
E   requests.exceptions.HTTPError: 404 Client Error: Not Found for url: http+docker://localhost/v1.40/containers/85ce8001b4112cefe1fb3b53143467f7be85a8c73d74a8a8ce87c8e8effba350/update

During handling of the above exception, another exception occurred:
tests/integration/api_container_test.py:1416: in test_restart_policy_update
    self.client.update_container(container,
docker/utils/decorators.py:34: in wrapper
    return f(self, *args, **kwargs)
docker/utils/decorators.py:19: in wrapped
    return f(self, resource_id, *args, **kwargs)
docker/api/container.py:1268: in update_container
    return self._result(res, True)
docker/api/client.py:302: in _result
    self._raise_for_status(response)
docker/api/client.py:298: in _raise_for_status
    raise create_api_error_from_http_exception(e)
docker/errors.py:31: in create_api_error_from_http_exception
    raise cls(e, response=response, explanation=explanation)
E   docker.errors.NotFound: 404 Client Error for http+docker://localhost/v1.40/containers/85ce8001b4112cefe1fb3b53143467f7be85a8c73d74a8a8ce87c8e8effba350/update: Not Found ("b'Not Found'")</failure><system-out>--------------------------------- Captured Log ---------------------------------

--------------------------------- Captured Out ---------------------------------

</system-out><system-err>--------------------------------- Captured Err ---------------------------------

</system-err></testcase><testcase classname="tests.integration.api_container_test.ContainerUpdateTest" name="test_update_container" time="7.726"><failure message="docker.errors.NotFound: 404 Client Error for http+docker://localhost/v1.40/containers/11658e7a82e5d92c8370d44d7ba2de827461e597ed1d271483f8c011277c71d5/update: Not Found (&quot;b'Not Found'&quot;)">docker/api/client.py:296: in _raise_for_status
    response.raise_for_status()
../../.virtualenvs/docker-py/lib/python3.9/site-packages/requests/models.py:953: in raise_for_status
    raise HTTPError(http_error_msg, response=self)
E   requests.exceptions.HTTPError: 404 Client Error: Not Found for url: http+docker://localhost/v1.40/containers/11658e7a82e5d92c8370d44d7ba2de827461e597ed1d271483f8c011277c71d5/update

During handling of the above exception, another exception occurred:
tests/integration/api_container_test.py:1394: in test_update_container
    self.client.update_container(container, mem_limit=new_mem_limit)
docker/utils/decorators.py:34: in wrapper
    return f(self, *args, **kwargs)
docker/utils/decorators.py:19: in wrapped
    return f(self, resource_id, *args, **kwargs)
docker/api/container.py:1268: in update_container
    return self._result(res, True)
docker/api/client.py:302: in _result
    self._raise_for_status(response)
docker/api/client.py:298: in _raise_for_status
    raise create_api_error_from_http_exception(e)
docker/errors.py:31: in create_api_error_from_http_exception
    raise cls(e, response=response, explanation=explanation)
E   docker.errors.NotFound: 404 Client Error for http+docker://localhost/v1.40/containers/11658e7a82e5d92c8370d44d7ba2de827461e597ed1d271483f8c011277c71d5/update: Not Found ("b'Not Found'")</failure><system-out>--------------------------------- Captured Log ---------------------------------

--------------------------------- Captured Out ---------------------------------

</system-out><system-err>--------------------------------- Captured Err ---------------------------------

</system-err></testcase><testcase classname="tests.integration.api_container_test.ContainerCPUTest" name="test_container_cpu_shares" time="7.504" /><testcase classname="tests.integration.api_container_test.ContainerCPUTest" name="test_container_cpuset" time="7.409" /><testcase classname="tests.integration.api_container_test.ContainerCPUTest" name="test_create_with_runtime" time="7.142"><failure message="AssertionError: assert 'oci' == 'runc'&#10;  - runc&#10;  + oci">tests/integration/api_container_test.py:1461: in test_create_with_runtime
    assert config['HostConfig']['Runtime'] == 'runc'
E   AssertionError: assert 'oci' == 'runc'
E     - runc
E     + oci</failure><system-out>--------------------------------- Captured Log ---------------------------------

--------------------------------- Captured Out ---------------------------------

</system-out><system-err>--------------------------------- Captured Err ---------------------------------

</system-err></testcase><testcase classname="tests.integration.api_exec_test.ExecTest" name="test_detach_with_config_file" time="12.899"><failure message="AssertionError">tests/integration/api_exec_test.py:227: in test_detach_with_config_file
    assert_cat_socket_detached_with_keys(sock, [ctrl_with('p')])
tests/helpers.py:137: in assert_cat_socket_detached_with_keys
    assert data == b'' or data.startswith(
E   AssertionError</failure><system-out>--------------------------------- Captured Log ---------------------------------

--------------------------------- Captured Out ---------------------------------

</system-out><system-err>--------------------------------- Captured Err ---------------------------------

</system-err></testcase><testcase classname="tests.integration.api_exec_test.ExecTest" name="test_detach_with_default" time="13.484"><failure message="AssertionError">tests/integration/api_exec_test.py:208: in test_detach_with_default
    assert_cat_socket_detached_with_keys(
tests/helpers.py:137: in assert_cat_socket_detached_with_keys
    assert data == b'' or data.startswith(
E   AssertionError</failure><system-out>--------------------------------- Captured Log ---------------------------------

--------------------------------- Captured Out ---------------------------------

</system-out><system-err>--------------------------------- Captured Err ---------------------------------

</system-err></testcase><testcase classname="tests.integration.api_exec_test.ExecTest" name="test_exec_command_as_root" time="8.021" /><testcase classname="tests.integration.api_exec_test.ExecTest" name="test_exec_command_as_user" time="7.888" /><testcase classname="tests.integration.api_exec_test.ExecTest" name="test_exec_command_streaming" time="7.999" /><testcase classname="tests.integration.api_exec_test.ExecTest" name="test_exec_command_string" time="7.933" /><testcase classname="tests.integration.api_exec_test.ExecTest" name="test_exec_command_with_env" time="7.867" /><testcase classname="tests.integration.api_exec_test.ExecTest" name="test_exec_command_with_workdir" time="7.948" /><testcase classname="tests.integration.api_exec_test.ExecTest" name="test_exec_inspect" time="8.068" /><testcase classname="tests.integration.api_exec_test.ExecTest" name="test_exec_start_detached" time="7.847"><failure message="AssertionError: assert '\n' == ''&#10;  Strings contain only whitespace, escaping them using repr()&#10;  - ''&#10;  + '\n'">tests/integration/api_exec_test.py:152: in test_exec_start_detached
    assert response == ""
E   AssertionError: assert '\n' == ''
E     Strings contain only whitespace, escaping them using repr()
E     - ''
E     + '\n'</failure><system-out>--------------------------------- Captured Log ---------------------------------

--------------------------------- Captured Out ---------------------------------

</system-out><system-err>--------------------------------- Captured Err ---------------------------------

</system-err></testcase><testcase classname="tests.integration.api_exec_test.ExecTest" name="test_exec_start_socket" time="7.858"><failure message="AssertionError: assert 121 == 1&#10;  +121&#10;  -1">tests/integration/api_exec_test.py:134: in test_exec_start_socket
    assert stream == 1  # stdout (0 = stdin, 1 = stdout, 2 = stderr)
E   AssertionError: assert 121 == 1
E     +121
E     -1</failure><system-out>--------------------------------- Captured Log ---------------------------------

--------------------------------- Captured Out ---------------------------------

</system-out><system-err>--------------------------------- Captured Err ---------------------------------

</system-err></testcase><testcase classname="tests.integration.api_exec_test.ExecTest" name="test_execute_command" time="8.001" /><testcase classname="tests.integration.api_exec_test.ExecTest" name="test_execute_command_with_proxy_env" time="8.074" /><testcase classname="tests.integration.api_exec_test.ExecDemuxTest" name="test_exec_command_no_stream_demux" time="8.449" /><testcase classname="tests.integration.api_exec_test.ExecDemuxTest" name="test_exec_command_no_stream_no_demux" time="8.305" /><testcase classname="tests.integration.api_exec_test.ExecDemuxTest" name="test_exec_command_stream_demux" time="8.484" /><testcase classname="tests.integration.api_exec_test.ExecDemuxTest" name="test_exec_command_stream_no_demux" time="8.438" /><testcase classname="tests.integration.api_exec_test.ExecDemuxTest" name="test_exec_command_tty_no_stream_demux" time="7.872"><failure message="ValueError: 104 is not a valid stream">tests/integration/api_exec_test.py:299: in test_exec_command_tty_no_stream_demux
    exec_log = self.client.exec_start(res, demux=True)
docker/utils/decorators.py:19: in wrapped
    return f(self, resource_id, *args, **kwargs)
docker/api/exec_api.py:173: in exec_start
    output = self._read_from_socket(res, stream, tty=tty, demux=demux)
docker/api/client.py:457: in _read_from_socket
    return consume_socket_output(gen, demux=demux)
docker/utils/socket.py:140: in consume_socket_output
    for frame in frames:
docker/api/client.py:447: in &lt;genexpr&gt;
    gen = (demux_adaptor(*frame) for frame in gen)
docker/utils/socket.py:167: in demux_adaptor
    raise ValueError(f'{stream_id} is not a valid stream')
E   ValueError: 104 is not a valid stream</failure><system-out>--------------------------------- Captured Log ---------------------------------

--------------------------------- Captured Out ---------------------------------

</system-out><system-err>--------------------------------- Captured Err ---------------------------------

</system-err></testcase><testcase classname="tests.integration.api_exec_test.ExecDemuxTest" name="test_exec_command_tty_no_stream_no_demux" time="8.274"><failure message="AssertionError: assert b't\r\nhello err\r\n' == b'hello out\r\nhello err\r\n'&#10;  At index 0 diff: b't' != b'h'&#10;  Full diff:&#10;  - b'hello out\r\nhello err\r\n'&#10;  ?   --------&#10;  + b't\r\nhello err\r\n'">tests/integration/api_exec_test.py:282: in test_exec_command_tty_no_stream_no_demux
    assert exec_log == b'hello out\r\nhello err\r\n'
E   AssertionError: assert b't\r\nhello err\r\n' == b'hello out\r\nhello err\r\n'
E     At index 0 diff: b't' != b'h'
E     Full diff:
E     - b'hello out\r\nhello err\r\n'
E     ?   --------
E     + b't\r\nhello err\r\n'</failure><system-out>--------------------------------- Captured Log ---------------------------------

--------------------------------- Captured Out ---------------------------------

</system-out><system-err>--------------------------------- Captured Err ---------------------------------

</system-err></testcase><testcase classname="tests.integration.api_exec_test.ExecDemuxTest" name="test_exec_command_tty_stream_demux" time="7.905"><failure message="ValueError: 104 is not a valid stream">tests/integration/api_exec_test.py:305: in test_exec_command_tty_stream_demux
    exec_log = list(self.client.exec_start(res, demux=True, stream=True))
docker/types/daemon.py:32: in __next__
    return next(self._stream)
docker/api/client.py:447: in &lt;genexpr&gt;
    gen = (demux_adaptor(*frame) for frame in gen)
docker/utils/socket.py:167: in demux_adaptor
    raise ValueError(f'{stream_id} is not a valid stream')
E   ValueError: 104 is not a valid stream</failure><system-out>--------------------------------- Captured Log ---------------------------------

--------------------------------- Captured Out ---------------------------------

</system-out><system-err>--------------------------------- Captured Err ---------------------------------

</system-err></testcase><testcase classname="tests.integration.api_exec_test.ExecDemuxTest" name="test_exec_command_tty_stream_no_demux" time="8.470"><failure message="AssertionError: assert b'hello out\r\n' in [b't\r\n', b'hello err\r\n']">tests/integration/api_exec_test.py:288: in test_exec_command_tty_stream_no_demux
    assert b'hello out\r\n' in exec_log
E   AssertionError: assert b'hello out\r\n' in [b't\r\n', b'hello err\r\n']</failure><system-out>--------------------------------- Captured Log ---------------------------------

--------------------------------- Captured Out ---------------------------------

</system-out><system-err>--------------------------------- Captured Err ---------------------------------

</system-err></testcase><testcase classname="tests.integration.api_healthcheck_test.HealthcheckTest" name="test_healthcheck_fails" time="8.154" /><testcase classname="tests.integration.api_healthcheck_test.HealthcheckTest" name="test_healthcheck_passes" time="8.273" /><testcase classname="tests.integration.api_healthcheck_test.HealthcheckTest" name="test_healthcheck_shell_command" time="7.203" /><testcase classname="tests.integration.api_healthcheck_test.HealthcheckTest" name="test_healthcheck_start_period" time="11.718" /><testcase classname="tests.integration.api_image_test.ListImagesTest" name="test_images" time="9.941" /><testcase classname="tests.integration.api_image_test.ListImagesTest" name="test_images_quiet" time="8.038" /><testcase classname="tests.integration.api_image_test.PullImageTest" name="test_pull" time="11.137" /><testcase classname="tests.integration.api_image_test.PullImageTest" name="test_pull_invalid_platform" time="10.822"><failure message="Failed: DID NOT RAISE &lt;class 'docker.errors.APIError'&gt;">tests/integration/api_image_test.py:69: in test_pull_invalid_platform
    self.client.pull('hello-world', platform='foobar')
E   Failed: DID NOT RAISE &lt;class 'docker.errors.APIError'&gt;</failure><system-out>--------------------------------- Captured Log ---------------------------------

--------------------------------- Captured Out ---------------------------------

</system-out><system-err>--------------------------------- Captured Err ---------------------------------

</system-err></testcase><testcase classname="tests.integration.api_image_test.PullImageTest" name="test_pull_streaming" time="10.371" /><testcase classname="tests.integration.api_image_test.CommitTest" name="test_commit" time="8.271"><failure message="AssertionError: assert False&#10; +  where False = &lt;built-in method startswith of str object at 0x7f863886d670&gt;('772d8c62ff8d81ad374d3243d2e31dd2580ef1d445d1fa463a6ba402e5b41f07')&#10; +    where &lt;built-in method startswith of str object at 0x7f863886d670&gt; = ''.startswith">tests/integration/api_image_test.py:89: in test_commit
    assert img['Container'].startswith(id)
E   AssertionError: assert False
E    +  where False = &lt;built-in method startswith of str object at 0x7f863886d670&gt;('772d8c62ff8d81ad374d3243d2e31dd2580ef1d445d1fa463a6ba402e5b41f07')
E    +    where &lt;built-in method startswith of str object at 0x7f863886d670&gt; = ''.startswith</failure><system-out>--------------------------------- Captured Log ---------------------------------

--------------------------------- Captured Out ---------------------------------

</system-out><system-err>--------------------------------- Captured Err ---------------------------------

</system-err></testcase><testcase classname="tests.integration.api_image_test.CommitTest" name="test_commit_with_changes" time="7.988"><failure message="AssertionError: assert False&#10; +  where False = &lt;built-in method startswith of str object at 0x7f863886d670&gt;('4238a9b2236b02953a57359556d26a63844a61e204c5c92feaba4506b5aba840')&#10; +    where &lt;built-in method startswith of str object at 0x7f863886d670&gt; = ''.startswith">tests/integration/api_image_test.py:107: in test_commit_with_changes
    assert img['Container'].startswith(cid['Id'])
E   AssertionError: assert False
E    +  where False = &lt;built-in method startswith of str object at 0x7f863886d670&gt;('4238a9b2236b02953a57359556d26a63844a61e204c5c92feaba4506b5aba840')
E    +    where &lt;built-in method startswith of str object at 0x7f863886d670&gt; = ''.startswith</failure><system-out>--------------------------------- Captured Log ---------------------------------

--------------------------------- Captured Out ---------------------------------

</system-out><system-err>--------------------------------- Captured Err ---------------------------------

</system-err></testcase><testcase classname="tests.integration.api_image_test.RemoveImageTest" name="test_remove" time="8.264" /><testcase classname="tests.integration.api_image_test.ImportImageTest" name="test_get_load_image" time="13.197"><failure message="AssertionError: assert False&#10; +  where False = any([])">tests/integration/api_image_test.py:266: in test_get_load_image
    assert any([
E   AssertionError: assert False
E    +  where False = any([])</failure><system-out>--------------------------------- Captured Log ---------------------------------

--------------------------------- Captured Out ---------------------------------

</system-out><system-err>--------------------------------- Captured Err ---------------------------------

</system-err></testcase><testcase classname="tests.integration.api_image_test.ImportImageTest" name="test_import_from_bytes" time="7.333" /><testcase classname="tests.integration.api_image_test.ImportImageTest" name="test_import_from_file" time="7.436" /><testcase classname="tests.integration.api_image_test.ImportImageTest" name="test_import_from_stream" time="7.336" /><testcase classname="tests.integration.api_image_test.ImportImageTest" name="test_import_from_url" time="0.001"><skipped type="pytest.skip" message="Doesn't work inside a container - FIXME">/home/riyad/src/docker-py/tests/integration/api_image_test.py:291: Doesn't work inside a container - FIXME</skipped><system-out>--------------------------------- Captured Log ---------------------------------

--------------------------------- Captured Out ---------------------------------

</system-out><system-err>--------------------------------- Captured Err ---------------------------------

</system-err></testcase><testcase classname="tests.integration.api_image_test.ImportImageTest" name="test_import_image_from_data_with_changes" time="7.442" /><testcase classname="tests.integration.api_image_test.ImportImageTest" name="test_import_image_with_changes" time="7.450" /><testcase classname="tests.integration.api_image_test.PruneImagesTest" name="test_prune_images" time="10.796"><failure message="docker.errors.APIError: 500 Server Error for http+docker://localhost/v1.40/images/prune: Internal Server Error (&quot;Image used by ee806f61affd47885d3687d0a8c7ba2e48561421b64a68e88d92afabc50f01b2: image is in use by a container&quot;)">docker/api/client.py:296: in _raise_for_status
    response.raise_for_status()
../../.virtualenvs/docker-py/lib/python3.9/site-packages/requests/models.py:953: in raise_for_status
    raise HTTPError(http_error_msg, response=self)
E   requests.exceptions.HTTPError: 500 Server Error: Internal Server Error for url: http+docker://localhost/v1.40/images/prune

During handling of the above exception, another exception occurred:
tests/integration/api_image_test.py:327: in test_prune_images
    result = self.client.prune_images()
docker/utils/decorators.py:34: in wrapper
    return f(self, *args, **kwargs)
docker/api/image.py:349: in prune_images
    return self._result(self._post(url, params=params), True)
docker/api/client.py:302: in _result
    self._raise_for_status(response)
docker/api/client.py:298: in _raise_for_status
    raise create_api_error_from_http_exception(e)
docker/errors.py:31: in create_api_error_from_http_exception
    raise cls(e, response=response, explanation=explanation)
E   docker.errors.APIError: 500 Server Error for http+docker://localhost/v1.40/images/prune: Internal Server Error ("Image used by ee806f61affd47885d3687d0a8c7ba2e48561421b64a68e88d92afabc50f01b2: image is in use by a container")</failure><system-out>--------------------------------- Captured Log ---------------------------------

--------------------------------- Captured Out ---------------------------------

</system-out><system-err>--------------------------------- Captured Err ---------------------------------

</system-err></testcase><testcase classname="tests.integration.api_image_test.SaveLoadImagesTest" name="test_get_image_load_image" time="7.473"><failure message="AssertionError: assert False is True">tests/integration/api_image_test.py:360: in test_get_image_load_image
    assert success is True
E   AssertionError: assert False is True</failure><system-out>--------------------------------- Captured Log ---------------------------------

--------------------------------- Captured Out ---------------------------------
{'stream': 'Loaded image: docker.io/library/alpine:3.10'}

</system-out><system-err>--------------------------------- Captured Err ---------------------------------

</system-err></testcase><testcase classname="tests.integration.api_image_test.InspectDistributionTest" name="test_inspect_distribution" time="7.292"><failure message="docker.errors.NotFound: 404 Client Error for http+docker://localhost/v1.40/distribution/busybox:latest/json: Not Found (&quot;Path /v1.40/distribution/busybox:latest/json is not supported&quot;)">docker/api/client.py:296: in _raise_for_status
    response.raise_for_status()
../../.virtualenvs/docker-py/lib/python3.9/site-packages/requests/models.py:953: in raise_for_status
    raise HTTPError(http_error_msg, response=self)
E   requests.exceptions.HTTPError: 404 Client Error: Not Found for url: http+docker://localhost/v1.40/distribution/busybox:latest/json

During handling of the above exception, another exception occurred:
tests/integration/api_image_test.py:366: in test_inspect_distribution
    data = self.client.inspect_distribution('busybox:latest')
docker/utils/decorators.py:34: in wrapper
    return f(self, *args, **kwargs)
docker/utils/decorators.py:19: in wrapped
    return f(self, resource_id, *args, **kwargs)
docker/api/image.py:287: in inspect_distribution
    return self._result(
docker/api/client.py:302: in _result
    self._raise_for_status(response)
docker/api/client.py:298: in _raise_for_status
    raise create_api_error_from_http_exception(e)
docker/errors.py:31: in create_api_error_from_http_exception
    raise cls(e, response=response, explanation=explanation)
E   docker.errors.NotFound: 404 Client Error for http+docker://localhost/v1.40/distribution/busybox:latest/json: Not Found ("Path /v1.40/distribution/busybox:latest/json is not supported")</failure><system-out>--------------------------------- Captured Log ---------------------------------

--------------------------------- Captured Out ---------------------------------

</system-out><system-err>--------------------------------- Captured Err ---------------------------------

</system-err></testcase><testcase classname="tests.integration.api_network_test.TestNetworks" name="test_connect_and_disconnect_container" time="8.312" /><testcase classname="tests.integration.api_network_test.TestNetworks" name="test_connect_and_force_disconnect_container" time="8.161" /><testcase classname="tests.integration.api_network_test.TestNetworks" name="test_connect_on_container_create" time="7.891" /><testcase classname="tests.integration.api_network_test.TestNetworks" name="test_connect_with_aliases" time="8.157" /><testcase classname="tests.integration.api_network_test.TestNetworks" name="test_connect_with_ipv4_address" time="7.525"><failure message="docker.errors.APIError: 500 Server Error for http+docker://localhost/v1.40/containers/d39880255f8ccc01b2f81c530e573c810a73aca6b881fde915d01ebd83b07781/start: Internal Server Error (&quot;plugin type=&quot;bridge&quot; failed (add): cni plugin bridge failed: failed to set bridge addr: &quot;cni-podman1&quot; already has an IP address different from 172.28.5.254/16&quot;)">docker/api/client.py:296: in _raise_for_status
    response.raise_for_status()
../../.virtualenvs/docker-py/lib/python3.9/site-packages/requests/models.py:953: in raise_for_status
    raise HTTPError(http_error_msg, response=self)
E   requests.exceptions.HTTPError: 500 Server Error: Internal Server Error for url: http+docker://localhost/v1.40/containers/d39880255f8ccc01b2f81c530e573c810a73aca6b881fde915d01ebd83b07781/start

During handling of the above exception, another exception occurred:
tests/integration/api_network_test.py:369: in test_connect_with_ipv4_address
    container = self.create_and_start(
tests/integration/base.py:124: in create_and_start
    self.client.start(container)
docker/utils/decorators.py:19: in wrapped
    return f(self, resource_id, *args, **kwargs)
docker/api/container.py:1109: in start
    self._raise_for_status(res)
docker/api/client.py:298: in _raise_for_status
    raise create_api_error_from_http_exception(e)
docker/errors.py:31: in create_api_error_from_http_exception
    raise cls(e, response=response, explanation=explanation)
E   docker.errors.APIError: 500 Server Error for http+docker://localhost/v1.40/containers/d39880255f8ccc01b2f81c530e573c810a73aca6b881fde915d01ebd83b07781/start: Internal Server Error ("plugin type="bridge" failed (add): cni plugin bridge failed: failed to set bridge addr: "cni-podman1" already has an IP address different from 172.28.5.254/16")</failure><system-out>--------------------------------- Captured Log ---------------------------------

--------------------------------- Captured Out ---------------------------------

</system-out><system-err>--------------------------------- Captured Err ---------------------------------

</system-err></testcase><testcase classname="tests.integration.api_network_test.TestNetworks" name="test_connect_with_ipv6_address" time="12.048"><failure message="TypeError: 'NoneType' object is not subscriptable">tests/integration/api_network_test.py:405: in test_connect_with_ipv6_address
    assert net_data['IPAMConfig']['IPv6Address'] == '2001:389::f00d'
E   TypeError: 'NoneType' object is not subscriptable</failure><system-out>--------------------------------- Captured Log ---------------------------------

--------------------------------- Captured Out ---------------------------------

</system-out><system-err>--------------------------------- Captured Err ---------------------------------

</system-err></testcase><testcase classname="tests.integration.api_network_test.TestNetworks" name="test_connect_with_links" time="8.159"><failure message="AssertionError: assert None == ['docker-py-t...upstream:bar']&#10;  +None&#10;  -['docker-py-test-upstream:bar']">tests/integration/api_network_test.py:344: in test_connect_with_links
    assert net_settings['Networks'][net_name]['Links'] == [
E   AssertionError: assert None == ['docker-py-t...upstream:bar']
E     +None
E     -['docker-py-test-upstream:bar']</failure><system-out>--------------------------------- Captured Log ---------------------------------

--------------------------------- Captured Out ---------------------------------

</system-out><system-err>--------------------------------- Captured Err ---------------------------------

</system-err></testcase><testcase classname="tests.integration.api_network_test.TestNetworks" name="test_create_check_duplicate" time="7.207"><failure message="docker.errors.APIError: 500 Server Error for http+docker://localhost/v1.40/networks/create: Internal Server Error (&quot;network name dockerpytest_b28b1356cdb0cccb already used: network already exists&quot;)">docker/api/client.py:296: in _raise_for_status
    response.raise_for_status()
../../.virtualenvs/docker-py/lib/python3.9/site-packages/requests/models.py:953: in raise_for_status
    raise HTTPError(http_error_msg, response=self)
E   requests.exceptions.HTTPError: 500 Server Error: Internal Server Error for url: http+docker://localhost/v1.40/networks/create

During handling of the above exception, another exception occurred:
tests/integration/api_network_test.py:326: in test_create_check_duplicate
    net_id = self.client.create_network(net_name, check_duplicate=False)
docker/api/network.py:153: in create_network
    return self._result(res, json=True)
docker/api/client.py:302: in _result
    self._raise_for_status(response)
docker/api/client.py:298: in _raise_for_status
    raise create_api_error_from_http_exception(e)
docker/errors.py:31: in create_api_error_from_http_exception
    raise cls(e, response=response, explanation=explanation)
E   docker.errors.APIError: 500 Server Error for http+docker://localhost/v1.40/networks/create: Internal Server Error ("network name dockerpytest_b28b1356cdb0cccb already used: network already exists")</failure><system-out>--------------------------------- Captured Log ---------------------------------

--------------------------------- Captured Out ---------------------------------

</system-out><system-err>--------------------------------- Captured Err ---------------------------------

</system-err></testcase><testcase classname="tests.integration.api_network_test.TestNetworks" name="test_create_internal_networks" time="7.204" /><testcase classname="tests.integration.api_network_test.TestNetworks" name="test_create_network_ipv6_enabled" time="7.227" /><testcase classname="tests.integration.api_network_test.TestNetworks" name="test_create_network_with_host_driver_fails" time="7.151" /><testcase classname="tests.integration.api_network_test.TestNetworks" name="test_create_network_with_ipam_config" time="7.186"><failure message="AssertionError: assert {'driver': 'host-local'} is None&#10; +  where {'driver': 'host-local'} = &lt;built-in method pop of dict object at 0x7f8635235c40&gt;('Options', None)&#10; +    where &lt;built-in method pop of dict object at 0x7f8635235c40&gt; = {'Config': [{'Gateway': '172.28.5.254', 'Subnet': '172.28.0.0/16'}], 'Driver': 'default'}.pop">tests/integration/api_network_test.py:62: in test_create_network_with_ipam_config
    assert ipam.pop('Options', None) is None
E   AssertionError: assert {'driver': 'host-local'} is None
E    +  where {'driver': 'host-local'} = &lt;built-in method pop of dict object at 0x7f8635235c40&gt;('Options', None)
E    +    where &lt;built-in method pop of dict object at 0x7f8635235c40&gt; = {'Config': [{'Gateway': '172.28.5.254', 'Subnet': '172.28.0.0/16'}], 'Driver': 'default'}.pop</failure><system-out>--------------------------------- Captured Log ---------------------------------

--------------------------------- Captured Out ---------------------------------

</system-out><system-err>--------------------------------- Captured Err ---------------------------------

</system-err></testcase><testcase classname="tests.integration.api_network_test.TestNetworks" name="test_create_network_with_labels" time="7.217" /><testcase classname="tests.integration.api_network_test.TestNetworks" name="test_create_network_with_labels_wrong_type" time="7.149" /><testcase classname="tests.integration.api_network_test.TestNetworks" name="test_create_remove_network_with_space_in_name" time="7.213"><failure message="docker.errors.APIError: 500 Server Error for http+docker://localhost/v1.40/networks/create: Internal Server Error (&quot;network name test 01 invalid: names must match [a-zA-Z0-9][a-zA-Z0-9_.-]*: invalid argument&quot;)">docker/api/client.py:296: in _raise_for_status
    response.raise_for_status()
../../.virtualenvs/docker-py/lib/python3.9/site-packages/requests/models.py:953: in raise_for_status
    raise HTTPError(http_error_msg, response=self)
E   requests.exceptions.HTTPError: 500 Server Error: Internal Server Error for url: http+docker://localhost/v1.40/networks/create

During handling of the above exception, another exception occurred:
tests/integration/api_network_test.py:454: in test_create_remove_network_with_space_in_name
    net_id = self.client.create_network('test 01')
docker/api/network.py:153: in create_network
    return self._result(res, json=True)
docker/api/client.py:302: in _result
    self._raise_for_status(response)
docker/api/client.py:298: in _raise_for_status
    raise create_api_error_from_http_exception(e)
docker/errors.py:31: in create_api_error_from_http_exception
    raise cls(e, response=response, explanation=explanation)
E   docker.errors.APIError: 500 Server Error for http+docker://localhost/v1.40/networks/create: Internal Server Error ("network name test 01 invalid: names must match [a-zA-Z0-9][a-zA-Z0-9_.-]*: invalid argument")</failure><system-out>--------------------------------- Captured Log ---------------------------------

--------------------------------- Captured Out ---------------------------------

</system-out><system-err>--------------------------------- Captured Err ---------------------------------

</system-err></testcase><testcase classname="tests.integration.api_network_test.TestNetworks" name="test_create_with_aliases" time="7.897" /><testcase classname="tests.integration.api_network_test.TestNetworks" name="test_create_with_driveropt" time="7.200"><failure message="docker.errors.APIError: 500 Server Error for http+docker://localhost/v1.40/containers/create: Internal Server Error (&quot;container create: unable to find network with name or ID bridge: network not found&quot;)">docker/api/client.py:296: in _raise_for_status
    response.raise_for_status()
../../.virtualenvs/docker-py/lib/python3.9/site-packages/requests/models.py:953: in raise_for_status
    raise HTTPError(http_error_msg, response=self)
E   requests.exceptions.HTTPError: 500 Server Error: Internal Server Error for url: http+docker://localhost/v1.40/containers/create

During handling of the above exception, another exception occurred:
tests/integration/api_network_test.py:276: in test_create_with_driveropt
    container = self.client.create_container(
docker/api/container.py:428: in create_container
    return self.create_container_from_config(config, name)
docker/api/container.py:439: in create_container_from_config
    return self._result(res, True)
docker/api/client.py:302: in _result
    self._raise_for_status(response)
docker/api/client.py:298: in _raise_for_status
    raise create_api_error_from_http_exception(e)
docker/errors.py:31: in create_api_error_from_http_exception
    raise cls(e, response=response, explanation=explanation)
E   docker.errors.APIError: 500 Server Error for http+docker://localhost/v1.40/containers/create: Internal Server Error ("container create: unable to find network with name or ID bridge: network not found")</failure><system-out>--------------------------------- Captured Log ---------------------------------

--------------------------------- Captured Out ---------------------------------

</system-out><system-err>--------------------------------- Captured Err ---------------------------------

</system-err></testcase><testcase classname="tests.integration.api_network_test.TestNetworks" name="test_create_with_ipv4_address" time="7.469"><failure message="docker.errors.APIError: 500 Server Error for http+docker://localhost/v1.40/containers/43bc47b3017f1600d2c5e860e9651ab6fb8875b1cbd7df2aa686c49e878e12e6/start: Internal Server Error (&quot;plugin type=&quot;bridge&quot; failed (add): cni plugin bridge failed: failed to set bridge addr: &quot;cni-podman1&quot; already has an IP address different from 132.124.0.1/16&quot;)">docker/api/client.py:296: in _raise_for_status
    response.raise_for_status()
../../.virtualenvs/docker-py/lib/python3.9/site-packages/requests/models.py:953: in raise_for_status
    raise HTTPError(http_error_msg, response=self)
E   requests.exceptions.HTTPError: 500 Server Error: Internal Server Error for url: http+docker://localhost/v1.40/containers/43bc47b3017f1600d2c5e860e9651ab6fb8875b1cbd7df2aa686c49e878e12e6/start

During handling of the above exception, another exception occurred:
tests/integration/api_network_test.py:219: in test_create_with_ipv4_address
    self.client.start(container)
docker/utils/decorators.py:19: in wrapped
    return f(self, resource_id, *args, **kwargs)
docker/api/container.py:1109: in start
    self._raise_for_status(res)
docker/api/client.py:298: in _raise_for_status
    raise create_api_error_from_http_exception(e)
docker/errors.py:31: in create_api_error_from_http_exception
    raise cls(e, response=response, explanation=explanation)
E   docker.errors.APIError: 500 Server Error for http+docker://localhost/v1.40/containers/43bc47b3017f1600d2c5e860e9651ab6fb8875b1cbd7df2aa686c49e878e12e6/start: Internal Server Error ("plugin type="bridge" failed (add): cni plugin bridge failed: failed to set bridge addr: "cni-podman1" already has an IP address different from 132.124.0.1/16")</failure><system-out>--------------------------------- Captured Log ---------------------------------

--------------------------------- Captured Out ---------------------------------

</system-out><system-err>--------------------------------- Captured Err ---------------------------------

</system-err></testcase><testcase classname="tests.integration.api_network_test.TestNetworks" name="test_create_with_ipv6_address" time="9.563"><failure message="docker.errors.APIError: 500 Server Error for http+docker://localhost/v1.40/containers/2a7f3d5817a5f71dfeb8d5293ed2cedccbb2afd9954f4b3496c1932682d08b4f/start: Internal Server Error (&quot;plugin type=&quot;bridge&quot; failed (add): cni plugin bridge failed: failed to set bridge addr: &quot;cni-podman1&quot; already has an IP address different from 2001:389::1/64&quot;)">docker/api/client.py:296: in _raise_for_status
    response.raise_for_status()
../../.virtualenvs/docker-py/lib/python3.9/site-packages/requests/models.py:953: in raise_for_status
    raise HTTPError(http_error_msg, response=self)
E   requests.exceptions.HTTPError: 500 Server Error: Internal Server Error for url: http+docker://localhost/v1.40/containers/2a7f3d5817a5f71dfeb8d5293ed2cedccbb2afd9954f4b3496c1932682d08b4f/start

During handling of the above exception, another exception occurred:
tests/integration/api_network_test.py:245: in test_create_with_ipv6_address
    self.client.start(container)
docker/utils/decorators.py:19: in wrapped
    return f(self, resource_id, *args, **kwargs)
docker/api/container.py:1109: in start
    self._raise_for_status(res)
docker/api/client.py:298: in _raise_for_status
    raise create_api_error_from_http_exception(e)
docker/errors.py:31: in create_api_error_from_http_exception
    raise cls(e, response=response, explanation=explanation)
E   docker.errors.APIError: 500 Server Error for http+docker://localhost/v1.40/containers/2a7f3d5817a5f71dfeb8d5293ed2cedccbb2afd9954f4b3496c1932682d08b4f/start: Internal Server Error ("plugin type="bridge" failed (add): cni plugin bridge failed: failed to set bridge addr: "cni-podman1" already has an IP address different from 2001:389::1/64")</failure><system-out>--------------------------------- Captured Log ---------------------------------

--------------------------------- Captured Out ---------------------------------

</system-out><system-err>--------------------------------- Captured Err ---------------------------------

</system-err></testcase><testcase classname="tests.integration.api_network_test.TestNetworks" name="test_create_with_linklocal_ips" time="7.175"><failure message="docker.errors.APIError: 500 Server Error for http+docker://localhost/v1.40/containers/create: Internal Server Error (&quot;container create: unable to find network with name or ID bridge: network not found&quot;)">docker/api/client.py:296: in _raise_for_status
    response.raise_for_status()
../../.virtualenvs/docker-py/lib/python3.9/site-packages/requests/models.py:953: in raise_for_status
    raise HTTPError(http_error_msg, response=self)
E   requests.exceptions.HTTPError: 500 Server Error: Internal Server Error for url: http+docker://localhost/v1.40/containers/create

During handling of the above exception, another exception occurred:
tests/integration/api_network_test.py:255: in test_create_with_linklocal_ips
    container = self.client.create_container(
docker/api/container.py:428: in create_container
    return self.create_container_from_config(config, name)
docker/api/container.py:439: in create_container_from_config
    return self._result(res, True)
docker/api/client.py:302: in _result
    self._raise_for_status(response)
docker/api/client.py:298: in _raise_for_status
    raise create_api_error_from_http_exception(e)
docker/errors.py:31: in create_api_error_from_http_exception
    raise cls(e, response=response, explanation=explanation)
E   docker.errors.APIError: 500 Server Error for http+docker://localhost/v1.40/containers/create: Internal Server Error ("container create: unable to find network with name or ID bridge: network not found")</failure><system-out>--------------------------------- Captured Log ---------------------------------

--------------------------------- Captured Out ---------------------------------

</system-out><system-err>--------------------------------- Captured Err ---------------------------------

</system-err></testcase><testcase classname="tests.integration.api_network_test.TestNetworks" name="test_create_with_links" time="7.936"><failure message="AssertionError: assert None == ['docker-py-t...upstream:bar']&#10;  +None&#10;  -['docker-py-test-upstream:bar']">tests/integration/api_network_test.py:311: in test_create_with_links
    assert net_settings['Networks'][net_name]['Links'] == [
E   AssertionError: assert None == ['docker-py-t...upstream:bar']
E     +None
E     -['docker-py-test-upstream:bar']</failure><system-out>--------------------------------- Captured Log ---------------------------------

--------------------------------- Captured Out ---------------------------------

</system-out><system-err>--------------------------------- Captured Err ---------------------------------

</system-err></testcase><testcase classname="tests.integration.api_network_test.TestNetworks" name="test_inspect_network" time="7.217" /><testcase classname="tests.integration.api_network_test.TestNetworks" name="test_list_networks" time="7.224" /><testcase classname="tests.integration.api_network_test.TestNetworks" name="test_prune_networks" time="7.192" /><testcase classname="tests.integration.api_network_test.TestNetworks" name="test_remove_network" time="7.219" /><testcase classname="tests.integration.api_secret_test.SecretAPITest" name="test_create_secret" time="11.957" /><testcase classname="tests.integration.api_secret_test.SecretAPITest" name="test_create_secret_unicode_data" time="7.138" /><testcase classname="tests.integration.api_secret_test.SecretAPITest" name="test_inspect_secret" time="7.177" /><testcase classname="tests.integration.api_secret_test.SecretAPITest" name="test_list_secrets" time="7.152" /><testcase classname="tests.integration.api_secret_test.SecretAPITest" name="test_remove_secret" time="11.957" /><testcase classname="tests.integration.api_volume_test.TestVolumes" name="test_create_volume" time="7.170" /><testcase classname="tests.integration.api_volume_test.TestVolumes" name="test_create_volume_invalid_driver" time="7.177"><failure message="docker.errors.APIError: 500 Server Error for http+docker://localhost/v1.40/volumes/create: Internal Server Error (&quot;volume perfectcherryblossom uses volume plugin invalid.driver but it could not be retrieved: no volume plugin with name invalid.driver available: required plugin missing&quot;)">docker/api/client.py:296: in _raise_for_status
    response.raise_for_status()
../../.virtualenvs/docker-py/lib/python3.9/site-packages/requests/models.py:953: in raise_for_status
    raise HTTPError(http_error_msg, response=self)
E   requests.exceptions.HTTPError: 500 Server Error: Internal Server Error for url: http+docker://localhost/v1.40/volumes/create

During handling of the above exception, another exception occurred:
/home/ubuntu/docker-py/tests/integration/api_volume_test.py:22: in test_create_volume_invalid_driver
    ???
docker/api/volume.py:89: in create_volume
    return self._result(self._post_json(url, data=data), True)
docker/api/client.py:302: in _result
    self._raise_for_status(response)
docker/api/client.py:298: in _raise_for_status
    raise create_api_error_from_http_exception(e)
docker/errors.py:31: in create_api_error_from_http_exception
    raise cls(e, response=response, explanation=explanation)
E   docker.errors.APIError: 500 Server Error for http+docker://localhost/v1.40/volumes/create: Internal Server Error ("volume perfectcherryblossom uses volume plugin invalid.driver but it could not be retrieved: no volume plugin with name invalid.driver available: required plugin missing")</failure><system-out>--------------------------------- Captured Log ---------------------------------

--------------------------------- Captured Out ---------------------------------

</system-out><system-err>--------------------------------- Captured Err ---------------------------------

</system-err></testcase><testcase classname="tests.integration.api_volume_test.TestVolumes" name="test_force_remove_volume" time="7.176" /><testcase classname="tests.integration.api_volume_test.TestVolumes" name="test_inspect_nonexistent_volume" time="7.177" /><testcase classname="tests.integration.api_volume_test.TestVolumes" name="test_inspect_volume" time="7.190"><failure message="AssertionError: assert {'CreatedAt':...l/_data', ...} == {'CreatedAt':...l/_data', ...}&#10;  Omitting 6 identical items, use -vv to show&#10;  Differing items:&#10;  {'Options': None} != {'Options': {}}&#10;  Full diff:&#10;    {&#10;     'CreatedAt': '2022-05-03T16:16:48+02:00',&#10;     'Driver': 'local',...&#10;  &#10;  ...Full output truncated (10 lines hidden), use '-vv' to show">/home/ubuntu/docker-py/tests/integration/api_volume_test.py:38: in test_inspect_volume
    ???
E   AssertionError: assert {'CreatedAt':...l/_data', ...} == {'CreatedAt':...l/_data', ...}
E     Omitting 6 identical items, use -vv to show
E     Differing items:
E     {'Options': None} != {'Options': {}}
E     Full diff:
E       {
E        'CreatedAt': '2022-05-03T16:16:48+02:00',
E        'Driver': 'local',...
E     
E     ...Full output truncated (10 lines hidden), use '-vv' to show</failure><system-out>--------------------------------- Captured Log ---------------------------------

--------------------------------- Captured Out ---------------------------------

</system-out><system-err>--------------------------------- Captured Err ---------------------------------

</system-err></testcase><testcase classname="tests.integration.api_volume_test.TestVolumes" name="test_list_volumes" time="7.193"><failure message="AssertionError: assert {'CreatedAt': '2022-05-03T16:16:56+02:00', 'Driver': 'local', 'Labels': {}, 'Mountpoint': '/home/riyad/podman/storage/volumes/imperishablenight/_data', ...} in [{'CreatedAt': '2022-05-03T15:59:10+02:00', 'Driver': 'local', 'Labels': {}, 'Mountpoint': '/home/riyad/podman/storage...00', 'Driver': 'local', 'Labels': {}, 'Mountpoint': '/home/riyad/podman/storage/volumes/imperishablenight/_data', ...}]">/home/ubuntu/docker-py/tests/integration/api_volume_test.py:31: in test_list_volumes
    ???
E   AssertionError: assert {'CreatedAt': '2022-05-03T16:16:56+02:00', 'Driver': 'local', 'Labels': {}, 'Mountpoint': '/home/riyad/podman/storage/volumes/imperishablenight/_data', ...} in [{'CreatedAt': '2022-05-03T15:59:10+02:00', 'Driver': 'local', 'Labels': {}, 'Mountpoint': '/home/riyad/podman/storage...00', 'Driver': 'local', 'Labels': {}, 'Mountpoint': '/home/riyad/podman/storage/volumes/imperishablenight/_data', ...}]</failure><system-out>--------------------------------- Captured Log ---------------------------------

--------------------------------- Captured Out ---------------------------------

</system-out><system-err>--------------------------------- Captured Err ---------------------------------

</system-err></testcase><testcase classname="tests.integration.api_volume_test.TestVolumes" name="test_prune_volumes" time="7.197" /><testcase classname="tests.integration.api_volume_test.TestVolumes" name="test_remove_nonexistent_volume" time="7.184" /><testcase classname="tests.integration.api_volume_test.TestVolumes" name="test_remove_volume" time="7.159" /><testcase classname="tests.integration.client_test.ClientTest" name="test_df" time="0.065" /><testcase classname="tests.integration.client_test.ClientTest" name="test_info" time="1.605" /><testcase classname="tests.integration.client_test.ClientTest" name="test_ping" time="0.003" /><testcase classname="tests.integration.client_test.ClientTest" name="test_version" time="2.422" /><testcase classname="tests.integration.client_test.CancellableEventsTest" name="test_cancel_events" time="2.003" /><testcase classname="tests.integration.context_api_test.ContextLifecycleTest" name="test_context_remove" time="7.176" /><testcase classname="tests.integration.context_api_test.ContextLifecycleTest" name="test_lifecycle" time="7.178" /><testcase classname="tests.integration.context_api_test.ContextLifecycleTest" name="test_load_context_without_orchestrator" time="7.164" /><testcase classname="tests.integration.errors_test.ErrorsTest" name="test_api_error_parses_json" time="7.504"><failure message="AssertionError: assert 'You cannot remove a running container' in 'cannot remove container 4af18c47d0f9dda19543887f1a76d2cbfc303c11618b313601159a3a85ee905f as it is running - running or paused containers cannot be removed without force: container state improper'">/home/ubuntu/docker-py/tests/integration/errors_test.py:13: in test_api_error_parses_json
    ???
E   AssertionError: assert 'You cannot remove a running container' in 'cannot remove container 4af18c47d0f9dda19543887f1a76d2cbfc303c11618b313601159a3a85ee905f as it is running - running or paused containers cannot be removed without force: container state improper'</failure><system-out>--------------------------------- Captured Log ---------------------------------

--------------------------------- Captured Out ---------------------------------

</system-out><system-err>--------------------------------- Captured Err ---------------------------------

</system-err></testcase><testcase classname="tests.integration.models_containers_test.ContainerCollectionTest" name="test_get" time="5.404"><failure message="AssertionError: assert 'docker.io/li...alpine:latest' == 'alpine'&#10;  - alpine&#10;  + docker.io/library/alpine:latest">/home/ubuntu/docker-py/tests/integration/models_containers_test.py:189: in test_get
    ???
E   AssertionError: assert 'docker.io/li...alpine:latest' == 'alpine'
E     - alpine
E     + docker.io/library/alpine:latest</failure><system-out>--------------------------------- Captured Log ---------------------------------

--------------------------------- Captured Out ---------------------------------

</system-out><system-err>--------------------------------- Captured Err ---------------------------------

</system-err></testcase><testcase classname="tests.integration.models_containers_test.ContainerCollectionTest" name="test_list" time="5.553"><failure message="AssertionError: assert 'docker.io/li...alpine:latest' == 'alpine'&#10;  - alpine&#10;  + docker.io/library/alpine:latest">/home/ubuntu/docker-py/tests/integration/models_containers_test.py:202: in test_list
    ???
E   AssertionError: assert 'docker.io/li...alpine:latest' == 'alpine'
E     - alpine
E     + docker.io/library/alpine:latest</failure><system-out>--------------------------------- Captured Log ---------------------------------

--------------------------------- Captured Out ---------------------------------

</system-out><system-err>--------------------------------- Captured Err ---------------------------------

</system-err></testcase><testcase classname="tests.integration.models_containers_test.ContainerCollectionTest" name="test_list_sparse" time="5.399"><failure message="AssertionError: assert 'docker.io/li...alpine:latest' == 'alpine'&#10;  - alpine&#10;  + docker.io/library/alpine:latest">/home/ubuntu/docker-py/tests/integration/models_containers_test.py:220: in test_list_sparse
    ???
E   AssertionError: assert 'docker.io/li...alpine:latest' == 'alpine'
E     - alpine
E     + docker.io/library/alpine:latest</failure><system-out>--------------------------------- Captured Log ---------------------------------

--------------------------------- Captured Out ---------------------------------

</system-out><system-err>--------------------------------- Captured Err ---------------------------------

</system-err></testcase><testcase classname="tests.integration.models_containers_test.ContainerCollectionTest" name="test_run" time="5.323" /><testcase classname="tests.integration.models_containers_test.ContainerCollectionTest" name="test_run_detach" time="5.406"><failure message="AssertionError: assert 'docker.io/li...alpine:latest' == 'alpine'&#10;  - alpine&#10;  + docker.io/library/alpine:latest">/home/ubuntu/docker-py/tests/integration/models_containers_test.py:26: in test_run_detach
    ???
E   AssertionError: assert 'docker.io/li...alpine:latest' == 'alpine'
E     - alpine
E     + docker.io/library/alpine:latest</failure><system-out>--------------------------------- Captured Log ---------------------------------

--------------------------------- Captured Out ---------------------------------

</system-out><system-err>--------------------------------- Captured Err ---------------------------------

</system-err></testcase><testcase classname="tests.integration.models_containers_test.ContainerCollectionTest" name="test_run_with_auto_remove" time="7.666" /><testcase classname="tests.integration.models_containers_test.ContainerCollectionTest" name="test_run_with_auto_remove_error" time="7.612"><failure message="docker.errors.APIError: 500 Server Error for http+docker://localhost/v1.40/containers/f2d55fc5b53ab31e6d143480edff47efdcd0ec6820518be1fea2b308e6ab381a/json: Internal Server Error (&quot;container f2d55fc5b53ab31e6d143480edff47efdcd0ec6820518be1fea2b308e6ab381a does not exist in database: no such container&quot;)">docker/api/client.py:296: in _raise_for_status
    response.raise_for_status()
../../.virtualenvs/docker-py/lib/python3.9/site-packages/requests/models.py:953: in raise_for_status
    raise HTTPError(http_error_msg, response=self)
E   requests.exceptions.HTTPError: 500 Server Error: Internal Server Error for url: http+docker://localhost/v1.40/containers/f2d55fc5b53ab31e6d143480edff47efdcd0ec6820518be1fea2b308e6ab381a/json

During handling of the above exception, another exception occurred:
/home/ubuntu/docker-py/tests/integration/models_containers_test.py:139: in test_run_with_auto_remove_error
    ???
docker/models/containers.py:835: in run
    out = container.logs(
docker/models/containers.py:306: in logs
    return self.client.api.logs(self.id, **kwargs)
docker/utils/decorators.py:19: in wrapped
    return f(self, resource_id, *args, **kwargs)
docker/api/container.py:869: in logs
    output = self._get_result(container, stream, res)
docker/api/client.py:495: in _get_result
    return self._get_result_tty(stream, res, self._check_is_tty(container))
docker/utils/decorators.py:19: in wrapped
    return f(self, resource_id, *args, **kwargs)
docker/api/client.py:491: in _check_is_tty
    cont = self.inspect_container(container)
docker/utils/decorators.py:19: in wrapped
    return f(self, resource_id, *args, **kwargs)
docker/api/container.py:771: in inspect_container
    return self._result(
docker/api/client.py:302: in _result
    self._raise_for_status(response)
docker/api/client.py:298: in _raise_for_status
    raise create_api_error_from_http_exception(e)
docker/errors.py:31: in create_api_error_from_http_exception
    raise cls(e, response=response, explanation=explanation)
E   docker.errors.APIError: 500 Server Error for http+docker://localhost/v1.40/containers/f2d55fc5b53ab31e6d143480edff47efdcd0ec6820518be1fea2b308e6ab381a/json: Internal Server Error ("container f2d55fc5b53ab31e6d143480edff47efdcd0ec6820518be1fea2b308e6ab381a does not exist in database: no such container")</failure><system-out>--------------------------------- Captured Log ---------------------------------

--------------------------------- Captured Out ---------------------------------

</system-out><system-err>--------------------------------- Captured Err ---------------------------------

</system-err></testcase><testcase classname="tests.integration.models_containers_test.ContainerCollectionTest" name="test_run_with_error" time="5.388" /><testcase classname="tests.integration.models_containers_test.ContainerCollectionTest" name="test_run_with_image_that_does_not_exist" time="6.442" /><testcase classname="tests.integration.models_containers_test.ContainerCollectionTest" name="test_run_with_json_file_driver" time="5.408" /><testcase classname="tests.integration.models_containers_test.ContainerCollectionTest" name="test_run_with_named_volume" time="5.697" /><testcase classname="tests.integration.models_containers_test.ContainerCollectionTest" name="test_run_with_network" time="5.253" /><testcase classname="tests.integration.models_containers_test.ContainerCollectionTest" name="test_run_with_none_driver" time="5.122" /><testcase classname="tests.integration.models_containers_test.ContainerCollectionTest" name="test_run_with_proxy_config" time="5.141" /><testcase classname="tests.integration.models_containers_test.ContainerCollectionTest" name="test_run_with_streamed_logs" time="5.170" /><testcase classname="tests.integration.models_containers_test.ContainerCollectionTest" name="test_run_with_streamed_logs_and_cancel" time="5.000"><failure message="Failed: Timeout &gt;5.0s">tests/integration/base.py:30: in tearDown
    client = docker.from_env(version=TEST_API_VERSION)
docker/client.py:96: in from_env
    return cls(
docker/client.py:45: in __init__
    self.api = APIClient(*args, **kwargs)
docker/api/client.py:197: in __init__
    self._version = self._retrieve_server_version()
docker/api/client.py:214: in _retrieve_server_version
    return self.version(api_version=False)["ApiVersion"]
docker/api/daemon.py:181: in version
    return self._result(self._get(url), json=True)
docker/utils/decorators.py:46: in inner
    return f(self, *args, **kwargs)
docker/api/client.py:251: in _get
    return self.get(url, **self._set_request_timeout(kwargs))
../../.virtualenvs/docker-py/lib/python3.9/site-packages/requests/sessions.py:555: in get
    return self.request('GET', url, **kwargs)
../../.virtualenvs/docker-py/lib/python3.9/site-packages/requests/sessions.py:542: in request
    resp = self.send(prep, **send_kwargs)
../../.virtualenvs/docker-py/lib/python3.9/site-packages/requests/sessions.py:655: in send
    r = adapter.send(request, **kwargs)
../../.virtualenvs/docker-py/lib/python3.9/site-packages/requests/adapters.py:439: in send
    resp = conn.urlopen(
../../.virtualenvs/docker-py/lib/python3.9/site-packages/urllib3/connectionpool.py:699: in urlopen
    httplib_response = self._make_request(
../../.virtualenvs/docker-py/lib/python3.9/site-packages/urllib3/connectionpool.py:445: in _make_request
    six.raise_from(e, None)
../../.virtualenvs/docker-py/lib/python3.9/site-packages/urllib3/connectionpool.py:440: in _make_request
    httplib_response = conn.getresponse()
/usr/lib/python3.9/http/client.py:1371: in getresponse
    response.begin()
/usr/lib/python3.9/http/client.py:319: in begin
    version, status, reason = self._read_status()
/usr/lib/python3.9/http/client.py:280: in _read_status
    line = str(self.fp.readline(_MAXLINE + 1), "iso-8859-1")
/usr/lib/python3.9/socket.py:704: in readinto
    return self._sock.recv_into(b)
E   Failed: Timeout &gt;5.0s</failure><system-out>--------------------------------- Captured Log ---------------------------------

--------------------------------- Captured Out ---------------------------------

</system-out><system-err>--------------------------------- Captured Err ---------------------------------

</system-err></testcase><testcase classname="tests.integration.models_containers_test.ContainerCollectionTest" name="test_run_with_volume" time="5.611" /><testcase classname="tests.integration.models_containers_test.ContainerTest" name="test_commit" time="6.386" /><testcase classname="tests.integration.models_containers_test.ContainerTest" name="test_create_with_volume_driver" time="4.895"><failure message="AssertionError: assert '' == 'foo'&#10;  - foo">/home/ubuntu/docker-py/tests/integration/models_containers_test.py:456: in test_create_with_volume_driver
    ???
E   AssertionError: assert '' == 'foo'
E     - foo</failure><system-out>--------------------------------- Captured Log ---------------------------------

--------------------------------- Captured Out ---------------------------------

</system-out><system-err>--------------------------------- Captured Err ---------------------------------

</system-err></testcase><testcase classname="tests.integration.models_containers_test.ContainerTest" name="test_diff" time="5.286"><failure message="AssertionError: assert [{'Kind': 1, ...ath': '/etc'}] == [{'Kind': 1, 'Path': '/test'}]&#10;  Left contains one more item: {'Kind': 0, 'Path': '/etc'}&#10;  Full diff:&#10;  - [{'Kind': 1, 'Path': '/test'}]&#10;  + [{'Kind': 1, 'Path': '/test'}, {'Kind': 0, 'Path': '/etc'}]">/home/ubuntu/docker-py/tests/integration/models_containers_test.py:251: in test_diff
    ???
E   AssertionError: assert [{'Kind': 1, ...ath': '/etc'}] == [{'Kind': 1, 'Path': '/test'}]
E     Left contains one more item: {'Kind': 0, 'Path': '/etc'}
E     Full diff:
E     - [{'Kind': 1, 'Path': '/test'}]
E     + [{'Kind': 1, 'Path': '/test'}, {'Kind': 0, 'Path': '/etc'}]</failure><system-out>--------------------------------- Captured Log ---------------------------------

--------------------------------- Captured Out ---------------------------------

</system-out><system-err>--------------------------------- Captured Err ---------------------------------

</system-err></testcase><testcase classname="tests.integration.models_containers_test.ContainerTest" name="test_exec_run_failed" time="5.536"><failure message="AssertionError: assert 127 == 126&#10;  +127&#10;  -126">/home/ubuntu/docker-py/tests/integration/models_containers_test.py:270: in test_exec_run_failed
    ???
E   AssertionError: assert 127 == 126
E     +127
E     -126</failure><system-out>--------------------------------- Captured Log ---------------------------------

--------------------------------- Captured Out ---------------------------------

</system-out><system-err>--------------------------------- Captured Err ---------------------------------

</system-err></testcase><testcase classname="tests.integration.models_containers_test.ContainerTest" name="test_exec_run_success" time="5.609" /><testcase classname="tests.integration.models_containers_test.ContainerTest" name="test_kill" time="5.424" /><testcase classname="tests.integration.models_containers_test.ContainerTest" name="test_logs" time="5.240" /><testcase classname="tests.integration.models_containers_test.ContainerTest" name="test_pause" time="5.548" /><testcase classname="tests.integration.models_containers_test.ContainerTest" name="test_ports_target_list" time="5.043"><failure message="docker.errors.APIError: 500 Server Error for http+docker://localhost/v1.40/containers/5be9b4bcd0f4a55a4bfb6baa44bdbe4672ccc185abb9d57af4516ff05d9ba0f4/start: Internal Server Error (&quot;could not find &quot;rootlessport&quot; in one of [/usr/local/libexec/podman /usr/local/lib/podman /usr/libexec/podman /usr/lib/podman].  To resolve this error, set the helper_binaries_dir key in the `[engine]` section of containers.conf to the directory containing your helper binaries.&quot;)">docker/api/client.py:296: in _raise_for_status
    response.raise_for_status()
../../.virtualenvs/docker-py/lib/python3.9/site-packages/requests/models.py:953: in raise_for_status
    raise HTTPError(http_error_msg, response=self)
E   requests.exceptions.HTTPError: 500 Server Error: Internal Server Error for url: http+docker://localhost/v1.40/containers/5be9b4bcd0f4a55a4bfb6baa44bdbe4672ccc185abb9d57af4516ff05d9ba0f4/start

During handling of the above exception, another exception occurred:
/home/ubuntu/docker-py/tests/integration/models_containers_test.py:394: in test_ports_target_list
    ???
docker/models/containers.py:826: in run
    container.start()
docker/models/containers.py:404: in start
    return self.client.api.start(self.id, **kwargs)
docker/utils/decorators.py:19: in wrapped
    return f(self, resource_id, *args, **kwargs)
docker/api/container.py:1109: in start
    self._raise_for_status(res)
docker/api/client.py:298: in _raise_for_status
    raise create_api_error_from_http_exception(e)
docker/errors.py:31: in create_api_error_from_http_exception
    raise cls(e, response=response, explanation=explanation)
E   docker.errors.APIError: 500 Server Error for http+docker://localhost/v1.40/containers/5be9b4bcd0f4a55a4bfb6baa44bdbe4672ccc185abb9d57af4516ff05d9ba0f4/start: Internal Server Error ("could not find "rootlessport" in one of [/usr/local/libexec/podman /usr/local/lib/podman /usr/libexec/podman /usr/lib/podman].  To resolve this error, set the helper_binaries_dir key in the `[engine]` section of containers.conf to the directory containing your helper binaries.")</failure><system-out>--------------------------------- Captured Log ---------------------------------

--------------------------------- Captured Out ---------------------------------

</system-out><system-err>--------------------------------- Captured Err ---------------------------------

</system-err></testcase><testcase classname="tests.integration.models_containers_test.ContainerTest" name="test_ports_target_none" time="4.952"><failure message="docker.errors.APIError: 500 Server Error for http+docker://localhost/v1.40/containers/12115fd0bb99685a87c7af28ced12c832e4c35d2c1251f3409e3d85718ca02d5/start: Internal Server Error (&quot;could not find &quot;rootlessport&quot; in one of [/usr/local/libexec/podman /usr/local/lib/podman /usr/libexec/podman /usr/lib/podman].  To resolve this error, set the helper_binaries_dir key in the `[engine]` section of containers.conf to the directory containing your helper binaries.&quot;)">docker/api/client.py:296: in _raise_for_status
    response.raise_for_status()
../../.virtualenvs/docker-py/lib/python3.9/site-packages/requests/models.py:953: in raise_for_status
    raise HTTPError(http_error_msg, response=self)
E   requests.exceptions.HTTPError: 500 Server Error: Internal Server Error for url: http+docker://localhost/v1.40/containers/12115fd0bb99685a87c7af28ced12c832e4c35d2c1251f3409e3d85718ca02d5/start

During handling of the above exception, another exception occurred:
/home/ubuntu/docker-py/tests/integration/models_containers_test.py:354: in test_ports_target_none
    ???
docker/models/containers.py:826: in run
    container.start()
docker/models/containers.py:404: in start
    return self.client.api.start(self.id, **kwargs)
docker/utils/decorators.py:19: in wrapped
    return f(self, resource_id, *args, **kwargs)
docker/api/container.py:1109: in start
    self._raise_for_status(res)
docker/api/client.py:298: in _raise_for_status
    raise create_api_error_from_http_exception(e)
docker/errors.py:31: in create_api_error_from_http_exception
    raise cls(e, response=response, explanation=explanation)
E   docker.errors.APIError: 500 Server Error for http+docker://localhost/v1.40/containers/12115fd0bb99685a87c7af28ced12c832e4c35d2c1251f3409e3d85718ca02d5/start: Internal Server Error ("could not find "rootlessport" in one of [/usr/local/libexec/podman /usr/local/lib/podman /usr/libexec/podman /usr/lib/podman].  To resolve this error, set the helper_binaries_dir key in the `[engine]` section of containers.conf to the directory containing your helper binaries.")</failure><system-out>--------------------------------- Captured Log ---------------------------------

--------------------------------- Captured Out ---------------------------------

</system-out><system-err>--------------------------------- Captured Err ---------------------------------

</system-err></testcase><testcase classname="tests.integration.models_containers_test.ContainerTest" name="test_ports_target_tuple" time="5.023"><failure message="docker.errors.APIError: 500 Server Error for http+docker://localhost/v1.40/containers/7dfbe065898ef31af1869c385ab183f2fe4402ef396b6b4f0dc062e34c11dbd3/start: Internal Server Error (&quot;could not find &quot;rootlessport&quot; in one of [/usr/local/libexec/podman /usr/local/lib/podman /usr/libexec/podman /usr/lib/podman].  To resolve this error, set the helper_binaries_dir key in the `[engine]` section of containers.conf to the directory containing your helper binaries.&quot;)">docker/api/client.py:296: in _raise_for_status
    response.raise_for_status()
../../.virtualenvs/docker-py/lib/python3.9/site-packages/requests/models.py:953: in raise_for_status
    raise HTTPError(http_error_msg, response=self)
E   requests.exceptions.HTTPError: 500 Server Error: Internal Server Error for url: http+docker://localhost/v1.40/containers/7dfbe065898ef31af1869c385ab183f2fe4402ef396b6b4f0dc062e34c11dbd3/start

During handling of the above exception, another exception occurred:
/home/ubuntu/docker-py/tests/integration/models_containers_test.py:374: in test_ports_target_tuple
    ???
docker/models/containers.py:826: in run
    container.start()
docker/models/containers.py:404: in start
    return self.client.api.start(self.id, **kwargs)
docker/utils/decorators.py:19: in wrapped
    return f(self, resource_id, *args, **kwargs)
docker/api/container.py:1109: in start
    self._raise_for_status(res)
docker/api/client.py:298: in _raise_for_status
    raise create_api_error_from_http_exception(e)
docker/errors.py:31: in create_api_error_from_http_exception
    raise cls(e, response=response, explanation=explanation)
E   docker.errors.APIError: 500 Server Error for http+docker://localhost/v1.40/containers/7dfbe065898ef31af1869c385ab183f2fe4402ef396b6b4f0dc062e34c11dbd3/start: Internal Server Error ("could not find "rootlessport" in one of [/usr/local/libexec/podman /usr/local/lib/podman /usr/libexec/podman /usr/lib/podman].  To resolve this error, set the helper_binaries_dir key in the `[engine]` section of containers.conf to the directory containing your helper binaries.")</failure><system-out>--------------------------------- Captured Log ---------------------------------

--------------------------------- Captured Out ---------------------------------

</system-out><system-err>--------------------------------- Captured Err ---------------------------------

</system-err></testcase><testcase classname="tests.integration.models_containers_test.ContainerTest" name="test_remove" time="5.438" /><testcase classname="tests.integration.models_containers_test.ContainerTest" name="test_rename" time="5.090" /><testcase classname="tests.integration.models_containers_test.ContainerTest" name="test_restart" time="15.999" /><testcase classname="tests.integration.models_containers_test.ContainerTest" name="test_start" time="4.884"><failure message="AssertionError: assert 'initialized' == 'created'&#10;  - created&#10;  + initialized">/home/ubuntu/docker-py/tests/integration/models_containers_test.py:336: in test_start
    ???
E   AssertionError: assert 'initialized' == 'created'
E     - created
E     + initialized</failure><system-out>--------------------------------- Captured Log ---------------------------------

--------------------------------- Captured Out ---------------------------------

</system-out><system-err>--------------------------------- Captured Err ---------------------------------

</system-err></testcase><testcase classname="tests.integration.models_containers_test.ContainerTest" name="test_stats" time="5.517" /><testcase classname="tests.integration.models_containers_test.ContainerTest" name="test_stop" time="5.538"><failure message="AssertionError: assert 'initialized' in ('running', 'created')&#10; +  where 'initialized' = &lt;Container: 23ace28f6f&gt;.status">/home/ubuntu/docker-py/tests/integration/models_containers_test.py:414: in test_stop
    ???
E   AssertionError: assert 'initialized' in ('running', 'created')
E    +  where 'initialized' = &lt;Container: 23ace28f6f&gt;.status</failure><system-out>--------------------------------- Captured Log ---------------------------------

--------------------------------- Captured Out ---------------------------------

</system-out><system-err>--------------------------------- Captured Err ---------------------------------

</system-err></testcase><testcase classname="tests.integration.models_containers_test.ContainerTest" name="test_top" time="5.645"><failure message="AssertionError: assert 'sleep 60' in ['1 root      0:00 sleep 60']">/home/ubuntu/docker-py/tests/integration/models_containers_test.py:425: in test_top
    ???
E   AssertionError: assert 'sleep 60' in ['1 root      0:00 sleep 60']</failure><system-out>--------------------------------- Captured Log ---------------------------------

--------------------------------- Captured Out ---------------------------------

</system-out><system-err>--------------------------------- Captured Err ---------------------------------

</system-err></testcase><testcase classname="tests.integration.models_containers_test.ContainerTest" name="test_update" time="5.490"><failure message="docker.errors.NotFound: 404 Client Error for http+docker://localhost/v1.40/containers/0256d500efa4c48acd6c310dc30d1a171987572d70ea212b25a6a703d6416c86/update: Not Found (&quot;b'Not Found'&quot;)">docker/api/client.py:296: in _raise_for_status
    response.raise_for_status()
../../.virtualenvs/docker-py/lib/python3.9/site-packages/requests/models.py:953: in raise_for_status
    raise HTTPError(http_error_msg, response=self)
E   requests.exceptions.HTTPError: 404 Client Error: Not Found for url: http+docker://localhost/v1.40/containers/0256d500efa4c48acd6c310dc30d1a171987572d70ea212b25a6a703d6416c86/update

During handling of the above exception, another exception occurred:
/home/ubuntu/docker-py/tests/integration/models_containers_test.py:433: in test_update
    ???
docker/models/containers.py:489: in update
    return self.client.api.update_container(self.id, **kwargs)
docker/utils/decorators.py:34: in wrapper
    return f(self, *args, **kwargs)
docker/utils/decorators.py:19: in wrapped
    return f(self, resource_id, *args, **kwargs)
docker/api/container.py:1268: in update_container
    return self._result(res, True)
docker/api/client.py:302: in _result
    self._raise_for_status(response)
docker/api/client.py:298: in _raise_for_status
    raise create_api_error_from_http_exception(e)
docker/errors.py:31: in create_api_error_from_http_exception
    raise cls(e, response=response, explanation=explanation)
E   docker.errors.NotFound: 404 Client Error for http+docker://localhost/v1.40/containers/0256d500efa4c48acd6c310dc30d1a171987572d70ea212b25a6a703d6416c86/update: Not Found ("b'Not Found'")</failure><system-out>--------------------------------- Captured Log ---------------------------------

--------------------------------- Captured Out ---------------------------------

</system-out><system-err>--------------------------------- Captured Err ---------------------------------

</system-err></testcase><testcase classname="tests.integration.models_containers_test.ContainerTest" name="test_wait" time="5.586" /><testcase classname="tests.integration.models_images_test.ImageCollectionTest" name="test_build" time="5.295" /><testcase classname="tests.integration.models_images_test.ImageCollectionTest" name="test_build_with_error" time="5.245"><failure message="AssertionError: assert &quot;The command '/bin/sh -c exit 1' returned a non-zero code: 1&quot; in 'docker.errors.BuildError: error building at STEP &quot;RUN exit 1&quot;: error while running runtime: exit status 1'&#10; +  where 'docker.errors.BuildError: error building at STEP &quot;RUN exit 1&quot;: error while running runtime: exit status 1' = &lt;bound method ExceptionInfo.exconly of &lt;ExceptionInfo BuildError('error building at STEP &quot;RUN exit 1&quot;: error while running runtime: exit status 1\n') tblen=2&gt;&gt;()&#10; +    where &lt;bound method ExceptionInfo.exconly of &lt;ExceptionInfo BuildError('error building at STEP &quot;RUN exit 1&quot;: error while running runtime: exit status 1\n') tblen=2&gt;&gt; = &lt;ExceptionInfo BuildError('error building at STEP &quot;RUN exit 1&quot;: error while running runtime: exit status 1\n') tblen=2&gt;.exconly">tests/integration/models_images_test.py:30: in test_build_with_error
    assert (
E   AssertionError: assert "The command '/bin/sh -c exit 1' returned a non-zero code: 1" in 'docker.errors.BuildError: error building at STEP "RUN exit 1": error while running runtime: exit status 1'
E    +  where 'docker.errors.BuildError: error building at STEP "RUN exit 1": error while running runtime: exit status 1' = &lt;bound method ExceptionInfo.exconly of &lt;ExceptionInfo BuildError('error building at STEP "RUN exit 1": error while running runtime: exit status 1\n') tblen=2&gt;&gt;()
E    +    where &lt;bound method ExceptionInfo.exconly of &lt;ExceptionInfo BuildError('error building at STEP "RUN exit 1": error while running runtime: exit status 1\n') tblen=2&gt;&gt; = &lt;ExceptionInfo BuildError('error building at STEP "RUN exit 1": error while running runtime: exit status 1\n') tblen=2&gt;.exconly</failure><system-out>--------------------------------- Captured Log ---------------------------------

--------------------------------- Captured Out ---------------------------------

</system-out><system-err>--------------------------------- Captured Err ---------------------------------

</system-err></testcase><testcase classname="tests.integration.models_images_test.ImageCollectionTest" name="test_build_with_multiple_success" time="5.273" /><testcase classname="tests.integration.models_images_test.ImageCollectionTest" name="test_build_with_success_build_output" time="5.243" /><testcase classname="tests.integration.models_images_test.ImageCollectionTest" name="test_list" time="8.536" /><testcase classname="tests.integration.models_images_test.ImageCollectionTest" name="test_list_with_repository" time="9.299" /><testcase classname="tests.integration.models_images_test.ImageCollectionTest" name="test_load_error" time="4.796"><failure message="docker.errors.APIError: 500 Server Error for http+docker://localhost/v1.40/images/load: Internal Server Error (&quot;failed to load image: payload does not match any of the supported image formats:&#10; * oci: initializing source oci:/var/tmp/api_load.tar228833226:: open /var/tmp/api_load.tar228833226/index.json: not a directory&#10; * oci-archive: creating temp directory: untarring file &quot;/var/tmp/oci2859448139&quot;: unexpected EOF&#10; * docker-archive: loading tar component manifest.json: unexpected EOF&#10; * dir: open /var/tmp/api_load.tar228833226/manifest.json: not a directory&quot;)">docker/api/client.py:296: in _raise_for_status
    response.raise_for_status()
../../.virtualenvs/docker-py/lib/python3.9/site-packages/requests/models.py:953: in raise_for_status
    raise HTTPError(http_error_msg, response=self)
E   requests.exceptions.HTTPError: 500 Server Error: Internal Server Error for url: http+docker://localhost/v1.40/images/load

During handling of the above exception, another exception occurred:
tests/integration/models_images_test.py:98: in test_load_error
    client.images.load('abc')
docker/models/images.py:382: in load
    for chunk in resp:
docker/api/client.py:386: in _stream_helper
    yield self._result(response, json=decode)
docker/api/client.py:302: in _result
    self._raise_for_status(response)
docker/api/client.py:298: in _raise_for_status
    raise create_api_error_from_http_exception(e)
docker/errors.py:31: in create_api_error_from_http_exception
    raise cls(e, response=response, explanation=explanation)
E   docker.errors.APIError: 500 Server Error for http+docker://localhost/v1.40/images/load: Internal Server Error ("failed to load image: payload does not match any of the supported image formats:
E    * oci: initializing source oci:/var/tmp/api_load.tar228833226:: open /var/tmp/api_load.tar228833226/index.json: not a directory
E    * oci-archive: creating temp directory: untarring file "/var/tmp/oci2859448139": unexpected EOF
E    * docker-archive: loading tar component manifest.json: unexpected EOF
E    * dir: open /var/tmp/api_load.tar228833226/manifest.json: not a directory")</failure><system-out>--------------------------------- Captured Log ---------------------------------

--------------------------------- Captured Out ---------------------------------

</system-out><system-err>--------------------------------- Captured Err ---------------------------------

</system-err></testcase><testcase classname="tests.integration.models_images_test.ImageCollectionTest" name="test_pull" time="7.140"><failure message="AssertionError: assert 'alpine:latest' in ['docker.io/library/alpine:latest']">tests/integration/models_images_test.py:71: in test_pull
    assert 'alpine:latest' in image.attrs['RepoTags']
E   AssertionError: assert 'alpine:latest' in ['docker.io/library/alpine:latest']</failure><system-out>--------------------------------- Captured Log ---------------------------------

--------------------------------- Captured Out ---------------------------------

</system-out><system-err>--------------------------------- Captured Err ---------------------------------

</system-err></testcase><testcase classname="tests.integration.models_images_test.ImageCollectionTest" name="test_pull_multiple" time="10.361"><failure message="AssertionError: assert False&#10; +  where False = any([False])">tests/integration/models_images_test.py:91: in test_pull_multiple
    assert any([
E   AssertionError: assert False
E    +  where False = any([False])</failure><system-out>--------------------------------- Captured Log ---------------------------------

--------------------------------- Captured Out ---------------------------------

</system-out><system-err>--------------------------------- Captured Err ---------------------------------

</system-err></testcase><testcase classname="tests.integration.models_images_test.ImageCollectionTest" name="test_pull_with_sha" time="9.106"><failure message="AssertionError: assert 'hello-world@sha256:083de497cff944f969d8499ab94f07134c50bcf5e6b9559b27182d3fa80ce3f7' in ['docker.io/library/hello-world@sha256:083de497cff944f969d8499ab94f07134c50bcf5e6b9559b27182d3fa80ce3f7', 'docker.io/library/hello-world@sha256:8072a54ebb3bc136150e2f2860f00a7bf45f13eeb917cca2430fcd0054c8e51b']">tests/integration/models_images_test.py:85: in test_pull_with_sha
    assert image_ref in image.attrs['RepoDigests']
E   AssertionError: assert 'hello-world@sha256:083de497cff944f969d8499ab94f07134c50bcf5e6b9559b27182d3fa80ce3f7' in ['docker.io/library/hello-world@sha256:083de497cff944f969d8499ab94f07134c50bcf5e6b9559b27182d3fa80ce3f7', 'docker.io/library/hello-world@sha256:8072a54ebb3bc136150e2f2860f00a7bf45f13eeb917cca2430fcd0054c8e51b']</failure><system-out>--------------------------------- Captured Log ---------------------------------

--------------------------------- Captured Out ---------------------------------

</system-out><system-err>--------------------------------- Captured Err ---------------------------------

</system-err></testcase><testcase classname="tests.integration.models_images_test.ImageCollectionTest" name="test_pull_with_tag" time="8.189"><failure message="AssertionError: assert 'alpine:3.10' in ['docker.io/library/alpine:3.10']">tests/integration/models_images_test.py:76: in test_pull_with_tag
    assert 'alpine:3.10' in image.attrs['RepoTags']
E   AssertionError: assert 'alpine:3.10' in ['docker.io/library/alpine:3.10']</failure><system-out>--------------------------------- Captured Log ---------------------------------

--------------------------------- Captured Out ---------------------------------

</system-out><system-err>--------------------------------- Captured Err ---------------------------------

</system-err></testcase><testcase classname="tests.integration.models_images_test.ImageCollectionTest" name="test_save_and_load" time="5.005" /><testcase classname="tests.integration.models_images_test.ImageCollectionTest" name="test_save_and_load_repo_name" time="4.821"><failure message="docker.errors.InvalidArgument: dockerpytest_4104307fc772722c:latest is not a valid tag for this image">tests/integration/models_images_test.py:122: in test_save_and_load_repo_name
    stream = image.save(named=f'{additional_tag}:latest')
docker/models/images.py:96: in save
    raise InvalidArgument(
E   docker.errors.InvalidArgument: dockerpytest_4104307fc772722c:latest is not a valid tag for this image</failure><system-out>--------------------------------- Captured Log ---------------------------------

--------------------------------- Captured Out ---------------------------------

</system-out><system-err>--------------------------------- Captured Err ---------------------------------

</system-err></testcase><testcase classname="tests.integration.models_images_test.ImageCollectionTest" name="test_save_name_error" time="4.790" /><testcase classname="tests.integration.models_images_test.ImageTest" name="test_tag_and_remove" time="7.408" /><testcase classname="tests.integration.models_networks_test.NetworkCollectionTest" name="test_create" time="4.830" /><testcase classname="tests.integration.models_networks_test.NetworkCollectionTest" name="test_get" time="4.834" /><testcase classname="tests.integration.models_networks_test.NetworkCollectionTest" name="test_list_remove" time="4.933" /><testcase classname="tests.integration.models_networks_test.NetworkTest" name="test_connect_disconnect" time="5.827" /><testcase classname="tests.integration.models_resources_test.ModelTest" name="test_reload" time="5.687" /><testcase classname="tests.integration.models_volumes_test.VolumesTest" name="test_create_get" time="4.872" /><testcase classname="tests.integration.models_volumes_test.VolumesTest" name="test_list_remove" time="4.822"><failure message="AssertionError: assert &lt;Volume: dockerpyte&gt; in []&#10; +  where [] = &lt;bound method VolumeCollection.list of &lt;docker.models.volumes.VolumeCollection object at 0x7f86353c8310&gt;&gt;(filters={'name': 'dockerpytest_'})&#10; +    where &lt;bound method VolumeCollection.list of &lt;docker.models.volumes.VolumeCollection object at 0x7f86353c8310&gt;&gt; = &lt;docker.models.volumes.VolumeCollection object at 0x7f86353c8310&gt;.list&#10; +      where &lt;docker.models.volumes.VolumeCollection object at 0x7f86353c8310&gt; = &lt;docker.client.DockerClient object at 0x7f86353c8cd0&gt;.volumes">/home/ubuntu/docker-py/tests/integration/models_volumes_test.py:26: in test_list_remove
    ???
E   AssertionError: assert &lt;Volume: dockerpyte&gt; in []
E    +  where [] = &lt;bound method VolumeCollection.list of &lt;docker.models.volumes.VolumeCollection object at 0x7f86353c8310&gt;&gt;(filters={'name': 'dockerpytest_'})
E    +    where &lt;bound method VolumeCollection.list of &lt;docker.models.volumes.VolumeCollection object at 0x7f86353c8310&gt;&gt; = &lt;docker.models.volumes.VolumeCollection object at 0x7f86353c8310&gt;.list
E    +      where &lt;docker.models.volumes.VolumeCollection object at 0x7f86353c8310&gt; = &lt;docker.client.DockerClient object at 0x7f86353c8cd0&gt;.volumes</failure><system-out>--------------------------------- Captured Log ---------------------------------

--------------------------------- Captured Out ---------------------------------

</system-out><system-err>--------------------------------- Captured Err ---------------------------------

</system-err></testcase><testcase classname="tests.integration.regression_test.TestRegressions" name="test_443_handle_nonchunked_response_in_stream" time="7.211"><failure message="Failed: DID NOT RAISE &lt;class 'docker.errors.APIError'&gt;">tests/integration/regression_test.py:15: in test_443_handle_nonchunked_response_in_stream
    pass
E   Failed: DID NOT RAISE &lt;class 'docker.errors.APIError'&gt;</failure><system-out>--------------------------------- Captured Log ---------------------------------

--------------------------------- Captured Out ---------------------------------

</system-out><system-err>--------------------------------- Captured Err ---------------------------------

</system-err></testcase><testcase classname="tests.integration.regression_test.TestRegressions" name="test_542_truncate_ids_client_side" time="7.603" /><testcase classname="tests.integration.regression_test.TestRegressions" name="test_647_support_doubleslash_in_image_names" time="7.221" /><testcase classname="tests.integration.regression_test.TestRegressions" name="test_649_handle_timeout_value_none" time="7.796" /><testcase classname="tests.integration.regression_test.TestRegressions" name="test_715_handle_user_param_as_int_value" time="7.766" /><testcase classname="tests.integration.regression_test.TestRegressions" name="test_792_explicit_port_protocol" time="7.483"><failure message="docker.errors.APIError: 500 Server Error for http+docker://localhost/v1.40/containers/41a73afbed7df24f36dc09afbd7ff0716c16c32fc59f18ed9195c668cf3fcdc9/start: Internal Server Error (&quot;could not find &quot;rootlessport&quot; in one of [/usr/local/libexec/podman /usr/local/lib/podman /usr/libexec/podman /usr/lib/podman].  To resolve this error, set the helper_binaries_dir key in the `[engine]` section of containers.conf to the directory containing your helper binaries.&quot;)">docker/api/client.py:296: in _raise_for_status
    response.raise_for_status()
../../.virtualenvs/docker-py/lib/python3.9/site-packages/requests/models.py:953: in raise_for_status
    raise HTTPError(http_error_msg, response=self)
E   requests.exceptions.HTTPError: 500 Server Error: Internal Server Error for url: http+docker://localhost/v1.40/containers/41a73afbed7df24f36dc09afbd7ff0716c16c32fc59f18ed9195c668cf3fcdc9/start

During handling of the above exception, another exception occurred:
tests/integration/regression_test.py:54: in test_792_explicit_port_protocol
    self.client.start(ctnr)
docker/utils/decorators.py:19: in wrapped
    return f(self, resource_id, *args, **kwargs)
docker/api/container.py:1109: in start
    self._raise_for_status(res)
docker/api/client.py:298: in _raise_for_status
    raise create_api_error_from_http_exception(e)
docker/errors.py:31: in create_api_error_from_http_exception
    raise cls(e, response=response, explanation=explanation)
E   docker.errors.APIError: 500 Server Error for http+docker://localhost/v1.40/containers/41a73afbed7df24f36dc09afbd7ff0716c16c32fc59f18ed9195c668cf3fcdc9/start: Internal Server Error ("could not find "rootlessport" in one of [/usr/local/libexec/podman /usr/local/lib/podman /usr/libexec/podman /usr/lib/podman].  To resolve this error, set the helper_binaries_dir key in the `[engine]` section of containers.conf to the directory containing your helper binaries.")</failure><system-out>--------------------------------- Captured Log ---------------------------------

--------------------------------- Captured Out ---------------------------------

</system-out><system-err>--------------------------------- Captured Err ---------------------------------

</system-err></testcase><testcase classname="tests.integration.credentials.utils_test" name="test_create_environment_dict" time="0.004" /></testsuite></testsuites>