============================= test session starts ==============================
platform linux -- Python 3.9.7, pytest-6.2.5, py-1.10.0, pluggy-1.0.0 -- /home/riyad/.virtualenvs/docker-py/bin/python
cachedir: .pytest_cache
rootdir: /home/riyad/src/docker-py, configfile: pytest_podman_apiv2.ini, testpaths: tests/integration/
plugins: timeout-2.0.1, cov-3.0.0
collecting ... collected 420 items / 154 deselected / 266 selected

tests/integration/api_build_test.py::BuildTest::test_build_container_with_target PASSED [  0%]
tests/integration/api_build_test.py::BuildTest::test_build_from_stringio PASSED [  0%]
tests/integration/api_build_test.py::BuildTest::test_build_gzip_custom_encoding PASSED [  1%]
tests/integration/api_build_test.py::BuildTest::test_build_gzip_encoding PASSED [  1%]
tests/integration/api_build_test.py::BuildTest::test_build_in_context_abs_dockerfile PASSED [  1%]
tests/integration/api_build_test.py::BuildTest::test_build_in_context_dockerfile PASSED [  2%]
tests/integration/api_build_test.py::BuildTest::test_build_in_context_nested_dockerfile PASSED [  2%]
tests/integration/api_build_test.py::BuildTest::test_build_invalid_platform PASSED [  3%]
tests/integration/api_build_test.py::BuildTest::test_build_isolation PASSED [  3%]
tests/integration/api_build_test.py::BuildTest::test_build_labels FAILED [  3%]
tests/integration/api_build_test.py::BuildTest::test_build_out_of_context_dockerfile PASSED [  4%]
tests/integration/api_build_test.py::BuildTest::test_build_shmsize PASSED [  4%]
tests/integration/api_build_test.py::BuildTest::test_build_squash FAILED [  4%]
tests/integration/api_build_test.py::BuildTest::test_build_stderr_data FAILED [  5%]
tests/integration/api_build_test.py::BuildTest::test_build_streaming PASSED [  5%]
tests/integration/api_build_test.py::BuildTest::test_build_with_buildargs PASSED [  6%]
tests/integration/api_build_test.py::BuildTest::test_build_with_cache_from FAILED [  6%]
tests/integration/api_build_test.py::BuildTest::test_build_with_dockerfile_empty_lines PASSED [  6%]
tests/integration/api_build_test.py::BuildTest::test_build_with_dockerignore PASSED [  7%]
tests/integration/api_build_test.py::BuildTest::test_build_with_extra_hosts FAILED [  7%]
tests/integration/api_build_test.py::BuildTest::test_build_with_network_mode FAILED [  7%]
tests/integration/api_build_test.py::BuildTest::test_build_with_proxy PASSED [  8%]
tests/integration/api_build_test.py::BuildTest::test_build_with_proxy_and_buildargs PASSED [  8%]
tests/integration/api_build_test.py::BuildTest::test_prune_builds XFAIL  [  9%]
tests/integration/api_client_test.py::InformationTest::test_info PASSED  [  9%]
tests/integration/api_client_test.py::InformationTest::test_version PASSED [  9%]
tests/integration/api_client_test.py::AutoDetectVersionTest::test_client_init PASSED [ 10%]
tests/integration/api_client_test.py::ConnectionTimeoutTest::test_timeout PASSED [ 10%]
tests/integration/api_client_test.py::UnixconnTest::test_resource_warnings PASSED [ 10%]
tests/integration/api_container_test.py::ListContainersTest::test_list_containers PASSED [ 11%]
tests/integration/api_container_test.py::CreateContainerTest::test_create PASSED [ 11%]
tests/integration/api_container_test.py::CreateContainerTest::test_create_container_with_volumes_from PASSED [ 12%]
tests/integration/api_container_test.py::CreateContainerTest::test_create_with_auto_remove PASSED [ 12%]
tests/integration/api_container_test.py::CreateContainerTest::test_create_with_cpu_rt_options XPASS [ 12%]
tests/integration/api_container_test.py::CreateContainerTest::test_create_with_device_cgroup_rules FAILED [ 13%]
tests/integration/api_container_test.py::CreateContainerTest::test_create_with_environment_variable_no_value FAILED [ 13%]
tests/integration/api_container_test.py::CreateContainerTest::test_create_with_host_pid_mode PASSED [ 13%]
tests/integration/api_container_test.py::CreateContainerTest::test_create_with_init PASSED [ 14%]
tests/integration/api_container_test.py::CreateContainerTest::test_create_with_isolation FAILED [ 14%]
tests/integration/api_container_test.py::CreateContainerTest::test_create_with_links FAILED [ 15%]
tests/integration/api_container_test.py::CreateContainerTest::test_create_with_mac_address FAILED [ 15%]
tests/integration/api_container_test.py::CreateContainerTest::test_create_with_memory_constraints_with_int PASSED [ 15%]
tests/integration/api_container_test.py::CreateContainerTest::test_create_with_memory_constraints_with_str PASSED [ 16%]
tests/integration/api_container_test.py::CreateContainerTest::test_create_with_restart_policy FAILED [ 16%]
tests/integration/api_container_test.py::CreateContainerTest::test_create_with_stop_timeout PASSED [ 16%]
tests/integration/api_container_test.py::CreateContainerTest::test_create_with_storage_opt XFAIL [ 17%]
tests/integration/api_container_test.py::CreateContainerTest::test_create_with_tmpfs FAILED [ 17%]
tests/integration/api_container_test.py::CreateContainerTest::test_create_with_uts_mode PASSED [ 18%]
tests/integration/api_container_test.py::CreateContainerTest::test_group_id_ints PASSED [ 18%]
tests/integration/api_container_test.py::CreateContainerTest::test_group_id_strings PASSED [ 18%]
tests/integration/api_container_test.py::CreateContainerTest::test_invalid_log_driver_raises_exception FAILED [ 19%]
tests/integration/api_container_test.py::CreateContainerTest::test_valid_log_driver_and_log_opt FAILED [ 19%]
tests/integration/api_container_test.py::CreateContainerTest::test_valid_no_config_specified FAILED [ 19%]
tests/integration/api_container_test.py::CreateContainerTest::test_valid_no_log_driver_specified FAILED [ 20%]
tests/integration/api_container_test.py::VolumeBindTest::test_create_with_binds_ro PASSED [ 20%]
tests/integration/api_container_test.py::VolumeBindTest::test_create_with_binds_rw PASSED [ 21%]
tests/integration/api_container_test.py::VolumeBindTest::test_create_with_mounts PASSED [ 21%]
tests/integration/api_container_test.py::VolumeBindTest::test_create_with_mounts_ro PASSED [ 21%]
tests/integration/api_container_test.py::VolumeBindTest::test_create_with_volume_mount PASSED [ 22%]
tests/integration/api_container_test.py::ArchiveTest::test_copy_directory_to_container PASSED [ 22%]
tests/integration/api_container_test.py::ArchiveTest::test_copy_file_to_container PASSED [ 22%]
tests/integration/api_container_test.py::ArchiveTest::test_get_file_archive_from_container PASSED [ 23%]
tests/integration/api_container_test.py::ArchiveTest::test_get_file_stat_from_container PASSED [ 23%]
tests/integration/api_container_test.py::RenameContainerTest::test_rename_container PASSED [ 24%]
tests/integration/api_container_test.py::StartContainerTest::test_run_shlex_commands PASSED [ 24%]
tests/integration/api_container_test.py::StartContainerTest::test_start_container PASSED [ 24%]
tests/integration/api_container_test.py::StartContainerTest::test_start_container_with_dict_instead_of_id PASSED [ 25%]
tests/integration/api_container_test.py::WaitTest::test_wait PASSED      [ 25%]
tests/integration/api_container_test.py::WaitTest::test_wait_with_condition PASSED [ 25%]
tests/integration/api_container_test.py::WaitTest::test_wait_with_dict_instead_of_id PASSED [ 26%]
tests/integration/api_container_test.py::LogsTest::test_logs PASSED      [ 26%]
tests/integration/api_container_test.py::LogsTest::test_logs_streaming_and_follow PASSED [ 27%]
tests/integration/api_container_test.py::LogsTest::test_logs_streaming_and_follow_and_cancel FAILED [ 27%]
tests/integration/api_container_test.py::LogsTest::test_logs_tail_option PASSED [ 27%]
tests/integration/api_container_test.py::LogsTest::test_logs_with_dict_instead_of_id PASSED [ 28%]
tests/integration/api_container_test.py::LogsTest::test_logs_with_tail_0 PASSED [ 28%]
tests/integration/api_container_test.py::LogsTest::test_logs_with_until PASSED [ 28%]
tests/integration/api_container_test.py::DiffTest::test_diff PASSED      [ 29%]
tests/integration/api_container_test.py::DiffTest::test_diff_with_dict_instead_of_id PASSED [ 29%]
tests/integration/api_container_test.py::StopTest::test_stop PASSED      [ 30%]
tests/integration/api_container_test.py::StopTest::test_stop_with_dict_instead_of_id PASSED [ 30%]
tests/integration/api_container_test.py::KillTest::test_kill PASSED      [ 30%]
tests/integration/api_container_test.py::KillTest::test_kill_with_dict_instead_of_id PASSED [ 31%]
tests/integration/api_container_test.py::KillTest::test_kill_with_signal PASSED [ 31%]
tests/integration/api_container_test.py::KillTest::test_kill_with_signal_integer PASSED [ 31%]
tests/integration/api_container_test.py::KillTest::test_kill_with_signal_name PASSED [ 32%]
tests/integration/api_container_test.py::PortTest::test_port FAILED      [ 32%]
tests/integration/api_container_test.py::ContainerTopTest::test_top XFAIL [ 33%]
tests/integration/api_container_test.py::ContainerTopTest::test_top_with_psargs XFAIL [ 33%]
tests/integration/api_container_test.py::RestartContainerTest::test_restart PASSED [ 33%]
tests/integration/api_container_test.py::RestartContainerTest::test_restart_with_dict_instead_of_id PASSED [ 34%]
tests/integration/api_container_test.py::RestartContainerTest::test_restart_with_low_timeout PASSED [ 34%]
tests/integration/api_container_test.py::RemoveContainerTest::test_remove PASSED [ 34%]
tests/integration/api_container_test.py::RemoveContainerTest::test_remove_with_dict_instead_of_id PASSED [ 35%]
tests/integration/api_container_test.py::AttachContainerTest::test_attach_no_stream FAILED [ 35%]
tests/integration/api_container_test.py::AttachContainerTest::test_attach_stream_and_cancel FAILED [ 36%]
tests/integration/api_container_test.py::AttachContainerTest::test_detach_with_arg PASSED [ 36%]
tests/integration/api_container_test.py::AttachContainerTest::test_detach_with_config_file PASSED [ 36%]
tests/integration/api_container_test.py::AttachContainerTest::test_detach_with_default PASSED [ 37%]
tests/integration/api_container_test.py::AttachContainerTest::test_run_container_reading_socket PASSED [ 37%]
tests/integration/api_container_test.py::AttachContainerTest::test_run_container_streaming PASSED [ 37%]
tests/integration/api_container_test.py::PauseTest::test_pause_unpause PASSED [ 38%]
tests/integration/api_container_test.py::PruneTest::test_prune_containers PASSED [ 38%]
tests/integration/api_container_test.py::GetContainerStatsTest::test_get_container_stats_no_stream PASSED [ 39%]
tests/integration/api_container_test.py::ContainerUpdateTest::test_restart_policy_update FAILED [ 39%]
tests/integration/api_container_test.py::ContainerUpdateTest::test_update_container FAILED [ 39%]
tests/integration/api_container_test.py::ContainerCPUTest::test_container_cpu_shares PASSED [ 40%]
tests/integration/api_container_test.py::ContainerCPUTest::test_container_cpuset PASSED [ 40%]
tests/integration/api_container_test.py::ContainerCPUTest::test_create_with_runtime FAILED [ 40%]
tests/integration/api_exec_test.py::ExecTest::test_detach_with_config_file FAILED [ 41%]
tests/integration/api_exec_test.py::ExecTest::test_detach_with_default PASSED [ 41%]
tests/integration/api_exec_test.py::ExecTest::test_exec_command_as_root PASSED [ 42%]
tests/integration/api_exec_test.py::ExecTest::test_exec_command_as_user PASSED [ 42%]
tests/integration/api_exec_test.py::ExecTest::test_exec_command_streaming PASSED [ 42%]
tests/integration/api_exec_test.py::ExecTest::test_exec_command_string PASSED [ 43%]
tests/integration/api_exec_test.py::ExecTest::test_exec_command_with_env PASSED [ 43%]
tests/integration/api_exec_test.py::ExecTest::test_exec_command_with_workdir PASSED [ 43%]
tests/integration/api_exec_test.py::ExecTest::test_exec_inspect PASSED   [ 44%]
tests/integration/api_exec_test.py::ExecTest::test_exec_start_detached FAILED [ 44%]
tests/integration/api_exec_test.py::ExecTest::test_exec_start_socket FAILED [ 45%]
tests/integration/api_exec_test.py::ExecTest::test_execute_command PASSED [ 45%]
tests/integration/api_exec_test.py::ExecTest::test_execute_command_with_proxy_env PASSED [ 45%]
tests/integration/api_exec_test.py::ExecDemuxTest::test_exec_command_no_stream_demux PASSED [ 46%]
tests/integration/api_exec_test.py::ExecDemuxTest::test_exec_command_no_stream_no_demux PASSED [ 46%]
tests/integration/api_exec_test.py::ExecDemuxTest::test_exec_command_stream_demux PASSED [ 46%]
tests/integration/api_exec_test.py::ExecDemuxTest::test_exec_command_stream_no_demux PASSED [ 47%]
tests/integration/api_exec_test.py::ExecDemuxTest::test_exec_command_tty_no_stream_demux FAILED [ 47%]
tests/integration/api_exec_test.py::ExecDemuxTest::test_exec_command_tty_no_stream_no_demux FAILED [ 48%]
tests/integration/api_exec_test.py::ExecDemuxTest::test_exec_command_tty_stream_demux FAILED [ 48%]
tests/integration/api_exec_test.py::ExecDemuxTest::test_exec_command_tty_stream_no_demux FAILED [ 48%]
tests/integration/api_healthcheck_test.py::HealthcheckTest::test_healthcheck_fails PASSED [ 49%]
tests/integration/api_healthcheck_test.py::HealthcheckTest::test_healthcheck_passes PASSED [ 49%]
tests/integration/api_healthcheck_test.py::HealthcheckTest::test_healthcheck_shell_command PASSED [ 50%]
tests/integration/api_healthcheck_test.py::HealthcheckTest::test_healthcheck_start_period PASSED [ 50%]
tests/integration/api_image_test.py::ListImagesTest::test_images PASSED  [ 50%]
tests/integration/api_image_test.py::ListImagesTest::test_images_quiet PASSED [ 51%]
tests/integration/api_image_test.py::PullImageTest::test_pull PASSED     [ 51%]
tests/integration/api_image_test.py::PullImageTest::test_pull_invalid_platform FAILED [ 51%]
tests/integration/api_image_test.py::PullImageTest::test_pull_streaming PASSED [ 52%]
tests/integration/api_image_test.py::CommitTest::test_commit FAILED      [ 52%]
tests/integration/api_image_test.py::CommitTest::test_commit_with_changes FAILED [ 53%]
tests/integration/api_image_test.py::RemoveImageTest::test_remove PASSED [ 53%]
tests/integration/api_image_test.py::ImportImageTest::test_get_load_image FAILED [ 53%]
tests/integration/api_image_test.py::ImportImageTest::test_import_from_bytes PASSED [ 54%]
tests/integration/api_image_test.py::ImportImageTest::test_import_from_file PASSED [ 54%]
tests/integration/api_image_test.py::ImportImageTest::test_import_from_stream PASSED [ 54%]
tests/integration/api_image_test.py::ImportImageTest::test_import_from_url SKIPPED [ 55%]
tests/integration/api_image_test.py::ImportImageTest::test_import_image_from_data_with_changes FAILED [ 55%]
tests/integration/api_image_test.py::ImportImageTest::test_import_image_with_changes FAILED [ 56%]
tests/integration/api_image_test.py::PruneImagesTest::test_prune_images FAILED [ 56%]
tests/integration/api_image_test.py::SaveLoadImagesTest::test_get_image_load_image FAILED [ 56%]
tests/integration/api_image_test.py::InspectDistributionTest::test_inspect_distribution FAILED [ 57%]
tests/integration/api_network_test.py::TestNetworks::test_connect_and_disconnect_container FAILED [ 57%]
tests/integration/api_network_test.py::TestNetworks::test_connect_and_force_disconnect_container FAILED [ 57%]
tests/integration/api_network_test.py::TestNetworks::test_connect_on_container_create PASSED [ 58%]
tests/integration/api_network_test.py::TestNetworks::test_connect_with_aliases FAILED [ 58%]
tests/integration/api_network_test.py::TestNetworks::test_connect_with_ipv4_address FAILED [ 59%]
tests/integration/api_network_test.py::TestNetworks::test_connect_with_ipv6_address FAILED [ 59%]
tests/integration/api_network_test.py::TestNetworks::test_connect_with_links FAILED [ 59%]
tests/integration/api_network_test.py::TestNetworks::test_create_check_duplicate FAILED [ 60%]
tests/integration/api_network_test.py::TestNetworks::test_create_internal_networks PASSED [ 60%]
tests/integration/api_network_test.py::TestNetworks::test_create_network_ipv6_enabled PASSED [ 60%]
tests/integration/api_network_test.py::TestNetworks::test_create_network_with_host_driver_fails PASSED [ 61%]
tests/integration/api_network_test.py::TestNetworks::test_create_network_with_ipam_config FAILED [ 61%]
tests/integration/api_network_test.py::TestNetworks::test_create_network_with_labels PASSED [ 62%]
tests/integration/api_network_test.py::TestNetworks::test_create_network_with_labels_wrong_type PASSED [ 62%]
tests/integration/api_network_test.py::TestNetworks::test_create_remove_network_with_space_in_name FAILED [ 62%]
tests/integration/api_network_test.py::TestNetworks::test_create_with_aliases PASSED [ 63%]
tests/integration/api_network_test.py::TestNetworks::test_create_with_driveropt FAILED [ 63%]
tests/integration/api_network_test.py::TestNetworks::test_create_with_ipv4_address FAILED [ 63%]
tests/integration/api_network_test.py::TestNetworks::test_create_with_ipv6_address FAILED [ 64%]
tests/integration/api_network_test.py::TestNetworks::test_create_with_linklocal_ips FAILED [ 64%]
tests/integration/api_network_test.py::TestNetworks::test_create_with_links FAILED [ 65%]
tests/integration/api_network_test.py::TestNetworks::test_inspect_network PASSED [ 65%]
tests/integration/api_network_test.py::TestNetworks::test_list_networks PASSED [ 65%]
tests/integration/api_network_test.py::TestNetworks::test_prune_networks PASSED [ 66%]
tests/integration/api_network_test.py::TestNetworks::test_remove_network PASSED [ 66%]
tests/integration/api_secret_test.py::SecretAPITest::test_create_secret ERROR [ 66%]
tests/integration/api_secret_test.py::SecretAPITest::test_create_secret_unicode_data ERROR [ 67%]
tests/integration/api_secret_test.py::SecretAPITest::test_inspect_secret ERROR [ 67%]
tests/integration/api_secret_test.py::SecretAPITest::test_list_secrets ERROR [ 68%]
tests/integration/api_secret_test.py::SecretAPITest::test_remove_secret ERROR [ 68%]
tests/integration/api_volume_test.py::TestVolumes::test_create_volume PASSED [ 68%]
tests/integration/api_volume_test.py::TestVolumes::test_create_volume_invalid_driver FAILED [ 69%]
tests/integration/api_volume_test.py::TestVolumes::test_force_remove_volume PASSED [ 69%]
tests/integration/api_volume_test.py::TestVolumes::test_inspect_nonexistent_volume PASSED [ 69%]
tests/integration/api_volume_test.py::TestVolumes::test_inspect_volume FAILED [ 70%]
tests/integration/api_volume_test.py::TestVolumes::test_list_volumes FAILED [ 70%]
tests/integration/api_volume_test.py::TestVolumes::test_prune_volumes PASSED [ 71%]
tests/integration/api_volume_test.py::TestVolumes::test_remove_nonexistent_volume PASSED [ 71%]
tests/integration/api_volume_test.py::TestVolumes::test_remove_volume PASSED [ 71%]
tests/integration/client_test.py::ClientTest::test_df PASSED             [ 72%]
tests/integration/client_test.py::ClientTest::test_info PASSED           [ 72%]
tests/integration/client_test.py::ClientTest::test_ping PASSED           [ 72%]
tests/integration/client_test.py::ClientTest::test_version PASSED        [ 73%]
tests/integration/client_test.py::CancellableEventsTest::test_cancel_events PASSED [ 73%]
tests/integration/context_api_test.py::ContextLifecycleTest::test_context_remove PASSED [ 74%]
tests/integration/context_api_test.py::ContextLifecycleTest::test_lifecycle PASSED [ 74%]
tests/integration/context_api_test.py::ContextLifecycleTest::test_load_context_without_orchestrator PASSED [ 74%]
tests/integration/errors_test.py::ErrorsTest::test_api_error_parses_json FAILED [ 75%]
tests/integration/models_containers_test.py::ContainerCollectionTest::test_get FAILED [ 75%]
tests/integration/models_containers_test.py::ContainerCollectionTest::test_list FAILED [ 75%]
tests/integration/models_containers_test.py::ContainerCollectionTest::test_list_sparse FAILED [ 76%]
tests/integration/models_containers_test.py::ContainerCollectionTest::test_run PASSED [ 76%]
tests/integration/models_containers_test.py::ContainerCollectionTest::test_run_detach FAILED [ 77%]
tests/integration/models_containers_test.py::ContainerCollectionTest::test_run_with_auto_remove PASSED [ 77%]
tests/integration/models_containers_test.py::ContainerCollectionTest::test_run_with_auto_remove_error FAILED [ 77%]
tests/integration/models_containers_test.py::ContainerCollectionTest::test_run_with_error PASSED [ 78%]
tests/integration/models_containers_test.py::ContainerCollectionTest::test_run_with_image_that_does_not_exist PASSED [ 78%]
tests/integration/models_containers_test.py::ContainerCollectionTest::test_run_with_json_file_driver PASSED [ 78%]
tests/integration/models_containers_test.py::ContainerCollectionTest::test_run_with_named_volume PASSED [ 79%]
tests/integration/models_containers_test.py::ContainerCollectionTest::test_run_with_network PASSED [ 79%]
tests/integration/models_containers_test.py::ContainerCollectionTest::test_run_with_none_driver PASSED [ 80%]
tests/integration/models_containers_test.py::ContainerCollectionTest::test_run_with_proxy_config PASSED [ 80%]
tests/integration/models_containers_test.py::ContainerCollectionTest::test_run_with_streamed_logs PASSED [ 80%]
tests/integration/models_containers_test.py::ContainerCollectionTest::test_run_with_streamed_logs_and_cancel FAILED [ 81%]
tests/integration/models_containers_test.py::ContainerCollectionTest::test_run_with_volume PASSED [ 81%]
tests/integration/models_containers_test.py::ContainerTest::test_commit FAILED [ 81%]
tests/integration/models_containers_test.py::ContainerTest::test_create_with_volume_driver FAILED [ 82%]
tests/integration/models_containers_test.py::ContainerTest::test_diff FAILED [ 82%]
tests/integration/models_containers_test.py::ContainerTest::test_exec_run_failed FAILED [ 83%]
tests/integration/models_containers_test.py::ContainerTest::test_exec_run_success PASSED [ 83%]
tests/integration/models_containers_test.py::ContainerTest::test_kill FAILED [ 83%]
tests/integration/models_containers_test.py::ContainerTest::test_logs PASSED [ 84%]
tests/integration/models_containers_test.py::ContainerTest::test_pause PASSED [ 84%]
tests/integration/models_containers_test.py::ContainerTest::test_ports_target_list FAILED [ 84%]
tests/integration/models_containers_test.py::ContainerTest::test_ports_target_none FAILED [ 85%]
tests/integration/models_containers_test.py::ContainerTest::test_ports_target_tuple FAILED [ 85%]
tests/integration/models_containers_test.py::ContainerTest::test_remove PASSED [ 86%]
tests/integration/models_containers_test.py::ContainerTest::test_rename PASSED [ 86%]
tests/integration/models_containers_test.py::ContainerTest::test_restart PASSED [ 86%]
tests/integration/models_containers_test.py::ContainerTest::test_start PASSED [ 87%]
tests/integration/models_containers_test.py::ContainerTest::test_stats PASSED [ 87%]
tests/integration/models_containers_test.py::ContainerTest::test_stop PASSED [ 87%]
tests/integration/models_containers_test.py::ContainerTest::test_top FAILED [ 88%]
tests/integration/models_containers_test.py::ContainerTest::test_update FAILED [ 88%]
tests/integration/models_containers_test.py::ContainerTest::test_wait PASSED [ 89%]
tests/integration/models_images_test.py::ImageCollectionTest::test_build FAILED [ 89%]
tests/integration/models_images_test.py::ImageCollectionTest::test_build_with_error FAILED [ 89%]
tests/integration/models_images_test.py::ImageCollectionTest::test_build_with_multiple_success FAILED [ 90%]
tests/integration/models_images_test.py::ImageCollectionTest::test_build_with_success_build_output FAILED [ 90%]
tests/integration/models_images_test.py::ImageCollectionTest::test_list FAILED [ 90%]
tests/integration/models_images_test.py::ImageCollectionTest::test_list_with_repository FAILED [ 91%]
tests/integration/models_images_test.py::ImageCollectionTest::test_load_error FAILED [ 91%]
tests/integration/models_images_test.py::ImageCollectionTest::test_pull FAILED [ 92%]
tests/integration/models_images_test.py::ImageCollectionTest::test_pull_multiple FAILED [ 92%]
tests/integration/models_images_test.py::ImageCollectionTest::test_pull_with_sha FAILED [ 92%]
tests/integration/models_images_test.py::ImageCollectionTest::test_pull_with_tag FAILED [ 93%]
tests/integration/models_images_test.py::ImageCollectionTest::test_save_and_load FAILED [ 93%]
tests/integration/models_images_test.py::ImageCollectionTest::test_save_and_load_repo_name FAILED [ 93%]
tests/integration/models_images_test.py::ImageCollectionTest::test_save_name_error PASSED [ 94%]
tests/integration/models_images_test.py::ImageTest::test_tag_and_remove FAILED [ 94%]
tests/integration/models_networks_test.py::NetworkCollectionTest::test_create PASSED [ 95%]
tests/integration/models_networks_test.py::NetworkCollectionTest::test_get PASSED [ 95%]
tests/integration/models_networks_test.py::NetworkCollectionTest::test_list_remove PASSED [ 95%]
tests/integration/models_networks_test.py::NetworkTest::test_connect_disconnect FAILED [ 96%]
tests/integration/models_resources_test.py::ModelTest::test_reload PASSED [ 96%]
tests/integration/models_volumes_test.py::VolumesTest::test_create_get PASSED [ 96%]
tests/integration/models_volumes_test.py::VolumesTest::test_list_remove FAILED [ 97%]
tests/integration/regression_test.py::TestRegressions::test_443_handle_nonchunked_response_in_stream FAILED [ 97%]
tests/integration/regression_test.py::TestRegressions::test_542_truncate_ids_client_side PASSED [ 98%]
tests/integration/regression_test.py::TestRegressions::test_647_support_doubleslash_in_image_names PASSED [ 98%]
tests/integration/regression_test.py::TestRegressions::test_649_handle_timeout_value_none PASSED [ 98%]
tests/integration/regression_test.py::TestRegressions::test_715_handle_user_param_as_int_value PASSED [ 99%]
tests/integration/regression_test.py::TestRegressions::test_792_explicit_port_protocol FAILED [ 99%]
tests/integration/credentials/utils_test.py::test_create_environment_dict PASSED [100%]

==================================== ERRORS ====================================
______________ ERROR at setup of SecretAPITest.test_create_secret ______________
docker/api/client.py:296: in _raise_for_status
    response.raise_for_status()
../../.virtualenvs/docker-py/lib/python3.9/site-packages/requests/models.py:953: in raise_for_status
    raise HTTPError(http_error_msg, response=self)
E   requests.exceptions.HTTPError: 503 Server Error: Service Unavailable for url: http+docker://localhost/v1.40/swarm/init

During handling of the above exception, another exception occurred:
tests/integration/api_secret_test.py:15: in setup_class
    cls._init_swarm(client)
tests/integration/base.py:94: in _init_swarm
    return client.init_swarm(
docker/utils/decorators.py:34: in wrapper
    return f(self, *args, **kwargs)
docker/api/swarm.py:170: in init_swarm
    return self._result(response, json=True)
docker/api/client.py:302: in _result
    self._raise_for_status(response)
docker/api/client.py:298: in _raise_for_status
    raise create_api_error_from_http_exception(e)
docker/errors.py:31: in create_api_error_from_http_exception
    raise cls(e, response=response, explanation=explanation)
E   docker.errors.APIError: 503 Server Error for http+docker://localhost/v1.40/swarm/init: Service Unavailable ("Podman does not support service: /v1.40/swarm/init")
_______ ERROR at setup of SecretAPITest.test_create_secret_unicode_data ________
docker/api/client.py:296: in _raise_for_status
    response.raise_for_status()
../../.virtualenvs/docker-py/lib/python3.9/site-packages/requests/models.py:953: in raise_for_status
    raise HTTPError(http_error_msg, response=self)
E   requests.exceptions.HTTPError: 503 Server Error: Service Unavailable for url: http+docker://localhost/v1.40/swarm/init

During handling of the above exception, another exception occurred:
tests/integration/api_secret_test.py:15: in setup_class
    cls._init_swarm(client)
tests/integration/base.py:94: in _init_swarm
    return client.init_swarm(
docker/utils/decorators.py:34: in wrapper
    return f(self, *args, **kwargs)
docker/api/swarm.py:170: in init_swarm
    return self._result(response, json=True)
docker/api/client.py:302: in _result
    self._raise_for_status(response)
docker/api/client.py:298: in _raise_for_status
    raise create_api_error_from_http_exception(e)
docker/errors.py:31: in create_api_error_from_http_exception
    raise cls(e, response=response, explanation=explanation)
E   docker.errors.APIError: 503 Server Error for http+docker://localhost/v1.40/swarm/init: Service Unavailable ("Podman does not support service: /v1.40/swarm/init")
_____________ ERROR at setup of SecretAPITest.test_inspect_secret ______________
docker/api/client.py:296: in _raise_for_status
    response.raise_for_status()
../../.virtualenvs/docker-py/lib/python3.9/site-packages/requests/models.py:953: in raise_for_status
    raise HTTPError(http_error_msg, response=self)
E   requests.exceptions.HTTPError: 503 Server Error: Service Unavailable for url: http+docker://localhost/v1.40/swarm/init

During handling of the above exception, another exception occurred:
tests/integration/api_secret_test.py:15: in setup_class
    cls._init_swarm(client)
tests/integration/base.py:94: in _init_swarm
    return client.init_swarm(
docker/utils/decorators.py:34: in wrapper
    return f(self, *args, **kwargs)
docker/api/swarm.py:170: in init_swarm
    return self._result(response, json=True)
docker/api/client.py:302: in _result
    self._raise_for_status(response)
docker/api/client.py:298: in _raise_for_status
    raise create_api_error_from_http_exception(e)
docker/errors.py:31: in create_api_error_from_http_exception
    raise cls(e, response=response, explanation=explanation)
E   docker.errors.APIError: 503 Server Error for http+docker://localhost/v1.40/swarm/init: Service Unavailable ("Podman does not support service: /v1.40/swarm/init")
______________ ERROR at setup of SecretAPITest.test_list_secrets _______________
docker/api/client.py:296: in _raise_for_status
    response.raise_for_status()
../../.virtualenvs/docker-py/lib/python3.9/site-packages/requests/models.py:953: in raise_for_status
    raise HTTPError(http_error_msg, response=self)
E   requests.exceptions.HTTPError: 503 Server Error: Service Unavailable for url: http+docker://localhost/v1.40/swarm/init

During handling of the above exception, another exception occurred:
tests/integration/api_secret_test.py:15: in setup_class
    cls._init_swarm(client)
tests/integration/base.py:94: in _init_swarm
    return client.init_swarm(
docker/utils/decorators.py:34: in wrapper
    return f(self, *args, **kwargs)
docker/api/swarm.py:170: in init_swarm
    return self._result(response, json=True)
docker/api/client.py:302: in _result
    self._raise_for_status(response)
docker/api/client.py:298: in _raise_for_status
    raise create_api_error_from_http_exception(e)
docker/errors.py:31: in create_api_error_from_http_exception
    raise cls(e, response=response, explanation=explanation)
E   docker.errors.APIError: 503 Server Error for http+docker://localhost/v1.40/swarm/init: Service Unavailable ("Podman does not support service: /v1.40/swarm/init")
______________ ERROR at setup of SecretAPITest.test_remove_secret ______________
docker/api/client.py:296: in _raise_for_status
    response.raise_for_status()
../../.virtualenvs/docker-py/lib/python3.9/site-packages/requests/models.py:953: in raise_for_status
    raise HTTPError(http_error_msg, response=self)
E   requests.exceptions.HTTPError: 503 Server Error: Service Unavailable for url: http+docker://localhost/v1.40/swarm/init

During handling of the above exception, another exception occurred:
tests/integration/api_secret_test.py:15: in setup_class
    cls._init_swarm(client)
tests/integration/base.py:94: in _init_swarm
    return client.init_swarm(
docker/utils/decorators.py:34: in wrapper
    return f(self, *args, **kwargs)
docker/api/swarm.py:170: in init_swarm
    return self._result(response, json=True)
docker/api/client.py:302: in _result
    self._raise_for_status(response)
docker/api/client.py:298: in _raise_for_status
    raise create_api_error_from_http_exception(e)
docker/errors.py:31: in create_api_error_from_http_exception
    raise cls(e, response=response, explanation=explanation)
E   docker.errors.APIError: 503 Server Error for http+docker://localhost/v1.40/swarm/init: Service Unavailable ("Podman does not support service: /v1.40/swarm/init")
=================================== FAILURES ===================================
_________________________ BuildTest.test_build_labels __________________________
tests/integration/api_build_test.py:211: in test_build_labels
    assert info['Config']['Labels'] == labels
E   AssertionError: assert {'io.buildah.... 'test': 'OK'} == {'test': 'OK'}
E     Omitting 1 identical items, use -vv to show
E     Left contains 1 more item:
E     {'io.buildah.version': '1.23.1'}
E     Full diff:
E     - {'test': 'OK'}
E     + {'io.buildah.version': '1.23.1', 'test': 'OK'}
_________________________ BuildTest.test_build_squash __________________________
tests/integration/api_build_test.py:371: in test_build_squash
    assert len(squashed['RootFS']['Layers']) == 2
E   AssertionError: assert 1 == 2
E     +1
E     -2
_______________________ BuildTest.test_build_stderr_data _______________________
tests/integration/api_build_test.py:390: in test_build_stderr_data
    assert any([line == expected for line in lines])
E   AssertionError: assert False
E    +  where False = any([False, False, False, False, False, False, ...])
_____________________ BuildTest.test_build_with_cache_from _____________________
tests/integration/api_build_test.py:247: in test_build_with_cache_from
    assert counter == 0
E   AssertionError: assert 3 == 0
E     +3
E     -0
____________________ BuildTest.test_build_with_extra_hosts _____________________
docker/api/client.py:296: in _raise_for_status
    response.raise_for_status()
../../.virtualenvs/docker-py/lib/python3.9/site-packages/requests/models.py:953: in raise_for_status
    raise HTTPError(http_error_msg, response=self)
E   requests.exceptions.HTTPError: 400 Client Error: Bad Request for url: http+docker://localhost/v1.40/build?t=dockerpytest_extrahost_build&q=False&nocache=False&rm=False&forcerm=False&pull=False&extrahosts=extrahost.local.test%3A127.0.0.1&extrahosts=hello.world.test%3A127.0.0.1

During handling of the above exception, another exception occurred:
tests/integration/api_build_test.py:332: in test_build_with_extra_hosts
    for chunk in stream:
docker/api/client.py:386: in _stream_helper
    yield self._result(response, json=decode)
docker/api/client.py:302: in _result
    self._raise_for_status(response)
docker/api/client.py:298: in _raise_for_status
    raise create_api_error_from_http_exception(e)
docker/errors.py:31: in create_api_error_from_http_exception
    raise cls(e, response=response, explanation=explanation)
E   docker.errors.APIError: 400 Client Error for http+docker://localhost/v1.40/build?t=dockerpytest_extrahost_build&q=False&nocache=False&rm=False&forcerm=False&pull=False&extrahosts=extrahost.local.test%3A127.0.0.1&extrahosts=hello.world.test%3A127.0.0.1: Bad Request ("failed to parse query parameter 'extrahosts': "hello.world.test:127.0.0.1": invalid character 'h' looking for beginning of value")
____________________ BuildTest.test_build_with_network_mode ____________________
docker/api/client.py:296: in _raise_for_status
    response.raise_for_status()
../../.virtualenvs/docker-py/lib/python3.9/site-packages/requests/models.py:953: in raise_for_status
    raise HTTPError(http_error_msg, response=self)
E   requests.exceptions.HTTPError: 500 Server Error: Internal Server Error for url: http+docker://localhost/v1.40/networks/11a21b3f996154077369de4d090b3e5a0f2c7f7c1c01547ff16a53b92e842175/connect

During handling of the above exception, another exception occurred:
tests/integration/api_build_test.py:279: in test_build_with_network_mode
    self.client.connect_container_to_network(
docker/utils/decorators.py:19: in wrapped
    return f(self, resource_id, *args, **kwargs)
docker/api/network.py:250: in connect_container_to_network
    self._raise_for_status(res)
docker/api/client.py:298: in _raise_for_status
    raise create_api_error_from_http_exception(e)
docker/errors.py:31: in create_api_error_from_http_exception
    raise cls(e, response=response, explanation=explanation)
E   docker.errors.APIError: 500 Server Error for http+docker://localhost/v1.40/networks/11a21b3f996154077369de4d090b3e5a0f2c7f7c1c01547ff16a53b92e842175/connect: Internal Server Error (""slirp4netns" is not supported: invalid network mode")
___________ CreateContainerTest.test_create_with_device_cgroup_rules ___________
tests/integration/api_container_test.py:470: in test_create_with_device_cgroup_rules
    assert config['HostConfig']['DeviceCgroupRules'] == [rule]
E   AssertionError: assert None == ['c 7:128 rwm']
E     +None
E     -['c 7:128 rwm']
______ CreateContainerTest.test_create_with_environment_variable_no_value ______
tests/integration/api_container_test.py:366: in test_create_with_environment_variable_no_value
    assert 'Foo' in config['Config']['Env']
E   AssertionError: assert 'Foo' in ['PATH=/usr/local/sbin:/usr/local/bin:/usr/sbin:/usr/bin:/sbin:/bin', 'TERM=xterm', 'container=podman', 'Other=one', 'Blank=']
________________ CreateContainerTest.test_create_with_isolation ________________
tests/integration/api_container_test.py:395: in test_create_with_isolation
    assert config['HostConfig']['Isolation'] == 'default'
E   AssertionError: assert '' == 'default'
E     - default
__________________ CreateContainerTest.test_create_with_links __________________
docker/api/client.py:296: in _raise_for_status
    response.raise_for_status()
../../.virtualenvs/docker-py/lib/python3.9/site-packages/requests/models.py:953: in raise_for_status
    raise HTTPError(http_error_msg, response=self)
E   requests.exceptions.HTTPError: 400 Client Error: Bad Request for url: http+docker://localhost/v1.40/containers/create

During handling of the above exception, another exception occurred:
tests/integration/api_container_test.py:95: in test_create_with_links
    res2 = self.client.create_container(
docker/api/container.py:428: in create_container
    return self.create_container_from_config(config, name)
docker/api/container.py:439: in create_container_from_config
    return self._result(res, True)
docker/api/client.py:302: in _result
    self._raise_for_status(response)
docker/api/client.py:298: in _raise_for_status
    raise create_api_error_from_http_exception(e)
docker/errors.py:31: in create_api_error_from_http_exception
    raise cls(e, response=response, explanation=explanation)
E   docker.errors.APIError: 400 Client Error for http+docker://localhost/v1.40/containers/create: Bad Request ("bad parameter: Link is not supported")
_______________ CreateContainerTest.test_create_with_mac_address _______________
tests/integration/api_container_test.py:214: in test_create_with_mac_address
    assert mac_address_expected == res['NetworkSettings']['MacAddress']
E   AssertionError: assert '02:42:ac:11:00:0a' == ''
E     + 02:42:ac:11:00:0a
_____________ CreateContainerTest.test_create_with_restart_policy ______________
tests/integration/api_container_test.py:124: in test_create_with_restart_policy
    self.client.remove_container(id)
E   Failed: DID NOT RAISE <class 'docker.errors.APIError'>
__________________ CreateContainerTest.test_create_with_tmpfs __________________
tests/integration/api_container_test.py:384: in test_create_with_tmpfs
    assert config['HostConfig']['Tmpfs'] == tmpfs
E   AssertionError: assert {'/tmp1': 'si...ev,tmpcopyup'} == {'/tmp1': 'size=3M'}
E     Differing items:
E     {'/tmp1': 'size=3M,rw,rprivate,nosuid,nodev,tmpcopyup'} != {'/tmp1': 'size=3M'}
E     Full diff:
E     - {'/tmp1': 'size=3M'}
E     + {'/tmp1': 'size=3M,rw,rprivate,nosuid,nodev,tmpcopyup'}
_________ CreateContainerTest.test_invalid_log_driver_raises_exception _________
tests/integration/api_container_test.py:286: in test_invalid_log_driver_raises_exception
    assert excinfo.value.explanation in expected_msgs
E   AssertionError: assert 'container create: error running container create option: invalid log driver: invalid argument' in ["logger: no log driver named 'asdf' is registered", 'error looking up logging plugin asdf: plugin "asdf" not found']
E    +  where 'container create: error running container create option: invalid log driver: invalid argument' = APIError(HTTPError('500 Server Error: Internal Server Error for url: http+docker://localhost/v1.40/containers/create')).explanation
E    +    where APIError(HTTPError('500 Server Error: Internal Server Error for url: http+docker://localhost/v1.40/containers/create')) = <ExceptionInfo APIError(HTTPError('500 Server Error: Internal Server Error for url: http+docker://localhost/v1.40/containers/create')) tblen=6>.value
____________ CreateContainerTest.test_valid_log_driver_and_log_opt _____________
tests/integration/api_container_test.py:265: in test_valid_log_driver_and_log_opt
    assert container_log_config['Config'] == log_config.config
E   AssertionError: assert None == {'max-file': '100'}
E     +None
E     -{'max-file': '100'}
______________ CreateContainerTest.test_valid_no_config_specified ______________
tests/integration/api_container_test.py:324: in test_valid_no_config_specified
    assert container_log_config['Config'] == {}
E   AssertionError: assert None == {}
E     +None
E     -{}
____________ CreateContainerTest.test_valid_no_log_driver_specified ____________
tests/integration/api_container_test.py:304: in test_valid_no_log_driver_specified
    assert container_log_config['Type'] == "json-file"
E   AssertionError: assert 'journald' == 'json-file'
E     - json-file
E     + journald
______________ LogsTest.test_logs_streaming_and_follow_and_cancel ______________
tests/integration/base.py:80: in setUp
    self.is_podman = self._is_podman(self.client)
tests/integration/base.py:103: in _is_podman
    in client.version()['Components']
docker/api/daemon.py:181: in version
    return self._result(self._get(url), json=True)
docker/utils/decorators.py:46: in inner
    return f(self, *args, **kwargs)
docker/api/client.py:251: in _get
    return self.get(url, **self._set_request_timeout(kwargs))
../../.virtualenvs/docker-py/lib/python3.9/site-packages/requests/sessions.py:555: in get
    return self.request('GET', url, **kwargs)
../../.virtualenvs/docker-py/lib/python3.9/site-packages/requests/sessions.py:542: in request
    resp = self.send(prep, **send_kwargs)
../../.virtualenvs/docker-py/lib/python3.9/site-packages/requests/sessions.py:655: in send
    r = adapter.send(request, **kwargs)
../../.virtualenvs/docker-py/lib/python3.9/site-packages/requests/adapters.py:439: in send
    resp = conn.urlopen(
../../.virtualenvs/docker-py/lib/python3.9/site-packages/urllib3/connectionpool.py:699: in urlopen
    httplib_response = self._make_request(
../../.virtualenvs/docker-py/lib/python3.9/site-packages/urllib3/connectionpool.py:445: in _make_request
    six.raise_from(e, None)
../../.virtualenvs/docker-py/lib/python3.9/site-packages/urllib3/connectionpool.py:440: in _make_request
    httplib_response = conn.getresponse()
/usr/lib/python3.9/http/client.py:1371: in getresponse
    response.begin()
/usr/lib/python3.9/http/client.py:319: in begin
    version, status, reason = self._read_status()
/usr/lib/python3.9/http/client.py:280: in _read_status
    line = str(self.fp.readline(_MAXLINE + 1), "iso-8859-1")
/usr/lib/python3.9/socket.py:704: in readinto
    return self._sock.recv_into(b)
E   Failed: Timeout >5.0s
______________________________ PortTest.test_port ______________________________
docker/api/client.py:296: in _raise_for_status
    response.raise_for_status()
../../.virtualenvs/docker-py/lib/python3.9/site-packages/requests/models.py:953: in raise_for_status
    raise HTTPError(http_error_msg, response=self)
E   requests.exceptions.HTTPError: 500 Server Error: Internal Server Error for url: http+docker://localhost/v1.40/containers/2f6646da9415a8776b11d2d51b7399e62b12fecc4bfbae0d1e6406ac20830d09/start

During handling of the above exception, another exception occurred:
tests/integration/api_container_test.py:1068: in test_port
    self.client.start(container)
docker/utils/decorators.py:19: in wrapped
    return f(self, resource_id, *args, **kwargs)
docker/api/container.py:1109: in start
    self._raise_for_status(res)
docker/api/client.py:298: in _raise_for_status
    raise create_api_error_from_http_exception(e)
docker/errors.py:31: in create_api_error_from_http_exception
    raise cls(e, response=response, explanation=explanation)
E   docker.errors.APIError: 500 Server Error for http+docker://localhost/v1.40/containers/2f6646da9415a8776b11d2d51b7399e62b12fecc4bfbae0d1e6406ac20830d09/start: Internal Server Error ("could not find "rootlessport" in one of [/usr/local/libexec/podman /usr/local/lib/podman /usr/libexec/podman /usr/lib/podman].  To resolve this error, set the helper_binaries_dir key in the `[engine]` section of containers.conf to the directory containing your helper binaries.")
__________________ AttachContainerTest.test_attach_no_stream ___________________
docker/api/client.py:296: in _raise_for_status
    response.raise_for_status()
../../.virtualenvs/docker-py/lib/python3.9/site-packages/requests/models.py:953: in raise_for_status
    raise HTTPError(http_error_msg, response=self)
E   requests.exceptions.HTTPError: 500 Server Error: Internal Server Error for url: http+docker://localhost/v1.40/containers/28b5f437d0aaf1a82153cbdcac962a909cc11b807d2cddc40253f1ce6520b010/attach?logs=1&stdout=1&stderr=1&stream=0

During handling of the above exception, another exception occurred:
tests/integration/api_container_test.py:1229: in test_attach_no_stream
    output = self.client.attach(container, stream=False, logs=True)
docker/utils/decorators.py:19: in wrapped
    return f(self, resource_id, *args, **kwargs)
docker/api/container.py:60: in attach
    output = self._read_from_socket(
docker/api/client.py:441: in _read_from_socket
    socket = self._get_raw_response_socket(response)
docker/api/client.py:346: in _get_raw_response_socket
    self._raise_for_status(response)
docker/api/client.py:298: in _raise_for_status
    raise create_api_error_from_http_exception(e)
docker/errors.py:31: in create_api_error_from_http_exception
    raise cls(e, response=response, explanation=explanation)
E   docker.errors.APIError: 500 Server Error for http+docker://localhost/v1.40/containers/28b5f437d0aaf1a82153cbdcac962a909cc11b807d2cddc40253f1ce6520b010/attach?logs=1&stdout=1&stderr=1&stream=0: Internal Server Error ("can only attach to created or running containers - currently in state stopped: container state improper")
______________ AttachContainerTest.test_attach_stream_and_cancel _______________
tests/integration/base.py:83: in tearDown
    super().tearDown()
tests/integration/base.py:30: in tearDown
    client = docker.from_env(version=TEST_API_VERSION)
docker/client.py:96: in from_env
    return cls(
docker/client.py:45: in __init__
    self.api = APIClient(*args, **kwargs)
docker/api/client.py:197: in __init__
    self._version = self._retrieve_server_version()
docker/api/client.py:214: in _retrieve_server_version
    return self.version(api_version=False)["ApiVersion"]
docker/api/daemon.py:181: in version
    return self._result(self._get(url), json=True)
docker/utils/decorators.py:46: in inner
    return f(self, *args, **kwargs)
docker/api/client.py:251: in _get
    return self.get(url, **self._set_request_timeout(kwargs))
../../.virtualenvs/docker-py/lib/python3.9/site-packages/requests/sessions.py:555: in get
    return self.request('GET', url, **kwargs)
../../.virtualenvs/docker-py/lib/python3.9/site-packages/requests/sessions.py:542: in request
    resp = self.send(prep, **send_kwargs)
../../.virtualenvs/docker-py/lib/python3.9/site-packages/requests/sessions.py:655: in send
    r = adapter.send(request, **kwargs)
../../.virtualenvs/docker-py/lib/python3.9/site-packages/requests/adapters.py:439: in send
    resp = conn.urlopen(
../../.virtualenvs/docker-py/lib/python3.9/site-packages/urllib3/connectionpool.py:699: in urlopen
    httplib_response = self._make_request(
../../.virtualenvs/docker-py/lib/python3.9/site-packages/urllib3/connectionpool.py:445: in _make_request
    six.raise_from(e, None)
../../.virtualenvs/docker-py/lib/python3.9/site-packages/urllib3/connectionpool.py:440: in _make_request
    httplib_response = conn.getresponse()
/usr/lib/python3.9/http/client.py:1371: in getresponse
    response.begin()
/usr/lib/python3.9/http/client.py:319: in begin
    version, status, reason = self._read_status()
/usr/lib/python3.9/http/client.py:280: in _read_status
    line = str(self.fp.readline(_MAXLINE + 1), "iso-8859-1")
/usr/lib/python3.9/socket.py:704: in readinto
    return self._sock.recv_into(b)
E   Failed: Timeout >10.0s
________________ ContainerUpdateTest.test_restart_policy_update ________________
docker/api/client.py:296: in _raise_for_status
    response.raise_for_status()
../../.virtualenvs/docker-py/lib/python3.9/site-packages/requests/models.py:953: in raise_for_status
    raise HTTPError(http_error_msg, response=self)
E   requests.exceptions.HTTPError: 404 Client Error: Not Found for url: http+docker://localhost/v1.40/containers/89438c6f9e1affa822435601e602368e473d15e3288e4db9879fdc68df25b854/update

During handling of the above exception, another exception occurred:
tests/integration/api_container_test.py:1416: in test_restart_policy_update
    self.client.update_container(container,
docker/utils/decorators.py:34: in wrapper
    return f(self, *args, **kwargs)
docker/utils/decorators.py:19: in wrapped
    return f(self, resource_id, *args, **kwargs)
docker/api/container.py:1268: in update_container
    return self._result(res, True)
docker/api/client.py:302: in _result
    self._raise_for_status(response)
docker/api/client.py:298: in _raise_for_status
    raise create_api_error_from_http_exception(e)
docker/errors.py:31: in create_api_error_from_http_exception
    raise cls(e, response=response, explanation=explanation)
E   docker.errors.NotFound: 404 Client Error for http+docker://localhost/v1.40/containers/89438c6f9e1affa822435601e602368e473d15e3288e4db9879fdc68df25b854/update: Not Found ("b'Not Found'")
__________________ ContainerUpdateTest.test_update_container ___________________
docker/api/client.py:296: in _raise_for_status
    response.raise_for_status()
../../.virtualenvs/docker-py/lib/python3.9/site-packages/requests/models.py:953: in raise_for_status
    raise HTTPError(http_error_msg, response=self)
E   requests.exceptions.HTTPError: 404 Client Error: Not Found for url: http+docker://localhost/v1.40/containers/976ae0a2b68ae3fda6d3d718910b423d0f46406d86e0425401d3c893c270121e/update

During handling of the above exception, another exception occurred:
tests/integration/api_container_test.py:1394: in test_update_container
    self.client.update_container(container, mem_limit=new_mem_limit)
docker/utils/decorators.py:34: in wrapper
    return f(self, *args, **kwargs)
docker/utils/decorators.py:19: in wrapped
    return f(self, resource_id, *args, **kwargs)
docker/api/container.py:1268: in update_container
    return self._result(res, True)
docker/api/client.py:302: in _result
    self._raise_for_status(response)
docker/api/client.py:298: in _raise_for_status
    raise create_api_error_from_http_exception(e)
docker/errors.py:31: in create_api_error_from_http_exception
    raise cls(e, response=response, explanation=explanation)
E   docker.errors.NotFound: 404 Client Error for http+docker://localhost/v1.40/containers/976ae0a2b68ae3fda6d3d718910b423d0f46406d86e0425401d3c893c270121e/update: Not Found ("b'Not Found'")
__________________ ContainerCPUTest.test_create_with_runtime ___________________
tests/integration/api_container_test.py:1461: in test_create_with_runtime
    assert config['HostConfig']['Runtime'] == 'runc'
E   AssertionError: assert 'oci' == 'runc'
E     - runc
E     + oci
____________________ ExecTest.test_detach_with_config_file _____________________
/home/ubuntu/docker-py/tests/integration/api_exec_test.py:227: in test_detach_with_config_file
    ???
tests/helpers.py:137: in assert_cat_socket_detached_with_keys
    assert data == b'' or data.startswith(
E   AssertionError
______________________ ExecTest.test_exec_start_detached _______________________
/home/ubuntu/docker-py/tests/integration/api_exec_test.py:152: in test_exec_start_detached
    ???
E   AssertionError: assert '\n' == ''
E     Strings contain only whitespace, escaping them using repr()
E     - ''
E     + '\n'
_______________________ ExecTest.test_exec_start_socket ________________________
/home/ubuntu/docker-py/tests/integration/api_exec_test.py:134: in test_exec_start_socket
    ???
E   AssertionError: assert 121 == 1
E     +121
E     -1
_____________ ExecDemuxTest.test_exec_command_tty_no_stream_demux ______________
/home/ubuntu/docker-py/tests/integration/api_exec_test.py:299: in test_exec_command_tty_no_stream_demux
    ???
docker/utils/decorators.py:19: in wrapped
    return f(self, resource_id, *args, **kwargs)
docker/api/exec_api.py:173: in exec_start
    output = self._read_from_socket(res, stream, tty=tty, demux=demux)
docker/api/client.py:457: in _read_from_socket
    return consume_socket_output(gen, demux=demux)
docker/utils/socket.py:140: in consume_socket_output
    for frame in frames:
docker/api/client.py:447: in <genexpr>
    gen = (demux_adaptor(*frame) for frame in gen)
docker/utils/socket.py:167: in demux_adaptor
    raise ValueError(f'{stream_id} is not a valid stream')
E   ValueError: 104 is not a valid stream
____________ ExecDemuxTest.test_exec_command_tty_no_stream_no_demux ____________
/home/ubuntu/docker-py/tests/integration/api_exec_test.py:282: in test_exec_command_tty_no_stream_no_demux
    ???
E   AssertionError: assert b't\r\nhello err\r\n' == b'hello out\r\nhello err\r\n'
E     At index 0 diff: b't' != b'h'
E     Full diff:
E     - b'hello out\r\nhello err\r\n'
E     ?   --------
E     + b't\r\nhello err\r\n'
_______________ ExecDemuxTest.test_exec_command_tty_stream_demux _______________
/home/ubuntu/docker-py/tests/integration/api_exec_test.py:305: in test_exec_command_tty_stream_demux
    ???
docker/types/daemon.py:32: in __next__
    return next(self._stream)
docker/api/client.py:447: in <genexpr>
    gen = (demux_adaptor(*frame) for frame in gen)
docker/utils/socket.py:167: in demux_adaptor
    raise ValueError(f'{stream_id} is not a valid stream')
E   ValueError: 104 is not a valid stream
_____________ ExecDemuxTest.test_exec_command_tty_stream_no_demux ______________
/home/ubuntu/docker-py/tests/integration/api_exec_test.py:288: in test_exec_command_tty_stream_no_demux
    ???
E   AssertionError: assert b'hello out\r\n' in [b't\r\n', b'hello err\r\n']
___________________ PullImageTest.test_pull_invalid_platform ___________________
/home/ubuntu/docker-py/tests/integration/api_image_test.py:69: in test_pull_invalid_platform
    ???
E   Failed: DID NOT RAISE <class 'docker.errors.APIError'>
____________________________ CommitTest.test_commit ____________________________
/home/ubuntu/docker-py/tests/integration/api_image_test.py:89: in test_commit
    ???
E   AssertionError: assert False
E    +  where False = <built-in method startswith of str object at 0x7fcc3bc52670>('95f72656b48f6b3698ad7507bdb57c58b6da69ad1df0b8c054a15fb909b17fe1')
E    +    where <built-in method startswith of str object at 0x7fcc3bc52670> = ''.startswith
_____________________ CommitTest.test_commit_with_changes ______________________
docker/api/client.py:296: in _raise_for_status
    response.raise_for_status()
../../.virtualenvs/docker-py/lib/python3.9/site-packages/requests/models.py:953: in raise_for_status
    raise HTTPError(http_error_msg, response=self)
E   requests.exceptions.HTTPError: 500 Server Error: Internal Server Error for url: http+docker://localhost/v1.40/commit?container=6662fa0fbb32213946c6c011ac91cc6ed5bbf838d7aa9b2a76cb9856dc9ad8f6&changes=EXPOSE+8000&changes=CMD+%5B%22bash%22%5D

During handling of the above exception, another exception occurred:
/home/ubuntu/docker-py/tests/integration/api_image_test.py:101: in test_commit_with_changes
    ???
docker/utils/decorators.py:19: in wrapped
    return f(self, resource_id, *args, **kwargs)
docker/api/container.py:145: in commit
    return self._result(
docker/api/client.py:302: in _result
    self._raise_for_status(response)
docker/api/client.py:298: in _raise_for_status
    raise create_api_error_from_http_exception(e)
docker/errors.py:31: in create_api_error_from_http_exception
    raise cls(e, response=response, explanation=explanation)
E   docker.errors.APIError: 500 Server Error for http+docker://localhost/v1.40/commit?container=6662fa0fbb32213946c6c011ac91cc6ed5bbf838d7aa9b2a76cb9856dc9ad8f6&changes=EXPOSE+8000&changes=CMD+%5B%22bash%22%5D: Internal Server Error ("CommitFailure: invalid change "CMD" - must be formatted as KEY VALUE")
_____________________ ImportImageTest.test_get_load_image ______________________
/home/ubuntu/docker-py/tests/integration/api_image_test.py:266: in test_get_load_image
    ???
E   AssertionError: assert False
E    +  where False = any([])
___________ ImportImageTest.test_import_image_from_data_with_changes ___________
docker/api/client.py:296: in _raise_for_status
    response.raise_for_status()
../../.virtualenvs/docker-py/lib/python3.9/site-packages/requests/models.py:953: in raise_for_status
    raise HTTPError(http_error_msg, response=self)
E   requests.exceptions.HTTPError: 404 Client Error: Not Found for url: http+docker://localhost/v1.40/images/sha256:ec151c69b23d4253c19fa0f82dcd5336505da890536cada77132bfd203dc9974/json

During handling of the above exception, another exception occurred:
/home/ubuntu/docker-py/tests/integration/api_image_test.py:233: in test_import_image_from_data_with_changes
    ???
docker/utils/decorators.py:19: in wrapped
    return f(self, resource_id, *args, **kwargs)
docker/api/image.py:251: in inspect_image
    return self._result(
docker/api/client.py:302: in _result
    self._raise_for_status(response)
docker/api/client.py:298: in _raise_for_status
    raise create_api_error_from_http_exception(e)
docker/errors.py:31: in create_api_error_from_http_exception
    raise cls(e, response=response, explanation=explanation)
E   docker.errors.ImageNotFound: 404 Client Error for http+docker://localhost/v1.40/images/sha256:ec151c69b23d4253c19fa0f82dcd5336505da890536cada77132bfd203dc9974/json: Not Found ("failed to find image sha256:ec151c69b23d4253c19fa0f82dcd5336505da890536cada77132bfd203dc9974: docker.io/library/sha256:ec151c69b23d4253c19fa0f82dcd5336505da890536cada77132bfd203dc9974: No such image")
________________ ImportImageTest.test_import_image_with_changes ________________
docker/api/client.py:296: in _raise_for_status
    response.raise_for_status()
../../.virtualenvs/docker-py/lib/python3.9/site-packages/requests/models.py:953: in raise_for_status
    raise HTTPError(http_error_msg, response=self)
E   requests.exceptions.HTTPError: 404 Client Error: Not Found for url: http+docker://localhost/v1.40/images/sha256:345beaa30a73ed43096cb47529de88129fd9f87c114a3ff147b30497571554a6/json

During handling of the above exception, another exception occurred:
/home/ubuntu/docker-py/tests/integration/api_image_test.py:253: in test_import_image_with_changes
    ???
docker/utils/decorators.py:19: in wrapped
    return f(self, resource_id, *args, **kwargs)
docker/api/image.py:251: in inspect_image
    return self._result(
docker/api/client.py:302: in _result
    self._raise_for_status(response)
docker/api/client.py:298: in _raise_for_status
    raise create_api_error_from_http_exception(e)
docker/errors.py:31: in create_api_error_from_http_exception
    raise cls(e, response=response, explanation=explanation)
E   docker.errors.ImageNotFound: 404 Client Error for http+docker://localhost/v1.40/images/sha256:345beaa30a73ed43096cb47529de88129fd9f87c114a3ff147b30497571554a6/json: Not Found ("failed to find image sha256:345beaa30a73ed43096cb47529de88129fd9f87c114a3ff147b30497571554a6: docker.io/library/sha256:345beaa30a73ed43096cb47529de88129fd9f87c114a3ff147b30497571554a6: No such image")
______________________ PruneImagesTest.test_prune_images _______________________
docker/api/client.py:296: in _raise_for_status
    response.raise_for_status()
../../.virtualenvs/docker-py/lib/python3.9/site-packages/requests/models.py:953: in raise_for_status
    raise HTTPError(http_error_msg, response=self)
E   requests.exceptions.HTTPError: 500 Server Error: Internal Server Error for url: http+docker://localhost/v1.40/images/prune

During handling of the above exception, another exception occurred:
/home/ubuntu/docker-py/tests/integration/api_image_test.py:327: in test_prune_images
    ???
docker/utils/decorators.py:34: in wrapper
    return f(self, *args, **kwargs)
docker/api/image.py:349: in prune_images
    return self._result(self._post(url, params=params), True)
docker/api/client.py:302: in _result
    self._raise_for_status(response)
docker/api/client.py:298: in _raise_for_status
    raise create_api_error_from_http_exception(e)
docker/errors.py:31: in create_api_error_from_http_exception
    raise cls(e, response=response, explanation=explanation)
E   docker.errors.APIError: 500 Server Error for http+docker://localhost/v1.40/images/prune: Internal Server Error ("Image used by 9420c77a90c8d0d695f74a995dbbe1b6b598d1e834f00468bbd3fd1ae1452198: image is in use by a container")
_________________ SaveLoadImagesTest.test_get_image_load_image _________________
/home/ubuntu/docker-py/tests/integration/api_image_test.py:360: in test_get_image_load_image
    ???
E   AssertionError: assert False is True
----------------------------- Captured stdout call -----------------------------
{'stream': 'Loaded image: docker.io/library/alpine:3.10\n'}
______________ InspectDistributionTest.test_inspect_distribution _______________
docker/api/client.py:296: in _raise_for_status
    response.raise_for_status()
../../.virtualenvs/docker-py/lib/python3.9/site-packages/requests/models.py:953: in raise_for_status
    raise HTTPError(http_error_msg, response=self)
E   requests.exceptions.HTTPError: 404 Client Error: Not Found for url: http+docker://localhost/v1.40/distribution/busybox:latest/json

During handling of the above exception, another exception occurred:
/home/ubuntu/docker-py/tests/integration/api_image_test.py:366: in test_inspect_distribution
    ???
docker/utils/decorators.py:34: in wrapper
    return f(self, *args, **kwargs)
docker/utils/decorators.py:19: in wrapped
    return f(self, resource_id, *args, **kwargs)
docker/api/image.py:287: in inspect_distribution
    return self._result(
docker/api/client.py:302: in _result
    self._raise_for_status(response)
docker/api/client.py:298: in _raise_for_status
    raise create_api_error_from_http_exception(e)
docker/errors.py:31: in create_api_error_from_http_exception
    raise cls(e, response=response, explanation=explanation)
E   docker.errors.NotFound: 404 Client Error for http+docker://localhost/v1.40/distribution/busybox:latest/json: Not Found ("Path /v1.40/distribution/busybox:latest/json is not supported")
______________ TestNetworks.test_connect_and_disconnect_container ______________
docker/api/client.py:296: in _raise_for_status
    response.raise_for_status()
../../.virtualenvs/docker-py/lib/python3.9/site-packages/requests/models.py:953: in raise_for_status
    raise HTTPError(http_error_msg, response=self)
E   requests.exceptions.HTTPError: 500 Server Error: Internal Server Error for url: http+docker://localhost/v1.40/networks/e38657ddcabda43727172ff199ce87ac0f1dc6f59a48076bf9821c7fd8c1ad89/connect

During handling of the above exception, another exception occurred:
tests/integration/api_network_test.py:98: in test_connect_and_disconnect_container
    self.client.connect_container_to_network(container, net_id)
docker/utils/decorators.py:19: in wrapped
    return f(self, resource_id, *args, **kwargs)
docker/api/network.py:250: in connect_container_to_network
    self._raise_for_status(res)
docker/api/client.py:298: in _raise_for_status
    raise create_api_error_from_http_exception(e)
docker/errors.py:31: in create_api_error_from_http_exception
    raise cls(e, response=response, explanation=explanation)
E   docker.errors.APIError: 500 Server Error for http+docker://localhost/v1.40/networks/e38657ddcabda43727172ff199ce87ac0f1dc6f59a48076bf9821c7fd8c1ad89/connect: Internal Server Error (""slirp4netns" is not supported: invalid network mode")
___________ TestNetworks.test_connect_and_force_disconnect_container ___________
docker/api/client.py:296: in _raise_for_status
    response.raise_for_status()
../../.virtualenvs/docker-py/lib/python3.9/site-packages/requests/models.py:953: in raise_for_status
    raise HTTPError(http_error_msg, response=self)
E   requests.exceptions.HTTPError: 500 Server Error: Internal Server Error for url: http+docker://localhost/v1.40/networks/e592f748b3d426042f5c2586ff1fdabe1b45b454ef954c31b54275622ca9b8c3/connect

During handling of the above exception, another exception occurred:
tests/integration/api_network_test.py:125: in test_connect_and_force_disconnect_container
    self.client.connect_container_to_network(container, net_id)
docker/utils/decorators.py:19: in wrapped
    return f(self, resource_id, *args, **kwargs)
docker/api/network.py:250: in connect_container_to_network
    self._raise_for_status(res)
docker/api/client.py:298: in _raise_for_status
    raise create_api_error_from_http_exception(e)
docker/errors.py:31: in create_api_error_from_http_exception
    raise cls(e, response=response, explanation=explanation)
E   docker.errors.APIError: 500 Server Error for http+docker://localhost/v1.40/networks/e592f748b3d426042f5c2586ff1fdabe1b45b454ef954c31b54275622ca9b8c3/connect: Internal Server Error (""slirp4netns" is not supported: invalid network mode")
____________________ TestNetworks.test_connect_with_aliases ____________________
docker/api/client.py:296: in _raise_for_status
    response.raise_for_status()
../../.virtualenvs/docker-py/lib/python3.9/site-packages/requests/models.py:953: in raise_for_status
    raise HTTPError(http_error_msg, response=self)
E   requests.exceptions.HTTPError: 500 Server Error: Internal Server Error for url: http+docker://localhost/v1.40/networks/0ca87ee353583bdf0777ab643962fa9bcd714ca380bf6823460896908a4dd8ef/connect

During handling of the above exception, another exception occurred:
tests/integration/api_network_test.py:147: in test_connect_with_aliases
    self.client.connect_container_to_network(
docker/utils/decorators.py:19: in wrapped
    return f(self, resource_id, *args, **kwargs)
docker/api/network.py:250: in connect_container_to_network
    self._raise_for_status(res)
docker/api/client.py:298: in _raise_for_status
    raise create_api_error_from_http_exception(e)
docker/errors.py:31: in create_api_error_from_http_exception
    raise cls(e, response=response, explanation=explanation)
E   docker.errors.APIError: 500 Server Error for http+docker://localhost/v1.40/networks/0ca87ee353583bdf0777ab643962fa9bcd714ca380bf6823460896908a4dd8ef/connect: Internal Server Error (""slirp4netns" is not supported: invalid network mode")
_________________ TestNetworks.test_connect_with_ipv4_address __________________
tests/integration/api_network_test.py:379: in test_connect_with_ipv4_address
    assert net_data['IPAMConfig']['IPv4Address'] == '172.28.5.24'
E   TypeError: 'NoneType' object is not subscriptable
_________________ TestNetworks.test_connect_with_ipv6_address __________________
tests/integration/api_network_test.py:405: in test_connect_with_ipv6_address
    assert net_data['IPAMConfig']['IPv6Address'] == '2001:389::f00d'
E   TypeError: 'NoneType' object is not subscriptable
_____________________ TestNetworks.test_connect_with_links _____________________
tests/integration/api_network_test.py:344: in test_connect_with_links
    assert net_settings['Networks'][net_name]['Links'] == [
E   AssertionError: assert None == ['docker-py-t...upstream:bar']
E     +None
E     -['docker-py-test-upstream:bar']
___________________ TestNetworks.test_create_check_duplicate ___________________
docker/api/client.py:296: in _raise_for_status
    response.raise_for_status()
../../.virtualenvs/docker-py/lib/python3.9/site-packages/requests/models.py:953: in raise_for_status
    raise HTTPError(http_error_msg, response=self)
E   requests.exceptions.HTTPError: 500 Server Error: Internal Server Error for url: http+docker://localhost/v1.40/networks/create

During handling of the above exception, another exception occurred:
tests/integration/api_network_test.py:326: in test_create_check_duplicate
    net_id = self.client.create_network(net_name, check_duplicate=False)
docker/api/network.py:153: in create_network
    return self._result(res, json=True)
docker/api/client.py:302: in _result
    self._raise_for_status(response)
docker/api/client.py:298: in _raise_for_status
    raise create_api_error_from_http_exception(e)
docker/errors.py:31: in create_api_error_from_http_exception
    raise cls(e, response=response, explanation=explanation)
E   docker.errors.APIError: 500 Server Error for http+docker://localhost/v1.40/networks/create: Internal Server Error ("network name dockerpytest_8c4f4af031e6b622 already used: network already exists")
______________ TestNetworks.test_create_network_with_ipam_config _______________
tests/integration/api_network_test.py:62: in test_create_network_with_ipam_config
    assert ipam.pop('Options', None) is None
E   AssertionError: assert {'driver': 'host-local'} is None
E    +  where {'driver': 'host-local'} = <built-in method pop of dict object at 0x7fcc38720980>('Options', None)
E    +    where <built-in method pop of dict object at 0x7fcc38720980> = {'Config': [{'Gateway': '172.28.5.254', 'Subnet': '172.28.0.0/16'}], 'Driver': 'default'}.pop
__________ TestNetworks.test_create_remove_network_with_space_in_name __________
docker/api/client.py:296: in _raise_for_status
    response.raise_for_status()
../../.virtualenvs/docker-py/lib/python3.9/site-packages/requests/models.py:953: in raise_for_status
    raise HTTPError(http_error_msg, response=self)
E   requests.exceptions.HTTPError: 500 Server Error: Internal Server Error for url: http+docker://localhost/v1.40/networks/create

During handling of the above exception, another exception occurred:
tests/integration/api_network_test.py:454: in test_create_remove_network_with_space_in_name
    net_id = self.client.create_network('test 01')
docker/api/network.py:153: in create_network
    return self._result(res, json=True)
docker/api/client.py:302: in _result
    self._raise_for_status(response)
docker/api/client.py:298: in _raise_for_status
    raise create_api_error_from_http_exception(e)
docker/errors.py:31: in create_api_error_from_http_exception
    raise cls(e, response=response, explanation=explanation)
E   docker.errors.APIError: 500 Server Error for http+docker://localhost/v1.40/networks/create: Internal Server Error ("network name test 01 invalid: names must match [a-zA-Z0-9][a-zA-Z0-9_.-]*: invalid argument")
___________________ TestNetworks.test_create_with_driveropt ____________________
docker/api/client.py:296: in _raise_for_status
    response.raise_for_status()
../../.virtualenvs/docker-py/lib/python3.9/site-packages/requests/models.py:953: in raise_for_status
    raise HTTPError(http_error_msg, response=self)
E   requests.exceptions.HTTPError: 500 Server Error: Internal Server Error for url: http+docker://localhost/v1.40/containers/create

During handling of the above exception, another exception occurred:
tests/integration/api_network_test.py:276: in test_create_with_driveropt
    container = self.client.create_container(
docker/api/container.py:428: in create_container
    return self.create_container_from_config(config, name)
docker/api/container.py:439: in create_container_from_config
    return self._result(res, True)
docker/api/client.py:302: in _result
    self._raise_for_status(response)
docker/api/client.py:298: in _raise_for_status
    raise create_api_error_from_http_exception(e)
docker/errors.py:31: in create_api_error_from_http_exception
    raise cls(e, response=response, explanation=explanation)
E   docker.errors.APIError: 500 Server Error for http+docker://localhost/v1.40/containers/create: Internal Server Error ("container create: unable to find network with name or ID bridge: network not found")
__________________ TestNetworks.test_create_with_ipv4_address __________________
tests/integration/api_network_test.py:224: in test_create_with_ipv4_address
    assert net_settings['Networks'][net_name]['IPAMConfig']['IPv4Address']\
E   TypeError: 'NoneType' object is not subscriptable
__________________ TestNetworks.test_create_with_ipv6_address __________________
tests/integration/api_network_test.py:250: in test_create_with_ipv6_address
    assert net_settings['Networks'][net_name]['IPAMConfig']['IPv6Address']\
E   TypeError: 'NoneType' object is not subscriptable
_________________ TestNetworks.test_create_with_linklocal_ips __________________
docker/api/client.py:296: in _raise_for_status
    response.raise_for_status()
../../.virtualenvs/docker-py/lib/python3.9/site-packages/requests/models.py:953: in raise_for_status
    raise HTTPError(http_error_msg, response=self)
E   requests.exceptions.HTTPError: 500 Server Error: Internal Server Error for url: http+docker://localhost/v1.40/containers/create

During handling of the above exception, another exception occurred:
tests/integration/api_network_test.py:255: in test_create_with_linklocal_ips
    container = self.client.create_container(
docker/api/container.py:428: in create_container
    return self.create_container_from_config(config, name)
docker/api/container.py:439: in create_container_from_config
    return self._result(res, True)
docker/api/client.py:302: in _result
    self._raise_for_status(response)
docker/api/client.py:298: in _raise_for_status
    raise create_api_error_from_http_exception(e)
docker/errors.py:31: in create_api_error_from_http_exception
    raise cls(e, response=response, explanation=explanation)
E   docker.errors.APIError: 500 Server Error for http+docker://localhost/v1.40/containers/create: Internal Server Error ("container create: unable to find network with name or ID bridge: network not found")
_____________________ TestNetworks.test_create_with_links ______________________
tests/integration/api_network_test.py:311: in test_create_with_links
    assert net_settings['Networks'][net_name]['Links'] == [
E   AssertionError: assert None == ['docker-py-t...upstream:bar']
E     +None
E     -['docker-py-test-upstream:bar']
________________ TestVolumes.test_create_volume_invalid_driver _________________
docker/api/client.py:296: in _raise_for_status
    response.raise_for_status()
../../.virtualenvs/docker-py/lib/python3.9/site-packages/requests/models.py:953: in raise_for_status
    raise HTTPError(http_error_msg, response=self)
E   requests.exceptions.HTTPError: 500 Server Error: Internal Server Error for url: http+docker://localhost/v1.40/volumes/create

During handling of the above exception, another exception occurred:
/home/ubuntu/docker-py/tests/integration/api_volume_test.py:22: in test_create_volume_invalid_driver
    ???
docker/api/volume.py:89: in create_volume
    return self._result(self._post_json(url, data=data), True)
docker/api/client.py:302: in _result
    self._raise_for_status(response)
docker/api/client.py:298: in _raise_for_status
    raise create_api_error_from_http_exception(e)
docker/errors.py:31: in create_api_error_from_http_exception
    raise cls(e, response=response, explanation=explanation)
E   docker.errors.APIError: 500 Server Error for http+docker://localhost/v1.40/volumes/create: Internal Server Error ("volume perfectcherryblossom uses volume plugin invalid.driver but it could not be retrieved: no volume plugin with name invalid.driver available: required plugin missing")
_______________________ TestVolumes.test_inspect_volume ________________________
/home/ubuntu/docker-py/tests/integration/api_volume_test.py:38: in test_inspect_volume
    ???
E   AssertionError: assert {'CreatedAt':...l/_data', ...} == {'CreatedAt':...l/_data', ...}
E     Omitting 6 identical items, use -vv to show
E     Differing items:
E     {'Options': None} != {'Options': {}}
E     Full diff:
E       {
E        'CreatedAt': '2021-12-17T23:05:45+01:00',
E        'Driver': 'local',...
E     
E     ...Full output truncated (10 lines hidden), use '-vv' to show
________________________ TestVolumes.test_list_volumes _________________________
/home/ubuntu/docker-py/tests/integration/api_volume_test.py:31: in test_list_volumes
    ???
E   AssertionError: assert {'CreatedAt': '2021-12-17T23:05:52+01:00', 'Driver': 'local', 'Labels': {}, 'Mountpoint': '/home/riyad/podman/storage/volumes/imperishablenight/_data', ...} in [{'CreatedAt': '2021-12-17T22:18:03+01:00', 'Driver': 'local', 'Labels': {}, 'Mountpoint': '/home/riyad/podman/storage...00', 'Driver': 'local', 'Labels': {}, 'Mountpoint': '/home/riyad/podman/storage/volumes/imperishablenight/_data', ...}]
____________________ ErrorsTest.test_api_error_parses_json _____________________
/home/ubuntu/docker-py/tests/integration/errors_test.py:13: in test_api_error_parses_json
    ???
E   AssertionError: assert 'You cannot remove a running container' in 'cannot remove container aeb813665f3eb9ba9b600d09250fee6902c8e9f63d419594f8baad2eecbc3d31 as it is running - running or paused containers cannot be removed without force: container state improper'
_______________________ ContainerCollectionTest.test_get _______________________
/home/ubuntu/docker-py/tests/integration/models_containers_test.py:189: in test_get
    ???
E   AssertionError: assert 'docker.io/li...alpine:latest' == 'alpine'
E     - alpine
E     + docker.io/library/alpine:latest
______________________ ContainerCollectionTest.test_list _______________________
/home/ubuntu/docker-py/tests/integration/models_containers_test.py:202: in test_list
    ???
E   AssertionError: assert 'docker.io/li...alpine:latest' == 'alpine'
E     - alpine
E     + docker.io/library/alpine:latest
___________________ ContainerCollectionTest.test_list_sparse ___________________
/home/ubuntu/docker-py/tests/integration/models_containers_test.py:220: in test_list_sparse
    ???
E   AssertionError: assert 'docker.io/li...alpine:latest' == 'alpine'
E     - alpine
E     + docker.io/library/alpine:latest
___________________ ContainerCollectionTest.test_run_detach ____________________
/home/ubuntu/docker-py/tests/integration/models_containers_test.py:26: in test_run_detach
    ???
E   AssertionError: assert 'docker.io/li...alpine:latest' == 'alpine'
E     - alpine
E     + docker.io/library/alpine:latest
___________ ContainerCollectionTest.test_run_with_auto_remove_error ____________
docker/api/client.py:296: in _raise_for_status
    response.raise_for_status()
../../.virtualenvs/docker-py/lib/python3.9/site-packages/requests/models.py:953: in raise_for_status
    raise HTTPError(http_error_msg, response=self)
E   requests.exceptions.HTTPError: 404 Client Error: Not Found for url: http+docker://localhost/v1.40/containers/c1931447b76f6768d723c97426b27e11a902f15ed0d851f8acd1f005cb56e2e2/json

During handling of the above exception, another exception occurred:
/home/ubuntu/docker-py/tests/integration/models_containers_test.py:139: in test_run_with_auto_remove_error
    ???
docker/models/containers.py:835: in run
    out = container.logs(
docker/models/containers.py:306: in logs
    return self.client.api.logs(self.id, **kwargs)
docker/utils/decorators.py:19: in wrapped
    return f(self, resource_id, *args, **kwargs)
docker/api/container.py:869: in logs
    output = self._get_result(container, stream, res)
docker/api/client.py:495: in _get_result
    return self._get_result_tty(stream, res, self._check_is_tty(container))
docker/utils/decorators.py:19: in wrapped
    return f(self, resource_id, *args, **kwargs)
docker/api/client.py:491: in _check_is_tty
    cont = self.inspect_container(container)
docker/utils/decorators.py:19: in wrapped
    return f(self, resource_id, *args, **kwargs)
docker/api/container.py:771: in inspect_container
    return self._result(
docker/api/client.py:302: in _result
    self._raise_for_status(response)
docker/api/client.py:298: in _raise_for_status
    raise create_api_error_from_http_exception(e)
docker/errors.py:31: in create_api_error_from_http_exception
    raise cls(e, response=response, explanation=explanation)
E   docker.errors.NotFound: 404 Client Error for http+docker://localhost/v1.40/containers/c1931447b76f6768d723c97426b27e11a902f15ed0d851f8acd1f005cb56e2e2/json: Not Found ("no container with name or ID "c1931447b76f6768d723c97426b27e11a902f15ed0d851f8acd1f005cb56e2e2" found: no such container")
________ ContainerCollectionTest.test_run_with_streamed_logs_and_cancel ________
tests/integration/base.py:30: in tearDown
    client = docker.from_env(version=TEST_API_VERSION)
docker/client.py:96: in from_env
    return cls(
docker/client.py:45: in __init__
    self.api = APIClient(*args, **kwargs)
docker/api/client.py:197: in __init__
    self._version = self._retrieve_server_version()
docker/api/client.py:214: in _retrieve_server_version
    return self.version(api_version=False)["ApiVersion"]
docker/api/daemon.py:181: in version
    return self._result(self._get(url), json=True)
docker/utils/decorators.py:46: in inner
    return f(self, *args, **kwargs)
docker/api/client.py:251: in _get
    return self.get(url, **self._set_request_timeout(kwargs))
../../.virtualenvs/docker-py/lib/python3.9/site-packages/requests/sessions.py:555: in get
    return self.request('GET', url, **kwargs)
../../.virtualenvs/docker-py/lib/python3.9/site-packages/requests/sessions.py:542: in request
    resp = self.send(prep, **send_kwargs)
../../.virtualenvs/docker-py/lib/python3.9/site-packages/requests/sessions.py:655: in send
    r = adapter.send(request, **kwargs)
../../.virtualenvs/docker-py/lib/python3.9/site-packages/requests/adapters.py:439: in send
    resp = conn.urlopen(
../../.virtualenvs/docker-py/lib/python3.9/site-packages/urllib3/connectionpool.py:699: in urlopen
    httplib_response = self._make_request(
../../.virtualenvs/docker-py/lib/python3.9/site-packages/urllib3/connectionpool.py:445: in _make_request
    six.raise_from(e, None)
../../.virtualenvs/docker-py/lib/python3.9/site-packages/urllib3/connectionpool.py:440: in _make_request
    httplib_response = conn.getresponse()
/usr/lib/python3.9/http/client.py:1371: in getresponse
    response.begin()
/usr/lib/python3.9/http/client.py:319: in begin
    version, status, reason = self._read_status()
/usr/lib/python3.9/http/client.py:280: in _read_status
    line = str(self.fp.readline(_MAXLINE + 1), "iso-8859-1")
/usr/lib/python3.9/socket.py:704: in readinto
    return self._sock.recv_into(b)
E   Failed: Timeout >5.0s
__________________________ ContainerTest.test_commit ___________________________
docker/api/client.py:296: in _raise_for_status
    response.raise_for_status()
../../.virtualenvs/docker-py/lib/python3.9/site-packages/requests/models.py:953: in raise_for_status
    raise HTTPError(http_error_msg, response=self)
E   requests.exceptions.HTTPError: 404 Client Error: Not Found for url: http+docker://localhost/v1.40/containers/create

During handling of the above exception, another exception occurred:
docker/models/containers.py:819: in run
    container = self.create(image=image, command=command,
docker/models/containers.py:878: in create
    resp = self.client.api.create_container(**create_kwargs)
docker/api/container.py:428: in create_container
    return self.create_container_from_config(config, name)
docker/api/container.py:439: in create_container_from_config
    return self._result(res, True)
docker/api/client.py:302: in _result
    self._raise_for_status(response)
docker/api/client.py:298: in _raise_for_status
    raise create_api_error_from_http_exception(e)
docker/errors.py:31: in create_api_error_from_http_exception
    raise cls(e, response=response, explanation=explanation)
E   docker.errors.ImageNotFound: 404 Client Error for http+docker://localhost/v1.40/containers/create: Not Found ("No such image: docker.io/library/sha256:754a354c94ba46b70183244356a6f4b0b549a0212c5609a062e34d305e86c842: image not known")

During handling of the above exception, another exception occurred:
docker/api/client.py:296: in _raise_for_status
    response.raise_for_status()
../../.virtualenvs/docker-py/lib/python3.9/site-packages/requests/models.py:953: in raise_for_status
    raise HTTPError(http_error_msg, response=self)
E   requests.exceptions.HTTPError: 404 Client Error: Not Found for url: http+docker://localhost/v1.40/images/sha256:754a354c94ba46b70183244356a6f4b0b549a0212c5609a062e34d305e86c842/json

During handling of the above exception, another exception occurred:
/home/ubuntu/docker-py/tests/integration/models_containers_test.py:242: in test_commit
    ???
docker/models/containers.py:822: in run
    self.client.images.pull(image, platform=platform)
docker/models/images.py:453: in pull
    return self.get('{0}{2}{1}'.format(
docker/models/images.py:314: in get
    return self.prepare_model(self.client.api.inspect_image(name))
docker/utils/decorators.py:19: in wrapped
    return f(self, resource_id, *args, **kwargs)
docker/api/image.py:251: in inspect_image
    return self._result(
docker/api/client.py:302: in _result
    self._raise_for_status(response)
docker/api/client.py:298: in _raise_for_status
    raise create_api_error_from_http_exception(e)
docker/errors.py:31: in create_api_error_from_http_exception
    raise cls(e, response=response, explanation=explanation)
E   docker.errors.ImageNotFound: 404 Client Error for http+docker://localhost/v1.40/images/sha256:754a354c94ba46b70183244356a6f4b0b549a0212c5609a062e34d305e86c842/json: Not Found ("failed to find image sha256:754a354c94ba46b70183244356a6f4b0b549a0212c5609a062e34d305e86c842: docker.io/library/sha256:754a354c94ba46b70183244356a6f4b0b549a0212c5609a062e34d305e86c842: No such image")
_________________ ContainerTest.test_create_with_volume_driver _________________
/home/ubuntu/docker-py/tests/integration/models_containers_test.py:456: in test_create_with_volume_driver
    ???
E   AssertionError: assert '' == 'foo'
E     - foo
___________________________ ContainerTest.test_diff ____________________________
/home/ubuntu/docker-py/tests/integration/models_containers_test.py:251: in test_diff
    ???
E   AssertionError: assert [{'Kind': 1, ...ath': '/etc'}] == [{'Kind': 1, 'Path': '/test'}]
E     Left contains one more item: {'Kind': 0, 'Path': '/etc'}
E     Full diff:
E     - [{'Kind': 1, 'Path': '/test'}]
E     + [{'Kind': 1, 'Path': '/test'}, {'Kind': 0, 'Path': '/etc'}]
______________________ ContainerTest.test_exec_run_failed ______________________
/home/ubuntu/docker-py/tests/integration/models_containers_test.py:270: in test_exec_run_failed
    ???
E   AssertionError: assert 127 == 126
E     +127
E     -126
___________________________ ContainerTest.test_kill ____________________________
/home/ubuntu/docker-py/tests/integration/models_containers_test.py:281: in test_kill
    ???
E   AssertionError: assert 'stopped' == 'exited'
E     - exited
E     + stopped
_____________________ ContainerTest.test_ports_target_list _____________________
docker/api/client.py:296: in _raise_for_status
    response.raise_for_status()
../../.virtualenvs/docker-py/lib/python3.9/site-packages/requests/models.py:953: in raise_for_status
    raise HTTPError(http_error_msg, response=self)
E   requests.exceptions.HTTPError: 500 Server Error: Internal Server Error for url: http+docker://localhost/v1.40/containers/e7b962d160635389484da78771a2e6fab4afa823fd0e3c55bb3ce1f68e0b96ea/start

During handling of the above exception, another exception occurred:
/home/ubuntu/docker-py/tests/integration/models_containers_test.py:394: in test_ports_target_list
    ???
docker/models/containers.py:826: in run
    container.start()
docker/models/containers.py:404: in start
    return self.client.api.start(self.id, **kwargs)
docker/utils/decorators.py:19: in wrapped
    return f(self, resource_id, *args, **kwargs)
docker/api/container.py:1109: in start
    self._raise_for_status(res)
docker/api/client.py:298: in _raise_for_status
    raise create_api_error_from_http_exception(e)
docker/errors.py:31: in create_api_error_from_http_exception
    raise cls(e, response=response, explanation=explanation)
E   docker.errors.APIError: 500 Server Error for http+docker://localhost/v1.40/containers/e7b962d160635389484da78771a2e6fab4afa823fd0e3c55bb3ce1f68e0b96ea/start: Internal Server Error ("could not find "rootlessport" in one of [/usr/local/libexec/podman /usr/local/lib/podman /usr/libexec/podman /usr/lib/podman].  To resolve this error, set the helper_binaries_dir key in the `[engine]` section of containers.conf to the directory containing your helper binaries.")
_____________________ ContainerTest.test_ports_target_none _____________________
docker/api/client.py:296: in _raise_for_status
    response.raise_for_status()
../../.virtualenvs/docker-py/lib/python3.9/site-packages/requests/models.py:953: in raise_for_status
    raise HTTPError(http_error_msg, response=self)
E   requests.exceptions.HTTPError: 500 Server Error: Internal Server Error for url: http+docker://localhost/v1.40/containers/43041dd659bbd8542bfc69e219ba313a86f724cfaf3a7a8f61668d5fe245f3f2/start

During handling of the above exception, another exception occurred:
/home/ubuntu/docker-py/tests/integration/models_containers_test.py:354: in test_ports_target_none
    ???
docker/models/containers.py:826: in run
    container.start()
docker/models/containers.py:404: in start
    return self.client.api.start(self.id, **kwargs)
docker/utils/decorators.py:19: in wrapped
    return f(self, resource_id, *args, **kwargs)
docker/api/container.py:1109: in start
    self._raise_for_status(res)
docker/api/client.py:298: in _raise_for_status
    raise create_api_error_from_http_exception(e)
docker/errors.py:31: in create_api_error_from_http_exception
    raise cls(e, response=response, explanation=explanation)
E   docker.errors.APIError: 500 Server Error for http+docker://localhost/v1.40/containers/43041dd659bbd8542bfc69e219ba313a86f724cfaf3a7a8f61668d5fe245f3f2/start: Internal Server Error ("could not find "rootlessport" in one of [/usr/local/libexec/podman /usr/local/lib/podman /usr/libexec/podman /usr/lib/podman].  To resolve this error, set the helper_binaries_dir key in the `[engine]` section of containers.conf to the directory containing your helper binaries.")
____________________ ContainerTest.test_ports_target_tuple _____________________
docker/api/client.py:296: in _raise_for_status
    response.raise_for_status()
../../.virtualenvs/docker-py/lib/python3.9/site-packages/requests/models.py:953: in raise_for_status
    raise HTTPError(http_error_msg, response=self)
E   requests.exceptions.HTTPError: 500 Server Error: Internal Server Error for url: http+docker://localhost/v1.40/containers/684bb022fbf7404e65cd9547d2bec97f6c436c7d8b5414e4758e566a77cd560a/start

During handling of the above exception, another exception occurred:
/home/ubuntu/docker-py/tests/integration/models_containers_test.py:374: in test_ports_target_tuple
    ???
docker/models/containers.py:826: in run
    container.start()
docker/models/containers.py:404: in start
    return self.client.api.start(self.id, **kwargs)
docker/utils/decorators.py:19: in wrapped
    return f(self, resource_id, *args, **kwargs)
docker/api/container.py:1109: in start
    self._raise_for_status(res)
docker/api/client.py:298: in _raise_for_status
    raise create_api_error_from_http_exception(e)
docker/errors.py:31: in create_api_error_from_http_exception
    raise cls(e, response=response, explanation=explanation)
E   docker.errors.APIError: 500 Server Error for http+docker://localhost/v1.40/containers/684bb022fbf7404e65cd9547d2bec97f6c436c7d8b5414e4758e566a77cd560a/start: Internal Server Error ("could not find "rootlessport" in one of [/usr/local/libexec/podman /usr/local/lib/podman /usr/libexec/podman /usr/lib/podman].  To resolve this error, set the helper_binaries_dir key in the `[engine]` section of containers.conf to the directory containing your helper binaries.")
____________________________ ContainerTest.test_top ____________________________
/home/ubuntu/docker-py/tests/integration/models_containers_test.py:425: in test_top
    ???
E   AssertionError: assert 'sleep 60' in ['1 root      0:00 sleep 60']
__________________________ ContainerTest.test_update ___________________________
docker/api/client.py:296: in _raise_for_status
    response.raise_for_status()
../../.virtualenvs/docker-py/lib/python3.9/site-packages/requests/models.py:953: in raise_for_status
    raise HTTPError(http_error_msg, response=self)
E   requests.exceptions.HTTPError: 404 Client Error: Not Found for url: http+docker://localhost/v1.40/containers/3eec75fe06c7662b39b15d9b094d6f34d02fd5a2225168a04fa26cce72c45b9c/update

During handling of the above exception, another exception occurred:
/home/ubuntu/docker-py/tests/integration/models_containers_test.py:433: in test_update
    ???
docker/models/containers.py:489: in update
    return self.client.api.update_container(self.id, **kwargs)
docker/utils/decorators.py:34: in wrapper
    return f(self, *args, **kwargs)
docker/utils/decorators.py:19: in wrapped
    return f(self, resource_id, *args, **kwargs)
docker/api/container.py:1268: in update_container
    return self._result(res, True)
docker/api/client.py:302: in _result
    self._raise_for_status(response)
docker/api/client.py:298: in _raise_for_status
    raise create_api_error_from_http_exception(e)
docker/errors.py:31: in create_api_error_from_http_exception
    raise cls(e, response=response, explanation=explanation)
E   docker.errors.NotFound: 404 Client Error for http+docker://localhost/v1.40/containers/3eec75fe06c7662b39b15d9b094d6f34d02fd5a2225168a04fa26cce72c45b9c/update: Not Found ("b'Not Found'")
________________________ ImageCollectionTest.test_build ________________________
docker/api/client.py:296: in _raise_for_status
    response.raise_for_status()
../../.virtualenvs/docker-py/lib/python3.9/site-packages/requests/models.py:953: in raise_for_status
    raise HTTPError(http_error_msg, response=self)
E   requests.exceptions.HTTPError: 404 Client Error: Not Found for url: http+docker://localhost/v1.40/containers/create

During handling of the above exception, another exception occurred:
docker/models/containers.py:819: in run
    container = self.create(image=image, command=command,
docker/models/containers.py:878: in create
    resp = self.client.api.create_container(**create_kwargs)
docker/api/container.py:428: in create_container
    return self.create_container_from_config(config, name)
docker/api/container.py:439: in create_container_from_config
    return self._result(res, True)
docker/api/client.py:302: in _result
    self._raise_for_status(response)
docker/api/client.py:298: in _raise_for_status
    raise create_api_error_from_http_exception(e)
docker/errors.py:31: in create_api_error_from_http_exception
    raise cls(e, response=response, explanation=explanation)
E   docker.errors.ImageNotFound: 404 Client Error for http+docker://localhost/v1.40/containers/create: Not Found ("No such image: docker.io/library/sha256:8625c18694aef0aa9d9d41459edc886133adea4e9073659ed61a0cab998a188c: image not known")

During handling of the above exception, another exception occurred:
docker/api/client.py:296: in _raise_for_status
    response.raise_for_status()
../../.virtualenvs/docker-py/lib/python3.9/site-packages/requests/models.py:953: in raise_for_status
    raise HTTPError(http_error_msg, response=self)
E   requests.exceptions.HTTPError: 404 Client Error: Not Found for url: http+docker://localhost/v1.40/images/sha256:8625c18694aef0aa9d9d41459edc886133adea4e9073659ed61a0cab998a188c/json

During handling of the above exception, another exception occurred:
/home/ubuntu/docker-py/tests/integration/models_images_test.py:20: in test_build
    ???
docker/models/containers.py:822: in run
    self.client.images.pull(image, platform=platform)
docker/models/images.py:453: in pull
    return self.get('{0}{2}{1}'.format(
docker/models/images.py:314: in get
    return self.prepare_model(self.client.api.inspect_image(name))
docker/utils/decorators.py:19: in wrapped
    return f(self, resource_id, *args, **kwargs)
docker/api/image.py:251: in inspect_image
    return self._result(
docker/api/client.py:302: in _result
    self._raise_for_status(response)
docker/api/client.py:298: in _raise_for_status
    raise create_api_error_from_http_exception(e)
docker/errors.py:31: in create_api_error_from_http_exception
    raise cls(e, response=response, explanation=explanation)
E   docker.errors.ImageNotFound: 404 Client Error for http+docker://localhost/v1.40/images/sha256:8625c18694aef0aa9d9d41459edc886133adea4e9073659ed61a0cab998a188c/json: Not Found ("failed to find image sha256:8625c18694aef0aa9d9d41459edc886133adea4e9073659ed61a0cab998a188c: docker.io/library/sha256:8625c18694aef0aa9d9d41459edc886133adea4e9073659ed61a0cab998a188c: No such image")
__________________ ImageCollectionTest.test_build_with_error ___________________
/home/ubuntu/docker-py/tests/integration/models_images_test.py:30: in test_build_with_error
    ???
E   AssertionError: assert "The command '/bin/sh -c exit 1' returned a non-zero code: 1" in 'docker.errors.BuildError: error building at STEP "RUN exit 1": error while running runtime: exit status 1'
E    +  where 'docker.errors.BuildError: error building at STEP "RUN exit 1": error while running runtime: exit status 1' = <bound method ExceptionInfo.exconly of <ExceptionInfo BuildError('error building at STEP "RUN exit 1": error while running runtime: exit status 1\n') tblen=2>>()
E    +    where <bound method ExceptionInfo.exconly of <ExceptionInfo BuildError('error building at STEP "RUN exit 1": error while running runtime: exit status 1\n') tblen=2>> = <ExceptionInfo BuildError('error building at STEP "RUN exit 1": error while running runtime: exit status 1\n') tblen=2>.exconly
_____________ ImageCollectionTest.test_build_with_multiple_success _____________
docker/api/client.py:296: in _raise_for_status
    response.raise_for_status()
../../.virtualenvs/docker-py/lib/python3.9/site-packages/requests/models.py:953: in raise_for_status
    raise HTTPError(http_error_msg, response=self)
E   requests.exceptions.HTTPError: 404 Client Error: Not Found for url: http+docker://localhost/v1.40/containers/create

During handling of the above exception, another exception occurred:
docker/models/containers.py:819: in run
    container = self.create(image=image, command=command,
docker/models/containers.py:878: in create
    resp = self.client.api.create_container(**create_kwargs)
docker/api/container.py:428: in create_container
    return self.create_container_from_config(config, name)
docker/api/container.py:439: in create_container_from_config
    return self._result(res, True)
docker/api/client.py:302: in _result
    self._raise_for_status(response)
docker/api/client.py:298: in _raise_for_status
    raise create_api_error_from_http_exception(e)
docker/errors.py:31: in create_api_error_from_http_exception
    raise cls(e, response=response, explanation=explanation)
E   docker.errors.ImageNotFound: 404 Client Error for http+docker://localhost/v1.40/containers/create: Not Found ("No such image: docker.io/library/sha256:8625c18694aef0aa9d9d41459edc886133adea4e9073659ed61a0cab998a188c: image not known")

During handling of the above exception, another exception occurred:
docker/api/client.py:296: in _raise_for_status
    response.raise_for_status()
../../.virtualenvs/docker-py/lib/python3.9/site-packages/requests/models.py:953: in raise_for_status
    raise HTTPError(http_error_msg, response=self)
E   requests.exceptions.HTTPError: 404 Client Error: Not Found for url: http+docker://localhost/v1.40/images/sha256:8625c18694aef0aa9d9d41459edc886133adea4e9073659ed61a0cab998a188c/json

During handling of the above exception, another exception occurred:
/home/ubuntu/docker-py/tests/integration/models_images_test.py:44: in test_build_with_multiple_success
    ???
docker/models/containers.py:822: in run
    self.client.images.pull(image, platform=platform)
docker/models/images.py:453: in pull
    return self.get('{0}{2}{1}'.format(
docker/models/images.py:314: in get
    return self.prepare_model(self.client.api.inspect_image(name))
docker/utils/decorators.py:19: in wrapped
    return f(self, resource_id, *args, **kwargs)
docker/api/image.py:251: in inspect_image
    return self._result(
docker/api/client.py:302: in _result
    self._raise_for_status(response)
docker/api/client.py:298: in _raise_for_status
    raise create_api_error_from_http_exception(e)
docker/errors.py:31: in create_api_error_from_http_exception
    raise cls(e, response=response, explanation=explanation)
E   docker.errors.ImageNotFound: 404 Client Error for http+docker://localhost/v1.40/images/sha256:8625c18694aef0aa9d9d41459edc886133adea4e9073659ed61a0cab998a188c/json: Not Found ("failed to find image sha256:8625c18694aef0aa9d9d41459edc886133adea4e9073659ed61a0cab998a188c: docker.io/library/sha256:8625c18694aef0aa9d9d41459edc886133adea4e9073659ed61a0cab998a188c: No such image")
___________ ImageCollectionTest.test_build_with_success_build_output ___________
docker/api/client.py:296: in _raise_for_status
    response.raise_for_status()
../../.virtualenvs/docker-py/lib/python3.9/site-packages/requests/models.py:953: in raise_for_status
    raise HTTPError(http_error_msg, response=self)
E   requests.exceptions.HTTPError: 404 Client Error: Not Found for url: http+docker://localhost/v1.40/containers/create

During handling of the above exception, another exception occurred:
docker/models/containers.py:819: in run
    container = self.create(image=image, command=command,
docker/models/containers.py:878: in create
    resp = self.client.api.create_container(**create_kwargs)
docker/api/container.py:428: in create_container
    return self.create_container_from_config(config, name)
docker/api/container.py:439: in create_container_from_config
    return self._result(res, True)
docker/api/client.py:302: in _result
    self._raise_for_status(response)
docker/api/client.py:298: in _raise_for_status
    raise create_api_error_from_http_exception(e)
docker/errors.py:31: in create_api_error_from_http_exception
    raise cls(e, response=response, explanation=explanation)
E   docker.errors.ImageNotFound: 404 Client Error for http+docker://localhost/v1.40/containers/create: Not Found ("No such image: docker.io/library/sha256:032a793e79b53215aed7339de9c0b710bfdcacedfea1fd34b265432145cb07d4: image not known")

During handling of the above exception, another exception occurred:
docker/api/client.py:296: in _raise_for_status
    response.raise_for_status()
../../.virtualenvs/docker-py/lib/python3.9/site-packages/requests/models.py:953: in raise_for_status
    raise HTTPError(http_error_msg, response=self)
E   requests.exceptions.HTTPError: 404 Client Error: Not Found for url: http+docker://localhost/v1.40/images/sha256:032a793e79b53215aed7339de9c0b710bfdcacedfea1fd34b265432145cb07d4/json

During handling of the above exception, another exception occurred:
/home/ubuntu/docker-py/tests/integration/models_images_test.py:55: in test_build_with_success_build_output
    ???
docker/models/containers.py:822: in run
    self.client.images.pull(image, platform=platform)
docker/models/images.py:453: in pull
    return self.get('{0}{2}{1}'.format(
docker/models/images.py:314: in get
    return self.prepare_model(self.client.api.inspect_image(name))
docker/utils/decorators.py:19: in wrapped
    return f(self, resource_id, *args, **kwargs)
docker/api/image.py:251: in inspect_image
    return self._result(
docker/api/client.py:302: in _result
    self._raise_for_status(response)
docker/api/client.py:298: in _raise_for_status
    raise create_api_error_from_http_exception(e)
docker/errors.py:31: in create_api_error_from_http_exception
    raise cls(e, response=response, explanation=explanation)
E   docker.errors.ImageNotFound: 404 Client Error for http+docker://localhost/v1.40/images/sha256:032a793e79b53215aed7339de9c0b710bfdcacedfea1fd34b265432145cb07d4/json: Not Found ("failed to find image sha256:032a793e79b53215aed7339de9c0b710bfdcacedfea1fd34b265432145cb07d4: docker.io/library/sha256:032a793e79b53215aed7339de9c0b710bfdcacedfea1fd34b265432145cb07d4: No such image")
________________________ ImageCollectionTest.test_list _________________________
docker/api/client.py:296: in _raise_for_status
    response.raise_for_status()
../../.virtualenvs/docker-py/lib/python3.9/site-packages/requests/models.py:953: in raise_for_status
    raise HTTPError(http_error_msg, response=self)
E   requests.exceptions.HTTPError: 404 Client Error: Not Found for url: http+docker://localhost/v1.40/images/sha256:1b9c5f5389cac0c77e3d942622ff5f554ee6626b6618b151fc72b4923f3bed34/json

During handling of the above exception, another exception occurred:
/home/ubuntu/docker-py/tests/integration/models_images_test.py:60: in test_list
    ???
docker/models/images.py:362: in list
    return [self.get(r["Id"]) for r in resp]
docker/models/images.py:362: in <listcomp>
    return [self.get(r["Id"]) for r in resp]
docker/models/images.py:314: in get
    return self.prepare_model(self.client.api.inspect_image(name))
docker/utils/decorators.py:19: in wrapped
    return f(self, resource_id, *args, **kwargs)
docker/api/image.py:251: in inspect_image
    return self._result(
docker/api/client.py:302: in _result
    self._raise_for_status(response)
docker/api/client.py:298: in _raise_for_status
    raise create_api_error_from_http_exception(e)
docker/errors.py:31: in create_api_error_from_http_exception
    raise cls(e, response=response, explanation=explanation)
E   docker.errors.ImageNotFound: 404 Client Error for http+docker://localhost/v1.40/images/sha256:1b9c5f5389cac0c77e3d942622ff5f554ee6626b6618b151fc72b4923f3bed34/json: Not Found ("failed to find image sha256:1b9c5f5389cac0c77e3d942622ff5f554ee6626b6618b151fc72b4923f3bed34: docker.io/library/sha256:1b9c5f5389cac0c77e3d942622ff5f554ee6626b6618b151fc72b4923f3bed34: No such image")
________________ ImageCollectionTest.test_list_with_repository _________________
docker/api/client.py:296: in _raise_for_status
    response.raise_for_status()
../../.virtualenvs/docker-py/lib/python3.9/site-packages/requests/models.py:953: in raise_for_status
    raise HTTPError(http_error_msg, response=self)
E   requests.exceptions.HTTPError: 404 Client Error: Not Found for url: http+docker://localhost/v1.40/images/sha256:c059bfaa849c4d8e4aecaeb3a10c2d9b3d85f5165c66ad3a4d937758128c4d18/json

During handling of the above exception, another exception occurred:
/home/ubuntu/docker-py/tests/integration/models_images_test.py:65: in test_list_with_repository
    ???
docker/models/images.py:362: in list
    return [self.get(r["Id"]) for r in resp]
docker/models/images.py:362: in <listcomp>
    return [self.get(r["Id"]) for r in resp]
docker/models/images.py:314: in get
    return self.prepare_model(self.client.api.inspect_image(name))
docker/utils/decorators.py:19: in wrapped
    return f(self, resource_id, *args, **kwargs)
docker/api/image.py:251: in inspect_image
    return self._result(
docker/api/client.py:302: in _result
    self._raise_for_status(response)
docker/api/client.py:298: in _raise_for_status
    raise create_api_error_from_http_exception(e)
docker/errors.py:31: in create_api_error_from_http_exception
    raise cls(e, response=response, explanation=explanation)
E   docker.errors.ImageNotFound: 404 Client Error for http+docker://localhost/v1.40/images/sha256:c059bfaa849c4d8e4aecaeb3a10c2d9b3d85f5165c66ad3a4d937758128c4d18/json: Not Found ("failed to find image sha256:c059bfaa849c4d8e4aecaeb3a10c2d9b3d85f5165c66ad3a4d937758128c4d18: docker.io/library/sha256:c059bfaa849c4d8e4aecaeb3a10c2d9b3d85f5165c66ad3a4d937758128c4d18: No such image")
_____________________ ImageCollectionTest.test_load_error ______________________
docker/api/client.py:296: in _raise_for_status
    response.raise_for_status()
../../.virtualenvs/docker-py/lib/python3.9/site-packages/requests/models.py:953: in raise_for_status
    raise HTTPError(http_error_msg, response=self)
E   requests.exceptions.HTTPError: 500 Server Error: Internal Server Error for url: http+docker://localhost/v1.40/images/load

During handling of the above exception, another exception occurred:
/home/ubuntu/docker-py/tests/integration/models_images_test.py:98: in test_load_error
    ???
docker/models/images.py:382: in load
    for chunk in resp:
docker/api/client.py:386: in _stream_helper
    yield self._result(response, json=decode)
docker/api/client.py:302: in _result
    self._raise_for_status(response)
docker/api/client.py:298: in _raise_for_status
    raise create_api_error_from_http_exception(e)
docker/errors.py:31: in create_api_error_from_http_exception
    raise cls(e, response=response, explanation=explanation)
E   docker.errors.APIError: 500 Server Error for http+docker://localhost/v1.40/images/load: Internal Server Error ("failed to load image: payload does not match any of the supported image formats:
E    * docker-archive: loading tar component manifest.json: unexpected EOF
E    * oci: initializing source oci:/var/tmp/api_load.tar588488681:: open /var/tmp/api_load.tar588488681/index.json: not a directory
E    * oci-archive: creating temp directory: untarring file "/var/tmp/oci3906488639": unexpected EOF
E    * dir: determining manifest MIME type for dir:/var/tmp/api_load.tar588488681: open /var/tmp/api_load.tar588488681/manifest.json: not a directory")
________________________ ImageCollectionTest.test_pull _________________________
/home/ubuntu/docker-py/tests/integration/models_images_test.py:71: in test_pull
    ???
E   AssertionError: assert 'alpine:latest' in ['docker.io/library/alpine:latest']
____________________ ImageCollectionTest.test_pull_multiple ____________________
docker/api/client.py:296: in _raise_for_status
    response.raise_for_status()
../../.virtualenvs/docker-py/lib/python3.9/site-packages/requests/models.py:953: in raise_for_status
    raise HTTPError(http_error_msg, response=self)
E   requests.exceptions.HTTPError: 404 Client Error: Not Found for url: http+docker://localhost/v1.40/images/sha256:feb5d9fea6a5e9606aa995e879d862b825965ba48de054caab5ef356dc6b3412/json

During handling of the above exception, another exception occurred:
/home/ubuntu/docker-py/tests/integration/models_images_test.py:89: in test_pull_multiple
    ???
docker/models/images.py:456: in pull
    return self.list(repository)
docker/models/images.py:362: in list
    return [self.get(r["Id"]) for r in resp]
docker/models/images.py:362: in <listcomp>
    return [self.get(r["Id"]) for r in resp]
docker/models/images.py:314: in get
    return self.prepare_model(self.client.api.inspect_image(name))
docker/utils/decorators.py:19: in wrapped
    return f(self, resource_id, *args, **kwargs)
docker/api/image.py:251: in inspect_image
    return self._result(
docker/api/client.py:302: in _result
    self._raise_for_status(response)
docker/api/client.py:298: in _raise_for_status
    raise create_api_error_from_http_exception(e)
docker/errors.py:31: in create_api_error_from_http_exception
    raise cls(e, response=response, explanation=explanation)
E   docker.errors.ImageNotFound: 404 Client Error for http+docker://localhost/v1.40/images/sha256:feb5d9fea6a5e9606aa995e879d862b825965ba48de054caab5ef356dc6b3412/json: Not Found ("failed to find image sha256:feb5d9fea6a5e9606aa995e879d862b825965ba48de054caab5ef356dc6b3412: docker.io/library/sha256:feb5d9fea6a5e9606aa995e879d862b825965ba48de054caab5ef356dc6b3412: No such image")
____________________ ImageCollectionTest.test_pull_with_sha ____________________
/home/ubuntu/docker-py/tests/integration/models_images_test.py:85: in test_pull_with_sha
    ???
E   AssertionError: assert 'hello-world@sha256:083de497cff944f969d8499ab94f07134c50bcf5e6b9559b27182d3fa80ce3f7' in ['docker.io/library/hello-world@sha256:083de497cff944f969d8499ab94f07134c50bcf5e6b9559b27182d3fa80ce3f7', 'docker.io/library/hello-world@sha256:8072a54ebb3bc136150e2f2860f00a7bf45f13eeb917cca2430fcd0054c8e51b']
____________________ ImageCollectionTest.test_pull_with_tag ____________________
/home/ubuntu/docker-py/tests/integration/models_images_test.py:76: in test_pull_with_tag
    ???
E   AssertionError: assert 'alpine:3.10' in ['docker.io/library/alpine:3.10']
____________________ ImageCollectionTest.test_save_and_load ____________________
docker/api/client.py:296: in _raise_for_status
    response.raise_for_status()
../../.virtualenvs/docker-py/lib/python3.9/site-packages/requests/models.py:953: in raise_for_status
    raise HTTPError(http_error_msg, response=self)
E   requests.exceptions.HTTPError: 404 Client Error: Not Found for url: http+docker://localhost/v1.40/images/sha256:e7b300aee9f9bf3433d32bc9305bfdd22183beb59d933b48d77ab56ba53a197a/get

During handling of the above exception, another exception occurred:
/home/ubuntu/docker-py/tests/integration/models_images_test.py:105: in test_save_and_load
    ???
docker/api/client.py:427: in _stream_raw_result
    self._raise_for_status(response)
docker/api/client.py:298: in _raise_for_status
    raise create_api_error_from_http_exception(e)
docker/errors.py:31: in create_api_error_from_http_exception
    raise cls(e, response=response, explanation=explanation)
E   docker.errors.NotFound: 404 Client Error for http+docker://localhost/v1.40/images/sha256:e7b300aee9f9bf3433d32bc9305bfdd22183beb59d933b48d77ab56ba53a197a/get: Not Found ("failed to find image sha256:e7b300aee9f9bf3433d32bc9305bfdd22183beb59d933b48d77ab56ba53a197a: docker.io/library/sha256:e7b300aee9f9bf3433d32bc9305bfdd22183beb59d933b48d77ab56ba53a197a: image not known")
_______________ ImageCollectionTest.test_save_and_load_repo_name _______________
docker/api/client.py:296: in _raise_for_status
    response.raise_for_status()
../../.virtualenvs/docker-py/lib/python3.9/site-packages/requests/models.py:953: in raise_for_status
    raise HTTPError(http_error_msg, response=self)
E   requests.exceptions.HTTPError: 404 Client Error: Not Found for url: http+docker://localhost/v1.40/images/sha256:e7b300aee9f9bf3433d32bc9305bfdd22183beb59d933b48d77ab56ba53a197a/tag?repo=dockerpytest_61a60b169c25b7de&force=0

During handling of the above exception, another exception occurred:
/home/ubuntu/docker-py/tests/integration/models_images_test.py:118: in test_save_and_load_repo_name
    ???
docker/models/images.py:120: in tag
    return self.client.api.tag(self.id, repository, tag=tag, **kwargs)
docker/utils/decorators.py:19: in wrapped
    return f(self, resource_id, *args, **kwargs)
docker/api/image.py:565: in tag
    self._raise_for_status(res)
docker/api/client.py:298: in _raise_for_status
    raise create_api_error_from_http_exception(e)
docker/errors.py:31: in create_api_error_from_http_exception
    raise cls(e, response=response, explanation=explanation)
E   docker.errors.NotFound: 404 Client Error for http+docker://localhost/v1.40/images/sha256:e7b300aee9f9bf3433d32bc9305bfdd22183beb59d933b48d77ab56ba53a197a/tag?repo=dockerpytest_61a60b169c25b7de&force=0: Not Found ("failed to find image sha256:e7b300aee9f9bf3433d32bc9305bfdd22183beb59d933b48d77ab56ba53a197a: docker.io/library/sha256:e7b300aee9f9bf3433d32bc9305bfdd22183beb59d933b48d77ab56ba53a197a: image not known")
________________________ ImageTest.test_tag_and_remove _________________________
docker/api/client.py:296: in _raise_for_status
    response.raise_for_status()
../../.virtualenvs/docker-py/lib/python3.9/site-packages/requests/models.py:953: in raise_for_status
    raise HTTPError(http_error_msg, response=self)
E   requests.exceptions.HTTPError: 404 Client Error: Not Found for url: http+docker://localhost/v1.40/images/sha256:c059bfaa849c4d8e4aecaeb3a10c2d9b3d85f5165c66ad3a4d937758128c4d18/tag?tag=some-tag&repo=dockersdk.tests.images.test_tag&force=0

During handling of the above exception, another exception occurred:
/home/ubuntu/docker-py/tests/integration/models_images_test.py:151: in test_tag_and_remove
    ???
docker/models/images.py:120: in tag
    return self.client.api.tag(self.id, repository, tag=tag, **kwargs)
docker/utils/decorators.py:19: in wrapped
    return f(self, resource_id, *args, **kwargs)
docker/api/image.py:565: in tag
    self._raise_for_status(res)
docker/api/client.py:298: in _raise_for_status
    raise create_api_error_from_http_exception(e)
docker/errors.py:31: in create_api_error_from_http_exception
    raise cls(e, response=response, explanation=explanation)
E   docker.errors.NotFound: 404 Client Error for http+docker://localhost/v1.40/images/sha256:c059bfaa849c4d8e4aecaeb3a10c2d9b3d85f5165c66ad3a4d937758128c4d18/tag?tag=some-tag&repo=dockersdk.tests.images.test_tag&force=0: Not Found ("failed to find image sha256:c059bfaa849c4d8e4aecaeb3a10c2d9b3d85f5165c66ad3a4d937758128c4d18: docker.io/library/sha256:c059bfaa849c4d8e4aecaeb3a10c2d9b3d85f5165c66ad3a4d937758128c4d18: image not known")
_____________________ NetworkTest.test_connect_disconnect ______________________
docker/api/client.py:296: in _raise_for_status
    response.raise_for_status()
../../.virtualenvs/docker-py/lib/python3.9/site-packages/requests/models.py:953: in raise_for_status
    raise HTTPError(http_error_msg, response=self)
E   requests.exceptions.HTTPError: 500 Server Error: Internal Server Error for url: http+docker://localhost/v1.40/networks/c2b75dc994b790d08af1cf17412359b8dae3dc5843d25a4b6eb09bd062b70717/connect

During handling of the above exception, another exception occurred:
/home/ubuntu/docker-py/tests/integration/models_networks_test.py:59: in test_connect_disconnect
    ???
docker/models/networks.py:58: in connect
    return self.client.api.connect_container_to_network(
docker/utils/decorators.py:19: in wrapped
    return f(self, resource_id, *args, **kwargs)
docker/api/network.py:250: in connect_container_to_network
    self._raise_for_status(res)
docker/api/client.py:298: in _raise_for_status
    raise create_api_error_from_http_exception(e)
docker/errors.py:31: in create_api_error_from_http_exception
    raise cls(e, response=response, explanation=explanation)
E   docker.errors.APIError: 500 Server Error for http+docker://localhost/v1.40/networks/c2b75dc994b790d08af1cf17412359b8dae3dc5843d25a4b6eb09bd062b70717/connect: Internal Server Error (""slirp4netns" is not supported: invalid network mode")
_________________________ VolumesTest.test_list_remove _________________________
/home/ubuntu/docker-py/tests/integration/models_volumes_test.py:26: in test_list_remove
    ???
E   AssertionError: assert <Volume: dockerpyte> in []
E    +  where [] = <bound method VolumeCollection.list of <docker.models.volumes.VolumeCollection object at 0x7fcc3875f400>>(filters={'name': 'dockerpytest_'})
E    +    where <bound method VolumeCollection.list of <docker.models.volumes.VolumeCollection object at 0x7fcc3875f400>> = <docker.models.volumes.VolumeCollection object at 0x7fcc3875f400>.list
E    +      where <docker.models.volumes.VolumeCollection object at 0x7fcc3875f400> = <docker.client.DockerClient object at 0x7fcc386c6490>.volumes
________ TestRegressions.test_443_handle_nonchunked_response_in_stream _________
/home/ubuntu/docker-py/tests/integration/regression_test.py:15: in test_443_handle_nonchunked_response_in_stream
    ???
E   Failed: DID NOT RAISE <class 'docker.errors.APIError'>
_______________ TestRegressions.test_792_explicit_port_protocol ________________
docker/api/client.py:296: in _raise_for_status
    response.raise_for_status()
../../.virtualenvs/docker-py/lib/python3.9/site-packages/requests/models.py:953: in raise_for_status
    raise HTTPError(http_error_msg, response=self)
E   requests.exceptions.HTTPError: 500 Server Error: Internal Server Error for url: http+docker://localhost/v1.40/containers/b3c56252a6adbaf6122b6ed3ecc2eaa488337be75a4ec24d4ecf6620c297c273/start

During handling of the above exception, another exception occurred:
/home/ubuntu/docker-py/tests/integration/regression_test.py:54: in test_792_explicit_port_protocol
    ???
docker/utils/decorators.py:19: in wrapped
    return f(self, resource_id, *args, **kwargs)
docker/api/container.py:1109: in start
    self._raise_for_status(res)
docker/api/client.py:298: in _raise_for_status
    raise create_api_error_from_http_exception(e)
docker/errors.py:31: in create_api_error_from_http_exception
    raise cls(e, response=response, explanation=explanation)
E   docker.errors.APIError: 500 Server Error for http+docker://localhost/v1.40/containers/b3c56252a6adbaf6122b6ed3ecc2eaa488337be75a4ec24d4ecf6620c297c273/start: Internal Server Error ("could not find "rootlessport" in one of [/usr/local/libexec/podman /usr/local/lib/podman /usr/libexec/podman /usr/lib/podman].  To resolve this error, set the helper_binaries_dir key in the `[engine]` section of containers.conf to the directory containing your helper binaries.")
=============================== warnings summary ===============================
tests/integration/api_client_test.py::ConnectionTimeoutTest::test_timeout
  /home/riyad/src/docker-py/docker/utils/utils.py:269: DeprecationWarning: urllib.parse.splitnport() is deprecated as of 3.8, use urllib.parse.urlparse() instead
    host, port = splitnport(parsed_url.netloc)

-- Docs: https://docs.pytest.org/en/stable/warnings.html
- generated xml file: /home/riyad/src/docker-py/logs/pytest_integration_4.0.0-dev_2021-12-17T16:04:26+01:00_59766ebe76fe5bdd15256f5d39d063c95304989f.junit.xml -
=========================== short test summary info ============================
XFAIL tests/integration/api_build_test.py::BuildTest::test_prune_builds
  Currently fails on 18.09: https://github.com/moby/moby/issues/37920
XFAIL tests/integration/api_container_test.py::CreateContainerTest::test_create_with_storage_opt
  Not supported on most drivers
XFAIL tests/integration/api_container_test.py::ContainerTopTest::test_top
  Output of docker top depends on host distro, and is not formalized.
XFAIL tests/integration/api_container_test.py::ContainerTopTest::test_top_with_psargs
  Output of docker top depends on host distro, and is not formalized.
SKIPPED [1] ../../../ubuntu/docker-py/tests/integration/api_image_test.py:291: Doesn't work inside a container - FIXME
= 92 failed, 163 passed, 1 skipped, 154 deselected, 4 xfailed, 1 xpassed, 1 warning, 5 errors in 2298.45s (0:38:18) =
