<?xml version="1.0" encoding="utf-8"?><testsuites><testsuite name="docker-py" errors="0" failures="75" skipped="7" tests="269" time="2370.517" timestamp="2022-11-16T21:56:35.893332" hostname="acnologia"><testcase classname="tests.integration.api_build_test.BuildTest" name="test_build_container_with_target" time="16.540" /><testcase classname="tests.integration.api_build_test.BuildTest" name="test_build_from_stringio" time="9.286" /><testcase classname="tests.integration.api_build_test.BuildTest" name="test_build_gzip_custom_encoding" time="8.902" /><testcase classname="tests.integration.api_build_test.BuildTest" name="test_build_gzip_encoding" time="8.339" /><testcase classname="tests.integration.api_build_test.BuildTest" name="test_build_in_context_abs_dockerfile" time="8.966" /><testcase classname="tests.integration.api_build_test.BuildTest" name="test_build_in_context_dockerfile" time="8.051" /><testcase classname="tests.integration.api_build_test.BuildTest" name="test_build_in_context_nested_dockerfile" time="9.226" /><testcase classname="tests.integration.api_build_test.BuildTest" name="test_build_invalid_platform" time="9.026"><failure message="AssertionError: assert ('unknown operating system' in 'docker.errors.APIError: 400 Client Error for http+docker://localhost/v1.41/build?q=False&amp;nocache=False&amp;rm=False&amp;forcerm=False&amp;pull=False&amp;platform=foobar: Bad Request' or 'invalid platform' in 'docker.errors.APIError: 400 Client Error for http+docker://localhost/v1.41/build?q=False&amp;nocache=False&amp;rm=False&amp;forcerm=False&amp;pull=False&amp;platform=foobar: Bad Request')&#10; +  where 'docker.errors.APIError: 400 Client Error for http+docker://localhost/v1.41/build?q=False&amp;nocache=False&amp;rm=False&amp;forcerm=False&amp;pull=False&amp;platform=foobar: Bad Request' = &lt;bound method ExceptionInfo.exconly of &lt;ExceptionInfo APIError(HTTPError('400 Client Error: Bad Request for url: http+docker://localhost/v1.41/build?q=False&amp;nocache=False&amp;rm=False&amp;forcerm=False&amp;pull=False&amp;platform=foobar')) tblen=5&gt;&gt;()&#10; +    where &lt;bound method ExceptionInfo.exconly of &lt;ExceptionInfo APIError(HTTPError('400 Client Error: Bad Request for url: http+docker://localhost/v1.41/build?q=False&amp;nocache=False&amp;rm=False&amp;forcerm=False&amp;pull=False&amp;platform=foobar')) tblen=5&gt;&gt; = &lt;ExceptionInfo APIError(HTTPError('400 Client Error: Bad Request for url: http+docker://localhost/v1.41/build?q=False&amp;nocache=False&amp;rm=False&amp;forcerm=False&amp;pull=False&amp;platform=foobar')) tblen=5&gt;.exconly&#10; +  and   'docker.errors.APIError: 400 Client Error for http+docker://localhost/v1.41/build?q=False&amp;nocache=False&amp;rm=False&amp;forcerm=False&amp;pull=False&amp;platform=foobar: Bad Request' = &lt;bound method ExceptionInfo.exconly of &lt;ExceptionInfo APIError(HTTPError('400 Client Error: Bad Request for url: http+docker://localhost/v1.41/build?q=False&amp;nocache=False&amp;rm=False&amp;forcerm=False&amp;pull=False&amp;platform=foobar')) tblen=5&gt;&gt;()&#10; +    where &lt;bound method ExceptionInfo.exconly of &lt;ExceptionInfo APIError(HTTPError('400 Client Error: Bad Request for url: http+docker://localhost/v1.41/build?q=False&amp;nocache=False&amp;rm=False&amp;forcerm=False&amp;pull=False&amp;platform=foobar')) tblen=5&gt;&gt; = &lt;ExceptionInfo APIError(HTTPError('400 Client Error: Bad Request for url: http+docker://localhost/v1.41/build?q=False&amp;nocache=False&amp;rm=False&amp;forcerm=False&amp;pull=False&amp;platform=foobar')) tblen=5&gt;.exconly">tests/integration/api_build_test.py:464: in test_build_invalid_platform
    assert 'unknown operating system' in excinfo.exconly() \
E   AssertionError: assert ('unknown operating system' in 'docker.errors.APIError: 400 Client Error for http+docker://localhost/v1.41/build?q=False&amp;nocache=False&amp;rm=False&amp;forcerm=False&amp;pull=False&amp;platform=foobar: Bad Request' or 'invalid platform' in 'docker.errors.APIError: 400 Client Error for http+docker://localhost/v1.41/build?q=False&amp;nocache=False&amp;rm=False&amp;forcerm=False&amp;pull=False&amp;platform=foobar: Bad Request')
E    +  where 'docker.errors.APIError: 400 Client Error for http+docker://localhost/v1.41/build?q=False&amp;nocache=False&amp;rm=False&amp;forcerm=False&amp;pull=False&amp;platform=foobar: Bad Request' = &lt;bound method ExceptionInfo.exconly of &lt;ExceptionInfo APIError(HTTPError('400 Client Error: Bad Request for url: http+docker://localhost/v1.41/build?q=False&amp;nocache=False&amp;rm=False&amp;forcerm=False&amp;pull=False&amp;platform=foobar')) tblen=5&gt;&gt;()
E    +    where &lt;bound method ExceptionInfo.exconly of &lt;ExceptionInfo APIError(HTTPError('400 Client Error: Bad Request for url: http+docker://localhost/v1.41/build?q=False&amp;nocache=False&amp;rm=False&amp;forcerm=False&amp;pull=False&amp;platform=foobar')) tblen=5&gt;&gt; = &lt;ExceptionInfo APIError(HTTPError('400 Client Error: Bad Request for url: http+docker://localhost/v1.41/build?q=False&amp;nocache=False&amp;rm=False&amp;forcerm=False&amp;pull=False&amp;platform=foobar')) tblen=5&gt;.exconly
E    +  and   'docker.errors.APIError: 400 Client Error for http+docker://localhost/v1.41/build?q=False&amp;nocache=False&amp;rm=False&amp;forcerm=False&amp;pull=False&amp;platform=foobar: Bad Request' = &lt;bound method ExceptionInfo.exconly of &lt;ExceptionInfo APIError(HTTPError('400 Client Error: Bad Request for url: http+docker://localhost/v1.41/build?q=False&amp;nocache=False&amp;rm=False&amp;forcerm=False&amp;pull=False&amp;platform=foobar')) tblen=5&gt;&gt;()
E    +    where &lt;bound method ExceptionInfo.exconly of &lt;ExceptionInfo APIError(HTTPError('400 Client Error: Bad Request for url: http+docker://localhost/v1.41/build?q=False&amp;nocache=False&amp;rm=False&amp;forcerm=False&amp;pull=False&amp;platform=foobar')) tblen=5&gt;&gt; = &lt;ExceptionInfo APIError(HTTPError('400 Client Error: Bad Request for url: http+docker://localhost/v1.41/build?q=False&amp;nocache=False&amp;rm=False&amp;forcerm=False&amp;pull=False&amp;platform=foobar')) tblen=5&gt;.exconly</failure><system-out>--------------------------------- Captured Log ---------------------------------

--------------------------------- Captured Out ---------------------------------

</system-out><system-err>--------------------------------- Captured Err ---------------------------------

</system-err></testcase><testcase classname="tests.integration.api_build_test.BuildTest" name="test_build_isolation" time="7.343" /><testcase classname="tests.integration.api_build_test.BuildTest" name="test_build_labels" time="7.402" /><testcase classname="tests.integration.api_build_test.BuildTest" name="test_build_out_of_context_dockerfile" time="8.586" /><testcase classname="tests.integration.api_build_test.BuildTest" name="test_build_shmsize" time="7.265" /><testcase classname="tests.integration.api_build_test.BuildTest" name="test_build_squash" time="12.650" /><testcase classname="tests.integration.api_build_test.BuildTest" name="test_build_stderr_data" time="8.408" /><testcase classname="tests.integration.api_build_test.BuildTest" name="test_build_streaming" time="13.397" /><testcase classname="tests.integration.api_build_test.BuildTest" name="test_build_with_buildargs" time="8.731" /><testcase classname="tests.integration.api_build_test.BuildTest" name="test_build_with_cache_from" time="10.078"><failure message="assert 3 == 0">tests/integration/api_build_test.py:257: in test_build_with_cache_from
    assert counter == 0
E   assert 3 == 0</failure><system-out>--------------------------------- Captured Log ---------------------------------

--------------------------------- Captured Out ---------------------------------

</system-out><system-err>--------------------------------- Captured Err ---------------------------------

</system-err></testcase><testcase classname="tests.integration.api_build_test.BuildTest" name="test_build_with_dockerfile_empty_lines" time="7.451" /><testcase classname="tests.integration.api_build_test.BuildTest" name="test_build_with_dockerignore" time="9.427"><failure message="AssertionError: assert ['/test/#file.../not-ignored'] == ['/test/#file.../not-ignored']&#10;  At index 2 diff: '/test/not-ignored' != '/test/ignored/subdir/excepted-with-spaces'&#10;  Right contains one more item: '/test/not-ignored'&#10;  Full diff:&#10;    [&#10;     '/test/#file.txt',&#10;     '/test/ignored/subdir/excepted-file',&#10;  -  '/test/ignored/subdir/excepted-with-spaces',...&#10;  &#10;  ...Full output truncated (3 lines hidden), use '-vv' to show">tests/integration/api_build_test.py:145: in test_build_with_dockerignore
    assert sorted(list(filter(None, logs.split('\n')))) == sorted([
E   AssertionError: assert ['/test/#file.../not-ignored'] == ['/test/#file.../not-ignored']
E     At index 2 diff: '/test/not-ignored' != '/test/ignored/subdir/excepted-with-spaces'
E     Right contains one more item: '/test/not-ignored'
E     Full diff:
E       [
E        '/test/#file.txt',
E        '/test/ignored/subdir/excepted-file',
E     -  '/test/ignored/subdir/excepted-with-spaces',...
E     
E     ...Full output truncated (3 lines hidden), use '-vv' to show</failure><system-out>--------------------------------- Captured Log ---------------------------------

--------------------------------- Captured Out ---------------------------------

</system-out><system-err>--------------------------------- Captured Err ---------------------------------

</system-err></testcase><testcase classname="tests.integration.api_build_test.BuildTest" name="test_build_with_extra_hosts" time="7.184"><failure message="docker.errors.APIError: 400 Client Error for http+docker://localhost/v1.41/build?t=dockerpytest_extrahost_build&amp;q=False&amp;nocache=False&amp;rm=False&amp;forcerm=False&amp;pull=False&amp;extrahosts=extrahost.local.test%3A127.0.0.1&amp;extrahosts=hello.world.test%3A127.0.0.1: Bad Request">docker/api/client.py:296: in _raise_for_status
    response.raise_for_status()
../../.virtualenvs/docker-py/lib/python3.10/site-packages/requests/models.py:1021: in raise_for_status
    raise HTTPError(http_error_msg, response=self)
E   requests.exceptions.HTTPError: 400 Client Error: Bad Request for url: http+docker://localhost/v1.41/build?t=dockerpytest_extrahost_build&amp;q=False&amp;nocache=False&amp;rm=False&amp;forcerm=False&amp;pull=False&amp;extrahosts=extrahost.local.test%3A127.0.0.1&amp;extrahosts=hello.world.test%3A127.0.0.1

The above exception was the direct cause of the following exception:
tests/integration/api_build_test.py:342: in test_build_with_extra_hosts
    for chunk in stream:
docker/api/client.py:386: in _stream_helper
    yield self._result(response, json=decode)
docker/api/client.py:302: in _result
    self._raise_for_status(response)
docker/api/client.py:298: in _raise_for_status
    raise create_api_error_from_http_exception(e) from e
docker/errors.py:39: in create_api_error_from_http_exception
    raise cls(e, response=response, explanation=explanation) from e
E   docker.errors.APIError: 400 Client Error for http+docker://localhost/v1.41/build?t=dockerpytest_extrahost_build&amp;q=False&amp;nocache=False&amp;rm=False&amp;forcerm=False&amp;pull=False&amp;extrahosts=extrahost.local.test%3A127.0.0.1&amp;extrahosts=hello.world.test%3A127.0.0.1: Bad Request</failure><system-out>--------------------------------- Captured Log ---------------------------------

--------------------------------- Captured Out ---------------------------------

</system-out><system-err>--------------------------------- Captured Err ---------------------------------

</system-err></testcase><testcase classname="tests.integration.api_build_test.BuildTest" name="test_build_with_network_mode" time="8.831"><failure message="docker.errors.ImageNotFound: 404 Client Error for http+docker://localhost/v1.41/images/dockerpytest_customnetbuild/json: Not Found (&quot;failed to find image dockerpytest_customnetbuild: docker.io/library/dockerpytest_customnetbuild: No such image&quot;)">docker/api/client.py:296: in _raise_for_status
    response.raise_for_status()
../../.virtualenvs/docker-py/lib/python3.10/site-packages/requests/models.py:1021: in raise_for_status
    raise HTTPError(http_error_msg, response=self)
E   requests.exceptions.HTTPError: 404 Client Error: Not Found for url: http+docker://localhost/v1.41/images/dockerpytest_customnetbuild/json

The above exception was the direct cause of the following exception:
tests/integration/api_build_test.py:307: in test_build_with_network_mode
    assert self.client.inspect_image('dockerpytest_customnetbuild')
docker/utils/decorators.py:19: in wrapped
    return f(self, resource_id, *args, **kwargs)
docker/api/image.py:251: in inspect_image
    return self._result(
docker/api/client.py:302: in _result
    self._raise_for_status(response)
docker/api/client.py:298: in _raise_for_status
    raise create_api_error_from_http_exception(e) from e
docker/errors.py:39: in create_api_error_from_http_exception
    raise cls(e, response=response, explanation=explanation) from e
E   docker.errors.ImageNotFound: 404 Client Error for http+docker://localhost/v1.41/images/dockerpytest_customnetbuild/json: Not Found ("failed to find image dockerpytest_customnetbuild: docker.io/library/dockerpytest_customnetbuild: No such image")</failure><system-out>--------------------------------- Captured Log ---------------------------------

--------------------------------- Captured Out ---------------------------------

</system-out><system-err>--------------------------------- Captured Err ---------------------------------

</system-err></testcase><testcase classname="tests.integration.api_build_test.BuildTest" name="test_build_with_proxy" time="7.273" /><testcase classname="tests.integration.api_build_test.BuildTest" name="test_build_with_proxy_and_buildargs" time="7.275" /><testcase classname="tests.integration.api_build_test.BuildTest" name="test_prune_builds" time="7.185"><skipped type="pytest.xfail" message="Currently fails on 18.09: https://github.com/moby/moby/issues/37920" /></testcase><testcase classname="tests.integration.api_client_test.InformationTest" name="test_info" time="8.840" /><testcase classname="tests.integration.api_client_test.InformationTest" name="test_version" time="9.617" /><testcase classname="tests.integration.api_client_test.AutoDetectVersionTest" name="test_client_init" time="7.267" /><testcase classname="tests.integration.api_client_test.ConnectionTimeoutTest" name="test_timeout" time="0.504" /><testcase classname="tests.integration.api_client_test.UnixconnTest" name="test_resource_warnings" time="2.546" /><testcase classname="tests.integration.api_container_test.ListContainersTest" name="test_list_containers" time="7.493" /><testcase classname="tests.integration.api_container_test.CreateContainerTest" name="test_create" time="7.270" /><testcase classname="tests.integration.api_container_test.CreateContainerTest" name="test_create_container_with_volumes_from" time="8.124" /><testcase classname="tests.integration.api_container_test.CreateContainerTest" name="test_create_with_auto_remove" time="7.284" /><testcase classname="tests.integration.api_container_test.CreateContainerTest" name="test_create_with_cgroupns" time="7.291"><failure message="AssertionError: assert 'private' == ''&#10;  + private">tests/integration/api_container_test.py:230: in test_create_with_cgroupns
    assert 'private' == res['HostConfig']['CgroupnsMode']
E   AssertionError: assert 'private' == ''
E     + private</failure><system-out>--------------------------------- Captured Log ---------------------------------

--------------------------------- Captured Out ---------------------------------

</system-out><system-err>--------------------------------- Captured Err ---------------------------------

</system-err></testcase><testcase classname="tests.integration.api_container_test.CreateContainerTest" name="test_create_with_cpu_rt_options" time="7.306"><skipped type="pytest.xfail" message="CONFIG_RT_GROUP_SCHED isn't enabled" /></testcase><testcase classname="tests.integration.api_container_test.CreateContainerTest" name="test_create_with_device_cgroup_rules" time="7.441"><failure message="AssertionError: assert None == ['c 7:128 rwm']">tests/integration/api_container_test.py:483: in test_create_with_device_cgroup_rules
    assert config['HostConfig']['DeviceCgroupRules'] == [rule]
E   AssertionError: assert None == ['c 7:128 rwm']</failure><system-out>--------------------------------- Captured Log ---------------------------------

--------------------------------- Captured Out ---------------------------------

</system-out><system-err>--------------------------------- Captured Err ---------------------------------

</system-err></testcase><testcase classname="tests.integration.api_container_test.CreateContainerTest" name="test_create_with_environment_variable_no_value" time="7.254"><failure message="AssertionError: assert 'Foo' in ['PATH=/usr/local/sbin:/usr/local/bin:/usr/sbin:/usr/bin:/sbin:/bin', 'TERM=xterm', 'container=podman', 'Other=one', 'Blank=']">tests/integration/api_container_test.py:380: in test_create_with_environment_variable_no_value
    assert 'Foo' in config['Config']['Env']
E   AssertionError: assert 'Foo' in ['PATH=/usr/local/sbin:/usr/local/bin:/usr/sbin:/usr/bin:/sbin:/bin', 'TERM=xterm', 'container=podman', 'Other=one', 'Blank=']</failure><system-out>--------------------------------- Captured Log ---------------------------------

--------------------------------- Captured Out ---------------------------------

</system-out><system-err>--------------------------------- Captured Err ---------------------------------

</system-err></testcase><testcase classname="tests.integration.api_container_test.CreateContainerTest" name="test_create_with_host_pid_mode" time="7.615" /><testcase classname="tests.integration.api_container_test.CreateContainerTest" name="test_create_with_init" time="7.635" /><testcase classname="tests.integration.api_container_test.CreateContainerTest" name="test_create_with_isolation" time="7.368"><failure message="AssertionError: assert '' == 'default'&#10;  - default">tests/integration/api_container_test.py:409: in test_create_with_isolation
    assert config['HostConfig']['Isolation'] == 'default'
E   AssertionError: assert '' == 'default'
E     - default</failure><system-out>--------------------------------- Captured Log ---------------------------------

--------------------------------- Captured Out ---------------------------------

</system-out><system-err>--------------------------------- Captured Err ---------------------------------

</system-err></testcase><testcase classname="tests.integration.api_container_test.CreateContainerTest" name="test_create_with_links" time="8.118"><failure message="docker.errors.APIError: 400 Client Error for http+docker://localhost/v1.41/containers/create: Bad Request (&quot;bad parameter: link is not supported&quot;)">docker/api/client.py:296: in _raise_for_status
    response.raise_for_status()
../../.virtualenvs/docker-py/lib/python3.10/site-packages/requests/models.py:1021: in raise_for_status
    raise HTTPError(http_error_msg, response=self)
E   requests.exceptions.HTTPError: 400 Client Error: Bad Request for url: http+docker://localhost/v1.41/containers/create

The above exception was the direct cause of the following exception:
tests/integration/api_container_test.py:95: in test_create_with_links
    res2 = self.client.create_container(
docker/api/container.py:431: in create_container
    return self.create_container_from_config(config, name, platform)
docker/api/container.py:448: in create_container_from_config
    return self._result(res, True)
docker/api/client.py:302: in _result
    self._raise_for_status(response)
docker/api/client.py:298: in _raise_for_status
    raise create_api_error_from_http_exception(e) from e
docker/errors.py:39: in create_api_error_from_http_exception
    raise cls(e, response=response, explanation=explanation) from e
E   docker.errors.APIError: 400 Client Error for http+docker://localhost/v1.41/containers/create: Bad Request ("bad parameter: link is not supported")</failure><system-out>--------------------------------- Captured Log ---------------------------------

--------------------------------- Captured Out ---------------------------------

</system-out><system-err>--------------------------------- Captured Err ---------------------------------

</system-err></testcase><testcase classname="tests.integration.api_container_test.CreateContainerTest" name="test_create_with_mac_address" time="7.429"><failure message="AssertionError: assert '02:42:ac:11:00:0a' == 'de:b8:8f:c7:d4:e2'&#10;  - de:b8:8f:c7:d4:e2&#10;  + 02:42:ac:11:00:0a">tests/integration/api_container_test.py:214: in test_create_with_mac_address
    assert mac_address_expected == res['NetworkSettings']['MacAddress']
E   AssertionError: assert '02:42:ac:11:00:0a' == 'de:b8:8f:c7:d4:e2'
E     - de:b8:8f:c7:d4:e2
E     + 02:42:ac:11:00:0a</failure><system-out>--------------------------------- Captured Log ---------------------------------

--------------------------------- Captured Out ---------------------------------

</system-out><system-err>--------------------------------- Captured Err ---------------------------------

</system-err></testcase><testcase classname="tests.integration.api_container_test.CreateContainerTest" name="test_create_with_memory_constraints_with_int" time="7.560"><failure message="docker.errors.APIError: 500 Server Error for http+docker://localhost/v1.41/containers/024fd0111f342376899f3beaaba8355631f863dd621728988433dbb252daaecf/start: Internal Server Error (&quot;crun: cannot set memory swappiness with cgroupv2: OCI runtime error&quot;)">docker/api/client.py:296: in _raise_for_status
    response.raise_for_status()
../../.virtualenvs/docker-py/lib/python3.10/site-packages/requests/models.py:1021: in raise_for_status
    raise HTTPError(http_error_msg, response=self)
E   requests.exceptions.HTTPError: 500 Server Error: Internal Server Error for url: http+docker://localhost/v1.41/containers/024fd0111f342376899f3beaaba8355631f863dd621728988433dbb252daaecf/start

The above exception was the direct cause of the following exception:
tests/integration/api_container_test.py:365: in test_create_with_memory_constraints_with_int
    self.client.start(ctnr)
docker/utils/decorators.py:19: in wrapped
    return f(self, resource_id, *args, **kwargs)
docker/api/container.py:1126: in start
    self._raise_for_status(res)
docker/api/client.py:298: in _raise_for_status
    raise create_api_error_from_http_exception(e) from e
docker/errors.py:39: in create_api_error_from_http_exception
    raise cls(e, response=response, explanation=explanation) from e
E   docker.errors.APIError: 500 Server Error for http+docker://localhost/v1.41/containers/024fd0111f342376899f3beaaba8355631f863dd621728988433dbb252daaecf/start: Internal Server Error ("crun: cannot set memory swappiness with cgroupv2: OCI runtime error")</failure><system-out>--------------------------------- Captured Log ---------------------------------

--------------------------------- Captured Out ---------------------------------

</system-out><system-err>--------------------------------- Captured Err ---------------------------------

</system-err></testcase><testcase classname="tests.integration.api_container_test.CreateContainerTest" name="test_create_with_memory_constraints_with_str" time="12.254" /><testcase classname="tests.integration.api_container_test.CreateContainerTest" name="test_create_with_restart_policy" time="37.400"><failure message="AssertionError: assert 'You cannot remove ' in 'cannot remove container a943fb652724aaccedea6d4262ab0dcb6f64f652b8462752cd376fa6c772382b as it is running - running or paused containers cannot be removed without force: container state improper'">tests/integration/api_container_test.py:126: in test_create_with_restart_policy
    assert 'You cannot remove ' in err
E   AssertionError: assert 'You cannot remove ' in 'cannot remove container a943fb652724aaccedea6d4262ab0dcb6f64f652b8462752cd376fa6c772382b as it is running - running or paused containers cannot be removed without force: container state improper'</failure><system-out>--------------------------------- Captured Log ---------------------------------

--------------------------------- Captured Out ---------------------------------

</system-out><system-err>--------------------------------- Captured Err ---------------------------------

</system-err></testcase><testcase classname="tests.integration.api_container_test.CreateContainerTest" name="test_create_with_stop_timeout" time="15.931" /><testcase classname="tests.integration.api_container_test.CreateContainerTest" name="test_create_with_storage_opt" time="14.175"><skipped type="pytest.xfail" message="Not supported on most drivers" /></testcase><testcase classname="tests.integration.api_container_test.CreateContainerTest" name="test_create_with_tmpfs" time="14.227"><failure message="AssertionError: assert {'/tmp1': 'si...ev,tmpcopyup'} == {'/tmp1': 'size=3M'}&#10;  Differing items:&#10;  {'/tmp1': 'size=3M,rw,rprivate,nosuid,nodev,tmpcopyup'} != {'/tmp1': 'size=3M'}&#10;  Full diff:&#10;  - {'/tmp1': 'size=3M'}&#10;  + {'/tmp1': 'size=3M,rw,rprivate,nosuid,nodev,tmpcopyup'}">tests/integration/api_container_test.py:398: in test_create_with_tmpfs
    assert config['HostConfig']['Tmpfs'] == tmpfs
E   AssertionError: assert {'/tmp1': 'si...ev,tmpcopyup'} == {'/tmp1': 'size=3M'}
E     Differing items:
E     {'/tmp1': 'size=3M,rw,rprivate,nosuid,nodev,tmpcopyup'} != {'/tmp1': 'size=3M'}
E     Full diff:
E     - {'/tmp1': 'size=3M'}
E     + {'/tmp1': 'size=3M,rw,rprivate,nosuid,nodev,tmpcopyup'}</failure><system-out>--------------------------------- Captured Log ---------------------------------

--------------------------------- Captured Out ---------------------------------

</system-out><system-err>--------------------------------- Captured Err ---------------------------------

</system-err></testcase><testcase classname="tests.integration.api_container_test.CreateContainerTest" name="test_create_with_uts_mode" time="12.875" /><testcase classname="tests.integration.api_container_test.CreateContainerTest" name="test_group_id_ints" time="14.367" /><testcase classname="tests.integration.api_container_test.CreateContainerTest" name="test_group_id_strings" time="16.991" /><testcase classname="tests.integration.api_container_test.CreateContainerTest" name="test_invalid_log_driver_raises_exception" time="17.828"><failure message="assert 'container create: running container create option: invalid log driver: invalid argument' in [&quot;logger: no log driver named 'asdf' is registered&quot;, 'error looking up logging plugin asdf: plugin &quot;asdf&quot; not found']&#10; +  where 'container create: running container create option: invalid log driver: invalid argument' = APIError(HTTPError('500 Server Error: Internal Server Error for url: http+docker://localhost/v1.41/containers/create')).explanation&#10; +    where APIError(HTTPError('500 Server Error: Internal Server Error for url: http+docker://localhost/v1.41/containers/create')) = &lt;ExceptionInfo APIError(HTTPError('500 Server Error: Internal Server Error for url: http+docker://localhost/v1.41/containers/create')) tblen=6&gt;.value">tests/integration/api_container_test.py:300: in test_invalid_log_driver_raises_exception
    assert excinfo.value.explanation in expected_msgs
E   assert 'container create: running container create option: invalid log driver: invalid argument' in ["logger: no log driver named 'asdf' is registered", 'error looking up logging plugin asdf: plugin "asdf" not found']
E    +  where 'container create: running container create option: invalid log driver: invalid argument' = APIError(HTTPError('500 Server Error: Internal Server Error for url: http+docker://localhost/v1.41/containers/create')).explanation
E    +    where APIError(HTTPError('500 Server Error: Internal Server Error for url: http+docker://localhost/v1.41/containers/create')) = &lt;ExceptionInfo APIError(HTTPError('500 Server Error: Internal Server Error for url: http+docker://localhost/v1.41/containers/create')) tblen=6&gt;.value</failure><system-out>--------------------------------- Captured Log ---------------------------------

--------------------------------- Captured Out ---------------------------------

</system-out><system-err>--------------------------------- Captured Err ---------------------------------

</system-err></testcase><testcase classname="tests.integration.api_container_test.CreateContainerTest" name="test_valid_log_driver_and_log_opt" time="13.372"><failure message="AssertionError: assert None == {'max-file': '100'}&#10; +  where {'max-file': '100'} = {'Type': 'json-file', 'Config': {'max-file': '100'}}.config">tests/integration/api_container_test.py:279: in test_valid_log_driver_and_log_opt
    assert container_log_config['Config'] == log_config.config
E   AssertionError: assert None == {'max-file': '100'}
E    +  where {'max-file': '100'} = {'Type': 'json-file', 'Config': {'max-file': '100'}}.config</failure><system-out>--------------------------------- Captured Log ---------------------------------

--------------------------------- Captured Out ---------------------------------

</system-out><system-err>--------------------------------- Captured Err ---------------------------------

</system-err></testcase><testcase classname="tests.integration.api_container_test.CreateContainerTest" name="test_valid_no_config_specified" time="16.546"><failure message="assert None == {}">tests/integration/api_container_test.py:338: in test_valid_no_config_specified
    assert container_log_config['Config'] == {}
E   assert None == {}</failure><system-out>--------------------------------- Captured Log ---------------------------------

--------------------------------- Captured Out ---------------------------------

</system-out><system-err>--------------------------------- Captured Err ---------------------------------

</system-err></testcase><testcase classname="tests.integration.api_container_test.CreateContainerTest" name="test_valid_no_log_driver_specified" time="15.167"><failure message="AssertionError: assert 'journald' == 'json-file'&#10;  - json-file&#10;  + journald">tests/integration/api_container_test.py:318: in test_valid_no_log_driver_specified
    assert container_log_config['Type'] == "json-file"
E   AssertionError: assert 'journald' == 'json-file'
E     - json-file
E     + journald</failure><system-out>--------------------------------- Captured Log ---------------------------------

--------------------------------- Captured Out ---------------------------------

</system-out><system-err>--------------------------------- Captured Err ---------------------------------

</system-err></testcase><testcase classname="tests.integration.api_container_test.VolumeBindTest" name="test_create_with_binds_ro" time="18.922" /><testcase classname="tests.integration.api_container_test.VolumeBindTest" name="test_create_with_binds_rw" time="17.145" /><testcase classname="tests.integration.api_container_test.VolumeBindTest" name="test_create_with_mounts" time="12.910" /><testcase classname="tests.integration.api_container_test.VolumeBindTest" name="test_create_with_mounts_ro" time="8.772" /><testcase classname="tests.integration.api_container_test.VolumeBindTest" name="test_create_with_volume_mount" time="7.653" /><testcase classname="tests.integration.api_container_test.ArchiveTest" name="test_copy_directory_to_container" time="8.122" /><testcase classname="tests.integration.api_container_test.ArchiveTest" name="test_copy_file_to_container" time="8.017" /><testcase classname="tests.integration.api_container_test.ArchiveTest" name="test_get_file_archive_from_container" time="8.265" /><testcase classname="tests.integration.api_container_test.ArchiveTest" name="test_get_file_stat_from_container" time="8.215" /><testcase classname="tests.integration.api_container_test.RenameContainerTest" name="test_rename_container" time="9.822" /><testcase classname="tests.integration.api_container_test.StartContainerTest" name="test_run_shlex_commands" time="11.909" /><testcase classname="tests.integration.api_container_test.StartContainerTest" name="test_start_container" time="7.566" /><testcase classname="tests.integration.api_container_test.StartContainerTest" name="test_start_container_with_dict_instead_of_id" time="8.110" /><testcase classname="tests.integration.api_container_test.WaitTest" name="test_wait" time="11.743" /><testcase classname="tests.integration.api_container_test.WaitTest" name="test_wait_with_condition" time="12.291" /><testcase classname="tests.integration.api_container_test.WaitTest" name="test_wait_with_dict_instead_of_id" time="11.113" /><testcase classname="tests.integration.api_container_test.LogsTest" name="test_logs" time="7.832" /><testcase classname="tests.integration.api_container_test.LogsTest" name="test_logs_streaming_and_follow" time="7.953" /><testcase classname="tests.integration.api_container_test.LogsTest" name="test_logs_streaming_and_follow_and_cancel" time="7.889"><failure message="Failed: Timeout &gt;5.0s">tests/integration/api_container_test.py:872: in test_logs_streaming_and_follow_and_cancel
    self.client.start(id)
docker/utils/decorators.py:19: in wrapped
    return f(self, resource_id, *args, **kwargs)
docker/api/container.py:1125: in start
    res = self._post(url)
docker/utils/decorators.py:46: in inner
    return f(self, *args, **kwargs)
docker/api/client.py:240: in _post
    return self.post(url, **self._set_request_timeout(kwargs))
../../.virtualenvs/docker-py/lib/python3.10/site-packages/requests/sessions.py:635: in post
    return self.request("POST", url, data=data, json=json, **kwargs)
../../.virtualenvs/docker-py/lib/python3.10/site-packages/requests/sessions.py:587: in request
    resp = self.send(prep, **send_kwargs)
../../.virtualenvs/docker-py/lib/python3.10/site-packages/requests/sessions.py:701: in send
    r = adapter.send(request, **kwargs)
../../.virtualenvs/docker-py/lib/python3.10/site-packages/requests/adapters.py:489: in send
    resp = conn.urlopen(
../../.virtualenvs/docker-py/lib/python3.10/site-packages/urllib3/connectionpool.py:703: in urlopen
    httplib_response = self._make_request(
../../.virtualenvs/docker-py/lib/python3.10/site-packages/urllib3/connectionpool.py:449: in _make_request
    six.raise_from(e, None)
&lt;string&gt;:3: in raise_from
    ???
../../.virtualenvs/docker-py/lib/python3.10/site-packages/urllib3/connectionpool.py:444: in _make_request
    httplib_response = conn.getresponse()
/usr/lib/python3.10/http/client.py:1374: in getresponse
    response.begin()
/usr/lib/python3.10/http/client.py:318: in begin
    version, status, reason = self._read_status()
/usr/lib/python3.10/http/client.py:279: in _read_status
    line = str(self.fp.readline(_MAXLINE + 1), "iso-8859-1")
/usr/lib/python3.10/socket.py:705: in readinto
    return self._sock.recv_into(b)
E   Failed: Timeout &gt;5.0s</failure><system-out>--------------------------------- Captured Log ---------------------------------

--------------------------------- Captured Out ---------------------------------

</system-out><system-err>--------------------------------- Captured Err ---------------------------------

</system-err></testcase><testcase classname="tests.integration.api_container_test.LogsTest" name="test_logs_tail_option" time="8.637" /><testcase classname="tests.integration.api_container_test.LogsTest" name="test_logs_with_dict_instead_of_id" time="8.243" /><testcase classname="tests.integration.api_container_test.LogsTest" name="test_logs_with_tail_0" time="8.472" /><testcase classname="tests.integration.api_container_test.LogsTest" name="test_logs_with_until" time="9.328" /><testcase classname="tests.integration.api_container_test.DiffTest" name="test_diff" time="8.859" /><testcase classname="tests.integration.api_container_test.DiffTest" name="test_diff_with_dict_instead_of_id" time="8.782" /><testcase classname="tests.integration.api_container_test.StopTest" name="test_stop" time="10.542" /><testcase classname="tests.integration.api_container_test.StopTest" name="test_stop_with_dict_instead_of_id" time="10.458" /><testcase classname="tests.integration.api_container_test.KillTest" name="test_kill" time="7.843" /><testcase classname="tests.integration.api_container_test.KillTest" name="test_kill_with_dict_instead_of_id" time="8.033" /><testcase classname="tests.integration.api_container_test.KillTest" name="test_kill_with_signal" time="7.992" /><testcase classname="tests.integration.api_container_test.KillTest" name="test_kill_with_signal_integer" time="7.882" /><testcase classname="tests.integration.api_container_test.KillTest" name="test_kill_with_signal_name" time="7.836" /><testcase classname="tests.integration.api_container_test.PortTest" name="test_port" time="8.012" /><testcase classname="tests.integration.api_container_test.ContainerTopTest" name="test_top" time="8.012"><skipped type="pytest.xfail" message="Output of docker top depends on host distro, and is not formalized." /></testcase><testcase classname="tests.integration.api_container_test.ContainerTopTest" name="test_top_with_psargs" time="7.945"><skipped type="pytest.xfail" message="Output of docker top depends on host distro, and is not formalized." /></testcase><testcase classname="tests.integration.api_container_test.RestartContainerTest" name="test_restart" time="10.624" /><testcase classname="tests.integration.api_container_test.RestartContainerTest" name="test_restart_with_dict_instead_of_id" time="10.439" /><testcase classname="tests.integration.api_container_test.RestartContainerTest" name="test_restart_with_low_timeout" time="11.173" /><testcase classname="tests.integration.api_container_test.RemoveContainerTest" name="test_remove" time="8.493" /><testcase classname="tests.integration.api_container_test.RemoveContainerTest" name="test_remove_with_dict_instead_of_id" time="7.881" /><testcase classname="tests.integration.api_container_test.AttachContainerTest" name="test_attach_no_stream" time="9.094"><failure message="AssertionError: assert b'hello' == b'hello\n'&#10;  Full diff:&#10;  - b'hello\n'&#10;  ?        --&#10;  + b'hello'">tests/integration/api_container_test.py:1262: in test_attach_no_stream
    assert output == 'hello\n'.encode(encoding='ascii')
E   AssertionError: assert b'hello' == b'hello\n'
E     Full diff:
E     - b'hello\n'
E     ?        --
E     + b'hello'</failure><system-out>--------------------------------- Captured Log ---------------------------------

--------------------------------- Captured Out ---------------------------------

</system-out><system-err>--------------------------------- Captured Err ---------------------------------

</system-err></testcase><testcase classname="tests.integration.api_container_test.AttachContainerTest" name="test_attach_stream_and_cancel" time="10.001"><failure message="Failed: Timeout &gt;10.0s">tests/integration/base.py:83: in tearDown
    super().tearDown()
tests/integration/base.py:30: in tearDown
    client = docker.from_env(version=TEST_API_VERSION)
docker/client.py:96: in from_env
    return cls(
docker/client.py:45: in __init__
    self.api = APIClient(*args, **kwargs)
docker/api/client.py:197: in __init__
    self._version = self._retrieve_server_version()
docker/api/client.py:214: in _retrieve_server_version
    return self.version(api_version=False)["ApiVersion"]
docker/api/daemon.py:181: in version
    return self._result(self._get(url), json=True)
docker/utils/decorators.py:46: in inner
    return f(self, *args, **kwargs)
docker/api/client.py:251: in _get
    return self.get(url, **self._set_request_timeout(kwargs))
../../.virtualenvs/docker-py/lib/python3.10/site-packages/requests/sessions.py:600: in get
    return self.request("GET", url, **kwargs)
../../.virtualenvs/docker-py/lib/python3.10/site-packages/requests/sessions.py:587: in request
    resp = self.send(prep, **send_kwargs)
../../.virtualenvs/docker-py/lib/python3.10/site-packages/requests/sessions.py:701: in send
    r = adapter.send(request, **kwargs)
../../.virtualenvs/docker-py/lib/python3.10/site-packages/requests/adapters.py:489: in send
    resp = conn.urlopen(
../../.virtualenvs/docker-py/lib/python3.10/site-packages/urllib3/connectionpool.py:703: in urlopen
    httplib_response = self._make_request(
../../.virtualenvs/docker-py/lib/python3.10/site-packages/urllib3/connectionpool.py:449: in _make_request
    six.raise_from(e, None)
../../.virtualenvs/docker-py/lib/python3.10/site-packages/urllib3/connectionpool.py:444: in _make_request
    httplib_response = conn.getresponse()
/usr/lib/python3.10/http/client.py:1374: in getresponse
    response.begin()
/usr/lib/python3.10/http/client.py:318: in begin
    version, status, reason = self._read_status()
/usr/lib/python3.10/http/client.py:279: in _read_status
    line = str(self.fp.readline(_MAXLINE + 1), "iso-8859-1")
/usr/lib/python3.10/socket.py:705: in readinto
    return self._sock.recv_into(b)
E   Failed: Timeout &gt;10.0s</failure><system-out>--------------------------------- Captured Log ---------------------------------

--------------------------------- Captured Out ---------------------------------

</system-out><system-err>--------------------------------- Captured Err ---------------------------------

</system-err></testcase><testcase classname="tests.integration.api_container_test.AttachContainerTest" name="test_detach_with_arg" time="8.209" /><testcase classname="tests.integration.api_container_test.AttachContainerTest" name="test_detach_with_config_file" time="8.139" /><testcase classname="tests.integration.api_container_test.AttachContainerTest" name="test_detach_with_default" time="9.154" /><testcase classname="tests.integration.api_container_test.AttachContainerTest" name="test_run_container_reading_socket_http" time="7.984" /><testcase classname="tests.integration.api_container_test.AttachContainerTest" name="test_run_container_reading_socket_ws" time="7.493"><failure message="ValueError: scheme http+docker is invalid">tests/integration/api_container_test.py:1245: in test_run_container_reading_socket_ws
    pty_stdout = self.client.attach_socket(container, opts, ws=True)
docker/utils/decorators.py:19: in wrapped
    return f(self, resource_id, *args, **kwargs)
docker/api/container.py:98: in attach_socket
    return self._attach_websocket(container, params)
docker/utils/decorators.py:19: in wrapped
    return f(self, resource_id, *args, **kwargs)
docker/api/client.py:340: in _attach_websocket
    return self._create_websocket_connection(full_url)
docker/api/client.py:343: in _create_websocket_connection
    return websocket.create_connection(url)
../../.virtualenvs/docker-py/lib/python3.10/site-packages/websocket/_core.py:601: in create_connection
    websock.connect(url, **options)
../../.virtualenvs/docker-py/lib/python3.10/site-packages/websocket/_core.py:244: in connect
    self.sock, addrs = connect(url, self.sock_opt, proxy_info(**options),
../../.virtualenvs/docker-py/lib/python3.10/site-packages/websocket/_http.py:117: in connect
    hostname, port, resource, is_secure = parse_url(url)
../../.virtualenvs/docker-py/lib/python3.10/site-packages/websocket/_url.py:62: in parse_url
    raise ValueError("scheme %s is invalid" % scheme)
E   ValueError: scheme http+docker is invalid</failure><system-out>--------------------------------- Captured Log ---------------------------------

--------------------------------- Captured Out ---------------------------------

</system-out><system-err>--------------------------------- Captured Err ---------------------------------

</system-err></testcase><testcase classname="tests.integration.api_container_test.AttachContainerTest" name="test_run_container_streaming" time="7.788" /><testcase classname="tests.integration.api_container_test.PauseTest" name="test_pause_unpause" time="7.825" /><testcase classname="tests.integration.api_container_test.PruneTest" name="test_prune_containers" time="7.986" /><testcase classname="tests.integration.api_container_test.GetContainerStatsTest" name="test_get_container_stats_no_stream" time="7.885" /><testcase classname="tests.integration.api_container_test.ContainerUpdateTest" name="test_restart_policy_update" time="7.820"><failure message="TypeError: a bytes-like object is required, not 'str'">docker/api/client.py:296: in _raise_for_status
    response.raise_for_status()
../../.virtualenvs/docker-py/lib/python3.10/site-packages/requests/models.py:1021: in raise_for_status
    raise HTTPError(http_error_msg, response=self)
E   requests.exceptions.HTTPError: 404 Client Error: Not Found for url: http+docker://localhost/v1.41/containers/1f3448e19c9f12275533ff476a2d60cb1e61309e3b7c90d7a7bd47f6cb2a01ec/update

During handling of the above exception, another exception occurred:
tests/integration/api_container_test.py:1448: in test_restart_policy_update
    self.client.update_container(container,
docker/utils/decorators.py:34: in wrapper
    return f(self, *args, **kwargs)
docker/utils/decorators.py:19: in wrapped
    return f(self, resource_id, *args, **kwargs)
docker/api/container.py:1285: in update_container
    return self._result(res, True)
docker/api/client.py:302: in _result
    self._raise_for_status(response)
docker/api/client.py:298: in _raise_for_status
    raise create_api_error_from_http_exception(e) from e
docker/errors.py:34: in create_api_error_from_http_exception
    if any(fragment in explanation_msg
docker/errors.py:34: in &lt;genexpr&gt;
    if any(fragment in explanation_msg
E   TypeError: a bytes-like object is required, not 'str'</failure><system-out>--------------------------------- Captured Log ---------------------------------

--------------------------------- Captured Out ---------------------------------

</system-out><system-err>--------------------------------- Captured Err ---------------------------------

</system-err></testcase><testcase classname="tests.integration.api_container_test.ContainerUpdateTest" name="test_update_container" time="8.036"><failure message="TypeError: a bytes-like object is required, not 'str'">docker/api/client.py:296: in _raise_for_status
    response.raise_for_status()
../../.virtualenvs/docker-py/lib/python3.10/site-packages/requests/models.py:1021: in raise_for_status
    raise HTTPError(http_error_msg, response=self)
E   requests.exceptions.HTTPError: 404 Client Error: Not Found for url: http+docker://localhost/v1.41/containers/6d0bb899b6df547928432e6e80f4aaea7740cefb05a888632235868934d9d324/update

During handling of the above exception, another exception occurred:
tests/integration/api_container_test.py:1426: in test_update_container
    self.client.update_container(container, mem_limit=new_mem_limit)
docker/utils/decorators.py:34: in wrapper
    return f(self, *args, **kwargs)
docker/utils/decorators.py:19: in wrapped
    return f(self, resource_id, *args, **kwargs)
docker/api/container.py:1285: in update_container
    return self._result(res, True)
docker/api/client.py:302: in _result
    self._raise_for_status(response)
docker/api/client.py:298: in _raise_for_status
    raise create_api_error_from_http_exception(e) from e
docker/errors.py:34: in create_api_error_from_http_exception
    if any(fragment in explanation_msg
docker/errors.py:34: in &lt;genexpr&gt;
    if any(fragment in explanation_msg
E   TypeError: a bytes-like object is required, not 'str'</failure><system-out>--------------------------------- Captured Log ---------------------------------

--------------------------------- Captured Out ---------------------------------

</system-out><system-err>--------------------------------- Captured Err ---------------------------------

</system-err></testcase><testcase classname="tests.integration.api_container_test.ContainerCPUTest" name="test_container_cpu_shares" time="8.141" /><testcase classname="tests.integration.api_container_test.ContainerCPUTest" name="test_container_cpuset" time="8.069" /><testcase classname="tests.integration.api_container_test.ContainerCPUTest" name="test_create_with_runtime" time="7.552"><failure message="AssertionError: assert 'oci' == 'runc'&#10;  - runc&#10;  + oci">tests/integration/api_container_test.py:1493: in test_create_with_runtime
    assert config['HostConfig']['Runtime'] == 'runc'
E   AssertionError: assert 'oci' == 'runc'
E     - runc
E     + oci</failure><system-out>--------------------------------- Captured Log ---------------------------------

--------------------------------- Captured Out ---------------------------------

</system-out><system-err>--------------------------------- Captured Err ---------------------------------

</system-err></testcase><testcase classname="tests.integration.api_exec_test.ExecTest" name="test_detach_with_config_file" time="13.157"><failure message="AssertionError">tests/integration/api_exec_test.py:227: in test_detach_with_config_file
    assert_cat_socket_detached_with_keys(sock, [ctrl_with('p')])
tests/helpers.py:137: in assert_cat_socket_detached_with_keys
    assert data == b'' or data.startswith(
E   AssertionError</failure><system-out>--------------------------------- Captured Log ---------------------------------

--------------------------------- Captured Out ---------------------------------

</system-out><system-err>--------------------------------- Captured Err ---------------------------------

</system-err></testcase><testcase classname="tests.integration.api_exec_test.ExecTest" name="test_detach_with_default" time="14.184"><failure message="AssertionError">tests/integration/api_exec_test.py:208: in test_detach_with_default
    assert_cat_socket_detached_with_keys(
tests/helpers.py:137: in assert_cat_socket_detached_with_keys
    assert data == b'' or data.startswith(
E   AssertionError</failure><system-out>--------------------------------- Captured Log ---------------------------------

--------------------------------- Captured Out ---------------------------------

</system-out><system-err>--------------------------------- Captured Err ---------------------------------

</system-err></testcase><testcase classname="tests.integration.api_exec_test.ExecTest" name="test_exec_command_as_root" time="7.755" /><testcase classname="tests.integration.api_exec_test.ExecTest" name="test_exec_command_as_user" time="7.716" /><testcase classname="tests.integration.api_exec_test.ExecTest" name="test_exec_command_streaming" time="7.788" /><testcase classname="tests.integration.api_exec_test.ExecTest" name="test_exec_command_string" time="7.762" /><testcase classname="tests.integration.api_exec_test.ExecTest" name="test_exec_command_with_env" time="7.795" /><testcase classname="tests.integration.api_exec_test.ExecTest" name="test_exec_command_with_workdir" time="7.566" /><testcase classname="tests.integration.api_exec_test.ExecTest" name="test_exec_inspect" time="7.575" /><testcase classname="tests.integration.api_exec_test.ExecTest" name="test_exec_start_detached" time="7.550"><failure message="AssertionError: assert '\n' == ''&#10;  Strings contain only whitespace, escaping them using repr()&#10;  - ''&#10;  + '\n'">tests/integration/api_exec_test.py:152: in test_exec_start_detached
    assert response == ""
E   AssertionError: assert '\n' == ''
E     Strings contain only whitespace, escaping them using repr()
E     - ''
E     + '\n'</failure><system-out>--------------------------------- Captured Log ---------------------------------

--------------------------------- Captured Out ---------------------------------

</system-out><system-err>--------------------------------- Captured Err ---------------------------------

</system-err></testcase><testcase classname="tests.integration.api_exec_test.ExecTest" name="test_exec_start_socket" time="7.732"><failure message="assert 121 == 1">tests/integration/api_exec_test.py:134: in test_exec_start_socket
    assert stream == 1  # stdout (0 = stdin, 1 = stdout, 2 = stderr)
E   assert 121 == 1</failure><system-out>--------------------------------- Captured Log ---------------------------------

--------------------------------- Captured Out ---------------------------------

</system-out><system-err>--------------------------------- Captured Err ---------------------------------

</system-err></testcase><testcase classname="tests.integration.api_exec_test.ExecTest" name="test_execute_command" time="7.674" /><testcase classname="tests.integration.api_exec_test.ExecTest" name="test_execute_command_with_proxy_env" time="7.845" /><testcase classname="tests.integration.api_exec_test.ExecDemuxTest" name="test_exec_command_no_stream_demux" time="8.153" /><testcase classname="tests.integration.api_exec_test.ExecDemuxTest" name="test_exec_command_no_stream_no_demux" time="8.954" /><testcase classname="tests.integration.api_exec_test.ExecDemuxTest" name="test_exec_command_stream_demux" time="8.077" /><testcase classname="tests.integration.api_exec_test.ExecDemuxTest" name="test_exec_command_stream_no_demux" time="8.004" /><testcase classname="tests.integration.api_exec_test.ExecDemuxTest" name="test_exec_command_tty_no_stream_demux" time="7.472"><failure message="ValueError: 104 is not a valid stream">tests/integration/api_exec_test.py:299: in test_exec_command_tty_no_stream_demux
    exec_log = self.client.exec_start(res, demux=True)
docker/utils/decorators.py:19: in wrapped
    return f(self, resource_id, *args, **kwargs)
docker/api/exec_api.py:173: in exec_start
    output = self._read_from_socket(res, stream, tty=tty, demux=demux)
docker/api/client.py:457: in _read_from_socket
    return consume_socket_output(gen, demux=demux)
docker/utils/socket.py:154: in consume_socket_output
    for frame in frames:
docker/api/client.py:447: in &lt;genexpr&gt;
    gen = (demux_adaptor(*frame) for frame in gen)
docker/utils/socket.py:181: in demux_adaptor
    raise ValueError(f'{stream_id} is not a valid stream')
E   ValueError: 104 is not a valid stream</failure><system-out>--------------------------------- Captured Log ---------------------------------

--------------------------------- Captured Out ---------------------------------

</system-out><system-err>--------------------------------- Captured Err ---------------------------------

</system-err></testcase><testcase classname="tests.integration.api_exec_test.ExecDemuxTest" name="test_exec_command_tty_no_stream_no_demux" time="8.013"><failure message="AssertionError: assert b't\r\nhello err\r\n' == b'hello out\r\nhello err\r\n'&#10;  At index 0 diff: b't' != b'h'&#10;  Full diff:&#10;  - b'hello out\r\nhello err\r\n'&#10;  ?   --------&#10;  + b't\r\nhello err\r\n'">tests/integration/api_exec_test.py:282: in test_exec_command_tty_no_stream_no_demux
    assert exec_log == b'hello out\r\nhello err\r\n'
E   AssertionError: assert b't\r\nhello err\r\n' == b'hello out\r\nhello err\r\n'
E     At index 0 diff: b't' != b'h'
E     Full diff:
E     - b'hello out\r\nhello err\r\n'
E     ?   --------
E     + b't\r\nhello err\r\n'</failure><system-out>--------------------------------- Captured Log ---------------------------------

--------------------------------- Captured Out ---------------------------------

</system-out><system-err>--------------------------------- Captured Err ---------------------------------

</system-err></testcase><testcase classname="tests.integration.api_exec_test.ExecDemuxTest" name="test_exec_command_tty_stream_demux" time="7.469"><failure message="ValueError: 104 is not a valid stream">tests/integration/api_exec_test.py:305: in test_exec_command_tty_stream_demux
    exec_log = list(self.client.exec_start(res, demux=True, stream=True))
docker/types/daemon.py:32: in __next__
    return next(self._stream)
docker/api/client.py:447: in &lt;genexpr&gt;
    gen = (demux_adaptor(*frame) for frame in gen)
docker/utils/socket.py:181: in demux_adaptor
    raise ValueError(f'{stream_id} is not a valid stream')
E   ValueError: 104 is not a valid stream</failure><system-out>--------------------------------- Captured Log ---------------------------------

--------------------------------- Captured Out ---------------------------------

</system-out><system-err>--------------------------------- Captured Err ---------------------------------

</system-err></testcase><testcase classname="tests.integration.api_exec_test.ExecDemuxTest" name="test_exec_command_tty_stream_no_demux" time="8.124"><failure message="AssertionError: assert b'hello out\r\n' in [b't\r\n', b'hello err\r\n']">tests/integration/api_exec_test.py:288: in test_exec_command_tty_stream_no_demux
    assert b'hello out\r\n' in exec_log
E   AssertionError: assert b'hello out\r\n' in [b't\r\n', b'hello err\r\n']</failure><system-out>--------------------------------- Captured Log ---------------------------------

--------------------------------- Captured Out ---------------------------------

</system-out><system-err>--------------------------------- Captured Err ---------------------------------

</system-err></testcase><testcase classname="tests.integration.api_healthcheck_test.HealthcheckTest" name="test_healthcheck_fails" time="7.807" /><testcase classname="tests.integration.api_healthcheck_test.HealthcheckTest" name="test_healthcheck_passes" time="7.765" /><testcase classname="tests.integration.api_healthcheck_test.HealthcheckTest" name="test_healthcheck_shell_command" time="7.998" /><testcase classname="tests.integration.api_healthcheck_test.HealthcheckTest" name="test_healthcheck_start_period" time="10.925" /><testcase classname="tests.integration.api_image_test.ListImagesTest" name="test_images" time="8.690" /><testcase classname="tests.integration.api_image_test.ListImagesTest" name="test_images_quiet" time="7.027" /><testcase classname="tests.integration.api_image_test.PullImageTest" name="test_pull" time="9.584" /><testcase classname="tests.integration.api_image_test.PullImageTest" name="test_pull_invalid_platform" time="14.916"><failure message="Failed: DID NOT RAISE &lt;class 'docker.errors.APIError'&gt;">tests/integration/api_image_test.py:68: in test_pull_invalid_platform
    with pytest.raises(docker.errors.APIError) as excinfo:
E   Failed: DID NOT RAISE &lt;class 'docker.errors.APIError'&gt;</failure><system-out>--------------------------------- Captured Log ---------------------------------

--------------------------------- Captured Out ---------------------------------

</system-out><system-err>--------------------------------- Captured Err ---------------------------------

</system-err></testcase><testcase classname="tests.integration.api_image_test.PullImageTest" name="test_pull_streaming" time="9.391" /><testcase classname="tests.integration.api_image_test.CommitTest" name="test_commit" time="8.222"><failure message="AssertionError: assert False&#10; +  where False = &lt;built-in method startswith of str object at 0x7f694873c030&gt;('6a21259e3d34a50aed190b46a3996629dd07a3172fbe2b10ce4a2b20213e76c3')&#10; +    where &lt;built-in method startswith of str object at 0x7f694873c030&gt; = ''.startswith">tests/integration/api_image_test.py:89: in test_commit
    assert img['Container'].startswith(id)
E   AssertionError: assert False
E    +  where False = &lt;built-in method startswith of str object at 0x7f694873c030&gt;('6a21259e3d34a50aed190b46a3996629dd07a3172fbe2b10ce4a2b20213e76c3')
E    +    where &lt;built-in method startswith of str object at 0x7f694873c030&gt; = ''.startswith</failure><system-out>--------------------------------- Captured Log ---------------------------------

--------------------------------- Captured Out ---------------------------------

</system-out><system-err>--------------------------------- Captured Err ---------------------------------

</system-err></testcase><testcase classname="tests.integration.api_image_test.CommitTest" name="test_commit_with_changes" time="8.024"><failure message="AssertionError: assert False&#10; +  where False = &lt;built-in method startswith of str object at 0x7f694873c030&gt;('58fde1e7cf25776d34565a26f717ff31d7d25b5fe12526d73d2b08889efbbcbd')&#10; +    where &lt;built-in method startswith of str object at 0x7f694873c030&gt; = ''.startswith">tests/integration/api_image_test.py:107: in test_commit_with_changes
    assert img['Container'].startswith(cid['Id'])
E   AssertionError: assert False
E    +  where False = &lt;built-in method startswith of str object at 0x7f694873c030&gt;('58fde1e7cf25776d34565a26f717ff31d7d25b5fe12526d73d2b08889efbbcbd')
E    +    where &lt;built-in method startswith of str object at 0x7f694873c030&gt; = ''.startswith</failure><system-out>--------------------------------- Captured Log ---------------------------------

--------------------------------- Captured Out ---------------------------------

</system-out><system-err>--------------------------------- Captured Err ---------------------------------

</system-err></testcase><testcase classname="tests.integration.api_image_test.RemoveImageTest" name="test_remove" time="8.050" /><testcase classname="tests.integration.api_image_test.ImportImageTest" name="test_get_load_image" time="9.423"><failure message="assert False&#10; +  where False = any([])">tests/integration/api_image_test.py:266: in test_get_load_image
    assert any([
E   assert False
E    +  where False = any([])</failure><system-out>--------------------------------- Captured Log ---------------------------------

--------------------------------- Captured Out ---------------------------------

</system-out><system-err>--------------------------------- Captured Err ---------------------------------

</system-err></testcase><testcase classname="tests.integration.api_image_test.ImportImageTest" name="test_import_from_bytes" time="7.137" /><testcase classname="tests.integration.api_image_test.ImportImageTest" name="test_import_from_file" time="7.145" /><testcase classname="tests.integration.api_image_test.ImportImageTest" name="test_import_from_stream" time="7.153" /><testcase classname="tests.integration.api_image_test.ImportImageTest" name="test_import_from_url" time="0.000"><skipped type="pytest.skip" message="Doesn't work inside a container - FIXME">/home/riyad/src/docker-py/tests/integration/api_image_test.py:291: Doesn't work inside a container - FIXME</skipped><system-out>--------------------------------- Captured Log ---------------------------------

--------------------------------- Captured Out ---------------------------------

</system-out><system-err>--------------------------------- Captured Err ---------------------------------

</system-err></testcase><testcase classname="tests.integration.api_image_test.ImportImageTest" name="test_import_image_from_data_with_changes" time="7.143" /><testcase classname="tests.integration.api_image_test.ImportImageTest" name="test_import_image_with_changes" time="7.163" /><testcase classname="tests.integration.api_image_test.PruneImagesTest" name="test_prune_images" time="9.945"><failure message="docker.errors.APIError: 500 Server Error for http+docker://localhost/v1.41/images/prune?filters=%7B%22dangling%22%3A+%5B%22false%22%5D%7D: Internal Server Error (&quot;specifying &quot;dangling&quot; filter more than once with different values is not supported&quot;)">docker/api/client.py:296: in _raise_for_status
    response.raise_for_status()
../../.virtualenvs/docker-py/lib/python3.10/site-packages/requests/models.py:1021: in raise_for_status
    raise HTTPError(http_error_msg, response=self)
E   requests.exceptions.HTTPError: 500 Server Error: Internal Server Error for url: http+docker://localhost/v1.41/images/prune?filters=%7B%22dangling%22%3A+%5B%22false%22%5D%7D

The above exception was the direct cause of the following exception:
tests/integration/api_image_test.py:331: in test_prune_images
    result = self.client.prune_images({'dangling': False})
docker/utils/decorators.py:34: in wrapper
    return f(self, *args, **kwargs)
docker/api/image.py:349: in prune_images
    return self._result(self._post(url, params=params), True)
docker/api/client.py:302: in _result
    self._raise_for_status(response)
docker/api/client.py:298: in _raise_for_status
    raise create_api_error_from_http_exception(e) from e
docker/errors.py:39: in create_api_error_from_http_exception
    raise cls(e, response=response, explanation=explanation) from e
E   docker.errors.APIError: 500 Server Error for http+docker://localhost/v1.41/images/prune?filters=%7B%22dangling%22%3A+%5B%22false%22%5D%7D: Internal Server Error ("specifying "dangling" filter more than once with different values is not supported")</failure><system-out>--------------------------------- Captured Log ---------------------------------

--------------------------------- Captured Out ---------------------------------

</system-out><system-err>--------------------------------- Captured Err ---------------------------------

</system-err></testcase><testcase classname="tests.integration.api_image_test.SaveLoadImagesTest" name="test_get_image_load_image" time="7.534"><failure message="assert False is True">tests/integration/api_image_test.py:360: in test_get_image_load_image
    assert success is True
E   assert False is True</failure><system-out>--------------------------------- Captured Log ---------------------------------

--------------------------------- Captured Out ---------------------------------
{'stream': 'Loaded image: docker.io/library/alpine:3.10'}

</system-out><system-err>--------------------------------- Captured Err ---------------------------------

</system-err></testcase><testcase classname="tests.integration.api_image_test.InspectDistributionTest" name="test_inspect_distribution" time="7.034"><failure message="docker.errors.NotFound: 404 Client Error for http+docker://localhost/v1.41/distribution/busybox:latest/json: Not Found (&quot;Path /v1.41/distribution/busybox:latest/json is not supported&quot;)">docker/api/client.py:296: in _raise_for_status
    response.raise_for_status()
../../.virtualenvs/docker-py/lib/python3.10/site-packages/requests/models.py:1021: in raise_for_status
    raise HTTPError(http_error_msg, response=self)
E   requests.exceptions.HTTPError: 404 Client Error: Not Found for url: http+docker://localhost/v1.41/distribution/busybox:latest/json

The above exception was the direct cause of the following exception:
tests/integration/api_image_test.py:366: in test_inspect_distribution
    data = self.client.inspect_distribution('busybox:latest')
docker/utils/decorators.py:34: in wrapper
    return f(self, *args, **kwargs)
docker/utils/decorators.py:19: in wrapped
    return f(self, resource_id, *args, **kwargs)
docker/api/image.py:287: in inspect_distribution
    return self._result(
docker/api/client.py:302: in _result
    self._raise_for_status(response)
docker/api/client.py:298: in _raise_for_status
    raise create_api_error_from_http_exception(e) from e
docker/errors.py:39: in create_api_error_from_http_exception
    raise cls(e, response=response, explanation=explanation) from e
E   docker.errors.NotFound: 404 Client Error for http+docker://localhost/v1.41/distribution/busybox:latest/json: Not Found ("Path /v1.41/distribution/busybox:latest/json is not supported")</failure><system-out>--------------------------------- Captured Log ---------------------------------

--------------------------------- Captured Out ---------------------------------

</system-out><system-err>--------------------------------- Captured Err ---------------------------------

</system-err></testcase><testcase classname="tests.integration.api_network_test.TestNetworks" name="test_connect_and_disconnect_container" time="7.749" /><testcase classname="tests.integration.api_network_test.TestNetworks" name="test_connect_and_force_disconnect_container" time="8.011" /><testcase classname="tests.integration.api_network_test.TestNetworks" name="test_connect_on_container_create" time="7.584" /><testcase classname="tests.integration.api_network_test.TestNetworks" name="test_connect_with_aliases" time="7.769" /><testcase classname="tests.integration.api_network_test.TestNetworks" name="test_connect_with_ipv4_address" time="7.793"><failure message="TypeError: 'NoneType' object is not subscriptable">tests/integration/api_network_test.py:379: in test_connect_with_ipv4_address
    assert net_data['IPAMConfig']['IPv4Address'] == '172.28.5.24'
E   TypeError: 'NoneType' object is not subscriptable</failure><system-out>--------------------------------- Captured Log ---------------------------------

--------------------------------- Captured Out ---------------------------------

</system-out><system-err>--------------------------------- Captured Err ---------------------------------

</system-err></testcase><testcase classname="tests.integration.api_network_test.TestNetworks" name="test_connect_with_ipv6_address" time="7.978"><failure message="TypeError: 'NoneType' object is not subscriptable">tests/integration/api_network_test.py:405: in test_connect_with_ipv6_address
    assert net_data['IPAMConfig']['IPv6Address'] == '2001:389::f00d'
E   TypeError: 'NoneType' object is not subscriptable</failure><system-out>--------------------------------- Captured Log ---------------------------------

--------------------------------- Captured Out ---------------------------------

</system-out><system-err>--------------------------------- Captured Err ---------------------------------

</system-err></testcase><testcase classname="tests.integration.api_network_test.TestNetworks" name="test_connect_with_links" time="7.985"><failure message="AssertionError: assert None == ['docker-py-test-upstream:bar']">tests/integration/api_network_test.py:344: in test_connect_with_links
    assert net_settings['Networks'][net_name]['Links'] == [
E   AssertionError: assert None == ['docker-py-test-upstream:bar']</failure><system-out>--------------------------------- Captured Log ---------------------------------

--------------------------------- Captured Out ---------------------------------

</system-out><system-err>--------------------------------- Captured Err ---------------------------------

</system-err></testcase><testcase classname="tests.integration.api_network_test.TestNetworks" name="test_connect_with_mac_address" time="7.147"><failure message="AssertionError: assert '' == '02:42:ac:11:00:02'&#10;  - 02:42:ac:11:00:02">tests/integration/api_network_test.py:421: in test_connect_with_mac_address
    assert net_data['MacAddress'] == '02:42:ac:11:00:02'
E   AssertionError: assert '' == '02:42:ac:11:00:02'
E     - 02:42:ac:11:00:02</failure><system-out>--------------------------------- Captured Log ---------------------------------

--------------------------------- Captured Out ---------------------------------

</system-out><system-err>--------------------------------- Captured Err ---------------------------------

</system-err></testcase><testcase classname="tests.integration.api_network_test.TestNetworks" name="test_create_check_duplicate" time="7.069"><failure message="docker.errors.APIError: 500 Server Error for http+docker://localhost/v1.41/networks/create: Internal Server Error (&quot;network name dockerpytest_e24fceb841cd7c62 already used: network already exists&quot;)">docker/api/client.py:296: in _raise_for_status
    response.raise_for_status()
../../.virtualenvs/docker-py/lib/python3.10/site-packages/requests/models.py:1021: in raise_for_status
    raise HTTPError(http_error_msg, response=self)
E   requests.exceptions.HTTPError: 500 Server Error: Internal Server Error for url: http+docker://localhost/v1.41/networks/create

The above exception was the direct cause of the following exception:
tests/integration/api_network_test.py:326: in test_create_check_duplicate
    net_id = self.client.create_network(net_name, check_duplicate=False)
docker/api/network.py:153: in create_network
    return self._result(res, json=True)
docker/api/client.py:302: in _result
    self._raise_for_status(response)
docker/api/client.py:298: in _raise_for_status
    raise create_api_error_from_http_exception(e) from e
docker/errors.py:39: in create_api_error_from_http_exception
    raise cls(e, response=response, explanation=explanation) from e
E   docker.errors.APIError: 500 Server Error for http+docker://localhost/v1.41/networks/create: Internal Server Error ("network name dockerpytest_e24fceb841cd7c62 already used: network already exists")</failure><system-out>--------------------------------- Captured Log ---------------------------------

--------------------------------- Captured Out ---------------------------------

</system-out><system-err>--------------------------------- Captured Err ---------------------------------

</system-err></testcase><testcase classname="tests.integration.api_network_test.TestNetworks" name="test_create_internal_networks" time="7.068" /><testcase classname="tests.integration.api_network_test.TestNetworks" name="test_create_network_ipv6_enabled" time="7.065" /><testcase classname="tests.integration.api_network_test.TestNetworks" name="test_create_network_with_host_driver_fails" time="7.067" /><testcase classname="tests.integration.api_network_test.TestNetworks" name="test_create_network_with_ipam_config" time="7.092"><failure message="AssertionError: assert {'driver': 'host-local'} is None&#10; +  where {'driver': 'host-local'} = &lt;built-in method pop of dict object at 0x7f6945683880&gt;('Options', None)&#10; +    where &lt;built-in method pop of dict object at 0x7f6945683880&gt; = {'Config': [{'Gateway': '172.28.5.254', 'Subnet': '172.28.0.0/16'}], 'Driver': 'default'}.pop">tests/integration/api_network_test.py:62: in test_create_network_with_ipam_config
    assert ipam.pop('Options', None) is None
E   AssertionError: assert {'driver': 'host-local'} is None
E    +  where {'driver': 'host-local'} = &lt;built-in method pop of dict object at 0x7f6945683880&gt;('Options', None)
E    +    where &lt;built-in method pop of dict object at 0x7f6945683880&gt; = {'Config': [{'Gateway': '172.28.5.254', 'Subnet': '172.28.0.0/16'}], 'Driver': 'default'}.pop</failure><system-out>--------------------------------- Captured Log ---------------------------------

--------------------------------- Captured Out ---------------------------------

</system-out><system-err>--------------------------------- Captured Err ---------------------------------

</system-err></testcase><testcase classname="tests.integration.api_network_test.TestNetworks" name="test_create_network_with_labels" time="7.046" /><testcase classname="tests.integration.api_network_test.TestNetworks" name="test_create_network_with_labels_wrong_type" time="7.006" /><testcase classname="tests.integration.api_network_test.TestNetworks" name="test_create_remove_network_with_space_in_name" time="7.159"><failure message="docker.errors.APIError: 500 Server Error for http+docker://localhost/v1.41/networks/create: Internal Server Error (&quot;network name test 01 invalid: names must match [a-zA-Z0-9][a-zA-Z0-9_.-]*: invalid argument&quot;)">docker/api/client.py:296: in _raise_for_status
    response.raise_for_status()
../../.virtualenvs/docker-py/lib/python3.10/site-packages/requests/models.py:1021: in raise_for_status
    raise HTTPError(http_error_msg, response=self)
E   requests.exceptions.HTTPError: 500 Server Error: Internal Server Error for url: http+docker://localhost/v1.41/networks/create

The above exception was the direct cause of the following exception:
tests/integration/api_network_test.py:470: in test_create_remove_network_with_space_in_name
    net_id = self.client.create_network('test 01')
docker/api/network.py:153: in create_network
    return self._result(res, json=True)
docker/api/client.py:302: in _result
    self._raise_for_status(response)
docker/api/client.py:298: in _raise_for_status
    raise create_api_error_from_http_exception(e) from e
docker/errors.py:39: in create_api_error_from_http_exception
    raise cls(e, response=response, explanation=explanation) from e
E   docker.errors.APIError: 500 Server Error for http+docker://localhost/v1.41/networks/create: Internal Server Error ("network name test 01 invalid: names must match [a-zA-Z0-9][a-zA-Z0-9_.-]*: invalid argument")</failure><system-out>--------------------------------- Captured Log ---------------------------------

--------------------------------- Captured Out ---------------------------------

</system-out><system-err>--------------------------------- Captured Err ---------------------------------

</system-err></testcase><testcase classname="tests.integration.api_network_test.TestNetworks" name="test_create_with_aliases" time="7.495" /><testcase classname="tests.integration.api_network_test.TestNetworks" name="test_create_with_driveropt" time="7.140"><failure message="docker.errors.APIError: 500 Server Error for http+docker://localhost/v1.41/containers/create: Internal Server Error (&quot;container create: unable to find network with name or ID bridge: network not found&quot;)">docker/api/client.py:296: in _raise_for_status
    response.raise_for_status()
../../.virtualenvs/docker-py/lib/python3.10/site-packages/requests/models.py:1021: in raise_for_status
    raise HTTPError(http_error_msg, response=self)
E   requests.exceptions.HTTPError: 500 Server Error: Internal Server Error for url: http+docker://localhost/v1.41/containers/create

The above exception was the direct cause of the following exception:
tests/integration/api_network_test.py:276: in test_create_with_driveropt
    container = self.client.create_container(
docker/api/container.py:431: in create_container
    return self.create_container_from_config(config, name, platform)
docker/api/container.py:448: in create_container_from_config
    return self._result(res, True)
docker/api/client.py:302: in _result
    self._raise_for_status(response)
docker/api/client.py:298: in _raise_for_status
    raise create_api_error_from_http_exception(e) from e
docker/errors.py:39: in create_api_error_from_http_exception
    raise cls(e, response=response, explanation=explanation) from e
E   docker.errors.APIError: 500 Server Error for http+docker://localhost/v1.41/containers/create: Internal Server Error ("container create: unable to find network with name or ID bridge: network not found")</failure><system-out>--------------------------------- Captured Log ---------------------------------

--------------------------------- Captured Out ---------------------------------

</system-out><system-err>--------------------------------- Captured Err ---------------------------------

</system-err></testcase><testcase classname="tests.integration.api_network_test.TestNetworks" name="test_create_with_ipv4_address" time="7.554"><failure message="TypeError: 'NoneType' object is not subscriptable">tests/integration/api_network_test.py:224: in test_create_with_ipv4_address
    assert net_settings['Networks'][net_name]['IPAMConfig']['IPv4Address']\
E   TypeError: 'NoneType' object is not subscriptable</failure><system-out>--------------------------------- Captured Log ---------------------------------

--------------------------------- Captured Out ---------------------------------

</system-out><system-err>--------------------------------- Captured Err ---------------------------------

</system-err></testcase><testcase classname="tests.integration.api_network_test.TestNetworks" name="test_create_with_ipv6_address" time="7.649"><failure message="TypeError: 'NoneType' object is not subscriptable">tests/integration/api_network_test.py:250: in test_create_with_ipv6_address
    assert net_settings['Networks'][net_name]['IPAMConfig']['IPv6Address']\
E   TypeError: 'NoneType' object is not subscriptable</failure><system-out>--------------------------------- Captured Log ---------------------------------

--------------------------------- Captured Out ---------------------------------

</system-out><system-err>--------------------------------- Captured Err ---------------------------------

</system-err></testcase><testcase classname="tests.integration.api_network_test.TestNetworks" name="test_create_with_linklocal_ips" time="7.066"><failure message="docker.errors.APIError: 500 Server Error for http+docker://localhost/v1.41/containers/create: Internal Server Error (&quot;container create: unable to find network with name or ID bridge: network not found&quot;)">docker/api/client.py:296: in _raise_for_status
    response.raise_for_status()
../../.virtualenvs/docker-py/lib/python3.10/site-packages/requests/models.py:1021: in raise_for_status
    raise HTTPError(http_error_msg, response=self)
E   requests.exceptions.HTTPError: 500 Server Error: Internal Server Error for url: http+docker://localhost/v1.41/containers/create

The above exception was the direct cause of the following exception:
tests/integration/api_network_test.py:255: in test_create_with_linklocal_ips
    container = self.client.create_container(
docker/api/container.py:431: in create_container
    return self.create_container_from_config(config, name, platform)
docker/api/container.py:448: in create_container_from_config
    return self._result(res, True)
docker/api/client.py:302: in _result
    self._raise_for_status(response)
docker/api/client.py:298: in _raise_for_status
    raise create_api_error_from_http_exception(e) from e
docker/errors.py:39: in create_api_error_from_http_exception
    raise cls(e, response=response, explanation=explanation) from e
E   docker.errors.APIError: 500 Server Error for http+docker://localhost/v1.41/containers/create: Internal Server Error ("container create: unable to find network with name or ID bridge: network not found")</failure><system-out>--------------------------------- Captured Log ---------------------------------

--------------------------------- Captured Out ---------------------------------

</system-out><system-err>--------------------------------- Captured Err ---------------------------------

</system-err></testcase><testcase classname="tests.integration.api_network_test.TestNetworks" name="test_create_with_links" time="7.607"><failure message="AssertionError: assert None == ['docker-py-test-upstream:bar']">tests/integration/api_network_test.py:311: in test_create_with_links
    assert net_settings['Networks'][net_name]['Links'] == [
E   AssertionError: assert None == ['docker-py-test-upstream:bar']</failure><system-out>--------------------------------- Captured Log ---------------------------------

--------------------------------- Captured Out ---------------------------------

</system-out><system-err>--------------------------------- Captured Err ---------------------------------

</system-err></testcase><testcase classname="tests.integration.api_network_test.TestNetworks" name="test_inspect_network" time="7.069" /><testcase classname="tests.integration.api_network_test.TestNetworks" name="test_list_networks" time="7.068" /><testcase classname="tests.integration.api_network_test.TestNetworks" name="test_prune_networks" time="7.023" /><testcase classname="tests.integration.api_network_test.TestNetworks" name="test_remove_network" time="7.097" /><testcase classname="tests.integration.api_secret_test.SecretAPITest" name="test_create_secret" time="11.868" /><testcase classname="tests.integration.api_secret_test.SecretAPITest" name="test_create_secret_unicode_data" time="7.221" /><testcase classname="tests.integration.api_secret_test.SecretAPITest" name="test_inspect_secret" time="7.053" /><testcase classname="tests.integration.api_secret_test.SecretAPITest" name="test_list_secrets" time="7.080" /><testcase classname="tests.integration.api_secret_test.SecretAPITest" name="test_remove_secret" time="11.778" /><testcase classname="tests.integration.api_volume_test.TestVolumes" name="test_create_volume" time="7.123" /><testcase classname="tests.integration.api_volume_test.TestVolumes" name="test_create_volume_invalid_driver" time="7.015"><failure message="docker.errors.APIError: 500 Server Error for http+docker://localhost/v1.41/volumes/create: Internal Server Error (&quot;volume perfectcherryblossom uses volume plugin invalid.driver but it could not be retrieved: no volume plugin with name invalid.driver available: required plugin missing&quot;)">docker/api/client.py:296: in _raise_for_status
    response.raise_for_status()
../../.virtualenvs/docker-py/lib/python3.10/site-packages/requests/models.py:1021: in raise_for_status
    raise HTTPError(http_error_msg, response=self)
E   requests.exceptions.HTTPError: 500 Server Error: Internal Server Error for url: http+docker://localhost/v1.41/volumes/create

The above exception was the direct cause of the following exception:
tests/integration/api_volume_test.py:22: in test_create_volume_invalid_driver
    self.client.create_volume('perfectcherryblossom', driver_name)
docker/api/volume.py:92: in create_volume
    return self._result(self._post_json(url, data=data), True)
docker/api/client.py:302: in _result
    self._raise_for_status(response)
docker/api/client.py:298: in _raise_for_status
    raise create_api_error_from_http_exception(e) from e
docker/errors.py:39: in create_api_error_from_http_exception
    raise cls(e, response=response, explanation=explanation) from e
E   docker.errors.APIError: 500 Server Error for http+docker://localhost/v1.41/volumes/create: Internal Server Error ("volume perfectcherryblossom uses volume plugin invalid.driver but it could not be retrieved: no volume plugin with name invalid.driver available: required plugin missing")</failure><system-out>--------------------------------- Captured Log ---------------------------------

--------------------------------- Captured Out ---------------------------------

</system-out><system-err>--------------------------------- Captured Err ---------------------------------

</system-err></testcase><testcase classname="tests.integration.api_volume_test.TestVolumes" name="test_force_remove_volume" time="7.089" /><testcase classname="tests.integration.api_volume_test.TestVolumes" name="test_inspect_nonexistent_volume" time="7.000" /><testcase classname="tests.integration.api_volume_test.TestVolumes" name="test_inspect_volume" time="7.098"><failure message="AssertionError: assert {'CreatedAt':...l/_data', ...} == {'CreatedAt':...l/_data', ...}&#10;  Omitting 6 identical items, use -vv to show&#10;  Differing items:&#10;  {'Options': None} != {'Options': {}}&#10;  Full diff:&#10;    {&#10;     'CreatedAt': '2022-11-16T22:24:52+01:00',&#10;     'Driver': 'local',...&#10;  &#10;  ...Full output truncated (10 lines hidden), use '-vv' to show">tests/integration/api_volume_test.py:38: in test_inspect_volume
    assert volume_info == result
E   AssertionError: assert {'CreatedAt':...l/_data', ...} == {'CreatedAt':...l/_data', ...}
E     Omitting 6 identical items, use -vv to show
E     Differing items:
E     {'Options': None} != {'Options': {}}
E     Full diff:
E       {
E        'CreatedAt': '2022-11-16T22:24:52+01:00',
E        'Driver': 'local',...
E     
E     ...Full output truncated (10 lines hidden), use '-vv' to show</failure><system-out>--------------------------------- Captured Log ---------------------------------

--------------------------------- Captured Out ---------------------------------

</system-out><system-err>--------------------------------- Captured Err ---------------------------------

</system-err></testcase><testcase classname="tests.integration.api_volume_test.TestVolumes" name="test_list_volumes" time="7.117"><failure message="AssertionError: assert {'CreatedAt': '2022-11-16T22:24:59+01:00', 'Driver': 'local', 'Labels': {}, 'Mountpoint': '/home/riyad/podman/storage/volumes/imperishablenight/_data', ...} in [{'CreatedAt': '2022-11-16T22:06:58+01:00', 'Driver': 'local', 'Labels': {}, 'Mountpoint': '/home/riyad/podman/storage/volumes/dockerpytest_fa05c2a0a2fd4452/_data', ...}, {'CreatedAt': '2022-11-16T22:24:59+01:00', 'Driver': 'local', 'Labels': {}, 'Mountpoint': '/home/riyad/podman/storage/volumes/imperishablenight/_data', ...}]">tests/integration/api_volume_test.py:31: in test_list_volumes
    assert volume_info in volumes
E   AssertionError: assert {'CreatedAt': '2022-11-16T22:24:59+01:00', 'Driver': 'local', 'Labels': {}, 'Mountpoint': '/home/riyad/podman/storage/volumes/imperishablenight/_data', ...} in [{'CreatedAt': '2022-11-16T22:06:58+01:00', 'Driver': 'local', 'Labels': {}, 'Mountpoint': '/home/riyad/podman/storage/volumes/dockerpytest_fa05c2a0a2fd4452/_data', ...}, {'CreatedAt': '2022-11-16T22:24:59+01:00', 'Driver': 'local', 'Labels': {}, 'Mountpoint': '/home/riyad/podman/storage/volumes/imperishablenight/_data', ...}]</failure><system-out>--------------------------------- Captured Log ---------------------------------

--------------------------------- Captured Out ---------------------------------

</system-out><system-err>--------------------------------- Captured Err ---------------------------------

</system-err></testcase><testcase classname="tests.integration.api_volume_test.TestVolumes" name="test_prune_volumes" time="7.118" /><testcase classname="tests.integration.api_volume_test.TestVolumes" name="test_remove_nonexistent_volume" time="7.141" /><testcase classname="tests.integration.api_volume_test.TestVolumes" name="test_remove_volume" time="7.099" /><testcase classname="tests.integration.client_test.ClientTest" name="test_df" time="0.032"><failure message="docker.errors.APIError: 500 Server Error for http+docker://localhost/v1.41/system/df: Internal Server Error (&quot;runtime error: invalid memory address or nil pointer dereference&quot;)">docker/api/client.py:296: in _raise_for_status
    response.raise_for_status()
../../.virtualenvs/docker-py/lib/python3.10/site-packages/requests/models.py:1021: in raise_for_status
    raise HTTPError(http_error_msg, response=self)
E   requests.exceptions.HTTPError: 500 Server Error: Internal Server Error for url: http+docker://localhost/v1.41/system/df

The above exception was the direct cause of the following exception:
tests/integration/client_test.py:28: in test_df
    data = self.client.df()
docker/client.py:191: in df
    return self.api.df()
docker/utils/decorators.py:34: in wrapper
    return f(self, *args, **kwargs)
docker/api/daemon.py:22: in df
    return self._result(self._get(url), True)
docker/api/client.py:302: in _result
    self._raise_for_status(response)
docker/api/client.py:298: in _raise_for_status
    raise create_api_error_from_http_exception(e) from e
docker/errors.py:39: in create_api_error_from_http_exception
    raise cls(e, response=response, explanation=explanation) from e
E   docker.errors.APIError: 500 Server Error for http+docker://localhost/v1.41/system/df: Internal Server Error ("runtime error: invalid memory address or nil pointer dereference")</failure><system-out>--------------------------------- Captured Log ---------------------------------

--------------------------------- Captured Out ---------------------------------

</system-out><system-err>--------------------------------- Captured Err ---------------------------------

</system-err></testcase><testcase classname="tests.integration.client_test.ClientTest" name="test_info" time="1.571" /><testcase classname="tests.integration.client_test.ClientTest" name="test_ping" time="0.003" /><testcase classname="tests.integration.client_test.ClientTest" name="test_version" time="2.355" /><testcase classname="tests.integration.client_test.CancellableEventsTest" name="test_cancel_events" time="2.003" /><testcase classname="tests.integration.context_api_test.ContextLifecycleTest" name="test_context_remove" time="7.130" /><testcase classname="tests.integration.context_api_test.ContextLifecycleTest" name="test_lifecycle" time="7.057" /><testcase classname="tests.integration.context_api_test.ContextLifecycleTest" name="test_load_context_without_orchestrator" time="7.200" /><testcase classname="tests.integration.errors_test.ErrorsTest" name="test_api_error_parses_json" time="8.104"><failure message="AssertionError: assert 'You cannot remove a running container' in 'cannot remove container b526f508fda050f8a1ba868e8f7bbb73e39878b347b412d1de3ddd4aed4b9fe7 as it is running - running or paused containers cannot be removed without force: container state improper'">tests/integration/errors_test.py:13: in test_api_error_parses_json
    assert 'You cannot remove a running container' in explanation
E   AssertionError: assert 'You cannot remove a running container' in 'cannot remove container b526f508fda050f8a1ba868e8f7bbb73e39878b347b412d1de3ddd4aed4b9fe7 as it is running - running or paused containers cannot be removed without force: container state improper'</failure><system-out>--------------------------------- Captured Log ---------------------------------

--------------------------------- Captured Out ---------------------------------

</system-out><system-err>--------------------------------- Captured Err ---------------------------------

</system-err></testcase><testcase classname="tests.integration.models_containers_test.ContainerCollectionTest" name="test_get" time="5.179"><failure message="AssertionError: assert 'docker.io/li...alpine:latest' == 'alpine'&#10;  - alpine&#10;  + docker.io/library/alpine:latest">tests/integration/models_containers_test.py:189: in test_get
    assert client.containers.get(container.id).attrs[
E   AssertionError: assert 'docker.io/li...alpine:latest' == 'alpine'
E     - alpine
E     + docker.io/library/alpine:latest</failure><system-out>--------------------------------- Captured Log ---------------------------------

--------------------------------- Captured Out ---------------------------------

</system-out><system-err>--------------------------------- Captured Err ---------------------------------

</system-err></testcase><testcase classname="tests.integration.models_containers_test.ContainerCollectionTest" name="test_list" time="5.537"><failure message="AssertionError: assert 'docker.io/li...alpine:latest' == 'alpine'&#10;  - alpine&#10;  + docker.io/library/alpine:latest">tests/integration/models_containers_test.py:202: in test_list
    assert container.attrs['Config']['Image'] == 'alpine'
E   AssertionError: assert 'docker.io/li...alpine:latest' == 'alpine'
E     - alpine
E     + docker.io/library/alpine:latest</failure><system-out>--------------------------------- Captured Log ---------------------------------

--------------------------------- Captured Out ---------------------------------

</system-out><system-err>--------------------------------- Captured Err ---------------------------------

</system-err></testcase><testcase classname="tests.integration.models_containers_test.ContainerCollectionTest" name="test_list_sparse" time="5.598"><failure message="AssertionError: assert 'docker.io/li...alpine:latest' == 'alpine'&#10;  - alpine&#10;  + docker.io/library/alpine:latest">tests/integration/models_containers_test.py:220: in test_list_sparse
    assert container.attrs['Image'] == 'alpine'
E   AssertionError: assert 'docker.io/li...alpine:latest' == 'alpine'
E     - alpine
E     + docker.io/library/alpine:latest</failure><system-out>--------------------------------- Captured Log ---------------------------------

--------------------------------- Captured Out ---------------------------------

</system-out><system-err>--------------------------------- Captured Err ---------------------------------

</system-err></testcase><testcase classname="tests.integration.models_containers_test.ContainerCollectionTest" name="test_run" time="5.518" /><testcase classname="tests.integration.models_containers_test.ContainerCollectionTest" name="test_run_detach" time="5.327"><failure message="AssertionError: assert 'docker.io/li...alpine:latest' == 'alpine'&#10;  - alpine&#10;  + docker.io/library/alpine:latest">tests/integration/models_containers_test.py:26: in test_run_detach
    assert container.attrs['Config']['Image'] == "alpine"
E   AssertionError: assert 'docker.io/li...alpine:latest' == 'alpine'
E     - alpine
E     + docker.io/library/alpine:latest</failure><system-out>--------------------------------- Captured Log ---------------------------------

--------------------------------- Captured Out ---------------------------------

</system-out><system-err>--------------------------------- Captured Err ---------------------------------

</system-err></testcase><testcase classname="tests.integration.models_containers_test.ContainerCollectionTest" name="test_run_with_auto_remove" time="8.187" /><testcase classname="tests.integration.models_containers_test.ContainerCollectionTest" name="test_run_with_auto_remove_error" time="8.547"><failure message="docker.errors.NotFound: 404 Client Error for http+docker://localhost/v1.41/containers/6e25c34868347a04fc616b6bcaa79ef18bd5f33d753a7b7bd8d6649a31a0ad91/json: Not Found (&quot;no container with name or ID &quot;6e25c34868347a04fc616b6bcaa79ef18bd5f33d753a7b7bd8d6649a31a0ad91&quot; found: no such container&quot;)">docker/api/client.py:296: in _raise_for_status
    response.raise_for_status()
../../.virtualenvs/docker-py/lib/python3.10/site-packages/requests/models.py:1021: in raise_for_status
    raise HTTPError(http_error_msg, response=self)
E   requests.exceptions.HTTPError: 404 Client Error: Not Found for url: http+docker://localhost/v1.41/containers/6e25c34868347a04fc616b6bcaa79ef18bd5f33d753a7b7bd8d6649a31a0ad91/json

The above exception was the direct cause of the following exception:
tests/integration/models_containers_test.py:139: in test_run_with_auto_remove_error
    client.containers.run(
docker/models/containers.py:863: in run
    out = container.logs(
docker/models/containers.py:307: in logs
    return self.client.api.logs(self.id, **kwargs)
docker/utils/decorators.py:19: in wrapped
    return f(self, resource_id, *args, **kwargs)
docker/api/container.py:886: in logs
    output = self._get_result(container, stream, res)
docker/api/client.py:495: in _get_result
    return self._get_result_tty(stream, res, self._check_is_tty(container))
docker/utils/decorators.py:19: in wrapped
    return f(self, resource_id, *args, **kwargs)
docker/api/client.py:491: in _check_is_tty
    cont = self.inspect_container(container)
docker/utils/decorators.py:19: in wrapped
    return f(self, resource_id, *args, **kwargs)
docker/api/container.py:783: in inspect_container
    return self._result(
docker/api/client.py:302: in _result
    self._raise_for_status(response)
docker/api/client.py:298: in _raise_for_status
    raise create_api_error_from_http_exception(e) from e
docker/errors.py:39: in create_api_error_from_http_exception
    raise cls(e, response=response, explanation=explanation) from e
E   docker.errors.NotFound: 404 Client Error for http+docker://localhost/v1.41/containers/6e25c34868347a04fc616b6bcaa79ef18bd5f33d753a7b7bd8d6649a31a0ad91/json: Not Found ("no container with name or ID "6e25c34868347a04fc616b6bcaa79ef18bd5f33d753a7b7bd8d6649a31a0ad91" found: no such container")</failure><system-out>--------------------------------- Captured Log ---------------------------------

--------------------------------- Captured Out ---------------------------------

</system-out><system-err>--------------------------------- Captured Err ---------------------------------

</system-err></testcase><testcase classname="tests.integration.models_containers_test.ContainerCollectionTest" name="test_run_with_error" time="5.765" /><testcase classname="tests.integration.models_containers_test.ContainerCollectionTest" name="test_run_with_image_that_does_not_exist" time="8.191" /><testcase classname="tests.integration.models_containers_test.ContainerCollectionTest" name="test_run_with_json_file_driver" time="5.712" /><testcase classname="tests.integration.models_containers_test.ContainerCollectionTest" name="test_run_with_named_volume" time="5.965" /><testcase classname="tests.integration.models_containers_test.ContainerCollectionTest" name="test_run_with_network" time="5.415" /><testcase classname="tests.integration.models_containers_test.ContainerCollectionTest" name="test_run_with_none_driver" time="5.451" /><testcase classname="tests.integration.models_containers_test.ContainerCollectionTest" name="test_run_with_proxy_config" time="6.409" /><testcase classname="tests.integration.models_containers_test.ContainerCollectionTest" name="test_run_with_streamed_logs" time="9.634" /><testcase classname="tests.integration.models_containers_test.ContainerCollectionTest" name="test_run_with_streamed_logs_and_cancel" time="10.384"><failure message="Failed: Timeout &gt;5.0s">tests/integration/models_containers_test.py:161: in test_run_with_streamed_logs_and_cancel
    client = docker.from_env(version=TEST_API_VERSION)
docker/client.py:96: in from_env
    return cls(
docker/client.py:45: in __init__
    self.api = APIClient(*args, **kwargs)
docker/api/client.py:197: in __init__
    self._version = self._retrieve_server_version()
docker/api/client.py:214: in _retrieve_server_version
    return self.version(api_version=False)["ApiVersion"]
docker/api/daemon.py:181: in version
    return self._result(self._get(url), json=True)
docker/utils/decorators.py:46: in inner
    return f(self, *args, **kwargs)
docker/api/client.py:251: in _get
    return self.get(url, **self._set_request_timeout(kwargs))
../../.virtualenvs/docker-py/lib/python3.10/site-packages/requests/sessions.py:600: in get
    return self.request("GET", url, **kwargs)
../../.virtualenvs/docker-py/lib/python3.10/site-packages/requests/sessions.py:587: in request
    resp = self.send(prep, **send_kwargs)
../../.virtualenvs/docker-py/lib/python3.10/site-packages/requests/sessions.py:701: in send
    r = adapter.send(request, **kwargs)
../../.virtualenvs/docker-py/lib/python3.10/site-packages/requests/adapters.py:489: in send
    resp = conn.urlopen(
../../.virtualenvs/docker-py/lib/python3.10/site-packages/urllib3/connectionpool.py:703: in urlopen
    httplib_response = self._make_request(
../../.virtualenvs/docker-py/lib/python3.10/site-packages/urllib3/connectionpool.py:449: in _make_request
    six.raise_from(e, None)
&lt;string&gt;:3: in raise_from
    ???
../../.virtualenvs/docker-py/lib/python3.10/site-packages/urllib3/connectionpool.py:444: in _make_request
    httplib_response = conn.getresponse()
/usr/lib/python3.10/http/client.py:1374: in getresponse
    response.begin()
/usr/lib/python3.10/http/client.py:318: in begin
    version, status, reason = self._read_status()
/usr/lib/python3.10/http/client.py:279: in _read_status
    line = str(self.fp.readline(_MAXLINE + 1), "iso-8859-1")
/usr/lib/python3.10/socket.py:705: in readinto
    return self._sock.recv_into(b)
E   Failed: Timeout &gt;5.0s</failure><system-out>--------------------------------- Captured Log ---------------------------------

--------------------------------- Captured Out ---------------------------------

</system-out><system-err>--------------------------------- Captured Err ---------------------------------

</system-err></testcase><testcase classname="tests.integration.models_containers_test.ContainerCollectionTest" name="test_run_with_volume" time="12.674" /><testcase classname="tests.integration.models_containers_test.ContainerTest" name="test_commit" time="11.559" /><testcase classname="tests.integration.models_containers_test.ContainerTest" name="test_create_with_volume_driver" time="9.183"><failure message="AssertionError: assert '' == 'foo'&#10;  - foo">tests/integration/models_containers_test.py:456: in test_create_with_volume_driver
    assert container.attrs['HostConfig']['VolumeDriver'] == 'foo'
E   AssertionError: assert '' == 'foo'
E     - foo</failure><system-out>--------------------------------- Captured Log ---------------------------------

--------------------------------- Captured Out ---------------------------------

</system-out><system-err>--------------------------------- Captured Err ---------------------------------

</system-err></testcase><testcase classname="tests.integration.models_containers_test.ContainerTest" name="test_diff" time="10.863"><failure message="AssertionError: assert [{'Kind': 0, ...th': '/test'}] == [{'Kind': 1, 'Path': '/test'}]&#10;  At index 0 diff: {'Path': '/etc', 'Kind': 0} != {'Path': '/test', 'Kind': 1}&#10;  Left contains one more item: {'Kind': 1, 'Path': '/test'}&#10;  Full diff:&#10;  - [{'Kind': 1, 'Path': '/test'}]&#10;  + [{'Kind': 0, 'Path': '/etc'}, {'Kind': 1, 'Path': '/test'}]">tests/integration/models_containers_test.py:251: in test_diff
    assert container.diff() == [{'Path': '/test', 'Kind': 1}]
E   AssertionError: assert [{'Kind': 0, ...th': '/test'}] == [{'Kind': 1, 'Path': '/test'}]
E     At index 0 diff: {'Path': '/etc', 'Kind': 0} != {'Path': '/test', 'Kind': 1}
E     Left contains one more item: {'Kind': 1, 'Path': '/test'}
E     Full diff:
E     - [{'Kind': 1, 'Path': '/test'}]
E     + [{'Kind': 0, 'Path': '/etc'}, {'Kind': 1, 'Path': '/test'}]</failure><system-out>--------------------------------- Captured Log ---------------------------------

--------------------------------- Captured Out ---------------------------------

</system-out><system-err>--------------------------------- Captured Err ---------------------------------

</system-err></testcase><testcase classname="tests.integration.models_containers_test.ContainerTest" name="test_exec_run_failed" time="10.029"><failure message="assert 127 == 126">tests/integration/models_containers_test.py:270: in test_exec_run_failed
    assert exec_output[0] == 126
E   assert 127 == 126</failure><system-out>--------------------------------- Captured Log ---------------------------------

--------------------------------- Captured Out ---------------------------------

</system-out><system-err>--------------------------------- Captured Err ---------------------------------

</system-err></testcase><testcase classname="tests.integration.models_containers_test.ContainerTest" name="test_exec_run_success" time="9.761" /><testcase classname="tests.integration.models_containers_test.ContainerTest" name="test_kill" time="9.679" /><testcase classname="tests.integration.models_containers_test.ContainerTest" name="test_logs" time="9.972" /><testcase classname="tests.integration.models_containers_test.ContainerTest" name="test_pause" time="9.663" /><testcase classname="tests.integration.models_containers_test.ContainerTest" name="test_ports_target_list" time="9.763" /><testcase classname="tests.integration.models_containers_test.ContainerTest" name="test_ports_target_none" time="9.114" /><testcase classname="tests.integration.models_containers_test.ContainerTest" name="test_ports_target_tuple" time="8.834" /><testcase classname="tests.integration.models_containers_test.ContainerTest" name="test_remove" time="8.884" /><testcase classname="tests.integration.models_containers_test.ContainerTest" name="test_rename" time="8.737" /><testcase classname="tests.integration.models_containers_test.ContainerTest" name="test_restart" time="19.472" /><testcase classname="tests.integration.models_containers_test.ContainerTest" name="test_start" time="9.499" /><testcase classname="tests.integration.models_containers_test.ContainerTest" name="test_stats" time="10.508" /><testcase classname="tests.integration.models_containers_test.ContainerTest" name="test_stop" time="9.280" /><testcase classname="tests.integration.models_containers_test.ContainerTest" name="test_top" time="9.063"><failure message="AssertionError: assert 'sleep 60' in ['1 root      0:00 sleep 60']">tests/integration/models_containers_test.py:425: in test_top
    assert 'sleep 60' in top['Processes'][0]
E   AssertionError: assert 'sleep 60' in ['1 root      0:00 sleep 60']</failure><system-out>--------------------------------- Captured Log ---------------------------------

--------------------------------- Captured Out ---------------------------------

</system-out><system-err>--------------------------------- Captured Err ---------------------------------

</system-err></testcase><testcase classname="tests.integration.models_containers_test.ContainerTest" name="test_update" time="8.976"><failure message="TypeError: a bytes-like object is required, not 'str'">docker/api/client.py:296: in _raise_for_status
    response.raise_for_status()
../../.virtualenvs/docker-py/lib/python3.10/site-packages/requests/models.py:1021: in raise_for_status
    raise HTTPError(http_error_msg, response=self)
E   requests.exceptions.HTTPError: 404 Client Error: Not Found for url: http+docker://localhost/v1.41/containers/503f608063fb3141dfb03dfaf45a35c74cb0716ff1f88ffd1d0a5a44795b13e1/update

During handling of the above exception, another exception occurred:
tests/integration/models_containers_test.py:433: in test_update
    container.update(cpu_shares=3)
docker/models/containers.py:490: in update
    return self.client.api.update_container(self.id, **kwargs)
docker/utils/decorators.py:34: in wrapper
    return f(self, *args, **kwargs)
docker/utils/decorators.py:19: in wrapped
    return f(self, resource_id, *args, **kwargs)
docker/api/container.py:1285: in update_container
    return self._result(res, True)
docker/api/client.py:302: in _result
    self._raise_for_status(response)
docker/api/client.py:298: in _raise_for_status
    raise create_api_error_from_http_exception(e) from e
docker/errors.py:34: in create_api_error_from_http_exception
    if any(fragment in explanation_msg
docker/errors.py:34: in &lt;genexpr&gt;
    if any(fragment in explanation_msg
E   TypeError: a bytes-like object is required, not 'str'</failure><system-out>--------------------------------- Captured Log ---------------------------------

--------------------------------- Captured Out ---------------------------------

</system-out><system-err>--------------------------------- Captured Err ---------------------------------

</system-err></testcase><testcase classname="tests.integration.models_containers_test.ContainerTest" name="test_wait" time="10.185" /><testcase classname="tests.integration.models_images_test.ImageCollectionTest" name="test_build" time="9.075" /><testcase classname="tests.integration.models_images_test.ImageCollectionTest" name="test_build_with_error" time="8.625"><failure message="assert &quot;The command '/bin/sh -c exit 1' returned a non-zero code: 1&quot; in 'docker.errors.BuildError: building at STEP &quot;RUN exit 1&quot;: while running runtime: exit status 1'&#10; +  where 'docker.errors.BuildError: building at STEP &quot;RUN exit 1&quot;: while running runtime: exit status 1' = &lt;bound method ExceptionInfo.exconly of &lt;ExceptionInfo BuildError('building at STEP &quot;RUN exit 1&quot;: while running runtime: exit status 1\n') tblen=2&gt;&gt;()&#10; +    where &lt;bound method ExceptionInfo.exconly of &lt;ExceptionInfo BuildError('building at STEP &quot;RUN exit 1&quot;: while running runtime: exit status 1\n') tblen=2&gt;&gt; = &lt;ExceptionInfo BuildError('building at STEP &quot;RUN exit 1&quot;: while running runtime: exit status 1\n') tblen=2&gt;.exconly">tests/integration/models_images_test.py:30: in test_build_with_error
    assert (
E   assert "The command '/bin/sh -c exit 1' returned a non-zero code: 1" in 'docker.errors.BuildError: building at STEP "RUN exit 1": while running runtime: exit status 1'
E    +  where 'docker.errors.BuildError: building at STEP "RUN exit 1": while running runtime: exit status 1' = &lt;bound method ExceptionInfo.exconly of &lt;ExceptionInfo BuildError('building at STEP "RUN exit 1": while running runtime: exit status 1\n') tblen=2&gt;&gt;()
E    +    where &lt;bound method ExceptionInfo.exconly of &lt;ExceptionInfo BuildError('building at STEP "RUN exit 1": while running runtime: exit status 1\n') tblen=2&gt;&gt; = &lt;ExceptionInfo BuildError('building at STEP "RUN exit 1": while running runtime: exit status 1\n') tblen=2&gt;.exconly</failure><system-out>--------------------------------- Captured Log ---------------------------------

--------------------------------- Captured Out ---------------------------------

</system-out><system-err>--------------------------------- Captured Err ---------------------------------

</system-err></testcase><testcase classname="tests.integration.models_images_test.ImageCollectionTest" name="test_build_with_multiple_success" time="9.393" /><testcase classname="tests.integration.models_images_test.ImageCollectionTest" name="test_build_with_success_build_output" time="8.850" /><testcase classname="tests.integration.models_images_test.ImageCollectionTest" name="test_list" time="15.473" /><testcase classname="tests.integration.models_images_test.ImageCollectionTest" name="test_list_with_repository" time="10.272" /><testcase classname="tests.integration.models_images_test.ImageCollectionTest" name="test_load_error" time="8.383"><failure message="docker.errors.APIError: 500 Server Error for http+docker://localhost/v1.41/images/load: Internal Server Error (&quot;failed to load image: payload does not match any of the supported image formats:&#10; * oci: initializing source oci:/var/tmp/api_load.tar322550573:: open /var/tmp/api_load.tar322550573/index.json: not a directory&#10; * oci-archive: creating temp directory: untarring file &quot;/var/tmp/oci468851899&quot;: unexpected EOF&#10; * docker-archive: loading tar component manifest.json: unexpected EOF&#10; * dir: open /var/tmp/api_load.tar322550573/manifest.json: not a directory&quot;)">docker/api/client.py:296: in _raise_for_status
    response.raise_for_status()
../../.virtualenvs/docker-py/lib/python3.10/site-packages/requests/models.py:1021: in raise_for_status
    raise HTTPError(http_error_msg, response=self)
E   requests.exceptions.HTTPError: 500 Server Error: Internal Server Error for url: http+docker://localhost/v1.41/images/load

The above exception was the direct cause of the following exception:
tests/integration/models_images_test.py:98: in test_load_error
    client.images.load('abc')
docker/models/images.py:403: in load
    for chunk in resp:
docker/api/client.py:386: in _stream_helper
    yield self._result(response, json=decode)
docker/api/client.py:302: in _result
    self._raise_for_status(response)
docker/api/client.py:298: in _raise_for_status
    raise create_api_error_from_http_exception(e) from e
docker/errors.py:39: in create_api_error_from_http_exception
    raise cls(e, response=response, explanation=explanation) from e
E   docker.errors.APIError: 500 Server Error for http+docker://localhost/v1.41/images/load: Internal Server Error ("failed to load image: payload does not match any of the supported image formats:
E    * oci: initializing source oci:/var/tmp/api_load.tar322550573:: open /var/tmp/api_load.tar322550573/index.json: not a directory
E    * oci-archive: creating temp directory: untarring file "/var/tmp/oci468851899": unexpected EOF
E    * docker-archive: loading tar component manifest.json: unexpected EOF
E    * dir: open /var/tmp/api_load.tar322550573/manifest.json: not a directory")</failure><system-out>--------------------------------- Captured Log ---------------------------------

--------------------------------- Captured Out ---------------------------------

</system-out><system-err>--------------------------------- Captured Err ---------------------------------

</system-err></testcase><testcase classname="tests.integration.models_images_test.ImageCollectionTest" name="test_pull" time="10.015"><failure message="AssertionError: assert 'alpine:latest' in ['docker.io/library/alpine:latest']">tests/integration/models_images_test.py:71: in test_pull
    assert 'alpine:latest' in image.attrs['RepoTags']
E   AssertionError: assert 'alpine:latest' in ['docker.io/library/alpine:latest']</failure><system-out>--------------------------------- Captured Log ---------------------------------

--------------------------------- Captured Out ---------------------------------

</system-out><system-err>--------------------------------- Captured Err ---------------------------------

</system-err></testcase><testcase classname="tests.integration.models_images_test.ImageCollectionTest" name="test_pull_multiple" time="10.659"><failure message="assert False&#10; +  where False = any([False])">tests/integration/models_images_test.py:91: in test_pull_multiple
    assert any([
E   assert False
E    +  where False = any([False])</failure><system-out>--------------------------------- Captured Log ---------------------------------

--------------------------------- Captured Out ---------------------------------

</system-out><system-err>--------------------------------- Captured Err ---------------------------------

</system-err></testcase><testcase classname="tests.integration.models_images_test.ImageCollectionTest" name="test_pull_with_sha" time="11.645"><failure message="AssertionError: assert 'hello-world@sha256:083de497cff944f969d8499ab94f07134c50bcf5e6b9559b27182d3fa80ce3f7' in ['docker.io/library/hello-world@sha256:083de497cff944f969d8499ab94f07134c50bcf5e6b9559b27182d3fa80ce3f7', 'docker.io/library/hello-world@sha256:8072a54ebb3bc136150e2f2860f00a7bf45f13eeb917cca2430fcd0054c8e51b']">tests/integration/models_images_test.py:85: in test_pull_with_sha
    assert image_ref in image.attrs['RepoDigests']
E   AssertionError: assert 'hello-world@sha256:083de497cff944f969d8499ab94f07134c50bcf5e6b9559b27182d3fa80ce3f7' in ['docker.io/library/hello-world@sha256:083de497cff944f969d8499ab94f07134c50bcf5e6b9559b27182d3fa80ce3f7', 'docker.io/library/hello-world@sha256:8072a54ebb3bc136150e2f2860f00a7bf45f13eeb917cca2430fcd0054c8e51b']</failure><system-out>--------------------------------- Captured Log ---------------------------------

--------------------------------- Captured Out ---------------------------------

</system-out><system-err>--------------------------------- Captured Err ---------------------------------

</system-err></testcase><testcase classname="tests.integration.models_images_test.ImageCollectionTest" name="test_pull_with_tag" time="10.246"><failure message="AssertionError: assert 'alpine:3.10' in ['docker.io/library/alpine:3.10']">tests/integration/models_images_test.py:76: in test_pull_with_tag
    assert 'alpine:3.10' in image.attrs['RepoTags']
E   AssertionError: assert 'alpine:3.10' in ['docker.io/library/alpine:3.10']</failure><system-out>--------------------------------- Captured Log ---------------------------------

--------------------------------- Captured Out ---------------------------------

</system-out><system-err>--------------------------------- Captured Err ---------------------------------

</system-err></testcase><testcase classname="tests.integration.models_images_test.ImageCollectionTest" name="test_save_and_load" time="8.611" /><testcase classname="tests.integration.models_images_test.ImageCollectionTest" name="test_save_and_load_repo_name" time="8.223"><failure message="docker.errors.InvalidArgument: dockerpytest_7564fbbe94f0e5dc:latest is not a valid tag for this image">tests/integration/models_images_test.py:122: in test_save_and_load_repo_name
    stream = image.save(named=f'{additional_tag}:latest')
docker/models/images.py:117: in save
    raise InvalidArgument(
E   docker.errors.InvalidArgument: dockerpytest_7564fbbe94f0e5dc:latest is not a valid tag for this image</failure><system-out>--------------------------------- Captured Log ---------------------------------

--------------------------------- Captured Out ---------------------------------

</system-out><system-err>--------------------------------- Captured Err ---------------------------------

</system-err></testcase><testcase classname="tests.integration.models_images_test.ImageCollectionTest" name="test_save_name_error" time="7.995" /><testcase classname="tests.integration.models_images_test.ImageTest" name="test_tag_and_remove" time="10.016" /><testcase classname="tests.integration.models_networks_test.NetworkCollectionTest" name="test_create" time="8.237" /><testcase classname="tests.integration.models_networks_test.NetworkCollectionTest" name="test_get" time="8.092" /><testcase classname="tests.integration.models_networks_test.NetworkCollectionTest" name="test_list_remove" time="8.439" /><testcase classname="tests.integration.models_networks_test.NetworkTest" name="test_connect_disconnect" time="9.653" /><testcase classname="tests.integration.models_resources_test.ModelTest" name="test_reload" time="9.257" /><testcase classname="tests.integration.models_volumes_test.VolumesTest" name="test_create_get" time="8.194" /><testcase classname="tests.integration.models_volumes_test.VolumesTest" name="test_list_remove" time="8.262" /><testcase classname="tests.integration.regression_test.TestRegressions" name="test_443_handle_nonchunked_response_in_stream" time="12.057"><skipped type="pytest.xfail" message="Docker API always returns chunked resp" /></testcase><testcase classname="tests.integration.regression_test.TestRegressions" name="test_542_truncate_ids_client_side" time="12.667" /><testcase classname="tests.integration.regression_test.TestRegressions" name="test_647_support_doubleslash_in_image_names" time="12.444" /><testcase classname="tests.integration.regression_test.TestRegressions" name="test_649_handle_timeout_value_none" time="12.805" /><testcase classname="tests.integration.regression_test.TestRegressions" name="test_715_handle_user_param_as_int_value" time="13.822" /><testcase classname="tests.integration.regression_test.TestRegressions" name="test_792_explicit_port_protocol" time="12.953" /><testcase classname="tests.integration.credentials.utils_test" name="test_create_environment_dict" time="0.049" /></testsuite></testsuites>