============================= test session starts ==============================
platform linux -- Python 3.8.5, pytest-6.2.2, py-1.10.0, pluggy-0.13.1 -- /home/ubuntu/.virtualenvs/docker-py/bin/python
cachedir: .pytest_cache
rootdir: /home/ubuntu/docker-py, configfile: pytest_podman_apiv2.ini, testpaths: tests/integration/
plugins: cov-2.6.1, timeout-1.3.3
collecting ... collected 415 items / 137 deselected / 278 selected

tests/integration/api_build_test.py::BuildTest::test_build_container_with_target PASSED [  0%]
tests/integration/api_build_test.py::BuildTest::test_build_from_stringio PASSED [  0%]
tests/integration/api_build_test.py::BuildTest::test_build_gzip_custom_encoding PASSED [  1%]
tests/integration/api_build_test.py::BuildTest::test_build_gzip_encoding PASSED [  1%]
tests/integration/api_build_test.py::BuildTest::test_build_in_context_abs_dockerfile FAILED [  1%]
tests/integration/api_build_test.py::BuildTest::test_build_in_context_dockerfile FAILED [  2%]
tests/integration/api_build_test.py::BuildTest::test_build_in_context_nested_dockerfile FAILED [  2%]
tests/integration/api_build_test.py::BuildTest::test_build_invalid_platform FAILED [  2%]
tests/integration/api_build_test.py::BuildTest::test_build_isolation FAILED [  3%]
tests/integration/api_build_test.py::BuildTest::test_build_labels FAILED [  3%]
tests/integration/api_build_test.py::BuildTest::test_build_out_of_context_dockerfile FAILED [  3%]
tests/integration/api_build_test.py::BuildTest::test_build_shmsize PASSED [  4%]
tests/integration/api_build_test.py::BuildTest::test_build_squash FAILED [  4%]
tests/integration/api_build_test.py::BuildTest::test_build_stderr_data FAILED [  5%]
tests/integration/api_build_test.py::BuildTest::test_build_streaming PASSED [  5%]
tests/integration/api_build_test.py::BuildTest::test_build_with_buildargs PASSED [  5%]
tests/integration/api_build_test.py::BuildTest::test_build_with_cache_from FAILED [  6%]
tests/integration/api_build_test.py::BuildTest::test_build_with_dockerfile_empty_lines PASSED [  6%]
tests/integration/api_build_test.py::BuildTest::test_build_with_dockerignore PASSED [  6%]
tests/integration/api_build_test.py::BuildTest::test_build_with_extra_hosts FAILED [  7%]
tests/integration/api_build_test.py::BuildTest::test_build_with_network_mode FAILED [  7%]
tests/integration/api_build_test.py::BuildTest::test_build_with_proxy PASSED [  7%]
tests/integration/api_build_test.py::BuildTest::test_build_with_proxy_and_buildargs PASSED [  8%]
tests/integration/api_build_test.py::BuildTest::test_prune_builds XFAIL  [  8%]
tests/integration/api_client_test.py::InformationTest::test_info PASSED  [  8%]
tests/integration/api_client_test.py::InformationTest::test_version PASSED [  9%]
tests/integration/api_client_test.py::AutoDetectVersionTest::test_client_init PASSED [  9%]
tests/integration/api_client_test.py::ConnectionTimeoutTest::test_timeout PASSED [ 10%]
tests/integration/api_client_test.py::UnixconnTest::test_resource_warnings PASSED [ 10%]
tests/integration/api_container_test.py::ListContainersTest::test_list_containers PASSED [ 10%]
tests/integration/api_container_test.py::CreateContainerTest::test_create PASSED [ 11%]
tests/integration/api_container_test.py::CreateContainerTest::test_create_container_with_volumes_from PASSED [ 11%]
tests/integration/api_container_test.py::CreateContainerTest::test_create_with_auto_remove PASSED [ 11%]
tests/integration/api_container_test.py::CreateContainerTest::test_create_with_cpu_rt_options XPASS [ 12%]
tests/integration/api_container_test.py::CreateContainerTest::test_create_with_device_cgroup_rules FAILED [ 12%]
tests/integration/api_container_test.py::CreateContainerTest::test_create_with_environment_variable_no_value FAILED [ 12%]
tests/integration/api_container_test.py::CreateContainerTest::test_create_with_host_pid_mode PASSED [ 13%]
tests/integration/api_container_test.py::CreateContainerTest::test_create_with_init PASSED [ 13%]
tests/integration/api_container_test.py::CreateContainerTest::test_create_with_isolation FAILED [ 14%]
tests/integration/api_container_test.py::CreateContainerTest::test_create_with_links FAILED [ 14%]
tests/integration/api_container_test.py::CreateContainerTest::test_create_with_mac_address FAILED [ 14%]
tests/integration/api_container_test.py::CreateContainerTest::test_create_with_memory_constraints_with_int PASSED [ 15%]
tests/integration/api_container_test.py::CreateContainerTest::test_create_with_memory_constraints_with_str PASSED [ 15%]
tests/integration/api_container_test.py::CreateContainerTest::test_create_with_restart_policy FAILED [ 15%]
tests/integration/api_container_test.py::CreateContainerTest::test_create_with_stop_timeout PASSED [ 16%]
tests/integration/api_container_test.py::CreateContainerTest::test_create_with_storage_opt XFAIL [ 16%]
tests/integration/api_container_test.py::CreateContainerTest::test_create_with_tmpfs FAILED [ 16%]
tests/integration/api_container_test.py::CreateContainerTest::test_create_with_uts_mode PASSED [ 17%]
tests/integration/api_container_test.py::CreateContainerTest::test_group_id_ints PASSED [ 17%]
tests/integration/api_container_test.py::CreateContainerTest::test_group_id_strings PASSED [ 17%]
tests/integration/api_container_test.py::CreateContainerTest::test_invalid_log_driver_raises_exception FAILED [ 18%]
tests/integration/api_container_test.py::CreateContainerTest::test_valid_log_driver_and_log_opt FAILED [ 18%]
tests/integration/api_container_test.py::CreateContainerTest::test_valid_no_config_specified FAILED [ 19%]
tests/integration/api_container_test.py::CreateContainerTest::test_valid_no_log_driver_specified FAILED [ 19%]
tests/integration/api_container_test.py::VolumeBindTest::test_create_with_binds_ro PASSED [ 19%]
tests/integration/api_container_test.py::VolumeBindTest::test_create_with_binds_rw PASSED [ 20%]
tests/integration/api_container_test.py::VolumeBindTest::test_create_with_mounts PASSED [ 20%]
tests/integration/api_container_test.py::VolumeBindTest::test_create_with_mounts_ro FAILED [ 20%]
tests/integration/api_container_test.py::VolumeBindTest::test_create_with_volume_mount PASSED [ 21%]
tests/integration/api_container_test.py::ArchiveTest::test_copy_directory_to_container PASSED [ 21%]
tests/integration/api_container_test.py::ArchiveTest::test_copy_file_to_container FAILED [ 21%]
tests/integration/api_container_test.py::ArchiveTest::test_get_file_archive_from_container PASSED [ 22%]
tests/integration/api_container_test.py::ArchiveTest::test_get_file_stat_from_container PASSED [ 22%]
tests/integration/api_container_test.py::RenameContainerTest::test_rename_container PASSED [ 23%]
tests/integration/api_container_test.py::StartContainerTest::test_run_shlex_commands PASSED [ 23%]
tests/integration/api_container_test.py::StartContainerTest::test_start_container PASSED [ 23%]
tests/integration/api_container_test.py::StartContainerTest::test_start_container_with_dict_instead_of_id PASSED [ 24%]
tests/integration/api_container_test.py::WaitTest::test_wait PASSED      [ 24%]
tests/integration/api_container_test.py::WaitTest::test_wait_with_condition PASSED [ 24%]
tests/integration/api_container_test.py::WaitTest::test_wait_with_dict_instead_of_id PASSED [ 25%]
tests/integration/api_container_test.py::LogsTest::test_logs PASSED      [ 25%]
tests/integration/api_container_test.py::LogsTest::test_logs_streaming_and_follow PASSED [ 25%]
tests/integration/api_container_test.py::LogsTest::test_logs_streaming_and_follow_and_cancel PASSED [ 26%]
tests/integration/api_container_test.py::LogsTest::test_logs_tail_option PASSED [ 26%]
tests/integration/api_container_test.py::LogsTest::test_logs_with_dict_instead_of_id PASSED [ 26%]
tests/integration/api_container_test.py::LogsTest::test_logs_with_tail_0 PASSED [ 27%]
tests/integration/api_container_test.py::LogsTest::test_logs_with_until PASSED [ 27%]
tests/integration/api_container_test.py::DiffTest::test_diff PASSED      [ 28%]
tests/integration/api_container_test.py::DiffTest::test_diff_with_dict_instead_of_id PASSED [ 28%]
tests/integration/api_container_test.py::StopTest::test_stop PASSED      [ 28%]
tests/integration/api_container_test.py::StopTest::test_stop_with_dict_instead_of_id PASSED [ 29%]
tests/integration/api_container_test.py::KillTest::test_kill PASSED      [ 29%]
tests/integration/api_container_test.py::KillTest::test_kill_with_dict_instead_of_id PASSED [ 29%]
tests/integration/api_container_test.py::KillTest::test_kill_with_signal PASSED [ 30%]
tests/integration/api_container_test.py::KillTest::test_kill_with_signal_integer PASSED [ 30%]
tests/integration/api_container_test.py::KillTest::test_kill_with_signal_name PASSED [ 30%]
tests/integration/api_container_test.py::PortTest::test_port FAILED      [ 31%]
tests/integration/api_container_test.py::ContainerTopTest::test_top XFAIL [ 31%]
tests/integration/api_container_test.py::ContainerTopTest::test_top_with_psargs XFAIL [ 32%]
tests/integration/api_container_test.py::RestartContainerTest::test_restart PASSED [ 32%]
tests/integration/api_container_test.py::RestartContainerTest::test_restart_with_dict_instead_of_id PASSED [ 32%]
tests/integration/api_container_test.py::RestartContainerTest::test_restart_with_low_timeout PASSED [ 33%]
tests/integration/api_container_test.py::RemoveContainerTest::test_remove PASSED [ 33%]
tests/integration/api_container_test.py::RemoveContainerTest::test_remove_with_dict_instead_of_id PASSED [ 33%]
tests/integration/api_container_test.py::AttachContainerTest::test_attach_no_stream FAILED [ 34%]
tests/integration/api_container_test.py::AttachContainerTest::test_attach_stream_and_cancel PASSED [ 34%]
tests/integration/api_container_test.py::AttachContainerTest::test_detach_with_arg PASSED [ 34%]
tests/integration/api_container_test.py::AttachContainerTest::test_detach_with_config_file PASSED [ 35%]
tests/integration/api_container_test.py::AttachContainerTest::test_detach_with_default PASSED [ 35%]
tests/integration/api_container_test.py::AttachContainerTest::test_run_container_reading_socket PASSED [ 35%]
tests/integration/api_container_test.py::AttachContainerTest::test_run_container_streaming PASSED [ 36%]
tests/integration/api_container_test.py::PauseTest::test_pause_unpause FAILED [ 36%]
tests/integration/api_container_test.py::PruneTest::test_prune_containers PASSED [ 37%]
tests/integration/api_container_test.py::GetContainerStatsTest::test_get_container_stats_no_stream PASSED [ 37%]
tests/integration/api_container_test.py::ContainerUpdateTest::test_restart_policy_update FAILED [ 37%]
tests/integration/api_container_test.py::ContainerUpdateTest::test_update_container FAILED [ 38%]
tests/integration/api_container_test.py::ContainerCPUTest::test_container_cpu_shares PASSED [ 38%]
tests/integration/api_container_test.py::ContainerCPUTest::test_container_cpuset PASSED [ 38%]
tests/integration/api_container_test.py::ContainerCPUTest::test_create_with_runtime FAILED [ 39%]
tests/integration/api_container_test.py::LinkTest::test_remove_link FAILED [ 39%]
tests/integration/api_exec_test.py::ExecTest::test_detach_with_config_file FAILED [ 39%]
tests/integration/api_exec_test.py::ExecTest::test_detach_with_default PASSED [ 40%]
tests/integration/api_exec_test.py::ExecTest::test_exec_command_as_root PASSED [ 40%]
tests/integration/api_exec_test.py::ExecTest::test_exec_command_as_user PASSED [ 41%]
tests/integration/api_exec_test.py::ExecTest::test_exec_command_streaming PASSED [ 41%]
tests/integration/api_exec_test.py::ExecTest::test_exec_command_string PASSED [ 41%]
tests/integration/api_exec_test.py::ExecTest::test_exec_command_with_env PASSED [ 42%]
tests/integration/api_exec_test.py::ExecTest::test_exec_command_with_workdir PASSED [ 42%]
tests/integration/api_exec_test.py::ExecTest::test_exec_inspect PASSED   [ 42%]
tests/integration/api_exec_test.py::ExecTest::test_exec_start_detached FAILED [ 43%]
tests/integration/api_exec_test.py::ExecTest::test_exec_start_socket FAILED [ 43%]
tests/integration/api_exec_test.py::ExecTest::test_execute_command PASSED [ 43%]
tests/integration/api_exec_test.py::ExecTest::test_execute_command_with_proxy_env PASSED [ 44%]
tests/integration/api_exec_test.py::ExecDemuxTest::test_exec_command_no_stream_demux PASSED [ 44%]
tests/integration/api_exec_test.py::ExecDemuxTest::test_exec_command_no_stream_no_demux PASSED [ 44%]
tests/integration/api_exec_test.py::ExecDemuxTest::test_exec_command_stream_demux PASSED [ 45%]
tests/integration/api_exec_test.py::ExecDemuxTest::test_exec_command_stream_no_demux PASSED [ 45%]
tests/integration/api_exec_test.py::ExecDemuxTest::test_exec_command_tty_no_stream_demux FAILED [ 46%]
tests/integration/api_exec_test.py::ExecDemuxTest::test_exec_command_tty_no_stream_no_demux FAILED [ 46%]
tests/integration/api_exec_test.py::ExecDemuxTest::test_exec_command_tty_stream_demux FAILED [ 46%]
tests/integration/api_exec_test.py::ExecDemuxTest::test_exec_command_tty_stream_no_demux FAILED [ 47%]
tests/integration/api_healthcheck_test.py::HealthcheckTest::test_healthcheck_fails FAILED [ 47%]
tests/integration/api_healthcheck_test.py::HealthcheckTest::test_healthcheck_passes FAILED [ 47%]
tests/integration/api_healthcheck_test.py::HealthcheckTest::test_healthcheck_shell_command FAILED [ 48%]
tests/integration/api_healthcheck_test.py::HealthcheckTest::test_healthcheck_start_period FAILED [ 48%]
tests/integration/api_image_test.py::ListImagesTest::test_images PASSED  [ 48%]
tests/integration/api_image_test.py::ListImagesTest::test_images_quiet PASSED [ 49%]
tests/integration/api_image_test.py::PullImageTest::test_pull PASSED     [ 49%]
tests/integration/api_image_test.py::PullImageTest::test_pull_invalid_platform FAILED [ 50%]
tests/integration/api_image_test.py::PullImageTest::test_pull_streaming PASSED [ 50%]
tests/integration/api_image_test.py::CommitTest::test_commit FAILED      [ 50%]
tests/integration/api_image_test.py::CommitTest::test_commit_with_changes FAILED [ 51%]
tests/integration/api_image_test.py::RemoveImageTest::test_remove PASSED [ 51%]
tests/integration/api_image_test.py::ImportImageTest::test_get_load_image FAILED [ 51%]
tests/integration/api_image_test.py::ImportImageTest::test_import_from_bytes PASSED [ 52%]
tests/integration/api_image_test.py::ImportImageTest::test_import_from_file PASSED [ 52%]
tests/integration/api_image_test.py::ImportImageTest::test_import_from_stream PASSED [ 52%]
tests/integration/api_image_test.py::ImportImageTest::test_import_from_url SKIPPED [ 53%]
tests/integration/api_image_test.py::ImportImageTest::test_import_image_from_data_with_changes PASSED [ 53%]
tests/integration/api_image_test.py::ImportImageTest::test_import_image_with_changes PASSED [ 53%]
tests/integration/api_image_test.py::PruneImagesTest::test_prune_images FAILED [ 54%]
tests/integration/api_image_test.py::SaveLoadImagesTest::test_get_image_load_image FAILED [ 54%]
tests/integration/api_image_test.py::InspectDistributionTest::test_inspect_distribution FAILED [ 55%]
tests/integration/api_network_test.py::TestNetworks::test_connect_and_disconnect_container FAILED [ 55%]
tests/integration/api_network_test.py::TestNetworks::test_connect_and_force_disconnect_container FAILED [ 55%]
tests/integration/api_network_test.py::TestNetworks::test_connect_on_container_create FAILED [ 56%]
tests/integration/api_network_test.py::TestNetworks::test_connect_with_aliases FAILED [ 56%]
tests/integration/api_network_test.py::TestNetworks::test_connect_with_ipv4_address FAILED [ 56%]
tests/integration/api_network_test.py::TestNetworks::test_connect_with_ipv6_address FAILED [ 57%]
tests/integration/api_network_test.py::TestNetworks::test_connect_with_links FAILED [ 57%]
tests/integration/api_network_test.py::TestNetworks::test_create_check_duplicate FAILED [ 57%]
tests/integration/api_network_test.py::TestNetworks::test_create_internal_networks PASSED [ 58%]
tests/integration/api_network_test.py::TestNetworks::test_create_network_ipv6_enabled FAILED [ 58%]
tests/integration/api_network_test.py::TestNetworks::test_create_network_with_host_driver_fails PASSED [ 58%]
tests/integration/api_network_test.py::TestNetworks::test_create_network_with_ipam_config FAILED [ 59%]
tests/integration/api_network_test.py::TestNetworks::test_create_network_with_labels PASSED [ 59%]
tests/integration/api_network_test.py::TestNetworks::test_create_network_with_labels_wrong_type PASSED [ 60%]
tests/integration/api_network_test.py::TestNetworks::test_create_remove_network_with_space_in_name PASSED [ 60%]
tests/integration/api_network_test.py::TestNetworks::test_create_with_aliases PASSED [ 60%]
tests/integration/api_network_test.py::TestNetworks::test_create_with_driveropt FAILED [ 61%]
tests/integration/api_network_test.py::TestNetworks::test_create_with_ipv4_address FAILED [ 61%]
tests/integration/api_network_test.py::TestNetworks::test_create_with_ipv6_address FAILED [ 61%]
tests/integration/api_network_test.py::TestNetworks::test_create_with_linklocal_ips FAILED [ 62%]
tests/integration/api_network_test.py::TestNetworks::test_create_with_links FAILED [ 62%]
tests/integration/api_network_test.py::TestNetworks::test_inspect_network PASSED [ 62%]
tests/integration/api_network_test.py::TestNetworks::test_list_networks PASSED [ 63%]
tests/integration/api_network_test.py::TestNetworks::test_prune_networks FAILED [ 63%]
tests/integration/api_network_test.py::TestNetworks::test_remove_network PASSED [ 64%]
tests/integration/api_plugin_test.py::PluginTest::test_configure_plugin FAILED [ 64%]
tests/integration/api_plugin_test.py::PluginTest::test_create_plugin FAILED [ 64%]
tests/integration/api_plugin_test.py::PluginTest::test_disable_plugin FAILED [ 65%]
tests/integration/api_plugin_test.py::PluginTest::test_enable_plugin FAILED [ 65%]
tests/integration/api_plugin_test.py::PluginTest::test_force_remove_plugin FAILED [ 65%]
tests/integration/api_plugin_test.py::PluginTest::test_inspect_plugin FAILED [ 66%]
tests/integration/api_plugin_test.py::PluginTest::test_install_plugin FAILED [ 66%]
tests/integration/api_plugin_test.py::PluginTest::test_list_plugins FAILED [ 66%]
tests/integration/api_plugin_test.py::PluginTest::test_plugin_privileges FAILED [ 67%]
tests/integration/api_plugin_test.py::PluginTest::test_remove_plugin FAILED [ 67%]
tests/integration/api_plugin_test.py::PluginTest::test_upgrade_plugin FAILED [ 67%]
tests/integration/api_secret_test.py::SecretAPITest::test_create_secret FAILED [ 68%]
tests/integration/api_secret_test.py::SecretAPITest::test_create_secret_unicode_data FAILED [ 68%]
tests/integration/api_secret_test.py::SecretAPITest::test_inspect_secret FAILED [ 69%]
tests/integration/api_secret_test.py::SecretAPITest::test_list_secrets FAILED [ 69%]
tests/integration/api_secret_test.py::SecretAPITest::test_remove_secret FAILED [ 69%]
tests/integration/api_volume_test.py::TestVolumes::test_create_volume PASSED [ 70%]
tests/integration/api_volume_test.py::TestVolumes::test_create_volume_invalid_driver FAILED [ 70%]
tests/integration/api_volume_test.py::TestVolumes::test_force_remove_volume PASSED [ 70%]
tests/integration/api_volume_test.py::TestVolumes::test_inspect_nonexistent_volume PASSED [ 71%]
tests/integration/api_volume_test.py::TestVolumes::test_inspect_volume FAILED [ 71%]
tests/integration/api_volume_test.py::TestVolumes::test_list_volumes FAILED [ 71%]
tests/integration/api_volume_test.py::TestVolumes::test_prune_volumes PASSED [ 72%]
tests/integration/api_volume_test.py::TestVolumes::test_remove_nonexistent_volume PASSED [ 72%]
tests/integration/api_volume_test.py::TestVolumes::test_remove_volume PASSED [ 73%]
tests/integration/client_test.py::ClientTest::test_df PASSED             [ 73%]
tests/integration/client_test.py::ClientTest::test_info PASSED           [ 73%]
tests/integration/client_test.py::ClientTest::test_ping PASSED           [ 74%]
tests/integration/client_test.py::ClientTest::test_version PASSED        [ 74%]
tests/integration/client_test.py::CancellableEventsTest::test_cancel_events PASSED [ 74%]
tests/integration/context_api_test.py::ContextLifecycleTest::test_context_remove PASSED [ 75%]
tests/integration/context_api_test.py::ContextLifecycleTest::test_lifecycle PASSED [ 75%]
tests/integration/context_api_test.py::ContextLifecycleTest::test_load_context_without_orchestrator PASSED [ 75%]
tests/integration/errors_test.py::ErrorsTest::test_api_error_parses_json FAILED [ 76%]
tests/integration/models_containers_test.py::ContainerCollectionTest::test_get FAILED [ 76%]
tests/integration/models_containers_test.py::ContainerCollectionTest::test_list FAILED [ 76%]
tests/integration/models_containers_test.py::ContainerCollectionTest::test_list_sparse FAILED [ 77%]
tests/integration/models_containers_test.py::ContainerCollectionTest::test_run PASSED [ 77%]
tests/integration/models_containers_test.py::ContainerCollectionTest::test_run_detach FAILED [ 78%]
tests/integration/models_containers_test.py::ContainerCollectionTest::test_run_with_auto_remove PASSED [ 78%]
tests/integration/models_containers_test.py::ContainerCollectionTest::test_run_with_auto_remove_error FAILED [ 78%]
tests/integration/models_containers_test.py::ContainerCollectionTest::test_run_with_error PASSED [ 79%]
tests/integration/models_containers_test.py::ContainerCollectionTest::test_run_with_image_that_does_not_exist FAILED [ 79%]
tests/integration/models_containers_test.py::ContainerCollectionTest::test_run_with_json_file_driver PASSED [ 79%]
tests/integration/models_containers_test.py::ContainerCollectionTest::test_run_with_named_volume PASSED [ 80%]
tests/integration/models_containers_test.py::ContainerCollectionTest::test_run_with_network PASSED [ 80%]
tests/integration/models_containers_test.py::ContainerCollectionTest::test_run_with_none_driver PASSED [ 80%]
tests/integration/models_containers_test.py::ContainerCollectionTest::test_run_with_proxy_config PASSED [ 81%]
tests/integration/models_containers_test.py::ContainerCollectionTest::test_run_with_streamed_logs PASSED [ 81%]
tests/integration/models_containers_test.py::ContainerCollectionTest::test_run_with_streamed_logs_and_cancel PASSED [ 82%]
tests/integration/models_containers_test.py::ContainerCollectionTest::test_run_with_volume PASSED [ 82%]
tests/integration/models_containers_test.py::ContainerTest::test_commit PASSED [ 82%]
tests/integration/models_containers_test.py::ContainerTest::test_create_with_volume_driver FAILED [ 83%]
tests/integration/models_containers_test.py::ContainerTest::test_diff FAILED [ 83%]
tests/integration/models_containers_test.py::ContainerTest::test_exec_run_failed FAILED [ 83%]
tests/integration/models_containers_test.py::ContainerTest::test_exec_run_success PASSED [ 84%]
tests/integration/models_containers_test.py::ContainerTest::test_kill FAILED [ 84%]
tests/integration/models_containers_test.py::ContainerTest::test_logs PASSED [ 84%]
tests/integration/models_containers_test.py::ContainerTest::test_pause FAILED [ 85%]
tests/integration/models_containers_test.py::ContainerTest::test_ports_target_list PASSED [ 85%]
tests/integration/models_containers_test.py::ContainerTest::test_ports_target_none PASSED [ 85%]
tests/integration/models_containers_test.py::ContainerTest::test_ports_target_tuple PASSED [ 86%]
tests/integration/models_containers_test.py::ContainerTest::test_remove PASSED [ 86%]
tests/integration/models_containers_test.py::ContainerTest::test_rename PASSED [ 87%]
tests/integration/models_containers_test.py::ContainerTest::test_restart PASSED [ 87%]
tests/integration/models_containers_test.py::ContainerTest::test_start PASSED [ 87%]
tests/integration/models_containers_test.py::ContainerTest::test_stats PASSED [ 88%]
tests/integration/models_containers_test.py::ContainerTest::test_stop PASSED [ 88%]
tests/integration/models_containers_test.py::ContainerTest::test_top FAILED [ 88%]
tests/integration/models_containers_test.py::ContainerTest::test_update FAILED [ 89%]
tests/integration/models_containers_test.py::ContainerTest::test_wait PASSED [ 89%]
tests/integration/models_images_test.py::ImageCollectionTest::test_build PASSED [ 89%]
tests/integration/models_images_test.py::ImageCollectionTest::test_build_with_error FAILED [ 90%]
tests/integration/models_images_test.py::ImageCollectionTest::test_build_with_multiple_success PASSED [ 90%]
tests/integration/models_images_test.py::ImageCollectionTest::test_build_with_success_build_output PASSED [ 91%]
tests/integration/models_images_test.py::ImageCollectionTest::test_list PASSED [ 91%]
tests/integration/models_images_test.py::ImageCollectionTest::test_list_with_repository PASSED [ 91%]
tests/integration/models_images_test.py::ImageCollectionTest::test_load_error FAILED [ 92%]
tests/integration/models_images_test.py::ImageCollectionTest::test_pull FAILED [ 92%]
tests/integration/models_images_test.py::ImageCollectionTest::test_pull_multiple FAILED [ 92%]
tests/integration/models_images_test.py::ImageCollectionTest::test_pull_with_sha FAILED [ 93%]
tests/integration/models_images_test.py::ImageCollectionTest::test_pull_with_tag FAILED [ 93%]
tests/integration/models_images_test.py::ImageCollectionTest::test_save_and_load PASSED [ 93%]
tests/integration/models_images_test.py::ImageCollectionTest::test_save_and_load_repo_name FAILED [ 94%]
tests/integration/models_images_test.py::ImageCollectionTest::test_save_name_error PASSED [ 94%]
tests/integration/models_images_test.py::ImageTest::test_tag_and_remove PASSED [ 94%]
tests/integration/models_networks_test.py::NetworkCollectionTest::test_create PASSED [ 95%]
tests/integration/models_networks_test.py::NetworkCollectionTest::test_get PASSED [ 95%]
tests/integration/models_networks_test.py::NetworkCollectionTest::test_list_remove FAILED [ 96%]
tests/integration/models_networks_test.py::NetworkTest::test_connect_disconnect FAILED [ 96%]
tests/integration/models_resources_test.py::ModelTest::test_reload PASSED [ 96%]
tests/integration/models_volumes_test.py::VolumesTest::test_create_get PASSED [ 97%]
tests/integration/models_volumes_test.py::VolumesTest::test_list_remove FAILED [ 97%]
tests/integration/regression_test.py::TestRegressions::test_443_handle_nonchunked_response_in_stream FAILED [ 97%]
tests/integration/regression_test.py::TestRegressions::test_542_truncate_ids_client_side PASSED [ 98%]
tests/integration/regression_test.py::TestRegressions::test_647_support_doubleslash_in_image_names PASSED [ 98%]
tests/integration/regression_test.py::TestRegressions::test_649_handle_timeout_value_none PASSED [ 98%]
tests/integration/regression_test.py::TestRegressions::test_715_handle_user_param_as_int_value PASSED [ 99%]
tests/integration/regression_test.py::TestRegressions::test_792_explicit_port_protocol PASSED [ 99%]
tests/integration/credentials/utils_test.py::test_create_environment_dict PASSED [100%]

=================================== FAILURES ===================================
________________ BuildTest.test_build_in_context_abs_dockerfile ________________
/home/riyad/src/docker-py/tests/integration/api_build_test.py:575: in test_build_in_context_abs_dockerfile
    ???
E   AssertionError: assert 'Successfully tagged' in 'Successfully built 249be9f6c2b5\n'
__________________ BuildTest.test_build_in_context_dockerfile __________________
/home/riyad/src/docker-py/tests/integration/api_build_test.py:510: in test_build_in_context_dockerfile
    ???
E   AssertionError: assert 'Successfully tagged' in 'Successfully built 73a18807593b\n'
______________ BuildTest.test_build_in_context_nested_dockerfile _______________
/home/riyad/src/docker-py/tests/integration/api_build_test.py:543: in test_build_in_context_nested_dockerfile
    ???
E   AssertionError: assert 'Successfully tagged' in 'Successfully built 67d74b36378b\n'
____________________ BuildTest.test_build_invalid_platform _____________________
/home/riyad/src/docker-py/tests/integration/api_build_test.py:448: in test_build_invalid_platform
    ???
E   Failed: DID NOT RAISE <class 'docker.errors.APIError'>
________________________ BuildTest.test_build_isolation ________________________
docker/api/client.py:296: in _raise_for_status
    response.raise_for_status()
../.virtualenvs/docker-py/lib/python3.8/site-packages/requests/models.py:940: in raise_for_status
    raise HTTPError(http_error_msg, response=self)
E   requests.exceptions.HTTPError: 400 Client Error: Bad Request for url: http+docker://localhost/v1.40/build?t=isolation&q=False&nocache=False&rm=False&forcerm=False&pull=False&isolation=default

During handling of the above exception, another exception occurred:
/home/riyad/src/docker-py/tests/integration/api_build_test.py:196: in test_build_isolation
    ???
docker/api/client.py:389: in _stream_helper
    yield self._result(response, json=decode)
docker/api/client.py:302: in _result
    self._raise_for_status(response)
docker/api/client.py:298: in _raise_for_status
    raise create_api_error_from_http_exception(e)
docker/errors.py:31: in create_api_error_from_http_exception
    raise cls(e, response=response, explanation=explanation)
E   docker.errors.APIError: 400 Client Error for http+docker://localhost/v1.40/build?t=isolation&q=False&nocache=False&rm=False&forcerm=False&pull=False&isolation=default: Bad Request ("schema: error converting value for "isolation"")
_________________________ BuildTest.test_build_labels __________________________
docker/api/client.py:296: in _raise_for_status
    response.raise_for_status()
../.virtualenvs/docker-py/lib/python3.8/site-packages/requests/models.py:940: in raise_for_status
    raise HTTPError(http_error_msg, response=self)
E   requests.exceptions.HTTPError: 400 Client Error: Bad Request for url: http+docker://localhost/v1.40/build?t=labels&q=False&nocache=False&rm=False&forcerm=False&pull=False&labels=%7B%22test%22%3A+%22OK%22%7D

During handling of the above exception, another exception occurred:
/home/riyad/src/docker-py/tests/integration/api_build_test.py:211: in test_build_labels
    ???
docker/api/client.py:389: in _stream_helper
    yield self._result(response, json=decode)
docker/api/client.py:302: in _result
    self._raise_for_status(response)
docker/api/client.py:298: in _raise_for_status
    raise create_api_error_from_http_exception(e)
docker/errors.py:31: in create_api_error_from_http_exception
    raise cls(e, response=response, explanation=explanation)
E   docker.errors.APIError: 400 Client Error for http+docker://localhost/v1.40/build?t=labels&q=False&nocache=False&rm=False&forcerm=False&pull=False&labels=%7B%22test%22%3A+%22OK%22%7D: Bad Request ("failed to parse query parameter 'labels': "{\"test\": \"OK\"}": json: cannot unmarshal object into Go value of type []string")
________________ BuildTest.test_build_out_of_context_dockerfile ________________
/home/riyad/src/docker-py/tests/integration/api_build_test.py:481: in test_build_out_of_context_dockerfile
    ???
E   KeyError: 'stream'
_________________________ BuildTest.test_build_squash __________________________
/home/riyad/src/docker-py/tests/integration/api_build_test.py:371: in test_build_squash
    ???
E   AssertionError: assert 2 == 4
E     +2
E     -4
_______________________ BuildTest.test_build_stderr_data _______________________
/home/riyad/src/docker-py/tests/integration/api_build_test.py:391: in test_build_stderr_data
    ???
E   AssertionError: assert False
E    +  where False = any([False, False, False, False, False, False, ...])
_____________________ BuildTest.test_build_with_cache_from _____________________
/home/riyad/src/docker-py/tests/integration/api_build_test.py:240: in test_build_with_cache_from
    ???
E   AssertionError: assert 0 == 3
E     +0
E     -3
____________________ BuildTest.test_build_with_extra_hosts _____________________
docker/api/client.py:296: in _raise_for_status
    response.raise_for_status()
../.virtualenvs/docker-py/lib/python3.8/site-packages/requests/models.py:940: in raise_for_status
    raise HTTPError(http_error_msg, response=self)
E   requests.exceptions.HTTPError: 400 Client Error: Bad Request for url: http+docker://localhost/v1.40/build?t=dockerpytest_extrahost_build&q=False&nocache=False&rm=False&forcerm=False&pull=False&extrahosts=extrahost.local.test%3A127.0.0.1&extrahosts=hello.world.test%3A127.0.0.1

During handling of the above exception, another exception occurred:
/home/riyad/src/docker-py/tests/integration/api_build_test.py:336: in test_build_with_extra_hosts
    ???
docker/api/client.py:389: in _stream_helper
    yield self._result(response, json=decode)
docker/api/client.py:302: in _result
    self._raise_for_status(response)
docker/api/client.py:298: in _raise_for_status
    raise create_api_error_from_http_exception(e)
docker/errors.py:31: in create_api_error_from_http_exception
    raise cls(e, response=response, explanation=explanation)
E   docker.errors.APIError: 400 Client Error for http+docker://localhost/v1.40/build?t=dockerpytest_extrahost_build&q=False&nocache=False&rm=False&forcerm=False&pull=False&extrahosts=extrahost.local.test%3A127.0.0.1&extrahosts=hello.world.test%3A127.0.0.1: Bad Request ("failed to parse query parameter 'extrahosts': "hello.world.test:127.0.0.1": invalid character 'h' looking for beginning of value")
____________________ BuildTest.test_build_with_network_mode ____________________
docker/api/client.py:296: in _raise_for_status
    response.raise_for_status()
../.virtualenvs/docker-py/lib/python3.8/site-packages/requests/models.py:940: in raise_for_status
    raise HTTPError(http_error_msg, response=self)
E   requests.exceptions.HTTPError: 500 Server Error: Internal Server Error for url: http+docker://localhost/v1.40/networks/c0cff9b02182fca0fbbdc664446583035579eb00c971d754fce1cc21acdd0f45/connect

During handling of the above exception, another exception occurred:
/home/riyad/src/docker-py/tests/integration/api_build_test.py:283: in test_build_with_network_mode
    ???
docker/utils/decorators.py:19: in wrapped
    return f(self, resource_id, *args, **kwargs)
docker/api/network.py:250: in connect_container_to_network
    self._raise_for_status(res)
docker/api/client.py:298: in _raise_for_status
    raise create_api_error_from_http_exception(e)
docker/errors.py:31: in create_api_error_from_http_exception
    raise cls(e, response=response, explanation=explanation)
E   docker.errors.APIError: 500 Server Error for http+docker://localhost/v1.40/networks/c0cff9b02182fca0fbbdc664446583035579eb00c971d754fce1cc21acdd0f45/connect: Internal Server Error ("network disconnect is not enabled for rootless containers")
___________ CreateContainerTest.test_create_with_device_cgroup_rules ___________
/home/riyad/src/docker-py/tests/integration/api_container_test.py:477: in test_create_with_device_cgroup_rules
    ???
E   AssertionError: assert None == ['c 7:128 rwm']
E     +None
E     -['c 7:128 rwm']
______ CreateContainerTest.test_create_with_environment_variable_no_value ______
/home/riyad/src/docker-py/tests/integration/api_container_test.py:373: in test_create_with_environment_variable_no_value
    ???
E   AssertionError: assert 'Foo' in ['PATH=/usr/local/sbin:/usr/local/bin:/usr/sbin:/usr/bin:/sbin:/bin', 'TERM=xterm', 'container=podman', 'Other=one', 'Blank=']
________________ CreateContainerTest.test_create_with_isolation ________________
/home/riyad/src/docker-py/tests/integration/api_container_test.py:402: in test_create_with_isolation
    ???
E   AssertionError: assert '' == 'default'
E     - default
__________________ CreateContainerTest.test_create_with_links __________________
docker/api/client.py:296: in _raise_for_status
    response.raise_for_status()
../.virtualenvs/docker-py/lib/python3.8/site-packages/requests/models.py:940: in raise_for_status
    raise HTTPError(http_error_msg, response=self)
E   requests.exceptions.HTTPError: 400 Client Error: Bad Request for url: http+docker://localhost/v1.40/containers/create

During handling of the above exception, another exception occurred:
/home/riyad/src/docker-py/tests/integration/api_container_test.py:96: in test_create_with_links
    ???
docker/api/container.py:430: in create_container
    return self.create_container_from_config(config, name)
docker/api/container.py:441: in create_container_from_config
    return self._result(res, True)
docker/api/client.py:302: in _result
    self._raise_for_status(response)
docker/api/client.py:298: in _raise_for_status
    raise create_api_error_from_http_exception(e)
docker/errors.py:31: in create_api_error_from_http_exception
    raise cls(e, response=response, explanation=explanation)
E   docker.errors.APIError: 400 Client Error for http+docker://localhost/v1.40/containers/create: Bad Request ("bad parameter: Link is not supported")
_______________ CreateContainerTest.test_create_with_mac_address _______________
/home/riyad/src/docker-py/tests/integration/api_container_test.py:217: in test_create_with_mac_address
    ???
E   AssertionError: assert '02:42:ac:11:00:0a' == ''
E     + 02:42:ac:11:00:0a
_____________ CreateContainerTest.test_create_with_restart_policy ______________
/home/riyad/src/docker-py/tests/integration/api_container_test.py:127: in test_create_with_restart_policy
    ???
E   Failed: DID NOT RAISE <class 'docker.errors.APIError'>
__________________ CreateContainerTest.test_create_with_tmpfs __________________
/home/riyad/src/docker-py/tests/integration/api_container_test.py:391: in test_create_with_tmpfs
    ???
E   AssertionError: assert {'/tmp1=size=...ev,tmpcopyup'} == {'/tmp1': 'size=3M'}
E     Left contains 1 more item:
E     {'/tmp1=size=3M': 'rw,rprivate,nosuid,nodev,tmpcopyup'}
E     Right contains 1 more item:
E     {'/tmp1': 'size=3M'}
E     Full diff:
E     - {'/tmp1': 'size=3M'}
E     + {'/tmp1=size=3M': 'rw,rprivate,nosuid,nodev,tmpcopyup'}
_________ CreateContainerTest.test_invalid_log_driver_raises_exception _________
/home/riyad/src/docker-py/tests/integration/api_container_test.py:293: in test_invalid_log_driver_raises_exception
    ???
E   AssertionError: assert 'container create: error running container create option: invalid log driver: invalid argument' in ["logger: no log driver named 'asdf' is registered", 'error looking up logging plugin asdf: plugin "asdf" not found']
E    +  where 'container create: error running container create option: invalid log driver: invalid argument' = APIError(HTTPError('500 Server Error: Internal Server Error for url: http+docker://localhost/v1.40/containers/create')).explanation
E    +    where APIError(HTTPError('500 Server Error: Internal Server Error for url: http+docker://localhost/v1.40/containers/create')) = <ExceptionInfo APIError(HTTPError('500 Server Error: Internal Server Error for url: http+docker://localhost/v1.40/containers/create')) tblen=6>.value
____________ CreateContainerTest.test_valid_log_driver_and_log_opt _____________
/home/riyad/src/docker-py/tests/integration/api_container_test.py:272: in test_valid_log_driver_and_log_opt
    ???
E   AssertionError: assert None == {'max-file': '100'}
E     +None
E     -{'max-file': '100'}
______________ CreateContainerTest.test_valid_no_config_specified ______________
/home/riyad/src/docker-py/tests/integration/api_container_test.py:331: in test_valid_no_config_specified
    ???
E   AssertionError: assert None == {}
E     +None
E     -{}
____________ CreateContainerTest.test_valid_no_log_driver_specified ____________
/home/riyad/src/docker-py/tests/integration/api_container_test.py:312: in test_valid_no_log_driver_specified
    ???
E   AssertionError: assert None == {'max-file': '100'}
E     +None
E     -{'max-file': '100'}
__________________ VolumeBindTest.test_create_with_mounts_ro ___________________
/home/riyad/src/docker-py/tests/integration/api_container_test.py:581: in test_create_with_mounts_ro
    ???
/home/riyad/src/docker-py/tests/integration/api_container_test.py:614: in check_container_data
    ???
E   AssertionError: assert True == False
E     +True
E     -False
___________________ ArchiveTest.test_copy_file_to_container ____________________
/home/riyad/src/docker-py/tests/integration/api_container_test.py:689: in test_copy_file_to_container
    ???
E   AssertionError: assert '' == 'Deaf To All But The Song'
E     - Deaf To All But The Song
______________________________ PortTest.test_port ______________________________
docker/api/client.py:296: in _raise_for_status
    response.raise_for_status()
../.virtualenvs/docker-py/lib/python3.8/site-packages/requests/models.py:940: in raise_for_status
    raise HTTPError(http_error_msg, response=self)
E   requests.exceptions.HTTPError: 500 Server Error: Internal Server Error for url: http+docker://localhost/v1.40/containers/01212881d80567365836f9f105ef2517a427a1e9dc3e32ab028a6990387d9894/start

During handling of the above exception, another exception occurred:
/home/riyad/src/docker-py/tests/integration/api_container_test.py:1090: in test_port
    ???
docker/utils/decorators.py:19: in wrapped
    return f(self, resource_id, *args, **kwargs)
docker/api/container.py:1111: in start
    self._raise_for_status(res)
docker/api/client.py:298: in _raise_for_status
    raise create_api_error_from_http_exception(e)
docker/errors.py:31: in create_api_error_from_http_exception
    raise cls(e, response=response, explanation=explanation)
E   docker.errors.APIError: 500 Server Error for http+docker://localhost/v1.40/containers/01212881d80567365836f9f105ef2517a427a1e9dc3e32ab028a6990387d9894/start: Internal Server Error ("command rootless-cni-infra [alloc 01212881d80567365836f9f105ef2517a427a1e9dc3e32ab028a6990387d9894 bridge condescending_meninsky   ] in container 25616a809d12095d3d13679ca21e2736e796a070a099bc7ddeb8bde8fc9199ec failed with status 1, stdout="", stderr="no net configuration with name \"bridge\" in /etc/cni/net.d\n"")
__________________ AttachContainerTest.test_attach_no_stream ___________________
docker/api/client.py:296: in _raise_for_status
    response.raise_for_status()
../.virtualenvs/docker-py/lib/python3.8/site-packages/requests/models.py:940: in raise_for_status
    raise HTTPError(http_error_msg, response=self)
E   requests.exceptions.HTTPError: 500 Server Error: Internal Server Error for url: http+docker://localhost/v1.40/containers/a06517d1f39c2a67d57ced38257c498514f8c34ecc6193b7fad09a770d7fd125/attach?logs=1&stdout=1&stderr=1&stream=0

During handling of the above exception, another exception occurred:
/home/riyad/src/docker-py/tests/integration/api_container_test.py:1251: in test_attach_no_stream
    ???
docker/utils/decorators.py:19: in wrapped
    return f(self, resource_id, *args, **kwargs)
docker/api/container.py:62: in attach
    output = self._read_from_socket(
docker/api/client.py:435: in _read_from_socket
    socket = self._get_raw_response_socket(response)
docker/api/client.py:346: in _get_raw_response_socket
    self._raise_for_status(response)
docker/api/client.py:298: in _raise_for_status
    raise create_api_error_from_http_exception(e)
docker/errors.py:31: in create_api_error_from_http_exception
    raise cls(e, response=response, explanation=explanation)
E   docker.errors.APIError: 500 Server Error for http+docker://localhost/v1.40/containers/a06517d1f39c2a67d57ced38257c498514f8c34ecc6193b7fad09a770d7fd125/attach?logs=1&stdout=1&stderr=1&stream=0: Internal Server Error ("can only attach to created or running containers - currently in state stopped: container state improper")
_________________________ PauseTest.test_pause_unpause _________________________
docker/api/client.py:296: in _raise_for_status
    response.raise_for_status()
../.virtualenvs/docker-py/lib/python3.8/site-packages/requests/models.py:940: in raise_for_status
    raise HTTPError(http_error_msg, response=self)
E   requests.exceptions.HTTPError: 500 Server Error: Internal Server Error for url: http+docker://localhost/v1.40/containers/6c8b57424384a6411d2434c7c20fef52d380fdf73d3a40d0a003fc83cc34c0fe/pause

During handling of the above exception, another exception occurred:
/home/riyad/src/docker-py/tests/integration/api_container_test.py:1336: in test_pause_unpause
    ???
docker/utils/decorators.py:19: in wrapped
    return f(self, resource_id, *args, **kwargs)
docker/api/container.py:892: in pause
    self._raise_for_status(res)
docker/api/client.py:298: in _raise_for_status
    raise create_api_error_from_http_exception(e)
docker/errors.py:31: in create_api_error_from_http_exception
    raise cls(e, response=response, explanation=explanation)
E   docker.errors.APIError: 500 Server Error for http+docker://localhost/v1.40/containers/6c8b57424384a6411d2434c7c20fef52d380fdf73d3a40d0a003fc83cc34c0fe/pause: Internal Server Error ("`/usr/bin/crun pause 6c8b57424384a6411d2434c7c20fef52d380fdf73d3a40d0a003fc83cc34c0fe` failed: exit status 1")
________________ ContainerUpdateTest.test_restart_policy_update ________________
docker/api/client.py:296: in _raise_for_status
    response.raise_for_status()
../.virtualenvs/docker-py/lib/python3.8/site-packages/requests/models.py:940: in raise_for_status
    raise HTTPError(http_error_msg, response=self)
E   requests.exceptions.HTTPError: 404 Client Error: Not Found for url: http+docker://localhost/v1.40/containers/885ddfc3ee71dfc4614216ad1afc3461894d648a4679a255e8cb4226abb4dd0f/update

During handling of the above exception, another exception occurred:
/home/riyad/src/docker-py/tests/integration/api_container_test.py:1438: in test_restart_policy_update
    ???
docker/utils/decorators.py:34: in wrapper
    return f(self, *args, **kwargs)
docker/utils/decorators.py:19: in wrapped
    return f(self, resource_id, *args, **kwargs)
docker/api/container.py:1270: in update_container
    return self._result(res, True)
docker/api/client.py:302: in _result
    self._raise_for_status(response)
docker/api/client.py:298: in _raise_for_status
    raise create_api_error_from_http_exception(e)
docker/errors.py:31: in create_api_error_from_http_exception
    raise cls(e, response=response, explanation=explanation)
E   docker.errors.NotFound: 404 Client Error for http+docker://localhost/v1.40/containers/885ddfc3ee71dfc4614216ad1afc3461894d648a4679a255e8cb4226abb4dd0f/update: Not Found ("b'Not Found'")
__________________ ContainerUpdateTest.test_update_container ___________________
docker/api/client.py:296: in _raise_for_status
    response.raise_for_status()
../.virtualenvs/docker-py/lib/python3.8/site-packages/requests/models.py:940: in raise_for_status
    raise HTTPError(http_error_msg, response=self)
E   requests.exceptions.HTTPError: 404 Client Error: Not Found for url: http+docker://localhost/v1.40/containers/19c77af63035668969f33db851f8b3dc064bba7a023751a27e43c0b77a7e6fa4/update

During handling of the above exception, another exception occurred:
/home/riyad/src/docker-py/tests/integration/api_container_test.py:1416: in test_update_container
    ???
docker/utils/decorators.py:34: in wrapper
    return f(self, *args, **kwargs)
docker/utils/decorators.py:19: in wrapped
    return f(self, resource_id, *args, **kwargs)
docker/api/container.py:1270: in update_container
    return self._result(res, True)
docker/api/client.py:302: in _result
    self._raise_for_status(response)
docker/api/client.py:298: in _raise_for_status
    raise create_api_error_from_http_exception(e)
docker/errors.py:31: in create_api_error_from_http_exception
    raise cls(e, response=response, explanation=explanation)
E   docker.errors.NotFound: 404 Client Error for http+docker://localhost/v1.40/containers/19c77af63035668969f33db851f8b3dc064bba7a023751a27e43c0b77a7e6fa4/update: Not Found ("b'Not Found'")
__________________ ContainerCPUTest.test_create_with_runtime ___________________
/home/riyad/src/docker-py/tests/integration/api_container_test.py:1483: in test_create_with_runtime
    ???
E   AssertionError: assert 'oci' == 'runc'
E     - runc
E     + oci
__________________________ LinkTest.test_remove_link ___________________________
docker/api/client.py:296: in _raise_for_status
    response.raise_for_status()
../.virtualenvs/docker-py/lib/python3.8/site-packages/requests/models.py:940: in raise_for_status
    raise HTTPError(http_error_msg, response=self)
E   requests.exceptions.HTTPError: 400 Client Error: Bad Request for url: http+docker://localhost/v1.40/containers/create

During handling of the above exception, another exception occurred:
/home/riyad/src/docker-py/tests/integration/api_container_test.py:1501: in test_remove_link
    ???
docker/api/container.py:430: in create_container
    return self.create_container_from_config(config, name)
docker/api/container.py:441: in create_container_from_config
    return self._result(res, True)
docker/api/client.py:302: in _result
    self._raise_for_status(response)
docker/api/client.py:298: in _raise_for_status
    raise create_api_error_from_http_exception(e)
docker/errors.py:31: in create_api_error_from_http_exception
    raise cls(e, response=response, explanation=explanation)
E   docker.errors.APIError: 400 Client Error for http+docker://localhost/v1.40/containers/create: Bad Request ("bad parameter: Link is not supported")
____________________ ExecTest.test_detach_with_config_file _____________________
/home/riyad/src/docker-py/tests/integration/api_exec_test.py:227: in test_detach_with_config_file
    ???
tests/helpers.py:138: in assert_cat_socket_detached_with_keys
    assert data == b'' or data.startswith(
E   AssertionError
______________________ ExecTest.test_exec_start_detached _______________________
/home/riyad/src/docker-py/tests/integration/api_exec_test.py:152: in test_exec_start_detached
    ???
E   AssertionError: assert '\n' == ''
E     Strings contain only whitespace, escaping them using repr()
E     - ''
E     + '\n'
_______________________ ExecTest.test_exec_start_socket ________________________
/home/riyad/src/docker-py/tests/integration/api_exec_test.py:134: in test_exec_start_socket
    ???
E   AssertionError: assert 121 == 1
E     +121
E     -1
_____________ ExecDemuxTest.test_exec_command_tty_no_stream_demux ______________
/home/riyad/src/docker-py/tests/integration/api_exec_test.py:299: in test_exec_command_tty_no_stream_demux
    ???
docker/utils/decorators.py:19: in wrapped
    return f(self, resource_id, *args, **kwargs)
docker/api/exec_api.py:169: in exec_start
    return self._read_from_socket(res, stream, tty=tty, demux=demux)
docker/api/client.py:450: in _read_from_socket
    return consume_socket_output(gen, demux=demux)
docker/utils/socket.py:142: in consume_socket_output
    for frame in frames:
docker/api/client.py:441: in <genexpr>
    gen = (demux_adaptor(*frame) for frame in gen)
docker/utils/socket.py:169: in demux_adaptor
    raise ValueError('{0} is not a valid stream'.format(stream_id))
E   ValueError: 104 is not a valid stream
____________ ExecDemuxTest.test_exec_command_tty_no_stream_no_demux ____________
/home/riyad/src/docker-py/tests/integration/api_exec_test.py:282: in test_exec_command_tty_no_stream_no_demux
    ???
E   AssertionError: assert b't\r\nhello err\r\n' == b'hello out\r\nhello err\r\n'
E     At index 0 diff: b't' != b'h'
E     Full diff:
E     - b'hello out\r\nhello err\r\n'
E     ?   --------
E     + b't\r\nhello err\r\n'
_______________ ExecDemuxTest.test_exec_command_tty_stream_demux _______________
/home/riyad/src/docker-py/tests/integration/api_exec_test.py:305: in test_exec_command_tty_stream_demux
    ???
docker/api/client.py:441: in <genexpr>
    gen = (demux_adaptor(*frame) for frame in gen)
docker/utils/socket.py:169: in demux_adaptor
    raise ValueError('{0} is not a valid stream'.format(stream_id))
E   ValueError: 104 is not a valid stream
_____________ ExecDemuxTest.test_exec_command_tty_stream_no_demux ______________
/home/riyad/src/docker-py/tests/integration/api_exec_test.py:288: in test_exec_command_tty_stream_no_demux
    ???
E   AssertionError: assert b'hello out\r\n' in [b't\r\n', b'hello err\r\n']
____________________ HealthcheckTest.test_healthcheck_fails ____________________
/home/riyad/src/docker-py/tests/integration/api_healthcheck_test.py:51: in test_healthcheck_fails
    ???
/home/riyad/src/docker-py/tests/integration/api_healthcheck_test.py:11: in wait_on_health_status
    ???
tests/helpers.py:82: in wait_on_condition
    while not condition():
/home/riyad/src/docker-py/tests/integration/api_healthcheck_test.py:10: in condition
    ???
E   KeyError: 'Health'
___________________ HealthcheckTest.test_healthcheck_passes ____________________
/home/riyad/src/docker-py/tests/integration/api_healthcheck_test.py:38: in test_healthcheck_passes
    ???
/home/riyad/src/docker-py/tests/integration/api_healthcheck_test.py:11: in wait_on_health_status
    ???
tests/helpers.py:82: in wait_on_condition
    while not condition():
/home/riyad/src/docker-py/tests/integration/api_healthcheck_test.py:10: in condition
    ???
E   KeyError: 'Health'
________________ HealthcheckTest.test_healthcheck_shell_command ________________
docker/api/client.py:296: in _raise_for_status
    response.raise_for_status()
../.virtualenvs/docker-py/lib/python3.8/site-packages/requests/models.py:940: in raise_for_status
    raise HTTPError(http_error_msg, response=self)
E   requests.exceptions.HTTPError: 500 Server Error: Internal Server Error for url: http+docker://localhost/v1.40/containers/create

During handling of the above exception, another exception occurred:
/home/riyad/src/docker-py/tests/integration/api_healthcheck_test.py:18: in test_healthcheck_shell_command
    ???
docker/api/container.py:430: in create_container
    return self.create_container_from_config(config, name)
docker/api/container.py:441: in create_container_from_config
    return self._result(res, True)
docker/api/client.py:302: in _result
    self._raise_for_status(response)
docker/api/client.py:298: in _raise_for_status
    raise create_api_error_from_http_exception(e)
docker/errors.py:31: in create_api_error_from_http_exception
    raise cls(e, response=response, explanation=explanation)
E   docker.errors.APIError: 500 Server Error for http+docker://localhost/v1.40/containers/create: Internal Server Error ("fill out specgen: healthcheck-retries must be greater than 0")
________________ HealthcheckTest.test_healthcheck_start_period _________________
/home/riyad/src/docker-py/tests/integration/api_healthcheck_test.py:68: in test_healthcheck_start_period
    ???
/home/riyad/src/docker-py/tests/integration/api_healthcheck_test.py:11: in wait_on_health_status
    ???
tests/helpers.py:82: in wait_on_condition
    while not condition():
/home/riyad/src/docker-py/tests/integration/api_healthcheck_test.py:10: in condition
    ???
E   KeyError: 'Health'
___________________ PullImageTest.test_pull_invalid_platform ___________________
/home/riyad/src/docker-py/tests/integration/api_image_test.py:70: in test_pull_invalid_platform
    ???
E   Failed: DID NOT RAISE <class 'docker.errors.APIError'>
____________________________ CommitTest.test_commit ____________________________
/home/riyad/src/docker-py/tests/integration/api_image_test.py:93: in test_commit
    ???
E   AssertionError: assert 'alpine:3.10' == 'docker.io/li...cb41504e8a27c'
E     - docker.io/library/sha256:be4e4bea2c2e15b403bb321562e78ea84b501fb41497472e91ecb41504e8a27c
E     + alpine:3.10
_____________________ CommitTest.test_commit_with_changes ______________________
docker/api/client.py:296: in _raise_for_status
    response.raise_for_status()
../.virtualenvs/docker-py/lib/python3.8/site-packages/requests/models.py:940: in raise_for_status
    raise HTTPError(http_error_msg, response=self)
E   requests.exceptions.HTTPError: 500 Server Error: Internal Server Error for url: http+docker://localhost/v1.40/commit?container=8e10f044dc8a009813e3aec2b9eca078c43ee9f7ec7a950cf26a5eaa0e338cdf&changes=EXPOSE+8000&changes=CMD+%5B%22bash%22%5D

During handling of the above exception, another exception occurred:
/home/riyad/src/docker-py/tests/integration/api_image_test.py:102: in test_commit_with_changes
    ???
docker/utils/decorators.py:19: in wrapped
    return f(self, resource_id, *args, **kwargs)
docker/api/container.py:147: in commit
    return self._result(
docker/api/client.py:302: in _result
    self._raise_for_status(response)
docker/api/client.py:298: in _raise_for_status
    raise create_api_error_from_http_exception(e)
docker/errors.py:31: in create_api_error_from_http_exception
    raise cls(e, response=response, explanation=explanation)
E   docker.errors.APIError: 500 Server Error for http+docker://localhost/v1.40/commit?container=8e10f044dc8a009813e3aec2b9eca078c43ee9f7ec7a950cf26a5eaa0e338cdf&changes=EXPOSE+8000&changes=CMD+%5B%22bash%22%5D: Internal Server Error ("CommitFailure: invalid change "CMD" - must be formatted as KEY VALUE")
_____________________ ImportImageTest.test_get_load_image ______________________
/home/riyad/src/docker-py/tests/integration/api_image_test.py:267: in test_get_load_image
    ???
E   AssertionError: assert False
E    +  where False = any([])
______________________ PruneImagesTest.test_prune_images _______________________
docker/api/client.py:296: in _raise_for_status
    response.raise_for_status()
../.virtualenvs/docker-py/lib/python3.8/site-packages/requests/models.py:940: in raise_for_status
    raise HTTPError(http_error_msg, response=self)
E   requests.exceptions.HTTPError: 500 Server Error: Internal Server Error for url: http+docker://localhost/v1.40/images/prune?filters=%7B%22dangling%22%3A+%5B%22false%22%5D%7D

During handling of the above exception, another exception occurred:
/home/riyad/src/docker-py/tests/integration/api_image_test.py:332: in test_prune_images
    ???
docker/utils/decorators.py:34: in wrapper
    return f(self, *args, **kwargs)
docker/api/image.py:351: in prune_images
    return self._result(self._post(url, params=params), True)
docker/api/client.py:302: in _result
    self._raise_for_status(response)
docker/api/client.py:298: in _raise_for_status
    raise create_api_error_from_http_exception(e)
docker/errors.py:31: in create_api_error_from_http_exception
    raise cls(e, response=response, explanation=explanation)
E   docker.errors.APIError: 500 Server Error for http+docker://localhost/v1.40/images/prune?filters=%7B%22dangling%22%3A+%5B%22false%22%5D%7D: Internal Server Error ("runtime error: invalid memory address or nil pointer dereference")
_________________ SaveLoadImagesTest.test_get_image_load_image _________________
/home/riyad/src/docker-py/tests/integration/api_image_test.py:361: in test_get_image_load_image
    ???
E   AssertionError: assert False is True
----------------------------- Captured stdout call -----------------------------
{'stream': 'Loaded image: docker.io/library/alpine:3.10\n'}
______________ InspectDistributionTest.test_inspect_distribution _______________
docker/api/client.py:296: in _raise_for_status
    response.raise_for_status()
../.virtualenvs/docker-py/lib/python3.8/site-packages/requests/models.py:940: in raise_for_status
    raise HTTPError(http_error_msg, response=self)
E   requests.exceptions.HTTPError: 404 Client Error: Not Found for url: http+docker://localhost/v1.40/distribution/busybox:latest/json

During handling of the above exception, another exception occurred:
/home/riyad/src/docker-py/tests/integration/api_image_test.py:367: in test_inspect_distribution
    ???
docker/utils/decorators.py:34: in wrapper
    return f(self, *args, **kwargs)
docker/utils/decorators.py:19: in wrapped
    return f(self, resource_id, *args, **kwargs)
docker/api/image.py:289: in inspect_distribution
    return self._result(
docker/api/client.py:302: in _result
    self._raise_for_status(response)
docker/api/client.py:298: in _raise_for_status
    raise create_api_error_from_http_exception(e)
docker/errors.py:31: in create_api_error_from_http_exception
    raise cls(e, response=response, explanation=explanation)
E   docker.errors.NotFound: 404 Client Error for http+docker://localhost/v1.40/distribution/busybox:latest/json: Not Found ("Path /v1.40/distribution/busybox:latest/json is not supported")
______________ TestNetworks.test_connect_and_disconnect_container ______________
docker/api/client.py:296: in _raise_for_status
    response.raise_for_status()
../.virtualenvs/docker-py/lib/python3.8/site-packages/requests/models.py:940: in raise_for_status
    raise HTTPError(http_error_msg, response=self)
E   requests.exceptions.HTTPError: 500 Server Error: Internal Server Error for url: http+docker://localhost/v1.40/networks/b592ac046a2b313cdb4c3ac8668e48cea9275fd10ac5ac640f78c47294e8edfc/connect

During handling of the above exception, another exception occurred:
/home/riyad/src/docker-py/tests/integration/api_network_test.py:98: in test_connect_and_disconnect_container
    ???
docker/utils/decorators.py:19: in wrapped
    return f(self, resource_id, *args, **kwargs)
docker/api/network.py:250: in connect_container_to_network
    self._raise_for_status(res)
docker/api/client.py:298: in _raise_for_status
    raise create_api_error_from_http_exception(e)
docker/errors.py:31: in create_api_error_from_http_exception
    raise cls(e, response=response, explanation=explanation)
E   docker.errors.APIError: 500 Server Error for http+docker://localhost/v1.40/networks/b592ac046a2b313cdb4c3ac8668e48cea9275fd10ac5ac640f78c47294e8edfc/connect: Internal Server Error ("network disconnect is not enabled for rootless containers")
___________ TestNetworks.test_connect_and_force_disconnect_container ___________
docker/api/client.py:296: in _raise_for_status
    response.raise_for_status()
../.virtualenvs/docker-py/lib/python3.8/site-packages/requests/models.py:940: in raise_for_status
    raise HTTPError(http_error_msg, response=self)
E   requests.exceptions.HTTPError: 500 Server Error: Internal Server Error for url: http+docker://localhost/v1.40/networks/bce7cc626aebd46e97307a07908d335120028d139e0f9b0890c2121c435680b0/connect

During handling of the above exception, another exception occurred:
/home/riyad/src/docker-py/tests/integration/api_network_test.py:125: in test_connect_and_force_disconnect_container
    ???
docker/utils/decorators.py:19: in wrapped
    return f(self, resource_id, *args, **kwargs)
docker/api/network.py:250: in connect_container_to_network
    self._raise_for_status(res)
docker/api/client.py:298: in _raise_for_status
    raise create_api_error_from_http_exception(e)
docker/errors.py:31: in create_api_error_from_http_exception
    raise cls(e, response=response, explanation=explanation)
E   docker.errors.APIError: 500 Server Error for http+docker://localhost/v1.40/networks/bce7cc626aebd46e97307a07908d335120028d139e0f9b0890c2121c435680b0/connect: Internal Server Error ("network disconnect is not enabled for rootless containers")
________________ TestNetworks.test_connect_on_container_create _________________
docker/api/client.py:296: in _raise_for_status
    response.raise_for_status()
../.virtualenvs/docker-py/lib/python3.8/site-packages/requests/models.py:940: in raise_for_status
    raise HTTPError(http_error_msg, response=self)
E   requests.exceptions.HTTPError: 500 Server Error: Internal Server Error for url: http+docker://localhost/v1.40/networks/9738710845450773cc344dd5491676033ed3ee1444489d069520bda8c802897c/disconnect

During handling of the above exception, another exception occurred:
/home/riyad/src/docker-py/tests/integration/api_network_test.py:171: in test_connect_on_container_create
    ???
docker/utils/decorators.py:19: in wrapped
    return f(self, resource_id, *args, **kwargs)
docker/api/network.py:274: in disconnect_container_from_network
    self._raise_for_status(res)
docker/api/client.py:298: in _raise_for_status
    raise create_api_error_from_http_exception(e)
docker/errors.py:31: in create_api_error_from_http_exception
    raise cls(e, response=response, explanation=explanation)
E   docker.errors.APIError: 500 Server Error for http+docker://localhost/v1.40/networks/9738710845450773cc344dd5491676033ed3ee1444489d069520bda8c802897c/disconnect: Internal Server Error ("network connect is not enabled for rootless containers")
____________________ TestNetworks.test_connect_with_aliases ____________________
docker/api/client.py:296: in _raise_for_status
    response.raise_for_status()
../.virtualenvs/docker-py/lib/python3.8/site-packages/requests/models.py:940: in raise_for_status
    raise HTTPError(http_error_msg, response=self)
E   requests.exceptions.HTTPError: 500 Server Error: Internal Server Error for url: http+docker://localhost/v1.40/networks/36f68ee5dfe1d142bf3a470a3b2603b80a6608e2234f0459b3d33307ae5d76d6/connect

During handling of the above exception, another exception occurred:
/home/riyad/src/docker-py/tests/integration/api_network_test.py:147: in test_connect_with_aliases
    ???
docker/utils/decorators.py:19: in wrapped
    return f(self, resource_id, *args, **kwargs)
docker/api/network.py:250: in connect_container_to_network
    self._raise_for_status(res)
docker/api/client.py:298: in _raise_for_status
    raise create_api_error_from_http_exception(e)
docker/errors.py:31: in create_api_error_from_http_exception
    raise cls(e, response=response, explanation=explanation)
E   docker.errors.APIError: 500 Server Error for http+docker://localhost/v1.40/networks/36f68ee5dfe1d142bf3a470a3b2603b80a6608e2234f0459b3d33307ae5d76d6/connect: Internal Server Error ("network disconnect is not enabled for rootless containers")
_________________ TestNetworks.test_connect_with_ipv4_address __________________
docker/api/client.py:296: in _raise_for_status
    response.raise_for_status()
../.virtualenvs/docker-py/lib/python3.8/site-packages/requests/models.py:940: in raise_for_status
    raise HTTPError(http_error_msg, response=self)
E   requests.exceptions.HTTPError: 500 Server Error: Internal Server Error for url: http+docker://localhost/v1.40/containers/a59d12acba1e2fe0c1ff000f823924b4f08e631bc3fb2345bbe412589e186835/start

During handling of the above exception, another exception occurred:
/home/riyad/src/docker-py/tests/integration/api_network_test.py:369: in test_connect_with_ipv4_address
    ???
tests/integration/base.py:115: in create_and_start
    self.client.start(container)
docker/utils/decorators.py:19: in wrapped
    return f(self, resource_id, *args, **kwargs)
docker/api/container.py:1111: in start
    self._raise_for_status(res)
docker/api/client.py:298: in _raise_for_status
    raise create_api_error_from_http_exception(e)
docker/errors.py:31: in create_api_error_from_http_exception
    raise cls(e, response=response, explanation=explanation)
E   docker.errors.APIError: 500 Server Error for http+docker://localhost/v1.40/containers/a59d12acba1e2fe0c1ff000f823924b4f08e631bc3fb2345bbe412589e186835/start: Internal Server Error ("command rootless-cni-infra [alloc a59d12acba1e2fe0c1ff000f823924b4f08e631bc3fb2345bbe412589e186835 dockerpytest_516680373e66dc01 determined_curran   ] in container 25616a809d12095d3d13679ca21e2736e796a070a099bc7ddeb8bde8fc9199ec failed with status 1, stdout="", stderr="failed to set bridge addr: \"cni-podman1\" already has an IP address different from 172.28.5.254/16\n"")
_________________ TestNetworks.test_connect_with_ipv6_address __________________
docker/api/client.py:296: in _raise_for_status
    response.raise_for_status()
../.virtualenvs/docker-py/lib/python3.8/site-packages/requests/models.py:940: in raise_for_status
    raise HTTPError(http_error_msg, response=self)
E   requests.exceptions.HTTPError: 500 Server Error: Internal Server Error for url: http+docker://localhost/v1.40/containers/4307522c329a682ee1afd04898795b83e4aa44dffd20bf5e25ae05c407d4d871/start

During handling of the above exception, another exception occurred:
/home/riyad/src/docker-py/tests/integration/api_network_test.py:395: in test_connect_with_ipv6_address
    ???
tests/integration/base.py:115: in create_and_start
    self.client.start(container)
docker/utils/decorators.py:19: in wrapped
    return f(self, resource_id, *args, **kwargs)
docker/api/container.py:1111: in start
    self._raise_for_status(res)
docker/api/client.py:298: in _raise_for_status
    raise create_api_error_from_http_exception(e)
docker/errors.py:31: in create_api_error_from_http_exception
    raise cls(e, response=response, explanation=explanation)
E   docker.errors.APIError: 500 Server Error for http+docker://localhost/v1.40/containers/4307522c329a682ee1afd04898795b83e4aa44dffd20bf5e25ae05c407d4d871/start: Internal Server Error ("command rootless-cni-infra [alloc 4307522c329a682ee1afd04898795b83e4aa44dffd20bf5e25ae05c407d4d871 dockerpytest_17672c53d872dc86 vigorous_liskov   ] in container 25616a809d12095d3d13679ca21e2736e796a070a099bc7ddeb8bde8fc9199ec failed with status 1, stdout="", stderr="failed to list chains: running [/sbin/ip6tables -t nat -S --wait]: exit status 3: modprobe: can't change directory to '/lib/modules': No such file or directory\nip6tables v1.8.4 (legacy): can't initialize ip6tables table `nat': Table does not exist (do you need to insmod?)\nPerhaps ip6tables or your kernel needs to be upgraded.\n\n"")
_____________________ TestNetworks.test_connect_with_links _____________________
docker/api/client.py:296: in _raise_for_status
    response.raise_for_status()
../.virtualenvs/docker-py/lib/python3.8/site-packages/requests/models.py:940: in raise_for_status
    raise HTTPError(http_error_msg, response=self)
E   requests.exceptions.HTTPError: 500 Server Error: Internal Server Error for url: http+docker://localhost/v1.40/networks/dockerpytest_93ed478d9dfb93c1/disconnect

During handling of the above exception, another exception occurred:
/home/riyad/src/docker-py/tests/integration/api_network_test.py:336: in test_connect_with_links
    ???
docker/utils/decorators.py:19: in wrapped
    return f(self, resource_id, *args, **kwargs)
docker/api/network.py:274: in disconnect_container_from_network
    self._raise_for_status(res)
docker/api/client.py:298: in _raise_for_status
    raise create_api_error_from_http_exception(e)
docker/errors.py:31: in create_api_error_from_http_exception
    raise cls(e, response=response, explanation=explanation)
E   docker.errors.APIError: 500 Server Error for http+docker://localhost/v1.40/networks/dockerpytest_93ed478d9dfb93c1/disconnect: Internal Server Error ("network connect is not enabled for rootless containers")
___________________ TestNetworks.test_create_check_duplicate ___________________
docker/api/client.py:296: in _raise_for_status
    response.raise_for_status()
../.virtualenvs/docker-py/lib/python3.8/site-packages/requests/models.py:940: in raise_for_status
    raise HTTPError(http_error_msg, response=self)
E   requests.exceptions.HTTPError: 500 Server Error: Internal Server Error for url: http+docker://localhost/v1.40/networks/create

During handling of the above exception, another exception occurred:
/home/riyad/src/docker-py/tests/integration/api_network_test.py:326: in test_create_check_duplicate
    ???
docker/api/network.py:153: in create_network
    return self._result(res, json=True)
docker/api/client.py:302: in _result
    self._raise_for_status(response)
docker/api/client.py:298: in _raise_for_status
    raise create_api_error_from_http_exception(e)
docker/errors.py:31: in create_api_error_from_http_exception
    raise cls(e, response=response, explanation=explanation)
E   docker.errors.APIError: 500 Server Error for http+docker://localhost/v1.40/networks/create: Internal Server Error ("the network name dockerpytest_eeba8b797411b619 is already used")
________________ TestNetworks.test_create_network_ipv6_enabled _________________
/home/riyad/src/docker-py/tests/integration/api_network_test.py:445: in test_create_network_ipv6_enabled
    ???
E   AssertionError: assert False is True
______________ TestNetworks.test_create_network_with_ipam_config _______________
/home/riyad/src/docker-py/tests/integration/api_network_test.py:66: in test_create_network_with_ipam_config
    ???
E   AssertionError: assert [{'Gateway': ...2.28.0.0/16'}] == [{'AuxiliaryA...2.28.0.0/16'}]
E     At index 0 diff: {'Subnet': '172.28.0.0/16', 'Gateway': '172.28.5.254'} != {'Subnet': '172.28.0.0/16', 'IPRange': '172.28.5.0/24', 'Gateway': '172.28.5.254', 'AuxiliaryAddresses': {'a': '172.28.1.5', 'b': '172.28.1.6', 'c': '172.28.1.7'}}
E     Full diff:
E       [
E     -  {'AuxiliaryAddresses': {'a': '172.28.1.5',
E     -                          'b': '172.28.1.6',
E     -                          'c': '172.28.1.7'},
E     -   'Gateway': '172.28.5.254',...
E     
E     ...Full output truncated (7 lines hidden), use '-vv' to show
___________________ TestNetworks.test_create_with_driveropt ____________________
docker/api/client.py:296: in _raise_for_status
    response.raise_for_status()
../.virtualenvs/docker-py/lib/python3.8/site-packages/requests/models.py:940: in raise_for_status
    raise HTTPError(http_error_msg, response=self)
E   requests.exceptions.HTTPError: 500 Server Error: Internal Server Error for url: http+docker://localhost/v1.40/containers/b1f922d6de7e16a7bbd34bea99ad4b6dd68d2cc3ebcdd27ac21d678088a2ec7c/start

During handling of the above exception, another exception occurred:
/home/riyad/src/docker-py/tests/integration/api_network_test.py:288: in test_create_with_driveropt
    ???
docker/utils/decorators.py:19: in wrapped
    return f(self, resource_id, *args, **kwargs)
docker/api/container.py:1111: in start
    self._raise_for_status(res)
docker/api/client.py:298: in _raise_for_status
    raise create_api_error_from_http_exception(e)
docker/errors.py:31: in create_api_error_from_http_exception
    raise cls(e, response=response, explanation=explanation)
E   docker.errors.APIError: 500 Server Error for http+docker://localhost/v1.40/containers/b1f922d6de7e16a7bbd34bea99ad4b6dd68d2cc3ebcdd27ac21d678088a2ec7c/start: Internal Server Error ("command rootless-cni-infra [alloc b1f922d6de7e16a7bbd34bea99ad4b6dd68d2cc3ebcdd27ac21d678088a2ec7c bridge loving_wozniak   ] in container 25616a809d12095d3d13679ca21e2736e796a070a099bc7ddeb8bde8fc9199ec failed with status 1, stdout="", stderr="no net configuration with name \"bridge\" in /etc/cni/net.d\n"")
__________________ TestNetworks.test_create_with_ipv4_address __________________
docker/api/client.py:296: in _raise_for_status
    response.raise_for_status()
../.virtualenvs/docker-py/lib/python3.8/site-packages/requests/models.py:940: in raise_for_status
    raise HTTPError(http_error_msg, response=self)
E   requests.exceptions.HTTPError: 500 Server Error: Internal Server Error for url: http+docker://localhost/v1.40/containers/ce5ebd32312a1e02443e09a8b686d6bf48e8647c76223fc42c6e53c87072dd23/start

During handling of the above exception, another exception occurred:
/home/riyad/src/docker-py/tests/integration/api_network_test.py:219: in test_create_with_ipv4_address
    ???
docker/utils/decorators.py:19: in wrapped
    return f(self, resource_id, *args, **kwargs)
docker/api/container.py:1111: in start
    self._raise_for_status(res)
docker/api/client.py:298: in _raise_for_status
    raise create_api_error_from_http_exception(e)
docker/errors.py:31: in create_api_error_from_http_exception
    raise cls(e, response=response, explanation=explanation)
E   docker.errors.APIError: 500 Server Error for http+docker://localhost/v1.40/containers/ce5ebd32312a1e02443e09a8b686d6bf48e8647c76223fc42c6e53c87072dd23/start: Internal Server Error ("command rootless-cni-infra [alloc ce5ebd32312a1e02443e09a8b686d6bf48e8647c76223fc42c6e53c87072dd23 dockerpytest_7d811448c87475ea trusting_pasteur   ] in container 25616a809d12095d3d13679ca21e2736e796a070a099bc7ddeb8bde8fc9199ec failed with status 1, stdout="", stderr="failed to set bridge addr: \"cni-podman1\" already has an IP address different from 132.124.0.1/16\n"")
__________________ TestNetworks.test_create_with_ipv6_address __________________
docker/api/client.py:296: in _raise_for_status
    response.raise_for_status()
../.virtualenvs/docker-py/lib/python3.8/site-packages/requests/models.py:940: in raise_for_status
    raise HTTPError(http_error_msg, response=self)
E   requests.exceptions.HTTPError: 500 Server Error: Internal Server Error for url: http+docker://localhost/v1.40/containers/e9a265921754578e4b1630f45ef2869f563f4583ed69e56edc0268fa9660851b/start

During handling of the above exception, another exception occurred:
/home/riyad/src/docker-py/tests/integration/api_network_test.py:245: in test_create_with_ipv6_address
    ???
docker/utils/decorators.py:19: in wrapped
    return f(self, resource_id, *args, **kwargs)
docker/api/container.py:1111: in start
    self._raise_for_status(res)
docker/api/client.py:298: in _raise_for_status
    raise create_api_error_from_http_exception(e)
docker/errors.py:31: in create_api_error_from_http_exception
    raise cls(e, response=response, explanation=explanation)
E   docker.errors.APIError: 500 Server Error for http+docker://localhost/v1.40/containers/e9a265921754578e4b1630f45ef2869f563f4583ed69e56edc0268fa9660851b/start: Internal Server Error ("command rootless-cni-infra [alloc e9a265921754578e4b1630f45ef2869f563f4583ed69e56edc0268fa9660851b dockerpytest_2b0a14c2fc68dd6a crazy_perlman   ] in container 25616a809d12095d3d13679ca21e2736e796a070a099bc7ddeb8bde8fc9199ec failed with status 1, stdout="", stderr="failed to set bridge addr: \"cni-podman1\" already has an IP address different from 2001:389::1/64\n"")
_________________ TestNetworks.test_create_with_linklocal_ips __________________
docker/api/client.py:296: in _raise_for_status
    response.raise_for_status()
../.virtualenvs/docker-py/lib/python3.8/site-packages/requests/models.py:940: in raise_for_status
    raise HTTPError(http_error_msg, response=self)
E   requests.exceptions.HTTPError: 500 Server Error: Internal Server Error for url: http+docker://localhost/v1.40/containers/056a3f0a7504ab3f7ccaa7da7306cab824a99ee4f339958ba7e264c461af2fc9/start

During handling of the above exception, another exception occurred:
/home/riyad/src/docker-py/tests/integration/api_network_test.py:267: in test_create_with_linklocal_ips
    ???
docker/utils/decorators.py:19: in wrapped
    return f(self, resource_id, *args, **kwargs)
docker/api/container.py:1111: in start
    self._raise_for_status(res)
docker/api/client.py:298: in _raise_for_status
    raise create_api_error_from_http_exception(e)
docker/errors.py:31: in create_api_error_from_http_exception
    raise cls(e, response=response, explanation=explanation)
E   docker.errors.APIError: 500 Server Error for http+docker://localhost/v1.40/containers/056a3f0a7504ab3f7ccaa7da7306cab824a99ee4f339958ba7e264c461af2fc9/start: Internal Server Error ("command rootless-cni-infra [alloc 056a3f0a7504ab3f7ccaa7da7306cab824a99ee4f339958ba7e264c461af2fc9 bridge unruffled_mccarthy   ] in container 25616a809d12095d3d13679ca21e2736e796a070a099bc7ddeb8bde8fc9199ec failed with status 1, stdout="", stderr="no net configuration with name \"bridge\" in /etc/cni/net.d\n"")
_____________________ TestNetworks.test_create_with_links ______________________
/home/riyad/src/docker-py/tests/integration/api_network_test.py:311: in test_create_with_links
    ???
E   AssertionError: assert None == ['docker-py-t...upstream:bar']
E     +None
E     -['docker-py-test-upstream:bar']
_______________________ TestNetworks.test_prune_networks _______________________
docker/api/client.py:296: in _raise_for_status
    response.raise_for_status()
../.virtualenvs/docker-py/lib/python3.8/site-packages/requests/models.py:940: in raise_for_status
    raise HTTPError(http_error_msg, response=self)
E   requests.exceptions.HTTPError: 404 Client Error: Not Found for url: http+docker://localhost/v1.40/networks/prune

During handling of the above exception, another exception occurred:
/home/riyad/src/docker-py/tests/integration/api_network_test.py:450: in test_prune_networks
    ???
docker/utils/decorators.py:34: in wrapper
    return f(self, *args, **kwargs)
docker/api/network.py:175: in prune_networks
    return self._result(self._post(url, params=params), True)
docker/api/client.py:302: in _result
    self._raise_for_status(response)
docker/api/client.py:298: in _raise_for_status
    raise create_api_error_from_http_exception(e)
docker/errors.py:31: in create_api_error_from_http_exception
    raise cls(e, response=response, explanation=explanation)
E   docker.errors.NotFound: 404 Client Error for http+docker://localhost/v1.40/networks/prune: Not Found ("Path /v1.40/networks/prune is not supported")
_______________________ PluginTest.test_configure_plugin _______________________
docker/api/client.py:296: in _raise_for_status
    response.raise_for_status()
../.virtualenvs/docker-py/lib/python3.8/site-packages/requests/models.py:940: in raise_for_status
    raise HTTPError(http_error_msg, response=self)
E   requests.exceptions.HTTPError: 404 Client Error: Not Found for url: http+docker://localhost/v1.40/plugins/vieux/sshfs:latest/json

During handling of the above exception, another exception occurred:
/home/riyad/src/docker-py/tests/integration/api_plugin_test.py:39: in ensure_plugin_installed
    ???
docker/utils/decorators.py:34: in wrapper
    return f(self, *args, **kwargs)
docker/api/plugin.py:104: in inspect_plugin
    return self._result(self._get(url), True)
docker/api/client.py:302: in _result
    self._raise_for_status(response)
docker/api/client.py:298: in _raise_for_status
    raise create_api_error_from_http_exception(e)
docker/errors.py:31: in create_api_error_from_http_exception
    raise cls(e, response=response, explanation=explanation)
E   docker.errors.NotFound: 404 Client Error for http+docker://localhost/v1.40/plugins/vieux/sshfs:latest/json: Not Found ("b'Not Found'")

During handling of the above exception, another exception occurred:
docker/api/client.py:296: in _raise_for_status
    response.raise_for_status()
../.virtualenvs/docker-py/lib/python3.8/site-packages/requests/models.py:940: in raise_for_status
    raise HTTPError(http_error_msg, response=self)
E   requests.exceptions.HTTPError: 404 Client Error: Not Found for url: http+docker://localhost/v1.40/plugins/privileges?remote=vieux%2Fsshfs%3Alatest

During handling of the above exception, another exception occurred:
/home/riyad/src/docker-py/tests/integration/api_plugin_test.py:90: in test_configure_plugin
    ???
/home/riyad/src/docker-py/tests/integration/api_plugin_test.py:41: in ensure_plugin_installed
    ???
docker/utils/decorators.py:34: in wrapper
    return f(self, *args, **kwargs)
docker/api/plugin.py:180: in plugin_privileges
    return self._result(
docker/api/client.py:302: in _result
    self._raise_for_status(response)
docker/api/client.py:298: in _raise_for_status
    raise create_api_error_from_http_exception(e)
docker/errors.py:31: in create_api_error_from_http_exception
    raise cls(e, response=response, explanation=explanation)
E   docker.errors.NotFound: 404 Client Error for http+docker://localhost/v1.40/plugins/privileges?remote=vieux%2Fsshfs%3Alatest: Not Found ("b'Not Found'")
________________________ PluginTest.test_create_plugin _________________________
docker/api/client.py:296: in _raise_for_status
    response.raise_for_status()
../.virtualenvs/docker-py/lib/python3.8/site-packages/requests/models.py:940: in raise_for_status
    raise HTTPError(http_error_msg, response=self)
E   requests.exceptions.HTTPError: 404 Client Error: Not Found for url: http+docker://localhost/v1.40/plugins/create?name=docker-sdk-py%2Fdummy

During handling of the above exception, another exception occurred:
/home/riyad/src/docker-py/tests/integration/api_plugin_test.py:140: in test_create_plugin
    ???
docker/utils/decorators.py:34: in wrapper
    return f(self, *args, **kwargs)
docker/api/plugin.py:52: in create_plugin
    self._raise_for_status(res)
docker/api/client.py:298: in _raise_for_status
    raise create_api_error_from_http_exception(e)
docker/errors.py:31: in create_api_error_from_http_exception
    raise cls(e, response=response, explanation=explanation)
E   docker.errors.NotFound: 404 Client Error for http+docker://localhost/v1.40/plugins/create?name=docker-sdk-py%2Fdummy: Not Found ("b'Not Found'")
________________________ PluginTest.test_disable_plugin ________________________
docker/api/client.py:296: in _raise_for_status
    response.raise_for_status()
../.virtualenvs/docker-py/lib/python3.8/site-packages/requests/models.py:940: in raise_for_status
    raise HTTPError(http_error_msg, response=self)
E   requests.exceptions.HTTPError: 404 Client Error: Not Found for url: http+docker://localhost/v1.40/plugins/vieux/sshfs:latest/json

During handling of the above exception, another exception occurred:
/home/riyad/src/docker-py/tests/integration/api_plugin_test.py:39: in ensure_plugin_installed
    ???
docker/utils/decorators.py:34: in wrapper
    return f(self, *args, **kwargs)
docker/api/plugin.py:104: in inspect_plugin
    return self._result(self._get(url), True)
docker/api/client.py:302: in _result
    self._raise_for_status(response)
docker/api/client.py:298: in _raise_for_status
    raise create_api_error_from_http_exception(e)
docker/errors.py:31: in create_api_error_from_http_exception
    raise cls(e, response=response, explanation=explanation)
E   docker.errors.NotFound: 404 Client Error for http+docker://localhost/v1.40/plugins/vieux/sshfs:latest/json: Not Found ("b'Not Found'")

During handling of the above exception, another exception occurred:
docker/api/client.py:296: in _raise_for_status
    response.raise_for_status()
../.virtualenvs/docker-py/lib/python3.8/site-packages/requests/models.py:940: in raise_for_status
    raise HTTPError(http_error_msg, response=self)
E   requests.exceptions.HTTPError: 404 Client Error: Not Found for url: http+docker://localhost/v1.40/plugins/privileges?remote=vieux%2Fsshfs%3Alatest

During handling of the above exception, another exception occurred:
/home/riyad/src/docker-py/tests/integration/api_plugin_test.py:56: in test_disable_plugin
    ???
/home/riyad/src/docker-py/tests/integration/api_plugin_test.py:41: in ensure_plugin_installed
    ???
docker/utils/decorators.py:34: in wrapper
    return f(self, *args, **kwargs)
docker/api/plugin.py:180: in plugin_privileges
    return self._result(
docker/api/client.py:302: in _result
    self._raise_for_status(response)
docker/api/client.py:298: in _raise_for_status
    raise create_api_error_from_http_exception(e)
docker/errors.py:31: in create_api_error_from_http_exception
    raise cls(e, response=response, explanation=explanation)
E   docker.errors.NotFound: 404 Client Error for http+docker://localhost/v1.40/plugins/privileges?remote=vieux%2Fsshfs%3Alatest: Not Found ("b'Not Found'")
________________________ PluginTest.test_enable_plugin _________________________
docker/api/client.py:296: in _raise_for_status
    response.raise_for_status()
../.virtualenvs/docker-py/lib/python3.8/site-packages/requests/models.py:940: in raise_for_status
    raise HTTPError(http_error_msg, response=self)
E   requests.exceptions.HTTPError: 404 Client Error: Not Found for url: http+docker://localhost/v1.40/plugins/vieux/sshfs:latest/json

During handling of the above exception, another exception occurred:
/home/riyad/src/docker-py/tests/integration/api_plugin_test.py:39: in ensure_plugin_installed
    ???
docker/utils/decorators.py:34: in wrapper
    return f(self, *args, **kwargs)
docker/api/plugin.py:104: in inspect_plugin
    return self._result(self._get(url), True)
docker/api/client.py:302: in _result
    self._raise_for_status(response)
docker/api/client.py:298: in _raise_for_status
    raise create_api_error_from_http_exception(e)
docker/errors.py:31: in create_api_error_from_http_exception
    raise cls(e, response=response, explanation=explanation)
E   docker.errors.NotFound: 404 Client Error for http+docker://localhost/v1.40/plugins/vieux/sshfs:latest/json: Not Found ("b'Not Found'")

During handling of the above exception, another exception occurred:
docker/api/client.py:296: in _raise_for_status
    response.raise_for_status()
../.virtualenvs/docker-py/lib/python3.8/site-packages/requests/models.py:940: in raise_for_status
    raise HTTPError(http_error_msg, response=self)
E   requests.exceptions.HTTPError: 404 Client Error: Not Found for url: http+docker://localhost/v1.40/plugins/privileges?remote=vieux%2Fsshfs%3Alatest

During handling of the above exception, another exception occurred:
/home/riyad/src/docker-py/tests/integration/api_plugin_test.py:47: in test_enable_plugin
    ???
/home/riyad/src/docker-py/tests/integration/api_plugin_test.py:41: in ensure_plugin_installed
    ???
docker/utils/decorators.py:34: in wrapper
    return f(self, *args, **kwargs)
docker/api/plugin.py:180: in plugin_privileges
    return self._result(
docker/api/client.py:302: in _result
    self._raise_for_status(response)
docker/api/client.py:298: in _raise_for_status
    raise create_api_error_from_http_exception(e)
docker/errors.py:31: in create_api_error_from_http_exception
    raise cls(e, response=response, explanation=explanation)
E   docker.errors.NotFound: 404 Client Error for http+docker://localhost/v1.40/plugins/privileges?remote=vieux%2Fsshfs%3Alatest: Not Found ("b'Not Found'")
_____________________ PluginTest.test_force_remove_plugin ______________________
docker/api/client.py:296: in _raise_for_status
    response.raise_for_status()
../.virtualenvs/docker-py/lib/python3.8/site-packages/requests/models.py:940: in raise_for_status
    raise HTTPError(http_error_msg, response=self)
E   requests.exceptions.HTTPError: 404 Client Error: Not Found for url: http+docker://localhost/v1.40/plugins/vieux/sshfs:latest/json

During handling of the above exception, another exception occurred:
/home/riyad/src/docker-py/tests/integration/api_plugin_test.py:39: in ensure_plugin_installed
    ???
docker/utils/decorators.py:34: in wrapper
    return f(self, *args, **kwargs)
docker/api/plugin.py:104: in inspect_plugin
    return self._result(self._get(url), True)
docker/api/client.py:302: in _result
    self._raise_for_status(response)
docker/api/client.py:298: in _raise_for_status
    raise create_api_error_from_http_exception(e)
docker/errors.py:31: in create_api_error_from_http_exception
    raise cls(e, response=response, explanation=explanation)
E   docker.errors.NotFound: 404 Client Error for http+docker://localhost/v1.40/plugins/vieux/sshfs:latest/json: Not Found ("b'Not Found'")

During handling of the above exception, another exception occurred:
docker/api/client.py:296: in _raise_for_status
    response.raise_for_status()
../.virtualenvs/docker-py/lib/python3.8/site-packages/requests/models.py:940: in raise_for_status
    raise HTTPError(http_error_msg, response=self)
E   requests.exceptions.HTTPError: 404 Client Error: Not Found for url: http+docker://localhost/v1.40/plugins/privileges?remote=vieux%2Fsshfs%3Alatest

During handling of the above exception, another exception occurred:
/home/riyad/src/docker-py/tests/integration/api_plugin_test.py:109: in test_force_remove_plugin
    ???
/home/riyad/src/docker-py/tests/integration/api_plugin_test.py:41: in ensure_plugin_installed
    ???
docker/utils/decorators.py:34: in wrapper
    return f(self, *args, **kwargs)
docker/api/plugin.py:180: in plugin_privileges
    return self._result(
docker/api/client.py:302: in _result
    self._raise_for_status(response)
docker/api/client.py:298: in _raise_for_status
    raise create_api_error_from_http_exception(e)
docker/errors.py:31: in create_api_error_from_http_exception
    raise cls(e, response=response, explanation=explanation)
E   docker.errors.NotFound: 404 Client Error for http+docker://localhost/v1.40/plugins/privileges?remote=vieux%2Fsshfs%3Alatest: Not Found ("b'Not Found'")
________________________ PluginTest.test_inspect_plugin ________________________
docker/api/client.py:296: in _raise_for_status
    response.raise_for_status()
../.virtualenvs/docker-py/lib/python3.8/site-packages/requests/models.py:940: in raise_for_status
    raise HTTPError(http_error_msg, response=self)
E   requests.exceptions.HTTPError: 404 Client Error: Not Found for url: http+docker://localhost/v1.40/plugins/vieux/sshfs:latest/json

During handling of the above exception, another exception occurred:
/home/riyad/src/docker-py/tests/integration/api_plugin_test.py:39: in ensure_plugin_installed
    ???
docker/utils/decorators.py:34: in wrapper
    return f(self, *args, **kwargs)
docker/api/plugin.py:104: in inspect_plugin
    return self._result(self._get(url), True)
docker/api/client.py:302: in _result
    self._raise_for_status(response)
docker/api/client.py:298: in _raise_for_status
    raise create_api_error_from_http_exception(e)
docker/errors.py:31: in create_api_error_from_http_exception
    raise cls(e, response=response, explanation=explanation)
E   docker.errors.NotFound: 404 Client Error for http+docker://localhost/v1.40/plugins/vieux/sshfs:latest/json: Not Found ("b'Not Found'")

During handling of the above exception, another exception occurred:
docker/api/client.py:296: in _raise_for_status
    response.raise_for_status()
../.virtualenvs/docker-py/lib/python3.8/site-packages/requests/models.py:940: in raise_for_status
    raise HTTPError(http_error_msg, response=self)
E   requests.exceptions.HTTPError: 404 Client Error: Not Found for url: http+docker://localhost/v1.40/plugins/privileges?remote=vieux%2Fsshfs%3Alatest

During handling of the above exception, another exception occurred:
/home/riyad/src/docker-py/tests/integration/api_plugin_test.py:68: in test_inspect_plugin
    ???
/home/riyad/src/docker-py/tests/integration/api_plugin_test.py:41: in ensure_plugin_installed
    ???
docker/utils/decorators.py:34: in wrapper
    return f(self, *args, **kwargs)
docker/api/plugin.py:180: in plugin_privileges
    return self._result(
docker/api/client.py:302: in _result
    self._raise_for_status(response)
docker/api/client.py:298: in _raise_for_status
    raise create_api_error_from_http_exception(e)
docker/errors.py:31: in create_api_error_from_http_exception
    raise cls(e, response=response, explanation=explanation)
E   docker.errors.NotFound: 404 Client Error for http+docker://localhost/v1.40/plugins/privileges?remote=vieux%2Fsshfs%3Alatest: Not Found ("b'Not Found'")
________________________ PluginTest.test_install_plugin ________________________
docker/api/client.py:296: in _raise_for_status
    response.raise_for_status()
../.virtualenvs/docker-py/lib/python3.8/site-packages/requests/models.py:940: in raise_for_status
    raise HTTPError(http_error_msg, response=self)
E   requests.exceptions.HTTPError: 404 Client Error: Not Found for url: http+docker://localhost/v1.40/plugins/privileges?remote=vieux%2Fsshfs%3Alatest

During handling of the above exception, another exception occurred:
/home/riyad/src/docker-py/tests/integration/api_plugin_test.py:120: in test_install_plugin
    ???
docker/utils/decorators.py:34: in wrapper
    return f(self, *args, **kwargs)
docker/api/plugin.py:180: in plugin_privileges
    return self._result(
docker/api/client.py:302: in _result
    self._raise_for_status(response)
docker/api/client.py:298: in _raise_for_status
    raise create_api_error_from_http_exception(e)
docker/errors.py:31: in create_api_error_from_http_exception
    raise cls(e, response=response, explanation=explanation)
E   docker.errors.NotFound: 404 Client Error for http+docker://localhost/v1.40/plugins/privileges?remote=vieux%2Fsshfs%3Alatest: Not Found ("b'Not Found'")
_________________________ PluginTest.test_list_plugins _________________________
docker/api/client.py:296: in _raise_for_status
    response.raise_for_status()
../.virtualenvs/docker-py/lib/python3.8/site-packages/requests/models.py:940: in raise_for_status
    raise HTTPError(http_error_msg, response=self)
E   requests.exceptions.HTTPError: 404 Client Error: Not Found for url: http+docker://localhost/v1.40/plugins/vieux/sshfs:latest/json

During handling of the above exception, another exception occurred:
/home/riyad/src/docker-py/tests/integration/api_plugin_test.py:39: in ensure_plugin_installed
    ???
docker/utils/decorators.py:34: in wrapper
    return f(self, *args, **kwargs)
docker/api/plugin.py:104: in inspect_plugin
    return self._result(self._get(url), True)
docker/api/client.py:302: in _result
    self._raise_for_status(response)
docker/api/client.py:298: in _raise_for_status
    raise create_api_error_from_http_exception(e)
docker/errors.py:31: in create_api_error_from_http_exception
    raise cls(e, response=response, explanation=explanation)
E   docker.errors.NotFound: 404 Client Error for http+docker://localhost/v1.40/plugins/vieux/sshfs:latest/json: Not Found ("b'Not Found'")

During handling of the above exception, another exception occurred:
docker/api/client.py:296: in _raise_for_status
    response.raise_for_status()
../.virtualenvs/docker-py/lib/python3.8/site-packages/requests/models.py:940: in raise_for_status
    raise HTTPError(http_error_msg, response=self)
E   requests.exceptions.HTTPError: 404 Client Error: Not Found for url: http+docker://localhost/v1.40/plugins/privileges?remote=vieux%2Fsshfs%3Alatest

During handling of the above exception, another exception occurred:
/home/riyad/src/docker-py/tests/integration/api_plugin_test.py:83: in test_list_plugins
    ???
/home/riyad/src/docker-py/tests/integration/api_plugin_test.py:41: in ensure_plugin_installed
    ???
docker/utils/decorators.py:34: in wrapper
    return f(self, *args, **kwargs)
docker/api/plugin.py:180: in plugin_privileges
    return self._result(
docker/api/client.py:302: in _result
    self._raise_for_status(response)
docker/api/client.py:298: in _raise_for_status
    raise create_api_error_from_http_exception(e)
docker/errors.py:31: in create_api_error_from_http_exception
    raise cls(e, response=response, explanation=explanation)
E   docker.errors.NotFound: 404 Client Error for http+docker://localhost/v1.40/plugins/privileges?remote=vieux%2Fsshfs%3Alatest: Not Found ("b'Not Found'")
______________________ PluginTest.test_plugin_privileges _______________________
docker/api/client.py:296: in _raise_for_status
    response.raise_for_status()
../.virtualenvs/docker-py/lib/python3.8/site-packages/requests/models.py:940: in raise_for_status
    raise HTTPError(http_error_msg, response=self)
E   requests.exceptions.HTTPError: 404 Client Error: Not Found for url: http+docker://localhost/v1.40/plugins/privileges?remote=vieux%2Fsshfs%3Alatest

During handling of the above exception, another exception occurred:
/home/riyad/src/docker-py/tests/integration/api_plugin_test.py:75: in test_plugin_privileges
    ???
docker/utils/decorators.py:34: in wrapper
    return f(self, *args, **kwargs)
docker/api/plugin.py:180: in plugin_privileges
    return self._result(
docker/api/client.py:302: in _result
    self._raise_for_status(response)
docker/api/client.py:298: in _raise_for_status
    raise create_api_error_from_http_exception(e)
docker/errors.py:31: in create_api_error_from_http_exception
    raise cls(e, response=response, explanation=explanation)
E   docker.errors.NotFound: 404 Client Error for http+docker://localhost/v1.40/plugins/privileges?remote=vieux%2Fsshfs%3Alatest: Not Found ("b'Not Found'")
________________________ PluginTest.test_remove_plugin _________________________
docker/api/client.py:296: in _raise_for_status
    response.raise_for_status()
../.virtualenvs/docker-py/lib/python3.8/site-packages/requests/models.py:940: in raise_for_status
    raise HTTPError(http_error_msg, response=self)
E   requests.exceptions.HTTPError: 404 Client Error: Not Found for url: http+docker://localhost/v1.40/plugins/vieux/sshfs:latest/json

During handling of the above exception, another exception occurred:
/home/riyad/src/docker-py/tests/integration/api_plugin_test.py:39: in ensure_plugin_installed
    ???
docker/utils/decorators.py:34: in wrapper
    return f(self, *args, **kwargs)
docker/api/plugin.py:104: in inspect_plugin
    return self._result(self._get(url), True)
docker/api/client.py:302: in _result
    self._raise_for_status(response)
docker/api/client.py:298: in _raise_for_status
    raise create_api_error_from_http_exception(e)
docker/errors.py:31: in create_api_error_from_http_exception
    raise cls(e, response=response, explanation=explanation)
E   docker.errors.NotFound: 404 Client Error for http+docker://localhost/v1.40/plugins/vieux/sshfs:latest/json: Not Found ("b'Not Found'")

During handling of the above exception, another exception occurred:
docker/api/client.py:296: in _raise_for_status
    response.raise_for_status()
../.virtualenvs/docker-py/lib/python3.8/site-packages/requests/models.py:940: in raise_for_status
    raise HTTPError(http_error_msg, response=self)
E   requests.exceptions.HTTPError: 404 Client Error: Not Found for url: http+docker://localhost/v1.40/plugins/privileges?remote=vieux%2Fsshfs%3Alatest

During handling of the above exception, another exception occurred:
/home/riyad/src/docker-py/tests/integration/api_plugin_test.py:104: in test_remove_plugin
    ???
/home/riyad/src/docker-py/tests/integration/api_plugin_test.py:41: in ensure_plugin_installed
    ???
docker/utils/decorators.py:34: in wrapper
    return f(self, *args, **kwargs)
docker/api/plugin.py:180: in plugin_privileges
    return self._result(
docker/api/client.py:302: in _result
    self._raise_for_status(response)
docker/api/client.py:298: in _raise_for_status
    raise create_api_error_from_http_exception(e)
docker/errors.py:31: in create_api_error_from_http_exception
    raise cls(e, response=response, explanation=explanation)
E   docker.errors.NotFound: 404 Client Error for http+docker://localhost/v1.40/plugins/privileges?remote=vieux%2Fsshfs%3Alatest: Not Found ("b'Not Found'")
________________________ PluginTest.test_upgrade_plugin ________________________
docker/api/client.py:296: in _raise_for_status
    response.raise_for_status()
../.virtualenvs/docker-py/lib/python3.8/site-packages/requests/models.py:940: in raise_for_status
    raise HTTPError(http_error_msg, response=self)
E   requests.exceptions.HTTPError: 404 Client Error: Not Found for url: http+docker://localhost/v1.40/plugins/vieux/sshfs:latest/json

During handling of the above exception, another exception occurred:
/home/riyad/src/docker-py/tests/integration/api_plugin_test.py:39: in ensure_plugin_installed
    ???
docker/utils/decorators.py:34: in wrapper
    return f(self, *args, **kwargs)
docker/api/plugin.py:104: in inspect_plugin
    return self._result(self._get(url), True)
docker/api/client.py:302: in _result
    self._raise_for_status(response)
docker/api/client.py:298: in _raise_for_status
    raise create_api_error_from_http_exception(e)
docker/errors.py:31: in create_api_error_from_http_exception
    raise cls(e, response=response, explanation=explanation)
E   docker.errors.NotFound: 404 Client Error for http+docker://localhost/v1.40/plugins/vieux/sshfs:latest/json: Not Found ("b'Not Found'")

During handling of the above exception, another exception occurred:
docker/api/client.py:296: in _raise_for_status
    response.raise_for_status()
../.virtualenvs/docker-py/lib/python3.8/site-packages/requests/models.py:940: in raise_for_status
    raise HTTPError(http_error_msg, response=self)
E   requests.exceptions.HTTPError: 404 Client Error: Not Found for url: http+docker://localhost/v1.40/plugins/privileges?remote=vieux%2Fsshfs%3Alatest

During handling of the above exception, another exception occurred:
/home/riyad/src/docker-py/tests/integration/api_plugin_test.py:128: in test_upgrade_plugin
    ???
/home/riyad/src/docker-py/tests/integration/api_plugin_test.py:41: in ensure_plugin_installed
    ???
docker/utils/decorators.py:34: in wrapper
    return f(self, *args, **kwargs)
docker/api/plugin.py:180: in plugin_privileges
    return self._result(
docker/api/client.py:302: in _result
    self._raise_for_status(response)
docker/api/client.py:298: in _raise_for_status
    raise create_api_error_from_http_exception(e)
docker/errors.py:31: in create_api_error_from_http_exception
    raise cls(e, response=response, explanation=explanation)
E   docker.errors.NotFound: 404 Client Error for http+docker://localhost/v1.40/plugins/privileges?remote=vieux%2Fsshfs%3Alatest: Not Found ("b'Not Found'")
_______________________ SecretAPITest.test_create_secret _______________________
docker/api/client.py:296: in _raise_for_status
    response.raise_for_status()
../.virtualenvs/docker-py/lib/python3.8/site-packages/requests/models.py:940: in raise_for_status
    raise HTTPError(http_error_msg, response=self)
E   requests.exceptions.HTTPError: 503 Server Error: Service Unavailable for url: http+docker://localhost/v1.40/secrets/create

During handling of the above exception, another exception occurred:
/home/riyad/src/docker-py/tests/integration/api_secret_test.py:32: in test_create_secret
    ???
docker/utils/decorators.py:34: in wrapper
    return f(self, *args, **kwargs)
docker/api/secret.py:45: in create_secret
    return self._result(
docker/api/client.py:302: in _result
    self._raise_for_status(response)
docker/api/client.py:298: in _raise_for_status
    raise create_api_error_from_http_exception(e)
docker/errors.py:31: in create_api_error_from_http_exception
    raise cls(e, response=response, explanation=explanation)
E   docker.errors.APIError: 503 Server Error for http+docker://localhost/v1.40/secrets/create: Service Unavailable ("Podman does not support service: /v1.40/secrets/create")
________________ SecretAPITest.test_create_secret_unicode_data _________________
docker/api/client.py:296: in _raise_for_status
    response.raise_for_status()
../.virtualenvs/docker-py/lib/python3.8/site-packages/requests/models.py:940: in raise_for_status
    raise HTTPError(http_error_msg, response=self)
E   requests.exceptions.HTTPError: 503 Server Error: Service Unavailable for url: http+docker://localhost/v1.40/secrets/create

During handling of the above exception, another exception occurred:
/home/riyad/src/docker-py/tests/integration/api_secret_test.py:41: in test_create_secret_unicode_data
    ???
docker/utils/decorators.py:34: in wrapper
    return f(self, *args, **kwargs)
docker/api/secret.py:45: in create_secret
    return self._result(
docker/api/client.py:302: in _result
    self._raise_for_status(response)
docker/api/client.py:298: in _raise_for_status
    raise create_api_error_from_http_exception(e)
docker/errors.py:31: in create_api_error_from_http_exception
    raise cls(e, response=response, explanation=explanation)
E   docker.errors.APIError: 503 Server Error for http+docker://localhost/v1.40/secrets/create: Service Unavailable ("Podman does not support service: /v1.40/secrets/create")
______________________ SecretAPITest.test_inspect_secret _______________________
docker/api/client.py:296: in _raise_for_status
    response.raise_for_status()
../.virtualenvs/docker-py/lib/python3.8/site-packages/requests/models.py:940: in raise_for_status
    raise HTTPError(http_error_msg, response=self)
E   requests.exceptions.HTTPError: 503 Server Error: Service Unavailable for url: http+docker://localhost/v1.40/secrets/create

During handling of the above exception, another exception occurred:
/home/riyad/src/docker-py/tests/integration/api_secret_test.py:51: in test_inspect_secret
    ???
docker/utils/decorators.py:34: in wrapper
    return f(self, *args, **kwargs)
docker/api/secret.py:45: in create_secret
    return self._result(
docker/api/client.py:302: in _result
    self._raise_for_status(response)
docker/api/client.py:298: in _raise_for_status
    raise create_api_error_from_http_exception(e)
docker/errors.py:31: in create_api_error_from_http_exception
    raise cls(e, response=response, explanation=explanation)
E   docker.errors.APIError: 503 Server Error for http+docker://localhost/v1.40/secrets/create: Service Unavailable ("Podman does not support service: /v1.40/secrets/create")
_______________________ SecretAPITest.test_list_secrets ________________________
docker/api/client.py:296: in _raise_for_status
    response.raise_for_status()
../.virtualenvs/docker-py/lib/python3.8/site-packages/requests/models.py:940: in raise_for_status
    raise HTTPError(http_error_msg, response=self)
E   requests.exceptions.HTTPError: 503 Server Error: Service Unavailable for url: http+docker://localhost/v1.40/secrets/create

During handling of the above exception, another exception occurred:
/home/riyad/src/docker-py/tests/integration/api_secret_test.py:73: in test_list_secrets
    ???
docker/utils/decorators.py:34: in wrapper
    return f(self, *args, **kwargs)
docker/api/secret.py:45: in create_secret
    return self._result(
docker/api/client.py:302: in _result
    self._raise_for_status(response)
docker/api/client.py:298: in _raise_for_status
    raise create_api_error_from_http_exception(e)
docker/errors.py:31: in create_api_error_from_http_exception
    raise cls(e, response=response, explanation=explanation)
E   docker.errors.APIError: 503 Server Error for http+docker://localhost/v1.40/secrets/create: Service Unavailable ("Podman does not support service: /v1.40/secrets/create")
_______________________ SecretAPITest.test_remove_secret _______________________
docker/api/client.py:296: in _raise_for_status
    response.raise_for_status()
../.virtualenvs/docker-py/lib/python3.8/site-packages/requests/models.py:940: in raise_for_status
    raise HTTPError(http_error_msg, response=self)
E   requests.exceptions.HTTPError: 503 Server Error: Service Unavailable for url: http+docker://localhost/v1.40/secrets/create

During handling of the above exception, another exception occurred:
/home/riyad/src/docker-py/tests/integration/api_secret_test.py:62: in test_remove_secret
    ???
docker/utils/decorators.py:34: in wrapper
    return f(self, *args, **kwargs)
docker/api/secret.py:45: in create_secret
    return self._result(
docker/api/client.py:302: in _result
    self._raise_for_status(response)
docker/api/client.py:298: in _raise_for_status
    raise create_api_error_from_http_exception(e)
docker/errors.py:31: in create_api_error_from_http_exception
    raise cls(e, response=response, explanation=explanation)
E   docker.errors.APIError: 503 Server Error for http+docker://localhost/v1.40/secrets/create: Service Unavailable ("Podman does not support service: /v1.40/secrets/create")
________________ TestVolumes.test_create_volume_invalid_driver _________________
docker/api/client.py:296: in _raise_for_status
    response.raise_for_status()
../.virtualenvs/docker-py/lib/python3.8/site-packages/requests/models.py:940: in raise_for_status
    raise HTTPError(http_error_msg, response=self)
E   requests.exceptions.HTTPError: 500 Server Error: Internal Server Error for url: http+docker://localhost/v1.40/volumes/create

During handling of the above exception, another exception occurred:
/home/riyad/src/docker-py/tests/integration/api_volume_test.py:22: in test_create_volume_invalid_driver
    ???
docker/api/volume.py:89: in create_volume
    return self._result(self._post_json(url, data=data), True)
docker/api/client.py:302: in _result
    self._raise_for_status(response)
docker/api/client.py:298: in _raise_for_status
    raise create_api_error_from_http_exception(e)
docker/errors.py:31: in create_api_error_from_http_exception
    raise cls(e, response=response, explanation=explanation)
E   docker.errors.APIError: 500 Server Error for http+docker://localhost/v1.40/volumes/create: Internal Server Error ("volume perfectcherryblossom uses volume plugin invalid.driver but it could not be retrieved: no volume plugin with name invalid.driver available: required plugin missing")
_______________________ TestVolumes.test_inspect_volume ________________________
/home/riyad/src/docker-py/tests/integration/api_volume_test.py:38: in test_inspect_volume
    ???
E   AssertionError: assert {'CreatedAt':...l/_data', ...} == {'CreatedAt':...l/_data', ...}
E     Omitting 6 identical items, use -vv to show
E     Differing items:
E     {'Options': None} != {'Options': {}}
E     Full diff:
E       {
E        'CreatedAt': '2021-02-22T14:56:51Z',
E        'Driver': 'local',...
E     
E     ...Full output truncated (10 lines hidden), use '-vv' to show
________________________ TestVolumes.test_list_volumes _________________________
/home/riyad/src/docker-py/tests/integration/api_volume_test.py:31: in test_list_volumes
    ???
E   AssertionError: assert {'CreatedAt': '2021-02-22T14:56:52Z', 'Driver': 'local', 'Labels': {}, 'Mountpoint': '/home/ubuntu/.local/share/containers/storage/volumes/imperishablenight/_data', ...} in [{'CreatedAt': '2021-02-22T14:16:39Z', 'Driver': 'local', 'Labels': {}, 'Mountpoint': '/home/ubuntu/.local/share/conta...r': 'local', 'Labels': {}, 'Mountpoint': '/home/ubuntu/.local/share/containers/storage/volumes/somevolume/_data', ...}]
____________________ ErrorsTest.test_api_error_parses_json _____________________
/home/riyad/src/docker-py/tests/integration/errors_test.py:13: in test_api_error_parses_json
    ???
E   AssertionError: assert 'You cannot remove a running container' in 'cannot remove container 7d6e43f8f1415d5101a754998012d0eac5bad90abecd4aa522f3b90655b3c744 as it is running - running or paused containers cannot be removed without force: container state improper'
_______________________ ContainerCollectionTest.test_get _______________________
/home/riyad/src/docker-py/tests/integration/models_containers_test.py:189: in test_get
    ???
E   AssertionError: assert 'docker.io/li...alpine:latest' == 'alpine'
E     - alpine
E     + docker.io/library/alpine:latest
______________________ ContainerCollectionTest.test_list _______________________
/home/riyad/src/docker-py/tests/integration/models_containers_test.py:202: in test_list
    ???
E   AssertionError: assert 'docker.io/li...alpine:latest' == 'alpine'
E     - alpine
E     + docker.io/library/alpine:latest
___________________ ContainerCollectionTest.test_list_sparse ___________________
/home/riyad/src/docker-py/tests/integration/models_containers_test.py:220: in test_list_sparse
    ???
E   AssertionError: assert 'docker.io/li...alpine:latest' == 'alpine'
E     - alpine
E     + docker.io/library/alpine:latest
___________________ ContainerCollectionTest.test_run_detach ____________________
/home/riyad/src/docker-py/tests/integration/models_containers_test.py:26: in test_run_detach
    ???
E   AssertionError: assert 'docker.io/li...alpine:latest' == 'alpine'
E     - alpine
E     + docker.io/library/alpine:latest
___________ ContainerCollectionTest.test_run_with_auto_remove_error ____________
docker/api/client.py:296: in _raise_for_status
    response.raise_for_status()
../.virtualenvs/docker-py/lib/python3.8/site-packages/requests/models.py:940: in raise_for_status
    raise HTTPError(http_error_msg, response=self)
E   requests.exceptions.HTTPError: 404 Client Error: Not Found for url: http+docker://localhost/v1.40/containers/d0d24c796a302ca32825808ef66b139de0630975a08e101737b81b0edd757af8/json

During handling of the above exception, another exception occurred:
/home/riyad/src/docker-py/tests/integration/models_containers_test.py:139: in test_run_with_auto_remove_error
    ???
docker/models/containers.py:827: in run
    out = container.logs(
docker/models/containers.py:306: in logs
    return self.client.api.logs(self.id, **kwargs)
docker/utils/decorators.py:19: in wrapped
    return f(self, resource_id, *args, **kwargs)
docker/api/container.py:871: in logs
    output = self._get_result(container, stream, res)
docker/api/client.py:486: in _get_result
    return self._get_result_tty(stream, res, self._check_is_tty(container))
docker/utils/decorators.py:19: in wrapped
    return f(self, resource_id, *args, **kwargs)
docker/api/client.py:482: in _check_is_tty
    cont = self.inspect_container(container)
docker/utils/decorators.py:19: in wrapped
    return f(self, resource_id, *args, **kwargs)
docker/api/container.py:773: in inspect_container
    return self._result(
docker/api/client.py:302: in _result
    self._raise_for_status(response)
docker/api/client.py:298: in _raise_for_status
    raise create_api_error_from_http_exception(e)
docker/errors.py:31: in create_api_error_from_http_exception
    raise cls(e, response=response, explanation=explanation)
E   docker.errors.NotFound: 404 Client Error for http+docker://localhost/v1.40/containers/d0d24c796a302ca32825808ef66b139de0630975a08e101737b81b0edd757af8/json: Not Found ("no container with name or ID d0d24c796a302ca32825808ef66b139de0630975a08e101737b81b0edd757af8 found: no such container")
_______ ContainerCollectionTest.test_run_with_image_that_does_not_exist ________
docker/api/client.py:296: in _raise_for_status
    response.raise_for_status()
../.virtualenvs/docker-py/lib/python3.8/site-packages/requests/models.py:940: in raise_for_status
    raise HTTPError(http_error_msg, response=self)
E   requests.exceptions.HTTPError: 404 Client Error: Not Found for url: http+docker://localhost/v1.40/containers/create

During handling of the above exception, another exception occurred:
/home/riyad/src/docker-py/tests/integration/models_containers_test.py:41: in test_run_with_image_that_does_not_exist
    ???
docker/models/containers.py:811: in run
    container = self.create(image=image, command=command,
docker/models/containers.py:870: in create
    resp = self.client.api.create_container(**create_kwargs)
docker/api/container.py:430: in create_container
    return self.create_container_from_config(config, name)
docker/api/container.py:441: in create_container_from_config
    return self._result(res, True)
docker/api/client.py:302: in _result
    self._raise_for_status(response)
docker/api/client.py:298: in _raise_for_status
    raise create_api_error_from_http_exception(e)
docker/errors.py:31: in create_api_error_from_http_exception
    raise cls(e, response=response, explanation=explanation)
E   docker.errors.NotFound: 404 Client Error for http+docker://localhost/v1.40/containers/create: Not Found ("unable to find a name and tag match for dockerpytest_does_not_exist in repotags: no such image")
_________________ ContainerTest.test_create_with_volume_driver _________________
/home/riyad/src/docker-py/tests/integration/models_containers_test.py:456: in test_create_with_volume_driver
    ???
E   AssertionError: assert '' == 'foo'
E     - foo
___________________________ ContainerTest.test_diff ____________________________
/home/riyad/src/docker-py/tests/integration/models_containers_test.py:251: in test_diff
    ???
E   AssertionError: assert [{'Kind': 0, ...th': '/test'}] == [{'Kind': 1, 'Path': '/test'}]
E     At index 0 diff: {'Path': '/etc', 'Kind': 0} != {'Path': '/test', 'Kind': 1}
E     Left contains one more item: {'Kind': 1, 'Path': '/test'}
E     Full diff:
E     - [{'Kind': 1, 'Path': '/test'}]
E     + [{'Kind': 0, 'Path': '/etc'}, {'Kind': 1, 'Path': '/test'}]
______________________ ContainerTest.test_exec_run_failed ______________________
/home/riyad/src/docker-py/tests/integration/models_containers_test.py:270: in test_exec_run_failed
    ???
E   AssertionError: assert 127 == 126
E     +127
E     -126
___________________________ ContainerTest.test_kill ____________________________
/home/riyad/src/docker-py/tests/integration/models_containers_test.py:281: in test_kill
    ???
E   AssertionError: assert 'stopped' == 'exited'
E     - exited
E     + stopped
___________________________ ContainerTest.test_pause ___________________________
docker/api/client.py:296: in _raise_for_status
    response.raise_for_status()
../.virtualenvs/docker-py/lib/python3.8/site-packages/requests/models.py:940: in raise_for_status
    raise HTTPError(http_error_msg, response=self)
E   requests.exceptions.HTTPError: 500 Server Error: Internal Server Error for url: http+docker://localhost/v1.40/containers/25bf9914c7bf6c6cf3d734dc56632ca9bdfa1e701f12d41feb4044ba8f994ba0/pause

During handling of the above exception, another exception occurred:
/home/riyad/src/docker-py/tests/integration/models_containers_test.py:295: in test_pause
    ???
docker/models/containers.py:316: in pause
    return self.client.api.pause(self.id)
docker/utils/decorators.py:19: in wrapped
    return f(self, resource_id, *args, **kwargs)
docker/api/container.py:892: in pause
    self._raise_for_status(res)
docker/api/client.py:298: in _raise_for_status
    raise create_api_error_from_http_exception(e)
docker/errors.py:31: in create_api_error_from_http_exception
    raise cls(e, response=response, explanation=explanation)
E   docker.errors.APIError: 500 Server Error for http+docker://localhost/v1.40/containers/25bf9914c7bf6c6cf3d734dc56632ca9bdfa1e701f12d41feb4044ba8f994ba0/pause: Internal Server Error ("`/usr/bin/crun pause 25bf9914c7bf6c6cf3d734dc56632ca9bdfa1e701f12d41feb4044ba8f994ba0` failed: exit status 1")
____________________________ ContainerTest.test_top ____________________________
/home/riyad/src/docker-py/tests/integration/models_containers_test.py:425: in test_top
    ???
E   AssertionError: assert 'sleep 60' in ['    1 root      0:00 sleep 60']
__________________________ ContainerTest.test_update ___________________________
docker/api/client.py:296: in _raise_for_status
    response.raise_for_status()
../.virtualenvs/docker-py/lib/python3.8/site-packages/requests/models.py:940: in raise_for_status
    raise HTTPError(http_error_msg, response=self)
E   requests.exceptions.HTTPError: 404 Client Error: Not Found for url: http+docker://localhost/v1.40/containers/98218f64abead5ad70e83ef26bc45302d30145a766d156f10ebf8300f2d9fe6c/update

During handling of the above exception, another exception occurred:
/home/riyad/src/docker-py/tests/integration/models_containers_test.py:433: in test_update
    ???
docker/models/containers.py:489: in update
    return self.client.api.update_container(self.id, **kwargs)
docker/utils/decorators.py:34: in wrapper
    return f(self, *args, **kwargs)
docker/utils/decorators.py:19: in wrapped
    return f(self, resource_id, *args, **kwargs)
docker/api/container.py:1270: in update_container
    return self._result(res, True)
docker/api/client.py:302: in _result
    self._raise_for_status(response)
docker/api/client.py:298: in _raise_for_status
    raise create_api_error_from_http_exception(e)
docker/errors.py:31: in create_api_error_from_http_exception
    raise cls(e, response=response, explanation=explanation)
E   docker.errors.NotFound: 404 Client Error for http+docker://localhost/v1.40/containers/98218f64abead5ad70e83ef26bc45302d30145a766d156f10ebf8300f2d9fe6c/update: Not Found ("b'Not Found'")
__________________ ImageCollectionTest.test_build_with_error ___________________
/home/riyad/src/docker-py/tests/integration/models_images_test.py:30: in test_build_with_error
    ???
E   AssertionError: assert "The command '/bin/sh -c exit 1' returned a non-zero code: 1" in 'docker.errors.BuildError: error building at STEP "RUN exit 1": exit status 1'
E    +  where 'docker.errors.BuildError: error building at STEP "RUN exit 1": exit status 1' = <bound method ExceptionInfo.exconly of <ExceptionInfo BuildError('error building at STEP "RUN exit 1": exit status 1\n') tblen=2>>()
E    +    where <bound method ExceptionInfo.exconly of <ExceptionInfo BuildError('error building at STEP "RUN exit 1": exit status 1\n') tblen=2>> = <ExceptionInfo BuildError('error building at STEP "RUN exit 1": exit status 1\n') tblen=2>.exconly
_____________________ ImageCollectionTest.test_load_error ______________________
/home/riyad/src/docker-py/tests/integration/models_images_test.py:98: in test_load_error
    ???
E   Failed: DID NOT RAISE <class 'docker.errors.ImageLoadError'>
________________________ ImageCollectionTest.test_pull _________________________
/home/riyad/src/docker-py/tests/integration/models_images_test.py:71: in test_pull
    ???
E   AssertionError: assert 'alpine:latest' in ['docker.io/library/alpine:latest']
____________________ ImageCollectionTest.test_pull_multiple ____________________
/home/riyad/src/docker-py/tests/integration/models_images_test.py:91: in test_pull_multiple
    ???
/home/riyad/src/docker-py/tests/integration/models_images_test.py:91: in <listcomp>
    ???
E   TypeError: argument of type 'NoneType' is not iterable
____________________ ImageCollectionTest.test_pull_with_sha ____________________
/home/riyad/src/docker-py/tests/integration/models_images_test.py:85: in test_pull_with_sha
    ???
E   AssertionError: assert 'hello-world@sha256:083de497cff944f969d8499ab94f07134c50bcf5e6b9559b27182d3fa80ce3f7' in ['docker.io/library/hello-world@sha256:083de497cff944f969d8499ab94f07134c50bcf5e6b9559b27182d3fa80ce3f7', 'docker.io/library/hello-world@sha256:8072a54ebb3bc136150e2f2860f00a7bf45f13eeb917cca2430fcd0054c8e51b']
____________________ ImageCollectionTest.test_pull_with_tag ____________________
/home/riyad/src/docker-py/tests/integration/models_images_test.py:76: in test_pull_with_tag
    ???
E   AssertionError: assert 'alpine:3.10' in ['docker.io/library/alpine:3.10', 'docker.io/library/sha256:be4e4bea2c2e15b403bb321562e78ea84b501fb41497472e91ecb41504e8a27c']
_______________ ImageCollectionTest.test_save_and_load_repo_name _______________
/home/riyad/src/docker-py/tests/integration/models_images_test.py:122: in test_save_and_load_repo_name
    ???
docker/models/images.py:98: in save
    raise InvalidArgument(
E   docker.errors.InvalidArgument: dockerpytest_fd587b17cecf0b85:latest is not a valid tag for this image
____________________ NetworkCollectionTest.test_list_remove ____________________
/home/riyad/src/docker-py/tests/integration/models_networks_test.py:30: in test_list_remove
    ???
docker/models/networks.py:210: in list
    networks = [self.prepare_model(item) for item in resp]
E   TypeError: 'NoneType' object is not iterable
_____________________ NetworkTest.test_connect_disconnect ______________________
docker/api/client.py:296: in _raise_for_status
    response.raise_for_status()
../.virtualenvs/docker-py/lib/python3.8/site-packages/requests/models.py:940: in raise_for_status
    raise HTTPError(http_error_msg, response=self)
E   requests.exceptions.HTTPError: 500 Server Error: Internal Server Error for url: http+docker://localhost/v1.40/networks/af56924e8b184a75c62b8477e8e5e20e409e4a414827ae98fb4e873e63046221/connect

During handling of the above exception, another exception occurred:
/home/riyad/src/docker-py/tests/integration/models_networks_test.py:59: in test_connect_disconnect
    ???
docker/models/networks.py:58: in connect
    return self.client.api.connect_container_to_network(
docker/utils/decorators.py:19: in wrapped
    return f(self, resource_id, *args, **kwargs)
docker/api/network.py:250: in connect_container_to_network
    self._raise_for_status(res)
docker/api/client.py:298: in _raise_for_status
    raise create_api_error_from_http_exception(e)
docker/errors.py:31: in create_api_error_from_http_exception
    raise cls(e, response=response, explanation=explanation)
E   docker.errors.APIError: 500 Server Error for http+docker://localhost/v1.40/networks/af56924e8b184a75c62b8477e8e5e20e409e4a414827ae98fb4e873e63046221/connect: Internal Server Error ("network disconnect is not enabled for rootless containers")
_________________________ VolumesTest.test_list_remove _________________________
/home/riyad/src/docker-py/tests/integration/models_volumes_test.py:26: in test_list_remove
    ???
E   AssertionError: assert <Volume: dockerpyte> in []
E    +  where [] = <bound method VolumeCollection.list of <docker.models.volumes.VolumeCollection object at 0x7f1f8530c3a0>>(filters={'name': 'dockerpytest_'})
E    +    where <bound method VolumeCollection.list of <docker.models.volumes.VolumeCollection object at 0x7f1f8530c3a0>> = <docker.models.volumes.VolumeCollection object at 0x7f1f8530c3a0>.list
E    +      where <docker.models.volumes.VolumeCollection object at 0x7f1f8530c3a0> = <docker.client.DockerClient object at 0x7f1f8530cf10>.volumes
________ TestRegressions.test_443_handle_nonchunked_response_in_stream _________
/home/riyad/src/docker-py/tests/integration/regression_test.py:16: in test_443_handle_nonchunked_response_in_stream
    ???
E   Failed: DID NOT RAISE <class 'docker.errors.APIError'>
=============================== warnings summary ===============================
../.virtualenvs/docker-py/lib/python3.8/site-packages/paramiko/hostkeys.py:23
  /home/ubuntu/.virtualenvs/docker-py/lib/python3.8/site-packages/paramiko/hostkeys.py:23: DeprecationWarning: Using or importing the ABCs from 'collections' instead of from 'collections.abc' is deprecated since Python 3.3, and in 3.9 it will stop working
    from collections import MutableMapping

tests/integration/api_client_test.py::ConnectionTimeoutTest::test_timeout
  /home/ubuntu/docker-py/docker/utils/utils.py:276: DeprecationWarning: urllib.parse.splitnport() is deprecated as of 3.8, use urllib.parse.urlparse() instead
    host, port = splitnport(parsed_url.netloc)

-- Docs: https://docs.pytest.org/en/stable/warnings.html
- generated xml file: /home/ubuntu/docker-py/logs.podman-test/pytest_integration_3.0.1-lxd___inside lxd.junit.xml -
=========================== short test summary info ============================
XFAIL tests/integration/api_build_test.py::BuildTest::test_prune_builds
  Currently fails on 18.09: https://github.com/moby/moby/issues/37920
XFAIL tests/integration/api_container_test.py::CreateContainerTest::test_create_with_storage_opt
  Not supported on most drivers
XFAIL tests/integration/api_container_test.py::ContainerTopTest::test_top
  Output of docker top depends on host distro, and is not formalized.
XFAIL tests/integration/api_container_test.py::ContainerTopTest::test_top_with_psargs
  Output of docker top depends on host distro, and is not formalized.
SKIPPED [1] ../../riyad/src/docker-py/tests/integration/api_image_test.py:292: Doesn't work inside a container - FIXME
= 110 failed, 162 passed, 1 skipped, 137 deselected, 4 xfailed, 1 xpassed, 2 warnings in 246.66s (0:04:06) =
