<?xml version="1.0" encoding="utf-8"?><testsuites><testsuite name="docker-py" errors="5" failures="74" skipped="5" tests="266" time="1840.388" timestamp="2021-12-09T15:13:42.220680" hostname="acnologia"><testcase classname="tests.integration.api_build_test.BuildTest" name="test_build_container_with_target" time="15.104" /><testcase classname="tests.integration.api_build_test.BuildTest" name="test_build_from_stringio" time="6.485" /><testcase classname="tests.integration.api_build_test.BuildTest" name="test_build_gzip_custom_encoding" time="6.618" /><testcase classname="tests.integration.api_build_test.BuildTest" name="test_build_gzip_encoding" time="7.672" /><testcase classname="tests.integration.api_build_test.BuildTest" name="test_build_in_context_abs_dockerfile" time="7.812" /><testcase classname="tests.integration.api_build_test.BuildTest" name="test_build_in_context_dockerfile" time="7.146" /><testcase classname="tests.integration.api_build_test.BuildTest" name="test_build_in_context_nested_dockerfile" time="7.679" /><testcase classname="tests.integration.api_build_test.BuildTest" name="test_build_invalid_platform" time="7.838" /><testcase classname="tests.integration.api_build_test.BuildTest" name="test_build_isolation" time="6.532" /><testcase classname="tests.integration.api_build_test.BuildTest" name="test_build_labels" time="7.718"><failure message="AssertionError: assert {'io.buildah.... 'test': 'OK'} == {'test': 'OK'}&#10;  Omitting 1 identical items, use -vv to show&#10;  Left contains 1 more item:&#10;  {'io.buildah.version': '1.23.1'}&#10;  Full diff:&#10;  - {'test': 'OK'}&#10;  + {'io.buildah.version': '1.23.1', 'test': 'OK'}">tests/integration/api_build_test.py:211: in test_build_labels
    assert info['Config']['Labels'] == labels
E   AssertionError: assert {'io.buildah.... 'test': 'OK'} == {'test': 'OK'}
E     Omitting 1 identical items, use -vv to show
E     Left contains 1 more item:
E     {'io.buildah.version': '1.23.1'}
E     Full diff:
E     - {'test': 'OK'}
E     + {'io.buildah.version': '1.23.1', 'test': 'OK'}</failure><system-out>--------------------------------- Captured Log ---------------------------------

--------------------------------- Captured Out ---------------------------------

</system-out><system-err>--------------------------------- Captured Err ---------------------------------

</system-err></testcase><testcase classname="tests.integration.api_build_test.BuildTest" name="test_build_out_of_context_dockerfile" time="9.392" /><testcase classname="tests.integration.api_build_test.BuildTest" name="test_build_shmsize" time="8.609" /><testcase classname="tests.integration.api_build_test.BuildTest" name="test_build_squash" time="11.566"><failure message="AssertionError: assert 1 == 2&#10;  +1&#10;  -2">tests/integration/api_build_test.py:371: in test_build_squash
    assert len(squashed['RootFS']['Layers']) == 2
E   AssertionError: assert 1 == 2
E     +1
E     -2</failure><system-out>--------------------------------- Captured Log ---------------------------------

--------------------------------- Captured Out ---------------------------------

</system-out><system-err>--------------------------------- Captured Err ---------------------------------

</system-err></testcase><testcase classname="tests.integration.api_build_test.BuildTest" name="test_build_stderr_data" time="7.676"><failure message="AssertionError: assert False&#10; +  where False = any([False, False, False, False, False, False, ...])">tests/integration/api_build_test.py:390: in test_build_stderr_data
    assert any([line == expected for line in lines])
E   AssertionError: assert False
E    +  where False = any([False, False, False, False, False, False, ...])</failure><system-out>--------------------------------- Captured Log ---------------------------------

--------------------------------- Captured Out ---------------------------------

</system-out><system-err>--------------------------------- Captured Err ---------------------------------

</system-err></testcase><testcase classname="tests.integration.api_build_test.BuildTest" name="test_build_streaming" time="8.514" /><testcase classname="tests.integration.api_build_test.BuildTest" name="test_build_with_buildargs" time="6.707" /><testcase classname="tests.integration.api_build_test.BuildTest" name="test_build_with_cache_from" time="9.222"><failure message="AssertionError: assert 3 == 0&#10;  +3&#10;  -0">tests/integration/api_build_test.py:247: in test_build_with_cache_from
    assert counter == 0
E   AssertionError: assert 3 == 0
E     +3
E     -0</failure><system-out>--------------------------------- Captured Log ---------------------------------

--------------------------------- Captured Out ---------------------------------

</system-out><system-err>--------------------------------- Captured Err ---------------------------------

</system-err></testcase><testcase classname="tests.integration.api_build_test.BuildTest" name="test_build_with_dockerfile_empty_lines" time="6.946" /><testcase classname="tests.integration.api_build_test.BuildTest" name="test_build_with_dockerignore" time="7.307" /><testcase classname="tests.integration.api_build_test.BuildTest" name="test_build_with_extra_hosts" time="6.351"><failure message="docker.errors.APIError: 400 Client Error for http+docker://localhost/v1.40/build?t=dockerpytest_extrahost_build&amp;q=False&amp;nocache=False&amp;rm=False&amp;forcerm=False&amp;pull=False&amp;extrahosts=extrahost.local.test%3A127.0.0.1&amp;extrahosts=hello.world.test%3A127.0.0.1: Bad Request (&quot;failed to parse query parameter 'extrahosts': &quot;hello.world.test:127.0.0.1&quot;: invalid character 'h' looking for beginning of value&quot;)">docker/api/client.py:296: in _raise_for_status
    response.raise_for_status()
../../.virtualenvs/docker-py/lib/python3.9/site-packages/requests/models.py:953: in raise_for_status
    raise HTTPError(http_error_msg, response=self)
E   requests.exceptions.HTTPError: 400 Client Error: Bad Request for url: http+docker://localhost/v1.40/build?t=dockerpytest_extrahost_build&amp;q=False&amp;nocache=False&amp;rm=False&amp;forcerm=False&amp;pull=False&amp;extrahosts=extrahost.local.test%3A127.0.0.1&amp;extrahosts=hello.world.test%3A127.0.0.1

During handling of the above exception, another exception occurred:
tests/integration/api_build_test.py:332: in test_build_with_extra_hosts
    for chunk in stream:
docker/api/client.py:386: in _stream_helper
    yield self._result(response, json=decode)
docker/api/client.py:302: in _result
    self._raise_for_status(response)
docker/api/client.py:298: in _raise_for_status
    raise create_api_error_from_http_exception(e)
docker/errors.py:31: in create_api_error_from_http_exception
    raise cls(e, response=response, explanation=explanation)
E   docker.errors.APIError: 400 Client Error for http+docker://localhost/v1.40/build?t=dockerpytest_extrahost_build&amp;q=False&amp;nocache=False&amp;rm=False&amp;forcerm=False&amp;pull=False&amp;extrahosts=extrahost.local.test%3A127.0.0.1&amp;extrahosts=hello.world.test%3A127.0.0.1: Bad Request ("failed to parse query parameter 'extrahosts': "hello.world.test:127.0.0.1": invalid character 'h' looking for beginning of value")</failure><system-out>--------------------------------- Captured Log ---------------------------------

--------------------------------- Captured Out ---------------------------------

</system-out><system-err>--------------------------------- Captured Err ---------------------------------

</system-err></testcase><testcase classname="tests.integration.api_build_test.BuildTest" name="test_build_with_network_mode" time="7.817"><failure message="docker.errors.ImageNotFound: 404 Client Error for http+docker://localhost/v1.40/images/dockerpytest_customnetbuild/json: Not Found (&quot;failed to find image dockerpytest_customnetbuild: dockerpytest_customnetbuild: No such image&quot;)">docker/api/client.py:296: in _raise_for_status
    response.raise_for_status()
../../.virtualenvs/docker-py/lib/python3.9/site-packages/requests/models.py:953: in raise_for_status
    raise HTTPError(http_error_msg, response=self)
E   requests.exceptions.HTTPError: 404 Client Error: Not Found for url: http+docker://localhost/v1.40/images/dockerpytest_customnetbuild/json

During handling of the above exception, another exception occurred:
tests/integration/api_build_test.py:297: in test_build_with_network_mode
    assert self.client.inspect_image('dockerpytest_customnetbuild')
docker/utils/decorators.py:19: in wrapped
    return f(self, resource_id, *args, **kwargs)
docker/api/image.py:251: in inspect_image
    return self._result(
docker/api/client.py:302: in _result
    self._raise_for_status(response)
docker/api/client.py:298: in _raise_for_status
    raise create_api_error_from_http_exception(e)
docker/errors.py:31: in create_api_error_from_http_exception
    raise cls(e, response=response, explanation=explanation)
E   docker.errors.ImageNotFound: 404 Client Error for http+docker://localhost/v1.40/images/dockerpytest_customnetbuild/json: Not Found ("failed to find image dockerpytest_customnetbuild: dockerpytest_customnetbuild: No such image")</failure><system-out>--------------------------------- Captured Log ---------------------------------

--------------------------------- Captured Out ---------------------------------

</system-out><system-err>--------------------------------- Captured Err ---------------------------------

</system-err></testcase><testcase classname="tests.integration.api_build_test.BuildTest" name="test_build_with_proxy" time="7.596" /><testcase classname="tests.integration.api_build_test.BuildTest" name="test_build_with_proxy_and_buildargs" time="6.990" /><testcase classname="tests.integration.api_build_test.BuildTest" name="test_prune_builds" time="6.657"><skipped type="pytest.xfail" message="Currently fails on 18.09: https://github.com/moby/moby/issues/37920" /></testcase><testcase classname="tests.integration.api_client_test.InformationTest" name="test_info" time="8.084" /><testcase classname="tests.integration.api_client_test.InformationTest" name="test_version" time="8.834" /><testcase classname="tests.integration.api_client_test.AutoDetectVersionTest" name="test_client_init" time="6.472" /><testcase classname="tests.integration.api_client_test.ConnectionTimeoutTest" name="test_timeout" time="0.505" /><testcase classname="tests.integration.api_client_test.UnixconnTest" name="test_resource_warnings" time="2.251" /><testcase classname="tests.integration.api_container_test.ListContainersTest" name="test_list_containers" time="6.649" /><testcase classname="tests.integration.api_container_test.CreateContainerTest" name="test_create" time="6.415" /><testcase classname="tests.integration.api_container_test.CreateContainerTest" name="test_create_container_with_volumes_from" time="7.374" /><testcase classname="tests.integration.api_container_test.CreateContainerTest" name="test_create_with_auto_remove" time="6.445" /><testcase classname="tests.integration.api_container_test.CreateContainerTest" name="test_create_with_cpu_rt_options" time="6.519" /><testcase classname="tests.integration.api_container_test.CreateContainerTest" name="test_create_with_device_cgroup_rules" time="6.711"><failure message="AssertionError: assert None == ['c 7:128 rwm']&#10;  +None&#10;  -['c 7:128 rwm']">tests/integration/api_container_test.py:470: in test_create_with_device_cgroup_rules
    assert config['HostConfig']['DeviceCgroupRules'] == [rule]
E   AssertionError: assert None == ['c 7:128 rwm']
E     +None
E     -['c 7:128 rwm']</failure><system-out>--------------------------------- Captured Log ---------------------------------

--------------------------------- Captured Out ---------------------------------

</system-out><system-err>--------------------------------- Captured Err ---------------------------------

</system-err></testcase><testcase classname="tests.integration.api_container_test.CreateContainerTest" name="test_create_with_environment_variable_no_value" time="7.360"><failure message="AssertionError: assert 'Foo' in ['PATH=/usr/local/sbin:/usr/local/bin:/usr/sbin:/usr/bin:/sbin:/bin', 'TERM=xterm', 'container=podman', 'Other=one', 'Blank=']">tests/integration/api_container_test.py:366: in test_create_with_environment_variable_no_value
    assert 'Foo' in config['Config']['Env']
E   AssertionError: assert 'Foo' in ['PATH=/usr/local/sbin:/usr/local/bin:/usr/sbin:/usr/bin:/sbin:/bin', 'TERM=xterm', 'container=podman', 'Other=one', 'Blank=']</failure><system-out>--------------------------------- Captured Log ---------------------------------

--------------------------------- Captured Out ---------------------------------

</system-out><system-err>--------------------------------- Captured Err ---------------------------------

</system-err></testcase><testcase classname="tests.integration.api_container_test.CreateContainerTest" name="test_create_with_host_pid_mode" time="6.856" /><testcase classname="tests.integration.api_container_test.CreateContainerTest" name="test_create_with_init" time="7.557" /><testcase classname="tests.integration.api_container_test.CreateContainerTest" name="test_create_with_isolation" time="8.803"><failure message="AssertionError: assert '' == 'default'&#10;  - default">tests/integration/api_container_test.py:395: in test_create_with_isolation
    assert config['HostConfig']['Isolation'] == 'default'
E   AssertionError: assert '' == 'default'
E     - default</failure><system-out>--------------------------------- Captured Log ---------------------------------

--------------------------------- Captured Out ---------------------------------

</system-out><system-err>--------------------------------- Captured Err ---------------------------------

</system-err></testcase><testcase classname="tests.integration.api_container_test.CreateContainerTest" name="test_create_with_links" time="8.897"><failure message="docker.errors.APIError: 400 Client Error for http+docker://localhost/v1.40/containers/create: Bad Request (&quot;bad parameter: Link is not supported&quot;)">docker/api/client.py:296: in _raise_for_status
    response.raise_for_status()
../../.virtualenvs/docker-py/lib/python3.9/site-packages/requests/models.py:953: in raise_for_status
    raise HTTPError(http_error_msg, response=self)
E   requests.exceptions.HTTPError: 400 Client Error: Bad Request for url: http+docker://localhost/v1.40/containers/create

During handling of the above exception, another exception occurred:
tests/integration/api_container_test.py:95: in test_create_with_links
    res2 = self.client.create_container(
docker/api/container.py:428: in create_container
    return self.create_container_from_config(config, name)
docker/api/container.py:439: in create_container_from_config
    return self._result(res, True)
docker/api/client.py:302: in _result
    self._raise_for_status(response)
docker/api/client.py:298: in _raise_for_status
    raise create_api_error_from_http_exception(e)
docker/errors.py:31: in create_api_error_from_http_exception
    raise cls(e, response=response, explanation=explanation)
E   docker.errors.APIError: 400 Client Error for http+docker://localhost/v1.40/containers/create: Bad Request ("bad parameter: Link is not supported")</failure><system-out>--------------------------------- Captured Log ---------------------------------

--------------------------------- Captured Out ---------------------------------

</system-out><system-err>--------------------------------- Captured Err ---------------------------------

</system-err></testcase><testcase classname="tests.integration.api_container_test.CreateContainerTest" name="test_create_with_mac_address" time="8.140"><failure message="AssertionError: assert '02:42:ac:11:00:0a' == '16:66:e4:d9:ac:b5'&#10;  - 16:66:e4:d9:ac:b5&#10;  + 02:42:ac:11:00:0a">tests/integration/api_container_test.py:214: in test_create_with_mac_address
    assert mac_address_expected == res['NetworkSettings']['MacAddress']
E   AssertionError: assert '02:42:ac:11:00:0a' == '16:66:e4:d9:ac:b5'
E     - 16:66:e4:d9:ac:b5
E     + 02:42:ac:11:00:0a</failure><system-out>--------------------------------- Captured Log ---------------------------------

--------------------------------- Captured Out ---------------------------------

</system-out><system-err>--------------------------------- Captured Err ---------------------------------

</system-err></testcase><testcase classname="tests.integration.api_container_test.CreateContainerTest" name="test_create_with_memory_constraints_with_int" time="6.947"><failure message="docker.errors.APIError: 500 Server Error for http+docker://localhost/v1.40/containers/107fc80f7e815977aa86d5ed5e39e9edb13fc1c91ecf11e0847f41656c65837d/start: Internal Server Error (&quot;cannot set memory swappiness with cgroupv2: OCI runtime error&quot;)">docker/api/client.py:296: in _raise_for_status
    response.raise_for_status()
../../.virtualenvs/docker-py/lib/python3.9/site-packages/requests/models.py:953: in raise_for_status
    raise HTTPError(http_error_msg, response=self)
E   requests.exceptions.HTTPError: 500 Server Error: Internal Server Error for url: http+docker://localhost/v1.40/containers/107fc80f7e815977aa86d5ed5e39e9edb13fc1c91ecf11e0847f41656c65837d/start

During handling of the above exception, another exception occurred:
tests/integration/api_container_test.py:351: in test_create_with_memory_constraints_with_int
    self.client.start(ctnr)
docker/utils/decorators.py:19: in wrapped
    return f(self, resource_id, *args, **kwargs)
docker/api/container.py:1109: in start
    self._raise_for_status(res)
docker/api/client.py:298: in _raise_for_status
    raise create_api_error_from_http_exception(e)
docker/errors.py:31: in create_api_error_from_http_exception
    raise cls(e, response=response, explanation=explanation)
E   docker.errors.APIError: 500 Server Error for http+docker://localhost/v1.40/containers/107fc80f7e815977aa86d5ed5e39e9edb13fc1c91ecf11e0847f41656c65837d/start: Internal Server Error ("cannot set memory swappiness with cgroupv2: OCI runtime error")</failure><system-out>--------------------------------- Captured Log ---------------------------------

--------------------------------- Captured Out ---------------------------------

</system-out><system-err>--------------------------------- Captured Err ---------------------------------

</system-err></testcase><testcase classname="tests.integration.api_container_test.CreateContainerTest" name="test_create_with_memory_constraints_with_str" time="7.737" /><testcase classname="tests.integration.api_container_test.CreateContainerTest" name="test_create_with_restart_policy" time="9.734"><failure message="Failed: DID NOT RAISE &lt;class 'docker.errors.APIError'&gt;">tests/integration/api_container_test.py:124: in test_create_with_restart_policy
    self.client.remove_container(id)
E   Failed: DID NOT RAISE &lt;class 'docker.errors.APIError'&gt;</failure><system-out>--------------------------------- Captured Log ---------------------------------

--------------------------------- Captured Out ---------------------------------

</system-out><system-err>--------------------------------- Captured Err ---------------------------------

</system-err></testcase><testcase classname="tests.integration.api_container_test.CreateContainerTest" name="test_create_with_stop_timeout" time="7.301" /><testcase classname="tests.integration.api_container_test.CreateContainerTest" name="test_create_with_storage_opt" time="7.369"><skipped type="pytest.xfail" message="Not supported on most drivers" /></testcase><testcase classname="tests.integration.api_container_test.CreateContainerTest" name="test_create_with_tmpfs" time="7.067"><failure message="AssertionError: assert {'/tmp1': 'si...ev,tmpcopyup'} == {'/tmp1': 'size=3M'}&#10;  Differing items:&#10;  {'/tmp1': 'size=3M,rw,rprivate,nosuid,nodev,tmpcopyup'} != {'/tmp1': 'size=3M'}&#10;  Full diff:&#10;  - {'/tmp1': 'size=3M'}&#10;  + {'/tmp1': 'size=3M,rw,rprivate,nosuid,nodev,tmpcopyup'}">tests/integration/api_container_test.py:384: in test_create_with_tmpfs
    assert config['HostConfig']['Tmpfs'] == tmpfs
E   AssertionError: assert {'/tmp1': 'si...ev,tmpcopyup'} == {'/tmp1': 'size=3M'}
E     Differing items:
E     {'/tmp1': 'size=3M,rw,rprivate,nosuid,nodev,tmpcopyup'} != {'/tmp1': 'size=3M'}
E     Full diff:
E     - {'/tmp1': 'size=3M'}
E     + {'/tmp1': 'size=3M,rw,rprivate,nosuid,nodev,tmpcopyup'}</failure><system-out>--------------------------------- Captured Log ---------------------------------

--------------------------------- Captured Out ---------------------------------

</system-out><system-err>--------------------------------- Captured Err ---------------------------------

</system-err></testcase><testcase classname="tests.integration.api_container_test.CreateContainerTest" name="test_create_with_uts_mode" time="6.622" /><testcase classname="tests.integration.api_container_test.CreateContainerTest" name="test_group_id_ints" time="6.894" /><testcase classname="tests.integration.api_container_test.CreateContainerTest" name="test_group_id_strings" time="8.569" /><testcase classname="tests.integration.api_container_test.CreateContainerTest" name="test_invalid_log_driver_raises_exception" time="8.353"><failure message="AssertionError: assert 'container create: error running container create option: invalid log driver: invalid argument' in [&quot;logger: no log driver named 'asdf' is registered&quot;, 'error looking up logging plugin asdf: plugin &quot;asdf&quot; not found']&#10; +  where 'container create: error running container create option: invalid log driver: invalid argument' = APIError(HTTPError('500 Server Error: Internal Server Error for url: http+docker://localhost/v1.40/containers/create')).explanation&#10; +    where APIError(HTTPError('500 Server Error: Internal Server Error for url: http+docker://localhost/v1.40/containers/create')) = &lt;ExceptionInfo APIError(HTTPError('500 Server Error: Internal Server Error for url: http+docker://localhost/v1.40/containers/create')) tblen=6&gt;.value">tests/integration/api_container_test.py:286: in test_invalid_log_driver_raises_exception
    assert excinfo.value.explanation in expected_msgs
E   AssertionError: assert 'container create: error running container create option: invalid log driver: invalid argument' in ["logger: no log driver named 'asdf' is registered", 'error looking up logging plugin asdf: plugin "asdf" not found']
E    +  where 'container create: error running container create option: invalid log driver: invalid argument' = APIError(HTTPError('500 Server Error: Internal Server Error for url: http+docker://localhost/v1.40/containers/create')).explanation
E    +    where APIError(HTTPError('500 Server Error: Internal Server Error for url: http+docker://localhost/v1.40/containers/create')) = &lt;ExceptionInfo APIError(HTTPError('500 Server Error: Internal Server Error for url: http+docker://localhost/v1.40/containers/create')) tblen=6&gt;.value</failure><system-out>--------------------------------- Captured Log ---------------------------------

--------------------------------- Captured Out ---------------------------------

</system-out><system-err>--------------------------------- Captured Err ---------------------------------

</system-err></testcase><testcase classname="tests.integration.api_container_test.CreateContainerTest" name="test_valid_log_driver_and_log_opt" time="7.442"><failure message="AssertionError: assert None == {'max-file': '100'}&#10;  +None&#10;  -{'max-file': '100'}">tests/integration/api_container_test.py:265: in test_valid_log_driver_and_log_opt
    assert container_log_config['Config'] == log_config.config
E   AssertionError: assert None == {'max-file': '100'}
E     +None
E     -{'max-file': '100'}</failure><system-out>--------------------------------- Captured Log ---------------------------------

--------------------------------- Captured Out ---------------------------------

</system-out><system-err>--------------------------------- Captured Err ---------------------------------

</system-err></testcase><testcase classname="tests.integration.api_container_test.CreateContainerTest" name="test_valid_no_config_specified" time="7.072"><failure message="AssertionError: assert None == {}&#10;  +None&#10;  -{}">tests/integration/api_container_test.py:324: in test_valid_no_config_specified
    assert container_log_config['Config'] == {}
E   AssertionError: assert None == {}
E     +None
E     -{}</failure><system-out>--------------------------------- Captured Log ---------------------------------

--------------------------------- Captured Out ---------------------------------

</system-out><system-err>--------------------------------- Captured Err ---------------------------------

</system-err></testcase><testcase classname="tests.integration.api_container_test.CreateContainerTest" name="test_valid_no_log_driver_specified" time="7.631"><failure message="AssertionError: assert 'journald' == 'json-file'&#10;  - json-file&#10;  + journald">tests/integration/api_container_test.py:304: in test_valid_no_log_driver_specified
    assert container_log_config['Type'] == "json-file"
E   AssertionError: assert 'journald' == 'json-file'
E     - json-file
E     + journald</failure><system-out>--------------------------------- Captured Log ---------------------------------

--------------------------------- Captured Out ---------------------------------

</system-out><system-err>--------------------------------- Captured Err ---------------------------------

</system-err></testcase><testcase classname="tests.integration.api_container_test.VolumeBindTest" name="test_create_with_binds_ro" time="8.443" /><testcase classname="tests.integration.api_container_test.VolumeBindTest" name="test_create_with_binds_rw" time="7.082" /><testcase classname="tests.integration.api_container_test.VolumeBindTest" name="test_create_with_mounts" time="7.422" /><testcase classname="tests.integration.api_container_test.VolumeBindTest" name="test_create_with_mounts_ro" time="8.319" /><testcase classname="tests.integration.api_container_test.VolumeBindTest" name="test_create_with_volume_mount" time="7.347" /><testcase classname="tests.integration.api_container_test.ArchiveTest" name="test_copy_directory_to_container" time="7.455" /><testcase classname="tests.integration.api_container_test.ArchiveTest" name="test_copy_file_to_container" time="8.229"><failure message="AssertionError: assert b'' == b'Deaf To All But The Song'&#10;  Full diff:&#10;  - b'Deaf To All But The Song'&#10;  + b''">tests/integration/api_container_test.py:669: in test_copy_file_to_container
    assert logs.strip() == data
E   AssertionError: assert b'' == b'Deaf To All But The Song'
E     Full diff:
E     - b'Deaf To All But The Song'
E     + b''</failure><system-out>--------------------------------- Captured Log ---------------------------------

--------------------------------- Captured Out ---------------------------------

</system-out><system-err>--------------------------------- Captured Err ---------------------------------

</system-err></testcase><testcase classname="tests.integration.api_container_test.ArchiveTest" name="test_get_file_archive_from_container" time="7.934" /><testcase classname="tests.integration.api_container_test.ArchiveTest" name="test_get_file_stat_from_container" time="7.535" /><testcase classname="tests.integration.api_container_test.RenameContainerTest" name="test_rename_container" time="10.464" /><testcase classname="tests.integration.api_container_test.StartContainerTest" name="test_run_shlex_commands" time="10.324" /><testcase classname="tests.integration.api_container_test.StartContainerTest" name="test_start_container" time="10.621" /><testcase classname="tests.integration.api_container_test.StartContainerTest" name="test_start_container_with_dict_instead_of_id" time="9.998" /><testcase classname="tests.integration.api_container_test.WaitTest" name="test_wait" time="14.629" /><testcase classname="tests.integration.api_container_test.WaitTest" name="test_wait_with_condition" time="17.170" /><testcase classname="tests.integration.api_container_test.WaitTest" name="test_wait_with_dict_instead_of_id" time="10.884" /><testcase classname="tests.integration.api_container_test.LogsTest" name="test_logs" time="10.252" /><testcase classname="tests.integration.api_container_test.LogsTest" name="test_logs_streaming_and_follow" time="7.338" /><testcase classname="tests.integration.api_container_test.LogsTest" name="test_logs_streaming_and_follow_and_cancel" time="7.942"><failure message="Failed: Timeout &gt;5.0s">tests/integration/api_container_test.py:867: in test_logs_streaming_and_follow_and_cancel
    for chunk in generator:
docker/types/daemon.py:32: in __next__
    return next(self._stream)
docker/api/client.py:414: in _multiplexed_response_stream_helper
    header = response.raw.read(STREAM_HEADER_SIZE_BYTES)
../../.virtualenvs/docker-py/lib/python3.9/site-packages/urllib3/response.py:519: in read
    data = self._fp.read(amt) if not fp_closed else b""
/usr/lib/python3.9/http/client.py:462: in read
    n = self.readinto(b)
/usr/lib/python3.9/http/client.py:496: in readinto
    return self._readinto_chunked(b)
/usr/lib/python3.9/http/client.py:591: in _readinto_chunked
    chunk_left = self._get_chunk_left()
/usr/lib/python3.9/http/client.py:559: in _get_chunk_left
    chunk_left = self._read_next_chunk_size()
/usr/lib/python3.9/http/client.py:519: in _read_next_chunk_size
    line = self.fp.readline(_MAXLINE + 1)
/usr/lib/python3.9/socket.py:704: in readinto
    return self._sock.recv_into(b)
E   Failed: Timeout &gt;5.0s</failure><system-out>--------------------------------- Captured Log ---------------------------------

--------------------------------- Captured Out ---------------------------------

</system-out><system-err>--------------------------------- Captured Err ---------------------------------

+++++++++++++++++++++++++++++++++++ Timeout ++++++++++++++++++++++++++++++++++++

~~~~~~~~~~~~~~~~~~~~~ Stack of Thread-1 (139715118396992) ~~~~~~~~~~~~~~~~~~~~~~
  File "/usr/lib/python3.9/threading.py", line 930, in _bootstrap
    self._bootstrap_inner()
  File "/usr/lib/python3.9/threading.py", line 973, in _bootstrap_inner
    self.run()
  File "/usr/lib/python3.9/threading.py", line 1284, in run
    self.finished.wait(self.interval)
  File "/usr/lib/python3.9/threading.py", line 574, in wait
    signaled = self._cond.wait(timeout)
  File "/usr/lib/python3.9/threading.py", line 316, in wait
    gotit = waiter.acquire(True, timeout)

+++++++++++++++++++++++++++++++++++ Timeout ++++++++++++++++++++++++++++++++++++

</system-err></testcase><testcase classname="tests.integration.api_container_test.LogsTest" name="test_logs_tail_option" time="7.018" /><testcase classname="tests.integration.api_container_test.LogsTest" name="test_logs_with_dict_instead_of_id" time="7.159" /><testcase classname="tests.integration.api_container_test.LogsTest" name="test_logs_with_tail_0" time="7.029" /><testcase classname="tests.integration.api_container_test.LogsTest" name="test_logs_with_until" time="7.275" /><testcase classname="tests.integration.api_container_test.DiffTest" name="test_diff" time="6.860" /><testcase classname="tests.integration.api_container_test.DiffTest" name="test_diff_with_dict_instead_of_id" time="6.767" /><testcase classname="tests.integration.api_container_test.StopTest" name="test_stop" time="9.308" /><testcase classname="tests.integration.api_container_test.StopTest" name="test_stop_with_dict_instead_of_id" time="9.016" /><testcase classname="tests.integration.api_container_test.KillTest" name="test_kill" time="6.643" /><testcase classname="tests.integration.api_container_test.KillTest" name="test_kill_with_dict_instead_of_id" time="6.642" /><testcase classname="tests.integration.api_container_test.KillTest" name="test_kill_with_signal" time="6.837" /><testcase classname="tests.integration.api_container_test.KillTest" name="test_kill_with_signal_integer" time="6.617" /><testcase classname="tests.integration.api_container_test.KillTest" name="test_kill_with_signal_name" time="6.640" /><testcase classname="tests.integration.api_container_test.PortTest" name="test_port" time="6.900" /><testcase classname="tests.integration.api_container_test.ContainerTopTest" name="test_top" time="6.956"><skipped type="pytest.xfail" message="Output of docker top depends on host distro, and is not formalized." /></testcase><testcase classname="tests.integration.api_container_test.ContainerTopTest" name="test_top_with_psargs" time="6.847"><skipped type="pytest.xfail" message="Output of docker top depends on host distro, and is not formalized." /></testcase><testcase classname="tests.integration.api_container_test.RestartContainerTest" name="test_restart" time="9.195" /><testcase classname="tests.integration.api_container_test.RestartContainerTest" name="test_restart_with_dict_instead_of_id" time="9.020" /><testcase classname="tests.integration.api_container_test.RestartContainerTest" name="test_restart_with_low_timeout" time="9.754" /><testcase classname="tests.integration.api_container_test.RemoveContainerTest" name="test_remove" time="6.635" /><testcase classname="tests.integration.api_container_test.RemoveContainerTest" name="test_remove_with_dict_instead_of_id" time="6.678" /><testcase classname="tests.integration.api_container_test.AttachContainerTest" name="test_attach_no_stream" time="6.594"><failure message="docker.errors.APIError: 500 Server Error for http+docker://localhost/v1.40/containers/f6f17f9491fe059d9fe440d4cd2b42db0317f0fd0ed8835ca60425dad65c3a67/attach?logs=1&amp;stdout=1&amp;stderr=1&amp;stream=0: Internal Server Error (&quot;can only attach to created or running containers - currently in state stopped: container state improper&quot;)">docker/api/client.py:296: in _raise_for_status
    response.raise_for_status()
../../.virtualenvs/docker-py/lib/python3.9/site-packages/requests/models.py:953: in raise_for_status
    raise HTTPError(http_error_msg, response=self)
E   requests.exceptions.HTTPError: 500 Server Error: Internal Server Error for url: http+docker://localhost/v1.40/containers/f6f17f9491fe059d9fe440d4cd2b42db0317f0fd0ed8835ca60425dad65c3a67/attach?logs=1&amp;stdout=1&amp;stderr=1&amp;stream=0

During handling of the above exception, another exception occurred:
tests/integration/api_container_test.py:1229: in test_attach_no_stream
    output = self.client.attach(container, stream=False, logs=True)
docker/utils/decorators.py:19: in wrapped
    return f(self, resource_id, *args, **kwargs)
docker/api/container.py:60: in attach
    output = self._read_from_socket(
docker/api/client.py:441: in _read_from_socket
    socket = self._get_raw_response_socket(response)
docker/api/client.py:346: in _get_raw_response_socket
    self._raise_for_status(response)
docker/api/client.py:298: in _raise_for_status
    raise create_api_error_from_http_exception(e)
docker/errors.py:31: in create_api_error_from_http_exception
    raise cls(e, response=response, explanation=explanation)
E   docker.errors.APIError: 500 Server Error for http+docker://localhost/v1.40/containers/f6f17f9491fe059d9fe440d4cd2b42db0317f0fd0ed8835ca60425dad65c3a67/attach?logs=1&amp;stdout=1&amp;stderr=1&amp;stream=0: Internal Server Error ("can only attach to created or running containers - currently in state stopped: container state improper")</failure><system-out>--------------------------------- Captured Log ---------------------------------

--------------------------------- Captured Out ---------------------------------

</system-out><system-err>--------------------------------- Captured Err ---------------------------------

</system-err></testcase><testcase classname="tests.integration.api_container_test.AttachContainerTest" name="test_attach_stream_and_cancel" time="9.868" /><testcase classname="tests.integration.api_container_test.AttachContainerTest" name="test_detach_with_arg" time="7.369" /><testcase classname="tests.integration.api_container_test.AttachContainerTest" name="test_detach_with_config_file" time="7.270" /><testcase classname="tests.integration.api_container_test.AttachContainerTest" name="test_detach_with_default" time="7.952" /><testcase classname="tests.integration.api_container_test.AttachContainerTest" name="test_run_container_reading_socket" time="6.527" /><testcase classname="tests.integration.api_container_test.AttachContainerTest" name="test_run_container_streaming" time="6.796" /><testcase classname="tests.integration.api_container_test.PauseTest" name="test_pause_unpause" time="6.956" /><testcase classname="tests.integration.api_container_test.PruneTest" name="test_prune_containers" time="6.934" /><testcase classname="tests.integration.api_container_test.GetContainerStatsTest" name="test_get_container_stats_no_stream" time="6.620" /><testcase classname="tests.integration.api_container_test.ContainerUpdateTest" name="test_restart_policy_update" time="6.681"><failure message="docker.errors.NotFound: 404 Client Error for http+docker://localhost/v1.40/containers/e8281ee0f9f6bcc537d573e039a40528655a6970f9309a27d9af7bec1e6ba4be/update: Not Found (&quot;b'Not Found'&quot;)">docker/api/client.py:296: in _raise_for_status
    response.raise_for_status()
../../.virtualenvs/docker-py/lib/python3.9/site-packages/requests/models.py:953: in raise_for_status
    raise HTTPError(http_error_msg, response=self)
E   requests.exceptions.HTTPError: 404 Client Error: Not Found for url: http+docker://localhost/v1.40/containers/e8281ee0f9f6bcc537d573e039a40528655a6970f9309a27d9af7bec1e6ba4be/update

During handling of the above exception, another exception occurred:
tests/integration/api_container_test.py:1416: in test_restart_policy_update
    self.client.update_container(container,
docker/utils/decorators.py:34: in wrapper
    return f(self, *args, **kwargs)
docker/utils/decorators.py:19: in wrapped
    return f(self, resource_id, *args, **kwargs)
docker/api/container.py:1268: in update_container
    return self._result(res, True)
docker/api/client.py:302: in _result
    self._raise_for_status(response)
docker/api/client.py:298: in _raise_for_status
    raise create_api_error_from_http_exception(e)
docker/errors.py:31: in create_api_error_from_http_exception
    raise cls(e, response=response, explanation=explanation)
E   docker.errors.NotFound: 404 Client Error for http+docker://localhost/v1.40/containers/e8281ee0f9f6bcc537d573e039a40528655a6970f9309a27d9af7bec1e6ba4be/update: Not Found ("b'Not Found'")</failure><system-out>--------------------------------- Captured Log ---------------------------------

--------------------------------- Captured Out ---------------------------------

</system-out><system-err>--------------------------------- Captured Err ---------------------------------

</system-err></testcase><testcase classname="tests.integration.api_container_test.ContainerUpdateTest" name="test_update_container" time="6.731"><failure message="docker.errors.NotFound: 404 Client Error for http+docker://localhost/v1.40/containers/474e9bdd4e22829f0c9421255bf0bc5fa364f0ab07240a881c5c42b40b7e84d9/update: Not Found (&quot;b'Not Found'&quot;)">docker/api/client.py:296: in _raise_for_status
    response.raise_for_status()
../../.virtualenvs/docker-py/lib/python3.9/site-packages/requests/models.py:953: in raise_for_status
    raise HTTPError(http_error_msg, response=self)
E   requests.exceptions.HTTPError: 404 Client Error: Not Found for url: http+docker://localhost/v1.40/containers/474e9bdd4e22829f0c9421255bf0bc5fa364f0ab07240a881c5c42b40b7e84d9/update

During handling of the above exception, another exception occurred:
tests/integration/api_container_test.py:1394: in test_update_container
    self.client.update_container(container, mem_limit=new_mem_limit)
docker/utils/decorators.py:34: in wrapper
    return f(self, *args, **kwargs)
docker/utils/decorators.py:19: in wrapped
    return f(self, resource_id, *args, **kwargs)
docker/api/container.py:1268: in update_container
    return self._result(res, True)
docker/api/client.py:302: in _result
    self._raise_for_status(response)
docker/api/client.py:298: in _raise_for_status
    raise create_api_error_from_http_exception(e)
docker/errors.py:31: in create_api_error_from_http_exception
    raise cls(e, response=response, explanation=explanation)
E   docker.errors.NotFound: 404 Client Error for http+docker://localhost/v1.40/containers/474e9bdd4e22829f0c9421255bf0bc5fa364f0ab07240a881c5c42b40b7e84d9/update: Not Found ("b'Not Found'")</failure><system-out>--------------------------------- Captured Log ---------------------------------

--------------------------------- Captured Out ---------------------------------

</system-out><system-err>--------------------------------- Captured Err ---------------------------------

</system-err></testcase><testcase classname="tests.integration.api_container_test.ContainerCPUTest" name="test_container_cpu_shares" time="6.546" /><testcase classname="tests.integration.api_container_test.ContainerCPUTest" name="test_container_cpuset" time="6.544" /><testcase classname="tests.integration.api_container_test.ContainerCPUTest" name="test_create_with_runtime" time="6.238"><failure message="AssertionError: assert 'oci' == 'runc'&#10;  - runc&#10;  + oci">tests/integration/api_container_test.py:1461: in test_create_with_runtime
    assert config['HostConfig']['Runtime'] == 'runc'
E   AssertionError: assert 'oci' == 'runc'
E     - runc
E     + oci</failure><system-out>--------------------------------- Captured Log ---------------------------------

--------------------------------- Captured Out ---------------------------------

</system-out><system-err>--------------------------------- Captured Err ---------------------------------

</system-err></testcase><testcase classname="tests.integration.api_exec_test.ExecTest" name="test_detach_with_config_file" time="11.819"><failure message="AssertionError">/home/ubuntu/docker-py/tests/integration/api_exec_test.py:227: in test_detach_with_config_file
    ???
tests/helpers.py:137: in assert_cat_socket_detached_with_keys
    assert data == b'' or data.startswith(
E   AssertionError</failure><system-out>--------------------------------- Captured Log ---------------------------------

--------------------------------- Captured Out ---------------------------------

</system-out><system-err>--------------------------------- Captured Err ---------------------------------

</system-err></testcase><testcase classname="tests.integration.api_exec_test.ExecTest" name="test_detach_with_default" time="7.870" /><testcase classname="tests.integration.api_exec_test.ExecTest" name="test_exec_command_as_root" time="6.907" /><testcase classname="tests.integration.api_exec_test.ExecTest" name="test_exec_command_as_user" time="7.109" /><testcase classname="tests.integration.api_exec_test.ExecTest" name="test_exec_command_streaming" time="6.982" /><testcase classname="tests.integration.api_exec_test.ExecTest" name="test_exec_command_string" time="6.943" /><testcase classname="tests.integration.api_exec_test.ExecTest" name="test_exec_command_with_env" time="6.845" /><testcase classname="tests.integration.api_exec_test.ExecTest" name="test_exec_command_with_workdir" time="6.945" /><testcase classname="tests.integration.api_exec_test.ExecTest" name="test_exec_inspect" time="6.880" /><testcase classname="tests.integration.api_exec_test.ExecTest" name="test_exec_start_detached" time="6.970"><failure message="AssertionError: assert '\n' == ''&#10;  Strings contain only whitespace, escaping them using repr()&#10;  - ''&#10;  + '\n'">/home/ubuntu/docker-py/tests/integration/api_exec_test.py:152: in test_exec_start_detached
    ???
E   AssertionError: assert '\n' == ''
E     Strings contain only whitespace, escaping them using repr()
E     - ''
E     + '\n'</failure><system-out>--------------------------------- Captured Log ---------------------------------

--------------------------------- Captured Out ---------------------------------

</system-out><system-err>--------------------------------- Captured Err ---------------------------------

</system-err></testcase><testcase classname="tests.integration.api_exec_test.ExecTest" name="test_exec_start_socket" time="6.935"><failure message="AssertionError: assert 121 == 1&#10;  +121&#10;  -1">/home/ubuntu/docker-py/tests/integration/api_exec_test.py:134: in test_exec_start_socket
    ???
E   AssertionError: assert 121 == 1
E     +121
E     -1</failure><system-out>--------------------------------- Captured Log ---------------------------------

--------------------------------- Captured Out ---------------------------------

</system-out><system-err>--------------------------------- Captured Err ---------------------------------

</system-err></testcase><testcase classname="tests.integration.api_exec_test.ExecTest" name="test_execute_command" time="6.875" /><testcase classname="tests.integration.api_exec_test.ExecTest" name="test_execute_command_with_proxy_env" time="7.217" /><testcase classname="tests.integration.api_exec_test.ExecDemuxTest" name="test_exec_command_no_stream_demux" time="7.405" /><testcase classname="tests.integration.api_exec_test.ExecDemuxTest" name="test_exec_command_no_stream_no_demux" time="7.313" /><testcase classname="tests.integration.api_exec_test.ExecDemuxTest" name="test_exec_command_stream_demux" time="7.564" /><testcase classname="tests.integration.api_exec_test.ExecDemuxTest" name="test_exec_command_stream_no_demux" time="7.312" /><testcase classname="tests.integration.api_exec_test.ExecDemuxTest" name="test_exec_command_tty_no_stream_demux" time="6.850"><failure message="ValueError: 104 is not a valid stream">/home/ubuntu/docker-py/tests/integration/api_exec_test.py:299: in test_exec_command_tty_no_stream_demux
    ???
docker/utils/decorators.py:19: in wrapped
    return f(self, resource_id, *args, **kwargs)
docker/api/exec_api.py:173: in exec_start
    output = self._read_from_socket(res, stream, tty=tty, demux=demux)
docker/api/client.py:457: in _read_from_socket
    return consume_socket_output(gen, demux=demux)
docker/utils/socket.py:140: in consume_socket_output
    for frame in frames:
docker/api/client.py:447: in &lt;genexpr&gt;
    gen = (demux_adaptor(*frame) for frame in gen)
docker/utils/socket.py:167: in demux_adaptor
    raise ValueError(f'{stream_id} is not a valid stream')
E   ValueError: 104 is not a valid stream</failure><system-out>--------------------------------- Captured Log ---------------------------------

--------------------------------- Captured Out ---------------------------------

</system-out><system-err>--------------------------------- Captured Err ---------------------------------

</system-err></testcase><testcase classname="tests.integration.api_exec_test.ExecDemuxTest" name="test_exec_command_tty_no_stream_no_demux" time="7.423"><failure message="AssertionError: assert b't\r\nhello err\r\n' == b'hello out\r\nhello err\r\n'&#10;  At index 0 diff: b't' != b'h'&#10;  Full diff:&#10;  - b'hello out\r\nhello err\r\n'&#10;  ?   --------&#10;  + b't\r\nhello err\r\n'">/home/ubuntu/docker-py/tests/integration/api_exec_test.py:282: in test_exec_command_tty_no_stream_no_demux
    ???
E   AssertionError: assert b't\r\nhello err\r\n' == b'hello out\r\nhello err\r\n'
E     At index 0 diff: b't' != b'h'
E     Full diff:
E     - b'hello out\r\nhello err\r\n'
E     ?   --------
E     + b't\r\nhello err\r\n'</failure><system-out>--------------------------------- Captured Log ---------------------------------

--------------------------------- Captured Out ---------------------------------

</system-out><system-err>--------------------------------- Captured Err ---------------------------------

</system-err></testcase><testcase classname="tests.integration.api_exec_test.ExecDemuxTest" name="test_exec_command_tty_stream_demux" time="6.869"><failure message="ValueError: 104 is not a valid stream">/home/ubuntu/docker-py/tests/integration/api_exec_test.py:305: in test_exec_command_tty_stream_demux
    ???
docker/types/daemon.py:32: in __next__
    return next(self._stream)
docker/api/client.py:447: in &lt;genexpr&gt;
    gen = (demux_adaptor(*frame) for frame in gen)
docker/utils/socket.py:167: in demux_adaptor
    raise ValueError(f'{stream_id} is not a valid stream')
E   ValueError: 104 is not a valid stream</failure><system-out>--------------------------------- Captured Log ---------------------------------

--------------------------------- Captured Out ---------------------------------

</system-out><system-err>--------------------------------- Captured Err ---------------------------------

</system-err></testcase><testcase classname="tests.integration.api_exec_test.ExecDemuxTest" name="test_exec_command_tty_stream_no_demux" time="7.393"><failure message="AssertionError: assert b'hello out\r\n' in [b't\r\n', b'hello err\r\n']">/home/ubuntu/docker-py/tests/integration/api_exec_test.py:288: in test_exec_command_tty_stream_no_demux
    ???
E   AssertionError: assert b'hello out\r\n' in [b't\r\n', b'hello err\r\n']</failure><system-out>--------------------------------- Captured Log ---------------------------------

--------------------------------- Captured Out ---------------------------------

</system-out><system-err>--------------------------------- Captured Err ---------------------------------

</system-err></testcase><testcase classname="tests.integration.api_healthcheck_test.HealthcheckTest" name="test_healthcheck_fails" time="7.090" /><testcase classname="tests.integration.api_healthcheck_test.HealthcheckTest" name="test_healthcheck_passes" time="7.198" /><testcase classname="tests.integration.api_healthcheck_test.HealthcheckTest" name="test_healthcheck_shell_command" time="6.343" /><testcase classname="tests.integration.api_healthcheck_test.HealthcheckTest" name="test_healthcheck_start_period" time="11.035" /><testcase classname="tests.integration.api_image_test.ListImagesTest" name="test_images" time="7.896" /><testcase classname="tests.integration.api_image_test.ListImagesTest" name="test_images_quiet" time="6.655" /><testcase classname="tests.integration.api_image_test.PullImageTest" name="test_pull" time="9.412" /><testcase classname="tests.integration.api_image_test.PullImageTest" name="test_pull_invalid_platform" time="8.930"><failure message="Failed: DID NOT RAISE &lt;class 'docker.errors.APIError'&gt;">/home/ubuntu/docker-py/tests/integration/api_image_test.py:69: in test_pull_invalid_platform
    ???
E   Failed: DID NOT RAISE &lt;class 'docker.errors.APIError'&gt;</failure><system-out>--------------------------------- Captured Log ---------------------------------

--------------------------------- Captured Out ---------------------------------

</system-out><system-err>--------------------------------- Captured Err ---------------------------------

</system-err></testcase><testcase classname="tests.integration.api_image_test.PullImageTest" name="test_pull_streaming" time="9.110" /><testcase classname="tests.integration.api_image_test.CommitTest" name="test_commit" time="6.949"><failure message="AssertionError: assert False&#10; +  where False = &lt;built-in method startswith of str object at 0x7f11f973b670&gt;('caa59985d3243d7b58346eb25c8d80045fc6397d76ed5c6bea534ab38be31663')&#10; +    where &lt;built-in method startswith of str object at 0x7f11f973b670&gt; = ''.startswith">/home/ubuntu/docker-py/tests/integration/api_image_test.py:89: in test_commit
    ???
E   AssertionError: assert False
E    +  where False = &lt;built-in method startswith of str object at 0x7f11f973b670&gt;('caa59985d3243d7b58346eb25c8d80045fc6397d76ed5c6bea534ab38be31663')
E    +    where &lt;built-in method startswith of str object at 0x7f11f973b670&gt; = ''.startswith</failure><system-out>--------------------------------- Captured Log ---------------------------------

--------------------------------- Captured Out ---------------------------------

</system-out><system-err>--------------------------------- Captured Err ---------------------------------

</system-err></testcase><testcase classname="tests.integration.api_image_test.CommitTest" name="test_commit_with_changes" time="6.519"><failure message="docker.errors.APIError: 500 Server Error for http+docker://localhost/v1.40/commit?container=dd16e151fe898f8ae571b6c6c98c318c300ec1bcf73a8151f3a7710d92113d9e&amp;changes=EXPOSE+8000&amp;changes=CMD+%5B%22bash%22%5D: Internal Server Error (&quot;CommitFailure: invalid change &quot;CMD&quot; - must be formatted as KEY VALUE&quot;)">docker/api/client.py:296: in _raise_for_status
    response.raise_for_status()
../../.virtualenvs/docker-py/lib/python3.9/site-packages/requests/models.py:953: in raise_for_status
    raise HTTPError(http_error_msg, response=self)
E   requests.exceptions.HTTPError: 500 Server Error: Internal Server Error for url: http+docker://localhost/v1.40/commit?container=dd16e151fe898f8ae571b6c6c98c318c300ec1bcf73a8151f3a7710d92113d9e&amp;changes=EXPOSE+8000&amp;changes=CMD+%5B%22bash%22%5D

During handling of the above exception, another exception occurred:
/home/ubuntu/docker-py/tests/integration/api_image_test.py:101: in test_commit_with_changes
    ???
docker/utils/decorators.py:19: in wrapped
    return f(self, resource_id, *args, **kwargs)
docker/api/container.py:145: in commit
    return self._result(
docker/api/client.py:302: in _result
    self._raise_for_status(response)
docker/api/client.py:298: in _raise_for_status
    raise create_api_error_from_http_exception(e)
docker/errors.py:31: in create_api_error_from_http_exception
    raise cls(e, response=response, explanation=explanation)
E   docker.errors.APIError: 500 Server Error for http+docker://localhost/v1.40/commit?container=dd16e151fe898f8ae571b6c6c98c318c300ec1bcf73a8151f3a7710d92113d9e&amp;changes=EXPOSE+8000&amp;changes=CMD+%5B%22bash%22%5D: Internal Server Error ("CommitFailure: invalid change "CMD" - must be formatted as KEY VALUE")</failure><system-out>--------------------------------- Captured Log ---------------------------------

--------------------------------- Captured Out ---------------------------------

</system-out><system-err>--------------------------------- Captured Err ---------------------------------

</system-err></testcase><testcase classname="tests.integration.api_image_test.RemoveImageTest" name="test_remove" time="7.651" /><testcase classname="tests.integration.api_image_test.ImportImageTest" name="test_get_load_image" time="9.239"><failure message="AssertionError: assert False&#10; +  where False = any([])">/home/ubuntu/docker-py/tests/integration/api_image_test.py:266: in test_get_load_image
    ???
E   AssertionError: assert False
E    +  where False = any([])</failure><system-out>--------------------------------- Captured Log ---------------------------------

--------------------------------- Captured Out ---------------------------------

</system-out><system-err>--------------------------------- Captured Err ---------------------------------

</system-err></testcase><testcase classname="tests.integration.api_image_test.ImportImageTest" name="test_import_from_bytes" time="6.419" /><testcase classname="tests.integration.api_image_test.ImportImageTest" name="test_import_from_file" time="6.361" /><testcase classname="tests.integration.api_image_test.ImportImageTest" name="test_import_from_stream" time="6.391" /><testcase classname="tests.integration.api_image_test.ImportImageTest" name="test_import_from_url" time="0.000"><skipped type="pytest.skip" message="Doesn't work inside a container - FIXME">/home/ubuntu/docker-py/tests/integration/api_image_test.py:291: Doesn't work inside a container - FIXME</skipped><system-out>--------------------------------- Captured Log ---------------------------------

--------------------------------- Captured Out ---------------------------------

</system-out><system-err>--------------------------------- Captured Err ---------------------------------

</system-err></testcase><testcase classname="tests.integration.api_image_test.ImportImageTest" name="test_import_image_from_data_with_changes" time="6.345" /><testcase classname="tests.integration.api_image_test.ImportImageTest" name="test_import_image_with_changes" time="6.542" /><testcase classname="tests.integration.api_image_test.PruneImagesTest" name="test_prune_images" time="10.366"><failure message="docker.errors.APIError: 500 Server Error for http+docker://localhost/v1.40/images/prune: Internal Server Error (&quot;Image used by c7399d80f789d1256b30219188f4bb297f6aeed18d7b193d9963367a7fab9d24: image is in use by a container&quot;)">docker/api/client.py:296: in _raise_for_status
    response.raise_for_status()
../../.virtualenvs/docker-py/lib/python3.9/site-packages/requests/models.py:953: in raise_for_status
    raise HTTPError(http_error_msg, response=self)
E   requests.exceptions.HTTPError: 500 Server Error: Internal Server Error for url: http+docker://localhost/v1.40/images/prune

During handling of the above exception, another exception occurred:
/home/ubuntu/docker-py/tests/integration/api_image_test.py:327: in test_prune_images
    ???
docker/utils/decorators.py:34: in wrapper
    return f(self, *args, **kwargs)
docker/api/image.py:349: in prune_images
    return self._result(self._post(url, params=params), True)
docker/api/client.py:302: in _result
    self._raise_for_status(response)
docker/api/client.py:298: in _raise_for_status
    raise create_api_error_from_http_exception(e)
docker/errors.py:31: in create_api_error_from_http_exception
    raise cls(e, response=response, explanation=explanation)
E   docker.errors.APIError: 500 Server Error for http+docker://localhost/v1.40/images/prune: Internal Server Error ("Image used by c7399d80f789d1256b30219188f4bb297f6aeed18d7b193d9963367a7fab9d24: image is in use by a container")</failure><system-out>--------------------------------- Captured Log ---------------------------------

--------------------------------- Captured Out ---------------------------------

</system-out><system-err>--------------------------------- Captured Err ---------------------------------

</system-err></testcase><testcase classname="tests.integration.api_image_test.SaveLoadImagesTest" name="test_get_image_load_image" time="6.775"><failure message="AssertionError: assert False is True">/home/ubuntu/docker-py/tests/integration/api_image_test.py:360: in test_get_image_load_image
    ???
E   AssertionError: assert False is True</failure><system-out>--------------------------------- Captured Log ---------------------------------

--------------------------------- Captured Out ---------------------------------
{'stream': 'Loaded image: docker.io/library/alpine:3.10\n'}

</system-out><system-err>--------------------------------- Captured Err ---------------------------------

</system-err></testcase><testcase classname="tests.integration.api_image_test.InspectDistributionTest" name="test_inspect_distribution" time="7.205"><failure message="docker.errors.NotFound: 404 Client Error for http+docker://localhost/v1.40/distribution/busybox:latest/json: Not Found (&quot;Path /v1.40/distribution/busybox:latest/json is not supported&quot;)">docker/api/client.py:296: in _raise_for_status
    response.raise_for_status()
../../.virtualenvs/docker-py/lib/python3.9/site-packages/requests/models.py:953: in raise_for_status
    raise HTTPError(http_error_msg, response=self)
E   requests.exceptions.HTTPError: 404 Client Error: Not Found for url: http+docker://localhost/v1.40/distribution/busybox:latest/json

During handling of the above exception, another exception occurred:
/home/ubuntu/docker-py/tests/integration/api_image_test.py:366: in test_inspect_distribution
    ???
docker/utils/decorators.py:34: in wrapper
    return f(self, *args, **kwargs)
docker/utils/decorators.py:19: in wrapped
    return f(self, resource_id, *args, **kwargs)
docker/api/image.py:287: in inspect_distribution
    return self._result(
docker/api/client.py:302: in _result
    self._raise_for_status(response)
docker/api/client.py:298: in _raise_for_status
    raise create_api_error_from_http_exception(e)
docker/errors.py:31: in create_api_error_from_http_exception
    raise cls(e, response=response, explanation=explanation)
E   docker.errors.NotFound: 404 Client Error for http+docker://localhost/v1.40/distribution/busybox:latest/json: Not Found ("Path /v1.40/distribution/busybox:latest/json is not supported")</failure><system-out>--------------------------------- Captured Log ---------------------------------

--------------------------------- Captured Out ---------------------------------

</system-out><system-err>--------------------------------- Captured Err ---------------------------------

</system-err></testcase><testcase classname="tests.integration.api_network_test.TestNetworks" name="test_connect_and_disconnect_container" time="7.391" /><testcase classname="tests.integration.api_network_test.TestNetworks" name="test_connect_and_force_disconnect_container" time="7.462" /><testcase classname="tests.integration.api_network_test.TestNetworks" name="test_connect_on_container_create" time="7.256" /><testcase classname="tests.integration.api_network_test.TestNetworks" name="test_connect_with_aliases" time="7.449" /><testcase classname="tests.integration.api_network_test.TestNetworks" name="test_connect_with_ipv4_address" time="6.865"><failure message="docker.errors.APIError: 500 Server Error for http+docker://localhost/v1.40/containers/12fcb088dfb863282c710100b86a2438e84543b34c08079e848cb3f6aa519973/start: Internal Server Error (&quot;error configuring network namespace for container 12fcb088dfb863282c710100b86a2438e84543b34c08079e848cb3f6aa519973: error adding pod tender_mcclintock_tender_mcclintock to CNI network &quot;dockerpytest_1f0caafc806608eb&quot;: failed to set bridge addr: &quot;cni-podman1&quot; already has an IP address different from 172.28.5.254/16&quot;)">docker/api/client.py:296: in _raise_for_status
    response.raise_for_status()
../../.virtualenvs/docker-py/lib/python3.9/site-packages/requests/models.py:953: in raise_for_status
    raise HTTPError(http_error_msg, response=self)
E   requests.exceptions.HTTPError: 500 Server Error: Internal Server Error for url: http+docker://localhost/v1.40/containers/12fcb088dfb863282c710100b86a2438e84543b34c08079e848cb3f6aa519973/start

During handling of the above exception, another exception occurred:
tests/integration/api_network_test.py:369: in test_connect_with_ipv4_address
    container = self.create_and_start(
tests/integration/base.py:124: in create_and_start
    self.client.start(container)
docker/utils/decorators.py:19: in wrapped
    return f(self, resource_id, *args, **kwargs)
docker/api/container.py:1109: in start
    self._raise_for_status(res)
docker/api/client.py:298: in _raise_for_status
    raise create_api_error_from_http_exception(e)
docker/errors.py:31: in create_api_error_from_http_exception
    raise cls(e, response=response, explanation=explanation)
E   docker.errors.APIError: 500 Server Error for http+docker://localhost/v1.40/containers/12fcb088dfb863282c710100b86a2438e84543b34c08079e848cb3f6aa519973/start: Internal Server Error ("error configuring network namespace for container 12fcb088dfb863282c710100b86a2438e84543b34c08079e848cb3f6aa519973: error adding pod tender_mcclintock_tender_mcclintock to CNI network "dockerpytest_1f0caafc806608eb": failed to set bridge addr: "cni-podman1" already has an IP address different from 172.28.5.254/16")</failure><system-out>--------------------------------- Captured Log ---------------------------------

--------------------------------- Captured Out ---------------------------------

</system-out><system-err>--------------------------------- Captured Err ---------------------------------

</system-err></testcase><testcase classname="tests.integration.api_network_test.TestNetworks" name="test_connect_with_ipv6_address" time="10.866"><failure message="TypeError: 'NoneType' object is not subscriptable">tests/integration/api_network_test.py:405: in test_connect_with_ipv6_address
    assert net_data['IPAMConfig']['IPv6Address'] == '2001:389::f00d'
E   TypeError: 'NoneType' object is not subscriptable</failure><system-out>--------------------------------- Captured Log ---------------------------------

--------------------------------- Captured Out ---------------------------------

</system-out><system-err>--------------------------------- Captured Err ---------------------------------

</system-err></testcase><testcase classname="tests.integration.api_network_test.TestNetworks" name="test_connect_with_links" time="7.239"><failure message="AssertionError: assert None == ['docker-py-t...upstream:bar']&#10;  +None&#10;  -['docker-py-test-upstream:bar']">tests/integration/api_network_test.py:344: in test_connect_with_links
    assert net_settings['Networks'][net_name]['Links'] == [
E   AssertionError: assert None == ['docker-py-t...upstream:bar']
E     +None
E     -['docker-py-test-upstream:bar']</failure><system-out>--------------------------------- Captured Log ---------------------------------

--------------------------------- Captured Out ---------------------------------

</system-out><system-err>--------------------------------- Captured Err ---------------------------------

</system-err></testcase><testcase classname="tests.integration.api_network_test.TestNetworks" name="test_create_check_duplicate" time="6.871"><failure message="docker.errors.APIError: 500 Server Error for http+docker://localhost/v1.40/networks/create: Internal Server Error (&quot;the network name dockerpytest_83769dc42c9f1478 is already used&quot;)">docker/api/client.py:296: in _raise_for_status
    response.raise_for_status()
../../.virtualenvs/docker-py/lib/python3.9/site-packages/requests/models.py:953: in raise_for_status
    raise HTTPError(http_error_msg, response=self)
E   requests.exceptions.HTTPError: 500 Server Error: Internal Server Error for url: http+docker://localhost/v1.40/networks/create

During handling of the above exception, another exception occurred:
tests/integration/api_network_test.py:326: in test_create_check_duplicate
    net_id = self.client.create_network(net_name, check_duplicate=False)
docker/api/network.py:153: in create_network
    return self._result(res, json=True)
docker/api/client.py:302: in _result
    self._raise_for_status(response)
docker/api/client.py:298: in _raise_for_status
    raise create_api_error_from_http_exception(e)
docker/errors.py:31: in create_api_error_from_http_exception
    raise cls(e, response=response, explanation=explanation)
E   docker.errors.APIError: 500 Server Error for http+docker://localhost/v1.40/networks/create: Internal Server Error ("the network name dockerpytest_83769dc42c9f1478 is already used")</failure><system-out>--------------------------------- Captured Log ---------------------------------

--------------------------------- Captured Out ---------------------------------

</system-out><system-err>--------------------------------- Captured Err ---------------------------------

</system-err></testcase><testcase classname="tests.integration.api_network_test.TestNetworks" name="test_create_internal_networks" time="6.332" /><testcase classname="tests.integration.api_network_test.TestNetworks" name="test_create_network_ipv6_enabled" time="7.229"><failure message="AssertionError: assert False is True">tests/integration/api_network_test.py:445: in test_create_network_ipv6_enabled
    assert net['EnableIPv6'] is True
E   AssertionError: assert False is True</failure><system-out>--------------------------------- Captured Log ---------------------------------

--------------------------------- Captured Out ---------------------------------

</system-out><system-err>--------------------------------- Captured Err ---------------------------------

</system-err></testcase><testcase classname="tests.integration.api_network_test.TestNetworks" name="test_create_network_with_host_driver_fails" time="6.481" /><testcase classname="tests.integration.api_network_test.TestNetworks" name="test_create_network_with_ipam_config" time="6.523"><failure message="AssertionError: assert {} is None&#10; +  where {} = &lt;built-in method pop of dict object at 0x7f11f6433a80&gt;('Options', None)&#10; +    where &lt;built-in method pop of dict object at 0x7f11f6433a80&gt; = {'Config': [{'Gateway': '172.28.5.254', 'Subnet': '172.28.0.0/16'}], 'Driver': 'default'}.pop">tests/integration/api_network_test.py:62: in test_create_network_with_ipam_config
    assert ipam.pop('Options', None) is None
E   AssertionError: assert {} is None
E    +  where {} = &lt;built-in method pop of dict object at 0x7f11f6433a80&gt;('Options', None)
E    +    where &lt;built-in method pop of dict object at 0x7f11f6433a80&gt; = {'Config': [{'Gateway': '172.28.5.254', 'Subnet': '172.28.0.0/16'}], 'Driver': 'default'}.pop</failure><system-out>--------------------------------- Captured Log ---------------------------------

--------------------------------- Captured Out ---------------------------------

</system-out><system-err>--------------------------------- Captured Err ---------------------------------

</system-err></testcase><testcase classname="tests.integration.api_network_test.TestNetworks" name="test_create_network_with_labels" time="7.260" /><testcase classname="tests.integration.api_network_test.TestNetworks" name="test_create_network_with_labels_wrong_type" time="6.822" /><testcase classname="tests.integration.api_network_test.TestNetworks" name="test_create_remove_network_with_space_in_name" time="6.364" /><testcase classname="tests.integration.api_network_test.TestNetworks" name="test_create_with_aliases" time="6.726" /><testcase classname="tests.integration.api_network_test.TestNetworks" name="test_create_with_driveropt" time="6.313"><failure message="docker.errors.APIError: 500 Server Error for http+docker://localhost/v1.40/containers/create: Internal Server Error (&quot;container create: unable to find network configuration for bridge: network not found&quot;)">docker/api/client.py:296: in _raise_for_status
    response.raise_for_status()
../../.virtualenvs/docker-py/lib/python3.9/site-packages/requests/models.py:953: in raise_for_status
    raise HTTPError(http_error_msg, response=self)
E   requests.exceptions.HTTPError: 500 Server Error: Internal Server Error for url: http+docker://localhost/v1.40/containers/create

During handling of the above exception, another exception occurred:
tests/integration/api_network_test.py:276: in test_create_with_driveropt
    container = self.client.create_container(
docker/api/container.py:428: in create_container
    return self.create_container_from_config(config, name)
docker/api/container.py:439: in create_container_from_config
    return self._result(res, True)
docker/api/client.py:302: in _result
    self._raise_for_status(response)
docker/api/client.py:298: in _raise_for_status
    raise create_api_error_from_http_exception(e)
docker/errors.py:31: in create_api_error_from_http_exception
    raise cls(e, response=response, explanation=explanation)
E   docker.errors.APIError: 500 Server Error for http+docker://localhost/v1.40/containers/create: Internal Server Error ("container create: unable to find network configuration for bridge: network not found")</failure><system-out>--------------------------------- Captured Log ---------------------------------

--------------------------------- Captured Out ---------------------------------

</system-out><system-err>--------------------------------- Captured Err ---------------------------------

</system-err></testcase><testcase classname="tests.integration.api_network_test.TestNetworks" name="test_create_with_ipv4_address" time="6.597"><failure message="docker.errors.APIError: 500 Server Error for http+docker://localhost/v1.40/containers/77424df1a6a5e02d4ee5e58f1f9bb8153fb2569eb84f08864d578e6af52c8468/start: Internal Server Error (&quot;error configuring network namespace for container 77424df1a6a5e02d4ee5e58f1f9bb8153fb2569eb84f08864d578e6af52c8468: error adding pod wizardly_nash_wizardly_nash to CNI network &quot;dockerpytest_e6c52d1b862034&quot;: failed to set bridge addr: &quot;cni-podman1&quot; already has an IP address different from 132.124.0.1/16&quot;)">docker/api/client.py:296: in _raise_for_status
    response.raise_for_status()
../../.virtualenvs/docker-py/lib/python3.9/site-packages/requests/models.py:953: in raise_for_status
    raise HTTPError(http_error_msg, response=self)
E   requests.exceptions.HTTPError: 500 Server Error: Internal Server Error for url: http+docker://localhost/v1.40/containers/77424df1a6a5e02d4ee5e58f1f9bb8153fb2569eb84f08864d578e6af52c8468/start

During handling of the above exception, another exception occurred:
tests/integration/api_network_test.py:219: in test_create_with_ipv4_address
    self.client.start(container)
docker/utils/decorators.py:19: in wrapped
    return f(self, resource_id, *args, **kwargs)
docker/api/container.py:1109: in start
    self._raise_for_status(res)
docker/api/client.py:298: in _raise_for_status
    raise create_api_error_from_http_exception(e)
docker/errors.py:31: in create_api_error_from_http_exception
    raise cls(e, response=response, explanation=explanation)
E   docker.errors.APIError: 500 Server Error for http+docker://localhost/v1.40/containers/77424df1a6a5e02d4ee5e58f1f9bb8153fb2569eb84f08864d578e6af52c8468/start: Internal Server Error ("error configuring network namespace for container 77424df1a6a5e02d4ee5e58f1f9bb8153fb2569eb84f08864d578e6af52c8468: error adding pod wizardly_nash_wizardly_nash to CNI network "dockerpytest_e6c52d1b862034": failed to set bridge addr: "cni-podman1" already has an IP address different from 132.124.0.1/16")</failure><system-out>--------------------------------- Captured Log ---------------------------------

--------------------------------- Captured Out ---------------------------------

</system-out><system-err>--------------------------------- Captured Err ---------------------------------

</system-err></testcase><testcase classname="tests.integration.api_network_test.TestNetworks" name="test_create_with_ipv6_address" time="7.985"><failure message="docker.errors.APIError: 500 Server Error for http+docker://localhost/v1.40/containers/5834a76d644ba004e672d5dd011d2313acae56fa8f46a4dc46b146c1eb47b64b/start: Internal Server Error (&quot;error configuring network namespace for container 5834a76d644ba004e672d5dd011d2313acae56fa8f46a4dc46b146c1eb47b64b: error adding pod determined_chatterjee_determined_chatterjee to CNI network &quot;dockerpytest_74ef133c41d57373&quot;: failed to set bridge addr: &quot;cni-podman1&quot; already has an IP address different from 2001:389::1/64&quot;)">docker/api/client.py:296: in _raise_for_status
    response.raise_for_status()
../../.virtualenvs/docker-py/lib/python3.9/site-packages/requests/models.py:953: in raise_for_status
    raise HTTPError(http_error_msg, response=self)
E   requests.exceptions.HTTPError: 500 Server Error: Internal Server Error for url: http+docker://localhost/v1.40/containers/5834a76d644ba004e672d5dd011d2313acae56fa8f46a4dc46b146c1eb47b64b/start

During handling of the above exception, another exception occurred:
tests/integration/api_network_test.py:245: in test_create_with_ipv6_address
    self.client.start(container)
docker/utils/decorators.py:19: in wrapped
    return f(self, resource_id, *args, **kwargs)
docker/api/container.py:1109: in start
    self._raise_for_status(res)
docker/api/client.py:298: in _raise_for_status
    raise create_api_error_from_http_exception(e)
docker/errors.py:31: in create_api_error_from_http_exception
    raise cls(e, response=response, explanation=explanation)
E   docker.errors.APIError: 500 Server Error for http+docker://localhost/v1.40/containers/5834a76d644ba004e672d5dd011d2313acae56fa8f46a4dc46b146c1eb47b64b/start: Internal Server Error ("error configuring network namespace for container 5834a76d644ba004e672d5dd011d2313acae56fa8f46a4dc46b146c1eb47b64b: error adding pod determined_chatterjee_determined_chatterjee to CNI network "dockerpytest_74ef133c41d57373": failed to set bridge addr: "cni-podman1" already has an IP address different from 2001:389::1/64")</failure><system-out>--------------------------------- Captured Log ---------------------------------

--------------------------------- Captured Out ---------------------------------

</system-out><system-err>--------------------------------- Captured Err ---------------------------------

</system-err></testcase><testcase classname="tests.integration.api_network_test.TestNetworks" name="test_create_with_linklocal_ips" time="6.289"><failure message="docker.errors.APIError: 500 Server Error for http+docker://localhost/v1.40/containers/create: Internal Server Error (&quot;container create: unable to find network configuration for bridge: network not found&quot;)">docker/api/client.py:296: in _raise_for_status
    response.raise_for_status()
../../.virtualenvs/docker-py/lib/python3.9/site-packages/requests/models.py:953: in raise_for_status
    raise HTTPError(http_error_msg, response=self)
E   requests.exceptions.HTTPError: 500 Server Error: Internal Server Error for url: http+docker://localhost/v1.40/containers/create

During handling of the above exception, another exception occurred:
tests/integration/api_network_test.py:255: in test_create_with_linklocal_ips
    container = self.client.create_container(
docker/api/container.py:428: in create_container
    return self.create_container_from_config(config, name)
docker/api/container.py:439: in create_container_from_config
    return self._result(res, True)
docker/api/client.py:302: in _result
    self._raise_for_status(response)
docker/api/client.py:298: in _raise_for_status
    raise create_api_error_from_http_exception(e)
docker/errors.py:31: in create_api_error_from_http_exception
    raise cls(e, response=response, explanation=explanation)
E   docker.errors.APIError: 500 Server Error for http+docker://localhost/v1.40/containers/create: Internal Server Error ("container create: unable to find network configuration for bridge: network not found")</failure><system-out>--------------------------------- Captured Log ---------------------------------

--------------------------------- Captured Out ---------------------------------

</system-out><system-err>--------------------------------- Captured Err ---------------------------------

</system-err></testcase><testcase classname="tests.integration.api_network_test.TestNetworks" name="test_create_with_links" time="6.812"><failure message="AssertionError: assert None == ['docker-py-t...upstream:bar']&#10;  +None&#10;  -['docker-py-test-upstream:bar']">tests/integration/api_network_test.py:311: in test_create_with_links
    assert net_settings['Networks'][net_name]['Links'] == [
E   AssertionError: assert None == ['docker-py-t...upstream:bar']
E     +None
E     -['docker-py-test-upstream:bar']</failure><system-out>--------------------------------- Captured Log ---------------------------------

--------------------------------- Captured Out ---------------------------------

</system-out><system-err>--------------------------------- Captured Err ---------------------------------

</system-err></testcase><testcase classname="tests.integration.api_network_test.TestNetworks" name="test_inspect_network" time="6.275" /><testcase classname="tests.integration.api_network_test.TestNetworks" name="test_list_networks" time="6.382" /><testcase classname="tests.integration.api_network_test.TestNetworks" name="test_prune_networks" time="6.235" /><testcase classname="tests.integration.api_network_test.TestNetworks" name="test_remove_network" time="6.429" /><testcase classname="tests.integration.api_secret_test.SecretAPITest" name="test_create_secret" time="4.143"><error message="failed on setup with &quot;docker.errors.APIError: 503 Server Error for http+docker://localhost/v1.40/swarm/init: Service Unavailable (&quot;Podman does not support service: /v1.40/swarm/init&quot;)&quot;">docker/api/client.py:296: in _raise_for_status
    response.raise_for_status()
../../.virtualenvs/docker-py/lib/python3.9/site-packages/requests/models.py:953: in raise_for_status
    raise HTTPError(http_error_msg, response=self)
E   requests.exceptions.HTTPError: 503 Server Error: Service Unavailable for url: http+docker://localhost/v1.40/swarm/init

During handling of the above exception, another exception occurred:
tests/integration/api_secret_test.py:15: in setup_class
    cls._init_swarm(client)
tests/integration/base.py:94: in _init_swarm
    return client.init_swarm(
docker/utils/decorators.py:34: in wrapper
    return f(self, *args, **kwargs)
docker/api/swarm.py:170: in init_swarm
    return self._result(response, json=True)
docker/api/client.py:302: in _result
    self._raise_for_status(response)
docker/api/client.py:298: in _raise_for_status
    raise create_api_error_from_http_exception(e)
docker/errors.py:31: in create_api_error_from_http_exception
    raise cls(e, response=response, explanation=explanation)
E   docker.errors.APIError: 503 Server Error for http+docker://localhost/v1.40/swarm/init: Service Unavailable ("Podman does not support service: /v1.40/swarm/init")</error></testcase><testcase classname="tests.integration.api_secret_test.SecretAPITest" name="test_create_secret_unicode_data" time="0.001"><error message="failed on setup with &quot;docker.errors.APIError: 503 Server Error for http+docker://localhost/v1.40/swarm/init: Service Unavailable (&quot;Podman does not support service: /v1.40/swarm/init&quot;)&quot;">docker/api/client.py:296: in _raise_for_status
    response.raise_for_status()
../../.virtualenvs/docker-py/lib/python3.9/site-packages/requests/models.py:953: in raise_for_status
    raise HTTPError(http_error_msg, response=self)
E   requests.exceptions.HTTPError: 503 Server Error: Service Unavailable for url: http+docker://localhost/v1.40/swarm/init

During handling of the above exception, another exception occurred:
tests/integration/api_secret_test.py:15: in setup_class
    cls._init_swarm(client)
tests/integration/base.py:94: in _init_swarm
    return client.init_swarm(
docker/utils/decorators.py:34: in wrapper
    return f(self, *args, **kwargs)
docker/api/swarm.py:170: in init_swarm
    return self._result(response, json=True)
docker/api/client.py:302: in _result
    self._raise_for_status(response)
docker/api/client.py:298: in _raise_for_status
    raise create_api_error_from_http_exception(e)
docker/errors.py:31: in create_api_error_from_http_exception
    raise cls(e, response=response, explanation=explanation)
E   docker.errors.APIError: 503 Server Error for http+docker://localhost/v1.40/swarm/init: Service Unavailable ("Podman does not support service: /v1.40/swarm/init")</error></testcase><testcase classname="tests.integration.api_secret_test.SecretAPITest" name="test_inspect_secret" time="0.000"><error message="failed on setup with &quot;docker.errors.APIError: 503 Server Error for http+docker://localhost/v1.40/swarm/init: Service Unavailable (&quot;Podman does not support service: /v1.40/swarm/init&quot;)&quot;">docker/api/client.py:296: in _raise_for_status
    response.raise_for_status()
../../.virtualenvs/docker-py/lib/python3.9/site-packages/requests/models.py:953: in raise_for_status
    raise HTTPError(http_error_msg, response=self)
E   requests.exceptions.HTTPError: 503 Server Error: Service Unavailable for url: http+docker://localhost/v1.40/swarm/init

During handling of the above exception, another exception occurred:
tests/integration/api_secret_test.py:15: in setup_class
    cls._init_swarm(client)
tests/integration/base.py:94: in _init_swarm
    return client.init_swarm(
docker/utils/decorators.py:34: in wrapper
    return f(self, *args, **kwargs)
docker/api/swarm.py:170: in init_swarm
    return self._result(response, json=True)
docker/api/client.py:302: in _result
    self._raise_for_status(response)
docker/api/client.py:298: in _raise_for_status
    raise create_api_error_from_http_exception(e)
docker/errors.py:31: in create_api_error_from_http_exception
    raise cls(e, response=response, explanation=explanation)
E   docker.errors.APIError: 503 Server Error for http+docker://localhost/v1.40/swarm/init: Service Unavailable ("Podman does not support service: /v1.40/swarm/init")</error></testcase><testcase classname="tests.integration.api_secret_test.SecretAPITest" name="test_list_secrets" time="0.000"><error message="failed on setup with &quot;docker.errors.APIError: 503 Server Error for http+docker://localhost/v1.40/swarm/init: Service Unavailable (&quot;Podman does not support service: /v1.40/swarm/init&quot;)&quot;">docker/api/client.py:296: in _raise_for_status
    response.raise_for_status()
../../.virtualenvs/docker-py/lib/python3.9/site-packages/requests/models.py:953: in raise_for_status
    raise HTTPError(http_error_msg, response=self)
E   requests.exceptions.HTTPError: 503 Server Error: Service Unavailable for url: http+docker://localhost/v1.40/swarm/init

During handling of the above exception, another exception occurred:
tests/integration/api_secret_test.py:15: in setup_class
    cls._init_swarm(client)
tests/integration/base.py:94: in _init_swarm
    return client.init_swarm(
docker/utils/decorators.py:34: in wrapper
    return f(self, *args, **kwargs)
docker/api/swarm.py:170: in init_swarm
    return self._result(response, json=True)
docker/api/client.py:302: in _result
    self._raise_for_status(response)
docker/api/client.py:298: in _raise_for_status
    raise create_api_error_from_http_exception(e)
docker/errors.py:31: in create_api_error_from_http_exception
    raise cls(e, response=response, explanation=explanation)
E   docker.errors.APIError: 503 Server Error for http+docker://localhost/v1.40/swarm/init: Service Unavailable ("Podman does not support service: /v1.40/swarm/init")</error></testcase><testcase classname="tests.integration.api_secret_test.SecretAPITest" name="test_remove_secret" time="0.000"><error message="failed on setup with &quot;docker.errors.APIError: 503 Server Error for http+docker://localhost/v1.40/swarm/init: Service Unavailable (&quot;Podman does not support service: /v1.40/swarm/init&quot;)&quot;">docker/api/client.py:296: in _raise_for_status
    response.raise_for_status()
../../.virtualenvs/docker-py/lib/python3.9/site-packages/requests/models.py:953: in raise_for_status
    raise HTTPError(http_error_msg, response=self)
E   requests.exceptions.HTTPError: 503 Server Error: Service Unavailable for url: http+docker://localhost/v1.40/swarm/init

During handling of the above exception, another exception occurred:
tests/integration/api_secret_test.py:15: in setup_class
    cls._init_swarm(client)
tests/integration/base.py:94: in _init_swarm
    return client.init_swarm(
docker/utils/decorators.py:34: in wrapper
    return f(self, *args, **kwargs)
docker/api/swarm.py:170: in init_swarm
    return self._result(response, json=True)
docker/api/client.py:302: in _result
    self._raise_for_status(response)
docker/api/client.py:298: in _raise_for_status
    raise create_api_error_from_http_exception(e)
docker/errors.py:31: in create_api_error_from_http_exception
    raise cls(e, response=response, explanation=explanation)
E   docker.errors.APIError: 503 Server Error for http+docker://localhost/v1.40/swarm/init: Service Unavailable ("Podman does not support service: /v1.40/swarm/init")</error></testcase><testcase classname="tests.integration.api_volume_test.TestVolumes" name="test_create_volume" time="6.254" /><testcase classname="tests.integration.api_volume_test.TestVolumes" name="test_create_volume_invalid_driver" time="6.279"><failure message="docker.errors.APIError: 500 Server Error for http+docker://localhost/v1.40/volumes/create: Internal Server Error (&quot;volume perfectcherryblossom uses volume plugin invalid.driver but it could not be retrieved: no volume plugin with name invalid.driver available: required plugin missing&quot;)">docker/api/client.py:296: in _raise_for_status
    response.raise_for_status()
../../.virtualenvs/docker-py/lib/python3.9/site-packages/requests/models.py:953: in raise_for_status
    raise HTTPError(http_error_msg, response=self)
E   requests.exceptions.HTTPError: 500 Server Error: Internal Server Error for url: http+docker://localhost/v1.40/volumes/create

During handling of the above exception, another exception occurred:
/home/ubuntu/docker-py/tests/integration/api_volume_test.py:22: in test_create_volume_invalid_driver
    ???
docker/api/volume.py:89: in create_volume
    return self._result(self._post_json(url, data=data), True)
docker/api/client.py:302: in _result
    self._raise_for_status(response)
docker/api/client.py:298: in _raise_for_status
    raise create_api_error_from_http_exception(e)
docker/errors.py:31: in create_api_error_from_http_exception
    raise cls(e, response=response, explanation=explanation)
E   docker.errors.APIError: 500 Server Error for http+docker://localhost/v1.40/volumes/create: Internal Server Error ("volume perfectcherryblossom uses volume plugin invalid.driver but it could not be retrieved: no volume plugin with name invalid.driver available: required plugin missing")</failure><system-out>--------------------------------- Captured Log ---------------------------------

--------------------------------- Captured Out ---------------------------------

</system-out><system-err>--------------------------------- Captured Err ---------------------------------

</system-err></testcase><testcase classname="tests.integration.api_volume_test.TestVolumes" name="test_force_remove_volume" time="6.215" /><testcase classname="tests.integration.api_volume_test.TestVolumes" name="test_inspect_nonexistent_volume" time="6.252" /><testcase classname="tests.integration.api_volume_test.TestVolumes" name="test_inspect_volume" time="6.280"><failure message="AssertionError: assert {'CreatedAt':...l/_data', ...} == {'CreatedAt':...l/_data', ...}&#10;  Omitting 6 identical items, use -vv to show&#10;  Differing items:&#10;  {'Options': None} != {'Options': {}}&#10;  Full diff:&#10;    {&#10;     'CreatedAt': '2021-12-09T15:36:37+01:00',&#10;     'Driver': 'local',...&#10;  &#10;  ...Full output truncated (10 lines hidden), use '-vv' to show">/home/ubuntu/docker-py/tests/integration/api_volume_test.py:38: in test_inspect_volume
    ???
E   AssertionError: assert {'CreatedAt':...l/_data', ...} == {'CreatedAt':...l/_data', ...}
E     Omitting 6 identical items, use -vv to show
E     Differing items:
E     {'Options': None} != {'Options': {}}
E     Full diff:
E       {
E        'CreatedAt': '2021-12-09T15:36:37+01:00',
E        'Driver': 'local',...
E     
E     ...Full output truncated (10 lines hidden), use '-vv' to show</failure><system-out>--------------------------------- Captured Log ---------------------------------

--------------------------------- Captured Out ---------------------------------

</system-out><system-err>--------------------------------- Captured Err ---------------------------------

</system-err></testcase><testcase classname="tests.integration.api_volume_test.TestVolumes" name="test_list_volumes" time="6.304"><failure message="AssertionError: assert {'CreatedAt': '2021-12-09T15:36:43+01:00', 'Driver': 'local', 'Labels': {}, 'Mountpoint': '/home/riyad/podman/storage/volumes/imperishablenight/_data', ...} in [{'CreatedAt': '2021-12-09T15:21:09+01:00', 'Driver': 'local', 'Labels': {}, 'Mountpoint': '/home/riyad/podman/storage...00', 'Driver': 'local', 'Labels': {}, 'Mountpoint': '/home/riyad/podman/storage/volumes/imperishablenight/_data', ...}]">/home/ubuntu/docker-py/tests/integration/api_volume_test.py:31: in test_list_volumes
    ???
E   AssertionError: assert {'CreatedAt': '2021-12-09T15:36:43+01:00', 'Driver': 'local', 'Labels': {}, 'Mountpoint': '/home/riyad/podman/storage/volumes/imperishablenight/_data', ...} in [{'CreatedAt': '2021-12-09T15:21:09+01:00', 'Driver': 'local', 'Labels': {}, 'Mountpoint': '/home/riyad/podman/storage...00', 'Driver': 'local', 'Labels': {}, 'Mountpoint': '/home/riyad/podman/storage/volumes/imperishablenight/_data', ...}]</failure><system-out>--------------------------------- Captured Log ---------------------------------

--------------------------------- Captured Out ---------------------------------

</system-out><system-err>--------------------------------- Captured Err ---------------------------------

</system-err></testcase><testcase classname="tests.integration.api_volume_test.TestVolumes" name="test_prune_volumes" time="6.302" /><testcase classname="tests.integration.api_volume_test.TestVolumes" name="test_remove_nonexistent_volume" time="6.891" /><testcase classname="tests.integration.api_volume_test.TestVolumes" name="test_remove_volume" time="6.556" /><testcase classname="tests.integration.client_test.ClientTest" name="test_df" time="0.045" /><testcase classname="tests.integration.client_test.ClientTest" name="test_info" time="1.532" /><testcase classname="tests.integration.client_test.ClientTest" name="test_ping" time="0.003" /><testcase classname="tests.integration.client_test.ClientTest" name="test_version" time="2.228" /><testcase classname="tests.integration.client_test.CancellableEventsTest" name="test_cancel_events" time="2.006" /><testcase classname="tests.integration.context_api_test.ContextLifecycleTest" name="test_context_remove" time="6.498" /><testcase classname="tests.integration.context_api_test.ContextLifecycleTest" name="test_lifecycle" time="6.261" /><testcase classname="tests.integration.context_api_test.ContextLifecycleTest" name="test_load_context_without_orchestrator" time="6.622" /><testcase classname="tests.integration.errors_test.ErrorsTest" name="test_api_error_parses_json" time="7.934"><failure message="AssertionError: assert 'You cannot remove a running container' in 'cannot remove container 917a6f408202d1e50529287da1c29f257534198723d4452e8daac7fa8ffd9461 as it is running - running or paused containers cannot be removed without force: container state improper'">/home/ubuntu/docker-py/tests/integration/errors_test.py:13: in test_api_error_parses_json
    ???
E   AssertionError: assert 'You cannot remove a running container' in 'cannot remove container 917a6f408202d1e50529287da1c29f257534198723d4452e8daac7fa8ffd9461 as it is running - running or paused containers cannot be removed without force: container state improper'</failure><system-out>--------------------------------- Captured Log ---------------------------------

--------------------------------- Captured Out ---------------------------------

</system-out><system-err>--------------------------------- Captured Err ---------------------------------

</system-err></testcase><testcase classname="tests.integration.models_containers_test.ContainerCollectionTest" name="test_get" time="7.547"><failure message="AssertionError: assert 'docker.io/li...alpine:latest' == 'alpine'&#10;  - alpine&#10;  + docker.io/library/alpine:latest">/home/ubuntu/docker-py/tests/integration/models_containers_test.py:189: in test_get
    ???
E   AssertionError: assert 'docker.io/li...alpine:latest' == 'alpine'
E     - alpine
E     + docker.io/library/alpine:latest</failure><system-out>--------------------------------- Captured Log ---------------------------------

--------------------------------- Captured Out ---------------------------------

</system-out><system-err>--------------------------------- Captured Err ---------------------------------

</system-err></testcase><testcase classname="tests.integration.models_containers_test.ContainerCollectionTest" name="test_list" time="8.110"><failure message="AssertionError: assert 'docker.io/li...alpine:latest' == 'alpine'&#10;  - alpine&#10;  + docker.io/library/alpine:latest">/home/ubuntu/docker-py/tests/integration/models_containers_test.py:202: in test_list
    ???
E   AssertionError: assert 'docker.io/li...alpine:latest' == 'alpine'
E     - alpine
E     + docker.io/library/alpine:latest</failure><system-out>--------------------------------- Captured Log ---------------------------------

--------------------------------- Captured Out ---------------------------------

</system-out><system-err>--------------------------------- Captured Err ---------------------------------

</system-err></testcase><testcase classname="tests.integration.models_containers_test.ContainerCollectionTest" name="test_list_sparse" time="7.526"><failure message="AssertionError: assert 'docker.io/li...alpine:latest' == 'alpine'&#10;  - alpine&#10;  + docker.io/library/alpine:latest">/home/ubuntu/docker-py/tests/integration/models_containers_test.py:220: in test_list_sparse
    ???
E   AssertionError: assert 'docker.io/li...alpine:latest' == 'alpine'
E     - alpine
E     + docker.io/library/alpine:latest</failure><system-out>--------------------------------- Captured Log ---------------------------------

--------------------------------- Captured Out ---------------------------------

</system-out><system-err>--------------------------------- Captured Err ---------------------------------

</system-err></testcase><testcase classname="tests.integration.models_containers_test.ContainerCollectionTest" name="test_run" time="5.685" /><testcase classname="tests.integration.models_containers_test.ContainerCollectionTest" name="test_run_detach" time="5.020"><failure message="AssertionError: assert 'docker.io/li...alpine:latest' == 'alpine'&#10;  - alpine&#10;  + docker.io/library/alpine:latest">/home/ubuntu/docker-py/tests/integration/models_containers_test.py:26: in test_run_detach
    ???
E   AssertionError: assert 'docker.io/li...alpine:latest' == 'alpine'
E     - alpine
E     + docker.io/library/alpine:latest</failure><system-out>--------------------------------- Captured Log ---------------------------------

--------------------------------- Captured Out ---------------------------------

</system-out><system-err>--------------------------------- Captured Err ---------------------------------

</system-err></testcase><testcase classname="tests.integration.models_containers_test.ContainerCollectionTest" name="test_run_with_auto_remove" time="7.260" /><testcase classname="tests.integration.models_containers_test.ContainerCollectionTest" name="test_run_with_auto_remove_error" time="7.200"><failure message="docker.errors.NotFound: 404 Client Error for http+docker://localhost/v1.40/containers/bc27ca17bbcc4532e1c9ec08d3ca42f677a154ceedaea2467da3a2dc88999a10/json: Not Found (&quot;no container with name or ID &quot;bc27ca17bbcc4532e1c9ec08d3ca42f677a154ceedaea2467da3a2dc88999a10&quot; found: no such container&quot;)">docker/api/client.py:296: in _raise_for_status
    response.raise_for_status()
../../.virtualenvs/docker-py/lib/python3.9/site-packages/requests/models.py:953: in raise_for_status
    raise HTTPError(http_error_msg, response=self)
E   requests.exceptions.HTTPError: 404 Client Error: Not Found for url: http+docker://localhost/v1.40/containers/bc27ca17bbcc4532e1c9ec08d3ca42f677a154ceedaea2467da3a2dc88999a10/json

During handling of the above exception, another exception occurred:
/home/ubuntu/docker-py/tests/integration/models_containers_test.py:139: in test_run_with_auto_remove_error
    ???
docker/models/containers.py:835: in run
    out = container.logs(
docker/models/containers.py:306: in logs
    return self.client.api.logs(self.id, **kwargs)
docker/utils/decorators.py:19: in wrapped
    return f(self, resource_id, *args, **kwargs)
docker/api/container.py:869: in logs
    output = self._get_result(container, stream, res)
docker/api/client.py:495: in _get_result
    return self._get_result_tty(stream, res, self._check_is_tty(container))
docker/utils/decorators.py:19: in wrapped
    return f(self, resource_id, *args, **kwargs)
docker/api/client.py:491: in _check_is_tty
    cont = self.inspect_container(container)
docker/utils/decorators.py:19: in wrapped
    return f(self, resource_id, *args, **kwargs)
docker/api/container.py:771: in inspect_container
    return self._result(
docker/api/client.py:302: in _result
    self._raise_for_status(response)
docker/api/client.py:298: in _raise_for_status
    raise create_api_error_from_http_exception(e)
docker/errors.py:31: in create_api_error_from_http_exception
    raise cls(e, response=response, explanation=explanation)
E   docker.errors.NotFound: 404 Client Error for http+docker://localhost/v1.40/containers/bc27ca17bbcc4532e1c9ec08d3ca42f677a154ceedaea2467da3a2dc88999a10/json: Not Found ("no container with name or ID "bc27ca17bbcc4532e1c9ec08d3ca42f677a154ceedaea2467da3a2dc88999a10" found: no such container")</failure><system-out>--------------------------------- Captured Log ---------------------------------

--------------------------------- Captured Out ---------------------------------

</system-out><system-err>--------------------------------- Captured Err ---------------------------------

</system-err></testcase><testcase classname="tests.integration.models_containers_test.ContainerCollectionTest" name="test_run_with_error" time="5.025" /><testcase classname="tests.integration.models_containers_test.ContainerCollectionTest" name="test_run_with_image_that_does_not_exist" time="5.882" /><testcase classname="tests.integration.models_containers_test.ContainerCollectionTest" name="test_run_with_json_file_driver" time="4.877" /><testcase classname="tests.integration.models_containers_test.ContainerCollectionTest" name="test_run_with_named_volume" time="5.372" /><testcase classname="tests.integration.models_containers_test.ContainerCollectionTest" name="test_run_with_network" time="6.018" /><testcase classname="tests.integration.models_containers_test.ContainerCollectionTest" name="test_run_with_none_driver" time="5.527" /><testcase classname="tests.integration.models_containers_test.ContainerCollectionTest" name="test_run_with_proxy_config" time="6.068" /><testcase classname="tests.integration.models_containers_test.ContainerCollectionTest" name="test_run_with_streamed_logs" time="7.090" /><testcase classname="tests.integration.models_containers_test.ContainerCollectionTest" name="test_run_with_streamed_logs_and_cancel" time="5.000"><failure message="Failed: Timeout &gt;5.0s">tests/integration/base.py:30: in tearDown
    client = docker.from_env(version=TEST_API_VERSION)
docker/client.py:96: in from_env
    return cls(
docker/client.py:45: in __init__
    self.api = APIClient(*args, **kwargs)
docker/api/client.py:197: in __init__
    self._version = self._retrieve_server_version()
docker/api/client.py:214: in _retrieve_server_version
    return self.version(api_version=False)["ApiVersion"]
docker/api/daemon.py:181: in version
    return self._result(self._get(url), json=True)
docker/utils/decorators.py:46: in inner
    return f(self, *args, **kwargs)
docker/api/client.py:251: in _get
    return self.get(url, **self._set_request_timeout(kwargs))
../../.virtualenvs/docker-py/lib/python3.9/site-packages/requests/sessions.py:555: in get
    return self.request('GET', url, **kwargs)
../../.virtualenvs/docker-py/lib/python3.9/site-packages/requests/sessions.py:542: in request
    resp = self.send(prep, **send_kwargs)
../../.virtualenvs/docker-py/lib/python3.9/site-packages/requests/sessions.py:655: in send
    r = adapter.send(request, **kwargs)
../../.virtualenvs/docker-py/lib/python3.9/site-packages/requests/adapters.py:439: in send
    resp = conn.urlopen(
../../.virtualenvs/docker-py/lib/python3.9/site-packages/urllib3/connectionpool.py:699: in urlopen
    httplib_response = self._make_request(
../../.virtualenvs/docker-py/lib/python3.9/site-packages/urllib3/connectionpool.py:445: in _make_request
    six.raise_from(e, None)
../../.virtualenvs/docker-py/lib/python3.9/site-packages/urllib3/connectionpool.py:440: in _make_request
    httplib_response = conn.getresponse()
/usr/lib/python3.9/http/client.py:1371: in getresponse
    response.begin()
/usr/lib/python3.9/http/client.py:319: in begin
    version, status, reason = self._read_status()
/usr/lib/python3.9/http/client.py:280: in _read_status
    line = str(self.fp.readline(_MAXLINE + 1), "iso-8859-1")
/usr/lib/python3.9/socket.py:704: in readinto
    return self._sock.recv_into(b)
E   Failed: Timeout &gt;5.0s</failure><system-out>--------------------------------- Captured Log ---------------------------------

--------------------------------- Captured Out ---------------------------------

</system-out><system-err>--------------------------------- Captured Err ---------------------------------

</system-err></testcase><testcase classname="tests.integration.models_containers_test.ContainerCollectionTest" name="test_run_with_volume" time="5.486" /><testcase classname="tests.integration.models_containers_test.ContainerTest" name="test_commit" time="7.101" /><testcase classname="tests.integration.models_containers_test.ContainerTest" name="test_create_with_volume_driver" time="5.148"><failure message="AssertionError: assert '' == 'foo'&#10;  - foo">/home/ubuntu/docker-py/tests/integration/models_containers_test.py:456: in test_create_with_volume_driver
    ???
E   AssertionError: assert '' == 'foo'
E     - foo</failure><system-out>--------------------------------- Captured Log ---------------------------------

--------------------------------- Captured Out ---------------------------------

</system-out><system-err>--------------------------------- Captured Err ---------------------------------

</system-err></testcase><testcase classname="tests.integration.models_containers_test.ContainerTest" name="test_diff" time="5.083"><failure message="AssertionError: assert [{'Kind': 1, ...ath': '/etc'}] == [{'Kind': 1, 'Path': '/test'}]&#10;  Left contains one more item: {'Kind': 0, 'Path': '/etc'}&#10;  Full diff:&#10;  - [{'Kind': 1, 'Path': '/test'}]&#10;  + [{'Kind': 1, 'Path': '/test'}, {'Kind': 0, 'Path': '/etc'}]">/home/ubuntu/docker-py/tests/integration/models_containers_test.py:251: in test_diff
    ???
E   AssertionError: assert [{'Kind': 1, ...ath': '/etc'}] == [{'Kind': 1, 'Path': '/test'}]
E     Left contains one more item: {'Kind': 0, 'Path': '/etc'}
E     Full diff:
E     - [{'Kind': 1, 'Path': '/test'}]
E     + [{'Kind': 1, 'Path': '/test'}, {'Kind': 0, 'Path': '/etc'}]</failure><system-out>--------------------------------- Captured Log ---------------------------------

--------------------------------- Captured Out ---------------------------------

</system-out><system-err>--------------------------------- Captured Err ---------------------------------

</system-err></testcase><testcase classname="tests.integration.models_containers_test.ContainerTest" name="test_exec_run_failed" time="4.930"><failure message="AssertionError: assert 127 == 126&#10;  +127&#10;  -126">/home/ubuntu/docker-py/tests/integration/models_containers_test.py:270: in test_exec_run_failed
    ???
E   AssertionError: assert 127 == 126
E     +127
E     -126</failure><system-out>--------------------------------- Captured Log ---------------------------------

--------------------------------- Captured Out ---------------------------------

</system-out><system-err>--------------------------------- Captured Err ---------------------------------

</system-err></testcase><testcase classname="tests.integration.models_containers_test.ContainerTest" name="test_exec_run_success" time="4.928" /><testcase classname="tests.integration.models_containers_test.ContainerTest" name="test_kill" time="4.844"><failure message="AssertionError: assert 'stopped' == 'exited'&#10;  - exited&#10;  + stopped">/home/ubuntu/docker-py/tests/integration/models_containers_test.py:281: in test_kill
    ???
E   AssertionError: assert 'stopped' == 'exited'
E     - exited
E     + stopped</failure><system-out>--------------------------------- Captured Log ---------------------------------

--------------------------------- Captured Out ---------------------------------

</system-out><system-err>--------------------------------- Captured Err ---------------------------------

</system-err></testcase><testcase classname="tests.integration.models_containers_test.ContainerTest" name="test_logs" time="4.641" /><testcase classname="tests.integration.models_containers_test.ContainerTest" name="test_pause" time="4.822" /><testcase classname="tests.integration.models_containers_test.ContainerTest" name="test_ports_target_list" time="4.997" /><testcase classname="tests.integration.models_containers_test.ContainerTest" name="test_ports_target_none" time="4.971" /><testcase classname="tests.integration.models_containers_test.ContainerTest" name="test_ports_target_tuple" time="5.090" /><testcase classname="tests.integration.models_containers_test.ContainerTest" name="test_remove" time="4.765" /><testcase classname="tests.integration.models_containers_test.ContainerTest" name="test_rename" time="4.644" /><testcase classname="tests.integration.models_containers_test.ContainerTest" name="test_restart" time="15.466" /><testcase classname="tests.integration.models_containers_test.ContainerTest" name="test_start" time="7.358" /><testcase classname="tests.integration.models_containers_test.ContainerTest" name="test_stats" time="7.657" /><testcase classname="tests.integration.models_containers_test.ContainerTest" name="test_stop" time="6.826" /><testcase classname="tests.integration.models_containers_test.ContainerTest" name="test_top" time="5.756"><failure message="AssertionError: assert 'sleep 60' in ['1 root      0:00 sleep 60']">/home/ubuntu/docker-py/tests/integration/models_containers_test.py:425: in test_top
    ???
E   AssertionError: assert 'sleep 60' in ['1 root      0:00 sleep 60']</failure><system-out>--------------------------------- Captured Log ---------------------------------

--------------------------------- Captured Out ---------------------------------

</system-out><system-err>--------------------------------- Captured Err ---------------------------------

</system-err></testcase><testcase classname="tests.integration.models_containers_test.ContainerTest" name="test_update" time="5.524"><failure message="docker.errors.NotFound: 404 Client Error for http+docker://localhost/v1.40/containers/c5df0c565e7e64b7ee2a957e1dc75270854cdbacc890f80da0a98fd1b6b6f744/update: Not Found (&quot;b'Not Found'&quot;)">docker/api/client.py:296: in _raise_for_status
    response.raise_for_status()
../../.virtualenvs/docker-py/lib/python3.9/site-packages/requests/models.py:953: in raise_for_status
    raise HTTPError(http_error_msg, response=self)
E   requests.exceptions.HTTPError: 404 Client Error: Not Found for url: http+docker://localhost/v1.40/containers/c5df0c565e7e64b7ee2a957e1dc75270854cdbacc890f80da0a98fd1b6b6f744/update

During handling of the above exception, another exception occurred:
/home/ubuntu/docker-py/tests/integration/models_containers_test.py:433: in test_update
    ???
docker/models/containers.py:489: in update
    return self.client.api.update_container(self.id, **kwargs)
docker/utils/decorators.py:34: in wrapper
    return f(self, *args, **kwargs)
docker/utils/decorators.py:19: in wrapped
    return f(self, resource_id, *args, **kwargs)
docker/api/container.py:1268: in update_container
    return self._result(res, True)
docker/api/client.py:302: in _result
    self._raise_for_status(response)
docker/api/client.py:298: in _raise_for_status
    raise create_api_error_from_http_exception(e)
docker/errors.py:31: in create_api_error_from_http_exception
    raise cls(e, response=response, explanation=explanation)
E   docker.errors.NotFound: 404 Client Error for http+docker://localhost/v1.40/containers/c5df0c565e7e64b7ee2a957e1dc75270854cdbacc890f80da0a98fd1b6b6f744/update: Not Found ("b'Not Found'")</failure><system-out>--------------------------------- Captured Log ---------------------------------

--------------------------------- Captured Out ---------------------------------

</system-out><system-err>--------------------------------- Captured Err ---------------------------------

</system-err></testcase><testcase classname="tests.integration.models_containers_test.ContainerTest" name="test_wait" time="6.177" /><testcase classname="tests.integration.models_images_test.ImageCollectionTest" name="test_build" time="7.777" /><testcase classname="tests.integration.models_images_test.ImageCollectionTest" name="test_build_with_error" time="7.744"><failure message="AssertionError: assert &quot;The command '/bin/sh -c exit 1' returned a non-zero code: 1&quot; in 'docker.errors.BuildError: error building at STEP &quot;RUN exit 1&quot;: error while running runtime: exit status 1'&#10; +  where 'docker.errors.BuildError: error building at STEP &quot;RUN exit 1&quot;: error while running runtime: exit status 1' = &lt;bound method ExceptionInfo.exconly of &lt;ExceptionInfo BuildError('error building at STEP &quot;RUN exit 1&quot;: error while running runtime: exit status 1\n') tblen=2&gt;&gt;()&#10; +    where &lt;bound method ExceptionInfo.exconly of &lt;ExceptionInfo BuildError('error building at STEP &quot;RUN exit 1&quot;: error while running runtime: exit status 1\n') tblen=2&gt;&gt; = &lt;ExceptionInfo BuildError('error building at STEP &quot;RUN exit 1&quot;: error while running runtime: exit status 1\n') tblen=2&gt;.exconly">/home/ubuntu/docker-py/tests/integration/models_images_test.py:30: in test_build_with_error
    ???
E   AssertionError: assert "The command '/bin/sh -c exit 1' returned a non-zero code: 1" in 'docker.errors.BuildError: error building at STEP "RUN exit 1": error while running runtime: exit status 1'
E    +  where 'docker.errors.BuildError: error building at STEP "RUN exit 1": error while running runtime: exit status 1' = &lt;bound method ExceptionInfo.exconly of &lt;ExceptionInfo BuildError('error building at STEP "RUN exit 1": error while running runtime: exit status 1\n') tblen=2&gt;&gt;()
E    +    where &lt;bound method ExceptionInfo.exconly of &lt;ExceptionInfo BuildError('error building at STEP "RUN exit 1": error while running runtime: exit status 1\n') tblen=2&gt;&gt; = &lt;ExceptionInfo BuildError('error building at STEP "RUN exit 1": error while running runtime: exit status 1\n') tblen=2&gt;.exconly</failure><system-out>--------------------------------- Captured Log ---------------------------------

--------------------------------- Captured Out ---------------------------------

</system-out><system-err>--------------------------------- Captured Err ---------------------------------

</system-err></testcase><testcase classname="tests.integration.models_images_test.ImageCollectionTest" name="test_build_with_multiple_success" time="7.892" /><testcase classname="tests.integration.models_images_test.ImageCollectionTest" name="test_build_with_success_build_output" time="6.179" /><testcase classname="tests.integration.models_images_test.ImageCollectionTest" name="test_list" time="8.028" /><testcase classname="tests.integration.models_images_test.ImageCollectionTest" name="test_list_with_repository" time="7.080" /><testcase classname="tests.integration.models_images_test.ImageCollectionTest" name="test_load_error" time="4.457"><failure message="docker.errors.APIError: 500 Server Error for http+docker://localhost/v1.40/images/load: Internal Server Error (&quot;failed to load image: payload does not match any of the supported image formats (oci, oci-archive, dir, docker-archive)&quot;)">docker/api/client.py:296: in _raise_for_status
    response.raise_for_status()
../../.virtualenvs/docker-py/lib/python3.9/site-packages/requests/models.py:953: in raise_for_status
    raise HTTPError(http_error_msg, response=self)
E   requests.exceptions.HTTPError: 500 Server Error: Internal Server Error for url: http+docker://localhost/v1.40/images/load

During handling of the above exception, another exception occurred:
/home/ubuntu/docker-py/tests/integration/models_images_test.py:98: in test_load_error
    ???
docker/models/images.py:382: in load
    for chunk in resp:
docker/api/client.py:386: in _stream_helper
    yield self._result(response, json=decode)
docker/api/client.py:302: in _result
    self._raise_for_status(response)
docker/api/client.py:298: in _raise_for_status
    raise create_api_error_from_http_exception(e)
docker/errors.py:31: in create_api_error_from_http_exception
    raise cls(e, response=response, explanation=explanation)
E   docker.errors.APIError: 500 Server Error for http+docker://localhost/v1.40/images/load: Internal Server Error ("failed to load image: payload does not match any of the supported image formats (oci, oci-archive, dir, docker-archive)")</failure><system-out>--------------------------------- Captured Log ---------------------------------

--------------------------------- Captured Out ---------------------------------

</system-out><system-err>--------------------------------- Captured Err ---------------------------------

</system-err></testcase><testcase classname="tests.integration.models_images_test.ImageCollectionTest" name="test_pull" time="6.900"><failure message="AssertionError: assert 'alpine:latest' in ['docker.io/library/alpine:latest']">/home/ubuntu/docker-py/tests/integration/models_images_test.py:71: in test_pull
    ???
E   AssertionError: assert 'alpine:latest' in ['docker.io/library/alpine:latest']</failure><system-out>--------------------------------- Captured Log ---------------------------------

--------------------------------- Captured Out ---------------------------------

</system-out><system-err>--------------------------------- Captured Err ---------------------------------

</system-err></testcase><testcase classname="tests.integration.models_images_test.ImageCollectionTest" name="test_pull_multiple" time="8.088"><failure message="AssertionError: assert False&#10; +  where False = any([False])">/home/ubuntu/docker-py/tests/integration/models_images_test.py:91: in test_pull_multiple
    ???
E   AssertionError: assert False
E    +  where False = any([False])</failure><system-out>--------------------------------- Captured Log ---------------------------------

--------------------------------- Captured Out ---------------------------------

</system-out><system-err>--------------------------------- Captured Err ---------------------------------

</system-err></testcase><testcase classname="tests.integration.models_images_test.ImageCollectionTest" name="test_pull_with_sha" time="7.576"><failure message="AssertionError: assert 'hello-world@sha256:083de497cff944f969d8499ab94f07134c50bcf5e6b9559b27182d3fa80ce3f7' in ['docker.io/library/hello-world@sha256:083de497cff944f969d8499ab94f07134c50bcf5e6b9559b27182d3fa80ce3f7', 'docker.io/library/hello-world@sha256:8072a54ebb3bc136150e2f2860f00a7bf45f13eeb917cca2430fcd0054c8e51b']">/home/ubuntu/docker-py/tests/integration/models_images_test.py:85: in test_pull_with_sha
    ???
E   AssertionError: assert 'hello-world@sha256:083de497cff944f969d8499ab94f07134c50bcf5e6b9559b27182d3fa80ce3f7' in ['docker.io/library/hello-world@sha256:083de497cff944f969d8499ab94f07134c50bcf5e6b9559b27182d3fa80ce3f7', 'docker.io/library/hello-world@sha256:8072a54ebb3bc136150e2f2860f00a7bf45f13eeb917cca2430fcd0054c8e51b']</failure><system-out>--------------------------------- Captured Log ---------------------------------

--------------------------------- Captured Out ---------------------------------

</system-out><system-err>--------------------------------- Captured Err ---------------------------------

</system-err></testcase><testcase classname="tests.integration.models_images_test.ImageCollectionTest" name="test_pull_with_tag" time="7.395"><failure message="AssertionError: assert 'alpine:3.10' in ['docker.io/library/alpine:3.10']">/home/ubuntu/docker-py/tests/integration/models_images_test.py:76: in test_pull_with_tag
    ???
E   AssertionError: assert 'alpine:3.10' in ['docker.io/library/alpine:3.10']</failure><system-out>--------------------------------- Captured Log ---------------------------------

--------------------------------- Captured Out ---------------------------------

</system-out><system-err>--------------------------------- Captured Err ---------------------------------

</system-err></testcase><testcase classname="tests.integration.models_images_test.ImageCollectionTest" name="test_save_and_load" time="5.246" /><testcase classname="tests.integration.models_images_test.ImageCollectionTest" name="test_save_and_load_repo_name" time="4.432"><failure message="docker.errors.InvalidArgument: dockerpytest_4fdeef30b78408d3:latest is not a valid tag for this image">/home/ubuntu/docker-py/tests/integration/models_images_test.py:122: in test_save_and_load_repo_name
    ???
docker/models/images.py:96: in save
    raise InvalidArgument(
E   docker.errors.InvalidArgument: dockerpytest_4fdeef30b78408d3:latest is not a valid tag for this image</failure><system-out>--------------------------------- Captured Log ---------------------------------

--------------------------------- Captured Out ---------------------------------

</system-out><system-err>--------------------------------- Captured Err ---------------------------------

</system-err></testcase><testcase classname="tests.integration.models_images_test.ImageCollectionTest" name="test_save_name_error" time="4.311" /><testcase classname="tests.integration.models_images_test.ImageTest" name="test_tag_and_remove" time="6.725" /><testcase classname="tests.integration.models_networks_test.NetworkCollectionTest" name="test_create" time="4.418" /><testcase classname="tests.integration.models_networks_test.NetworkCollectionTest" name="test_get" time="4.343" /><testcase classname="tests.integration.models_networks_test.NetworkCollectionTest" name="test_list_remove" time="4.385" /><testcase classname="tests.integration.models_networks_test.NetworkTest" name="test_connect_disconnect" time="5.140" /><testcase classname="tests.integration.models_resources_test.ModelTest" name="test_reload" time="5.317" /><testcase classname="tests.integration.models_volumes_test.VolumesTest" name="test_create_get" time="4.882" /><testcase classname="tests.integration.models_volumes_test.VolumesTest" name="test_list_remove" time="4.637"><failure message="AssertionError: assert &lt;Volume: dockerpyte&gt; in []&#10; +  where [] = &lt;bound method VolumeCollection.list of &lt;docker.models.volumes.VolumeCollection object at 0x7f11f623b910&gt;&gt;(filters={'name': 'dockerpytest_'})&#10; +    where &lt;bound method VolumeCollection.list of &lt;docker.models.volumes.VolumeCollection object at 0x7f11f623b910&gt;&gt; = &lt;docker.models.volumes.VolumeCollection object at 0x7f11f623b910&gt;.list&#10; +      where &lt;docker.models.volumes.VolumeCollection object at 0x7f11f623b910&gt; = &lt;docker.client.DockerClient object at 0x7f11f6480700&gt;.volumes">/home/ubuntu/docker-py/tests/integration/models_volumes_test.py:26: in test_list_remove
    ???
E   AssertionError: assert &lt;Volume: dockerpyte&gt; in []
E    +  where [] = &lt;bound method VolumeCollection.list of &lt;docker.models.volumes.VolumeCollection object at 0x7f11f623b910&gt;&gt;(filters={'name': 'dockerpytest_'})
E    +    where &lt;bound method VolumeCollection.list of &lt;docker.models.volumes.VolumeCollection object at 0x7f11f623b910&gt;&gt; = &lt;docker.models.volumes.VolumeCollection object at 0x7f11f623b910&gt;.list
E    +      where &lt;docker.models.volumes.VolumeCollection object at 0x7f11f623b910&gt; = &lt;docker.client.DockerClient object at 0x7f11f6480700&gt;.volumes</failure><system-out>--------------------------------- Captured Log ---------------------------------

--------------------------------- Captured Out ---------------------------------

</system-out><system-err>--------------------------------- Captured Err ---------------------------------

</system-err></testcase><testcase classname="tests.integration.regression_test.TestRegressions" name="test_443_handle_nonchunked_response_in_stream" time="6.596"><failure message="Failed: DID NOT RAISE &lt;class 'docker.errors.APIError'&gt;">/home/ubuntu/docker-py/tests/integration/regression_test.py:15: in test_443_handle_nonchunked_response_in_stream
    ???
E   Failed: DID NOT RAISE &lt;class 'docker.errors.APIError'&gt;</failure><system-out>--------------------------------- Captured Log ---------------------------------

--------------------------------- Captured Out ---------------------------------

</system-out><system-err>--------------------------------- Captured Err ---------------------------------

</system-err></testcase><testcase classname="tests.integration.regression_test.TestRegressions" name="test_542_truncate_ids_client_side" time="6.997" /><testcase classname="tests.integration.regression_test.TestRegressions" name="test_647_support_doubleslash_in_image_names" time="6.680" /><testcase classname="tests.integration.regression_test.TestRegressions" name="test_649_handle_timeout_value_none" time="7.956" /><testcase classname="tests.integration.regression_test.TestRegressions" name="test_715_handle_user_param_as_int_value" time="7.593" /><testcase classname="tests.integration.regression_test.TestRegressions" name="test_792_explicit_port_protocol" time="9.148" /><testcase classname="tests.integration.credentials.utils_test" name="test_create_environment_dict" time="0.021" /></testsuite></testsuites>