<?xml version="1.0" encoding="utf-8"?><testsuites><testsuite name="docker-py" errors="0" failures="74" skipped="7" tests="269" time="2737.944" timestamp="2023-05-28T20:17:09.945407" hostname="acnologia"><testcase classname="tests.integration.api_build_test.BuildTest" name="test_build_container_with_target" time="20.478" /><testcase classname="tests.integration.api_build_test.BuildTest" name="test_build_from_stringio" time="11.103" /><testcase classname="tests.integration.api_build_test.BuildTest" name="test_build_gzip_custom_encoding" time="11.155" /><testcase classname="tests.integration.api_build_test.BuildTest" name="test_build_gzip_encoding" time="12.266" /><testcase classname="tests.integration.api_build_test.BuildTest" name="test_build_in_context_abs_dockerfile" time="12.833" /><testcase classname="tests.integration.api_build_test.BuildTest" name="test_build_in_context_dockerfile" time="12.573" /><testcase classname="tests.integration.api_build_test.BuildTest" name="test_build_in_context_nested_dockerfile" time="12.528" /><testcase classname="tests.integration.api_build_test.BuildTest" name="test_build_invalid_platform" time="13.728"><failure message="AssertionError: assert ('unknown operating system' in 'docker.errors.APIError: 400 Client Error for http+docker://localhost/v1.41/build?q=False&amp;nocache=False&amp;rm=False&amp;forcerm=False&amp;pull=False&amp;platform=foobar: Bad Request' or 'invalid platform' in 'docker.errors.APIError: 400 Client Error for http+docker://localhost/v1.41/build?q=False&amp;nocache=False&amp;rm=False&amp;forcerm=False&amp;pull=False&amp;platform=foobar: Bad Request')&#10; +  where 'docker.errors.APIError: 400 Client Error for http+docker://localhost/v1.41/build?q=False&amp;nocache=False&amp;rm=False&amp;forcerm=False&amp;pull=False&amp;platform=foobar: Bad Request' = &lt;bound method ExceptionInfo.exconly of &lt;ExceptionInfo APIError(HTTPError('400 Client Error: Bad Request for url: http+docker://localhost/v1.41/build?q=False&amp;nocache=False&amp;rm=False&amp;forcerm=False&amp;pull=False&amp;platform=foobar')) tblen=5&gt;&gt;()&#10; +    where &lt;bound method ExceptionInfo.exconly of &lt;ExceptionInfo APIError(HTTPError('400 Client Error: Bad Request for url: http+docker://localhost/v1.41/build?q=False&amp;nocache=False&amp;rm=False&amp;forcerm=False&amp;pull=False&amp;platform=foobar')) tblen=5&gt;&gt; = &lt;ExceptionInfo APIError(HTTPError('400 Client Error: Bad Request for url: http+docker://localhost/v1.41/build?q=False&amp;nocache=False&amp;rm=False&amp;forcerm=False&amp;pull=False&amp;platform=foobar')) tblen=5&gt;.exconly&#10; +  and   'docker.errors.APIError: 400 Client Error for http+docker://localhost/v1.41/build?q=False&amp;nocache=False&amp;rm=False&amp;forcerm=False&amp;pull=False&amp;platform=foobar: Bad Request' = &lt;bound method ExceptionInfo.exconly of &lt;ExceptionInfo APIError(HTTPError('400 Client Error: Bad Request for url: http+docker://localhost/v1.41/build?q=False&amp;nocache=False&amp;rm=False&amp;forcerm=False&amp;pull=False&amp;platform=foobar')) tblen=5&gt;&gt;()&#10; +    where &lt;bound method ExceptionInfo.exconly of &lt;ExceptionInfo APIError(HTTPError('400 Client Error: Bad Request for url: http+docker://localhost/v1.41/build?q=False&amp;nocache=False&amp;rm=False&amp;forcerm=False&amp;pull=False&amp;platform=foobar')) tblen=5&gt;&gt; = &lt;ExceptionInfo APIError(HTTPError('400 Client Error: Bad Request for url: http+docker://localhost/v1.41/build?q=False&amp;nocache=False&amp;rm=False&amp;forcerm=False&amp;pull=False&amp;platform=foobar')) tblen=5&gt;.exconly">tests/integration/api_build_test.py:464: in test_build_invalid_platform
    assert 'unknown operating system' in excinfo.exconly() \
E   AssertionError: assert ('unknown operating system' in 'docker.errors.APIError: 400 Client Error for http+docker://localhost/v1.41/build?q=False&amp;nocache=False&amp;rm=False&amp;forcerm=False&amp;pull=False&amp;platform=foobar: Bad Request' or 'invalid platform' in 'docker.errors.APIError: 400 Client Error for http+docker://localhost/v1.41/build?q=False&amp;nocache=False&amp;rm=False&amp;forcerm=False&amp;pull=False&amp;platform=foobar: Bad Request')
E    +  where 'docker.errors.APIError: 400 Client Error for http+docker://localhost/v1.41/build?q=False&amp;nocache=False&amp;rm=False&amp;forcerm=False&amp;pull=False&amp;platform=foobar: Bad Request' = &lt;bound method ExceptionInfo.exconly of &lt;ExceptionInfo APIError(HTTPError('400 Client Error: Bad Request for url: http+docker://localhost/v1.41/build?q=False&amp;nocache=False&amp;rm=False&amp;forcerm=False&amp;pull=False&amp;platform=foobar')) tblen=5&gt;&gt;()
E    +    where &lt;bound method ExceptionInfo.exconly of &lt;ExceptionInfo APIError(HTTPError('400 Client Error: Bad Request for url: http+docker://localhost/v1.41/build?q=False&amp;nocache=False&amp;rm=False&amp;forcerm=False&amp;pull=False&amp;platform=foobar')) tblen=5&gt;&gt; = &lt;ExceptionInfo APIError(HTTPError('400 Client Error: Bad Request for url: http+docker://localhost/v1.41/build?q=False&amp;nocache=False&amp;rm=False&amp;forcerm=False&amp;pull=False&amp;platform=foobar')) tblen=5&gt;.exconly
E    +  and   'docker.errors.APIError: 400 Client Error for http+docker://localhost/v1.41/build?q=False&amp;nocache=False&amp;rm=False&amp;forcerm=False&amp;pull=False&amp;platform=foobar: Bad Request' = &lt;bound method ExceptionInfo.exconly of &lt;ExceptionInfo APIError(HTTPError('400 Client Error: Bad Request for url: http+docker://localhost/v1.41/build?q=False&amp;nocache=False&amp;rm=False&amp;forcerm=False&amp;pull=False&amp;platform=foobar')) tblen=5&gt;&gt;()
E    +    where &lt;bound method ExceptionInfo.exconly of &lt;ExceptionInfo APIError(HTTPError('400 Client Error: Bad Request for url: http+docker://localhost/v1.41/build?q=False&amp;nocache=False&amp;rm=False&amp;forcerm=False&amp;pull=False&amp;platform=foobar')) tblen=5&gt;&gt; = &lt;ExceptionInfo APIError(HTTPError('400 Client Error: Bad Request for url: http+docker://localhost/v1.41/build?q=False&amp;nocache=False&amp;rm=False&amp;forcerm=False&amp;pull=False&amp;platform=foobar')) tblen=5&gt;.exconly</failure><system-out>--------------------------------- Captured Log ---------------------------------

--------------------------------- Captured Out ---------------------------------

</system-out><system-err>--------------------------------- Captured Err ---------------------------------

</system-err></testcase><testcase classname="tests.integration.api_build_test.BuildTest" name="test_build_isolation" time="11.439" /><testcase classname="tests.integration.api_build_test.BuildTest" name="test_build_labels" time="10.970" /><testcase classname="tests.integration.api_build_test.BuildTest" name="test_build_out_of_context_dockerfile" time="13.238" /><testcase classname="tests.integration.api_build_test.BuildTest" name="test_build_shmsize" time="11.435" /><testcase classname="tests.integration.api_build_test.BuildTest" name="test_build_squash" time="20.242" /><testcase classname="tests.integration.api_build_test.BuildTest" name="test_build_stderr_data" time="13.020" /><testcase classname="tests.integration.api_build_test.BuildTest" name="test_build_streaming" time="12.044" /><testcase classname="tests.integration.api_build_test.BuildTest" name="test_build_with_buildargs" time="11.250" /><testcase classname="tests.integration.api_build_test.BuildTest" name="test_build_with_cache_from" time="15.426"><failure message="assert 3 == 0">tests/integration/api_build_test.py:257: in test_build_with_cache_from
    assert counter == 0
E   assert 3 == 0</failure><system-out>--------------------------------- Captured Log ---------------------------------

--------------------------------- Captured Out ---------------------------------

</system-out><system-err>--------------------------------- Captured Err ---------------------------------

</system-err></testcase><testcase classname="tests.integration.api_build_test.BuildTest" name="test_build_with_dockerfile_empty_lines" time="11.637" /><testcase classname="tests.integration.api_build_test.BuildTest" name="test_build_with_dockerignore" time="14.388"><failure message="AssertionError: assert ['/test/#file.../not-ignored'] == ['/test/#file.../not-ignored']&#10;  At index 2 diff: '/test/not-ignored' != '/test/ignored/subdir/excepted-with-spaces'&#10;  Right contains one more item: '/test/not-ignored'&#10;  Full diff:&#10;    [&#10;     '/test/#file.txt',&#10;     '/test/ignored/subdir/excepted-file',&#10;  -  '/test/ignored/subdir/excepted-with-spaces',&#10;     '/test/not-ignored',&#10;    ]">tests/integration/api_build_test.py:145: in test_build_with_dockerignore
    assert sorted(list(filter(None, logs.split('\n')))) == sorted([
E   AssertionError: assert ['/test/#file.../not-ignored'] == ['/test/#file.../not-ignored']
E     At index 2 diff: '/test/not-ignored' != '/test/ignored/subdir/excepted-with-spaces'
E     Right contains one more item: '/test/not-ignored'
E     Full diff:
E       [
E        '/test/#file.txt',
E        '/test/ignored/subdir/excepted-file',
E     -  '/test/ignored/subdir/excepted-with-spaces',
E        '/test/not-ignored',
E       ]</failure><system-out>--------------------------------- Captured Log ---------------------------------

--------------------------------- Captured Out ---------------------------------

</system-out><system-err>--------------------------------- Captured Err ---------------------------------

</system-err></testcase><testcase classname="tests.integration.api_build_test.BuildTest" name="test_build_with_extra_hosts" time="11.322"><failure message="docker.errors.APIError: 400 Client Error for http+docker://localhost/v1.41/build?t=dockerpytest_extrahost_build&amp;q=False&amp;nocache=False&amp;rm=False&amp;forcerm=False&amp;pull=False&amp;extrahosts=extrahost.local.test%3A127.0.0.1&amp;extrahosts=hello.world.test%3A127.0.0.1: Bad Request">docker/api/client.py:296: in _raise_for_status
    response.raise_for_status()
../../.virtualenvs/docker-py/lib/python3.11/site-packages/requests/models.py:1021: in raise_for_status
    raise HTTPError(http_error_msg, response=self)
E   requests.exceptions.HTTPError: 400 Client Error: Bad Request for url: http+docker://localhost/v1.41/build?t=dockerpytest_extrahost_build&amp;q=False&amp;nocache=False&amp;rm=False&amp;forcerm=False&amp;pull=False&amp;extrahosts=extrahost.local.test%3A127.0.0.1&amp;extrahosts=hello.world.test%3A127.0.0.1

The above exception was the direct cause of the following exception:
tests/integration/api_build_test.py:342: in test_build_with_extra_hosts
    for chunk in stream:
docker/api/client.py:386: in _stream_helper
    yield self._result(response, json=decode)
docker/api/client.py:302: in _result
    self._raise_for_status(response)
docker/api/client.py:298: in _raise_for_status
    raise create_api_error_from_http_exception(e) from e
docker/errors.py:39: in create_api_error_from_http_exception
    raise cls(e, response=response, explanation=explanation) from e
E   docker.errors.APIError: 400 Client Error for http+docker://localhost/v1.41/build?t=dockerpytest_extrahost_build&amp;q=False&amp;nocache=False&amp;rm=False&amp;forcerm=False&amp;pull=False&amp;extrahosts=extrahost.local.test%3A127.0.0.1&amp;extrahosts=hello.world.test%3A127.0.0.1: Bad Request</failure><system-out>--------------------------------- Captured Log ---------------------------------

--------------------------------- Captured Out ---------------------------------

</system-out><system-err>--------------------------------- Captured Err ---------------------------------

</system-err></testcase><testcase classname="tests.integration.api_build_test.BuildTest" name="test_build_with_network_mode" time="13.282"><failure message="docker.errors.ImageNotFound: 404 Client Error for http+docker://localhost/v1.41/images/dockerpytest_customnetbuild/json: Not Found (&quot;failed to find image dockerpytest_customnetbuild: docker.io/library/dockerpytest_customnetbuild: No such image&quot;)">docker/api/client.py:296: in _raise_for_status
    response.raise_for_status()
../../.virtualenvs/docker-py/lib/python3.11/site-packages/requests/models.py:1021: in raise_for_status
    raise HTTPError(http_error_msg, response=self)
E   requests.exceptions.HTTPError: 404 Client Error: Not Found for url: http+docker://localhost/v1.41/images/dockerpytest_customnetbuild/json

The above exception was the direct cause of the following exception:
tests/integration/api_build_test.py:307: in test_build_with_network_mode
    assert self.client.inspect_image('dockerpytest_customnetbuild')
docker/utils/decorators.py:19: in wrapped
    return f(self, resource_id, *args, **kwargs)
docker/api/image.py:251: in inspect_image
    return self._result(
docker/api/client.py:302: in _result
    self._raise_for_status(response)
docker/api/client.py:298: in _raise_for_status
    raise create_api_error_from_http_exception(e) from e
docker/errors.py:39: in create_api_error_from_http_exception
    raise cls(e, response=response, explanation=explanation) from e
E   docker.errors.ImageNotFound: 404 Client Error for http+docker://localhost/v1.41/images/dockerpytest_customnetbuild/json: Not Found ("failed to find image dockerpytest_customnetbuild: docker.io/library/dockerpytest_customnetbuild: No such image")</failure><system-out>--------------------------------- Captured Log ---------------------------------

--------------------------------- Captured Out ---------------------------------

</system-out><system-err>--------------------------------- Captured Err ---------------------------------

</system-err></testcase><testcase classname="tests.integration.api_build_test.BuildTest" name="test_build_with_proxy" time="11.172" /><testcase classname="tests.integration.api_build_test.BuildTest" name="test_build_with_proxy_and_buildargs" time="11.492" /><testcase classname="tests.integration.api_build_test.BuildTest" name="test_prune_builds" time="12.137"><skipped type="pytest.xfail" message="Currently fails on 18.09: https://github.com/moby/moby/issues/37920" /></testcase><testcase classname="tests.integration.api_client_test.InformationTest" name="test_info" time="13.912" /><testcase classname="tests.integration.api_client_test.InformationTest" name="test_version" time="15.577" /><testcase classname="tests.integration.api_client_test.AutoDetectVersionTest" name="test_client_init" time="11.079" /><testcase classname="tests.integration.api_client_test.ConnectionTimeoutTest" name="test_timeout" time="0.539" /><testcase classname="tests.integration.api_client_test.UnixconnTest" name="test_resource_warnings" time="3.771" /><testcase classname="tests.integration.api_container_test.ListContainersTest" name="test_list_containers" time="11.564" /><testcase classname="tests.integration.api_container_test.CreateContainerTest" name="test_create" time="11.450" /><testcase classname="tests.integration.api_container_test.CreateContainerTest" name="test_create_container_with_volumes_from" time="12.670" /><testcase classname="tests.integration.api_container_test.CreateContainerTest" name="test_create_with_auto_remove" time="11.742" /><testcase classname="tests.integration.api_container_test.CreateContainerTest" name="test_create_with_cgroupns" time="12.112"><failure message="AssertionError: assert 'private' == ''&#10;  + private">tests/integration/api_container_test.py:230: in test_create_with_cgroupns
    assert 'private' == res['HostConfig']['CgroupnsMode']
E   AssertionError: assert 'private' == ''
E     + private</failure><system-out>--------------------------------- Captured Log ---------------------------------

--------------------------------- Captured Out ---------------------------------

</system-out><system-err>--------------------------------- Captured Err ---------------------------------

</system-err></testcase><testcase classname="tests.integration.api_container_test.CreateContainerTest" name="test_create_with_cpu_rt_options" time="12.063"><skipped type="pytest.xfail" message="CONFIG_RT_GROUP_SCHED isn't enabled" /></testcase><testcase classname="tests.integration.api_container_test.CreateContainerTest" name="test_create_with_device_cgroup_rules" time="11.383"><failure message="AssertionError: assert None == ['c 7:128 rwm']">tests/integration/api_container_test.py:483: in test_create_with_device_cgroup_rules
    assert config['HostConfig']['DeviceCgroupRules'] == [rule]
E   AssertionError: assert None == ['c 7:128 rwm']</failure><system-out>--------------------------------- Captured Log ---------------------------------

--------------------------------- Captured Out ---------------------------------

</system-out><system-err>--------------------------------- Captured Err ---------------------------------

</system-err></testcase><testcase classname="tests.integration.api_container_test.CreateContainerTest" name="test_create_with_environment_variable_no_value" time="11.209"><failure message="AssertionError: assert 'Foo' in ['Other=one', 'Blank=', 'PATH=/usr/local/sbin:/usr/local/bin:/usr/sbin:/usr/bin:/sbin:/bin', 'TERM=xterm', 'container=podman']">tests/integration/api_container_test.py:380: in test_create_with_environment_variable_no_value
    assert 'Foo' in config['Config']['Env']
E   AssertionError: assert 'Foo' in ['Other=one', 'Blank=', 'PATH=/usr/local/sbin:/usr/local/bin:/usr/sbin:/usr/bin:/sbin:/bin', 'TERM=xterm', 'container=podman']</failure><system-out>--------------------------------- Captured Log ---------------------------------

--------------------------------- Captured Out ---------------------------------

</system-out><system-err>--------------------------------- Captured Err ---------------------------------

</system-err></testcase><testcase classname="tests.integration.api_container_test.CreateContainerTest" name="test_create_with_host_pid_mode" time="11.484" /><testcase classname="tests.integration.api_container_test.CreateContainerTest" name="test_create_with_init" time="11.550" /><testcase classname="tests.integration.api_container_test.CreateContainerTest" name="test_create_with_isolation" time="11.893"><failure message="AssertionError: assert '' == 'default'&#10;  - default">tests/integration/api_container_test.py:409: in test_create_with_isolation
    assert config['HostConfig']['Isolation'] == 'default'
E   AssertionError: assert '' == 'default'
E     - default</failure><system-out>--------------------------------- Captured Log ---------------------------------

--------------------------------- Captured Out ---------------------------------

</system-out><system-err>--------------------------------- Captured Err ---------------------------------

</system-err></testcase><testcase classname="tests.integration.api_container_test.CreateContainerTest" name="test_create_with_links" time="12.475"><failure message="docker.errors.APIError: 400 Client Error for http+docker://localhost/v1.41/containers/create: Bad Request (&quot;bad parameter: link is not supported&quot;)">docker/api/client.py:296: in _raise_for_status
    response.raise_for_status()
../../.virtualenvs/docker-py/lib/python3.11/site-packages/requests/models.py:1021: in raise_for_status
    raise HTTPError(http_error_msg, response=self)
E   requests.exceptions.HTTPError: 400 Client Error: Bad Request for url: http+docker://localhost/v1.41/containers/create

The above exception was the direct cause of the following exception:
tests/integration/api_container_test.py:95: in test_create_with_links
    res2 = self.client.create_container(
docker/api/container.py:431: in create_container
    return self.create_container_from_config(config, name, platform)
docker/api/container.py:448: in create_container_from_config
    return self._result(res, True)
docker/api/client.py:302: in _result
    self._raise_for_status(response)
docker/api/client.py:298: in _raise_for_status
    raise create_api_error_from_http_exception(e) from e
docker/errors.py:39: in create_api_error_from_http_exception
    raise cls(e, response=response, explanation=explanation) from e
E   docker.errors.APIError: 400 Client Error for http+docker://localhost/v1.41/containers/create: Bad Request ("bad parameter: link is not supported")</failure><system-out>--------------------------------- Captured Log ---------------------------------

--------------------------------- Captured Out ---------------------------------

</system-out><system-err>--------------------------------- Captured Err ---------------------------------

</system-err></testcase><testcase classname="tests.integration.api_container_test.CreateContainerTest" name="test_create_with_mac_address" time="11.556"><failure message="AssertionError: assert '02:42:ac:11:00:0a' == 'ea:26:e8:66:68:9a'&#10;  - ea:26:e8:66:68:9a&#10;  + 02:42:ac:11:00:0a">tests/integration/api_container_test.py:214: in test_create_with_mac_address
    assert mac_address_expected == res['NetworkSettings']['MacAddress']
E   AssertionError: assert '02:42:ac:11:00:0a' == 'ea:26:e8:66:68:9a'
E     - ea:26:e8:66:68:9a
E     + 02:42:ac:11:00:0a</failure><system-out>--------------------------------- Captured Log ---------------------------------

--------------------------------- Captured Out ---------------------------------

</system-out><system-err>--------------------------------- Captured Err ---------------------------------

</system-err></testcase><testcase classname="tests.integration.api_container_test.CreateContainerTest" name="test_create_with_memory_constraints_with_int" time="11.744"><failure message="docker.errors.APIError: 500 Server Error for http+docker://localhost/v1.41/containers/9d3bedd1842dab3b741db26e5e4d66e26251615808cf59d8e12397070b6feae6/start: Internal Server Error (&quot;crun: cannot set memory swappiness with cgroupv2: OCI runtime error&quot;)">docker/api/client.py:296: in _raise_for_status
    response.raise_for_status()
../../.virtualenvs/docker-py/lib/python3.11/site-packages/requests/models.py:1021: in raise_for_status
    raise HTTPError(http_error_msg, response=self)
E   requests.exceptions.HTTPError: 500 Server Error: Internal Server Error for url: http+docker://localhost/v1.41/containers/9d3bedd1842dab3b741db26e5e4d66e26251615808cf59d8e12397070b6feae6/start

The above exception was the direct cause of the following exception:
tests/integration/api_container_test.py:365: in test_create_with_memory_constraints_with_int
    self.client.start(ctnr)
docker/utils/decorators.py:19: in wrapped
    return f(self, resource_id, *args, **kwargs)
docker/api/container.py:1127: in start
    self._raise_for_status(res)
docker/api/client.py:298: in _raise_for_status
    raise create_api_error_from_http_exception(e) from e
docker/errors.py:39: in create_api_error_from_http_exception
    raise cls(e, response=response, explanation=explanation) from e
E   docker.errors.APIError: 500 Server Error for http+docker://localhost/v1.41/containers/9d3bedd1842dab3b741db26e5e4d66e26251615808cf59d8e12397070b6feae6/start: Internal Server Error ("crun: cannot set memory swappiness with cgroupv2: OCI runtime error")</failure><system-out>--------------------------------- Captured Log ---------------------------------

--------------------------------- Captured Out ---------------------------------

</system-out><system-err>--------------------------------- Captured Err ---------------------------------

</system-err></testcase><testcase classname="tests.integration.api_container_test.CreateContainerTest" name="test_create_with_memory_constraints_with_str" time="11.791" /><testcase classname="tests.integration.api_container_test.CreateContainerTest" name="test_create_with_restart_policy" time="33.622"><failure message="AssertionError: assert 'You cannot remove ' in 'cannot remove container c58aa74af4aedb73d45b2eec79c2e6deb5c32e918a1c34756cc3476bd62ee5a9 as it is running - running or paused containers cannot be removed without force: container state improper'">tests/integration/api_container_test.py:126: in test_create_with_restart_policy
    assert 'You cannot remove ' in err
E   AssertionError: assert 'You cannot remove ' in 'cannot remove container c58aa74af4aedb73d45b2eec79c2e6deb5c32e918a1c34756cc3476bd62ee5a9 as it is running - running or paused containers cannot be removed without force: container state improper'</failure><system-out>--------------------------------- Captured Log ---------------------------------

--------------------------------- Captured Out ---------------------------------

</system-out><system-err>--------------------------------- Captured Err ---------------------------------

</system-err></testcase><testcase classname="tests.integration.api_container_test.CreateContainerTest" name="test_create_with_stop_timeout" time="11.218" /><testcase classname="tests.integration.api_container_test.CreateContainerTest" name="test_create_with_storage_opt" time="11.434"><skipped type="pytest.xfail" message="Not supported on most drivers" /></testcase><testcase classname="tests.integration.api_container_test.CreateContainerTest" name="test_create_with_tmpfs" time="11.822"><failure message="AssertionError: assert {'/tmp1': 'si...ev,tmpcopyup'} == {'/tmp1': 'size=3M'}&#10;  Differing items:&#10;  {'/tmp1': 'size=3M,rw,rprivate,nosuid,nodev,tmpcopyup'} != {'/tmp1': 'size=3M'}&#10;  Full diff:&#10;  - {'/tmp1': 'size=3M'}&#10;  + {'/tmp1': 'size=3M,rw,rprivate,nosuid,nodev,tmpcopyup'}">tests/integration/api_container_test.py:398: in test_create_with_tmpfs
    assert config['HostConfig']['Tmpfs'] == tmpfs
E   AssertionError: assert {'/tmp1': 'si...ev,tmpcopyup'} == {'/tmp1': 'size=3M'}
E     Differing items:
E     {'/tmp1': 'size=3M,rw,rprivate,nosuid,nodev,tmpcopyup'} != {'/tmp1': 'size=3M'}
E     Full diff:
E     - {'/tmp1': 'size=3M'}
E     + {'/tmp1': 'size=3M,rw,rprivate,nosuid,nodev,tmpcopyup'}</failure><system-out>--------------------------------- Captured Log ---------------------------------

--------------------------------- Captured Out ---------------------------------

</system-out><system-err>--------------------------------- Captured Err ---------------------------------

</system-err></testcase><testcase classname="tests.integration.api_container_test.CreateContainerTest" name="test_create_with_uts_mode" time="11.574" /><testcase classname="tests.integration.api_container_test.CreateContainerTest" name="test_group_id_ints" time="12.538" /><testcase classname="tests.integration.api_container_test.CreateContainerTest" name="test_group_id_strings" time="12.499" /><testcase classname="tests.integration.api_container_test.CreateContainerTest" name="test_invalid_log_driver_raises_exception" time="11.329"><failure message="assert 'container create: running container create option: invalid log driver: invalid argument' in [&quot;logger: no log driver named 'asdf' is registered&quot;, 'error looking up logging plugin asdf: plugin &quot;asdf&quot; not found']&#10; +  where 'container create: running container create option: invalid log driver: invalid argument' = APIError(HTTPError('500 Server Error: Internal Server Error for url: http+docker://localhost/v1.41/containers/create')).explanation&#10; +    where APIError(HTTPError('500 Server Error: Internal Server Error for url: http+docker://localhost/v1.41/containers/create')) = &lt;ExceptionInfo APIError(HTTPError('500 Server Error: Internal Server Error for url: http+docker://localhost/v1.41/containers/create')) tblen=6&gt;.value">tests/integration/api_container_test.py:300: in test_invalid_log_driver_raises_exception
    assert excinfo.value.explanation in expected_msgs
E   assert 'container create: running container create option: invalid log driver: invalid argument' in ["logger: no log driver named 'asdf' is registered", 'error looking up logging plugin asdf: plugin "asdf" not found']
E    +  where 'container create: running container create option: invalid log driver: invalid argument' = APIError(HTTPError('500 Server Error: Internal Server Error for url: http+docker://localhost/v1.41/containers/create')).explanation
E    +    where APIError(HTTPError('500 Server Error: Internal Server Error for url: http+docker://localhost/v1.41/containers/create')) = &lt;ExceptionInfo APIError(HTTPError('500 Server Error: Internal Server Error for url: http+docker://localhost/v1.41/containers/create')) tblen=6&gt;.value</failure><system-out>--------------------------------- Captured Log ---------------------------------

--------------------------------- Captured Out ---------------------------------

</system-out><system-err>--------------------------------- Captured Err ---------------------------------

</system-err></testcase><testcase classname="tests.integration.api_container_test.CreateContainerTest" name="test_valid_log_driver_and_log_opt" time="10.564"><failure message="AssertionError: assert None == {'max-file': '100'}&#10; +  where {'max-file': '100'} = {'Type': 'json-file', 'Config': {'max-file': '100'}}.config">tests/integration/api_container_test.py:279: in test_valid_log_driver_and_log_opt
    assert container_log_config['Config'] == log_config.config
E   AssertionError: assert None == {'max-file': '100'}
E    +  where {'max-file': '100'} = {'Type': 'json-file', 'Config': {'max-file': '100'}}.config</failure><system-out>--------------------------------- Captured Log ---------------------------------

--------------------------------- Captured Out ---------------------------------

</system-out><system-err>--------------------------------- Captured Err ---------------------------------

</system-err></testcase><testcase classname="tests.integration.api_container_test.CreateContainerTest" name="test_valid_no_config_specified" time="8.384"><failure message="assert None == {}">tests/integration/api_container_test.py:338: in test_valid_no_config_specified
    assert container_log_config['Config'] == {}
E   assert None == {}</failure><system-out>--------------------------------- Captured Log ---------------------------------

--------------------------------- Captured Out ---------------------------------

</system-out><system-err>--------------------------------- Captured Err ---------------------------------

</system-err></testcase><testcase classname="tests.integration.api_container_test.CreateContainerTest" name="test_valid_no_log_driver_specified" time="7.588"><failure message="AssertionError: assert 'journald' == 'json-file'&#10;  - json-file&#10;  + journald">tests/integration/api_container_test.py:318: in test_valid_no_log_driver_specified
    assert container_log_config['Type'] == "json-file"
E   AssertionError: assert 'journald' == 'json-file'
E     - json-file
E     + journald</failure><system-out>--------------------------------- Captured Log ---------------------------------

--------------------------------- Captured Out ---------------------------------

</system-out><system-err>--------------------------------- Captured Err ---------------------------------

</system-err></testcase><testcase classname="tests.integration.api_container_test.VolumeBindTest" name="test_create_with_binds_ro" time="8.667" /><testcase classname="tests.integration.api_container_test.VolumeBindTest" name="test_create_with_binds_rw" time="8.298" /><testcase classname="tests.integration.api_container_test.VolumeBindTest" name="test_create_with_mounts" time="9.072" /><testcase classname="tests.integration.api_container_test.VolumeBindTest" name="test_create_with_mounts_ro" time="8.808" /><testcase classname="tests.integration.api_container_test.VolumeBindTest" name="test_create_with_volume_mount" time="7.383" /><testcase classname="tests.integration.api_container_test.ArchiveTest" name="test_copy_directory_to_container" time="7.745" /><testcase classname="tests.integration.api_container_test.ArchiveTest" name="test_copy_file_to_container" time="8.102" /><testcase classname="tests.integration.api_container_test.ArchiveTest" name="test_get_file_archive_from_container" time="8.009" /><testcase classname="tests.integration.api_container_test.ArchiveTest" name="test_get_file_stat_from_container" time="7.925" /><testcase classname="tests.integration.api_container_test.RenameContainerTest" name="test_rename_container" time="9.357" /><testcase classname="tests.integration.api_container_test.StartContainerTest" name="test_run_shlex_commands" time="13.557" /><testcase classname="tests.integration.api_container_test.StartContainerTest" name="test_start_container" time="7.346" /><testcase classname="tests.integration.api_container_test.StartContainerTest" name="test_start_container_with_dict_instead_of_id" time="7.349" /><testcase classname="tests.integration.api_container_test.WaitTest" name="test_wait" time="11.208" /><testcase classname="tests.integration.api_container_test.WaitTest" name="test_wait_with_condition" time="12.438" /><testcase classname="tests.integration.api_container_test.WaitTest" name="test_wait_with_dict_instead_of_id" time="11.372" /><testcase classname="tests.integration.api_container_test.LogsTest" name="test_logs" time="9.203" /><testcase classname="tests.integration.api_container_test.LogsTest" name="test_logs_streaming_and_follow" time="8.073" /><testcase classname="tests.integration.api_container_test.LogsTest" name="test_logs_streaming_and_follow_and_cancel" time="7.706"><failure message="Failed: Timeout &gt;5.0s">tests/integration/api_container_test.py:872: in test_logs_streaming_and_follow_and_cancel
    self.client.start(id)
docker/utils/decorators.py:19: in wrapped
    return f(self, resource_id, *args, **kwargs)
docker/api/container.py:1126: in start
    res = self._post(url)
docker/utils/decorators.py:46: in inner
    return f(self, *args, **kwargs)
docker/api/client.py:240: in _post
    return self.post(url, **self._set_request_timeout(kwargs))
../../.virtualenvs/docker-py/lib/python3.11/site-packages/requests/sessions.py:635: in post
    return self.request("POST", url, data=data, json=json, **kwargs)
../../.virtualenvs/docker-py/lib/python3.11/site-packages/requests/sessions.py:587: in request
    resp = self.send(prep, **send_kwargs)
../../.virtualenvs/docker-py/lib/python3.11/site-packages/requests/sessions.py:701: in send
    r = adapter.send(request, **kwargs)
../../.virtualenvs/docker-py/lib/python3.11/site-packages/requests/adapters.py:489: in send
    resp = conn.urlopen(
../../.virtualenvs/docker-py/lib/python3.11/site-packages/urllib3/connectionpool.py:703: in urlopen
    httplib_response = self._make_request(
../../.virtualenvs/docker-py/lib/python3.11/site-packages/urllib3/connectionpool.py:449: in _make_request
    six.raise_from(e, None)
&lt;string&gt;:3: in raise_from
    ???
../../.virtualenvs/docker-py/lib/python3.11/site-packages/urllib3/connectionpool.py:444: in _make_request
    httplib_response = conn.getresponse()
/usr/lib/python3.11/http/client.py:1374: in getresponse
    response.begin()
/usr/lib/python3.11/http/client.py:318: in begin
    version, status, reason = self._read_status()
/usr/lib/python3.11/http/client.py:279: in _read_status
    line = str(self.fp.readline(_MAXLINE + 1), "iso-8859-1")
/usr/lib/python3.11/socket.py:706: in readinto
    return self._sock.recv_into(b)
E   Failed: Timeout &gt;5.0s</failure><system-out>--------------------------------- Captured Log ---------------------------------

--------------------------------- Captured Out ---------------------------------

</system-out><system-err>--------------------------------- Captured Err ---------------------------------

</system-err></testcase><testcase classname="tests.integration.api_container_test.LogsTest" name="test_logs_tail_option" time="7.828" /><testcase classname="tests.integration.api_container_test.LogsTest" name="test_logs_with_dict_instead_of_id" time="8.099" /><testcase classname="tests.integration.api_container_test.LogsTest" name="test_logs_with_tail_0" time="7.809" /><testcase classname="tests.integration.api_container_test.LogsTest" name="test_logs_with_until" time="7.973" /><testcase classname="tests.integration.api_container_test.DiffTest" name="test_diff" time="8.077" /><testcase classname="tests.integration.api_container_test.DiffTest" name="test_diff_with_dict_instead_of_id" time="7.964" /><testcase classname="tests.integration.api_container_test.StopTest" name="test_stop" time="9.760" /><testcase classname="tests.integration.api_container_test.StopTest" name="test_stop_with_dict_instead_of_id" time="9.760" /><testcase classname="tests.integration.api_container_test.KillTest" name="test_kill" time="7.839" /><testcase classname="tests.integration.api_container_test.KillTest" name="test_kill_with_dict_instead_of_id" time="7.897" /><testcase classname="tests.integration.api_container_test.KillTest" name="test_kill_with_signal" time="7.987" /><testcase classname="tests.integration.api_container_test.KillTest" name="test_kill_with_signal_integer" time="7.811" /><testcase classname="tests.integration.api_container_test.KillTest" name="test_kill_with_signal_name" time="7.846" /><testcase classname="tests.integration.api_container_test.PortTest" name="test_port" time="8.136" /><testcase classname="tests.integration.api_container_test.ContainerTopTest" name="test_top" time="7.923"><skipped type="pytest.xfail" message="Output of docker top depends on host distro, and is not formalized." /></testcase><testcase classname="tests.integration.api_container_test.ContainerTopTest" name="test_top_with_psargs" time="8.064"><skipped type="pytest.xfail" message="Output of docker top depends on host distro, and is not formalized." /></testcase><testcase classname="tests.integration.api_container_test.RestartContainerTest" name="test_restart" time="10.485" /><testcase classname="tests.integration.api_container_test.RestartContainerTest" name="test_restart_with_dict_instead_of_id" time="11.191" /><testcase classname="tests.integration.api_container_test.RestartContainerTest" name="test_restart_with_low_timeout" time="13.776" /><testcase classname="tests.integration.api_container_test.RemoveContainerTest" name="test_remove" time="12.505" /><testcase classname="tests.integration.api_container_test.RemoveContainerTest" name="test_remove_with_dict_instead_of_id" time="13.054" /><testcase classname="tests.integration.api_container_test.AttachContainerTest" name="test_attach_no_stream" time="10.001"><failure message="Failed: Timeout &gt;10.0s">tests/integration/base.py:83: in tearDown
    super().tearDown()
tests/integration/base.py:30: in tearDown
    client = docker.from_env(version=TEST_API_VERSION)
docker/client.py:96: in from_env
    return cls(
docker/client.py:45: in __init__
    self.api = APIClient(*args, **kwargs)
docker/api/client.py:197: in __init__
    self._version = self._retrieve_server_version()
docker/api/client.py:214: in _retrieve_server_version
    return self.version(api_version=False)["ApiVersion"]
docker/api/daemon.py:181: in version
    return self._result(self._get(url), json=True)
docker/utils/decorators.py:46: in inner
    return f(self, *args, **kwargs)
docker/api/client.py:251: in _get
    return self.get(url, **self._set_request_timeout(kwargs))
../../.virtualenvs/docker-py/lib/python3.11/site-packages/requests/sessions.py:600: in get
    return self.request("GET", url, **kwargs)
../../.virtualenvs/docker-py/lib/python3.11/site-packages/requests/sessions.py:587: in request
    resp = self.send(prep, **send_kwargs)
../../.virtualenvs/docker-py/lib/python3.11/site-packages/requests/sessions.py:701: in send
    r = adapter.send(request, **kwargs)
../../.virtualenvs/docker-py/lib/python3.11/site-packages/requests/adapters.py:489: in send
    resp = conn.urlopen(
../../.virtualenvs/docker-py/lib/python3.11/site-packages/urllib3/connectionpool.py:703: in urlopen
    httplib_response = self._make_request(
../../.virtualenvs/docker-py/lib/python3.11/site-packages/urllib3/connectionpool.py:449: in _make_request
    six.raise_from(e, None)
../../.virtualenvs/docker-py/lib/python3.11/site-packages/urllib3/connectionpool.py:444: in _make_request
    httplib_response = conn.getresponse()
/usr/lib/python3.11/http/client.py:1374: in getresponse
    response.begin()
/usr/lib/python3.11/http/client.py:318: in begin
    version, status, reason = self._read_status()
/usr/lib/python3.11/http/client.py:279: in _read_status
    line = str(self.fp.readline(_MAXLINE + 1), "iso-8859-1")
/usr/lib/python3.11/socket.py:706: in readinto
    return self._sock.recv_into(b)
E   Failed: Timeout &gt;10.0s</failure><system-out>--------------------------------- Captured Log ---------------------------------

--------------------------------- Captured Out ---------------------------------

</system-out><system-err>--------------------------------- Captured Err ---------------------------------

</system-err></testcase><testcase classname="tests.integration.api_container_test.AttachContainerTest" name="test_attach_stream_and_cancel" time="14.009"><failure message="Failed: Timeout &gt;10.0s">tests/integration/api_container_test.py:1282: in test_attach_stream_and_cancel
    for line in output:
docker/types/daemon.py:29: in __next__
    return next(self._stream)
docker/api/client.py:450: in &lt;genexpr&gt;
    gen = (data for (_, data) in gen)
docker/utils/socket.py:102: in &lt;genexpr&gt;
    return ((STDOUT, frame) for frame in frames_iter_tty(socket))
docker/utils/socket.py:134: in frames_iter_tty
    result = read(socket)
docker/utils/socket.py:41: in read
    poll.poll()
E   Failed: Timeout &gt;10.0s</failure><system-out>--------------------------------- Captured Log ---------------------------------

--------------------------------- Captured Out ---------------------------------

</system-out><system-err>--------------------------------- Captured Err ---------------------------------

+++++++++++++++++++++++++++++++++++ Timeout ++++++++++++++++++++++++++++++++++++

~~~~~~~~~~~~~~~~~~~~~ Stack of Thread-1 (139857422710464) ~~~~~~~~~~~~~~~~~~~~~~
  File "/usr/lib/python3.11/threading.py", line 995, in _bootstrap
    self._bootstrap_inner()
  File "/usr/lib/python3.11/threading.py", line 1038, in _bootstrap_inner
    self.run()
  File "/usr/lib/python3.11/threading.py", line 1392, in run
    self.finished.wait(self.interval)
  File "/usr/lib/python3.11/threading.py", line 622, in wait
    signaled = self._cond.wait(timeout)
  File "/usr/lib/python3.11/threading.py", line 324, in wait
    gotit = waiter.acquire(True, timeout)

+++++++++++++++++++++++++++++++++++ Timeout ++++++++++++++++++++++++++++++++++++

</system-err></testcase><testcase classname="tests.integration.api_container_test.AttachContainerTest" name="test_detach_with_arg" time="12.774" /><testcase classname="tests.integration.api_container_test.AttachContainerTest" name="test_detach_with_config_file" time="16.040" /><testcase classname="tests.integration.api_container_test.AttachContainerTest" name="test_detach_with_default" time="15.473" /><testcase classname="tests.integration.api_container_test.AttachContainerTest" name="test_run_container_reading_socket_http" time="13.279" /><testcase classname="tests.integration.api_container_test.AttachContainerTest" name="test_run_container_reading_socket_ws" time="11.728"><failure message="ValueError: scheme http+docker is invalid">tests/integration/api_container_test.py:1245: in test_run_container_reading_socket_ws
    pty_stdout = self.client.attach_socket(container, opts, ws=True)
docker/utils/decorators.py:19: in wrapped
    return f(self, resource_id, *args, **kwargs)
docker/api/container.py:98: in attach_socket
    return self._attach_websocket(container, params)
docker/utils/decorators.py:19: in wrapped
    return f(self, resource_id, *args, **kwargs)
docker/api/client.py:340: in _attach_websocket
    return self._create_websocket_connection(full_url)
docker/api/client.py:343: in _create_websocket_connection
    return websocket.create_connection(url)
../../.virtualenvs/docker-py/lib/python3.11/site-packages/websocket/_core.py:601: in create_connection
    websock.connect(url, **options)
../../.virtualenvs/docker-py/lib/python3.11/site-packages/websocket/_core.py:244: in connect
    self.sock, addrs = connect(url, self.sock_opt, proxy_info(**options),
../../.virtualenvs/docker-py/lib/python3.11/site-packages/websocket/_http.py:117: in connect
    hostname, port, resource, is_secure = parse_url(url)
../../.virtualenvs/docker-py/lib/python3.11/site-packages/websocket/_url.py:62: in parse_url
    raise ValueError("scheme %s is invalid" % scheme)
E   ValueError: scheme http+docker is invalid</failure><system-out>--------------------------------- Captured Log ---------------------------------

--------------------------------- Captured Out ---------------------------------

</system-out><system-err>--------------------------------- Captured Err ---------------------------------

</system-err></testcase><testcase classname="tests.integration.api_container_test.AttachContainerTest" name="test_run_container_streaming" time="12.195" /><testcase classname="tests.integration.api_container_test.PauseTest" name="test_pause_unpause" time="12.313" /><testcase classname="tests.integration.api_container_test.PruneTest" name="test_prune_containers" time="13.042" /><testcase classname="tests.integration.api_container_test.GetContainerStatsTest" name="test_get_container_stats_no_stream" time="12.146" /><testcase classname="tests.integration.api_container_test.ContainerUpdateTest" name="test_restart_policy_update" time="12.052"><failure message="TypeError: a bytes-like object is required, not 'str'">docker/api/client.py:296: in _raise_for_status
    response.raise_for_status()
../../.virtualenvs/docker-py/lib/python3.11/site-packages/requests/models.py:1021: in raise_for_status
    raise HTTPError(http_error_msg, response=self)
E   requests.exceptions.HTTPError: 404 Client Error: Not Found for url: http+docker://localhost/v1.41/containers/e1b3cdc75e2bdbe91f5d7565664a660f850f5428055e397748200b62de321f96/update

During handling of the above exception, another exception occurred:
tests/integration/api_container_test.py:1448: in test_restart_policy_update
    self.client.update_container(container,
docker/utils/decorators.py:34: in wrapper
    return f(self, *args, **kwargs)
docker/utils/decorators.py:19: in wrapped
    return f(self, resource_id, *args, **kwargs)
docker/api/container.py:1303: in update_container
    return self._result(res, True)
docker/api/client.py:302: in _result
    self._raise_for_status(response)
docker/api/client.py:298: in _raise_for_status
    raise create_api_error_from_http_exception(e) from e
docker/errors.py:34: in create_api_error_from_http_exception
    if any(fragment in explanation_msg
docker/errors.py:34: in &lt;genexpr&gt;
    if any(fragment in explanation_msg
E   TypeError: a bytes-like object is required, not 'str'</failure><system-out>--------------------------------- Captured Log ---------------------------------

--------------------------------- Captured Out ---------------------------------

</system-out><system-err>--------------------------------- Captured Err ---------------------------------

</system-err></testcase><testcase classname="tests.integration.api_container_test.ContainerUpdateTest" name="test_update_container" time="11.976"><failure message="TypeError: a bytes-like object is required, not 'str'">docker/api/client.py:296: in _raise_for_status
    response.raise_for_status()
../../.virtualenvs/docker-py/lib/python3.11/site-packages/requests/models.py:1021: in raise_for_status
    raise HTTPError(http_error_msg, response=self)
E   requests.exceptions.HTTPError: 404 Client Error: Not Found for url: http+docker://localhost/v1.41/containers/356b6e7f40581626592d46cae8aca1986ef74246c126d96d41d8a38fb33b5dc8/update

During handling of the above exception, another exception occurred:
tests/integration/api_container_test.py:1426: in test_update_container
    self.client.update_container(container, mem_limit=new_mem_limit)
docker/utils/decorators.py:34: in wrapper
    return f(self, *args, **kwargs)
docker/utils/decorators.py:19: in wrapped
    return f(self, resource_id, *args, **kwargs)
docker/api/container.py:1303: in update_container
    return self._result(res, True)
docker/api/client.py:302: in _result
    self._raise_for_status(response)
docker/api/client.py:298: in _raise_for_status
    raise create_api_error_from_http_exception(e) from e
docker/errors.py:34: in create_api_error_from_http_exception
    if any(fragment in explanation_msg
docker/errors.py:34: in &lt;genexpr&gt;
    if any(fragment in explanation_msg
E   TypeError: a bytes-like object is required, not 'str'</failure><system-out>--------------------------------- Captured Log ---------------------------------

--------------------------------- Captured Out ---------------------------------

</system-out><system-err>--------------------------------- Captured Err ---------------------------------

</system-err></testcase><testcase classname="tests.integration.api_container_test.ContainerCPUTest" name="test_container_cpu_shares" time="12.199" /><testcase classname="tests.integration.api_container_test.ContainerCPUTest" name="test_container_cpuset" time="12.127" /><testcase classname="tests.integration.api_container_test.ContainerCPUTest" name="test_create_with_runtime" time="13.106"><failure message="AssertionError: assert 'oci' == 'runc'&#10;  - runc&#10;  + oci">tests/integration/api_container_test.py:1493: in test_create_with_runtime
    assert config['HostConfig']['Runtime'] == 'runc'
E   AssertionError: assert 'oci' == 'runc'
E     - runc
E     + oci</failure><system-out>--------------------------------- Captured Log ---------------------------------

--------------------------------- Captured Out ---------------------------------

</system-out><system-err>--------------------------------- Captured Err ---------------------------------

</system-err></testcase><testcase classname="tests.integration.api_exec_test.ExecTest" name="test_detach_with_config_file" time="17.686"><failure message="AssertionError">tests/integration/api_exec_test.py:227: in test_detach_with_config_file
    assert_cat_socket_detached_with_keys(sock, [ctrl_with('p')])
tests/helpers.py:137: in assert_cat_socket_detached_with_keys
    assert data == b'' or data.startswith(
E   AssertionError</failure><system-out>--------------------------------- Captured Log ---------------------------------

--------------------------------- Captured Out ---------------------------------

</system-out><system-err>--------------------------------- Captured Err ---------------------------------

</system-err></testcase><testcase classname="tests.integration.api_exec_test.ExecTest" name="test_detach_with_default" time="18.070"><failure message="AssertionError">tests/integration/api_exec_test.py:208: in test_detach_with_default
    assert_cat_socket_detached_with_keys(
tests/helpers.py:137: in assert_cat_socket_detached_with_keys
    assert data == b'' or data.startswith(
E   AssertionError</failure><system-out>--------------------------------- Captured Log ---------------------------------

--------------------------------- Captured Out ---------------------------------

</system-out><system-err>--------------------------------- Captured Err ---------------------------------

</system-err></testcase><testcase classname="tests.integration.api_exec_test.ExecTest" name="test_exec_command_as_root" time="13.258" /><testcase classname="tests.integration.api_exec_test.ExecTest" name="test_exec_command_as_user" time="14.403" /><testcase classname="tests.integration.api_exec_test.ExecTest" name="test_exec_command_streaming" time="14.658" /><testcase classname="tests.integration.api_exec_test.ExecTest" name="test_exec_command_string" time="14.410" /><testcase classname="tests.integration.api_exec_test.ExecTest" name="test_exec_command_with_env" time="13.458" /><testcase classname="tests.integration.api_exec_test.ExecTest" name="test_exec_command_with_workdir" time="12.982" /><testcase classname="tests.integration.api_exec_test.ExecTest" name="test_exec_inspect" time="12.494" /><testcase classname="tests.integration.api_exec_test.ExecTest" name="test_exec_start_detached" time="11.307"><failure message="AssertionError: assert '\n' == ''&#10;  Strings contain only whitespace, escaping them using repr()&#10;  - ''&#10;  + '\n'">tests/integration/api_exec_test.py:152: in test_exec_start_detached
    assert response == ""
E   AssertionError: assert '\n' == ''
E     Strings contain only whitespace, escaping them using repr()
E     - ''
E     + '\n'</failure><system-out>--------------------------------- Captured Log ---------------------------------

--------------------------------- Captured Out ---------------------------------

</system-out><system-err>--------------------------------- Captured Err ---------------------------------

</system-err></testcase><testcase classname="tests.integration.api_exec_test.ExecTest" name="test_exec_start_socket" time="8.939"><failure message="assert 121 == 1">tests/integration/api_exec_test.py:134: in test_exec_start_socket
    assert stream == 1  # stdout (0 = stdin, 1 = stdout, 2 = stderr)
E   assert 121 == 1</failure><system-out>--------------------------------- Captured Log ---------------------------------

--------------------------------- Captured Out ---------------------------------

</system-out><system-err>--------------------------------- Captured Err ---------------------------------

</system-err></testcase><testcase classname="tests.integration.api_exec_test.ExecTest" name="test_execute_command" time="8.632" /><testcase classname="tests.integration.api_exec_test.ExecTest" name="test_execute_command_with_proxy_env" time="8.858" /><testcase classname="tests.integration.api_exec_test.ExecDemuxTest" name="test_exec_command_no_stream_demux" time="9.183" /><testcase classname="tests.integration.api_exec_test.ExecDemuxTest" name="test_exec_command_no_stream_no_demux" time="9.138" /><testcase classname="tests.integration.api_exec_test.ExecDemuxTest" name="test_exec_command_stream_demux" time="10.414" /><testcase classname="tests.integration.api_exec_test.ExecDemuxTest" name="test_exec_command_stream_no_demux" time="11.183" /><testcase classname="tests.integration.api_exec_test.ExecDemuxTest" name="test_exec_command_tty_no_stream_demux" time="10.326"><failure message="ValueError: 104 is not a valid stream">tests/integration/api_exec_test.py:299: in test_exec_command_tty_no_stream_demux
    exec_log = self.client.exec_start(res, demux=True)
docker/utils/decorators.py:19: in wrapped
    return f(self, resource_id, *args, **kwargs)
docker/api/exec_api.py:173: in exec_start
    output = self._read_from_socket(res, stream, tty=tty, demux=demux)
docker/api/client.py:457: in _read_from_socket
    return consume_socket_output(gen, demux=demux)
docker/utils/socket.py:161: in consume_socket_output
    for frame in frames:
docker/api/client.py:447: in &lt;genexpr&gt;
    gen = (demux_adaptor(*frame) for frame in gen)
docker/utils/socket.py:188: in demux_adaptor
    raise ValueError(f'{stream_id} is not a valid stream')
E   ValueError: 104 is not a valid stream</failure><system-out>--------------------------------- Captured Log ---------------------------------

--------------------------------- Captured Out ---------------------------------

</system-out><system-err>--------------------------------- Captured Err ---------------------------------

</system-err></testcase><testcase classname="tests.integration.api_exec_test.ExecDemuxTest" name="test_exec_command_tty_no_stream_no_demux" time="8.679"><failure message="AssertionError: assert b't\r\nhello err\r\n' == b'hello out\r\nhello err\r\n'&#10;  At index 0 diff: b't' != b'h'&#10;  Full diff:&#10;  - b'hello out\r\nhello err\r\n'&#10;  ?   --------&#10;  + b't\r\nhello err\r\n'">tests/integration/api_exec_test.py:282: in test_exec_command_tty_no_stream_no_demux
    assert exec_log == b'hello out\r\nhello err\r\n'
E   AssertionError: assert b't\r\nhello err\r\n' == b'hello out\r\nhello err\r\n'
E     At index 0 diff: b't' != b'h'
E     Full diff:
E     - b'hello out\r\nhello err\r\n'
E     ?   --------
E     + b't\r\nhello err\r\n'</failure><system-out>--------------------------------- Captured Log ---------------------------------

--------------------------------- Captured Out ---------------------------------

</system-out><system-err>--------------------------------- Captured Err ---------------------------------

</system-err></testcase><testcase classname="tests.integration.api_exec_test.ExecDemuxTest" name="test_exec_command_tty_stream_demux" time="8.393"><failure message="ValueError: 104 is not a valid stream">tests/integration/api_exec_test.py:305: in test_exec_command_tty_stream_demux
    exec_log = list(self.client.exec_start(res, demux=True, stream=True))
docker/types/daemon.py:29: in __next__
    return next(self._stream)
docker/api/client.py:447: in &lt;genexpr&gt;
    gen = (demux_adaptor(*frame) for frame in gen)
docker/utils/socket.py:188: in demux_adaptor
    raise ValueError(f'{stream_id} is not a valid stream')
E   ValueError: 104 is not a valid stream</failure><system-out>--------------------------------- Captured Log ---------------------------------

--------------------------------- Captured Out ---------------------------------

</system-out><system-err>--------------------------------- Captured Err ---------------------------------

</system-err></testcase><testcase classname="tests.integration.api_exec_test.ExecDemuxTest" name="test_exec_command_tty_stream_no_demux" time="8.710"><failure message="AssertionError: assert b'hello out\r\n' in [b't\r\n', b'hello err\r\n']">tests/integration/api_exec_test.py:288: in test_exec_command_tty_stream_no_demux
    assert b'hello out\r\n' in exec_log
E   AssertionError: assert b'hello out\r\n' in [b't\r\n', b'hello err\r\n']</failure><system-out>--------------------------------- Captured Log ---------------------------------

--------------------------------- Captured Out ---------------------------------

</system-out><system-err>--------------------------------- Captured Err ---------------------------------

</system-err></testcase><testcase classname="tests.integration.api_healthcheck_test.HealthcheckTest" name="test_healthcheck_fails" time="8.429" /><testcase classname="tests.integration.api_healthcheck_test.HealthcheckTest" name="test_healthcheck_passes" time="8.330" /><testcase classname="tests.integration.api_healthcheck_test.HealthcheckTest" name="test_healthcheck_shell_command" time="7.950" /><testcase classname="tests.integration.api_healthcheck_test.HealthcheckTest" name="test_healthcheck_start_period" time="11.099" /><testcase classname="tests.integration.api_image_test.ListImagesTest" name="test_images" time="8.660" /><testcase classname="tests.integration.api_image_test.ListImagesTest" name="test_images_quiet" time="7.041" /><testcase classname="tests.integration.api_image_test.PullImageTest" name="test_pull" time="8.941" /><testcase classname="tests.integration.api_image_test.PullImageTest" name="test_pull_invalid_platform" time="9.655"><failure message="Failed: DID NOT RAISE &lt;class 'docker.errors.APIError'&gt;">tests/integration/api_image_test.py:68: in test_pull_invalid_platform
    with pytest.raises(docker.errors.APIError) as excinfo:
E   Failed: DID NOT RAISE &lt;class 'docker.errors.APIError'&gt;</failure><system-out>--------------------------------- Captured Log ---------------------------------

--------------------------------- Captured Out ---------------------------------

</system-out><system-err>--------------------------------- Captured Err ---------------------------------

</system-err></testcase><testcase classname="tests.integration.api_image_test.PullImageTest" name="test_pull_streaming" time="8.780" /><testcase classname="tests.integration.api_image_test.CommitTest" name="test_commit" time="7.800"><failure message="AssertionError: assert False&#10; +  where False = &lt;built-in method startswith of str object at 0xa65e80&gt;('3dd874ccab1d821e7317b03b57a328a087669ccc4fa97cd38c52fff3ca2c4754')&#10; +    where &lt;built-in method startswith of str object at 0xa65e80&gt; = ''.startswith">tests/integration/api_image_test.py:89: in test_commit
    assert img['Container'].startswith(id)
E   AssertionError: assert False
E    +  where False = &lt;built-in method startswith of str object at 0xa65e80&gt;('3dd874ccab1d821e7317b03b57a328a087669ccc4fa97cd38c52fff3ca2c4754')
E    +    where &lt;built-in method startswith of str object at 0xa65e80&gt; = ''.startswith</failure><system-out>--------------------------------- Captured Log ---------------------------------

--------------------------------- Captured Out ---------------------------------

</system-out><system-err>--------------------------------- Captured Err ---------------------------------

</system-err></testcase><testcase classname="tests.integration.api_image_test.CommitTest" name="test_commit_with_changes" time="9.587"><failure message="AssertionError: assert False&#10; +  where False = &lt;built-in method startswith of str object at 0xa65e80&gt;('e296b7390052e5963d08d7011690d6acc95bdeb26748df239cc5fe54f09e49ba')&#10; +    where &lt;built-in method startswith of str object at 0xa65e80&gt; = ''.startswith">tests/integration/api_image_test.py:107: in test_commit_with_changes
    assert img['Container'].startswith(cid['Id'])
E   AssertionError: assert False
E    +  where False = &lt;built-in method startswith of str object at 0xa65e80&gt;('e296b7390052e5963d08d7011690d6acc95bdeb26748df239cc5fe54f09e49ba')
E    +    where &lt;built-in method startswith of str object at 0xa65e80&gt; = ''.startswith</failure><system-out>--------------------------------- Captured Log ---------------------------------

--------------------------------- Captured Out ---------------------------------

</system-out><system-err>--------------------------------- Captured Err ---------------------------------

</system-err></testcase><testcase classname="tests.integration.api_image_test.RemoveImageTest" name="test_remove" time="9.905" /><testcase classname="tests.integration.api_image_test.ImportImageTest" name="test_get_load_image" time="10.719"><failure message="assert False&#10; +  where False = any([])">tests/integration/api_image_test.py:266: in test_get_load_image
    assert any([
E   assert False
E    +  where False = any([])</failure><system-out>--------------------------------- Captured Log ---------------------------------

--------------------------------- Captured Out ---------------------------------

</system-out><system-err>--------------------------------- Captured Err ---------------------------------

</system-err></testcase><testcase classname="tests.integration.api_image_test.ImportImageTest" name="test_import_from_bytes" time="8.135" /><testcase classname="tests.integration.api_image_test.ImportImageTest" name="test_import_from_file" time="8.260" /><testcase classname="tests.integration.api_image_test.ImportImageTest" name="test_import_from_stream" time="8.037" /><testcase classname="tests.integration.api_image_test.ImportImageTest" name="test_import_from_url" time="0.000"><skipped type="pytest.skip" message="Doesn't work inside a container - FIXME">/home/riyad/src/docker-py/tests/integration/api_image_test.py:291: Doesn't work inside a container - FIXME</skipped><system-out>--------------------------------- Captured Log ---------------------------------

--------------------------------- Captured Out ---------------------------------

</system-out><system-err>--------------------------------- Captured Err ---------------------------------

</system-err></testcase><testcase classname="tests.integration.api_image_test.ImportImageTest" name="test_import_image_from_data_with_changes" time="8.135" /><testcase classname="tests.integration.api_image_test.ImportImageTest" name="test_import_image_with_changes" time="8.231" /><testcase classname="tests.integration.api_image_test.PruneImagesTest" name="test_prune_images" time="10.006"><failure message="docker.errors.APIError: 500 Server Error for http+docker://localhost/v1.41/images/prune?filters=%7B%22dangling%22%3A+%5B%22false%22%5D%7D: Internal Server Error (&quot;specifying &quot;dangling&quot; filter more than once with different values is not supported&quot;)">docker/api/client.py:296: in _raise_for_status
    response.raise_for_status()
../../.virtualenvs/docker-py/lib/python3.11/site-packages/requests/models.py:1021: in raise_for_status
    raise HTTPError(http_error_msg, response=self)
E   requests.exceptions.HTTPError: 500 Server Error: Internal Server Error for url: http+docker://localhost/v1.41/images/prune?filters=%7B%22dangling%22%3A+%5B%22false%22%5D%7D

The above exception was the direct cause of the following exception:
tests/integration/api_image_test.py:331: in test_prune_images
    result = self.client.prune_images({'dangling': False})
docker/utils/decorators.py:34: in wrapper
    return f(self, *args, **kwargs)
docker/api/image.py:349: in prune_images
    return self._result(self._post(url, params=params), True)
docker/api/client.py:302: in _result
    self._raise_for_status(response)
docker/api/client.py:298: in _raise_for_status
    raise create_api_error_from_http_exception(e) from e
docker/errors.py:39: in create_api_error_from_http_exception
    raise cls(e, response=response, explanation=explanation) from e
E   docker.errors.APIError: 500 Server Error for http+docker://localhost/v1.41/images/prune?filters=%7B%22dangling%22%3A+%5B%22false%22%5D%7D: Internal Server Error ("specifying "dangling" filter more than once with different values is not supported")</failure><system-out>--------------------------------- Captured Log ---------------------------------

--------------------------------- Captured Out ---------------------------------

</system-out><system-err>--------------------------------- Captured Err ---------------------------------

</system-err></testcase><testcase classname="tests.integration.api_image_test.SaveLoadImagesTest" name="test_get_image_load_image" time="8.161"><failure message="assert False is True">tests/integration/api_image_test.py:360: in test_get_image_load_image
    assert success is True
E   assert False is True</failure><system-out>--------------------------------- Captured Log ---------------------------------

--------------------------------- Captured Out ---------------------------------
{'stream': 'Loaded image: docker.io/library/alpine:3.10'}

</system-out><system-err>--------------------------------- Captured Err ---------------------------------

</system-err></testcase><testcase classname="tests.integration.api_image_test.InspectDistributionTest" name="test_inspect_distribution" time="8.114"><failure message="docker.errors.NotFound: 404 Client Error for http+docker://localhost/v1.41/distribution/busybox:latest/json: Not Found (&quot;Path /v1.41/distribution/busybox:latest/json is not supported&quot;)">docker/api/client.py:296: in _raise_for_status
    response.raise_for_status()
../../.virtualenvs/docker-py/lib/python3.11/site-packages/requests/models.py:1021: in raise_for_status
    raise HTTPError(http_error_msg, response=self)
E   requests.exceptions.HTTPError: 404 Client Error: Not Found for url: http+docker://localhost/v1.41/distribution/busybox:latest/json

The above exception was the direct cause of the following exception:
tests/integration/api_image_test.py:366: in test_inspect_distribution
    data = self.client.inspect_distribution('busybox:latest')
docker/utils/decorators.py:34: in wrapper
    return f(self, *args, **kwargs)
docker/utils/decorators.py:19: in wrapped
    return f(self, resource_id, *args, **kwargs)
docker/api/image.py:287: in inspect_distribution
    return self._result(
docker/api/client.py:302: in _result
    self._raise_for_status(response)
docker/api/client.py:298: in _raise_for_status
    raise create_api_error_from_http_exception(e) from e
docker/errors.py:39: in create_api_error_from_http_exception
    raise cls(e, response=response, explanation=explanation) from e
E   docker.errors.NotFound: 404 Client Error for http+docker://localhost/v1.41/distribution/busybox:latest/json: Not Found ("Path /v1.41/distribution/busybox:latest/json is not supported")</failure><system-out>--------------------------------- Captured Log ---------------------------------

--------------------------------- Captured Out ---------------------------------

</system-out><system-err>--------------------------------- Captured Err ---------------------------------

</system-err></testcase><testcase classname="tests.integration.api_network_test.TestNetworks" name="test_connect_and_disconnect_container" time="9.145" /><testcase classname="tests.integration.api_network_test.TestNetworks" name="test_connect_and_force_disconnect_container" time="9.695" /><testcase classname="tests.integration.api_network_test.TestNetworks" name="test_connect_on_container_create" time="8.795" /><testcase classname="tests.integration.api_network_test.TestNetworks" name="test_connect_with_aliases" time="9.005" /><testcase classname="tests.integration.api_network_test.TestNetworks" name="test_connect_with_ipv4_address" time="9.339"><failure message="TypeError: 'NoneType' object is not subscriptable">tests/integration/api_network_test.py:379: in test_connect_with_ipv4_address
    assert net_data['IPAMConfig']['IPv4Address'] == '172.28.5.24'
E   TypeError: 'NoneType' object is not subscriptable</failure><system-out>--------------------------------- Captured Log ---------------------------------

--------------------------------- Captured Out ---------------------------------

</system-out><system-err>--------------------------------- Captured Err ---------------------------------

</system-err></testcase><testcase classname="tests.integration.api_network_test.TestNetworks" name="test_connect_with_ipv6_address" time="9.584"><failure message="TypeError: 'NoneType' object is not subscriptable">tests/integration/api_network_test.py:405: in test_connect_with_ipv6_address
    assert net_data['IPAMConfig']['IPv6Address'] == '2001:389::f00d'
E   TypeError: 'NoneType' object is not subscriptable</failure><system-out>--------------------------------- Captured Log ---------------------------------

--------------------------------- Captured Out ---------------------------------

</system-out><system-err>--------------------------------- Captured Err ---------------------------------

</system-err></testcase><testcase classname="tests.integration.api_network_test.TestNetworks" name="test_connect_with_links" time="9.644"><failure message="AssertionError: assert None == ['docker-py-test-upstream:bar']">tests/integration/api_network_test.py:344: in test_connect_with_links
    assert net_settings['Networks'][net_name]['Links'] == [
E   AssertionError: assert None == ['docker-py-test-upstream:bar']</failure><system-out>--------------------------------- Captured Log ---------------------------------

--------------------------------- Captured Out ---------------------------------

</system-out><system-err>--------------------------------- Captured Err ---------------------------------

</system-err></testcase><testcase classname="tests.integration.api_network_test.TestNetworks" name="test_connect_with_mac_address" time="8.254"><failure message="AssertionError: assert '' == '02:42:ac:11:00:02'&#10;  - 02:42:ac:11:00:02">tests/integration/api_network_test.py:421: in test_connect_with_mac_address
    assert net_data['MacAddress'] == '02:42:ac:11:00:02'
E   AssertionError: assert '' == '02:42:ac:11:00:02'
E     - 02:42:ac:11:00:02</failure><system-out>--------------------------------- Captured Log ---------------------------------

--------------------------------- Captured Out ---------------------------------

</system-out><system-err>--------------------------------- Captured Err ---------------------------------

</system-err></testcase><testcase classname="tests.integration.api_network_test.TestNetworks" name="test_create_check_duplicate" time="7.999" /><testcase classname="tests.integration.api_network_test.TestNetworks" name="test_create_internal_networks" time="8.023" /><testcase classname="tests.integration.api_network_test.TestNetworks" name="test_create_network_ipv6_enabled" time="8.352" /><testcase classname="tests.integration.api_network_test.TestNetworks" name="test_create_network_with_host_driver_fails" time="8.056" /><testcase classname="tests.integration.api_network_test.TestNetworks" name="test_create_network_with_ipam_config" time="8.130"><failure message="AssertionError: assert {'driver': 'host-local'} is None&#10; +  where {'driver': 'host-local'} = &lt;built-in method pop of dict object at 0x7f3318647840&gt;('Options', None)&#10; +    where &lt;built-in method pop of dict object at 0x7f3318647840&gt; = {'Config': [{'Gateway': '172.28.5.254', 'Subnet': '172.28.0.0/16'}], 'Driver': 'default'}.pop">tests/integration/api_network_test.py:62: in test_create_network_with_ipam_config
    assert ipam.pop('Options', None) is None
E   AssertionError: assert {'driver': 'host-local'} is None
E    +  where {'driver': 'host-local'} = &lt;built-in method pop of dict object at 0x7f3318647840&gt;('Options', None)
E    +    where &lt;built-in method pop of dict object at 0x7f3318647840&gt; = {'Config': [{'Gateway': '172.28.5.254', 'Subnet': '172.28.0.0/16'}], 'Driver': 'default'}.pop</failure><system-out>--------------------------------- Captured Log ---------------------------------

--------------------------------- Captured Out ---------------------------------

</system-out><system-err>--------------------------------- Captured Err ---------------------------------

</system-err></testcase><testcase classname="tests.integration.api_network_test.TestNetworks" name="test_create_network_with_labels" time="8.036" /><testcase classname="tests.integration.api_network_test.TestNetworks" name="test_create_network_with_labels_wrong_type" time="8.026" /><testcase classname="tests.integration.api_network_test.TestNetworks" name="test_create_remove_network_with_space_in_name" time="8.039"><failure message="docker.errors.APIError: 500 Server Error for http+docker://localhost/v1.41/networks/create: Internal Server Error (&quot;network name test 01 invalid: names must match [a-zA-Z0-9][a-zA-Z0-9_.-]*: invalid argument&quot;)">docker/api/client.py:296: in _raise_for_status
    response.raise_for_status()
../../.virtualenvs/docker-py/lib/python3.11/site-packages/requests/models.py:1021: in raise_for_status
    raise HTTPError(http_error_msg, response=self)
E   requests.exceptions.HTTPError: 500 Server Error: Internal Server Error for url: http+docker://localhost/v1.41/networks/create

The above exception was the direct cause of the following exception:
tests/integration/api_network_test.py:470: in test_create_remove_network_with_space_in_name
    net_id = self.client.create_network('test 01')
docker/api/network.py:153: in create_network
    return self._result(res, json=True)
docker/api/client.py:302: in _result
    self._raise_for_status(response)
docker/api/client.py:298: in _raise_for_status
    raise create_api_error_from_http_exception(e) from e
docker/errors.py:39: in create_api_error_from_http_exception
    raise cls(e, response=response, explanation=explanation) from e
E   docker.errors.APIError: 500 Server Error for http+docker://localhost/v1.41/networks/create: Internal Server Error ("network name test 01 invalid: names must match [a-zA-Z0-9][a-zA-Z0-9_.-]*: invalid argument")</failure><system-out>--------------------------------- Captured Log ---------------------------------

--------------------------------- Captured Out ---------------------------------

</system-out><system-err>--------------------------------- Captured Err ---------------------------------

</system-err></testcase><testcase classname="tests.integration.api_network_test.TestNetworks" name="test_create_with_aliases" time="8.673" /><testcase classname="tests.integration.api_network_test.TestNetworks" name="test_create_with_driveropt" time="8.037"><failure message="docker.errors.APIError: 500 Server Error for http+docker://localhost/v1.41/containers/create: Internal Server Error (&quot;container create: unable to find network with name or ID bridge: network not found&quot;)">docker/api/client.py:296: in _raise_for_status
    response.raise_for_status()
../../.virtualenvs/docker-py/lib/python3.11/site-packages/requests/models.py:1021: in raise_for_status
    raise HTTPError(http_error_msg, response=self)
E   requests.exceptions.HTTPError: 500 Server Error: Internal Server Error for url: http+docker://localhost/v1.41/containers/create

The above exception was the direct cause of the following exception:
tests/integration/api_network_test.py:276: in test_create_with_driveropt
    container = self.client.create_container(
docker/api/container.py:431: in create_container
    return self.create_container_from_config(config, name, platform)
docker/api/container.py:448: in create_container_from_config
    return self._result(res, True)
docker/api/client.py:302: in _result
    self._raise_for_status(response)
docker/api/client.py:298: in _raise_for_status
    raise create_api_error_from_http_exception(e) from e
docker/errors.py:39: in create_api_error_from_http_exception
    raise cls(e, response=response, explanation=explanation) from e
E   docker.errors.APIError: 500 Server Error for http+docker://localhost/v1.41/containers/create: Internal Server Error ("container create: unable to find network with name or ID bridge: network not found")</failure><system-out>--------------------------------- Captured Log ---------------------------------

--------------------------------- Captured Out ---------------------------------

</system-out><system-err>--------------------------------- Captured Err ---------------------------------

</system-err></testcase><testcase classname="tests.integration.api_network_test.TestNetworks" name="test_create_with_ipv4_address" time="8.759"><failure message="TypeError: 'NoneType' object is not subscriptable">tests/integration/api_network_test.py:224: in test_create_with_ipv4_address
    assert net_settings['Networks'][net_name]['IPAMConfig']['IPv4Address']\
E   TypeError: 'NoneType' object is not subscriptable</failure><system-out>--------------------------------- Captured Log ---------------------------------

--------------------------------- Captured Out ---------------------------------

</system-out><system-err>--------------------------------- Captured Err ---------------------------------

</system-err></testcase><testcase classname="tests.integration.api_network_test.TestNetworks" name="test_create_with_ipv6_address" time="8.857"><failure message="TypeError: 'NoneType' object is not subscriptable">tests/integration/api_network_test.py:250: in test_create_with_ipv6_address
    assert net_settings['Networks'][net_name]['IPAMConfig']['IPv6Address']\
E   TypeError: 'NoneType' object is not subscriptable</failure><system-out>--------------------------------- Captured Log ---------------------------------

--------------------------------- Captured Out ---------------------------------

</system-out><system-err>--------------------------------- Captured Err ---------------------------------

</system-err></testcase><testcase classname="tests.integration.api_network_test.TestNetworks" name="test_create_with_linklocal_ips" time="8.010"><failure message="docker.errors.APIError: 500 Server Error for http+docker://localhost/v1.41/containers/create: Internal Server Error (&quot;container create: unable to find network with name or ID bridge: network not found&quot;)">docker/api/client.py:296: in _raise_for_status
    response.raise_for_status()
../../.virtualenvs/docker-py/lib/python3.11/site-packages/requests/models.py:1021: in raise_for_status
    raise HTTPError(http_error_msg, response=self)
E   requests.exceptions.HTTPError: 500 Server Error: Internal Server Error for url: http+docker://localhost/v1.41/containers/create

The above exception was the direct cause of the following exception:
tests/integration/api_network_test.py:255: in test_create_with_linklocal_ips
    container = self.client.create_container(
docker/api/container.py:431: in create_container
    return self.create_container_from_config(config, name, platform)
docker/api/container.py:448: in create_container_from_config
    return self._result(res, True)
docker/api/client.py:302: in _result
    self._raise_for_status(response)
docker/api/client.py:298: in _raise_for_status
    raise create_api_error_from_http_exception(e) from e
docker/errors.py:39: in create_api_error_from_http_exception
    raise cls(e, response=response, explanation=explanation) from e
E   docker.errors.APIError: 500 Server Error for http+docker://localhost/v1.41/containers/create: Internal Server Error ("container create: unable to find network with name or ID bridge: network not found")</failure><system-out>--------------------------------- Captured Log ---------------------------------

--------------------------------- Captured Out ---------------------------------

</system-out><system-err>--------------------------------- Captured Err ---------------------------------

</system-err></testcase><testcase classname="tests.integration.api_network_test.TestNetworks" name="test_create_with_links" time="8.795"><failure message="AssertionError: assert None == ['docker-py-test-upstream:bar']">tests/integration/api_network_test.py:311: in test_create_with_links
    assert net_settings['Networks'][net_name]['Links'] == [
E   AssertionError: assert None == ['docker-py-test-upstream:bar']</failure><system-out>--------------------------------- Captured Log ---------------------------------

--------------------------------- Captured Out ---------------------------------

</system-out><system-err>--------------------------------- Captured Err ---------------------------------

</system-err></testcase><testcase classname="tests.integration.api_network_test.TestNetworks" name="test_inspect_network" time="8.012" /><testcase classname="tests.integration.api_network_test.TestNetworks" name="test_list_networks" time="8.175" /><testcase classname="tests.integration.api_network_test.TestNetworks" name="test_prune_networks" time="7.964" /><testcase classname="tests.integration.api_network_test.TestNetworks" name="test_remove_network" time="8.134" /><testcase classname="tests.integration.api_secret_test.SecretAPITest" name="test_create_secret" time="13.996" /><testcase classname="tests.integration.api_secret_test.SecretAPITest" name="test_create_secret_unicode_data" time="15.319" /><testcase classname="tests.integration.api_secret_test.SecretAPITest" name="test_inspect_secret" time="21.417" /><testcase classname="tests.integration.api_secret_test.SecretAPITest" name="test_list_secrets" time="19.043" /><testcase classname="tests.integration.api_secret_test.SecretAPITest" name="test_remove_secret" time="29.029" /><testcase classname="tests.integration.api_volume_test.TestVolumes" name="test_create_volume" time="17.507" /><testcase classname="tests.integration.api_volume_test.TestVolumes" name="test_create_volume_invalid_driver" time="19.544"><failure message="docker.errors.APIError: 500 Server Error for http+docker://localhost/v1.41/volumes/create: Internal Server Error (&quot;volume perfectcherryblossom uses volume plugin invalid.driver but it could not be retrieved: no volume plugin with name invalid.driver available: required plugin missing&quot;)">docker/api/client.py:296: in _raise_for_status
    response.raise_for_status()
../../.virtualenvs/docker-py/lib/python3.11/site-packages/requests/models.py:1021: in raise_for_status
    raise HTTPError(http_error_msg, response=self)
E   requests.exceptions.HTTPError: 500 Server Error: Internal Server Error for url: http+docker://localhost/v1.41/volumes/create

The above exception was the direct cause of the following exception:
tests/integration/api_volume_test.py:22: in test_create_volume_invalid_driver
    self.client.create_volume('perfectcherryblossom', driver_name)
docker/api/volume.py:92: in create_volume
    return self._result(self._post_json(url, data=data), True)
docker/api/client.py:302: in _result
    self._raise_for_status(response)
docker/api/client.py:298: in _raise_for_status
    raise create_api_error_from_http_exception(e) from e
docker/errors.py:39: in create_api_error_from_http_exception
    raise cls(e, response=response, explanation=explanation) from e
E   docker.errors.APIError: 500 Server Error for http+docker://localhost/v1.41/volumes/create: Internal Server Error ("volume perfectcherryblossom uses volume plugin invalid.driver but it could not be retrieved: no volume plugin with name invalid.driver available: required plugin missing")</failure><system-out>--------------------------------- Captured Log ---------------------------------

--------------------------------- Captured Out ---------------------------------

</system-out><system-err>--------------------------------- Captured Err ---------------------------------

</system-err></testcase><testcase classname="tests.integration.api_volume_test.TestVolumes" name="test_force_remove_volume" time="17.912" /><testcase classname="tests.integration.api_volume_test.TestVolumes" name="test_inspect_nonexistent_volume" time="17.550" /><testcase classname="tests.integration.api_volume_test.TestVolumes" name="test_inspect_volume" time="19.976"><failure message="AssertionError: assert {'CreatedAt':...l/_data', ...} == {'CreatedAt':...l/_data', ...}&#10;  Omitting 6 identical items, use -vv to show&#10;  Differing items:&#10;  {'Options': None} != {'Options': {}}&#10;  Full diff:&#10;    {&#10;     'CreatedAt': '2023-05-28T20:52:01+02:00',&#10;     'Driver': 'local',...&#10;  &#10;  ...Full output truncated (9 lines hidden), use '-vv' to show">tests/integration/api_volume_test.py:38: in test_inspect_volume
    assert volume_info == result
E   AssertionError: assert {'CreatedAt':...l/_data', ...} == {'CreatedAt':...l/_data', ...}
E     Omitting 6 identical items, use -vv to show
E     Differing items:
E     {'Options': None} != {'Options': {}}
E     Full diff:
E       {
E        'CreatedAt': '2023-05-28T20:52:01+02:00',
E        'Driver': 'local',...
E     
E     ...Full output truncated (9 lines hidden), use '-vv' to show</failure><system-out>--------------------------------- Captured Log ---------------------------------

--------------------------------- Captured Out ---------------------------------

</system-out><system-err>--------------------------------- Captured Err ---------------------------------

</system-err></testcase><testcase classname="tests.integration.api_volume_test.TestVolumes" name="test_list_volumes" time="18.608"><failure message="AssertionError: assert {'CreatedAt': '2023-05-28T20:52:19+02:00', 'Driver': 'local', 'Labels': {}, 'Mountpoint': '/home/riyad/podman/storage/volumes/imperishablenight/_data', ...} in [{'CreatedAt': '2023-05-28T20:29:15+02:00', 'Driver': 'local', 'Labels': {}, 'Mountpoint': '/home/riyad/podman/storage/volumes/dockerpytest_891725f5ee4d4b15/_data', ...}, {'CreatedAt': '2023-05-28T20:52:19+02:00', 'Driver': 'local', 'Labels': {}, 'Mountpoint': '/home/riyad/podman/storage/volumes/imperishablenight/_data', ...}]">tests/integration/api_volume_test.py:31: in test_list_volumes
    assert volume_info in volumes
E   AssertionError: assert {'CreatedAt': '2023-05-28T20:52:19+02:00', 'Driver': 'local', 'Labels': {}, 'Mountpoint': '/home/riyad/podman/storage/volumes/imperishablenight/_data', ...} in [{'CreatedAt': '2023-05-28T20:29:15+02:00', 'Driver': 'local', 'Labels': {}, 'Mountpoint': '/home/riyad/podman/storage/volumes/dockerpytest_891725f5ee4d4b15/_data', ...}, {'CreatedAt': '2023-05-28T20:52:19+02:00', 'Driver': 'local', 'Labels': {}, 'Mountpoint': '/home/riyad/podman/storage/volumes/imperishablenight/_data', ...}]</failure><system-out>--------------------------------- Captured Log ---------------------------------

--------------------------------- Captured Out ---------------------------------

</system-out><system-err>--------------------------------- Captured Err ---------------------------------

</system-err></testcase><testcase classname="tests.integration.api_volume_test.TestVolumes" name="test_prune_volumes" time="17.478" /><testcase classname="tests.integration.api_volume_test.TestVolumes" name="test_remove_nonexistent_volume" time="17.787" /><testcase classname="tests.integration.api_volume_test.TestVolumes" name="test_remove_volume" time="18.070" /><testcase classname="tests.integration.client_test.ClientTest" name="test_df" time="0.104"><failure message="docker.errors.APIError: 500 Server Error for http+docker://localhost/v1.41/system/df: Internal Server Error (&quot;runtime error: invalid memory address or nil pointer dereference&quot;)">docker/api/client.py:296: in _raise_for_status
    response.raise_for_status()
../../.virtualenvs/docker-py/lib/python3.11/site-packages/requests/models.py:1021: in raise_for_status
    raise HTTPError(http_error_msg, response=self)
E   requests.exceptions.HTTPError: 500 Server Error: Internal Server Error for url: http+docker://localhost/v1.41/system/df

The above exception was the direct cause of the following exception:
tests/integration/client_test.py:28: in test_df
    data = self.client.df()
docker/client.py:191: in df
    return self.api.df()
docker/utils/decorators.py:34: in wrapper
    return f(self, *args, **kwargs)
docker/api/daemon.py:22: in df
    return self._result(self._get(url), True)
docker/api/client.py:302: in _result
    self._raise_for_status(response)
docker/api/client.py:298: in _raise_for_status
    raise create_api_error_from_http_exception(e) from e
docker/errors.py:39: in create_api_error_from_http_exception
    raise cls(e, response=response, explanation=explanation) from e
E   docker.errors.APIError: 500 Server Error for http+docker://localhost/v1.41/system/df: Internal Server Error ("runtime error: invalid memory address or nil pointer dereference")</failure><system-out>--------------------------------- Captured Log ---------------------------------

--------------------------------- Captured Out ---------------------------------

</system-out><system-err>--------------------------------- Captured Err ---------------------------------

</system-err></testcase><testcase classname="tests.integration.client_test.ClientTest" name="test_info" time="4.465" /><testcase classname="tests.integration.client_test.ClientTest" name="test_ping" time="0.008" /><testcase classname="tests.integration.client_test.ClientTest" name="test_version" time="5.962" /><testcase classname="tests.integration.client_test.CancellableEventsTest" name="test_cancel_events" time="2.017" /><testcase classname="tests.integration.context_api_test.ContextLifecycleTest" name="test_context_remove" time="20.079" /><testcase classname="tests.integration.context_api_test.ContextLifecycleTest" name="test_lifecycle" time="24.160" /><testcase classname="tests.integration.context_api_test.ContextLifecycleTest" name="test_load_context_without_orchestrator" time="18.749" /><testcase classname="tests.integration.errors_test.ErrorsTest" name="test_api_error_parses_json" time="16.287"><failure message="AssertionError: assert 'You cannot remove a running container' in 'cannot remove container 7677d11d767f61280a503e60c49dd9249a898a4762a4e76f42787b212c719535 as it is running - running or paused containers cannot be removed without force: container state improper'">tests/integration/errors_test.py:13: in test_api_error_parses_json
    assert 'You cannot remove a running container' in explanation
E   AssertionError: assert 'You cannot remove a running container' in 'cannot remove container 7677d11d767f61280a503e60c49dd9249a898a4762a4e76f42787b212c719535 as it is running - running or paused containers cannot be removed without force: container state improper'</failure><system-out>--------------------------------- Captured Log ---------------------------------

--------------------------------- Captured Out ---------------------------------

</system-out><system-err>--------------------------------- Captured Err ---------------------------------

</system-err></testcase><testcase classname="tests.integration.models_containers_test.ContainerCollectionTest" name="test_get" time="11.265"><failure message="AssertionError: assert 'docker.io/li...alpine:latest' == 'alpine'&#10;  - alpine&#10;  + docker.io/library/alpine:latest">tests/integration/models_containers_test.py:189: in test_get
    assert client.containers.get(container.id).attrs[
E   AssertionError: assert 'docker.io/li...alpine:latest' == 'alpine'
E     - alpine
E     + docker.io/library/alpine:latest</failure><system-out>--------------------------------- Captured Log ---------------------------------

--------------------------------- Captured Out ---------------------------------

</system-out><system-err>--------------------------------- Captured Err ---------------------------------

</system-err></testcase><testcase classname="tests.integration.models_containers_test.ContainerCollectionTest" name="test_list" time="11.595"><failure message="AssertionError: assert 'docker.io/li...alpine:latest' == 'alpine'&#10;  - alpine&#10;  + docker.io/library/alpine:latest">tests/integration/models_containers_test.py:202: in test_list
    assert container.attrs['Config']['Image'] == 'alpine'
E   AssertionError: assert 'docker.io/li...alpine:latest' == 'alpine'
E     - alpine
E     + docker.io/library/alpine:latest</failure><system-out>--------------------------------- Captured Log ---------------------------------

--------------------------------- Captured Out ---------------------------------

</system-out><system-err>--------------------------------- Captured Err ---------------------------------

</system-err></testcase><testcase classname="tests.integration.models_containers_test.ContainerCollectionTest" name="test_list_sparse" time="12.591"><failure message="AssertionError: assert 'docker.io/li...alpine:latest' == 'alpine'&#10;  - alpine&#10;  + docker.io/library/alpine:latest">tests/integration/models_containers_test.py:220: in test_list_sparse
    assert container.attrs['Image'] == 'alpine'
E   AssertionError: assert 'docker.io/li...alpine:latest' == 'alpine'
E     - alpine
E     + docker.io/library/alpine:latest</failure><system-out>--------------------------------- Captured Log ---------------------------------

--------------------------------- Captured Out ---------------------------------

</system-out><system-err>--------------------------------- Captured Err ---------------------------------

</system-err></testcase><testcase classname="tests.integration.models_containers_test.ContainerCollectionTest" name="test_run" time="14.056" /><testcase classname="tests.integration.models_containers_test.ContainerCollectionTest" name="test_run_detach" time="11.495"><failure message="AssertionError: assert 'docker.io/li...alpine:latest' == 'alpine'&#10;  - alpine&#10;  + docker.io/library/alpine:latest">tests/integration/models_containers_test.py:26: in test_run_detach
    assert container.attrs['Config']['Image'] == "alpine"
E   AssertionError: assert 'docker.io/li...alpine:latest' == 'alpine'
E     - alpine
E     + docker.io/library/alpine:latest</failure><system-out>--------------------------------- Captured Log ---------------------------------

--------------------------------- Captured Out ---------------------------------

</system-out><system-err>--------------------------------- Captured Err ---------------------------------

</system-err></testcase><testcase classname="tests.integration.models_containers_test.ContainerCollectionTest" name="test_run_with_auto_remove" time="12.010" /><testcase classname="tests.integration.models_containers_test.ContainerCollectionTest" name="test_run_with_auto_remove_error" time="13.862"><failure message="docker.errors.NotFound: 404 Client Error for http+docker://localhost/v1.41/containers/b414c790f58ea360a09506de924ef71f37e0728b42c2ad1ae8bcca100365ec00/json: Not Found (&quot;no container with name or ID &quot;b414c790f58ea360a09506de924ef71f37e0728b42c2ad1ae8bcca100365ec00&quot; found: no such container&quot;)">docker/api/client.py:296: in _raise_for_status
    response.raise_for_status()
../../.virtualenvs/docker-py/lib/python3.11/site-packages/requests/models.py:1021: in raise_for_status
    raise HTTPError(http_error_msg, response=self)
E   requests.exceptions.HTTPError: 404 Client Error: Not Found for url: http+docker://localhost/v1.41/containers/b414c790f58ea360a09506de924ef71f37e0728b42c2ad1ae8bcca100365ec00/json

The above exception was the direct cause of the following exception:
tests/integration/models_containers_test.py:139: in test_run_with_auto_remove_error
    client.containers.run(
docker/models/containers.py:874: in run
    out = container.logs(
docker/models/containers.py:308: in logs
    return self.client.api.logs(self.id, **kwargs)
docker/utils/decorators.py:19: in wrapped
    return f(self, resource_id, *args, **kwargs)
docker/api/container.py:887: in logs
    output = self._get_result(container, stream, res)
docker/api/client.py:495: in _get_result
    return self._get_result_tty(stream, res, self._check_is_tty(container))
docker/utils/decorators.py:19: in wrapped
    return f(self, resource_id, *args, **kwargs)
docker/api/client.py:491: in _check_is_tty
    cont = self.inspect_container(container)
docker/utils/decorators.py:19: in wrapped
    return f(self, resource_id, *args, **kwargs)
docker/api/container.py:784: in inspect_container
    return self._result(
docker/api/client.py:302: in _result
    self._raise_for_status(response)
docker/api/client.py:298: in _raise_for_status
    raise create_api_error_from_http_exception(e) from e
docker/errors.py:39: in create_api_error_from_http_exception
    raise cls(e, response=response, explanation=explanation) from e
E   docker.errors.NotFound: 404 Client Error for http+docker://localhost/v1.41/containers/b414c790f58ea360a09506de924ef71f37e0728b42c2ad1ae8bcca100365ec00/json: Not Found ("no container with name or ID "b414c790f58ea360a09506de924ef71f37e0728b42c2ad1ae8bcca100365ec00" found: no such container")</failure><system-out>--------------------------------- Captured Log ---------------------------------

--------------------------------- Captured Out ---------------------------------

</system-out><system-err>--------------------------------- Captured Err ---------------------------------

</system-err></testcase><testcase classname="tests.integration.models_containers_test.ContainerCollectionTest" name="test_run_with_error" time="8.227" /><testcase classname="tests.integration.models_containers_test.ContainerCollectionTest" name="test_run_with_image_that_does_not_exist" time="7.060" /><testcase classname="tests.integration.models_containers_test.ContainerCollectionTest" name="test_run_with_json_file_driver" time="6.366" /><testcase classname="tests.integration.models_containers_test.ContainerCollectionTest" name="test_run_with_named_volume" time="6.910" /><testcase classname="tests.integration.models_containers_test.ContainerCollectionTest" name="test_run_with_network" time="6.277" /><testcase classname="tests.integration.models_containers_test.ContainerCollectionTest" name="test_run_with_none_driver" time="6.207" /><testcase classname="tests.integration.models_containers_test.ContainerCollectionTest" name="test_run_with_proxy_config" time="6.216" /><testcase classname="tests.integration.models_containers_test.ContainerCollectionTest" name="test_run_with_streamed_logs" time="6.188" /><testcase classname="tests.integration.models_containers_test.ContainerCollectionTest" name="test_run_with_streamed_logs_and_cancel" time="5.001"><failure message="Failed: Timeout &gt;5.0s">tests/integration/base.py:30: in tearDown
    client = docker.from_env(version=TEST_API_VERSION)
docker/client.py:96: in from_env
    return cls(
docker/client.py:45: in __init__
    self.api = APIClient(*args, **kwargs)
docker/api/client.py:197: in __init__
    self._version = self._retrieve_server_version()
docker/api/client.py:214: in _retrieve_server_version
    return self.version(api_version=False)["ApiVersion"]
docker/api/daemon.py:181: in version
    return self._result(self._get(url), json=True)
docker/utils/decorators.py:46: in inner
    return f(self, *args, **kwargs)
docker/api/client.py:251: in _get
    return self.get(url, **self._set_request_timeout(kwargs))
../../.virtualenvs/docker-py/lib/python3.11/site-packages/requests/sessions.py:600: in get
    return self.request("GET", url, **kwargs)
../../.virtualenvs/docker-py/lib/python3.11/site-packages/requests/sessions.py:587: in request
    resp = self.send(prep, **send_kwargs)
../../.virtualenvs/docker-py/lib/python3.11/site-packages/requests/sessions.py:701: in send
    r = adapter.send(request, **kwargs)
../../.virtualenvs/docker-py/lib/python3.11/site-packages/requests/adapters.py:489: in send
    resp = conn.urlopen(
../../.virtualenvs/docker-py/lib/python3.11/site-packages/urllib3/connectionpool.py:703: in urlopen
    httplib_response = self._make_request(
../../.virtualenvs/docker-py/lib/python3.11/site-packages/urllib3/connectionpool.py:449: in _make_request
    six.raise_from(e, None)
../../.virtualenvs/docker-py/lib/python3.11/site-packages/urllib3/connectionpool.py:444: in _make_request
    httplib_response = conn.getresponse()
/usr/lib/python3.11/http/client.py:1374: in getresponse
    response.begin()
/usr/lib/python3.11/http/client.py:318: in begin
    version, status, reason = self._read_status()
/usr/lib/python3.11/http/client.py:279: in _read_status
    line = str(self.fp.readline(_MAXLINE + 1), "iso-8859-1")
/usr/lib/python3.11/socket.py:706: in readinto
    return self._sock.recv_into(b)
E   Failed: Timeout &gt;5.0s</failure><system-out>--------------------------------- Captured Log ---------------------------------

--------------------------------- Captured Out ---------------------------------

</system-out><system-err>--------------------------------- Captured Err ---------------------------------

</system-err></testcase><testcase classname="tests.integration.models_containers_test.ContainerCollectionTest" name="test_run_with_volume" time="6.572" /><testcase classname="tests.integration.models_containers_test.ContainerTest" name="test_commit" time="7.700" /><testcase classname="tests.integration.models_containers_test.ContainerTest" name="test_create_with_volume_driver" time="5.901"><failure message="AssertionError: assert '' == 'foo'&#10;  - foo">tests/integration/models_containers_test.py:456: in test_create_with_volume_driver
    assert container.attrs['HostConfig']['VolumeDriver'] == 'foo'
E   AssertionError: assert '' == 'foo'
E     - foo</failure><system-out>--------------------------------- Captured Log ---------------------------------

--------------------------------- Captured Out ---------------------------------

</system-out><system-err>--------------------------------- Captured Err ---------------------------------

</system-err></testcase><testcase classname="tests.integration.models_containers_test.ContainerTest" name="test_diff" time="6.199"><failure message="AssertionError: assert [{'Kind': 1, ...ath': '/etc'}] == [{'Kind': 1, 'Path': '/test'}]&#10;  Left contains one more item: {'Kind': 0, 'Path': '/etc'}&#10;  Full diff:&#10;  - [{'Kind': 1, 'Path': '/test'}]&#10;  + [{'Kind': 1, 'Path': '/test'}, {'Kind': 0, 'Path': '/etc'}]">tests/integration/models_containers_test.py:251: in test_diff
    assert container.diff() == [{'Path': '/test', 'Kind': 1}]
E   AssertionError: assert [{'Kind': 1, ...ath': '/etc'}] == [{'Kind': 1, 'Path': '/test'}]
E     Left contains one more item: {'Kind': 0, 'Path': '/etc'}
E     Full diff:
E     - [{'Kind': 1, 'Path': '/test'}]
E     + [{'Kind': 1, 'Path': '/test'}, {'Kind': 0, 'Path': '/etc'}]</failure><system-out>--------------------------------- Captured Log ---------------------------------

--------------------------------- Captured Out ---------------------------------

</system-out><system-err>--------------------------------- Captured Err ---------------------------------

</system-err></testcase><testcase classname="tests.integration.models_containers_test.ContainerTest" name="test_exec_run_failed" time="6.045"><failure message="assert 127 == 126">tests/integration/models_containers_test.py:270: in test_exec_run_failed
    assert exec_output[0] == 126
E   assert 127 == 126</failure><system-out>--------------------------------- Captured Log ---------------------------------

--------------------------------- Captured Out ---------------------------------

</system-out><system-err>--------------------------------- Captured Err ---------------------------------

</system-err></testcase><testcase classname="tests.integration.models_containers_test.ContainerTest" name="test_exec_run_success" time="6.245" /><testcase classname="tests.integration.models_containers_test.ContainerTest" name="test_kill" time="6.107" /><testcase classname="tests.integration.models_containers_test.ContainerTest" name="test_logs" time="6.838" /><testcase classname="tests.integration.models_containers_test.ContainerTest" name="test_pause" time="6.232" /><testcase classname="tests.integration.models_containers_test.ContainerTest" name="test_ports_target_list" time="6.184" /><testcase classname="tests.integration.models_containers_test.ContainerTest" name="test_ports_target_none" time="6.153" /><testcase classname="tests.integration.models_containers_test.ContainerTest" name="test_ports_target_tuple" time="6.026" /><testcase classname="tests.integration.models_containers_test.ContainerTest" name="test_remove" time="6.210" /><testcase classname="tests.integration.models_containers_test.ContainerTest" name="test_rename" time="5.790" /><testcase classname="tests.integration.models_containers_test.ContainerTest" name="test_restart" time="16.063" /><testcase classname="tests.integration.models_containers_test.ContainerTest" name="test_start" time="5.966" /><testcase classname="tests.integration.models_containers_test.ContainerTest" name="test_stats" time="5.934" /><testcase classname="tests.integration.models_containers_test.ContainerTest" name="test_stop" time="5.893" /><testcase classname="tests.integration.models_containers_test.ContainerTest" name="test_top" time="5.994"><failure message="AssertionError: assert 'sleep 60' in ['1 root      0:00 sleep 60']">tests/integration/models_containers_test.py:425: in test_top
    assert 'sleep 60' in top['Processes'][0]
E   AssertionError: assert 'sleep 60' in ['1 root      0:00 sleep 60']</failure><system-out>--------------------------------- Captured Log ---------------------------------

--------------------------------- Captured Out ---------------------------------

</system-out><system-err>--------------------------------- Captured Err ---------------------------------

</system-err></testcase><testcase classname="tests.integration.models_containers_test.ContainerTest" name="test_update" time="6.076"><failure message="TypeError: a bytes-like object is required, not 'str'">docker/api/client.py:296: in _raise_for_status
    response.raise_for_status()
../../.virtualenvs/docker-py/lib/python3.11/site-packages/requests/models.py:1021: in raise_for_status
    raise HTTPError(http_error_msg, response=self)
E   requests.exceptions.HTTPError: 404 Client Error: Not Found for url: http+docker://localhost/v1.41/containers/a6b892efbe366364958f570fa8341b92d8a82226f04a5e65b299c91334f7bb01/update

During handling of the above exception, another exception occurred:
tests/integration/models_containers_test.py:433: in test_update
    container.update(cpu_shares=3)
docker/models/containers.py:491: in update
    return self.client.api.update_container(self.id, **kwargs)
docker/utils/decorators.py:34: in wrapper
    return f(self, *args, **kwargs)
docker/utils/decorators.py:19: in wrapped
    return f(self, resource_id, *args, **kwargs)
docker/api/container.py:1303: in update_container
    return self._result(res, True)
docker/api/client.py:302: in _result
    self._raise_for_status(response)
docker/api/client.py:298: in _raise_for_status
    raise create_api_error_from_http_exception(e) from e
docker/errors.py:34: in create_api_error_from_http_exception
    if any(fragment in explanation_msg
docker/errors.py:34: in &lt;genexpr&gt;
    if any(fragment in explanation_msg
E   TypeError: a bytes-like object is required, not 'str'</failure><system-out>--------------------------------- Captured Log ---------------------------------

--------------------------------- Captured Out ---------------------------------

</system-out><system-err>--------------------------------- Captured Err ---------------------------------

</system-err></testcase><testcase classname="tests.integration.models_containers_test.ContainerTest" name="test_wait" time="6.408" /><testcase classname="tests.integration.models_images_test.ImageCollectionTest" name="test_build" time="6.077" /><testcase classname="tests.integration.models_images_test.ImageCollectionTest" name="test_build_with_error" time="6.064"><failure message="assert &quot;The command '/bin/sh -c exit 1' returned a non-zero code: 1&quot; in 'docker.errors.BuildError: building at STEP &quot;RUN exit 1&quot;: while running runtime: exit status 1'&#10; +  where 'docker.errors.BuildError: building at STEP &quot;RUN exit 1&quot;: while running runtime: exit status 1' = &lt;bound method ExceptionInfo.exconly of &lt;ExceptionInfo BuildError('building at STEP &quot;RUN exit 1&quot;: while running runtime: exit status 1\n') tblen=2&gt;&gt;()&#10; +    where &lt;bound method ExceptionInfo.exconly of &lt;ExceptionInfo BuildError('building at STEP &quot;RUN exit 1&quot;: while running runtime: exit status 1\n') tblen=2&gt;&gt; = &lt;ExceptionInfo BuildError('building at STEP &quot;RUN exit 1&quot;: while running runtime: exit status 1\n') tblen=2&gt;.exconly">tests/integration/models_images_test.py:30: in test_build_with_error
    assert (
E   assert "The command '/bin/sh -c exit 1' returned a non-zero code: 1" in 'docker.errors.BuildError: building at STEP "RUN exit 1": while running runtime: exit status 1'
E    +  where 'docker.errors.BuildError: building at STEP "RUN exit 1": while running runtime: exit status 1' = &lt;bound method ExceptionInfo.exconly of &lt;ExceptionInfo BuildError('building at STEP "RUN exit 1": while running runtime: exit status 1\n') tblen=2&gt;&gt;()
E    +    where &lt;bound method ExceptionInfo.exconly of &lt;ExceptionInfo BuildError('building at STEP "RUN exit 1": while running runtime: exit status 1\n') tblen=2&gt;&gt; = &lt;ExceptionInfo BuildError('building at STEP "RUN exit 1": while running runtime: exit status 1\n') tblen=2&gt;.exconly</failure><system-out>--------------------------------- Captured Log ---------------------------------

--------------------------------- Captured Out ---------------------------------

</system-out><system-err>--------------------------------- Captured Err ---------------------------------

</system-err></testcase><testcase classname="tests.integration.models_images_test.ImageCollectionTest" name="test_build_with_multiple_success" time="5.941" /><testcase classname="tests.integration.models_images_test.ImageCollectionTest" name="test_build_with_success_build_output" time="6.376" /><testcase classname="tests.integration.models_images_test.ImageCollectionTest" name="test_list" time="7.406" /><testcase classname="tests.integration.models_images_test.ImageCollectionTest" name="test_list_with_repository" time="7.150" /><testcase classname="tests.integration.models_images_test.ImageCollectionTest" name="test_load_error" time="5.417"><failure message="docker.errors.APIError: 500 Server Error for http+docker://localhost/v1.41/images/load: Internal Server Error (&quot;failed to load image: payload does not match any of the supported image formats:&#10; * oci: initializing source oci:/var/tmp/api_load.tar242076123:: open /var/tmp/api_load.tar242076123/index.json: not a directory&#10; * oci-archive: creating temp directory: untarring file &quot;/var/tmp/oci1530119874&quot;: unexpected EOF&#10; * docker-archive: loading tar component manifest.json: unexpected EOF&#10; * dir: open /var/tmp/api_load.tar242076123/manifest.json: not a directory&quot;)">docker/api/client.py:296: in _raise_for_status
    response.raise_for_status()
../../.virtualenvs/docker-py/lib/python3.11/site-packages/requests/models.py:1021: in raise_for_status
    raise HTTPError(http_error_msg, response=self)
E   requests.exceptions.HTTPError: 500 Server Error: Internal Server Error for url: http+docker://localhost/v1.41/images/load

The above exception was the direct cause of the following exception:
tests/integration/models_images_test.py:98: in test_load_error
    client.images.load('abc')
docker/models/images.py:403: in load
    for chunk in resp:
docker/api/client.py:386: in _stream_helper
    yield self._result(response, json=decode)
docker/api/client.py:302: in _result
    self._raise_for_status(response)
docker/api/client.py:298: in _raise_for_status
    raise create_api_error_from_http_exception(e) from e
docker/errors.py:39: in create_api_error_from_http_exception
    raise cls(e, response=response, explanation=explanation) from e
E   docker.errors.APIError: 500 Server Error for http+docker://localhost/v1.41/images/load: Internal Server Error ("failed to load image: payload does not match any of the supported image formats:
E    * oci: initializing source oci:/var/tmp/api_load.tar242076123:: open /var/tmp/api_load.tar242076123/index.json: not a directory
E    * oci-archive: creating temp directory: untarring file "/var/tmp/oci1530119874": unexpected EOF
E    * docker-archive: loading tar component manifest.json: unexpected EOF
E    * dir: open /var/tmp/api_load.tar242076123/manifest.json: not a directory")</failure><system-out>--------------------------------- Captured Log ---------------------------------

--------------------------------- Captured Out ---------------------------------

</system-out><system-err>--------------------------------- Captured Err ---------------------------------

</system-err></testcase><testcase classname="tests.integration.models_images_test.ImageCollectionTest" name="test_pull" time="6.784"><failure message="AssertionError: assert 'alpine:latest' in ['docker.io/library/alpine:latest']">tests/integration/models_images_test.py:71: in test_pull
    assert 'alpine:latest' in image.attrs['RepoTags']
E   AssertionError: assert 'alpine:latest' in ['docker.io/library/alpine:latest']</failure><system-out>--------------------------------- Captured Log ---------------------------------

--------------------------------- Captured Out ---------------------------------

</system-out><system-err>--------------------------------- Captured Err ---------------------------------

</system-err></testcase><testcase classname="tests.integration.models_images_test.ImageCollectionTest" name="test_pull_multiple" time="7.042"><failure message="assert False&#10; +  where False = any([False])">tests/integration/models_images_test.py:91: in test_pull_multiple
    assert any([
E   assert False
E    +  where False = any([False])</failure><system-out>--------------------------------- Captured Log ---------------------------------

--------------------------------- Captured Out ---------------------------------

</system-out><system-err>--------------------------------- Captured Err ---------------------------------

</system-err></testcase><testcase classname="tests.integration.models_images_test.ImageCollectionTest" name="test_pull_with_sha" time="7.177"><failure message="AssertionError: assert 'hello-world@sha256:083de497cff944f969d8499ab94f07134c50bcf5e6b9559b27182d3fa80ce3f7' in ['docker.io/library/hello-world@sha256:083de497cff944f969d8499ab94f07134c50bcf5e6b9559b27182d3fa80ce3f7', 'docker.io/library/hello-world@sha256:8072a54ebb3bc136150e2f2860f00a7bf45f13eeb917cca2430fcd0054c8e51b']">tests/integration/models_images_test.py:85: in test_pull_with_sha
    assert image_ref in image.attrs['RepoDigests']
E   AssertionError: assert 'hello-world@sha256:083de497cff944f969d8499ab94f07134c50bcf5e6b9559b27182d3fa80ce3f7' in ['docker.io/library/hello-world@sha256:083de497cff944f969d8499ab94f07134c50bcf5e6b9559b27182d3fa80ce3f7', 'docker.io/library/hello-world@sha256:8072a54ebb3bc136150e2f2860f00a7bf45f13eeb917cca2430fcd0054c8e51b']</failure><system-out>--------------------------------- Captured Log ---------------------------------

--------------------------------- Captured Out ---------------------------------

</system-out><system-err>--------------------------------- Captured Err ---------------------------------

</system-err></testcase><testcase classname="tests.integration.models_images_test.ImageCollectionTest" name="test_pull_with_tag" time="6.870"><failure message="AssertionError: assert 'alpine:3.10' in ['docker.io/library/alpine:3.10']">tests/integration/models_images_test.py:76: in test_pull_with_tag
    assert 'alpine:3.10' in image.attrs['RepoTags']
E   AssertionError: assert 'alpine:3.10' in ['docker.io/library/alpine:3.10']</failure><system-out>--------------------------------- Captured Log ---------------------------------

--------------------------------- Captured Out ---------------------------------

</system-out><system-err>--------------------------------- Captured Err ---------------------------------

</system-err></testcase><testcase classname="tests.integration.models_images_test.ImageCollectionTest" name="test_save_and_load" time="5.685" /><testcase classname="tests.integration.models_images_test.ImageCollectionTest" name="test_save_and_load_repo_name" time="5.510"><failure message="docker.errors.InvalidArgument: dockerpytest_a600973e1ce5b57a:latest is not a valid tag for this image">tests/integration/models_images_test.py:122: in test_save_and_load_repo_name
    stream = image.save(named=f'{additional_tag}:latest')
docker/models/images.py:117: in save
    raise InvalidArgument(
E   docker.errors.InvalidArgument: dockerpytest_a600973e1ce5b57a:latest is not a valid tag for this image</failure><system-out>--------------------------------- Captured Log ---------------------------------

--------------------------------- Captured Out ---------------------------------

</system-out><system-err>--------------------------------- Captured Err ---------------------------------

</system-err></testcase><testcase classname="tests.integration.models_images_test.ImageCollectionTest" name="test_save_name_error" time="5.744" /><testcase classname="tests.integration.models_images_test.ImageTest" name="test_tag_and_remove" time="6.969" /><testcase classname="tests.integration.models_networks_test.NetworkCollectionTest" name="test_create" time="5.599" /><testcase classname="tests.integration.models_networks_test.NetworkCollectionTest" name="test_get" time="5.537" /><testcase classname="tests.integration.models_networks_test.NetworkCollectionTest" name="test_list_remove" time="5.707" /><testcase classname="tests.integration.models_networks_test.NetworkTest" name="test_connect_disconnect" time="6.475" /><testcase classname="tests.integration.models_resources_test.ModelTest" name="test_reload" time="6.305" /><testcase classname="tests.integration.models_volumes_test.VolumesTest" name="test_create_get" time="5.632" /><testcase classname="tests.integration.models_volumes_test.VolumesTest" name="test_list_remove" time="5.595" /><testcase classname="tests.integration.regression_test.TestRegressions" name="test_443_handle_nonchunked_response_in_stream" time="8.215"><skipped type="pytest.xfail" message="Docker API always returns chunked resp" /></testcase><testcase classname="tests.integration.regression_test.TestRegressions" name="test_542_truncate_ids_client_side" time="8.826" /><testcase classname="tests.integration.regression_test.TestRegressions" name="test_647_support_doubleslash_in_image_names" time="8.500" /><testcase classname="tests.integration.regression_test.TestRegressions" name="test_649_handle_timeout_value_none" time="8.780" /><testcase classname="tests.integration.regression_test.TestRegressions" name="test_715_handle_user_param_as_int_value" time="9.831" /><testcase classname="tests.integration.regression_test.TestRegressions" name="test_792_explicit_port_protocol" time="8.598" /><testcase classname="tests.integration.credentials.utils_test" name="test_create_environment_dict" time="0.005" /></testsuite></testsuites>